Workbook
Name \C: #REF!
Name \C: #REF!
Name \C: #REF!
Name \C: #REF!
Name \F: #REF!
Name \F: #REF!
Name _1_0_0TO_LT1_IN_C: #REF!
Name _10.1.2_P2: #REF!
Name _10.1.2_P2: #REF!
Name _10.1.2_P3: #REF!
Name _10.1.2_P3: #REF!
Name _10.1.2_P4: #REF!
Name _10.1.2_P4: #REF!
Name _2_0_0TO_LT1_IN_C: #REF!
Name _3_0_0TO_LT2_IN_C: #REF!
Name _4_0_0TO_LT2_IN_C: #REF!
Name _7.0.13_P10: #REF!
Name _7.0.13_P10: #REF!
Name _7.0.13_P12: #REF!
Name _7.0.13_P12: #REF!
Name _7.0.13_P14: #REF!
Name _7.0.13_P14: #REF!
Name _7.0.13_P16: #REF!
Name _7.0.13_P16: #REF!
Name _7.0.13_P18: #REF!
Name _7.0.13_P18: #REF!
Name _7.0.13_P2: #REF!
Name _7.0.13_P2: #REF!
Name _7.0.13_P20: #REF!
Name _7.0.13_P20: #REF!
Name _7.0.13_P4: #REF!
Name _7.0.13_P4: #REF!
Name _7.0.13_P6: #REF!
Name _7.0.13_P6: #REF!
Name _7.0.13_P8: #REF!
Name _7.0.13_P8: #REF!
Name compclasses: #REF!
Name compclasses: #REF!
Name compclasses: #REF!
Name compcomps: #REF!
Name compcomps: #REF!
Name compcomps: #REF!
Name COMPLIST: #REF!
Name COMPLIST: #REF!
Name COMPLIST: #REF!
Name FROM_RDGOVADJ_1: #REF!
Name FROM_RDGOVADJ_1: #REF!
Name FROM_RDGOVADJ_2: #REF!
Name FROM_RDGOVADJ_2: #REF!
Name MACROS: #REF!
Name MACROS: #REF!
Name PIECES_1: #REF!
Name PIECES_1: #REF!
Name PIECES_2: #REF!
Name PIECES_2: #REF!
Name SPR_IN_TO_SUB_1: #REF!
Name SPR_IN_TO_SUB_1: #REF!
Name SPR_IN_TO_SUB_2: #REF!
Name SPR_IN_TO_SUB_2: #REF!
Name sumcode: #REF!

Sheet NOTES
A1: =Inputs!$C$4 -> Unit Delivery Cost Model - 12/16/2025
A2: UDCINPUTS DOCUMENTATION PAGE
A4: Worksheet | B4: USPS-FY25-19 Synopsis
A5: Inputs | B5: Various Inputs needed thoroughout the model
A6: 7.0.6 | B6: Inputs from USPS-FY25-32, CS06&7.xls, W/S 7.0.6
A7: 7.0.8 | B7: Inputs from USPS-FY25-19, CS06&7.xls, W/S 7.0.8
A8: 7.0.6.10 | B8: Inputs from USPS-FY25-19, CS06&7.xls, W/S 7.0.6.10
A9: City DAL Costs | B9: City DAL direct labor street costs are brought over from USPS-FY25-32 CS06&7.xls WS 7.0.6, and cost for flat host pieces are calculated.
A10: CS06&7 CRA | B10: From USPS-FY25-32, CS06&7.xls, Outputs to CRA
A11: CS7Shape | B11: USPS-FY25-32, 7.0.6 City carrier letter route street costs by shape
A12: CS10CRA | B12: USPS-FY25-32 CS10, Outputs to CRA
A13: Rural DAL Costs | B13: Rural DAL direct labor street costs are brought over from CS10.xls 10.3, and cost for flat host pieces are calculated.
A14: RuralCosts | B14: USPS-FY25-32, CS10.xls WS 10.1.3, 10.2.3, Rural carrier costs for evaluated and other routes
A15: RuralVols | B15: USPS-FY25-32 CS10.xlsx, Inputs DK, RCS volumes by rural evaluation factor
... A31: ParcelVols | B31: Crosswalks Periodicals parcels to flats by taking ratio of CCCS and RCCS parcels to RPW parcels.

Sheet Changes
A1: Sheet | B1: Change
A3: December 2019 Changes
A4: 7.0.6.6 | B4: Added sheet for distribution of Sunday/Holiday costs, as per Docket No RM2018-5, Order 4972.
A5: 7.0.6 | B5: Sunday Delivery column removed as no longer needed because of the addition of sheet 7.0.6.6.
A6: CS6&7 CRA | B6: Sunday/Holidays costs added into Delivery Activities column from CS06&7-NP-FY19.xlsx source.
A8: 2020 Changes for RM2019-6 Proposal One, SPR
A9: 7.0.6 | B9: New SPR columns added from CS06&7, C-F. Old SPR columns removed.
A10: 7.0.6.6 | B10: Removed Sheet, no longer needed as all data is on Sheet 7.0.6
A12: 2021 Changes for RM2021-7, SPR Peak and Non-Peak
A13: 7.0.6 | B13: New SPR columns for SPR Peak and Non-Peak from CS06&7, D-E. Changed formulas for columns F-Z to point to the correct column in CS06&7.
A15: 2024 Changes for RRECS (RM2024-2, Order 7919)
A16: CS10 CRA | B16: Updated references to CS10 Outputs to CRA tab, including removal of second costpool for other routes and renaming of evaluated routes costpool
A17: RuralVols | B17: Updated references to CS10 Inputs DK tab, including removal of old costpools and addition of new ones consistent with RRECS; added formulas to look up values based on CRA class numbers
A18: RuralVols | B18: Updated links to RCCS Matrix consistent with RRECS and allocate Direct Bundle volumes to Door Parcels
A19: RuralCosts | B19: Updated links to CS10 to refer to 10.1.2 tab, including removal of old costpools and addition of new ones consistent with RRECS; added formulas to look up values based on CRA class numbers
A20: Rural DAL Costs | B20: Updated references to other worksheets consistent with new methodology; remove split between evaluated and other routes as DALs costs no longer need to be split
A21: BYPBack | B21: Added links to PB workbook and updated values
A22: RCSECRVols | B22: Updated links to RCCS Matrix consistent with RRECS, including removal of old costpools and addition of new ones consistent with RRECS
A23: BoxholderbyShape | B23: Updated links to RCCS Matrix consistent with RRECS
A24: PeriodicalsVolAdj | B24: Updated references to 7.0.8 tab for Parcels
A25: ParcelVols | B25: Updated formulas to include three Parcel costpools
A27: 2024 Changes for Top Down (RM2022-3)
A28: CS6&7 CRA | B28: Updated all references to refer to CS06&7 Outputs to CRA tab, including costpools no longer relevant under Top Down; added formulas to look up values based on CRA class numbers
A29: 7.0.8 | B29: Updated references to I_FORMS
A30: 7.0.8 | B30: Updated references to CS06&7 7.0.8 tab; added formulas to look up values based on CRA class numbers
A31: 7.0.6 | B31: Updated references to CS06&7 7.0.6 tab, including removing costpools no longer relevant under Top Down; added formulas to look up values based on CRA class numbers
A32: 7.0.6.10 | B32: Renamed 7.0.6.5; Updated references to refer to CS06&7 7.0.6.5 tab, including removing costpools no longer relevant under Top Down; added formulas to look up values based on CRA class numbers; ultimately deleted as not needed (data on 7.0.6 tab)
A33: CS7Shape | B33: Updated references to CS06&7 7.0.6.5 tab, including combining Deviation Parcels and Accountables into one costpool; added formulas to look up values based on CRA class numbers
A35: 2024 Changes Additional
A36: 7.0.8 | B36: Removed FSS
A37: CS7Shape | B37: Removed FSS
A38: RuralCosts | B38: Removed FSS
A39: RuralVols | B39: Removed FSS
A40: CCSDALs | B40: Removed FSS
A41: CCSECRVols | B41: Removed FSS
A42: RCSECRVols | B42: Removed FSS
A43: CARMM | B43: Removed note on FSS Split
A44: CARMMCasing | B44: Removed note on FSS Split
A45: BYPBack | B45: Added formulas to look up values based on CRA class numbers
A46: DPS% | B46: Added formulas to look up values
...

Sheet Inputs
B1: Inputs Used in USPS-FY25-19
A3: Line No.
A4: 1 | B4: Library Reference & Revision Date | C4: Unit Delivery Cost Model - 12/16/2025
A6: 2 | B6: YEAR | C6: FY 2025
A8: =A6+1 -> 3 | B8: Adjustment factor for HD Letters to HD Flats | C8: =[1]MM_HD_SAT_Summary!$I$9 -> 0.0031055058 | D8: Source:
A9: =A8+1 -> 4 | B9: Adjustment factor for Sat Letters to Sat Flats | C9: =[1]MM_HD_SAT_Summary!$I$10 -> 0.067217436 | D9: FCM_MM_WGTI_FY25_EOYv.xlsx

Sheet CS6&7 CRA
A1: ='7.0.6'!A1 -> Unit Delivery Cost Model - 12/16/2025
A2: C/S 6&7 CITY CARRIERS
A3: OUTPUTS TO CRA MODEL
A5: LINE NO. | B5: CLASS, SUBCLASS, OR SPECIAL SERVICE | C5: IN-OFFICE DIRECT LABOR | D5: IN-OFFICE SUPPORT OVERHEAD | E5: IN-OFFICE ROUTE SUPPORT | F5: DELIVERY ACTIVITIES
B6: COLUMN NUMBER | C6: -1 | D6: =C6-1 -> -2 | E6: =D6-1 -> -3 | F6: -3
B7: UNITS | C7: $(000) | D7: $(000) | E7: $(000) | F7: $(000)
B8: COLUMN SOURCE/NOTES | C8: WS 6.0.2.1 C2 | D8: ="L"&A30&" dist on C"&-C6 -> L21 dist on C1 | E8: Outputs to CRA | F8: Outputs to CRA
B9: MODEL COMPONENT | C9: 43 | D9: 44 | E9: 604 | F9: 47 + 48 + 49
A10: 1 | B10: FIRST-CLASS MAIL
A11: =A10+1 -> 2 | B11: SINGLE-PIECE LETTERS | C11: ='[2]6.0.2.1'!F11 -> 166731.92 | D11: =C11/C$31*D$31 -> 22864.588 | E11: ='[2]Outputs to CRA'!E12 -> 14195.783 | F11: ='[2]Outputs to CRA'!F12+'[2]Outputs to CRA'!G12+'[2]Outputs to CRA'!H12 -> 280972.66
A12: =A11+1 -> 3 | B12: SINGLE-PIECE CARDS | C12: ='[2]6.0.2.1'!F12 -> 9361.7585 | D12: =C12/C$31*D$31 -> 1283.8139 | E12: ='[2]Outputs to CRA'!E13 -> 635.21465 | F12: ='[2]Outputs to CRA'!F13+'[2]Outputs to CRA'!G13+'[2]Outputs to CRA'!H13 -> 10015.63
A13: =A12+1 -> 4 | B13: PRESORT LETTERS | C13: ='[2]6.0.2.1'!F13 -> 361821.5 | D13: =C13/C$31*D$31 -> 49617.971 | E13: ='[2]Outputs to CRA'!E14 -> 27551.071 | F13: ='[2]Outputs to CRA'!F14+'[2]Outputs to CRA'!G14+'[2]Outputs to CRA'!H14 -> 423776.48
A14: =A13+1 -> 5 | B14: PRESORT CARDS | C14: ='[2]6.0.2.1'!F14 -> 26921.232 | D14: =C14/C$31*D$31 -> 3691.8119 | E14: ='[2]Outputs to CRA'!E15 -> 2132.0624 | F14: ='[2]Outputs to CRA'!F15+'[2]Outputs to CRA'!G15+'[2]Outputs to CRA'!H15 -> 34003.954
A15: =A14+1 -> 6 | B15: SINGLE PIECE FLATS | C15: ='[2]6.0.2.1'!F15 -> 63759.544 | D15: =C15/C$31*D$31 -> 8743.591 | E15: ='[2]Outputs to CRA'!E16 -> 2702.7843 | F15: ='[2]Outputs to CRA'!F16+'[2]Outputs to CRA'!G16+'[2]Outputs to CRA'!H16 -> 11658.984
A16: =A15+1 -> 7 | B16: PRESORT FLATS | C16: ='[2]6.0.2.1'!F16 -> 66608.274 | D16: =C16/C$31*D$31 -> 9134.2483 | E16: ='[2]Outputs to CRA'!E17 -> 2653.5014 | F16: ='[2]Outputs to CRA'!F17+'[2]Outputs to CRA'!G17+'[2]Outputs to CRA'!H17 -> 5195.9811
A17: =A16+1 -> 8 | B17: USPS MARKETING MAIL
A18: =A17+1 -> 9 | B18: HIGH DENSITY & SATURATION LETTERS | C18: ='[2]6.0.2.1'!F19 -> 55182.385 | D18: =C18/C$31*D$31 -> 7567.3723 | E18: ='[2]Outputs to CRA'!E20 -> 5205.1514 | F18: ='[2]Outputs to CRA'!F20+'[2]Outputs to CRA'!G20+'[2]Outputs to CRA'!H20 -> 94839.18
A19: =A18+1 -> 10 | B19: HIGH DENSITY & SATURATION FLATS & PARCELS | C19: ='[2]6.0.2.1'!F20 -> 70465.38 | D19: =C19/C$31*D$31 -> 9663.1881 | E19: ='[2]Outputs to CRA'!E21 -> 9031.315 | F19: ='[2]Outputs to CRA'!F21+'[2]Outputs to CRA'!G21+'[2]Outputs to CRA'!H21 -> 192903.99
A20: =A19+1 -> 11 | B20: EVERY DOOR DIRECT MAIL RETAIL | C20: ='[2]6.0.2.1'!F21 -> 5007.5316 | D20: =C20/C$31*D$31 -> 686.70204 | E20: ='[2]Outputs to CRA'!E22 -> 635.2942 | F20: ='[2]Outputs to CRA'!F22+'[2]Outputs to CRA'!G22+'[2]Outputs to CRA'!H22 -> 13512.623
A21: =A20+1 -> 12 | B21: CARRIER ROUTE | C21: ='[2]6.0.2.1'!F22 -> 193209.9 | D21: =C21/C$31*D$31 -> 26495.615 | E21: ='[2]Outputs to CRA'!E23 -> 8220.6369 | F21: ='[2]Outputs to CRA'!F23+'[2]Outputs to CRA'!G23+'[2]Outputs to CRA'!H23 -> 30838.966
A22: =A21+1 -> 13 | B22: LETTERS | C22: ='[2]6.0.2.1'!F23 -> 476552.55 | D22: =C22/C$31*D$31 -> 65351.481 | E22: ='[2]Outputs to CRA'!E24 -> 36408.862 | F22: ='[2]Outputs to CRA'!F24+'[2]Outputs to CRA'!G24+'[2]Outputs to CRA'!H24 -> 562270.52
A23: =A22+1 -> 14 | B23: FLATS | C23: ='[2]6.0.2.1'!F24 -> 225228.98 | D23: =C23/C$31*D$31 -> 30886.515 | E23: ='[2]Outputs to CRA'!E25 -> 9059.4731 | F23: ='[2]Outputs to CRA'!F25+'[2]Outputs to CRA'!G25+'[2]Outputs to CRA'!H25 -> 20207.345
A24: =A23+1 -> 15 | B24: PARCELS | C24: ='[2]6.0.2.1'!F25 -> 1482.9199 | D24: =C24/C$31*D$31 -> 203.3585 | E24: ='[2]Outputs to CRA'!E26 -> 110.95859 | F24: ='[2]Outputs to CRA'!F26+'[2]Outputs to CRA'!G26+'[2]Outputs to CRA'!H26 -> 1903.1363
A25: =A24+1 -> 16 | B25: TOTAL PERIODICALS | C25: ='[2]6.0.2.1'!F30 -> 195656.05 | D25: =C25/C$31*D$31 -> 26831.065 | E25: ='[2]Outputs to CRA'!$E$31 -> 8060.2961 | F25: ='[2]Outputs to CRA'!$F$31+'[2]Outputs to CRA'!$G$31+'[2]Outputs to CRA'!$H$31 -> 23335.638
A26: =A25+1 -> 17 | B26: PACKAGE SERVICES
A27: =A26+1 -> 18 | B27: BOUND PRINTED MATTER FLATS | C27: ='[2]6.0.2.1'!F32 -> 8053.5989 | D27: =C27/C$31*D$31 -> 1104.4209 | E27: ='[2]Outputs to CRA'!E33 -> 348.67338 | F27: ='[2]Outputs to CRA'!F33+'[2]Outputs to CRA'!G33+'[2]Outputs to CRA'!H33 -> 1466.7021
A28: =A27+1 -> 19 | B28: BOUND PRINTED MATTER PARCELS | C28: ='[2]6.0.2.1'!F33 -> 24420.664 | D28: =C28/C$31*D$31 -> 3348.8993 | E28: ='[2]Outputs to CRA'!E34 -> 2465.1661 | F28: ='[2]Outputs to CRA'!F34+'[2]Outputs to CRA'!G34+'[2]Outputs to CRA'!H34 -> 53953.591
A29: =A28+1 -> 20 | B29: MEDIA MAIL | C29: ='[2]6.0.2.1'!F34 -> 8300.1564 | D29: =C29/C$31*D$31 -> 1138.2323 | E29: ='[2]Outputs to CRA'!E35 -> 890.71788 | F29: ='[2]Outputs to CRA'!F35+'[2]Outputs to CRA'!G35+'[2]Outputs to CRA'!H35 -> 21421.829
A30: =A29+1 -> 21 | B30: TOTAL VOLUME VARIABLE | C30: ='[2]6.0.2.1'!$D$62 -> 2735847.1 | D30: =C30/C$31*D$31 -> 375177.21 | E30: ='[2]Outputs to CRA'!$E$62 -> 208118.93 | F30: ='[2]Outputs to CRA'!F62+'[2]Outputs to CRA'!G64+'[2]Outputs to CRA'!H62 -> 3698548.7
A31: =A30+1 -> 22 | B31: TOTAL | C31: ='[2]6.0.2.1'!$F$64 -> 2835480 | D31: ='[2]Outputs to CRA'!Q8 -> 388840.26 | E31: ='[2]Outputs to CRA'!$E$64 -> 592626.64 | F31: ='[2]Outputs to CRA'!$F$64+'[2]Outputs to CRA'!$G$64+'[2]Outputs to CRA'!$H$64 -> 15467431
A32: =A31+1 -> 23 | B32: USPS MARKETING MAIL
A33: =A32+1 -> 24 | B33: HIGH DENSITY & SATURATION LETTERS | C33: =C18 -> 55182.385 | D33: =D18 -> 7567.3723 | E33: =E18 -> 5205.1514 | F33: =F18 -> 94839.18
A34: =A33+1 -> 25 | B34: HD Letters | C34: =CARMM!D18 -> 33827.056 | D34: =IFERROR(C34/C$31*D$31,0) -> 4638.834 | E34: ='7.0.6'!M34 -> 2957.5134 | F34: ='7.0.6'!L34 -> 51124.897
A35: =A34+1 -> 26 | B35: Sat Letters | C35: =CARMM!D19 -> 21372.307 | D35: =IFERROR(C35/C$31*D$31,0) -> 2930.8665 | E35: ='7.0.6'!M35 -> 2247.638 | F35: ='7.0.6'!L35 -> 43714.284
A36: =A35+1 -> 27 | B36: HIGH DENSITY & SATURATION FLATS & PARCELS | C36: =C19 -> 70465.38 | D36: =D19 -> 9663.1881 | E36: =E19 -> 9031.315 | F36: =F19 -> 192903.99
A37: =A36+1 -> 28 | B37: HD Flats | C37: =CARMM!D23 -> 45414.554 | D37: =IFERROR(C37/C$31*D$31,0) -> 6227.8721 | E37: ='7.0.6'!M37 -> 2305.9052 | F37: ='7.0.6'!L37 -> 18506.279
A38: =A37+1 -> 29 | B38: Sat Flats | C38: =CARMM!D25 -> 25061.774 | D38: =IFERROR(C38/C$31*D$31,0) -> 3436.8173 | E38: ='7.0.6'!M38 -> 6725.4097 | F38: ='7.0.6'!L38 -> 174397.71
A39: =A38+1 -> 30 | B39: HD Parcels | C39: =CARMM!D24 -> 0 | D39: =IFERROR(C39/C$31*D$31,0) -> 0 | E39: ='7.0.6'!M39 -> 0 | F39: ='7.0.6'!L39 -> 0
A40: =A39+1 -> 31 | B40: Sat Parcels | C40: =CARMM!D29 -> 0 | D40: =IFERROR(C40/C$31*D$31,0) -> 0 | E40: ='7.0.6'!M40 -> 0 | F40: ='7.0.6'!L40 -> 0

Sheet 7.0.8
A1: =Inputs!C4 -> Unit Delivery Cost Model - 12/16/2025
A2: CS 7 CITY CARRIERS STREET
A3: WS 7.0.8 DEVELOP DIST KEYS W/ CCS VOL
A5: LINE NO. | B5: CLASS TITLE | C5: RPW TOTAL | D5: COLLECTIONS | E5: CASED MAIL | F5: CASED MAIL LETTERS | G5: CASED MAIL FLATS | H5: DPS | I5: SMALL PARCELS | J5: SEQUENCED | K5: ACCOUNTABLES | L5: LARGE PARCELS
B6: COLUMN NUMBER | C6: -1 | D6: =C6-1 -> -2 | E6: =D6-1 -> -3 | F6: =E6-1 -> -4 | G6: =F6-1 -> -5 | H6: =G6-1 -> -6 | I6: =H6-1 -> -7 | J6: =I6-1 -> -8 | K6: =J6-1 -> -9 | L6: =K6-1 -> -10
B7: CALCULATIONS
B8: UNITS | C8: Pieces (000) | D8: Pieces (000) | E8: Pieces (000) | F8: Pieces (000) | G8: Pieces (000) | H8: Pieces (000) | I8: Pieces (000) | J8: Pieces (000) | K8: Pieces (000) | L8: Pieces (000)
B9: COLUMN SOURCE/NOTES | C9: WS 1.1.2 | D9: CCS | E9: CCS | F9: CCS | G9: CCS | H9: CCS | I9: CCS | J9: CCS | K9: CCS | L9: CCS
A10: 1 | B10: FIRST-CLASS MAIL
A11: =A10+1 -> 2 | B11: SINGLE-PIECE LETTERS | C11: ='[2]7.0.8'!D11 -> 9372495.3 | D11: ='[2]7.0.8'!E11 -> 1843932.9 | E11: ='[2]7.0.8'!F11 -> 562209.02 | F11: =[3]CCCS_Matrix_FY25!E3 -> 562209.02 | G11: =[3]CCCS_Matrix_FY25!F3 -> 0 | H11: ='[2]7.0.8'!G11 -> 3966989.2 | I11: ='[2]7.0.8'!H11 -> 229.54725 | J11: ='[2]7.0.8'!I11 -> 0 | K11: ='[2]7.0.8'!K11 -> 2577.0309 | L11: ='[2]7.0.8'!L11 -> 0
A12: =A11+1 -> 3 | B12: SINGLE-PIECE CARDS | C12: ='[2]7.0.8'!D12 -> 326604.93 | D12: ='[2]7.0.8'!E12 -> 64255.842 | E12: ='[2]7.0.8'!F12 -> 34284.935 | F12: =[3]CCCS_Matrix_FY25!E9 -> 34284.935 | G12: =[3]CCCS_Matrix_FY25!F9 -> 0 | H12: ='[2]7.0.8'!G12 -> 137332.12 | I12: ='[2]7.0.8'!H12 -> 5.4856643 | J12: ='[2]7.0.8'!I12 -> 0 | K12: ='[2]7.0.8'!K12 -> 97.491877 | L12: ='[2]7.0.8'!L12 -> 0
A13: =A12+1 -> 4 | B13: PRESORT LETTERS | C13: ='[2]7.0.8'!D13 -> 29129460 | D13: ='[2]7.0.8'!E13 -> 0 | E13: ='[2]7.0.8'!F13 -> 1113191.2 | F13: =[3]CCCS_Matrix_FY25!E6 -> 1113191.2 | G13: =[3]CCCS_Matrix_FY25!F6 -> 0 | H13: ='[2]7.0.8'!G13 -> 15643945 | I13: ='[2]7.0.8'!H13 -> 0 | J13: ='[2]7.0.8'!I13 -> 0 | K13: ='[2]7.0.8'!K13 -> 0 | L13: ='[2]7.0.8'!L13 -> 0
A14: =A13+1 -> 5 | B14: PRESORT CARDS | C14: ='[2]7.0.8'!D14 -> 2340299.4 | D14: ='[2]7.0.8'!E14 -> 0 | E14: ='[2]7.0.8'!F14 -> 103307.35 | F14: =[3]CCCS_Matrix_FY25!E10 -> 103307.35 | G14: =[3]CCCS_Matrix_FY25!F10 -> 0 | H14: ='[2]7.0.8'!G14 -> 1245279.5 | I14: ='[2]7.0.8'!H14 -> 16.595866 | J14: ='[2]7.0.8'!I14 -> 0 | K14: ='[2]7.0.8'!K14 -> 0 | L14: ='[2]7.0.8'!L14 -> 0
A15: =A14+1 -> 6 | B15: SINGLE PIECE FLATS | C15: ='[2]7.0.8'!D15 -> 407262.06 | D15: ='[2]7.0.8'!E15 -> 80124.224 | E15: ='[2]7.0.8'!F15 -> 236517.94 | F15: =[3]CCCS_Matrix_FY25!E4 -> 0 | G15: =[3]CCCS_Matrix_FY25!F4 -> 236517.94 | H15: ='[2]7.0.8'!G15 -> 0 | I15: ='[2]7.0.8'!H15 -> 33.033469 | J15: ='[2]7.0.8'!I15 -> 0 | K15: ='[2]7.0.8'!K15 -> 134.37511 | L15: ='[2]7.0.8'!L15 -> 0
A16: =A15+1 -> 7 | B16: PRESORT FLATS | C16: ='[2]7.0.8'!D16 -> 432797.83 | D16: ='[2]7.0.8'!E16 -> 0 | E16: ='[2]7.0.8'!F16 -> 286041.99 | F16: =[3]CCCS_Matrix_FY25!$E$7 -> 0 | G16: =[3]CCCS_Matrix_FY25!$F$7 -> 286041.99 | H16: ='[2]7.0.8'!G16 -> 0 | I16: ='[2]7.0.8'!H16 -> 0 | J16: ='[2]7.0.8'!I16 -> 0 | K16: ='[2]7.0.8'!K16 -> 0 | L16: ='[2]7.0.8'!L16 -> 0
A17: =A16+1 -> 8 | B17: USPS MARKETING MAIL
A18: =A17+1 -> 9 | B18: HIGH DENSITY & SATURATION LETTERS | C18: ='[2]7.0.8'!D19 -> 6017413.6 | D18: ='[2]7.0.8'!E19 -> 0 | E18: ='[2]7.0.8'!F19 -> 768413.85 | F18: =[3]CCCS_Matrix_FY25!E26+[3]CCCS_Matrix_FY25!E30-J18 -> 768413.85 | G18: =[3]CCCS_Matrix_FY25!F26+[3]CCCS_Matrix_FY25!F30 -> 0 | H18: ='[2]7.0.8'!G19 -> 2817705 | I18: ='[2]7.0.8'!H19 -> 0 | J18: ='[2]7.0.8'!I19 -> 202943.25 | K18: ='[2]7.0.8'!K19 -> 0 | L18: ='[2]7.0.8'!L19 -> 0
A19: =A18+1 -> 10 | B19: HIGH DENSITY & SATURATION FLATS & PARCELS | C19: ='[2]7.0.8'!D20 -> 7868876.8 | D19: ='[2]7.0.8'!E20 -> 0 | E19: ='[2]7.0.8'!F20 -> 2046717 | F19: =[3]CCCS_Matrix_FY25!E27+[3]CCCS_Matrix_FY25!E28+[3]CCCS_Matrix_FY25!E31+[3]CCCS_Matrix_FY25!E32 -> 0 | G19: =[3]CCCS_Matrix_FY25!F27+[3]CCCS_Matrix_FY25!F28+[3]CCCS_Matrix_FY25!F29+[3]CCCS_Matrix_FY25!F31+[3]CCCS_Matrix_FY25!$F$32+[3]CCCS_Matrix_FY25!$E$29-J19 -> 2046717 | H19: ='[2]7.0.8'!G20 -> 0 | I19: ='[2]7.0.8'!H20 -> 0 | J19: ='[2]7.0.8'!I20 -> 3085341.8 | K19: ='[2]7.0.8'!K20 -> 0 | L19: ='[2]7.0.8'!L20 -> 0
A20: =A19+1 -> 11 | B20: EVERY DOOR DIRECT MAIL RETAIL | C20: ='[2]7.0.8'!D21 -> 559191.61 | D20: ='[2]7.0.8'!E21 -> 0 | E20: ='[2]7.0.8'!F21 -> 0 | H20: ='[2]7.0.8'!G21 -> 0 | I20: ='[2]7.0.8'!H21 -> 0 | J20: ='[2]7.0.8'!I21 -> 0 | K20: ='[2]7.0.8'!K21 -> 0 | L20: ='[2]7.0.8'!L21 -> 0
A21: =A20+1 -> 12 | B21: CARRIER ROUTE | C21: ='[2]7.0.8'!D22 -> 2745353.6 | D21: ='[2]7.0.8'!E22 -> 0 | E21: ='[2]7.0.8'!F22 -> 1685118.5 | F21: =SUM([3]CCCS_Matrix_FY25!E22:E24) -> 7634.0384 | G21: =SUM([3]CCCS_Matrix_FY25!F22:F24) -> 1677484.4 | H21: ='[2]7.0.8'!G22 -> 7677.7877 | I21: ='[2]7.0.8'!H22 -> 133.03005 | J21: ='[2]7.0.8'!I22 -> 0 | K21: ='[2]7.0.8'!K22 -> 0 | L21: ='[2]7.0.8'!L22 -> 0
A22: =A21+1 -> 13 | B22: LETTERS | C22: ='[2]7.0.8'!D23 -> 37911961 | D22: ='[2]7.0.8'!E23 -> 209499.51 | E22: ='[2]7.0.8'!F23 -> 1769970 | F22: =[3]CCCS_Matrix_FY25!E17 -> 1769970 | G22: =[3]CCCS_Matrix_FY25!F17 -> 0 | H22: ='[2]7.0.8'!G23 -> 19974964 | I22: ='[2]7.0.8'!H23 -> 257.65505 | J22: ='[2]7.0.8'!I23 -> 0 | K22: ='[2]7.0.8'!K23 -> 0 | L22: ='[2]7.0.8'!L23 -> 0
A23: =A22+1 -> 14 | B23: FLATS | C23: ='[2]7.0.8'!D24 -> 1668400.6 | D23: ='[2]7.0.8'!E24 -> 9219.494 | E23: ='[2]7.0.8'!F24 -> 1075918.7 | F23: =[3]CCCS_Matrix_FY25!E18 -> 0 | G23: =[3]CCCS_Matrix_FY25!F18 -> 1075918.7 | H23: ='[2]7.0.8'!G24 -> 0 | I23: ='[2]7.0.8'!H24 -> 55.43277 | J23: ='[2]7.0.8'!I24 -> 0 | K23: ='[2]7.0.8'!K24 -> 0 | L23: ='[2]7.0.8'!L24 -> 0
A24: =A23+1 -> 15 | B24: PARCELS | C24: ='[2]7.0.8'!D25 -> 11706.037 | D24: ='[2]7.0.8'!E25 -> 2568 | E24: ='[2]7.0.8'!F25 -> 0 | F24: =[3]CCCS_Matrix_FY25!E19 -> 0 | G24: =[3]CCCS_Matrix_FY25!F19 -> 0 | H24: ='[2]7.0.8'!G25 -> 0 | I24: ='[2]7.0.8'!H25 -> 3983.7749 | J24: ='[2]7.0.8'!I25 -> 0 | K24: ='[2]7.0.8'!K25 -> 0 | L24: ='[2]7.0.8'!L25 -> 847.68225
A25: =A24+1 -> 16 | B25: TOTAL PERIODICALS | C25: ='[2]7.0.8'!D30 -> 2442702 | D25: ='[2]7.0.8'!E30 -> 5938 | E25: ='[2]7.0.8'!F30 -> 1236646.9 | F25: =[3]CCCS_Matrix_FY25!E15 -> 2468.5903 | G25: =[3]CCCS_Matrix_FY25!F15 -> 1234178.3 | H25: ='[2]7.0.8'!G30 -> 3222.7953 | I25: ='[2]7.0.8'!H30 -> 1123.6544 | J25: ='[2]7.0.8'!I30 -> 0 | K25: ='[2]7.0.8'!K30 -> 0 | L25: ='[2]7.0.8'!$L$30 -> 82.017669
A26: =A25+1 -> 17 | B26: PACKAGE SERVICES
A27: =A26+1 -> 18 | B27: BOUND PRINTED MATTER FLATS | C27: ='[2]7.0.8'!D32 -> 104285.95 | D27: ='[2]7.0.8'!E32 -> 2772 | E27: ='[2]7.0.8'!F32 -> 62408.081 | F27: =[3]CCCS_Matrix_FY25!E43 -> 16.580178 | G27: =[3]CCCS_Matrix_FY25!F43 -> 62391.501 | H27: ='[2]7.0.8'!G32 -> 0 | I27: ='[2]7.0.8'!H32 -> 516.01717 | J27: ='[2]7.0.8'!I32 -> 0 | K27: ='[2]7.0.8'!K32 -> 35.744654 | L27: ='[2]7.0.8'!L32 -> 0
A28: =A27+1 -> 19 | B28: BOUND PRINTED MATTER PARCELS | C28: ='[2]7.0.8'!D33 -> 225885.53 | D28: ='[2]7.0.8'!E33 -> 1553 | E28: ='[2]7.0.8'!F33 -> 0 | F28: =[3]CCCS_Matrix_FY25!E44 -> 0 | G28: =[3]CCCS_Matrix_FY25!F44 -> 0 | H28: ='[2]7.0.8'!G33 -> 0 | I28: ='[2]7.0.8'!H33 -> 83223.558 | J28: ='[2]7.0.8'!I33 -> 0 | K28: ='[2]7.0.8'!K33 -> 47.275962 | L28: ='[2]7.0.8'!L33 -> 39823.766
A29: =A28+1 -> 20 | B29: MEDIA AND LIBRARY MAIL | C29: ='[2]7.0.8'!D34 -> 69096.131 | D29: ='[2]7.0.8'!E34 -> 3868 | E29: ='[2]7.0.8'!F34 -> 734.76084 | F29: =[3]CCCS_Matrix_FY25!E45 -> 62.414398 | G29: =[3]CCCS_Matrix_FY25!F45 -> 672.34645 | H29: ='[2]7.0.8'!G34 -> 0 | I29: ='[2]7.0.8'!H34 -> 16901.441 | J29: ='[2]7.0.8'!I34 -> 0 | K29: ='[2]7.0.8'!K34 -> 0 | L29: ='[2]7.0.8'!L34 -> 19277.314
A30: =A29+1 -> 21 | B30: FREE + USPS MAIL | C30: ='[2]7.0.8'!D36+'[2]7.0.8'!D37 -> 376368.17 | D30: ='[2]7.0.8'!E36+'[2]7.0.8'!E37 -> 0 | E30: ='[2]7.0.8'!F36+'[2]7.0.8'!F37 -> 51974.774 | F30: =SUM([3]CCCS_Matrix_FY25!E49:E50) -> 40310.166 | G30: =SUM([3]CCCS_Matrix_FY25!F49:F50) -> 11664.608 | H30: ='[2]7.0.8'!G36+'[2]7.0.8'!G37 -> 173980.44 | I30: ='[2]7.0.8'!H36+'[2]7.0.8'!H37 -> 10791.101 | J30: ='[2]7.0.8'!I36+'[2]7.0.8'!I37 -> 0 | K30: ='[2]7.0.8'!K36+'[2]7.0.8'!K37 -> 0 | L30: ='[2]7.0.8'!L36+'[2]7.0.8'!L37 -> 2824.7213
A31: =A30+1 -> 22 | B31: TOTAL VOLUME | C31: ='[2]7.0.8'!D62 -> 1.088848e+08 | D31: ='[2]7.0.8'!E62 -> 2638286 | E31: ='[2]7.0.8'!F62 -> 11059370 | F31: =E31*SUM(F11:F30)/SUM(F11:G30) -> 4412206.9 | G31: =E31*SUM(G11:G30)/SUM(F11:G30) -> 6647162.7 | H31: ='[2]7.0.8'!G62 -> 43997885 | I31: ='[2]7.0.8'!H62 -> 1902016.6 | J31: ='[2]7.0.8'!I62 -> 3288285 | K31: ='[2]7.0.8'!K62 -> 128718.77 | L31: ='[2]7.0.8'!L62 -> 1412797
A33: =A31+1 -> 23 | B33: USPS MARKETING MAIL
A34: =A33+1 -> 24 | B34: HIGH DENSITY & SATURATION LETTERS | C34: =C18 -> 6017413.6 | E34: =E18 -> 768413.85 | F34: =F18 -> 768413.85 | G34: =G18 -> 0 | H34: =H18 -> 2817705 | J34: =J18 -> 202943.25
A35: =A34+1 -> 25 | B35: HD Letters | C35: =RPWShape!C18 -> 3430799.2 | E35: =[3]CCCS_Matrix_FY25!E26*'[4]I-CS07 DALs'!E19 -> 378613.7 | F35: =E35 -> 378613.7 | H35: =[3]CCCS_Matrix_FY25!D26 -> 1643112.6 | J35: =[3]CCCS_Matrix_FY25!E26*(1-'[4]I-CS07 DALs'!E19) -> 35086.244
A36: =A35+1 -> 26 | B36: Sat Letters | C36: =RPWShape!C19 -> 2586614.3 | E36: =[3]CCCS_Matrix_FY25!E30*'[4]I-CS07 DALs'!D19 -> 389800.16 | F36: =F34-F35 -> 389800.16 | H36: =H34-H35 -> 1174592.4 | J36: =J34-J35 -> 167857.01
A37: =A36+1 -> 27 | B37: HIGH DENSITY & SATURATION FLATS & PARCELS | C37: =C19 -> 7868876.8 | E37: =E19 -> 2046717 | F37: =F19 -> 0 | G37: =G19 -> 2046717 | I37: =I19 -> 0 | J37: =J19 -> 3085341.8 | L37: =L19 -> 0
A38: =A37+1 -> 28 | B38: HD Flats | C38: =RPWShape!D21 -> 1307868.7 | E38: =[3]CCCS_Matrix_FY25!F27*'[4]I-CS07 DALs'!E20 -> 819032.93 | G38: =E38 -> 819032.93 | I38: =[3]CCCS_Matrix_FY25!H27+[3]CCCS_Matrix_FY25!$I$27 -> 0 | J38: =[3]CCCS_Matrix_FY25!F27*(1-'[4]I-CS07 DALs'!E20) -> 90981.705
A39: =A38+1 -> 29 | B39: Sat Flats | C39: =RPWShape!D22 -> 6561008.2 | E39: =([3]CCCS_Matrix_FY25!F29+[3]CCCS_Matrix_FY25!F31+[3]CCCS_Matrix_FY25!E29)*'[4]I-CS07 DALs'!D20 -> 1227684.1 | G39: =E39 -> 1227684.1 | I39: =[3]CCCS_Matrix_FY25!$H$31+[3]CCCS_Matrix_FY25!$I$31 -> 0 | J39: =([3]CCCS_Matrix_FY25!F29+[3]CCCS_Matrix_FY25!F31+[3]CCCS_Matrix_FY25!E29)*(1-'[4]I-CS07 DALs'!$D$20) -> 2994360.1
A40: =A39+1 -> 30 | B40: HD Parcels | C40: =RPWShape!E21 -> 0 | I40: =[3]CCCS_Matrix_FY25!H28+[3]CCCS_Matrix_FY25!I28 -> 0 | L40: =[3]CCCS_Matrix_FY25!J29 -> 0
A41: =A40+1 -> 31 | B41: Sat Parcels | C41: =RPWShape!E22 -> 0 | I41: =[3]CCCS_Matrix_FY25!$H$32+[3]CCCS_Matrix_FY25!$I$32 -> 0 | L41: =L37 -> 0
B42: HD & SAT Flats and PRCLS TOTAL | C42: =SUM(C38:C41) -> 7868876.8 | E42: =SUM(E38:E41) -> 2046717 | G42: =SUM(G38:G41) -> 2046717 | H42: =SUM(H38:H41) -> 0 | I42: =SUM(I38:I41) -> 0 | J42: =SUM(J38:J41) -> 3085341.8
...

Sheet 7.0.6
A1: =Inputs!C4 -> Unit Delivery Cost Model - 12/16/2025
A2: CS 7 CITY CARRIERS STREET
A3: WS 7.0.6 DISTRIB. AND SUMMARY OF SPR
B4: AND LTR COST POOLS
A5: LINE NO. | B5: CLASS, SUBCLASS, OR SPECIAL SERVICE | C5: SPR COLLECTION | D5: SPR MON - SAT DELIVERY NON-PEAK | E5: SPR MON - SAT DELIVERY PEAK | F5: SPR SUNDAY/ HOLIDAY DELIVERY | G5: SPR PME COLLECTION | H5: LTR - DELIVERY ACTIVITIES | I5: LTR IN-OFFICE SUPPORT TO OFFICE | J5: LTR IN-OFFICE SUPPORT TO DELIVERY ACTIVITIES | K5: PRODUCT SPECIFIC DELIVERY ACTIVITIES | L5: TOTAL DELIVERY ACTIVITIES | M5: TOTAL IN-OFFICE ROUTE SUPPORT
B6: COLUMN NUMBER | C6: -1 | D6: =C6-1 -> -2 | E6: =D6-1 -> -3 | F6: =E6-1 -> -4 | G6: =F6-1 -> -5 | H6: =G6-1 -> -6 | I6: =H6-1 -> -7 | J6: =I6-1 -> -8 | K6: =J6-1 -> -9 | ... M6: =L6-1 -> -11
B7: UNITS | C7: $(000) | D7: $(000) | E7: $(000) | F7: $(000) | G7: $(000) | H7: $(000) | I7: $(000) | J7: $(000) | K7: $(000) | L7: $(000) | M7: $(000)
B8: COLUMN SOURCE/NOTES
A9: 1 | B9: FIRST-CLASS MAIL
A10: =A9+1 -> 2 | B10: SINGLE-PIECE LETTERS | C10: ='[2]7.0.6'!D12 -> 39848.01 | D10: ='[2]7.0.6'!E12 -> 345.00996 | E10: ='[2]7.0.6'!F12 -> 48.779805 | F10: ='[2]7.0.6'!G12 -> 287.80835 | G10: ='[2]7.0.6'!H12 -> 0 | H10: ='[2]7.0.6'!I12 -> 240443.05 | I10: ='[2]7.0.6'!J12 -> 6210.1993 | J10: ='[2]7.0.6'!K12 -> 7985.5832 | ... M10: ='[2]7.0.6'!N12 -> 14195.783
A11: =A10+1 -> 3 | B11: SINGLE-PIECE CARDS | C11: ='[2]7.0.6'!D13 -> 1388.5903 | D11: ='[2]7.0.6'!E13 -> 0 | E11: ='[2]7.0.6'!F13 -> 0 | F11: ='[2]7.0.6'!G13 -> 0 | G11: ='[2]7.0.6'!H13 -> 0 | H11: ='[2]7.0.6'!I13 -> 8627.0398 | I11: ='[2]7.0.6'!J13 -> 348.69381 | J11: ='[2]7.0.6'!K13 -> 286.52084 | ... M11: ='[2]7.0.6'!N13 -> 635.21465
A12: =A11+1 -> 4 | B12: PRESORT LETTERS | C12: ='[2]7.0.6'!D14 -> 0 | D12: ='[2]7.0.6'!E14 -> 0 | E12: ='[2]7.0.6'!F14 -> 0 | F12: ='[2]7.0.6'!G14 -> 0 | G12: ='[2]7.0.6'!H14 -> 0 | H12: ='[2]7.0.6'!I14 -> 423776.48 | I12: ='[2]7.0.6'!J14 -> 13476.626 | J12: ='[2]7.0.6'!K14 -> 14074.445 | ... M12: ='[2]7.0.6'!N14 -> 27551.071
A13: =A12+1 -> 5 | B13: PRESORT CARDS | C13: ='[2]7.0.6'!D15 -> 0 | D13: ='[2]7.0.6'!E15 -> 0 | E13: ='[2]7.0.6'!F15 -> 0 | F13: ='[2]7.0.6'!G15 -> 0 | G13: ='[2]7.0.6'!H15 -> 0 | H13: ='[2]7.0.6'!I15 -> 34003.954 | I13: ='[2]7.0.6'!J15 -> 1002.7247 | J13: ='[2]7.0.6'!K15 -> 1129.3377 | ... M13: ='[2]7.0.6'!N15 -> 2132.0624
A14: =A13+1 -> 6 | B14: SINGLE PIECE FLATS | C14: ='[2]7.0.6'!D16 -> 1731.5114 | D14: ='[2]7.0.6'!E16 -> 3.5551159 | E14: ='[2]7.0.6'!F16 -> 0.38937634 | F14: ='[2]7.0.6'!G16 -> 48.854963 | G14: ='[2]7.0.6'!H16 -> 0 | H14: ='[2]7.0.6'!I16 -> 9874.6731 | I14: ='[2]7.0.6'!J16 -> 2374.8271 | J14: ='[2]7.0.6'!K16 -> 327.95718 | ... M14: ='[2]7.0.6'!N16 -> 2702.7843
A15: =A14+1 -> 7 | B15: PRESORT FLATS | C15: ='[2]7.0.6'!D17 -> 0 | D15: ='[2]7.0.6'!E17 -> 0 | E15: ='[2]7.0.6'!F17 -> 0 | F15: ='[2]7.0.6'!G17 -> 0 | G15: ='[2]7.0.6'!H17 -> 0 | H15: ='[2]7.0.6'!I17 -> 5195.9811 | I15: ='[2]7.0.6'!J17 -> 2480.9327 | J15: ='[2]7.0.6'!K17 -> 172.56868 | ... M15: ='[2]7.0.6'!N17 -> 2653.5014
A16: =A15+1 -> 8 | B16: USPS MARKETING MAIL
A17: =A16+1 -> 9 | B17: HIGH DENSITY & SATURATION LETTERS | C17: ='[2]7.0.6'!D20 -> 0 | D17: ='[2]7.0.6'!E20 -> 0 | E17: ='[2]7.0.6'!F20 -> 0 | F17: ='[2]7.0.6'!G20 -> 0 | G17: ='[2]7.0.6'!H20 -> 0 | H17: ='[2]7.0.6'!I20 -> 94839.18 | I17: ='[2]7.0.6'!J20 -> 2055.357 | J17: ='[2]7.0.6'!K20 -> 3149.7944 | ... M17: ='[2]7.0.6'!N20 -> 5205.1514
A18: =A17+1 -> 10 | B18: HIGH DENSITY & SATURATION FLATS & PARCELS | C18: ='[2]7.0.6'!D21 -> 0 | D18: ='[2]7.0.6'!E21 -> 0 | E18: ='[2]7.0.6'!F21 -> 0 | F18: ='[2]7.0.6'!G21 -> 0 | G18: ='[2]7.0.6'!H21 -> 0 | H18: ='[2]7.0.6'!I21 -> 192903.99 | I18: ='[2]7.0.6'!J21 -> 2624.5968 | J18: ='[2]7.0.6'!K21 -> 6406.7181 | ... M18: ='[2]7.0.6'!N21 -> 9031.315
A19: =A18+1 -> 11 | B19: EVERY DOOR DIRECT MAIL RETAIL | C19: ='[2]7.0.6'!D22 -> 0 | D19: ='[2]7.0.6'!E22 -> 0 | E19: ='[2]7.0.6'!F22 -> 0 | F19: ='[2]7.0.6'!G22 -> 0 | G19: ='[2]7.0.6'!H22 -> 0 | H19: ='[2]7.0.6'!I22 -> 13512.623 | I19: ='[2]7.0.6'!J22 -> 186.5136 | J19: ='[2]7.0.6'!K22 -> 448.7806 | ... M19: ='[2]7.0.6'!N22 -> 635.2942
A20: =A19+1 -> 12 | B20: CARRIER ROUTE | C20: ='[2]7.0.6'!D23 -> 0 | D20: ='[2]7.0.6'!E23 -> 0 | E20: ='[2]7.0.6'!F23 -> 0 | F20: ='[2]7.0.6'!G23 -> 0 | G20: ='[2]7.0.6'!H23 -> 0 | H20: ='[2]7.0.6'!I23 -> 30838.966 | I20: ='[2]7.0.6'!J23 -> 7196.4146 | J20: ='[2]7.0.6'!K23 -> 1024.2223 | ... M20: ='[2]7.0.6'!N23 -> 8220.6369
A21: =A20+1 -> 13 | B21: LETTERS | C21: ='[2]7.0.6'!D24 -> 457.94013 | D21: ='[2]7.0.6'!E24 -> 0 | E21: ='[2]7.0.6'!F24 -> 0 | F21: ='[2]7.0.6'!G24 -> 0 | G21: ='[2]7.0.6'!H24 -> 0 | H21: ='[2]7.0.6'!I24 -> 561812.58 | I21: ='[2]7.0.6'!J24 -> 17749.969 | J21: ='[2]7.0.6'!K24 -> 18658.893 | ... M21: ='[2]7.0.6'!N24 -> 36408.862
A22: =A21+1 -> 14 | B22: FLATS | C22: ='[2]7.0.6'!D25 -> 20.152679 | D22: ='[2]7.0.6'!E25 -> 0 | E22: ='[2]7.0.6'!F25 -> 0 | F22: ='[2]7.0.6'!G25 -> 0 | G22: ='[2]7.0.6'!H25 -> 0 | H22: ='[2]7.0.6'!I25 -> 20187.192 | I22: ='[2]7.0.6'!J25 -> 8389.017 | J22: ='[2]7.0.6'!K25 -> 670.45609 | ... M22: ='[2]7.0.6'!N25 -> 9059.4731
A23: =A22+1 -> 15 | B23: PARCELS | C23: ='[2]7.0.6'!D26 -> 34.132377 | D23: ='[2]7.0.6'!E26 -> 123.45319 | E23: ='[2]7.0.6'!F26 -> 41.61928 | F23: ='[2]7.0.6'!G26 -> 26.076503 | G23: ='[2]7.0.6'!H26 -> 0 | H23: ='[2]7.0.6'!I26 -> 1677.8549 | I23: ='[2]7.0.6'!J26 -> 55.233747 | J23: ='[2]7.0.6'!K26 -> 55.724838 | ... M23: ='[2]7.0.6'!N26 -> 110.95859
A24: =A23+1 -> 16 | B24: TOTAL PERIODICALS | C24: ='[2]7.0.6'!D31 -> 67.785704 | D24: ='[2]7.0.6'!E31 -> 0 | E24: ='[2]7.0.6'!F31 -> 0 | F24: ='[2]7.0.6'!G31 -> 0 | G24: ='[2]7.0.6'!H31 -> 0 | H24: ='[2]7.0.6'!I31 -> 23267.853 | I24: ='[2]7.0.6'!J31 -> 7287.5253 | J24: ='[2]7.0.6'!K31 -> 772.77083 | ... M24: ='[2]7.0.6'!N31 -> 8060.2961
A25: =A24+1 -> 17 | B25: PACKAGE SERVICES
A26: =A25+1 -> 18 | B26: BOUND PRINTED MATTER FLATS | C26: ='[2]7.0.6'!D33 -> 0.23952545 | D26: ='[2]7.0.6'!E33 -> 0 | E26: ='[2]7.0.6'!F33 -> 0 | F26: ='[2]7.0.6'!G33 -> 0 | G26: ='[2]7.0.6'!H33 -> 0 | H26: ='[2]7.0.6'!I33 -> 1466.4626 | I26: ='[2]7.0.6'!J33 -> 299.96929 | J26: ='[2]7.0.6'!K33 -> 48.704086 | ... M26: ='[2]7.0.6'!N33 -> 348.67338
A27: =A26+1 -> 19 | B27: BOUND PRINTED MATTER PARCELS | C27: ='[2]7.0.6'!D34 -> 48.384142 | D27: ='[2]7.0.6'!E34 -> 5167.8723 | E27: ='[2]7.0.6'!F34 -> 1407.2798 | F27: ='[2]7.0.6'!G34 -> 492.1256 | G27: ='[2]7.0.6'!H34 -> 0 | H27: ='[2]7.0.6'!I34 -> 46837.929 | I27: ='[2]7.0.6'!J34 -> 909.58704 | J27: ='[2]7.0.6'!K34 -> 1555.5791 | ... M27: ='[2]7.0.6'!N34 -> 2465.1661
A28: =A27+1 -> 20 | B28: MEDIA MAIL | C28: ='[2]7.0.6'!D35 -> 47.306277 | D28: ='[2]7.0.6'!E35 -> 2853.547 | E28: ='[2]7.0.6'!F35 -> 672.98092 | F28: ='[2]7.0.6'!G35 -> 337.27663 | G28: ='[2]7.0.6'!H35 -> 0 | H28: ='[2]7.0.6'!I35 -> 17510.718 | I28: ='[2]7.0.6'!J35 -> 309.15272 | J28: ='[2]7.0.6'!K35 -> 581.56516 | ... M28: ='[2]7.0.6'!N35 -> 890.71788
A29: =A28+1 -> 21 | B29: TOTAL VOLUME VARIABLE & PRODUCT SPECIFIC | C29: ='[2]7.0.6'!D63 -> 45853.915 | D29: ='[2]7.0.6'!E63 -> 204029.98 | E29: ='[2]7.0.6'!F63 -> 65758.131 | F29: ='[2]7.0.6'!G63 -> 183445.85 | G29: ='[2]7.0.6'!H63 -> 1278.3068 | H29: ='[2]7.0.6'!I63 -> 3198182.5 | I29: ='[2]7.0.6'!J63 -> 101901.04 | J29: ='[2]7.0.6'!K63 -> 106217.89 | ... M29: ='[2]7.0.6'!N63 -> 208118.93
A30: =A29+1 -> 22 | B30: TOTAL | C30: ='[2]7.0.6'!D65 -> 189478.99 | D30: ='[2]7.0.6'!E65 -> 331925.41 | E30: ='[2]7.0.6'!F65 -> 81102.776 | F30: ='[2]7.0.6'!G65 -> 199810.31 | G30: ='[2]7.0.6'!H65 -> 1278.3068 | H30: ='[2]7.0.6'!I65 -> 14663835 | I30: ='[2]7.0.6'!J65 -> 105612.03 | J30: ='[2]7.0.6'!K65 -> 487014.62 | ... M30: ='[2]7.0.6'!N65 -> 592626.64
A32: =A30+1 -> 23 | B32: USPS MARKETING MAIL
A33: =A32+1 -> 24 | B33: HIGH DENSITY & SATURATION LETTERS | C33: =C17 -> 0 | D33: =D17 -> 0 | E33: =E17 -> 0 | F33: =F17 -> 0 | G33: =G17 -> 0 | H33: =H17 -> 94839.18 | I33: =I17 -> 2055.357 | J33: =J17 -> 3149.7944 | ... M33: =M17 -> 5205.1514
A34: =A33+1 -> 25 | B34: HD Letters | F34: =F$33*'7.0.8'!$C35/'7.0.8'!$C$43 -> 0 | H34: =CS7Shape!K57 -> 51124.897 | I34: =I33*CARMM!C18/CARMM!C17 -> 1259.5558 | J34: =J$33*$H34/$H$33 -> 1697.9577 | L34: =SUM(C34:G34)+H34 -> 51124.897 | M34: =SUM(I34:J34) -> 2957.5134
A35: =A34+1 -> 26 | B35: Sat Letters | F35: =F$33*'7.0.8'!$C36/'7.0.8'!$C$43 -> 0 | H35: =CS7Shape!K58 -> 43714.284 | I35: =I33*CARMM!C19/CARMM!C17 -> 795.80124 | J35: =J$33*$H35/$H$33 -> 1451.8367 | L35: =SUM(C35:G35)+H35 -> 43714.284 | M35: =SUM(I35:J35) -> 2247.638
A36: =A35+1 -> 27 | B36: HIGH DENSITY & SATURATION FLATS & PARCELS | C36: =C18 -> 0 | D36: =D18 -> 0 | E36: =E18 -> 0 | F36: =F18 -> 0 | G36: =G18 -> 0 | H36: =H18 -> 192903.99 | I36: =I18 -> 2624.5968 | J36: =J18 -> 6406.7181 | K36: =K18 -> 0 | L36: =SUM(C36:G36)+H36 -> 192903.99 | M36: =M18 -> 9031.315
A37: =A36+1 -> 28 | B37: HD Flats | D37: =D$36*'7.0.8'!$C38/'7.0.8'!$C$42 -> 0 | F37: =F$36*'7.0.8'!$C38/'7.0.8'!$C$42 -> 0 | H37: =CS7Shape!K60 -> 18506.279 | I37: =I36*CARMM!C23/CARMM!C20 -> 1691.2756 | J37: =J$36*$H37/$H$36 -> 614.62965 | L37: =SUM(C37:G37)+H37 -> 18506.279 | M37: =SUM(I37:J37) -> 2305.9052
A38: =A37+1 -> 29 | B38: Sat Flats | D38: =D$36*'7.0.8'!$C39/'7.0.8'!$C$42 -> 0 | F38: =F$36*'7.0.8'!$C39/'7.0.8'!$C$42 -> 0 | H38: =CS7Shape!K61 -> 174397.71 | I38: =I36*CARMM!C25/CARMM!C20 -> 933.32124 | J38: =J$36*$H38/$H$36 -> 5792.0885 | L38: =SUM(C38:G38)+H38 -> 174397.71 | M38: =SUM(I38:J38) -> 6725.4097
A39: =A38+1 -> 30 | B39: HD Parcels | D39: =D$36*'7.0.8'!$C40/'7.0.8'!$C$42 -> 0 | F39: =F$36*'7.0.8'!$C40/'7.0.8'!$C$42 -> 0 | H39: =CS7Shape!K62 -> 0 | I39: =I36*CARMM!C24/CARMM!C20 -> 0 | J39: =J$36*$H39/$H$36 -> 0 | L39: =SUM(C39:G39)+H39 -> 0 | M39: =SUM(I39:J39) -> 0
A40: =A39+1 -> 31 | B40: Sat Parcels | D40: =D$36*'7.0.8'!$C41/'7.0.8'!$C$42 -> 0 | F40: =F$36*'7.0.8'!$C41/'7.0.8'!$C$42 -> 0 | H40: =CS7Shape!K63 -> 0 | I40: =I36*CARMM!C29/CARMM!C20 -> 0 | J40: =J$36*$H40/$H$36 -> 0 | L40: =SUM(C40:G40)+H40 -> 0 | M40: =SUM(I40:J40) -> 0
B41: HD & SAT Flats and PRCLS TOTAL | C41: =SUM(C37:C40) -> 0 | E41: =SUM(E37:E40) -> 0 | G41: =SUM(G37:G40) -> 0 | H41: =SUM(H37:H40) -> 192903.99 | I41: =SUM(I37:I40) -> 2624.5968 | J41: =SUM(J37:J40) -> 6406.7181
...

Sheet CS7Shape
A1: =Inputs!$C$4 -> Unit Delivery Cost Model - 12/16/2025
A2: =Inputs!C6 & " C/S 7 CITY CARRIERS LETTER ROUTE STREET COSTS BY SHAPE" -> FY 2025 C/S 7 CITY CARRIERS LETTER ROUTE STREET COSTS BY SHAPE
A3: SOURCE: CS06&7-NP-FY25.xlsx
A5: LINE NO. | B5: CLASS, SUBCLASS, OR SPECIAL SERVICE | C5: CASED MAIL LETTERS WITH DAL COSTS REMOVED | D5: CASED MAIL FLATS | E5: DPS WITH DAL COST MOVED | F5: SMALL PARCELS | G5: DEVIATION PARCELS/ ACCOUNTABLES | H5: TOTAL LETTERS, FLATS, AND SMALL PARCELS, DEVIATION PARCELS | I5: SEQUENCED WITH DAL COST MOVED TO FLATS | J5: COLLECTIONS AT CUSTOMER DELIVERY POINTS | K5: TOTAL DELIVERY SECTIONS
B6: COLUMN NUMBER | C6: =-1 -> -1 | D6: =C6-1 -> -2 | E6: =D6-1 -> -3 | F6: =E6-1 -> -4 | G6: =F6-1 -> -5 | H6: =G6-1 -> -6 | I6: =H6-1 -> -7 | J6: =I6-1 -> -8 | K6: =J6-1 -> -9
B7: UNITS | C7: $(000) | D7: $(000) | E7: $(000) | F7: $(000) | G7: $(000) | H7: $(000) | I7: $(000) | J7: $(000) | K7: $(000)
B8: COLUMN SOURCE/NOTES
A9: 1 | B9: FIRST-CLASS MAIL
A10: =A9+1 -> 2 | B10: SINGLE-PIECE LETTERS | C10: =IF(SUM('7.0.8'!$F11:$G11),'[2]7.0.6.5'!$D11*'7.0.8'!F11/SUM('7.0.8'!$F11:$G11),0) -> 10212.583 | D10: =IF(SUM('7.0.8'!$F11:$G11),'[2]7.0.6.5'!$D11*'7.0.8'!G11/SUM('7.0.8'!$F11:$G11),0) -> 0 | E10: ='[2]7.0.6.5'!$E11 -> 102333.48 | F10: ='[2]7.0.6.5'!$F11 -> 52.737753 | G10: ='[2]7.0.6.5'!I11 -> 1784.64 | H10: =SUM(C10:G10) -> 114383.44 | I10: ='[2]7.0.6.5'!$G11 -> 0 | J10: ='[2]7.0.6.5'!$H11 -> 126059.6 | K10: =SUM(H10:J10) -> 240443.05
A11: =A10+1 -> 3 | B11: SINGLE-PIECE CARDS | C11: =IF(SUM('7.0.8'!$F12:$G12),'[2]7.0.6.5'!$D12*'7.0.8'!F12/SUM('7.0.8'!$F12:$G12),0) -> 622.78924 | D11: =IF(SUM('7.0.8'!$F12:$G12),'[2]7.0.6.5'!$D12*'7.0.8'!G12/SUM('7.0.8'!$F12:$G12),0) -> 0 | E11: ='[2]7.0.6.5'!$E12 -> 3542.655 | F11: ='[2]7.0.6.5'!$F12 -> 1.260314 | G11: ='[2]7.0.6.5'!I12 -> 67.514869 | H11: =SUM(C11:G11) -> 4234.2195 | I11: ='[2]7.0.6.5'!$G12 -> 0 | J11: ='[2]7.0.6.5'!$H12 -> 4392.8203 | K11: =SUM(H11:J11) -> 8627.0398
A12: =A11+1 -> 4 | B12: PRESORT LETTERS | C12: =IF(SUM('7.0.8'!$F13:$G13),'[2]7.0.6.5'!$D13*'7.0.8'!F13/SUM('7.0.8'!$F13:$G13),0) -> 20221.228 | D12: =IF(SUM('7.0.8'!$F13:$G13),'[2]7.0.6.5'!$D13*'7.0.8'!G13/SUM('7.0.8'!$F13:$G13),0) -> 0 | E12: ='[2]7.0.6.5'!$E13 -> 403555.25 | F12: ='[2]7.0.6.5'!$F13 -> 0 | G12: ='[2]7.0.6.5'!I13 -> 0 | H12: =SUM(C12:G12) -> 423776.48 | I12: ='[2]7.0.6.5'!$G13 -> 0 | J12: ='[2]7.0.6.5'!$H13 -> 0 | K12: =SUM(H12:J12) -> 423776.48
A13: =A12+1 -> 5 | B13: PRESORT CARDS | C13: =IF(SUM('7.0.8'!$F14:$G14),'[2]7.0.6.5'!$D14*'7.0.8'!F14/SUM('7.0.8'!$F14:$G14),0) -> 1876.5883 | D13: =IF(SUM('7.0.8'!$F14:$G14),'[2]7.0.6.5'!$D14*'7.0.8'!G14/SUM('7.0.8'!$F14:$G14),0) -> 0 | E13: ='[2]7.0.6.5'!$E14 -> 32123.552 | F13: ='[2]7.0.6.5'!$F14 -> 3.8128477 | G13: ='[2]7.0.6.5'!I14 -> 0 | H13: =SUM(C13:G13) -> 34003.954 | I13: ='[2]7.0.6.5'!$G14 -> 0 | J13: ='[2]7.0.6.5'!$H14 -> 0 | K13: =SUM(H13:J13) -> 34003.954
A14: =A13+1 -> 6 | B14: SINGLE PIECE FLATS | C14: =IF(SUM('7.0.8'!$F15:$G15),'[2]7.0.6.5'!$D15*'7.0.8'!F15/SUM('7.0.8'!$F15:$G15),0) -> 0 | D14: =IF(SUM('7.0.8'!$F15:$G15),'[2]7.0.6.5'!$D15*'7.0.8'!G15/SUM('7.0.8'!$F15:$G15),0) -> 4296.3718 | E14: ='[2]7.0.6.5'!$E15 -> 0 | F14: ='[2]7.0.6.5'!$F15 -> 7.5893349 | G14: ='[2]7.0.6.5'!I15 -> 93.057168 | H14: =SUM(C14:G14) -> 4397.0183 | I14: ='[2]7.0.6.5'!$G15 -> 0 | J14: ='[2]7.0.6.5'!$H15 -> 5477.6548 | K14: =SUM(H14:J14) -> 9874.6731
A15: =A14+1 -> 7 | B15: PRESORT FLATS | C15: =IF(SUM('7.0.8'!$F16:$G16),'[2]7.0.6.5'!$D16*'7.0.8'!F16/SUM('7.0.8'!$F16:$G16),0) -> 0 | D15: =IF(SUM('7.0.8'!$F16:$G16),'[2]7.0.6.5'!$D16*'7.0.8'!G16/SUM('7.0.8'!$F16:$G16),0) -> 5195.9811 | E15: ='[2]7.0.6.5'!$E16 -> 0 | F15: ='[2]7.0.6.5'!$F16 -> 0 | G15: ='[2]7.0.6.5'!I16 -> 0 | H15: =SUM(C15:G15) -> 5195.9811 | I15: ='[2]7.0.6.5'!$G16 -> 0 | J15: ='[2]7.0.6.5'!$H16 -> 0 | K15: =SUM(H15:J15) -> 5195.9811
A16: =A15+1 -> 8 | B16: TOTAL FIRST-CLASS | C16: =SUM(C10:C15) -> 32933.188 | D16: =SUM(D10:D15) -> 9492.3529 | E16: ='[2]7.0.6.5'!$E17 -> 541554.95 | F16: ='[2]7.0.6.5'!$F17 -> 65.400249 | G16: ='[2]7.0.6.5'!I17 -> 1945.2121 | H16: =SUM(C16:G16) -> 585991.1 | I16: ='[2]7.0.6.5'!$G17 -> 0 | J16: ='[2]7.0.6.5'!$H17 -> 135930.08 | K16: =SUM(H16:J16) -> 721921.18
A17: =A16+1 -> 9 | B17: USPS MARKETING MAIL
A18: =A17+1 -> 10 | B18: HIGH DENSITY & SATURATION LETTERS | C18: =IF(SUM('7.0.8'!$F18:$G18),('[2]7.0.6.5'!$D19-'City DAL Costs'!J10-'City DAL Costs'!L10)*'7.0.8'!$F18/SUM('7.0.8'!$F18:$G18),0) -> 13432.396 | D18: =IF(SUM('7.0.8'!$F18:$G18),('[2]7.0.6.5'!$D19-'City DAL Costs'!K10-'City DAL Costs'!M10)*'7.0.8'!$G18/SUM('7.0.8'!$F18:$G18),0) -> 0 | E18: ='[2]7.0.6.5'!$E19-'City DAL Costs'!J11-'City DAL Costs'!L11 -> 71929.886 | F18: ='[2]7.0.6.5'!$F19 -> 0 | G18: ='[2]7.0.6.5'!I19 -> 0 | H18: =SUM(C18:G18) -> 85362.282 | I18: ='[2]7.0.6.5'!$G19-'City DAL Costs'!J15-'City DAL Costs'!L15 -> 9476.8981 | J18: ='[2]7.0.6.5'!$H19 -> 0 | K18: =SUM(H18:J18) -> 94839.18
A19: =A18+1 -> 11 | B19: HIGH DENSITY & SATURATION FLATS & PARCELS | C19: =IF(SUM('7.0.8'!$F19:$G19),'[2]7.0.6.5'!$D20*'7.0.8'!$F19/SUM('7.0.8'!$F19:$G19),0) -> 0 | D19: ='City DAL Costs'!C12+'City DAL Costs'!J10+'City DAL Costs'!L10-'City DAL Costs'!D19 -> 35237.968 | E19: ='City DAL Costs'!J11+'City DAL Costs'!L11 -> 756.36279 | F19: ='[2]7.0.6.5'!$F20-'City DAL Costs'!D20 -> 0 | G19: ='[2]7.0.6.5'!I20 -> 0 | H19: =SUM(C19:G19) -> 35994.331 | I19: ='City DAL Costs'!E16+'City DAL Costs'!J15+'City DAL Costs'!L15 -> 156909.66 | J19: ='[2]7.0.6.5'!$H20 -> 0 | K19: =SUM(H19:J19) -> 192903.99
A20: =A19+1 -> 12 | B20: EVERY DOOR DIRECT MAIL RETAIL | C20: ='[2]7.0.6.5'!$D$21*[3]CCCS_Matrix_FY25!$E$29/([3]CCCS_Matrix_FY25!$E$29+[3]CCCS_Matrix_FY25!$F$29) -> 0 | D20: ='City DAL Costs'!D19 -> 2466.7672 | E20: ='[2]7.0.6.5'!$E21 -> 0 | F20: ='City DAL Costs'!D20 -> 0 | G20: ='[2]7.0.6.5'!I21 -> 0 | H20: =SUM(C20:G20) -> 2466.7672 | I20: ='City DAL Costs'!D21 -> 11045.856 | J20: ='[2]7.0.6.5'!$H21 -> 0 | K20: =SUM(H20:J20) -> 13512.623
A21: =A20+1 -> 13 | B21: CARRIER ROUTE | C21: =IF(SUM('7.0.8'!F21:G21),'[2]7.0.6.5'!D22*'7.0.8'!F21/SUM('7.0.8'!F21:G21),0) -> 138.67307 | D21: =IF(SUM('7.0.8'!F21:G21),'[2]7.0.6.5'!$D22*'7.0.8'!G21/SUM('7.0.8'!F21:G21),0) -> 30471.671 | E21: ='[2]7.0.6.5'!$E22 -> 198.0582 | F21: ='[2]7.0.6.5'!$F22 -> 30.563232 | G21: ='[2]7.0.6.5'!I22 -> 0 | H21: =SUM(C21:G21) -> 30838.966 | I21: ='[2]7.0.6.5'!$G22 -> 0 | J21: ='[2]7.0.6.5'!$H22 -> 0 | K21: =SUM(H21:J21) -> 30838.966
A22: =A21+1 -> 14 | B22: LETTERS | C22: =IF(SUM('7.0.8'!F22:G22),'[2]7.0.6.5'!D23*'7.0.8'!F22/SUM('7.0.8'!F22:G22),0) -> 32151.681 | D22: =IF(SUM('7.0.8'!F22:G22),'[2]7.0.6.5'!$D23*'7.0.8'!G22/SUM('7.0.8'!F22:G22),0) -> 0 | E22: ='[2]7.0.6.5'!$E23 -> 515279.37 | F22: ='[2]7.0.6.5'!$F23 -> 59.195431 | G22: ='[2]7.0.6.5'!I23 -> 0 | H22: =SUM(C22:G22) -> 547490.24 | I22: ='[2]7.0.6.5'!$G23 -> 0 | J22: ='[2]7.0.6.5'!$H23 -> 14322.335 | K22: =SUM(H22:J22) -> 561812.58
A23: =A22+1 -> 15 | B23: FLATS | C23: =IF(SUM('7.0.8'!F23:G23),'[2]7.0.6.5'!D24*'7.0.8'!F23/SUM('7.0.8'!F23:G23),0) -> 0 | D23: =IF(SUM('7.0.8'!F23:G23),'[2]7.0.6.5'!$D24*'7.0.8'!G23/SUM('7.0.8'!F23:G23),0) -> 19544.171 | E23: ='[2]7.0.6.5'!$E24 -> 0 | F23: ='[2]7.0.6.5'!$F24 -> 12.735503 | G23: ='[2]7.0.6.5'!I24 -> 0 | H23: =SUM(C23:G23) -> 19556.906 | I23: ='[2]7.0.6.5'!$G24 -> 0 | J23: ='[2]7.0.6.5'!$H24 -> 630.28635 | K23: =SUM(H23:J23) -> 20187.192
A24: =A23+1 -> 16 | B24: PARCELS | E24: ='[2]7.0.6.5'!$E25 -> 0 | F24: ='[2]7.0.6.5'!$F25 -> 915.25967 | G24: ='[2]7.0.6.5'!I25 -> 587.03512 | H24: =SUM(C24:G24) -> 1502.2948 | I24: ='[2]7.0.6.5'!$G25 -> 0 | J24: ='[2]7.0.6.5'!$H25 -> 175.56011 | K24: =SUM(H24:J24) -> 1677.8549
A25: =A24+1 -> 17 | B25: TOTAL USPS MARKETING MAIL | C25: =SUM(C18:C24) -> 45722.75 | D25: =SUM(D18:D24) -> 87720.577 | E25: ='[2]7.0.6.5'!$E26 -> 588163.67 | F25: ='[2]7.0.6.5'!$F26 -> 1017.7538 | G25: ='[2]7.0.6.5'!I26 -> 587.03512 | H25: =SUM(C25:G25) -> 723211.79 | I25: =SUM(I18:I24) -> 177432.41 | J25: ='[2]7.0.6.5'!$H26 -> 15128.181 | K25: =SUM(H25:J25) -> 915772.38
A26: =A25+1 -> 18 | B26: PERIODICALS
A27: =A26+1 -> 19 | B27: IN-COUNTY | E27: ='[2]7.0.6.5'!$E27 -> 0 | F27: 0 | H27: =SUM(C27:F27) -> 0 | I27: ='[2]7.0.6.5'!$G28 -> 0 | K27: =SUM(H27:J27) -> 0
A28: =A27+1 -> 20 | B28: OUTSIDE COUNTY | E28: ='[2]7.0.6.5'!$E29 -> 0 | F28: 0 | H28: =SUM(C28:F28) -> 0 | I28: ='[2]7.0.6.5'!$G29 -> 0 | K28: =SUM(H28:J28) -> 0
A29: =A28+1 -> 21 | B29: TOTAL PERIODICALS | C29: =IF(SUM('7.0.8'!F25:G25),'[2]7.0.6.5'!D30*'7.0.8'!F25/SUM('7.0.8'!F25:G25),0) -> 44.842188 | D29: =IF(SUM('7.0.8'!F25:G25),'[2]7.0.6.5'!$D30*'7.0.8'!G25/SUM('7.0.8'!F25:G25),0) -> 22418.971 | E29: ='[2]7.0.6.5'!$E$30 -> 83.136063 | F29: ='[2]7.0.6.5'!$F$30 -> 258.15603 | G29: ='[2]7.0.6.5'!I30 -> 56.798703 | H29: =SUM(C29:G29) -> 22861.904 | I29: ='[2]7.0.6.5'!$G30 -> 0 | J29: ='[2]7.0.6.5'!$H30 -> 405.94857 | K29: =SUM(H29:J29) -> 23267.853
A30: =A29+1 -> 22 | B30: PACKAGE SERVICES
A31: =A30+1 -> 23 | B31: BOUND PRINTED MATTER FLATS | C31: =IF(SUM('7.0.8'!$F27:$G27),'[2]7.0.6.5'!$D32*'7.0.8'!F27/SUM('7.0.8'!$F27:$G27),0) -> 0.30118058 | D31: =IF(SUM('7.0.8'!$F27:$G27),'[2]7.0.6.5'!$D32*'7.0.8'!G27/SUM('7.0.8'!$F27:$G27),0) -> 1133.3478 | E31: ='[2]7.0.6.5'!$E32 -> 0 | F31: ='[2]7.0.6.5'!$F32 -> 118.55331 | G31: ='[2]7.0.6.5'!I32 -> 24.753812 | H31: =SUM(C31:G31) -> 1276.9561 | I31: ='[2]7.0.6.5'!$G32 -> 0 | J31: ='[2]7.0.6.5'!$H32 -> 189.50647 | K31: =SUM(H31:J31) -> 1466.4626
A32: =A31+1 -> 24 | B32: BOUND PRINTED MATTER PARCELS | E32: ='[2]7.0.6.5'!$E33 -> 0 | F32: ='[2]7.0.6.5'!$F33 -> 19120.349 | G32: ='[2]7.0.6.5'!I33 -> 27611.41 | H32: =SUM(C32:G32) -> 46731.759 | I32: ='[2]7.0.6.5'!$G33 -> 0 | J32: ='[2]7.0.6.5'!$H33 -> 106.17011 | K32: =SUM(H32:J32) -> 46837.929
A33: =A32+1 -> 25 | B33: MEDIA AND LIBRARY MAIL | C33: =IF(SUM('7.0.8'!F29:G29),'[2]7.0.6.5'!D34*'7.0.8'!F29/SUM('7.0.8'!F29:G29),0) -> 1.1337637 | D33: =IF(SUM('7.0.8'!$F29:$G29),'[2]7.0.6.5'!$D34*'7.0.8'!G29/SUM('7.0.8'!$F29:$G29),0) -> 12.21324 | E33: ='[2]7.0.6.5'!$E34 -> 0 | F33: ='[2]7.0.6.5'!$F34 -> 3883.0526 | G33: ='[2]7.0.6.5'!I34 -> 13349.885 | H33: =SUM(C33:G33) -> 17246.284 | I33: ='[2]7.0.6.5'!$G34 -> 0 | J33: ='[2]7.0.6.5'!$H34 -> 264.43399 | K33: =SUM(H33:J33) -> 17510.718
A34: =A33+1 -> 26 | B34: TOTAL PACKAGE SERVICES | C34: =SUM(C31:C33) -> 1.4349443 | D34: =SUM(D31:D33) -> 1145.561 | E34: ='[2]7.0.6.5'!$E35 -> 0 | F34: ='[2]7.0.6.5'!$F35 -> 23121.955 | G34: ='[2]7.0.6.5'!I35 -> 40986.049 | H34: =SUM(C34:G34) -> 65254.999 | I34: ='[2]7.0.6.5'!$G35 -> 0 | J34: ='[2]7.0.6.5'!$H35 -> 560.11058 | K34: =SUM(H34:J34) -> 65815.11
A35: =A34+1 -> 27 | B35: US POSTAL SERVICE | C35: ='[2]7.0.6.5'!$D36*[3]CCCS_Matrix_FY25!E49/([3]CCCS_Matrix_FY25!$E49+[3]CCCS_Matrix_FY25!$F49) -> 728.12322 | D35: ='[2]7.0.6.5'!$D$36*[3]CCCS_Matrix_FY25!F$49/([3]CCCS_Matrix_FY25!$E$49+[3]CCCS_Matrix_FY25!$F$49) -> 76.910838 | E35: ='[2]7.0.6.5'!$E36 -> 4447.5363 | F35: ='[2]7.0.6.5'!$F36 -> 2202.2517 | G35: ='[2]7.0.6.5'!I36 -> 1664.8746 | H35: =SUM(C35:G35) -> 9119.6967 | I35: ='[2]7.0.6.5'!$G36 -> 0 | J35: ='[2]7.0.6.5'!$H36 -> 0 | K35: =SUM(H35:J35) -> 9119.6967
A36: =A35+1 -> 28 | B36: FREE MAIL | C36: ='[2]7.0.6.5'!$D37*[3]CCCS_Matrix_FY25!E50/([3]CCCS_Matrix_FY25!$E50+[3]CCCS_Matrix_FY25!$F50) -> 4.114946 | D36: ='[2]7.0.6.5'!$D37*[3]CCCS_Matrix_FY25!F50/([3]CCCS_Matrix_FY25!$E50+[3]CCCS_Matrix_FY25!$F50) -> 134.97793 | E36: ='[2]7.0.6.5'!$E37 -> 40.508248 | F36: ='[2]7.0.6.5'!$F37 -> 276.96967 | G36: ='[2]7.0.6.5'!I37 -> 291.29543 | H36: =SUM(C36:G36) -> 747.86622 | I36: ='[2]7.0.6.5'!$G37 -> 0 | J36: ='[2]7.0.6.5'!$H37 -> 0 | K36: =SUM(H36:J36) -> 747.86622
A37: =A36+1 -> 29 | B37: SPECIAL SERVICES: | H37: =SUM(C37:G37) -> 0 | K37: =SUM(H37:J37) -> 0
A38: =A37+1 -> 30 | B38: CERTIFIED | G38: ='[2]7.0.6.5'!I40 -> 72212.033 | H38: =SUM(C38:G38) -> 72212.033 | K38: =SUM(H38:J38) -> 72212.033
A39: =A38+1 -> 31 | B39: COD | G39: ='[2]7.0.6.5'!I41 -> 167.84825 | H39: =SUM(C39:G39) -> 167.84825 | K39: =SUM(H39:J39) -> 167.84825
A40: =A39+1 -> 32 | B40: INSURANCE | G40: ='[2]7.0.6.5'!I42 -> 816.36915 | H40: =SUM(C40:G40) -> 816.36915 | K40: =SUM(H40:J40) -> 816.36915
A41: =A40+1 -> 33 | B41: REGISTRY | G41: ='[2]7.0.6.5'!I43 -> 112.77531 | H41: =SUM(C41:G41) -> 112.77531 | K41: =SUM(H41:J41) -> 112.77531
...

Sheet City DAL Costs
A1: ='7.0.6'!A1 -> Unit Delivery Cost Model - 12/16/2025
A2: CS 7 CITY CARRIERS STREET
A3: WS 7.0.10 DAL AND EDDM-R COSTS
A5: Line No. | B5: DELIVERY-ACTIVITY ACCRUED COST POOL | C5: VOLUME VARIABLE COST ON DELIVERY SECTIONS | D5: EDDM-R Cost | E5: HD/SAT FLATS & PARCELS COST | F5: CCS PIECES | G5: COST PER CCS PIECE | H5: SATURATION DALS - REGULAR DELIVERY | I5: SATURATION DALS - SEQUENCED | J5: SATURATION DAL & HOST COST | K5: HD DALS | L5: HD DAL & HOST COST | M5: DAL COST TO MOVE TO FLATS | N5: REVISED LETTER/FLAT COSTS
B6: COLUMN NUMBER | C6: -1 | D6: =+C6-1 -> -2 | E6: =+D6-1 -> -3 | F6: =+E6-1 -> -4 | G6: =+F6-1 -> -5 | H6: =+G6-1 -> -6 | I6: =+H6-1 -> -7 | J6: =+I6-1 -> -8 | K6: =+J6-1 -> -9 | ... N6: =+M6-1 -> -12
B7: CALCULATIONS | G7: ="C"&-C6&" / C"&-F6 -> C1 / C4 | L7: ="C"&-K6&" x C"&-G6 -> C9 x C5 | M7: ="C"&-J6&" + C"&-L6 -> C8 + C10
B8: UNITS
B9: COLUMN SOURCE/NOTES | C9: 7.0.6.5 | D9: 7.0.8 | F9: 7.0.8 | H9: CCSDALs | I9: CCSDALs | K9: CCSDALs
A10: 1 | B10: Regular Delivery of Cased HD/Saturation Letters | C10: ='[2]7.0.6.5'!D19 -> 13958.314 | F10: ='7.0.8'!E18 -> 768413.85 | G10: =C10/F10 -> 0.018165099 | H10: =CCSDALs!E12 -> 28946.592 | J10: =H10*G10 -> 525.81772 | K10: =CCSDALs!F12 -> 5.5223437 | L10: =K10*G10 -> 0.10031392 | M10: =J10+L10 -> 525.91803 | N10: =C10-M10 -> 13432.396
A11: =A10+1 -> 2 | B11: Regular Delivery of DPS HD & Saturation Letters | C11: ='[2]7.0.6.5'!E19 -> 72686.249 | F11: ='7.0.8'!H18 -> 2817705 | G11: =C11/F11 -> 0.025796259 | H11: =CCSDALs!E7 -> 28082.675 | J11: =H11*G11 -> 724.42798 | K11: =CCSDALs!F7 -> 1237.9627 | L11: =K11*G11 -> 31.934806 | M11: =J11+L11 -> 756.36279 | N11: =C11-M11 -> 71929.886
A12: =A11+1 -> 3 | B12: Regular Delivery of Cased HD/Saturation Flats | C12: ='[2]7.0.6.5'!D20 -> 37178.817 | D12: =D19 -> 2466.7672 | N12: =C12-D12+M10 -> 35237.968
A13: =A12+1 -> 4 | B13: Regular Delivery of Parcels | C13: ='[2]7.0.6.5'!F20 -> 0 | D13: =D20 -> 0
A14: =A13+1 -> 5 | B14: Regular Delivery of Flats / Parcels | C14: =C12+C13 -> 37178.817 | E14: =C14-D19-D20 -> 34712.05 | N14: =E14+M10+M11 -> 35994.331
A15: =A14+1 -> 6 | B15: Delivery of Sequenced HD and Saturation Letters | C15: ='[2]7.0.6.5'!G19 -> 10950.605 | F15: ='7.0.8'!J18 -> 202943.25 | G15: =C15/F15 -> 0.053958951 | I15: =CCSDALs!E11 -> 27311.628 | J15: =I15*G15 -> 1473.7068 | K15: =CCSDALs!F11 -> 0 | L15: =K15*G15 -> 0 | M15: =J15+L15 -> 1473.7068 | N15: =C15-M15 -> 9476.8981
A16: =A15+1 -> 7 | B16: Delivery of Sequenced HD & Saturation Flats | C16: ='[2]7.0.6.5'!G20 -> 166481.8 | E16: =C16-D21 -> 155435.95 | F16: ='7.0.8'!J19 -> 3085341.8 | G16: =C16/F16 -> 0.053958951 | J16: =(H10+H11+I15)*G16 -> 4550.9462 | L16: =(K10+K11)*G16 -> 67.097146 | N16: =E16+M15 -> 156909.66
A17: =A16+1 -> 8 | B17: Revised Cost, HD & Saturation Letters | N17: =N10+N15+N11 -> 94839.18
A18: =A17+1 -> 9 | B18: Revised Cost, HD & Saturation Flats and Parcels | N18: =N14+N16 -> 192903.99
A19: =A18+1 -> 10 | B19: EDDM Cased Mail Delivery Cost | D19: =C12*'7.0.8'!C20/('7.0.8'!C19+'7.0.8'!C20) -> 2466.7672 | N19: =D19 -> 2466.7672
A20: =A19+1 -> 11 | B20: EDDM Parcel Delivery Cost | D20: =C13*'7.0.8'!C20/('7.0.8'!C20+'7.0.8'!C19) -> 0 | N20: =D20 -> 0
A21: =A20+1 -> 12 | B21: EDDM Retail Sequenced Delivery Cost | D21: =C16*'7.0.8'!C20/('7.0.8'!C19+'7.0.8'!C20) -> 11045.856 | N21: =D21 -> 11045.856
B22: NOTE: DAL costs moved from HD/Saturation Letters to HD/Saturation Flats
B23: NOTE: EDDM-R Costs are split out using RPW proportions

Sheet CS10 CRA
A1: ='7.0.6'!A1 -> Unit Delivery Cost Model - 12/16/2025
A2: C/S 10 RURAL CARRIERS
A3: OUTPUTS TO CRA MODEL
A5: LINE NO | B5: CLASS, SUBCLASS, OR SPECIAL SERVICE | C5: CRA CLASS | D5: All ROUTES
B6: COLUMN NUMBER | D6: -1
B7: UNITS | D7: $(000)
B8: COLUMN SOURCE/NOTES | D8: WS 10.1.2 C18
B9: MODEL COMPONENT | D9: 69
A10: 1 | B10: FIRST-CLASS MAIL
A11: =A10+1 -> 2 | B11: SINGLE-PIECE LETTERS | C11: 3 | D11: ='[5]Outputs to CRA'!$D12 -> 140775.7
A12: =A11+1 -> 3 | B12: SINGLE-PIECE CARDS | C12: 4 | D12: ='[5]Outputs to CRA'!$D13 -> 6824.807
A13: =A12+1 -> 4 | B13: PRESORT LETTERS | C13: 8 | D13: ='[5]Outputs to CRA'!$D14 -> 406771.86
A14: =A13+1 -> 5 | B14: PRESORT CARDS | C14: 9 | D14: ='[5]Outputs to CRA'!$D15 -> 31516.878
A15: =A14+1 -> 6 | B15: SINGLE PIECE FLATS | C15: 16 | D15: ='[5]Outputs to CRA'!$D16 -> 18222.698
A16: =A15+1 -> 7 | B16: PRESORT FLATS | C16: 17 | D16: ='[5]Outputs to CRA'!$D17 -> 22621.902
A17: =A16+1 -> 8 | B17: USPS MARKETING MAIL
A18: =A17+1 -> 9 | B18: HIGH DENSITY & SATURATION LETTERS | C18: 21 | D18: ='[5]Outputs to CRA'!$D20 -> 142793.23
A19: =A18+1 -> 10 | B19: HIGH DENSITY & SATURATION FLATS & PARCELS | C19: 22 | D19: ='[5]Outputs to CRA'!$D21 -> 311173.67
A20: =A19+1 -> 11 | B20: EVERY DOOR DIRECT MAIL RETAIL | C20: 24 | D20: ='[5]Outputs to CRA'!$F$22 -> 6265.5646
A21: =A20+1 -> 12 | B21: CARRIER ROUTE | C21: 23 | D21: ='[5]Outputs to CRA'!$D23 -> 160206.59
A22: =A21+1 -> 13 | B22: LETTERS | C22: 25 | D22: ='[5]Outputs to CRA'!$D24 -> 606006.31
A23: =A22+1 -> 14 | B23: FLATS | C23: 26 | D23: ='[5]Outputs to CRA'!$D25 -> 101205.37
A24: =A23+1 -> 15 | B24: PARCELS | C24: 27 | D24: ='[5]Outputs to CRA'!$D26 -> 2671.3112
A25: =A24+1 -> 16 | B25: TOTAL PERIODICALS | D25: ='[5]Outputs to CRA'!$D$31 -> 165184.75
A26: =A25+1 -> 17 | B26: PACKAGE SERVICES
A27: =A26+1 -> 18 | B27: BOUND PRINTED MATTER FLATS | C27: 42 | D27: ='[5]Outputs to CRA'!$D33 -> 6221.2778
A28: =A27+1 -> 19 | B28: BOUND PRINTED MATTER PARCELS | C28: 43 | D28: ='[5]Outputs to CRA'!$D34 -> 72646.687
A29: =A28+1 -> 20 | B29: MEDIA MAIL | C29: 44 | D29: ='[5]Outputs to CRA'!$D35 -> 22216.989
A30: =A29+1 -> 21 | B30: TOTAL VOLUME VARIABLE | C30: 198 | D30: ='[5]Outputs to CRA'!$D$62 -> 4758958

Sheet RuralCosts
A1: =Inputs!$C$4 -> Unit Delivery Cost Model - 12/16/2025
A2: RURAL COSTS BY EVALUATION CATEGORY
A3: SOURCE: CS10-NP-FY25.xlsx, W/S 10.1.2
C4: NOTE: CRA Spreadsheets have Sat & HD DAL, Shape Adjustments
A5: Line No. | C5: Letters | D5: Flats | E5: Mailbox Parcels | F5: Door Parcels | G5: Parcel Locker Parcels | H5: Boxholder | I5: DPS | J5: Postage Due | K5: End Of Shift Collections | L5: Carrier Pickup | M5: Misc to Door | N5: Misc Actv | O5: Total Delivered | P5: Total
B6: Col. No. | C6: -1 | D6: =C6-1 -> -2 | E6: =D6-1 -> -3 | F6: =E6-1 -> -4 | G6: =F6-1 -> -5 | H6: =G6-1 -> -6 | I6: =H6-1 -> -7 | J6: =I6-1 -> -8 | K6: =J6-1 -> -9 | ... P6: =O6-1 -> -14
B7: Units | C7: $(000) | D7: $(000) | E7: $(000) | F7: $(000) | G7: $(000) | H7: $(000) | I7: $(000) | J7: $(000) | K7: $(000) | L7: $(000) | M7: $(000) | N7: $(000) | O7: $(000) | P7: $(000)
B8: Source / Calculations
A9: 1 | B9: WS 10.1.2
A10: =A9+1 -> 2 | B10: First-Class
A11: =A10+1 -> 3 | B11: SINGLE-PIECE LETTERS | C11: ='[5]10.1.2'!D11 -> 49940.214 | D11: ='[5]10.1.2'!E11 -> 775.65753 | E11: ='[5]10.1.2'!F11 -> 0 | F11: ='[5]10.1.2'!G11 -> 0 | G11: ='[5]10.1.2'!H11 -> 0 | H11: ='[5]10.1.2'!I11 -> 0 | I11: ='[5]10.1.2'!K11 -> 78847.976 | J11: ='[5]10.1.2'!L11 -> 309.18189 | K11: ='[5]10.1.2'!M11 -> 7699.2631 | L11: ='[5]10.1.2'!N11 -> 0 | M11: ='[5]10.1.2'!S11 -> 2911.9357 | N11: ='[5]10.1.2'!T11 -> 291.47557 | O11: =SUM(C11:J11)+SUM(M11:N11) -> 133076.44 | P11: =SUM(C11:N11) -> 140775.7
A12: =A11+1 -> 4 | B12: SINGLE-PIECE CARDS | C12: ='[5]10.1.2'!D12 -> 3870.8245 | D12: ='[5]10.1.2'!E12 -> 6.405856 | E12: ='[5]10.1.2'!F12 -> 0 | F12: ='[5]10.1.2'!G12 -> 0 | G12: ='[5]10.1.2'!H12 -> 0 | H12: ='[5]10.1.2'!I12 -> 0 | I12: ='[5]10.1.2'!K12 -> 2829.7251 | J12: ='[5]10.1.2'!L12 -> 2.2576494 | K12: ='[5]10.1.2'!M12 -> 0 | L12: ='[5]10.1.2'!N12 -> 0 | M12: ='[5]10.1.2'!S12 -> 101.47271 | N12: ='[5]10.1.2'!T12 -> 14.12119 | O12: =SUM(C12:J12)+SUM(M12:N12) -> 6824.807 | P12: =SUM(C12:N12) -> 6824.807
A13: =A12+1 -> 5 | B13: PRESORT LETTERS | C13: ='[5]10.1.2'!D13 -> 95004.735 | D13: ='[5]10.1.2'!E13 -> 1185.642 | E13: ='[5]10.1.2'!F13 -> 0 | F13: ='[5]10.1.2'!G13 -> 0 | G13: ='[5]10.1.2'!H13 -> 0 | H13: ='[5]10.1.2'!I13 -> 0 | I13: ='[5]10.1.2'!K13 -> 300688.73 | J13: ='[5]10.1.2'!L13 -> 0 | K13: ='[5]10.1.2'!M13 -> 0 | L13: ='[5]10.1.2'!N13 -> 0 | M13: ='[5]10.1.2'!S13 -> 9050.2166 | N13: ='[5]10.1.2'!T13 -> 842.52924 | O13: =SUM(C13:J13)+SUM(M13:N13) -> 406771.86 | P13: =SUM(C13:N13) -> 406771.86
A14: =A13+1 -> 6 | B14: PRESORT CARDS | C14: ='[5]10.1.2'!D14 -> 7603.1914 | D14: ='[5]10.1.2'!E14 -> 18.777653 | E14: ='[5]10.1.2'!F14 -> 0 | F14: ='[5]10.1.2'!G14 -> 7.411511 | G14: ='[5]10.1.2'!H14 -> 0 | H14: ='[5]10.1.2'!I14 -> 0 | I14: ='[5]10.1.2'!K14 -> 23095.113 | J14: ='[5]10.1.2'!L14 -> 0 | K14: ='[5]10.1.2'!M14 -> 0 | L14: ='[5]10.1.2'!N14 -> 0 | M14: ='[5]10.1.2'!S14 -> 727.10639 | N14: ='[5]10.1.2'!T14 -> 65.277708 | O14: =SUM(C14:J14)+SUM(M14:N14) -> 31516.878 | P14: =SUM(C14:N14) -> 31516.878
A15: =A14+1 -> 7 | B15: SINGLE PIECE FLATS | C15: ='[5]10.1.2'!D15 -> 1.8691304 | D15: ='[5]10.1.2'!E15 -> 17855.054 | E15: ='[5]10.1.2'!F15 -> 0 | F15: ='[5]10.1.2'!G15 -> 0 | G15: ='[5]10.1.2'!H15 -> 0 | H15: ='[5]10.1.2'!I15 -> 0 | I15: ='[5]10.1.2'!K15 -> 0 | J15: ='[5]10.1.2'!L15 -> 201.41223 | K15: ='[5]10.1.2'!M15 -> 0 | L15: ='[5]10.1.2'!N15 -> 0 | M15: ='[5]10.1.2'!S15 -> 126.53204 | N15: ='[5]10.1.2'!T15 -> 37.830605 | O15: =SUM(C15:J15)+SUM(M15:N15) -> 18222.698 | P15: =SUM(C15:N15) -> 18222.698
A16: =A15+1 -> 8 | B16: PRESORT FLATS | C16: ='[5]10.1.2'!D16 -> 1.2545102 | D16: ='[5]10.1.2'!E16 -> 22439.219 | E16: ='[5]10.1.2'!F16 -> 0 | F16: ='[5]10.1.2'!G16 -> 0 | G16: ='[5]10.1.2'!H16 -> 0 | H16: ='[5]10.1.2'!I16 -> 0 | I16: ='[5]10.1.2'!K16 -> 0 | J16: ='[5]10.1.2'!L16 -> 0 | K16: ='[5]10.1.2'!M16 -> 0 | L16: ='[5]10.1.2'!N16 -> 0 | M16: ='[5]10.1.2'!S16 -> 134.46573 | N16: ='[5]10.1.2'!T16 -> 46.962724 | O16: =SUM(C16:J16)+SUM(M16:N16) -> 22621.902 | P16: =SUM(C16:N16) -> 22621.902
A17: =A16+1 -> 9 | B17: USPS MARKETING MAIL (A)
A18: =A17+1 -> 10 | B18: HIGH DENSITY & SATURATION LETTERS | C18: ='[5]10.1.2'!D19 -> 70440.997 | D18: ='[5]10.1.2'!E19 -> 1915.5951 | E18: ='[5]10.1.2'!F19 -> 0 | F18: ='[5]10.1.2'!G19 -> 0 | G18: ='[5]10.1.2'!H19 -> 0 | H18: ='[5]10.1.2'!I19 -> 12847.592 | I18: ='[5]10.1.2'!K19 -> 55415.843 | J18: ='[5]10.1.2'!L19 -> 0 | K18: ='[5]10.1.2'!M19 -> 0 | L18: ='[5]10.1.2'!N19 -> 0 | M18: ='[5]10.1.2'!S19 -> 1869.5471 | N18: ='[5]10.1.2'!T19 -> 303.65557 | O18: =SUM(C18:J18)+SUM(M18:N18) -> 142793.23 | P18: =SUM(C18:N18) -> 142793.23
A19: =A18+1 -> 11 | B19: HIGH DENSITY & SATURATION FLATS & PARCELS | C19: ='[5]10.1.2'!D20 -> 2892.0863 | D19: ='[5]10.1.2'!E20 -> 218533.41 | E19: ='[5]10.1.2'!F20 -> 0 | F19: ='[5]10.1.2'!G20 -> 0 | G19: ='[5]10.1.2'!H20 -> 0 | H19: ='[5]10.1.2'!I20 -> 86461.102 | I19: ='[5]10.1.2'!K20 -> 204.70492 | J19: ='[5]10.1.2'!L20 -> 0 | K19: ='[5]10.1.2'!M20 -> 0 | L19: ='[5]10.1.2'!N20 -> 0 | M19: ='[5]10.1.2'!S20 -> 2444.7772 | N19: ='[5]10.1.2'!T20 -> 637.59347 | O19: =SUM(C19:J19)+SUM(M19:N19) -> 311173.67 | P19: =SUM(C19:N19) -> 311173.67
A20: =A19+1 -> 12 | B20: EVERY DOOR DIRECT MAIL RETAIL | C20: ='[5]10.1.2'!D21 -> 0 | D20: ='[5]10.1.2'!E21 -> 0 | E20: ='[5]10.1.2'!F21 -> 0 | F20: ='[5]10.1.2'!G21 -> 0 | G20: ='[5]10.1.2'!H21 -> 0 | H20: ='[5]10.1.2'!I21 -> 6078.8403 | I20: ='[5]10.1.2'!K21 -> 0 | J20: ='[5]10.1.2'!L21 -> 0 | K20: ='[5]10.1.2'!M21 -> 0 | L20: ='[5]10.1.2'!N21 -> 0 | M20: ='[5]10.1.2'!S21 -> 173.73495 | N20: ='[5]10.1.2'!T21 -> 12.989366 | O20: =SUM(C20:J20)+SUM(M20:N20) -> 6265.5646 | P20: =SUM(C20:N20) -> 6265.5646
A21: =A20+1 -> 13 | B21: CARRIER ROUTE | C21: ='[5]10.1.2'!D22 -> 184.01704 | D21: ='[5]10.1.2'!E22 -> 157048.94 | E21: ='[5]10.1.2'!F22 -> 0 | F21: ='[5]10.1.2'!G22 -> 0 | G21: ='[5]10.1.2'!H22 -> 0 | H21: ='[5]10.1.2'!I22 -> 1680.8907 | I21: ='[5]10.1.2'!K22 -> 107.20299 | J21: ='[5]10.1.2'!L22 -> 0 | K21: ='[5]10.1.2'!M22 -> 0 | L21: ='[5]10.1.2'!N22 -> 0 | M21: ='[5]10.1.2'!S22 -> 852.95248 | N21: ='[5]10.1.2'!T22 -> 332.58017 | O21: =SUM(C21:J21)+SUM(M21:N21) -> 160206.59 | P21: =SUM(C21:N21) -> 160206.59
A22: =A21+1 -> 14 | B22: LETTERS | C22: ='[5]10.1.2'!D23 -> 172873.07 | D22: ='[5]10.1.2'!E23 -> 2512.2066 | E22: ='[5]10.1.2'!F23 -> 0 | F22: ='[5]10.1.2'!G23 -> 173.68427 | G22: ='[5]10.1.2'!H23 -> 0 | H22: ='[5]10.1.2'!I23 -> 398.74105 | I22: ='[5]10.1.2'!K23 -> 417010.15 | J22: ='[5]10.1.2'!L23 -> 4.6170293 | K22: ='[5]10.1.2'!M23 -> 0 | L22: ='[5]10.1.2'!N23 -> 0 | M22: ='[5]10.1.2'!S23 -> 11778.847 | N22: ='[5]10.1.2'!T23 -> 1254.9973 | O22: =SUM(C22:J22)+SUM(M22:N22) -> 606006.31 | P22: =SUM(C22:N22) -> 606006.31
