Workbook

Sheet NOTES
A1: =[1]Inputs!$C$4 -> Unit Delivery Cost Model - 12/16/2025
A2: UDCMODEL DOCUMENTATION PAGE
A4: Worksheet | B4: USPS-FY25-19 Synopsis
A5: 1.Table1 | B5: Summary of FY25 unit delivery costs
A6: 1a. Dadjustment | B6: Shifts delivery costs from ECR HD & Saturation Letters to ECR HD & Saturation Flats as in the D Report of Cost Segments and Components
A7: 3.SummaryBY | B7: Calculates FY25 unit delivery costs for First Class, Periodicals, Marketing Mail, and Package Services (BPM and Media Mail).
A8: 4.RuralCost | B8: Rural costs and unit costs by evaluation category for First Class, Periodicals, Marketing Mail, and Package Services.
A9: 5.RuralCrosswalk | B9: First Class, Periodicals, Marketing Mail, and Package Services (BPM and Media Mail) by shape. Cost and volumes for boxholders are distributed to shape and parcels and flat costs and volumes are adjusted for any parcels crosswalked to flats. Calculates total cost and volume by shape after all crosswalks.
A10: 6.DeliveryVols | B10: City and rural volumes by shape and mail class after all volume crosswalks.
A11: 7.RuralDisagg | B11: Disaggregates Permit volumes into DPS, sector segment, and Other, for First Class and Marketing Mail presort categories, and then calculates corresponding rural volumes.
A12: 8.CityCosts | B12: City costs for letter routes and rural by shape and mail class / rate category
A13: 9.ByShape | B13: FY25 IOCS in-office casing and non-casing costs by shape and mail class / rate category.
A14: 10.In-OfficeDetail | B14: Calculates FY25 in-office casing costs for FIrst Class auto and non-auto presort, and Marketing Mail machinable and non-machinable.

Sheet Changes
A1: None
A3: December 2019 Changes
A4: 1.Table 1 | B4: Media mail renamed Media/Library Mail
A5: 3.SummaryBY | B5: Sunday/Holiday costs from new 7.0.6.6 sheet on UDCInputs19.xlsx added to 7.2 Delivery Costs for BPM Parcels, Media/Library Mail, and Marketing Parcels.
B6: Media mail renamed Media/Library Mail
A7: 7.RuralDisagg | B7: FSS column added for Presort Cards
A8: 8.CityCosts | B8: Sunday/Holiday Delivery costs added, and added to subtotals for Special Purpose Route Street Costs where necessary.
A10: 2020 Changes for RM2019-6 Proposal One, SPR
A11: 2.FCSP_Let_Col_Cost_By_Indicia | B11: Remove SPR Delivery Activities Support
A12: 3.SummaryBY | B12: SPR In-Office Support removed from formulas.
A13: 8.CityCosts | B13: Changed formulas to link to new SPR columns in CS06&7. Removed SPR Delivery Activities Support and In-Office formulas.
A15: 2021 Changes for RM2021-7, SPR Peak and Non-Peak
A16: 8.CityCosts | B16: Changed formulas to link to new SPR Delivery columns in UDCInputs sheet 7.0.6. Changed check formulas pointing to CS06&7.
A18: 2024 Changes for RM2021-7, SPR Peak and Non-Peak
A20: 2024 Changes for RRECS (RM2024-2, Order 7919)
A21: 6.DeliveryVols | B21: Updated references to UDCInputs RuralVols tab
A22: 4.Rural cost | B22: Updated references to UDCInputs RuralVols and RuralCosts tabs, including removal of old costpools and addition of new ones consistent with RRECS
A23: 5.RuralCrosswalk | B23: Updated references to 4.Rural cost tab and UDCInputs RCSECRVols, BoxholderbyShape, RCSDALs and PeriodicalsVolAdj tabs, including removal of old costpools and addition of new ones consistent with RRECS
A25: 2024 Changes for Top Down (RM2022-3)
A26: 10.In-Office Detail | B26: Updated references to UDCInputs 7.0.8 tab
A27: 6.DeliveryVols | B27: Updated references to UDCInputs 7.0.8 tab
A28: 8.CityCosts | B28: Removed sections on Letter Routes - Deviation Delivery Accountables, Letter Route Delivery Activities Support Costs and Total Letter-Route Delivery Activity Support Costs as no longer relevant
A29: 8.CityCosts | B29: Updated references to UDC Inputs and CS06&7
A30: 2.FCSP_Let_Col_Cost_By_Indicia | B30: Removed Delivery Activities Support as no longer relevant
A31: 3.SummaryBY | B31: Removed Delivery Activities Support as no longer relevant
A32: 1a.DAdjustment | B32: Removed Delivery Activities Support as no longer relevant
A33: 7.RuralDisagg | B33: Removed costpools no longer relevant
A35: 2024 Changes Additional
A36: 4.Rural cost | B36: Removed FSS
A37: 5.RuralCrosswalk | B37: Removed FSS
A38: 7.RuralDisagg | B38: Removed FSS
A39: 6.DeliveryVols | B39: Updated formulas to reflect no FSS
A41: 2024 Corrections
A42: 4.Rural cost | B42: Added calculation of Total Parcels
A43: 5.RuralCrosswalk | B43: Corrected calculation of parcel costs in columns (30), (39), (41). Under RRECS (RM2024-3), there are three parcel cost pools, and cost per piece for parcels varies by product. Calculations multiply parcel pieces by average unit cost by product.

Sheet 1.Table 1
A1: =[1]Inputs!$C$4 -> Unit Delivery Cost Model - 12/16/2025
A3: Table 1: Fiscal Year 2025 Unit Delivery Costs
A5: Mail Class | C5: FY25 Unit Costs
A6: First-Class Single Piece
A7: Single-Piece Letters | C7: ='3.SummaryBY'!R10*100 -> 8.407902
A8: Single-Piece Stamped Letters | C8: ='3.SummaryBY'!R11*100 -> 7.2179001
A9: Single-Piece Metered Letters | C9: ='3.SummaryBY'!R12*100 -> 10.066519
A10: Single-Piece Other Letters | C10: ='3.SummaryBY'!R13*100 -> 14.93384
A11: Single-Piece Flats | C11: ='3.SummaryBY'!R14*100 -> 31.450286
A13: First-Class Presort
A14: Nonautomation -- Nonmach Mixed ADC | C14: ='3.SummaryBY'!R18*100 -> 28.420198
A15: Nonautomation -- Nonmach ADC | C15: ='3.SummaryBY'!R19*100 -> 0
A16: Nonautomation -- Mach Mixed AADC | C16: ='3.SummaryBY'!R20*100 -> 7.2605039
A17: Nonautomation -- Mach AADC | C17: ='3.SummaryBY'!R21*100 -> 6.0594173
A18: Nonautomation -- Nonmach 3-Digit | C18: ='3.SummaryBY'!R22*100 -> 28.420198
A19: Nonautomation -- Nonmach 5-Digit | C19: ='3.SummaryBY'!R23*100 -> 28.420198
A20: Nonautomation -- Mach 3-Digit | C20: ='3.SummaryBY'!R24*100 -> 0
A21: Nonautomation -- Mach 5-Digit | C21: ='3.SummaryBY'!R25*100 -> 0
A22: Automation Mixed AADC | C22: ='3.SummaryBY'!R26*100 -> 6.9939801
A23: Automation AADC | C23: ='3.SummaryBY'!R27*100 -> 6.2344184
A24: Auto 3-Digit Letters | C24: ='3.SummaryBY'!R28*100 -> 0
A25: Auto 5-Digit Letters CSBCS/Manual Sites | C25: ='3.SummaryBY'!R29*100 -> 28.420198
... A29: Presort Flats | C29: ='3.SummaryBY'!R33*100 -> 29.912119
A31: First-Class Cards
A32: Single Piece Cards | C32: ='3.SummaryBY'!R36*100 -> 10.760351
A33: FC Nonautomation Cards | C33: ='3.SummaryBY'!R39*100 -> 6.4762572
A34: Auto Mixed AADC Cards | C34: ='3.SummaryBY'!R40*100 -> 6.2643686
A35: Auto AADC Cards | C35: ='3.SummaryBY'!R41*100 -> 5.6605107
A36: Auto 3-Digit Cards
A37: Auto 5-Digit Cards | C37: ='3.SummaryBY'!R43*100 -> 4.7480641
A38: Auto 5-Digit Cards CSBCS/Manual Sites | C38: ='3.SummaryBY'!R44*100 -> 23.29839
A39: Auto 5-Digit Cards Other Sites | C39: ='3.SummaryBY'!R45*100 -> 4.0719443
A40: Presort Cards (Avg) | C40: ='3.SummaryBY'!R46*100 -> 5.2416452
A42: Periodicals
A43: Letters | C43: ='3.SummaryBY'!R50*100 -> 12.77482
A44: Flats | C44: ='3.SummaryBY'!R51*100 -> 20.8381
A45: Parcels | C45: ='3.SummaryBY'!R52*100 -> 47.807518
A47: Package Services - Bound Printed Matter
A48: Flats | C48: ='3.SummaryBY'!R56*100 -> 20.101117
A49: Parcels | C49: ='3.SummaryBY'!R57*100 -> 86.722944
...

Sheet 1a.DAdjustment
A1: =[1]Inputs!$C$4 -> Unit Delivery Cost Model - 12/16/2025
A2: Adjustment of ECR High Density and Saturation Letter and Flat Costs
B5: Class, Shape, or Rate Category | C5: Calculatons | D5: 6.1 In-Office Direct Labor, Casing [2] | E5: 6.1 In-Office Direct Labor, Non-Casing | F5: 6.2 In-Office Overhead, & Support Burdened on Office | G5: 7.2 Delivery Activities [3] | H5: 6.2 In-Office Support Burdened on Street | I5: 10 Rural Carriers [5] | J5: Permit Volume | K5: City Carrier In-Office Unit Cost | L5: City Carrier Street Unit Cost | M5: City Carrier Total Unit Cost | N5: Rural Carrier Total Unit Cost | O5: City Plus Rural Unit Cost
B6: Col. No. | D6: -1 | E6: =D6-1 -> -2 | F6: =E6-1 -> -3 | G6: =F6-1 -> -4 | H6: =G6-1 -> -5 | I6: =H6-1 -> -6 | J6: =I6-1 -> -7 | K6: =J6-1 -> -8 | L6: =K6-1 -> -9 | ... O6: =N6-1 -> -12
B7: Units | D7: $(000) | E7: $(000) | F7: $(000) | G7: $(000) | H7: $(000) | I7: $(000) | J7: Pieces (000)
B8: Source/Calculations | D8: =NOTES!A7&" C"&-'3.SummaryBY'!E6 -> 3.SummaryBY C3 | E8: =NOTES!A7&" C"&-'3.SummaryBY'!F6 -> 3.SummaryBY C4 | F8: =NOTES!A7&" C"&-'3.SummaryBY'!G6 -> 3.SummaryBY C5 | G8: =NOTES!A7&" C"&-'3.SummaryBY'!H6 -> 3.SummaryBY C6 | H8: =NOTES!A7&" C"&-'3.SummaryBY'!I6 -> 3.SummaryBY C7 | I8: =NOTES!A7&" C"&-'3.SummaryBY'!J6 -> 3.SummaryBY C8 | J8: =NOTES!A7&" C"&-'3.SummaryBY'!L6 -> 3.SummaryBY C10 | K8: =NOTES!A7&" C"&-'3.SummaryBY'!N6&"" -> 3.SummaryBY C12 | L8: =NOTES!A7&" C"&-'3.SummaryBY'!O6&"" -> 3.SummaryBY C13 | M8: =NOTES!A7&" C"&-'3.SummaryBY'!P6&"" -> 3.SummaryBY C14 | N8: =NOTES!A7&" C"&-'3.SummaryBY'!Q6&"" -> 3.SummaryBY C15 | O8: =NOTES!A7&" C"&-'3.SummaryBY'!R6&"" -> 3.SummaryBY C16
A9: 1 | B9: Unadjusted Costs
A10: =A9+1 -> 2 | B10: ECR High Density Letters | D10: ='3.SummaryBY'!E84 -> 25524.363 | E10: ='3.SummaryBY'!F84 -> 8302.6931 | F10: ='3.SummaryBY'!G84 -> 5898.3898 | G10: ='3.SummaryBY'!H84 -> 49231.68 | H10: ='3.SummaryBY'!I84 -> 1697.9577 | I10: ='3.SummaryBY'!J84 -> 73259.33 | J10: ='3.SummaryBY'!L84 -> 3430799.2 | K10: ='3.SummaryBY'!N84 -> 0.015400573 | L10: ='3.SummaryBY'!O84 -> 0.018303568 | M10: ='3.SummaryBY'!P84 -> 0.033704142 | N10: ='3.SummaryBY'!Q84 -> 0.025788678 | O10: ='3.SummaryBY'!R84 -> 0.05949282
A11: =A10+1 -> 3 | B11: ECR Saturation Letters | D11: ='3.SummaryBY'!E85 -> 16794.799 | E11: ='3.SummaryBY'!F85 -> 4577.5078 | F11: ='3.SummaryBY'!G85 -> 3726.6678 | G11: ='3.SummaryBY'!H85 -> 45607.5 | H11: ='3.SummaryBY'!I85 -> 1451.8367 | I11: ='3.SummaryBY'!J85 -> 56686.308 | J11: ='3.SummaryBY'!L85 -> 2586614.3 | K11: ='3.SummaryBY'!N85 -> 0.0130928 | L11: ='3.SummaryBY'!O85 -> 0.02249008 | M11: ='3.SummaryBY'!P85 -> 0.035582881 | N11: ='3.SummaryBY'!Q85 -> 0.026467196 | O11: ='3.SummaryBY'!R85 -> 0.062050077
A12: =A11+1 -> 4 | B12: ECR High Density Flats | D12: ='3.SummaryBY'!E88 -> 39792.276 | E12: ='3.SummaryBY'!F88 -> 5622.2775 | F12: ='3.SummaryBY'!G88 -> 7919.1477 | G12: ='3.SummaryBY'!H88 -> 13922.726 | H12: ='3.SummaryBY'!I88 -> 614.62965 | I12: ='3.SummaryBY'!J88 -> 71941.295 | J12: ='3.SummaryBY'!L88 -> 1307868.7 | K12: ='3.SummaryBY'!N88 -> 0.053079801 | L12: ='3.SummaryBY'!O88 -> 0.01369858 | M12: ='3.SummaryBY'!P88 -> 0.066778381 | N12: ='3.SummaryBY'!Q88 -> 0.06643173 | O12: ='3.SummaryBY'!R88 -> 0.13321011
A13: =A12+1 -> 5 | B13: ECR High Density Flats (No DAL Costs)1 | D13: ='3.SummaryBY'!E118 -> 39792.276 | E13: ='3.SummaryBY'!F118 -> 5622.2775 | F13: ='3.SummaryBY'!G118 -> 7919.1477 | G13: ='3.SummaryBY'!H118 -> 13890.69 | H13: ='3.SummaryBY'!I118 -> 613.52479 | I13: ='3.SummaryBY'!J118 -> 71608.828 | J13: ='3.SummaryBY'!L118 -> 1307868.7 | K13: ='3.SummaryBY'!N118 -> 0.053078714 | L13: ='3.SummaryBY'!O118 -> 0.01366706 | M13: ='3.SummaryBY'!P118 -> 0.066745774 | N13: ='3.SummaryBY'!Q118 -> 0.066124725 | O13: ='3.SummaryBY'!R118 -> 0.1328705
A14: =A13+1 -> 6 | B14: ECR Saturation Flats | D14: ='3.SummaryBY'!E89 -> 21534.623 | E14: ='3.SummaryBY'!F89 -> 3527.1517 | F14: ='3.SummaryBY'!G89 -> 4370.1386 | G14: ='3.SummaryBY'!H89 -> 178981.26 | H14: ='3.SummaryBY'!I89 -> 5792.0885 | I14: ='3.SummaryBY'!J89 -> 146692.44 | J14: ='3.SummaryBY'!L89 -> 6561008.2 | K14: ='3.SummaryBY'!N89 -> 0.0069084962 | L14: ='3.SummaryBY'!O89 -> 0.03510366 | M14: ='3.SummaryBY'!P89 -> 0.042012156 | N14: ='3.SummaryBY'!Q89 -> 0.027002165 | O14: ='3.SummaryBY'!R89 -> 0.069014321
A15: =A14+1 -> 7 | B15: ECR Saturation Flats (No DAL Costs)1 | D15: ='3.SummaryBY'!E111 -> 21370.171 | E15: ='3.SummaryBY'!F111 -> 3508.8054 | F15: ='3.SummaryBY'!G111 -> 4338.2632 | G15: ='3.SummaryBY'!H111 -> 176257.31 | H15: ='3.SummaryBY'!I111 -> 5705.3761 | I15: ='3.SummaryBY'!J111 -> 143097.5 | J15: ='3.SummaryBY'!L111 -> 6561008.2 | K15: ='3.SummaryBY'!N111 -> 0.0068493853 | L15: ='3.SummaryBY'!O111 -> 0.03456941 | M15: ='3.SummaryBY'!P111 -> 0.041418795 | N15: ='3.SummaryBY'!Q111 -> 0.026340433 | O15: ='3.SummaryBY'!R111 -> 0.067759228
A16: =A15+1 -> 8 | B16: Adjusted Costs
A17: =A16+1 -> 9 | B17: ECR High Density Letters | C17: ="L"&A10&" x [UDCInputs.xls] " &[1]NOTES!$A$5&" L"&[1]Inputs!A8 -> L2 x [UDCInputs.xls] Inputs L3 | D17: =D10*(1-[1]Inputs!$C$8) -> 25445.097 | E17: =E10*(1-[1]Inputs!$C$8) -> 8276.9091 | F17: =F10*(1-[1]Inputs!$C$8) -> 5880.0723 | G17: =G10*(1-[1]Inputs!$C$8) -> 49078.79 | H17: =H10*(1-[1]Inputs!$C$8) -> 1692.6846 | I17: =I10*(1-[1]Inputs!$C$8) -> 73031.823 | J17: =J10 -> 3430799.2 | K17: =SUM(D17:F17,H17)*[1]BYPBack!$D$17/J17 -> 0.015352747 | L17: =SUM(G17:G17)*[1]BYPBack!$D$17/J17 -> 0.018246727 | M17: =SUM(D17:H17)*[1]BYPBack!$D$17/J17 -> 0.033599473 | N17: =I17*[1]BYPBack!$E$17/J17 -> 0.025708591 | O17: =M17+N17 -> 0.059308065
A18: =A17+1 -> 10 | B18: ECR Saturation Letters | C18: ="L"&A11&" x [UDCInputs.xls] " &[1]NOTES!$A$5&" L"&[1]Inputs!A9 -> L3 x [UDCInputs.xls] Inputs L4 | D18: =D11*(1-[1]Inputs!$C$9) -> 15665.896 | E18: =E11*(1-[1]Inputs!$C$9) -> 4269.8195 | F18: =F11*(1-[1]Inputs!$C$9) -> 3476.1707 | G18: =G11*(1-[1]Inputs!$C$9) -> 42541.881 | H18: =H11*(1-[1]Inputs!$C$9) -> 1354.248 | I18: =I11*(1-[1]Inputs!$C$9) -> 52876 | J18: =J11 -> 2586614.3 | K18: =SUM(D18:F18,H18)*[1]BYPBack!$D$17/J18 -> 0.012212736 | L18: =SUM(G18:G18)*[1]BYPBack!$D$17/J18 -> 0.020978355 | M18: =SUM(D18:H18)*[1]BYPBack!$D$17/J18 -> 0.033191091 | N18: =I18*[1]BYPBack!$E$17/J18 -> 0.024688139 | O18: =M18+N18 -> 0.05787923
A19: =A18+1 -> 11 | B19: ECR High Density Flats | C19: ="L"&A12&" +(L"&A10&" - L"&A17&")" -> L4 +(L2 - L9) | D19: =D12+(D10-D17) -> 39871.542 | E19: =E12+(E10-E17) -> 5648.0615 | F19: =F12+(F10-F17) -> 7937.4651 | G19: =G12+(G10-G17) -> 14075.615 | H19: =H12+(H10-H17) -> 619.90267 | I19: =I12+(I10-I17) -> 72168.803 | J19: =J12 -> 1307868.7 | K19: =SUM(D19:F19,H19)*[1]BYPBack!$D$18/J19 -> 0.053206371 | L19: =SUM(G19:G19)*[1]BYPBack!$D$18/J19 -> 0.013849007 | M19: =SUM(D19:H19)*[1]BYPBack!$D$18/J19 -> 0.067055378 | N19: =I19*[1]BYPBack!$E$18/J19 -> 0.066641814 | O19: =M19+N19 -> 0.13369719
A20: =A19+1 -> 12 | B20: ECR High Density Flats (No DAL Costs)1 | C20: ="L"&A13&" +(L"&A10&" - L"&A17&")" -> L5 +(L2 - L9) | D20: =D13+(D10-D17) -> 39871.542 | E20: =E13+(E10-E17) -> 5648.0615 | F20: =F13+(F10-F17) -> 7937.4651 | G20: =G13+(G10-G17) -> 14043.58 | H20: =H13+(H10-H17) -> 618.79781 | I20: =I13+(I10-I17) -> 71836.335 | J20: =J13 -> 1307868.7 | K20: =SUM(D20:F20,H20)*[1]BYPBack!$D$18/J20 -> 0.053205284 | L20: =SUM(G20:G20)*[1]BYPBack!$D$18/J20 -> 0.013817488 | M20: =SUM(D20:H20)*[1]BYPBack!$D$18/J20 -> 0.067022772 | N20: =I20*[1]BYPBack!$E$18/J20 -> 0.066334808 | O20: =M20+N20 -> 0.13335758
A21: =A20+1 -> 13 | B21: ECR Saturation Flats | C21: ="L"&A14&" +(L"&A11&" - L"&A18&")" -> L6 +(L3 - L10) | D21: =D14+(D11-D18) -> 22663.526 | E21: =E14+(E11-E18) -> 3834.84 | F21: =F14+(F11-F18) -> 4620.6356 | G21: =G14+(G11-G18) -> 182046.88 | H21: =H14+(H11-H18) -> 5889.6772 | I21: =I14+(I11-I18) -> 150502.74 | J21: =J14 -> 6561008.2 | K21: =SUM(D21:F21,H21)*[1]BYPBack!$D$18/J21 -> 0.0072585256 | L21: =SUM(G21:G21)*[1]BYPBack!$D$18/J21 -> 0.035704921 | M21: =SUM(D21:H21)*[1]BYPBack!$D$18/J21 -> 0.042963446 | N21: =I21*[1]BYPBack!$E$18/J21 -> 0.027703541 | O21: =M21+N21 -> 0.070666987
A22: =A21+1 -> 14 | B22: ECR Saturation Flats (No DAL Costs)1 | C22: ="L"&A15&" +(L"&A11&" - L"&A18&")" -> L7 +(L3 - L10) | D22: =D15+(D11-D18) -> 22499.074 | E22: =E15+(E11-E18) -> 3816.4938 | F22: =F15+(F11-F18) -> 4588.7603 | G22: =G15+(G11-G18) -> 179322.93 | H22: =H15+(H11-H18) -> 5802.9649 | I22: =I15+(I11-I18) -> 146907.81 | J22: =J15 -> 6561008.2 | K22: =SUM(D22:F22,H22)*[1]BYPBack!$D$18/J22 -> 0.0071994147 | L22: =SUM(G22:G22)*[1]BYPBack!$D$18/J22 -> 0.035170671 | M22: =SUM(D22:H22)*[1]BYPBack!$D$18/J22 -> 0.042370086 | N22: =I22*[1]BYPBack!$E$18/J22 -> 0.02704181 | O22: =M22+N22 -> 0.069411895
A24: Table 1a: Schedule D Adjustment of ECR High Density and Saturation Letter and Flat Unit Costs
B26: USPS Marketing Mail ECR - | C26: FY25 Unit Costs
B27: ECR High Density Letters | C27: =O17*100 -> 5.9308065
B28: ECR Saturation Letters | C28: =O18*100 -> 5.787923
B29: ECR High Density Flats | C29: =O19*100 -> 13.369719
B30: ECR High Density Flats (No DAL Costs)1 | C30: =O20*100 -> 13.335758
B31: ECR Saturation Flats | C31: =O21*100 -> 7.0666987
B32: ECR Saturation Flats (No DAL Costs)1 | C32: =O22*100 -> 6.9411895
A34: Notes
A35: 1This label was previously Attached Label implying those with pieces with addresses affixed.
A36: However, this cost is the unit cost of the addressed and unaddressed flat pieces. DAL costs
A37: are not included

Sheet 2.FCSP_Let_Col_Cost_By_Indicia
A1: =[1]Inputs!$C$4 -> Unit Delivery Cost Model - 12/16/2025
A2: FIRST-CLASS SINGLE PIECE COLLECTION COSTS BY INDICIA
A5: Line No. | B5: Class, Shape, or Rate Category | C5: 6.1 In-Office Direct Labor, Casing [2] | D5: 6.1 In-Office Direct Labor, Non-Casing | E5: 6.2 In-Office Overhead, & Support Burdened on Office | F5: 7.1 Delivery Activities [3] | G5: 6.2 In-Office Support Burdened on Street | H5: 10 Rural Carriers [5] | I5: Total | J5: Permit Volume | L5: City Carrier In-Office Unit Cost | M5: City Carrier Street Unit Cost | N5: City Carrier Total Unit Cost | O5: Rural Carrier Total Unit Cost | P5: City Plus Rural Unit Cost
B6: Col. No. | C6: -1 | D6: =C6-1 -> -2 | E6: =D6-1 -> -3 | F6: =E6-1 -> -4 | G6: =F6-1 -> -5 | H6: =G6-1 -> -6 | I6: =H6-1 -> -7 | J6: =I6-1 -> -8 | L6: =J6-1 -> -9 | M6: =L6-1 -> -10 | N6: =M6-1 -> -11 | O6: =N6-1 -> -12 | P6: =O6-1 -> -13
B7: Units | C7: $(000) | D7: $(000) | E7: $(000) | F7: $(000) | G7: $(000) | H7: $(000) | I7: $(000) | J7: $(000) | L7: $(000) | M7: $(000) | N7: $(000) | O7: $(000) | P7: $(000)
A8: 1 | B8: First Class Single Piece
A9: =A8+1 -> 2 | B9: Single-Piece Letters | C9: ='3.SummaryBY'!E$10 -> 128202.82 | D9: ='3.SummaryBY'!F$10 -> 38581.942 | E9: ='3.SummaryBY'!G$10 -> 29074.787 | F9: ='3.SummaryBY'!H$10 -> 280684.85 | G9: ='3.SummaryBY'!I$10 -> 7985.5832 | H9: ='3.SummaryBY'!J$10 -> 140775.7 | I9: =SUM(C9:G9)*[1]BYPBack!$D$11+H9*[1]BYPBack!$E$11 -> 788030.23 | J9: ='3.SummaryBY'!L$10 -> 9372495.3 | L9: =SUM($C9:$E9, G9)*[1]BYPBack!$D$11/J9 -> 0.027741064 | M9: =SUM($F9:$F9)*[1]BYPBack!$D$11/J9 -> 0.038198097 | N9: =SUM($C9:$G9)*[1]BYPBack!$D$11/J9 -> 0.065939161 | O9: =H9*[1]BYPBack!$E$11/J9 -> 0.018139859 | P9: =I9/J9 -> 0.08407902
A10: 3 | B10: Single-Piece Letters Collection | C10: 0 | D10: =D13+D14 -> 1230.921 | E10: =(C10+D10)/(C9+D9)*E9 -> 214.58055 | F10: ='8.CityCosts'!$C$29+'8.CityCosts'!M11 -> 165899.21 | G10: =('8.CityCosts'!$C$29/'8.CityCosts'!$C$83*'8.CityCosts'!$C$102) -> 4186.4735 | H10: ='5.RuralCrosswalk'!$X$39 -> 7699.2631 | I10: =SUM(C10:G10)*[1]BYPBack!$D$11+H10*[1]BYPBack!$E$11 -> 228085.23 | J10: =J9 -> 9372495.3 | L10: =SUM($C10:$E10, G10)*[1]BYPBack!$D$11/J10 -> 0.00076644939 | M10: =SUM($F10:$F10)*[1]BYPBack!$D$11/J10 -> 0.022577043 | N10: =SUM($C10:$G10)*[1]BYPBack!$D$11/J10 -> 0.023343493 | O10: =H10*[1]BYPBack!$E$11/J10 -> 0.00099209982 | P10: =I10/J10 -> 0.024335593
A11: 4 | B11: Single-Piece Letters Delivery | C11: =C9-C10 -> 128202.82 | D11: =D9-D10 -> 37351.021 | E11: =E9-E10 -> 28860.206 | F11: =F9-F10 -> 114785.64 | G11: =G9-G10 -> 3799.1097 | H11: =H9-H10 -> 133076.44 | I11: =SUM(C11:G11)*[1]BYPBack!$D$11+H11*[1]BYPBack!$E$11 -> 559945 | J11: =J9 -> 9372495.3 | L11: =SUM($C11:$E11, G11)*[1]BYPBack!$D$11/J11 -> 0.026974614 | M11: =SUM($F11:$F11)*[1]BYPBack!$D$11/J11 -> 0.015621054 | N11: =SUM($C11:$G11)*[1]BYPBack!$D$11/J11 -> 0.042595668 | O11: =H11*[1]BYPBack!$E$11/J11 -> 0.01714776 | P11: =I11/J11 -> 0.059743428
A13: 5 | B13: Single-Piece Letters Stamped | D13: =[1]FCByIndicia!$C$10/1000 -> 0 | E13: =D13/D10*E10 -> 0 | F13: =F$10*$J13/$J$10 -> 96863.451 | G13: =G$10*$J13/$J$10 -> 2444.3533 | H13: =H$10*$J13/$J$10 -> 4495.3632 | I13: =SUM(C13:G13)*[1]BYPBack!$D$11+H13*[1]BYPBack!$E$11 -> 132095.46 | J13: =J11-SUM(J14:J15) -> 5472312.1 | L13: =SUM($C13:$E13, G13)*[1]BYPBack!$D$11/J13 -> 0.00056973265 | M13: =SUM($F13:$F13)*[1]BYPBack!$D$11/J13 -> 0.022577043 | N13: =SUM($C13:$G13)*[1]BYPBack!$D$11/J13 -> 0.023146776 | O13: =H13*[1]BYPBack!$E$11/J13 -> 0.00099209982 | P13: =I13/J13 -> 0.024138876
A14: 6 | B14: Single-Piece Letters Metered | D14: =[1]FCByIndicia!$C$11/1000 -> 1230.921 | E14: =D14/D10*E10 -> 214.58055 | F14: =F$10*$J14/$J$10 -> 68878.864 | G14: =G$10*$J14/$J$10 -> 1738.161 | H14: =H$10*$J14/$J$10 -> 3196.6186 | I14: =SUM(C14:G14)*[1]BYPBack!$D$11+H14*[1]BYPBack!$E$11 -> 95775.807 | J14: =[1]FCByIndicia!$F$11 -> 3891319.6 | L14: =SUM($C14:$E14, G14)*[1]BYPBack!$D$11/J14 -> 0.0010435377 | M14: =SUM($F14:$F14)*[1]BYPBack!$D$11/J14 -> 0.022577043 | N14: =SUM($C14:$G14)*[1]BYPBack!$D$11/J14 -> 0.023620581 | O14: =H14*[1]BYPBack!$E$11/J14 -> 0.00099209982 | P14: =I14/J14 -> 0.024612681
A15: 7 | B15: Single-Piece Letters Other | F15: =F$10*$J15/$J$10 -> 156.89189 | G15: =G$10*$J15/$J$10 -> 3.9591734 | H15: =H$10*$J15/$J$10 -> 7.2812398 | I15: =SUM(C15:G15)*[1]BYPBack!$D$11+H15*[1]BYPBack!$E$11 -> 213.95796 | J15: =[1]FCByIndicia!$F$12 -> 8863.6257 | L15: =SUM($C15:$E15, G15)*[1]BYPBack!$D$11/J15 -> 0.00056973265 | M15: =SUM($F15:$F15)*[1]BYPBack!$D$11/J15 -> 0.022577043 | N15: =SUM($C15:$G15)*[1]BYPBack!$D$11/J15 -> 0.023146776 | O15: =H15*[1]BYPBack!$E$11/J15 -> 0.00099209982 | P15: =I15/J15 -> 0.024138876
A18: Source for C/S 6 Collection: IOCS | B18: Q16F05 = 'Y' | C18: Handling Collection Mail | L18: FC SP Metered Collection * 0.6 (Per Order 1320) | P18: =P14*0.6 -> 0.014767609
B19: Q16B01C = 'B' | C19: On Collection Route
B20: Q16E01 = 'C' | C20: AMS Route Number = Collection Route
A22: *Categories
A23: Stamped:
A24: Stamped
A25: PVI
A26: Metered:
A27: Metered
A28: IBI
A29: Permit imprint
A30: Other:
A31: Other

Sheet 3.SummaryBY
A1: =[1]Inputs!$C$4 -> Unit Delivery Cost Model - 12/16/2025
A2: DEVELOPMENT OF UNIT DELIVERY COSTS
A3: =[1]Inputs!$C$6 -> FY 2025
A5: Line No. | B5: Class, Shape, or Rate Category | C5: %DPS | D5: 6.1 Unit Cost [1] | E5: 6.1 In-Office Direct Labor, Casing [2] | F5: 6.1 In-Office Direct Labor, Non-Casing | G5: 6.2 In-Office Overhead, & Support Burdened on Office | H5: 7.2 Delivery Activities [3] | I5: 6.2 In-Office Support Burdened on Street | J5: 10 Rural Carriers [5] | K5: Total | L5: RPW Volume | M5: RPW Volume Percentages | N5: City Carrier In-Office Unit Cost | O5: City Carrier Street Unit Cost | P5: City Carrier Total Unit Cost | Q5: Rural Carrier Total Unit Cost | R5: City Plus Rural Unit Cost
B6: Col. No. | C6: -1 | D6: =C6-1 -> -2 | E6: =D6-1 -> -3 | F6: =E6-1 -> -4 | G6: =F6-1 -> -5 | H6: =G6-1 -> -6 | I6: =H6-1 -> -7 | J6: =I6-1 -> -8 | K6: =J6-1 -> -9 | ... R6: =Q6-1 -> -16
B7: Units | E7: $(000) | F7: $(000) | G7: $(000) | H7: $(000) | I7: $(000) | J7: $(000) | K7: $(000) | L7: $(000)
B8: FIRST-CLASS SINGLE PIECE Source / Calculations | C8: =NOTES!A14&" C"&-'10.In-Office Detail'!C14 -> 10.In-OfficeDetail C9 | D8: ="L"&$A10&"..L"&$A118&" = (C"&-E6&"+C"&-F6&")/C"&-L6 -> L2..L95 = (C3+C4)/C10 | E8: ="L"&$A10&" ,L"&$A15&" from [UDCInputs.xls] CARMMCasing and FCByIndicia" -> L2 ,L7 from [UDCInputs.xls] CARMMCasing and FCByIndicia | F8: ="L"&$A10&" ,L"&$A15&" from [UDCInputs.xls] CARMMCasing and FCByIndicia" -> L2 ,L7 from [UDCInputs.xls] CARMMCasing and FCByIndicia | G8: ="L"&$A10&" ,L"&$A15&" from [UDCInputs.xls] 7.0.6 and CS6&7 CRA" -> L2 ,L7 from [UDCInputs.xls] 7.0.6 and CS6&7 CRA | H8: ="L"&$A10&" ,L"&$A15&".. from [UDCInputs.xls] 7.0.6" -> L2 ,L7.. from [UDCInputs.xls] 7.0.6 | I8: ="L"&$A10&" ,L"&$A15&".. from [UDCInputs.xls] 7.0.6" -> L2 ,L7.. from [UDCInputs.xls] 7.0.6 | J8: ="L"&$A10&" ,L"&$A15&".. from [UDCInputs.xls] Rural Costs" -> L2 ,L7.. from [UDCInputs.xls] Rural Costs | K8: ="L"&$A10&"..L"&$A118&" = (C"&-E6&"..C"&-I6&" x [UDCInputs.xls] " &[1]NOTES!$A$23&" C"&-[1]BYPBack!$E$7 & ") + (C"&-J6&" x [UDCInputs.xls] " &[1]NOTES!$A$23&" C"&-[1]BYPBack!$F$7&")" -> L2..L95 = (C3..C7 x [UDCInputs.xls] RPWShape C2) + (C8 x [UDCInputs.xls] RPWShape C0) | L8: ="[UDCInputs.xls] RPWShape and FCByIndicia" -> [UDCInputs.xls] RPWShape and FCByIndicia | N8: ="L"&$A10&"..L"&$A118&" = C"&-E6&"..C"&-G6&", C"&-I6&" x [UDCInputs.xls] " &[1]NOTES!$A$23&" C"&-[1]BYPBack!$E$7 -> L2..L95 = C3..C5, C7 x [UDCInputs.xls] RPWShape C2 | O8: ="L"&$A10&"..L"&$A118&" = C"&-H6&"..C"&" x [UDCInputs.xls] " &[1]NOTES!$A$23&" C"&-[1]BYPBack!$E$7 -> L2..L95 = C6..C x [UDCInputs.xls] RPWShape C2 | P8: ="L"&$A10&"..L"&$A118&" = C"&-E6&"..C"&-I6&" x [UDCInputs.xls] " &[1]NOTES!$A$23&" C"&-[1]BYPBack!$E$7 -> L2..L95 = C3..C7 x [UDCInputs.xls] RPWShape C2 | Q8: ="L"&$A10&"..L"&$A118&" = C"&-J6&" x [UDCInputs.xls] " &[1]NOTES!$A$23&" C"&-[1]BYPBack!$F$7 -> L2..L95 = C8 x [UDCInputs.xls] RPWShape C0 | R8: ="C"&-K6&" / C"&-L6 -> C9 / C10
A9: 1 | B9: First Class Single Piece
A10: =A9+1 -> 2 | B10: Single-Piece Letters | D10: =(E10+F10)/L10 -> 0.017795129 | E10: =[1]CARMMCasing!$D$10 -> 128202.82 | F10: =[1]CARMMCasing!$E$10 -> 38581.942 | G10: ='[1]7.0.6'!$I$10+'[1]CS6&7 CRA'!$D$11 -> 29074.787 | H10: ='[1]7.0.6'!$L$10 -> 280684.85 | I10: ='[1]7.0.6'!$J$10 -> 7985.5832 | J10: =[1]RuralCosts!$P$11 -> 140775.7 | K10: =SUM(E10:I10)*[1]BYPBack!$D$11+J10*[1]BYPBack!$E$11 -> 788030.23 | L10: =[1]RPWShape!$C$10 -> 9372495.3 | N10: =SUM($E10:$G10,I10)*[1]BYPBack!$D$11/L10 -> 0.027741064 | O10: =SUM($H10:$H10)*[1]BYPBack!$D$11/L10 -> 0.038198097 | P10: =SUM($E10:$I10)*[1]BYPBack!$D$11/L10 -> 0.065939161 | Q10: =J10*[1]BYPBack!$E$11/L10 -> 0.018139859 | R10: =K10/L10 -> 0.08407902
A11: =A10+1 -> 3 | B11: Stamped | D11: =(E11+F11)/L11 -> 0.01341031 | E11: =[1]FCByIndicia!$E10/1000 -> 57740.257 | F11: =([1]FCByIndicia!$D10-[1]FCByIndicia!$E10)/1000 -> 15645.165 | G11: =$G$10*(E11+F11)/(E$10+F$10) -> 12792.928 | H11: ='2.FCSP_Let_Col_Cost_By_Indicia'!F11*[1]FCByIndicia!$I$10+'2.FCSP_Let_Col_Cost_By_Indicia'!F13 -> 149970.8 | I11: ='2.FCSP_Let_Col_Cost_By_Indicia'!G$11*[1]FCByIndicia!$I10+'2.FCSP_Let_Col_Cost_By_Indicia'!G13 -> 4202.0701 | J11: =J$10*[1]FCByIndicia!$K10 -> 73213.061 | K11: =SUM(E11:I11)*[1]BYPBack!$D$11+J11*[1]BYPBack!$E$11 -> 394986.14 | L11: =[1]FCByIndicia!$F10 -> 5472313.8 | N11: =SUM($E11:$G11,I11)*[1]BYPBack!$D$11/L11 -> 0.021065965 | O11: =SUM($H11:$H11)*[1]BYPBack!$D$11/L11 -> 0.034955355 | P11: =SUM($E11:$I11)*[1]BYPBack!$D$11/L11 -> 0.05602132 | Q11: =J11*[1]BYPBack!$E$11/L11 -> 0.016157681 | R11: =K11/L11 -> 0.072179001
A12: =A11+1 -> 4 | B12: Metered | D12: =(E12+F12)/L12 -> 0.023919684 | E12: =[1]FCByIndicia!$E11/1000 -> 70175.815 | F12: =([1]FCByIndicia!$D11-[1]FCByIndicia!$E11)/1000 -> 22903.32 | G12: =$G$10*(E12+F12)/(E$10+F$10) -> 16226.039 | H12: ='2.FCSP_Let_Col_Cost_By_Indicia'!F$11*[1]FCByIndicia!$I11+'2.FCSP_Let_Col_Cost_By_Indicia'!F14 -> 130321.63 | I12: ='2.FCSP_Let_Col_Cost_By_Indicia'!G$11*[1]FCByIndicia!$I11+'2.FCSP_Let_Col_Cost_By_Indicia'!G14 -> 3771.7587 | J12: =J$10*[1]FCByIndicia!$K11 -> 67290.602 | K12: =SUM(E12:I12)*[1]BYPBack!$D$11+J12*[1]BYPBack!$E$11 -> 391720.41 | L12: =[1]FCByIndicia!$F11 -> 3891319.6 | N12: =SUM($E12:$G12,I12)*[1]BYPBack!$D$11/L12 -> 0.037064241 | O12: =SUM($H12:$H12)*[1]BYPBack!$D$11/L12 -> 0.04271669 | P12: =SUM($E12:$I12)*[1]BYPBack!$D$11/L12 -> 0.079780931 | Q12: =J12*[1]BYPBack!$E$11/L12 -> 0.020884254 | R12: =K12/L12 -> 0.10066519
A13: =A12+1 -> 5 | B13: Other | D13: =(E13+F13)/L13 -> 0.03612583 | E13: =[1]FCByIndicia!$E12/1000 -> 286.74989 | F13: =([1]FCByIndicia!$D12-[1]FCByIndicia!$E12)/1000 -> 33.455951 | G13: =$G$10*(E13+F13)/(E$10+F$10) -> 55.819946 | H13: ='2.FCSP_Let_Col_Cost_By_Indicia'!F$11*[1]FCByIndicia!$I12+'2.FCSP_Let_Col_Cost_By_Indicia'!F15 -> 392.41628 | I13: ='2.FCSP_Let_Col_Cost_By_Indicia'!G$11*[1]FCByIndicia!$I12+'2.FCSP_Let_Col_Cost_By_Indicia'!G15 -> 11.754426 | J13: =J$10*[1]FCByIndicia!$K12 -> 272.04014 | K13: =SUM(E13:I13)*[1]BYPBack!$D$11+J13*[1]BYPBack!$E$11 -> 1323.6796 | L13: =[1]FCByIndicia!$F12 -> 8863.6257 | N13: =SUM($E13:$G13,I13)*[1]BYPBack!$D$11/L13 -> 0.055802317 | O13: =SUM($H13:$H13)*[1]BYPBack!$D$11/L13 -> 0.056469456 | P13: =SUM($E13:$I13)*[1]BYPBack!$D$11/L13 -> 0.11227177 | Q13: =J13*[1]BYPBack!$E$11/L13 -> 0.037066623 | R13: =K13/L13 -> 0.1493384
A14: =A13+1 -> 6 | B14: Single-Piece Flats | D14: =(E14+F14)/L14 -> 0.15657893 | E14: =[1]CARMMCasing!$D$14 -> 50210.998 | F14: =[1]CARMMCasing!$E$14 -> 13557.658 | G14: ='[1]7.0.6'!$I$14+'[1]CS6&7 CRA'!$D$15 -> 11118.418 | H14: ='[1]7.0.6'!$L$14 -> 11610.129 | I14: ='[1]7.0.6'!$J$14 -> 327.95718 | J14: =[1]RuralCosts!$P15 -> 18222.698 | K14: =SUM(E14:I14)*[1]BYPBack!$D$15+J14*[1]BYPBack!$E$15 -> 128085.08 | L14: =[1]RPWShape!$D$14 -> 407262.06 | N14: =SUM($E14:$G14,I14)*[1]BYPBack!$D$15/L14 -> 0.22563579 | O14: =SUM($H14:$H14)*[1]BYPBack!$D$15/L14 -> 0.034828952 | P14: =SUM($E14:$I14)*[1]BYPBack!$D$15/L14 -> 0.26046475 | Q14: =J14*[1]BYPBack!$E$15/L14 -> 0.054038114 | R14: =K14/L14 -> 0.31450286
A15: =A14+1 -> 7 | B15: First-Class Single-Piece BY* | D15: =(E15+F15)/L15 -> 0.023574554 | E15: =E10+E14 -> 178413.82 | F15: =F10+F14 -> 52139.6 | G15: =G10+G14 -> 40193.205 | H15: =H10+H14 -> 292294.98 | I15: =I10+I14 -> 8313.5404 | J15: =J10+J14 -> 158998.4 | K15: =K10+K14 -> 916115.31 | L15: =L10+L14 -> 9779757.4 | N15: =SUMPRODUCT(N10:N14,$L10:$L14)/SUM($L10:$L14) -> 0.031949183 | O15: =SUMPRODUCT(O10:O14,$L10:$L14)/SUM($L10:$L14) -> 0.038126451 | P15: =SUMPRODUCT(P10:P14,$L10:$L14)/SUM($L10:$L14) -> 0.070075634 | Q15: =SUMPRODUCT(Q10:Q14,$L10:$L14)/SUM($L10:$L14) -> 0.018903214 | R15: =K15/L15 -> 0.093674646
B16: FIRST-CLASS PRESORT Source / Calculations | E16: ="L"&A17&".. L"&A31&" from "&NOTES!A14&" C"&-'10.In-Office Detail'!E14& "; L"&$A32&"..L"&A33&" from [UDCInputs.xls] CARMMCasing" -> L8.. L22 from 10.In-OfficeDetail C11; L23..L24 from [UDCInputs.xls] CARMMCasing | F16: ="L"&A17&".. L"&A31&" from "&NOTES!A14&" C"&-'10.In-Office Detail'!G$14&"; L"&$A32&"..L"&A33&" from [UDCInputs.xls] CARMMCasing" -> L8.. L22 from 10.In-OfficeDetail C13; L23..L24 from [UDCInputs.xls] CARMMCasing | G16: ="L"&A17&"..L"&A31&" = (C"&-E$6&"..C"&-F$6&") / (L"&A32&" C"&-E6&"..C"&-F$6&") x C"&-G$6&"L"&A32& "; L"&$A32&"..L"&A33&" from [UDCInputs.xls] 7.0.6 and CS6&7 CRA" -> L8..L22 = (C3..C4) / (L23 C3..C4) x C5L23; L23..L24 from [UDCInputs.xls] 7.0.6 and CS6&7 CRA | H16: ="L"&A17&"..L"&A31&" = C"&-$L$6&"L{i}/C"&-$L$6&"L"&$A$32&" x C"&-H$6&"L"&$A$32& "; L"&$A$32&"..L"&A33&" from [UDCInputs.xls] 7.0.6" -> L8..L22 = C10L{i}/C10L23 x C6L23; L23..L24 from [UDCInputs.xls] 7.0.6 | I16: ="L"&A17&"..L"&A31&" = C"&-$L6&"L{i}/C"&-$L6&"L"&$A32&" x C"&-I6&"L"&$A32& "; L"&$A32&"..L"&A33&" from [UDCInputs.xls] 7.0.6" -> L8..L22 = C10L{i}/C10L23 x C7L23; L23..L24 from [UDCInputs.xls] 7.0.6 | J16: ="L"&A17&"..L"&A31&" = from "&NOTES!A11&" C"&-'7.RuralDisagg'!O$6&"; L"&A32&"..L"&A33&" from [UDCInputs.xls] Rural Costs" -> L8..L22 = from 7.RuralDisagg C12; L23..L24 from [UDCInputs.xls] Rural Costs | L16: ="L"&A17&"..L"&A31&" = from [UDCInputs.xls] "& [1]NOTES!$A$24&"; L"&A33&" from [UDCInputs.xls] RPWShape" -> L8..L22 = from [UDCInputs.xls] DALs; L24 from [UDCInputs.xls] RPWShape | M16: ="L"&A17&"..L"&A31&" = C"&-L6&"L{i} / C"&-L6&"L"&A32 -> L8..L22 = C10L{i} / C10L23
A17: =A15+1 -> 8 | B17: First Class Presort
A18: =A17+1 -> 9 | B18: Nonautomation -- Nonmach Mixed ADC | C18: ='10.In-Office Detail'!C18 -> 0 | E18: ='10.In-Office Detail'!E18 -> 300.52866 | F18: ='10.In-Office Detail'!G18 -> 5.8717995 | G18: =(SUM(E18:F18)/SUM(E$32:F$32))*G$32 -> 53.414262 | H18: =L18/L$32*H$32 -> 32.386144 | I18: =$L18/$L$32*I$32 -> 1.0756071 | J18: ='7.RuralDisagg'!O10 -> 111.82531 | K18: =SUM(E18:I18)*[1]BYPBack!$D$13+J18*[1]BYPBack!$E$13 -> 632.67681 | L18: ='[1]DPS%'!$E8 -> 2226.152 | M18: ='3.SummaryBY'!L18/'3.SummaryBY'!L$32 -> 7.6422702e-05 | N18: =SUM($E18:$G18,I18)*[1]BYPBack!$D$13/L18 -> 0.20512772 | O18: =SUM($H18:$H18)*[1]BYPBack!$D$13/L18 -> 0.018408073 | P18: =SUM($E18:$I18)*[1]BYPBack!$D$13/L18 -> 0.22353579 | Q18: =R18-P18 -> 0.060666193 | R18: =K18/L18 -> 0.28420198
A19: =A18+1 -> 10 | B19: Nonautomation -- Nonmach ADC | C19: ='10.In-Office Detail'!C19 -> 0 | E19: ='10.In-Office Detail'!E19 -> 0 | F19: ='10.In-Office Detail'!G19 -> 0 | G19: =(SUM(E19:F19)/SUM(E$32:F$32))*G$32 -> 0 | H19: =L19/L$32*H$32 -> 0 | I19: =$L19/$L$32*I$32 -> 0 | J19: ='7.RuralDisagg'!O11 -> 0 | K19: =SUM(E19:I19)*[1]BYPBack!$D$13+J19*[1]BYPBack!$E$13 -> 0 | L19: ='[1]DPS%'!$E9 -> 0 | M19: ='3.SummaryBY'!L19/'3.SummaryBY'!L$32 -> 0 | N19: =IFERROR(SUM($E19:$G19,I19)*[1]BYPBack!$D$13/L19,0) -> 0 | O19: =IFERROR(SUM($H19:$H19)*[1]BYPBack!$D$13/L19,0) -> 0 | P19: =IFERROR(SUM($E19:$I19)*[1]BYPBack!$D$13/L19,0) -> 0 | Q19: =R19-P19 -> 0 | R19: =IFERROR(K19/L19,0) -> 0
A20: =A19+1 -> 11 | B20: Nonautomation -- Mach Mixed AADC | C20: ='10.In-Office Detail'!C20 -> 0.85382551 | E20: ='10.In-Office Detail'!E20 -> 3259.4459 | F20: ='10.In-Office Detail'!G20 -> 435.66986 | G20: =(SUM(E20:F20)/SUM(E$32:F$32))*G$32 -> 644.16313 | H20: =L20/L$32*H$32 -> 2402.9545 | I20: =$L20/$L$32*I$32 -> 79.806811 | J20: ='7.RuralDisagg'!O12 -> 2782.3932 | K20: =SUM(E20:I20)*[1]BYPBack!$D$13+J20*[1]BYPBack!$E$13 -> 11992.449 | L20: ='[1]DPS%'!$E10 -> 165173.78 | M20: ='3.SummaryBY'!L20/'3.SummaryBY'!L$32 -> 0.0056703346 | N20: =SUM($E20:$G20,I20)*[1]BYPBack!$D$13/L20 -> 0.033852849 | O20: =SUM($H20:$H20)*[1]BYPBack!$D$13/L20 -> 0.018408073 | P20: =SUM($E20:$I20)*[1]BYPBack!$D$13/L20 -> 0.052260922 | Q20: =R20-P20 -> 0.020344117 | R20: =K20/L20 -> 0.072605039
A21: =A20+1 -> 12 | B21: Nonautomation -- Mach AADC | C21: ='10.In-Office Detail'!C21 -> 0.90229116 | E21: ='10.In-Office Detail'!E21 -> 4362.1545 | F21: ='10.In-Office Detail'!G21 -> 872.27317 | G21: =(SUM(E21:F21)/SUM(E$32:F$32))*G$32 -> 912.5087 | H21: =L21/L$32*H$32 -> 4811.0574 | I21: =$L21/$L$32*I$32 -> 159.78461 | J21: ='7.RuralDisagg'!O13 -> 4944.015 | K21: =SUM(E21:I21)*[1]BYPBack!$D$13+J21*[1]BYPBack!$E$13 -> 20038.582 | L21: ='[1]DPS%'!$E11 -> 330701.46 | M21: ='3.SummaryBY'!L21/'3.SummaryBY'!L$32 -> 0.011352818 | N21: =SUM($E21:$G21,I21)*[1]BYPBack!$D$13/L21 -> 0.024130783 | O21: =SUM($H21:$H21)*[1]BYPBack!$D$13/L21 -> 0.018408073 | P21: =SUM($E21:$I21)*[1]BYPBack!$D$13/L21 -> 0.042538856 | Q21: =R21-P21 -> 0.018055317 | R21: =K21/L21 -> 0.060594173
A22: =A21+1 -> 13 | B22: Nonautomation -- Nonmach 3-Digit | C22: ='10.In-Office Detail'!C22 -> 0 | E22: ='10.In-Office Detail'!E22 -> 229.60861 | F22: ='10.In-Office Detail'!G22 -> 4.4861468 | G22: =(SUM(E22:F22)/SUM(E$32:F$32))*G$32 -> 40.809333 | H22: =L22/L$32*H$32 -> 24.743521 | I22: =$L22/$L$32*I$32 -> 0.82178066 | J22: ='7.RuralDisagg'!O14 -> 85.436288 | K22: =SUM(E22:I22)*[1]BYPBack!$D$13+J22*[1]BYPBack!$E$13 -> 483.37499 | L22: ='[1]DPS%'!$E12 -> 1700.815 | M22: ='3.SummaryBY'!L22/'3.SummaryBY'!L$32 -> 5.8388141e-05 | N22: =SUM($E22:$G22,I22)*[1]BYPBack!$D$13/L22 -> 0.20512772 | O22: =SUM($H22:$H22)*[1]BYPBack!$D$13/L22 -> 0.018408073 | P22: =SUM($E22:$I22)*[1]BYPBack!$D$13/L22 -> 0.22353579 | Q22: =R22-P22 -> 0.060666193 | R22: =K22/L22 -> 0.28420198
A23: =A22+1 -> 14 | B23: Nonautomation -- Nonmach 5-Digit | C23: ='10.In-Office Detail'!C23 -> 0 | E23: ='10.In-Office Detail'!E23 -> 174.83809 | F23: ='10.In-Office Detail'!G23 -> 3.4160277 | G23: =(SUM(E23:F23)/SUM(E$32:F$32))*G$32 -> 31.074732 | H23: =L23/L$32*H$32 -> 18.841237 | I23: =$L23/$L$32*I$32 -> 0.62575427 | J23: ='7.RuralDisagg'!O15 -> 65.056437 | K23: =SUM(E23:I23)*[1]BYPBack!$D$13+J23*[1]BYPBack!$E$13 -> 368.07141 | L23: ='[1]DPS%'!$E13 -> 1295.105 | M23: ='3.SummaryBY'!L23/'3.SummaryBY'!L$32 -> 4.4460317e-05 | N23: =SUM($E23:$G23,I23)*[1]BYPBack!$D$13/L23 -> 0.20512772 | O23: =SUM($H23:$H23)*[1]BYPBack!$D$13/L23 -> 0.018408073 | P23: =SUM($E23:$I23)*[1]BYPBack!$D$13/L23 -> 0.22353579 | Q23: =R23-P23 -> 0.060666193 | R23: =K23/L23 -> 0.28420198
A24: =A23+1 -> 15 | B24: Nonautomation -- Mach 3-Digit | C24: ='10.In-Office Detail'!C24 -> 0.90229116 | E24: ='10.In-Office Detail'!E24 -> 0 | F24: ='10.In-Office Detail'!G24 -> 0 | G24: =(SUM(E24:F24)/SUM(E$32:F$32))*G$32 -> 0 | H24: =L24/L$32*H$32 -> 0 | I24: =$L24/$L$32*I$32 -> 0 | J24: ='7.RuralDisagg'!O16 -> 0 | K24: =SUM(E24:I24)*[1]BYPBack!$D$13+J24*[1]BYPBack!$E$13 -> 0 | L24: ='[1]DPS%'!$E14 -> 0 | M24: ='3.SummaryBY'!L24/'3.SummaryBY'!L$32 -> 0 | N24: =IFERROR(SUM($E24:$G24,I24)*[1]BYPBack!$D$13/L24,0) -> 0 | O24: =IFERROR(SUM($H24:$H24)*[1]BYPBack!$D$13/L24,0) -> 0 | P24: =IFERROR(SUM($E24:$I24)*[1]BYPBack!$D$13/L24,0) -> 0 | Q24: =R24-P24 -> 0 | R24: =IFERROR(K24/L24,0) -> 0
A25: =A24+1 -> 16 | B25: Nonautomation -- Mach 5-Digit | C25: ='10.In-Office Detail'!C25 -> 0.90229116 | E25: ='10.In-Office Detail'!E25 -> 0 | F25: ='10.In-Office Detail'!G25 -> 0 | G25: =(SUM(E25:F25)/SUM(E$32:F$32))*G$32 -> 0 | H25: =L25/L$32*H$32 -> 0 | I25: =$L25/$L$32*I$32 -> 0 | J25: ='7.RuralDisagg'!O17 -> 0 | K25: =SUM(E25:I25)*[1]BYPBack!$D$13+J25*[1]BYPBack!$E$13 -> 0 | L25: ='[1]DPS%'!$E15 -> 0 | M25: ='3.SummaryBY'!L25/'3.SummaryBY'!L$32 -> 0 | N25: =IFERROR(SUM($E25:$G25,I25)*[1]BYPBack!$D$13/L25,0) -> 0 | O25: =IFERROR(SUM($H25:$H25)*[1]BYPBack!$D$13/L25,0) -> 0 | P25: =IFERROR(SUM($E25:$I25)*[1]BYPBack!$D$13/L25,0) -> 0 | Q25: =R25-P25 -> 0 | R25: =IFERROR(K25/L25,0) -> 0
A26: =A25+1 -> 17 | B26: Automation Mixed AADC | C26: ='10.In-Office Detail'!C26 -> 0.86458015 | E26: ='10.In-Office Detail'!E26 -> 23250.891 | F26: ='10.In-Office Detail'!G26 -> 3354.6142 | G26: =(SUM(E26:F26)/SUM(E$32:F$32))*G$32 -> 4638.0916 | H26: =L26/L$32*H$32 -> 18502.508 | I26: =$L26/$L$32*I$32 -> 614.50443 | J26: ='7.RuralDisagg'!O18 -> 20889.296 | K26: =SUM(E26:I26)*[1]BYPBack!$D$13+J26*[1]BYPBack!$E$13 -> 88950.946 | L26: ='[1]DPS%'!$E16 -> 1271821.6 | M26: ='3.SummaryBY'!L26/'3.SummaryBY'!L$32 -> 0.043661008 | N26: =SUM($E26:$G26,I26)*[1]BYPBack!$D$13/L26 -> 0.031695501 | O26: =SUM($H26:$H26)*[1]BYPBack!$D$13/L26 -> 0.018408073 | P26: =SUM($E26:$I26)*[1]BYPBack!$D$13/L26 -> 0.050103574 | Q26: =R26-P26 -> 0.019836227 | R26: =K26/L26 -> 0.069939801
A27: =A26+1 -> 18 | B27: Automation AADC | C27: ='10.In-Office Detail'!C27 -> 0.89522961 | E27: ='10.In-Office Detail'!E27 -> 85121.398 | F27: ='10.In-Office Detail'!G27 -> 15873.967 | G27: =(SUM(E27:F27)/SUM(E$32:F$32))*G$32 -> 17606.347 | H27: =L27/L$32*H$32 -> 87553.499 | I27: =$L27/$L$32*I$32 -> 2907.8227 | J27: ='7.RuralDisagg'!O19 -> 91634.926 | K27: =SUM(E27:I27)*[1]BYPBack!$D$13+J27*[1]BYPBack!$E$13 -> 375201.9 | L27: ='[1]DPS%'!$E17 -> 6018234.2 | M27: ='3.SummaryBY'!L27/'3.SummaryBY'!L$32 -> 0.20660302 | N27: =SUM($E27:$G27,I27)*[1]BYPBack!$D$13/L27 -> 0.025547311 | O27: =SUM($H27:$H27)*[1]BYPBack!$D$13/L27 -> 0.018408073 | P27: =SUM($E27:$I27)*[1]BYPBack!$D$13/L27 -> 0.043955384 | Q27: =R27-P27 -> 0.0183888 | R27: =K27/L27 -> 0.062344184
A28: =A27+1 -> 19 | B28: Auto 3-Digit Letters | C28: ='10.In-Office Detail'!C28 -> 0.88352278 | E28: ='10.In-Office Detail'!E28 -> 0 | F28: ='10.In-Office Detail'!G28 -> 0 | G28: =(SUM(E28:F28)/SUM(E$32:F$32))*G$32 -> 0 | H28: =L28/L$32*H$32 -> 0 | I28: =$L28/$L$32*I$32 -> 0 | J28: ='7.RuralDisagg'!O20 -> 0 | K28: =SUM(E28:I28)*[1]BYPBack!$D$13+J28*[1]BYPBack!$E$13 -> 0 | L28: ='[1]DPS%'!$E18 -> 0 | M28: ='3.SummaryBY'!L28/'3.SummaryBY'!L$32 -> 0
A29: =A28+1 -> 20 | B29: Auto 5-Digit Letters CSBCS/Manual Sites | C29: ='10.In-Office Detail'!C29 -> 0 | E29: ='10.In-Office Detail'!E29 -> 101301.45 | F29: ='10.In-Office Detail'!G29 -> 1979.2515 | G29: =(SUM(E29:F29)/SUM(E$32:F$32))*G$32 -> 18004.746 | H29: =L29/L$32*H$32 -> 10916.641 | I29: =$L29/$L$32*I$32 -> 362.56295 | J29: ='7.RuralDisagg'!O21 -> 37693.797 | K29: =SUM(E29:I29)*[1]BYPBack!$D$13+J29*[1]BYPBack!$E$13 -> 213261.12 | L29: ='[1]DPS%'!$E19 -> 750385.77 | M29: ='3.SummaryBY'!L29/'3.SummaryBY'!L$32 -> 0.025760374 | N29: =SUM($E29:$G29,I29)*[1]BYPBack!$D$13/L29 -> 0.20512772 | O29: =SUM($H29:$H29)*[1]BYPBack!$D$13/L29 -> 0.018408073 | P29: =SUM($E29:$I29)*[1]BYPBack!$D$13/L29 -> 0.22353579 | Q29: =R29-P29 -> 0.060666193 | R29: =K29/L29 -> 0.28420198
A30: =A29+1 -> 21 | B30: Auto 5-Digit Letters Other Sites | C30: ='10.In-Office Detail'!C30 -> 0.97585901 | E30: ='10.In-Office Detail'!E30 -> 67096.314 | F30: ='10.In-Office Detail'!G30 -> 54303.633 | G30: =(SUM(E30:F30)/SUM(E$32:F$32))*G$32 -> 21163.442 | H30: =L30/L$32*H$32 -> 299513.85 | I30: =$L30/$L$32*I$32 -> 9947.44 | J30: ='7.RuralDisagg'!O22 -> 248565.11 | K30: =SUM(E30:I30)*[1]BYPBack!$D$13+J30*[1]BYPBack!$E$13 -> 872154.26 | L30: ='[1]DPS%'!$E20 -> 20587921 | M30: ='3.SummaryBY'!L30/'3.SummaryBY'!L$32 -> 0.70677318 | N30: =SUM($E30:$G30,I30)*[1]BYPBack!$D$13/L30 -> 0.0093732912 | O30: =SUM($H30:$H30)*[1]BYPBack!$D$13/L30 -> 0.018408073 | P30: =SUM($E30:$I30)*[1]BYPBack!$D$13/L30 -> 0.027781364 | Q30: =R30-P30 -> 0.014581061 | R30: =K30/L30 -> 0.042362425
A31: =A30+1 -> 22 | B31: Auto 5-Digit Letters | C31: ='10.In-Office Detail'!C31 -> 0.94154182 | E31: ='10.In-Office Detail'!E31 -> 168397.77 | F31: ='10.In-Office Detail'!G31 -> 56282.885 | G31: =(SUM(E31:F31)/SUM(E$32:F$32))*G$32 -> 39168.189 | H31: =L31/L$32*H$32 -> 310430.49 | I31: =$L31/$L$32*I$32 -> 10310.003 | J31: ='7.RuralDisagg'!O23 -> 286258.91 | K31: =SUM(E31:I31)*[1]BYPBack!$D$13+J31*[1]BYPBack!$E$13 -> 1085415.4 | L31: ='[1]DPS%'!$E21 -> 21338307 | M31: ='3.SummaryBY'!L31/'3.SummaryBY'!L$32 -> 0.73253355 | N31: =SUM($E31:$G31,I31)*[1]BYPBack!$D$13/L31 -> 0.016257218 | O31: =SUM($H31:$H31)*[1]BYPBack!$D$13/L31 -> 0.018408073 | P31: =SUM($E31:$I31)*[1]BYPBack!$D$13/L31 -> 0.034665291 | Q31: =R31-P31 -> 0.016201697 | R31: =K31/L31 -> 0.050866988
A32: =A31+1 -> 23 | B32: Presort Letters Subtotal* | C32: ='10.In-Office Detail'!C32 -> 0.92750157 | E32: =[1]CARMMCasing!$D$12 -> 285096.63 | F32: =[1]CARMMCasing!$E12 -> 76833.183 | G32: ='[1]7.0.6'!$I$12+'[1]CS6&7 CRA'!$D$13 -> 63094.597 | H32: ='[1]7.0.6'!L$12 -> 423776.48 | I32: ='[1]7.0.6'!J$12 -> 14074.445 | J32: =[1]RuralCosts!$P$13 -> 406771.86 | K32: =SUM(E32:I32)*[1]BYPBack!$D$13+J32*[1]BYPBack!$E$13 -> 1583083.4 | L32: =SUM(L18:L30) -> 29129460 | N32: =SUM($E32:$G32,I32)*[1]BYPBack!$D$13/L32 -> 0.019073649 | O32: =SUM($H32:$H32)*[1]BYPBack!$D$13/L32 -> 0.018408073 | P32: =SUM($E32:$I32)*[1]BYPBack!$D$13/L32 -> 0.037481722 | Q32: =R32-P32 -> 0.01686475 | R32: =K32/L32 -> 0.054346473
A33: =A32+1 -> 24 | B33: Presort Flats | D33: =(E33+F33)/L33 -> 0.15392246 | E33: =[1]CARMMCasing!$D$15 -> 57186.657 | F33: =[1]CARMMCasing!$E15 -> 9430.6527 | G33: ='[1]7.0.6'!$I$15+'[1]CS6&7 CRA'!$D$16 -> 11615.181 | H33: ='[1]7.0.6'!L$15 -> 5195.9811 | I33: ='[1]7.0.6'!J$15 -> 172.56868 | J33: =[1]RuralCosts!$P$16 -> 22621.902 | K33: =SUM(E33:I33)*[1]BYPBack!$D$15+J33*[1]BYPBack!$E$15 -> 129459.01 | L33: =[1]RPWShape!$D$15 -> 432797.83 | N33: =SUM($E33:$G33,I33)*[1]BYPBack!$D$15/L33 -> 0.22132798 | O33: =SUM($H33:$H33)*[1]BYPBack!$D$15/L33 -> 0.014667625 | P33: =SUM($E33:$I33)*[1]BYPBack!$D$15/L33 -> 0.2359956 | Q33: =R33-P33 -> 0.063125594 | R33: =K33/L33 -> 0.29912119
A34: =A33+1 -> 25 | B34: Presort Subtotal BY* | D34: =(E34+F34)/L34 -> 0.014496428 | E34: =SUM(E32,E33) -> 342283.29 | F34: =SUM(F32,F33) -> 86263.836 | G34: =SUM(G32,G33) -> 74709.778 | H34: =SUM(H32,H33) -> 428972.46 | I34: =SUM(I32,I33) -> 14247.013 | J34: =SUM(J32,J33) -> 429393.76 | K34: =SUM(E34:I34)*[1]BYPBack!$D$13+J34*[1]BYPBack!$E$13 -> 1716186.9 | L34: =SUM(L32,L33) -> 29562257 | N34: =SUMPRODUCT(N32:N33,$L32:$L33)/SUM($L32:$L33) -> 0.022034696 | O34: =SUMPRODUCT(O32:O33,$L32:$L33)/SUM($L32:$L33) -> 0.018353312 | P34: =SUMPRODUCT(P32:P33,$L32:$L33)/SUM($L32:$L33) -> 0.040388009 | Q34: =SUMPRODUCT(Q32:Q33,$L32:$L33)/SUM($L32:$L33) -> 0.017542019 | R34: =K34/L34 -> 0.058053311
B35: SINGLE PIECE CARDS Source / Calculations | E35: ="L"&$A36&" from [UDCInputs.xls] CARMMCasing" -> L26 from [UDCInputs.xls] CARMMCasing | F35: ="L"&$A36&" from [UDCInputs.xls] CARMMCasing" -> L26 from [UDCInputs.xls] CARMMCasing | G35: ="L"&$A36&" from [UDCInputs.xls] 7.0.6 and CS6&7 CRA" -> L26 from [UDCInputs.xls] 7.0.6 and CS6&7 CRA | H35: ="L"&$A36&" from [UDCInputs.xls] 7.0.6" -> L26 from [UDCInputs.xls] 7.0.6 | I35: ="L"&$A36&" from [UDCInputs.xls] 7.0.6" -> L26 from [UDCInputs.xls] 7.0.6 | J35: ="L"&$A36 & " from CS10.xls W/S Outputs to CRA" -> L26 from CS10.xls W/S Outputs to CRA | L35: ="L"&$A36 & " from [UDCInputs.xls] " &[1]NOTES!$A$8 -> L26 from [UDCInputs.xls] 7.0.6.10
A36: =A34+1 -> 26 | B36: First-Class Single-Piece Cards BY* | D36: =(E36+F36)/L36 -> 0.028672364 | E36: =[1]CARMMCasing!$D$11 -> 6627.6225 | F36: =[1]CARMMCasing!$E$11 -> 2736.913 | G36: ='[1]CS6&7 CRA'!$D$12+'[1]7.0.6'!$I$11 -> 1632.5077 | H36: ='[1]7.0.6'!$L$11 -> 10015.63 | I36: ='[1]7.0.6'!$J$11 -> 286.52084 | J36: ='[1]CS10 CRA'!$D$12+'[1]CS10 CRA'!$E$12 -> 6824.807 | K36: =SUM(E36:I36)*[1]BYPBack!$D$12+J36*[1]BYPBack!$E$12 -> 35143.836 | L36: ='[1]7.0.8'!$C$12 -> 326604.93 | N36: =SUM($E36:$G36,I36)*[1]BYPBack!$D$12/L36 -> 0.043635146 | O36: =SUM($H36:$H36)*[1]BYPBack!$D$12/L36 -> 0.038731865 | P36: =SUM($E36:$I36)*[1]BYPBack!$D$12/L36 -> 0.082367011 | Q36: =R36-P36 -> 0.025236498 | R36: =K36/L36 -> 0.10760351
B37: PRESORT CARDS Source / Calculations | E37: ="L"&A39&"..L"&A46&" from "&NOTES!A14&" C"&-'10.In-Office Detail'!E14 -> L28..L35 from 10.In-OfficeDetail C11 | F37: ="L"&A39&"..L"&A46&" from "&NOTES!A14&" C"&-'10.In-Office Detail'!G14 -> L28..L35 from 10.In-OfficeDetail C13 | G37: ="L"&A39&"..L"&A46&" = (C"&-E6&"..C"&-F6&") / (L"&A47&" C"&-E6&"..C"&-F6&") x C"&-G6&"L"&A47&"; L"&A47&" from [UDCInputs.xls] 7.0.6" -> L28..L35 = (C3..C4) / (L36 C3..C4) x C5L36; L36 from [UDCInputs.xls] 7.0.6 | H37: ="L"&A39&"..L"&A46&" = C"&-$L6&"L{i}/C"&-$L6&"L"&$A$47&" x C"&-H6&"L"&$A47&"; L"&A47&" from [UDCInputs.xls] 7.0.6" -> L28..L35 = C10L{i}/C10L36 x C6L36; L36 from [UDCInputs.xls] 7.0.6 | I37: ="L"&A39&"..L"&A46&" = C"&-$L6&"L{i}/C"&-$L6&"L"&$A$47&" x C"&-I6&"L"&$A47&"; L"&A47&" from [UDCInputs.xls] 7.0.6" -> L28..L35 = C10L{i}/C10L36 x C7L36; L36 from [UDCInputs.xls] 7.0.6 | J37: ="L"&A39&"..L"&A46&" = from "&NOTES!A11&" C"&-'7.RuralDisagg'!O$6&"; L"&A47&" from [UDCInputs.xls] RuralCosts" -> L28..L35 = from 7.RuralDisagg C12; L36 from [UDCInputs.xls] RuralCosts | L37: ="L"&A39&"..L"&A46&" = from [UDCInputs.xls] "& [1]NOTES!$A$24 -> L28..L35 = from [UDCInputs.xls] DALs
A38: =A36+1 -> 27 | B38: Presort Cards
A39: =A38+1 -> 28 | B39: FC Nonautomation Cards | C39: ='10.In-Office Detail'!C34 -> 0.85382551 | E39: ='10.In-Office Detail'!E34 -> 1254.6729 | F39: ='10.In-Office Detail'!G34 -> 213.68072 | G39: =(SUM(E39:F39)/SUM(E$47:F$47))*G$47 -> 255.9646 | H39: =$L39/$L$47*H$47 -> 1174.8828 | I39: =$L39/$L$47*I$47 -> 39.020154 | J39: ='7.RuralDisagg'!O28 -> 1252.7372 | K39: =SUM(E39:I39)*[1]BYPBack!$D$14+J39*[1]BYPBack!$E$14 -> 5236.7356 | L39: ='[1]DPS%'!$E36 -> 80860.526 | M39: ='3.SummaryBY'!L39/'3.SummaryBY'!L$47 -> 0.03455136 | N39: =SUM($E39:$G39,I39)*[1]BYPBack!$D$14/L39 -> 0.027637615 | O39: =SUM($H39:$H39)*[1]BYPBack!$D$14/L39 -> 0.01841448 | P39: =SUM($E39:$I39)*[1]BYPBack!$D$14/L39 -> 0.046052095 | Q39: =J39*[1]BYPBack!$E$14/L39 -> 0.018710477 | R39: =K39/L39 -> 0.064762572
A40: =A39+1 -> 29 | B40: Auto Mixed AADC Cards | C40: ='10.In-Office Detail'!C35 -> 0.86458015 | E40: ='10.In-Office Detail'!E35 -> 2752.428 | F40: ='10.In-Office Detail'!G35 -> 505.98778 | G40: =(SUM(E40:F40)/SUM(E$47:F$47))*G$47 -> 568.0097 | H40: =$L40/$L$47*H$47 -> 2782.0777 | I40: =$L40/$L$47*I$47 -> 92.398234 | J40: ='7.RuralDisagg'!O29 -> 2899.8714 | K40: =SUM(E40:I40)*[1]BYPBack!$D$14+J40*[1]BYPBack!$E$14 -> 11994.677 | L40: ='[1]DPS%'!$E37 -> 191474.64 | M40: ='3.SummaryBY'!L40/'3.SummaryBY'!L$47 -> 0.081816301 | N40: =SUM($E40:$G40,I40)*[1]BYPBack!$D$14/L40 -> 0.025938564 | O40: =SUM($H40:$H40)*[1]BYPBack!$D$14/L40 -> 0.01841448 | P40: =SUM($E40:$I40)*[1]BYPBack!$D$14/L40 -> 0.044353045 | Q40: =J40*[1]BYPBack!$E$14/L40 -> 0.018290641 | R40: =K40/L40 -> 0.062643686
A41: =A40+1 -> 30 | B41: Auto AADC Cards | C41: ='10.In-Office Detail'!C36 -> 0.89522961 | E41: ='10.In-Office Detail'!E36 -> 8837.3503 | F41: ='10.In-Office Detail'!G36 -> 2099.8578 | G41: =(SUM(E41:F41)/SUM(E$47:F$47))*G$47 -> 1906.5831 | H41: =$L41/$L$47*H$47 -> 11545.669 | I41: =$L41/$L$47*I$47 -> 383.45423 | J41: ='7.RuralDisagg'!O30 -> 11247.277 | K41: =SUM(E41:I41)*[1]BYPBack!$D$14+J41*[1]BYPBack!$E$14 -> 44979.719 | L41: ='[1]DPS%'!$E38 -> 794622.97 | M41: ='3.SummaryBY'!L41/'3.SummaryBY'!L$47 -> 0.33953903 | N41: =SUM($E41:$G41,I41)*[1]BYPBack!$D$14/L41 -> 0.021096468 | O41: =SUM($H41:$H41)*[1]BYPBack!$D$14/L41 -> 0.01841448 | P41: =SUM($E41:$I41)*[1]BYPBack!$D$14/L41 -> 0.039510949 | Q41: =J41*[1]BYPBack!$E$14/L41 -> 0.017094159 | R41: =K41/L41 -> 0.056605107
...

Sheet 4.Rural cost
A1: =[1]Inputs!$C$4 -> Unit Delivery Cost Model - 12/16/2025
A2: ="DEVELOPMENT OF " & [1]Inputs!$C$6 & " RURAL CARRIER KEY" -> DEVELOPMENT OF FY 2025 RURAL CARRIER KEY
A3: =[1]RuralCosts!$A$3 & " for Costs" -> SOURCE: CS10-NP-FY25.xlsx, W/S 10.1.2 for Costs
A4: =[1]RuralVols!$A$3 & " for Volumes" -> SOURCE: CS10-NP-FY25.xlsx, Inputs DK for Volumes
A5: Line No. | C5: Letters | D5: Flats | E5: Mailbox Parcels | F5: Door Parcels | G5: Parcel Locker Parcels | H5: Total Parcels | I5: Boxholder | J5: DPS | K5: Postage Due | L5: Carrier Pickup | M5: Collections | N5: Misc_To_Door | O5: Misc_Actv | P5: Total Delivered | Q5: Total Incl Collections
B6: Col. No. | C6: -1 | D6: =C6-1 -> -2 | E6: =D6-1 -> -3 | F6: =E6-1 -> -4 | G6: =F6-1 -> -5 | H6: =G6-1 -> -6 | I6: =H6-1 -> -7 | J6: =I6-1 -> -8 | K6: =J6-1 -> -9 | ... Q6: =P6-1 -> -15
B7: Units | C7: $(000) | D7: $(000) | E7: $(000) | F7: $(000) | G7: $(000) | H7: $(000) | I7: $(000) | J7: $(000) | K7: $(000) | L7: $(000) | M7: $(000) | N7: $(000) | O7: $(000) | P7: $(000) | Q7: $(000)
B8: Source / Calculations | C8: ="L"&A12& ", " & A16 & ", " & A20 &", " & A22 &", " & A25&", " & A27&", " & A29&", " & A31&", " & A33&", " & A35&", " & A40&", " & A42&", " & A44& " = cost / volume" -> L4, 8, 12, 14, 17, 19, 21, 23, 25, 27, 32, 34, 36 = cost / volume | P8: ="=C"&-C6&"..C"&-K6 -> =C1..C9
A9: 1 | C9: =C12 -> 0.1561702 | D9: =D20 -> 0.14691668 | H9: =H18 -> 1.8903443 | I9: =I12 -> 0 | J9: =J12 -> 0.032138413 | K9: =K12 -> 0.5758252 | L9: =L44 -> 0.25715123 | M9: =M12 -> 0.0065550581
A10: =A9+1 -> 2 | B10: First-Class
A11: =A10+1 -> 3 | B11: Single-Piece Letters | C11: =[1]RuralCosts!C11 -> 49940.214 | D11: =[1]RuralCosts!D11 -> 775.65753 | E11: =[1]RuralCosts!E11 -> 0 | F11: =[1]RuralCosts!F11 -> 0 | G11: =[1]RuralCosts!G11 -> 0 | H11: =SUM(E11:G11) -> 0 | I11: =[1]RuralCosts!H11 -> 0 | J11: =[1]RuralCosts!I11 -> 78847.976 | K11: =[1]RuralCosts!J11 -> 309.18189 | L11: =[1]RuralCosts!$L$11 -> 0 | M11: =[1]RuralCosts!$K$11 -> 7699.2631 | N11: =[1]RuralCosts!M$11 -> 2911.9357 | O11: =[1]RuralCosts!N$11 -> 291.47557 | P11: =SUM(C11:K11)+O11+N11-H11 -> 133076.44 | Q11: =SUM(C11:O11)-H11 -> 140775.7
A12: =A11+1 -> 4 | B12: Unit Cost | C12: =IFERROR(C11/C52,0) -> 0.1561702 | D12: =IFERROR(D11/D52,0) -> 0.14691668 | E12: =IFERROR(E11/E52,0) -> 0 | F12: =IFERROR(F11/F52,0) -> 0 | G12: =IFERROR(G11/G52,0) -> 0 | H12: =IFERROR(H11/H52,0) -> 0 | I12: =IFERROR(I11/I52,0) -> 0 | J12: =IFERROR(J11/J52,0) -> 0.032138413 | ... M12: =IFERROR(M11/M52,0) -> 0.0065550581
A13: =A12+1 -> 5 | B13: Single-Piece Cards | C13: =[1]RuralCosts!C12 -> 3870.8245 | D13: =[1]RuralCosts!D12 -> 6.405856 | E13: =[1]RuralCosts!E12 -> 0 | F13: =[1]RuralCosts!F12 -> 0 | G13: =[1]RuralCosts!G12 -> 0 | H13: =SUM(E13:G13) -> 0 | I13: =[1]RuralCosts!H12 -> 0 | J13: =[1]RuralCosts!I12 -> 2829.7251 | K13: =[1]RuralCosts!J12 -> 2.2576494 | L13: =[1]RuralCosts!$L12 -> 0 | M13: =[1]RuralCosts!$K$12 -> 0 | N13: =[1]RuralCosts!M$12 -> 101.47271 | O13: =[1]RuralCosts!N$12 -> 14.12119 | P13: =SUM(C13:K13)+O13+N13-H13 -> 6824.807 | Q13: =SUM(C13:O13)-H13 -> 6824.807
A14: =A13+1 -> 6 | B14: Unit Cost | C14: =IFERROR(C13/C53,0) -> 0.1561702 | D14: =IFERROR(D13/D53,0) -> 0.14691668 | E14: =IFERROR(E13/E53,0) -> 0 | F14: =IFERROR(F13/F53,0) -> 0 | G14: =IFERROR(G13/G53,0) -> 0 | H14: =IFERROR(H13/H53,0) -> 0 | I14: =IFERROR(I13/I53,0) -> 0 | J14: =IFERROR(J13/J53,0) -> 0.032138413 | ... M14: =IFERROR(M13/M53,0) -> 0
A15: =A14+1 -> 7 | B15: Presort Letters | C15: =[1]RuralCosts!C13 -> 95004.735 | D15: =[1]RuralCosts!D13 -> 1185.642 | E15: =[1]RuralCosts!E13 -> 0 | F15: =[1]RuralCosts!F13 -> 0 | G15: =[1]RuralCosts!G13 -> 0 | H15: =SUM(E15:G15) -> 0 | I15: =[1]RuralCosts!H13 -> 0 | J15: =[1]RuralCosts!I13 -> 300688.73 | K15: =[1]RuralCosts!J13 -> 0 | L15: =[1]RuralCosts!$L13 -> 0 | M15: =[1]RuralCosts!$K$13 -> 0 | N15: =[1]RuralCosts!M$13 -> 9050.2166 | O15: =[1]RuralCosts!N$13 -> 842.52924 | P15: =SUM(C15:K15)+O15+N15-H15 -> 406771.86 | Q15: =SUM(C15:O15)-H15 -> 406771.86
A16: =A15+1 -> 8 | B16: Unit Cost | C16: =IFERROR(C15/C54,0) -> 0.1561702 | D16: =IFERROR(D15/D54,0) -> 0.14691668 | E16: =IFERROR(E15/E54,0) -> 0 | F16: =IFERROR(F15/F54,0) -> 0 | G16: =IFERROR(G15/G54,0) -> 0 | H16: =IFERROR(H15/H54,0) -> 0 | I16: =IFERROR(I15/I54,0) -> 0 | J16: =IFERROR(J15/J54,0) -> 0.032138413 | ... M16: =IFERROR(M15/M54,0) -> 0
A17: =A16+1 -> 9 | B17: Presort Cards | C17: =[1]RuralCosts!C14 -> 7603.1914 | D17: =[1]RuralCosts!D14 -> 18.777653 | E17: =[1]RuralCosts!E14 -> 0 | F17: =[1]RuralCosts!F14 -> 7.411511 | G17: =[1]RuralCosts!G14 -> 0 | H17: =SUM(E17:G17) -> 7.411511 | I17: =[1]RuralCosts!H14 -> 0 | J17: =[1]RuralCosts!I14 -> 23095.113 | K17: =[1]RuralCosts!J14 -> 0 | L17: =[1]RuralCosts!$L14 -> 0 | M17: =[1]RuralCosts!$K$14 -> 0 | N17: =[1]RuralCosts!M$14 -> 727.10639 | O17: =[1]RuralCosts!N$14 -> 65.277708 | P17: =SUM(C17:K17)+O17+N17-H17 -> 31516.878 | Q17: =SUM(C17:O17)-H17 -> 31516.878
A18: =A17+1 -> 10 | B18: Unit Cost | C18: =IFERROR(C17/C55,0) -> 0.1561702 | D18: =IFERROR(D17/D55,0) -> 0.14691668 | E18: =IFERROR(E17/E55,0) -> 0 | F18: =IFERROR(F17/F55,0) -> 1.8903443 | G18: =IFERROR(G17/G55,0) -> 0 | H18: =IFERROR(H17/H55,0) -> 1.8903443 | I18: =IFERROR(I17/I55,0) -> 0 | J18: =IFERROR(J17/J55,0) -> 0.032138413 | ... M18: =IFERROR(M17/M55,0) -> 0
A19: =A18+1 -> 11 | B19: Single Piece Flats | C19: =[1]RuralCosts!C15 -> 1.8691304 | D19: =[1]RuralCosts!D15 -> 17855.054 | E19: =[1]RuralCosts!E15 -> 0 | F19: =[1]RuralCosts!F15 -> 0 | G19: =[1]RuralCosts!G15 -> 0 | H19: =SUM(E19:G19) -> 0 | I19: =[1]RuralCosts!H15 -> 0 | J19: =[1]RuralCosts!I15 -> 0 | K19: =[1]RuralCosts!J15 -> 201.41223 | L19: =[1]RuralCosts!L15 -> 0 | M19: =[1]RuralCosts!K15 -> 0 | N19: =[1]RuralCosts!M15 -> 126.53204 | O19: =[1]RuralCosts!N15 -> 37.830605 | P19: =SUM(C19:K19)+O19+N19-H19 -> 18222.698 | Q19: =SUM(C19:O19)-H19 -> 18222.698
A20: =A19+1 -> 12 | B20: Unit Cost | C20: =IFERROR(C19/C56,0) -> 0.1561702 | D20: =IFERROR(D19/D56,0) -> 0.14691668 | E20: =IFERROR(E19/E56,0) -> 0 | F20: =IFERROR(F19/F56,0) -> 0 | G20: =IFERROR(G19/G56,0) -> 0 | H20: =IFERROR(H19/H56,0) -> 0 | I20: =IFERROR(I19/I56,0) -> 0 | J20: =IFERROR(J19/J56,0) -> 0 | ... M20: =IFERROR(M19/M56,0) -> 0
A21: =A20+1 -> 13 | B21: Presort Flats | C21: =[1]RuralCosts!C16 -> 1.2545102 | D21: =[1]RuralCosts!D16 -> 22439.219 | E21: =[1]RuralCosts!E16 -> 0 | F21: =[1]RuralCosts!F16 -> 0 | G21: =[1]RuralCosts!G16 -> 0 | H21: =SUM(E21:G21) -> 0 | I21: =[1]RuralCosts!H16 -> 0 | J21: =[1]RuralCosts!I16 -> 0 | K21: =[1]RuralCosts!J16 -> 0 | L21: =[1]RuralCosts!L16 -> 0 | M21: =[1]RuralCosts!K16 -> 0 | N21: =[1]RuralCosts!M16 -> 134.46573 | O21: =[1]RuralCosts!N16 -> 46.962724 | P21: =SUM(C21:K21)+O21+N21-H21 -> 22621.902 | Q21: =SUM(C21:O21)-H21 -> 22621.902
A22: =A21+1 -> 14 | B22: Unit Cost | C22: =IFERROR(C21/C57,0) -> 0.1561702 | D22: =IFERROR(D21/D57,0) -> 0.14691668 | E22: =IFERROR(E21/E57,0) -> 0 | F22: =IFERROR(F21/F57,0) -> 0 | G22: =IFERROR(G21/G57,0) -> 0 | H22: =IFERROR(H21/H57,0) -> 0 | I22: =IFERROR(I21/I57,0) -> 0 | J22: =IFERROR(J21/J57,0) -> 0 | ... M22: =IFERROR(M21/M57,0) -> 0
A23: =A22+1 -> 15 | B23: USPS Marketing Mail (A)
A24: =A23+1 -> 16 | B24: HIGH DENSITY & SATURATION LETTERS | C24: =[1]RuralCosts!C18 -> 70440.997 | D24: =[1]RuralCosts!D18 -> 1915.5951 | E24: =[1]RuralCosts!E18 -> 0 | F24: =[1]RuralCosts!F18 -> 0 | G24: =[1]RuralCosts!G18 -> 0 | H24: =SUM(E24:G24) -> 0 | I24: =[1]RuralCosts!H18 -> 12847.592 | J24: =[1]RuralCosts!I18 -> 55415.843 | K24: =[1]RuralCosts!J18 -> 0 | L24: =[1]RuralCosts!L18 -> 0 | M24: =[1]RuralCosts!K18 -> 0 | N24: =[1]RuralCosts!M$18 -> 1869.5471 | O24: =[1]RuralCosts!N$18 -> 303.65557 | P24: =SUM(C24:K24)+O24+N24-H24 -> 142793.23 | Q24: =SUM(C24:O24)-H24 -> 142793.23
A25: =A24+1 -> 17 | B25: Unit Cost | C25: =IFERROR(C24/C60,0) -> 0.1501951 | D25: =IFERROR(D24/D60,0) -> 0.14691668 | E25: =IFERROR(E24/E60,0) -> 0 | F25: =IFERROR(F24/F60,0) -> 0 | G25: =IFERROR(G24/G60,0) -> 0 | H25: =IFERROR(H24/H60,0) -> 0 | I25: =IFERROR(I24/I60,0) -> 0.062211817 | J25: =IFERROR(J24/J60,0) -> 0.032020131 | ... M25: =IFERROR(M24/M60,0) -> 0
A26: =A25+1 -> 18 | B26: HIGH DENSITY & SATURATION FLATS & PARCELS | C26: =[1]RuralCosts!C19 -> 2892.0863 | D26: =[1]RuralCosts!D19 -> 218533.41 | E26: =[1]RuralCosts!E19 -> 0 | F26: =[1]RuralCosts!F19 -> 0 | G26: =[1]RuralCosts!G19 -> 0 | H26: =SUM(E26:G26) -> 0 | I26: =[1]RuralCosts!H19 -> 86461.102 | J26: =[1]RuralCosts!I19 -> 204.70492 | K26: =[1]RuralCosts!J19 -> 0 | L26: =[1]RuralCosts!L19 -> 0 | M26: =[1]RuralCosts!K19 -> 0 | N26: =[1]RuralCosts!M$19 -> 2444.7772 | O26: =[1]RuralCosts!N$19 -> 637.59347 | P26: =SUM(C26:K26)+O26+N26-H26 -> 311173.67 | Q26: =SUM(C26:O26)-H26 -> 311173.67
A27: =A26+1 -> 19 | B27: Unit Cost | C27: =IFERROR(C26/C61,0) -> 5.0304317 | D27: =IFERROR(D26/D61,0) -> 0.14691668 | E27: =IFERROR(E26/E61,0) -> 0 | F27: =IFERROR(F26/F61,0) -> 0 | G27: =IFERROR(G26/G61,0) -> 0 | H27: =IFERROR(H26/H61,0) -> 0 | I27: =IFERROR(I26/I61,0) -> 0.076541637 | J27: =IFERROR(J26/J61,0) -> 0 | ... M27: =IFERROR(M26/M61,0) -> 0
A28: =A27+1 -> 20 | B28: EVERY DOOR DIRECT MAIL RETAIL | C28: =[1]RuralCosts!C20 -> 0 | D28: =[1]RuralCosts!D20 -> 0 | E28: =[1]RuralCosts!E20 -> 0 | F28: =[1]RuralCosts!F20 -> 0 | G28: =[1]RuralCosts!G20 -> 0 | H28: =SUM(E28:G28) -> 0 | I28: =[1]RuralCosts!H20 -> 6078.8403 | J28: =[1]RuralCosts!I20 -> 0 | K28: =[1]RuralCosts!J20 -> 0 | L28: =[1]RuralCosts!L20 -> 0 | M28: =[1]RuralCosts!K20 -> 0 | N28: =[1]RuralCosts!M$20 -> 173.73495 | O28: =[1]RuralCosts!N$20 -> 12.989366 | P28: =SUM(C28:K28)+O28+N28-H28 -> 6265.5646 | Q28: =SUM(C28:O28)-H28 -> 6265.5646
A29: =A28+1 -> 21 | B29: Unit Cost | C29: =IFERROR(C28/C62,0) -> 0 | D29: =IFERROR(D28/D62,0) -> 0 | E29: =IFERROR(E28/E62,0) -> 0 | F29: =IFERROR(F28/F62,0) -> 0 | G29: =IFERROR(G28/G62,0) -> 0 | H29: =IFERROR(H28/H62,0) -> 0 | I29: =IFERROR(I28/I62,0) -> 0.024846395 | J29: =IFERROR(J28/J62,0) -> 0 | ... M29: =IFERROR(M28/M62,0) -> 0
A30: =A29+1 -> 22 | B30: LETTERS | C30: =[1]RuralCosts!C22 -> 172873.07 | D30: =[1]RuralCosts!D22 -> 2512.2066 | E30: =[1]RuralCosts!E22 -> 0 | F30: =[1]RuralCosts!F22 -> 173.68427 | G30: =[1]RuralCosts!G22 -> 0 | H30: =SUM(E30:G30) -> 173.68427 | I30: =[1]RuralCosts!H22 -> 398.74105 | J30: =[1]RuralCosts!I22 -> 417010.15 | K30: =[1]RuralCosts!J22 -> 4.6170293 | L30: =[1]RuralCosts!L22 -> 0 | M30: =[1]RuralCosts!K22 -> 0 | N30: =[1]RuralCosts!M$22 -> 11778.847 | O30: =[1]RuralCosts!N$22 -> 1254.9973 | P30: =SUM(C30:K30)+O30+N30-H30 -> 606006.31 | Q30: =SUM(C30:O30)-H30 -> 606006.31
A31: =A30+1 -> 23 | B31: Unit Cost | C31: =IFERROR(C30/C65,0) -> 0.1561702 | D31: =IFERROR(D30/D65,0) -> 0.14691668 | E31: =IFERROR(E30/E65,0) -> 0 | F31: =IFERROR(F30/F65,0) -> 1.8903443 | G31: =IFERROR(G30/G65,0) -> 0 | H31: =IFERROR(H30/H65,0) -> 1.8903443 | I31: =IFERROR(I30/I65,0) -> 0.066668641 | J31: =IFERROR(J30/J65,0) -> 0.032138413 | ... M31: =IFERROR(M30/M65,0) -> 0
