Workbook

Sheet QBRM COST AVOIDANCE SUMMARY
A1: A. QBRM WORKSHARING RELATED SAVINGS ESTIMATE SUMMARY
E4: ="(1)" -> (1) | F4: ="(2)" -> (2) | G4: ="(3)" -> (3) | H4: ="(4)" -> (4)
I5: 01/29/25 version
F7: CRA | H7: MAIL PROC | I7: MAIL PROC | J7: Difference
E8: MAIL PROC | F8: PROPORTIONAL | G8: MAIL PROC | H8: WORKSHARING | I8: WORKSHARING
A9: BENCHMARK | E9: MODEL | F9: ADJUSTMENT | G9: ADJUSTED | H9: RELATED | I9: RELATED
B10: RATE CATEGORY | E10: UNIT COST | F10: FACTOR | G10: UNIT COST | H10: SAVINGS | I10: SAVINGS | J10: Revision - 01/29/25 version
A12: Handwritten Reply Mail Cards / Letters | E12: ='HAND COSTS'!K17 -> 2.8375627 | F12: ='QBRM COST AVOIDANCE INPUTS'!G50 -> 2.2965944 | G12: =E12*F12 -> 6.5167306 | H12: ="---" -> ---
B13: QBRM Cards / Letters | E13: ='QBRM COSTS'!K17 -> 1.5337422 | F13: ='QBRM COST AVOIDANCE INPUTS'!G50 -> 2.2965944 | G13: =E13*F13 -> 3.5223838 | H13: =G12-G13 -> 2.9943468 | I13: ='[1]QBRM COST AVOIDANCE SUMMARY'!$H$13 -> 3.0464761 | J13: =H13-'[1]QBRM COST AVOIDANCE SUMMARY'!$H$13 -> -0.052129258
A16: ="(1)" -> (1) | B16: Model Costs from "HAND COSTS" and "QBRM COSTS" worksheets
A17: ="(2)" -> (2) | B17: From "QBRM COST AVOIDANCE INPUTS" worksheet
A18: ="(3)" -> (3) | B18: (1) * (2)
A19: ="(4)" -> (4) | B19: Benchmark (3) - Rate Category (3)

Sheet HAND FLOW
A1: FIRST-CLASS SINGLE-PIECE HANDWRITTEN REPLY MAIL CARDS / LETTERS
A2: MAIL FLOW MODEL
B5: ENTERED = | C5: 10000 | F5: PROCESSED = | G5: =H18+E39+F39+K32+K37+N42+M45 -> 10000
A8: IMAGES FOR MAIL PIECES SORTED TO THE HANDWRITTEN BINS ON THE AFCS-ISS ARE LIFTED ON THAT
A9: MACHINE AND TRANSFERRED DIRECTLY TO THE REMOTE COMPUTER READ (RCR) SYSTEM. CONSEQUENTLY,
A10: THE MAIL VOLUME FIRST ENTERS THE "OUT RCR" OPERATION BELOW.
A14: OUTGOING RBCS
F16: Out ISS
C18: =C28 -> 19.125177 | F18: =C18+E20 -> 253.16175 | G18: 0 | H18: =F18*'QBRM COST AVOIDANCE INPUTS'!G34 -> 228.46763
I19: To automation operations
D20: ISS Refeeds | E20: =G32*'QBRM COST AVOIDANCE INPUTS'!G37 -> 234.03657 | I20: or finalized
F21: =F18*(1-'QBRM COST AVOIDANCE INPUTS'!G34) -> 24.694117
F23: Out RCR
F25: =G25+F21 -> 10024.694 | G25: =C5 -> 10000 | H25: =G25*(1-'QBRM COST AVOIDANCE INPUTS'!G46) -> 202
B26: Out LMLM | H26: =F21*(1-'QBRM COST AVOIDANCE INPUTS'!G46) -> 0.49882117 | I26: Out REC
B28: =C28 -> 19.125177 | C28: =C32 -> 19.125177 | F28: =F21*'QBRM COST AVOIDANCE INPUTS'!G46 -> 24.195296 | G28: =G25*'QBRM COST AVOIDANCE INPUTS'!G46 -> 9798 | I28: =J28+H26 -> 202.49882 | J28: =H25 -> 202
H29: =H26 -> 0.49882117
E30: OSS Refeeds | F30: Out OSS | I30: =J28 -> 202
E31: =G32*'QBRM COST AVOIDANCE INPUTS'!G38 -> 129.64351
C32: =G32*'QBRM COST AVOIDANCE INPUTS'!G39 -> 19.125177 | F32: =G32+(F28+E31+H29)*(1-'QBRM COST AVOIDANCE INPUTS'!G47) -> 9316.0441 | G32: =(G28+I30)*(1-'QBRM COST AVOIDANCE INPUTS'!G47) -> 9174.4478 | H32: =(G28+I30)*'QBRM COST AVOIDANCE INPUTS'!G47 -> 825.55217 | I32: Initial leakage | K32: =H32+H33 -> 838.29355 | L32: To outgoing manual operations
C33: ID Tag Errors | H33: =(F28+E31+H29)*'QBRM COST AVOIDANCE INPUTS'!G47 -> 12.741376 | I33: Subsequent leakage for
I34: reprocessed mail
G37: =G32*'QBRM COST AVOIDANCE INPUTS'!G40 -> 287.57855 | I37: Initial rejects | K37: =G37+G38 -> 297.92509 | L37: To outgoing manual operations
G38: =(F32-G32)*SUM('QBRM COST AVOIDANCE INPUTS'!G37:G40) -> 10.346544 | I38: Subsequent rejects for
E39: =(F32-G32)*'QBRM COST AVOIDANCE INPUTS'!G36 -> 131.2497 | F39: =G32*'QBRM COST AVOIDANCE INPUTS'!G36 -> 8504.064 | I39: reprocessed mail
L40: Out Prim Auto
F41: To automation operations | O41: To outgoing manual operations
F42: or finalized | L42: =M42 -> 0 | M42: 0 | N42: =M42*(1-'QBRM COST AVOIDANCE INPUTS'!G41) -> 0
M45: =M42*'QBRM COST AVOIDANCE INPUTS'!G41 -> 0
M47: To downstream
M48: automation operations
M49: or finalized

Sheet HAND COSTS
A1: ='HAND FLOW'!A1 -> FIRST-CLASS SINGLE-PIECE HANDWRITTEN REPLY MAIL CARDS / LETTERS
A2: COST SHEET
C4: ="(1)" -> (1) | D4: ="(2)" -> (2) | E4: ="(3)" -> (3) | F4: ="(4)" -> (4) | G4: ="(5)" -> (5) | H4: ="(6)" -> (6) | I4: ="(7)" -> (7) | J4: ="(8)" -> (8) | K4: ="(9)" -> (9)
F6: Direct | H6: Premium | I6: Premium | J6: Total | K6: Weighted
D7: Pieces | E7: Wage | F7: Cents | G7: Piggyback | H7: Pay | I7: Pay | J7: Cents | K7: Cents
A8: Operation | C8: TPH | D8: Per Hour | E8: Rate | F8: Per Piece | G8: Factor | H8: Factor | I8: Adjust | J8: Per Piece | K8: Per Piece
B9: OUT ISS | C9: ='HAND FLOW'!$F$18 -> 253.16175 | D9: ='QBRM COST AVOIDANCE INPUTS'!$G$13/'QBRM COST AVOIDANCE INPUTS'!$G$20 -> 6833.2327 | E9: ='QBRM COST AVOIDANCE INPUTS'!$G$8 -> 50.107175 | F9: =E9*100/D9 -> 0.73328652 | G9: ='QBRM COST AVOIDANCE INPUTS'!$G$27 -> 1.6888485 | H9: ='QBRM COST AVOIDANCE INPUTS'!$G$10 -> 1.0126008 | I9: =(H9-1)*F9 -> 0.0092400318 | J9: =F9*G9+I9 -> 1.2476499 | K9: =C9*J9/'HAND FLOW'!$C$5 -> 0.031585722
B10: OUT RCR | C10: ='HAND FLOW'!$F$25 -> 10024.694 | D10: ="---" -> --- | E10: ="---" -> --- | F10: ="---" -> --- | G10: ="---" -> --- | H10: ="---" -> --- | I10: ="---" -> --- | J10: =100*'QBRM COST AVOIDANCE INPUTS'!G44/'QBRM COST AVOIDANCE INPUTS'!G45 -> 0.27889541 | K10: =C10*J10/'HAND FLOW'!$C$5 -> 0.27958412
B11: OUT REC | C11: ='HAND FLOW'!$I$28 -> 202.49882 | D11: ='QBRM COST AVOIDANCE INPUTS'!$G$14/'QBRM COST AVOIDANCE INPUTS'!$G$21 -> 846.86663 | E11: ='QBRM COST AVOIDANCE INPUTS'!$G$7 -> 54.14236 | F11: =E11*100/D11 -> 6.393257 | G11: ='QBRM COST AVOIDANCE INPUTS'!$G$28 -> 1.2615773 | H11: ='QBRM COST AVOIDANCE INPUTS'!$G$10 -> 1.0126008 | I11: =(H11-1)*F11 -> 0.080560458 | J11: =F11*G11+I11 -> 8.1461485 | K11: =C11*J11/'HAND FLOW'!$C$5 -> 0.16495855
B12: OUT OSS | C12: ='HAND FLOW'!$F$32 -> 9316.0441 | D12: ='QBRM COST AVOIDANCE INPUTS'!$G$15/'QBRM COST AVOIDANCE INPUTS'!$G$22 -> 6833.2327 | E12: ='QBRM COST AVOIDANCE INPUTS'!$G$8 -> 50.107175 | F12: =E12*100/D12 -> 0.73328652 | G12: ='QBRM COST AVOIDANCE INPUTS'!$G$29 -> 1.6888485 | H12: ='QBRM COST AVOIDANCE INPUTS'!$G$10 -> 1.0126008 | I12: =(H12-1)*F12 -> 0.0092400318 | J12: =F12*G12+I12 -> 1.2476499 | K12: =C12*J12/'HAND FLOW'!$C$5 -> 1.1623161
B13: OUT LMLM | C13: ='HAND FLOW'!$B$28 -> 19.125177 | D13: ='QBRM COST AVOIDANCE INPUTS'!$G$16/'QBRM COST AVOIDANCE INPUTS'!$G$23 -> 1983.2154 | E13: ='QBRM COST AVOIDANCE INPUTS'!$G$8 -> 50.107175 | F13: =E13*100/D13 -> 2.5265624 | G13: ='QBRM COST AVOIDANCE INPUTS'!$G$30 -> 3.4396835 | H13: ='QBRM COST AVOIDANCE INPUTS'!$G$10 -> 1.0126008 | I13: =(H13-1)*F13 -> 0.031836828 | J13: =F13*G13+I13 -> 8.7224117 | K13: =C13*J13/'HAND FLOW'!$C$5 -> 0.016681767
B14: OUT PRIM AUTO | C14: 0 | D14: ='QBRM COST AVOIDANCE INPUTS'!$G$17/'QBRM COST AVOIDANCE INPUTS'!$G$24 -> 6833.2327 | E14: ='QBRM COST AVOIDANCE INPUTS'!$G$8 -> 50.107175 | F14: =E14*100/D14 -> 0.73328652 | G14: ='QBRM COST AVOIDANCE INPUTS'!$G$31 -> 1.6888485 | H14: ='QBRM COST AVOIDANCE INPUTS'!$G$10 -> 1.0126008 | I14: =(H14-1)*F14 -> 0.0092400318 | J14: =F14*G14+I14 -> 1.2476499 | K14: =C14*J14/'HAND FLOW'!$C$5 -> 0
B15: OUT PRIM Manual | C15: ='HAND FLOW'!K32+'HAND FLOW'!K37 -> 1136.2186 | D15: ='QBRM COST AVOIDANCE INPUTS'!$G$18/'QBRM COST AVOIDANCE INPUTS'!$G$25 -> 631.4274 | E15: ='QBRM COST AVOIDANCE INPUTS'!$G$8 -> 50.107175 | F15: =E15*100/D15 -> 7.9355402 | G15: ='QBRM COST AVOIDANCE INPUTS'!$G$32 -> 1.2988119 | H15: ='QBRM COST AVOIDANCE INPUTS'!$G$10 -> 1.0126008 | I15: =(H15-1)*F15 -> 0.099994533 | J15: =F15*G15+I15 -> 10.406769 | K15: =C15*J15/'HAND FLOW'!$C$5 -> 1.1824365
K16: ="(10)" -> (10)
J17: MODEL COST = | K17: =SUM(K9:K15) -> 2.8375627
A19: ="(1)" -> (1) | B19: Volumes From "HAND FLOW" worksheet | F19: ="(6)" -> (6) | G19: From "QBRM COST AVOIDANCE INPUTS" worksheet
A20: ="(2)" -> (2) | B20: Productivities / Volume Variability Factors from | F20: ="(7)" -> (7) | G20: [ (6) - 1 ] * (4)
B21: "QBRM COST AVOIDANCE INPUTS" worksheet | F21: ="(8)" -> (8) | G21: (4) * (5) + (7)
A22: ="(3)" -> (3) | B22: From "QBRM COST AVOIDANCE INPUTS" worksheet | F22: ="(9)" -> (9) | G22: (1) * (8) / 10,000 Pieces
A23: ="(4)" -> (4) | B23: [ (3) * (100 cents/dollar) ] / (2) | F23: ="(10)" -> (10) | G23: Sum (9)
A24: ="(5)" -> (5) | B24: From "QBRM COST AVOIDANCE INPUTS" worksheet

Sheet QBRM COSTS
A1: ='QBRM FLOW'!A1 -> FIRST-CLASS SINGLE-PIECE QBRM CARDS / LETTERS
A2: COST SHEET
C4: ="(1)" -> (1) | D4: ="(2)" -> (2) | E4: ="(3)" -> (3) | F4: ="(4)" -> (4) | G4: ="(5)" -> (5) | H4: ="(6)" -> (6) | I4: ="(7)" -> (7) | J4: ="(8)" -> (8) | K4: ="(9)" -> (9)
F6: Direct | H6: Premium | I6: Premium | J6: Total | K6: Weighted
D7: Pieces | E7: Wage | F7: Cents | G7: Piggyback | H7: Pay | I7: Pay | J7: Cents | K7: Cents
A8: Operation | C8: TPH | D8: Per Hour | E8: Rate | F8: Per Piece | G8: Factor | H8: Factor | I8: Adjust | J8: Per Piece | K8: Per Piece
B9: OUT ISS | C9: ='QBRM FLOW'!$F$18 -> 0 | D9: ='QBRM COST AVOIDANCE INPUTS'!$G$13/'QBRM COST AVOIDANCE INPUTS'!$G$20 -> 6833.2327 | E9: ='QBRM COST AVOIDANCE INPUTS'!$G$8 -> 50.107175 | F9: =E9*100/D9 -> 0.73328652 | G9: ='QBRM COST AVOIDANCE INPUTS'!$G$27 -> 1.6888485 | H9: ='QBRM COST AVOIDANCE INPUTS'!$G$10 -> 1.0126008 | I9: =(H9-1)*F9 -> 0.0092400318 | J9: =F9*G9+I9 -> 1.2476499 | K9: =(C9*J9)/'QBRM FLOW'!$C$5 -> 0
B10: OUT RCR | C10: ='QBRM FLOW'!$F$25 -> 0 | D10: ="---" -> --- | E10: ="---" -> --- | F10: ="---" -> --- | G10: ="---" -> --- | H10: ="---" -> --- | I10: ="---" -> --- | J10: =100*'QBRM COST AVOIDANCE INPUTS'!G44/'QBRM COST AVOIDANCE INPUTS'!G45 -> 0.27889541 | K10: =(C10*J10)/'QBRM FLOW'!$C$5 -> 0
B11: OUT REC | C11: ='QBRM FLOW'!$I$28 -> 0 | D11: ='QBRM COST AVOIDANCE INPUTS'!$G$14/'QBRM COST AVOIDANCE INPUTS'!$G$21 -> 846.86663 | E11: ='QBRM COST AVOIDANCE INPUTS'!$G$7 -> 54.14236 | F11: =E11*100/D11 -> 6.393257 | G11: ='QBRM COST AVOIDANCE INPUTS'!$G$28 -> 1.2615773 | H11: ='QBRM COST AVOIDANCE INPUTS'!$G$10 -> 1.0126008 | I11: =(H11-1)*F11 -> 0.080560458 | J11: =F11*G11+I11 -> 8.1461485 | K11: =(C11*J11)/'QBRM FLOW'!$C$5 -> 0
B12: OUT OSS | C12: ='QBRM FLOW'!$F$32 -> 0 | D12: ='QBRM COST AVOIDANCE INPUTS'!$G$15/'QBRM COST AVOIDANCE INPUTS'!$G$22 -> 6833.2327 | E12: ='QBRM COST AVOIDANCE INPUTS'!$G$8 -> 50.107175 | F12: =E12*100/D12 -> 0.73328652 | G12: ='QBRM COST AVOIDANCE INPUTS'!$G$29 -> 1.6888485 | H12: ='QBRM COST AVOIDANCE INPUTS'!$G$10 -> 1.0126008 | I12: =(H12-1)*F12 -> 0.0092400318 | J12: =F12*G12+I12 -> 1.2476499 | K12: =(C12*J12)/'QBRM FLOW'!$C$5 -> 0
B13: OUT LMLM | C13: ='QBRM FLOW'!$B$28 -> 0 | D13: ='QBRM COST AVOIDANCE INPUTS'!$G$16/'QBRM COST AVOIDANCE INPUTS'!$G$23 -> 1983.2154 | E13: ='QBRM COST AVOIDANCE INPUTS'!$G$8 -> 50.107175 | F13: =E13*100/D13 -> 2.5265624 | G13: ='QBRM COST AVOIDANCE INPUTS'!$G$30 -> 3.4396835 | H13: ='QBRM COST AVOIDANCE INPUTS'!$G$10 -> 1.0126008 | I13: =(H13-1)*F13 -> 0.031836828 | J13: =F13*G13+I13 -> 8.7224117 | K13: =(C13*J13)/'QBRM FLOW'!$C$5 -> 0
B14: OUT PRIM AUTO | C14: 10000 | D14: ='QBRM COST AVOIDANCE INPUTS'!$G$17/'QBRM COST AVOIDANCE INPUTS'!$G$24 -> 6833.2327 | E14: ='QBRM COST AVOIDANCE INPUTS'!$G$8 -> 50.107175 | F14: =E14*100/D14 -> 0.73328652 | G14: ='QBRM COST AVOIDANCE INPUTS'!$G$31 -> 1.6888485 | H14: ='QBRM COST AVOIDANCE INPUTS'!$G$10 -> 1.0126008 | I14: =(H14-1)*F14 -> 0.0092400318 | J14: =F14*G14+I14 -> 1.2476499 | K14: =(C14*J14)/'QBRM FLOW'!$C$5 -> 1.2476499
B15: OUT PRIM Manual | C15: ='QBRM FLOW'!N42 -> 274.90987 | D15: ='QBRM COST AVOIDANCE INPUTS'!$G$18/'QBRM COST AVOIDANCE INPUTS'!$G$25 -> 631.4274 | E15: ='QBRM COST AVOIDANCE INPUTS'!$G$8 -> 50.107175 | F15: =E15*100/D15 -> 7.9355402 | G15: ='QBRM COST AVOIDANCE INPUTS'!$G$32 -> 1.2988119 | H15: ='QBRM COST AVOIDANCE INPUTS'!$G$10 -> 1.0126008 | I15: =(H15-1)*F15 -> 0.099994533 | J15: =F15*G15+I15 -> 10.406769 | K15: =(C15*J15)/'QBRM FLOW'!$C$5 -> 0.28609235
K16: ="(10)" -> (10)
J17: MODEL COST = | K17: =SUM(K9:K15) -> 1.5337422
A19: ="(1)" -> (1) | B19: Volumes From "QBRM FLOW" worksheet | F19: ="(6)" -> (6) | G19: From "QBRM COST AVOIDANCE INPUTS" worksheet
A20: ="(2)" -> (2) | B20: Productivities / Volume Variability Factors from | F20: ="(7)" -> (7) | G20: [ (6) - 1 ] * (4)
B21: "QBRM COST AVOIDANCE INPUTS" worksheet | F21: ="(8)" -> (8) | G21: (4) * (5) + (7)
A22: ="(3)" -> (3) | B22: From "QBRM COST AVOIDANCE INPUTS" worksheet | F22: ="(9)" -> (9) | G22: (1) * (8) / 10,000 Pieces
A23: ="(4)" -> (4) | B23: [ (3) * (100 cents/dollar) ] / (2) | F23: ="(10)" -> (10) | G23: Sum (9)
A24: ="(5)" -> (5) | B24: From "QBRM COST AVOIDANCE INPUTS" worksheet

Sheet QBRM FLOW
A1: FIRST-CLASS SINGLE-PIECE QBRM CARDS / LETTERS
A2: MAIL FLOW MODEL
B5: ENTERED = | C5: 10000 | F5: PROCESSED = | G5: =H18+E39+F39+K32+K37+N42+M45 -> 10000
A8: THE AFCS-ISS SEPARATES THE PREBARCODED QBRM AND CRM MAIL PIECES FROM THE RESIDUAL
A9: SINGLE-PIECE MAIL PIECES. THE PREBARCODED MAIL IS THEN ROUTED TO THE AUTOMATION OUTGOING
A10: PRIMARY. CONSEQUENTLY, THE MAIL VOLUME FIRST ENTERS THE "OUT PRIM AUTO" OPERATION BELOW.
A14: OUTGOING RBCS
F16: Out ISS
C18: =C28 -> 0 | F18: =C18+E20 -> 0 | G18: 0 | H18: =F18*'QBRM COST AVOIDANCE INPUTS'!G34 -> 0
I19: To automation operations
D20: ISS Refeeds | E20: =G32*'QBRM COST AVOIDANCE INPUTS'!G37 -> 0 | I20: or finalized
F21: =F18*(1-'QBRM COST AVOIDANCE INPUTS'!G34) -> 0
F23: Out RCR
F25: =G25+F21 -> 0 | G25: 0 | H25: =G25*(1-'QBRM COST AVOIDANCE INPUTS'!G46) -> 0
B26: Out LMLM | H26: =F21*(1-'QBRM COST AVOIDANCE INPUTS'!G46) -> 0 | I26: Out REC
B28: =C28 -> 0 | C28: =C32 -> 0 | F28: =F21*'QBRM COST AVOIDANCE INPUTS'!G46 -> 0 | G28: =G25*'QBRM COST AVOIDANCE INPUTS'!G46 -> 0 | I28: =J28+H26 -> 0 | J28: =H25 -> 0
H29: =H26 -> 0
E30: OSS Refeeds | F30: Out OSS | I30: =J28 -> 0
E31: =G32*'QBRM COST AVOIDANCE INPUTS'!G38 -> 0
C32: =G32*'QBRM COST AVOIDANCE INPUTS'!G39 -> 0 | F32: =G32+(F28+E31+H29)*(1-'QBRM COST AVOIDANCE INPUTS'!G47) -> 0 | G32: =(G28+I30)*(1-'QBRM COST AVOIDANCE INPUTS'!G47) -> 0 | H32: =(G28+I30)*'QBRM COST AVOIDANCE INPUTS'!G47 -> 0 | I32: Initial leakage | K32: =H32+H33 -> 0 | L32: To outgoing manual operations
C33: ID Tag Errors | H33: =(F28+E31+H29)*'QBRM COST AVOIDANCE INPUTS'!G47 -> 0 | I33: Subsequent leakage for
I34: reprocessed mail
G37: =G32*'QBRM COST AVOIDANCE INPUTS'!G40 -> 0 | I37: Initial rejects | K37: =G37+G38 -> 0 | L37: To outgoing manual operations
G38: =(F32-G32)*SUM('QBRM COST AVOIDANCE INPUTS'!G37:G40) -> 0 | I38: Subsequent rejects for
E39: =(F32-G32)*'QBRM COST AVOIDANCE INPUTS'!G36 -> 0 | F39: =G32*'QBRM COST AVOIDANCE INPUTS'!G36 -> 0 | I39: reprocessed mail
L40: Out Prim Auto
F41: To automation operations | O41: To outgoing manual operations
F42: or finalized | L42: =M42 -> 10000 | M42: =C5 -> 10000 | N42: =M42*(1-'QBRM COST AVOIDANCE INPUTS'!G41) -> 274.90987
M45: =M42*'QBRM COST AVOIDANCE INPUTS'!G41 -> 9725.0901
M47: To downstream
M48: automation operations
M49: or finalized

Sheet QBRM COST AVOIDANCE INPUTS
A1: QBRM SAVINGS ESTIMATE COST MODEL INPUTS
B4: DESCRIPTION | F4: SOURCE | G4: VALUE
A6: 1.) | B6: Wage Rates
C7: Remote Encoding Centers (REC) | F7: USPS-FY25-7, Part 8 | G7: ='[2]Disaggregated wage rates'!$C$6 -> 54.14236
C8: Other Mail Processing | F8: =F7 -> USPS-FY25-7, Part 8 | G8: ='[2]Disaggregated wage rates'!$C$8 -> 50.107175
A10: 2.) | B10: Premium Pay Adjustment Factor | F10: USPS-FY25-7, Part 7 | G10: ='[2]Premium Pay Fctrs'!$D$7 -> 1.0126008
A12: 3.) | B12: Productivities
C13: Out Input Subsystem (ISS) | F13: USPS-FY25-23 | G13: ='[3]FY25 Table'!$I$13 -> 6758.7505
C14: Out REC | F14: =F13 -> USPS-FY25-23 | G14: ='[4]Prod Calc'!$E$13 -> 739.31457
C15: Out Output Subsystem (OSS) | F15: =F13 -> USPS-FY25-23 | G15: =G13 -> 6758.7505
C16: Out LCREM | F16: =F13 -> USPS-FY25-23 | G16: ='[3]FY25 Table'!$I$10 -> 1731.3471
C17: Out Prim Auto | F17: =F13 -> USPS-FY25-23 | G17: =G13 -> 6758.7505
C18: Out Prim Manual | F18: =F13 -> USPS-FY25-23 | G18: 614
A19: 4.) | B19: Volume Variability Factors
C20: Out ISS | F20: =F10 -> USPS-FY25-7, Part 7 | G20: ='[2]volume-variability factors'!$G$11 -> 0.9891
C21: Out REC | F21: =F20 -> USPS-FY25-7, Part 7 | G21: ='[2]volume-variability factors'!$G$27 -> 0.873
C22: Out OSS | F22: =F10 -> USPS-FY25-7, Part 7 | G22: =G20 -> 0.9891
C23: Out LMLM | F23: =F20 -> USPS-FY25-7, Part 7 | G23: =G21 -> 0.873
C24: Out Prim Auto | F24: =F23 -> USPS-FY25-7, Part 7 | G24: =G20 -> 0.9891
C25: Out Prim Manual | F25: =F23 -> USPS-FY25-7, Part 7 | G25: ='[2]volume-variability factors'!$G$23 -> 0.9724
A26: 5.) | B26: Piggyback Factors
C27: Out ISS | F27: USPS-FY25-25 | G27: ='[5]MP Piggybacks'!$J$68 -> 1.6888485
C28: Out REC | F28: =F27 -> USPS-FY25-25 | G28: ='[5]MP Piggybacks'!$J$77 -> 1.2615773
C29: Out OSS | F29: =F27 -> USPS-FY25-25 | G29: =G27 -> 1.6888485
C30: Out LCREM & LMLM | F30: =F27 -> USPS-FY25-25 | G30: ='[5]MP Piggybacks'!$J$71 -> 3.4396835
C31: Out Prim Auto | F31: =F27 -> USPS-FY25-25 | G31: =G27 -> 1.6888485
C32: Out Prim Manual | F32: =F27 -> USPS-FY25-25 | G32: ='[5]MP Piggybacks'!$J$15 -> 1.2988119
A33: 6.) | B33: Accept / Upgrade Rates
C34: DIOSS Accept Rate | F34: USPS-FY25-10 | G34: =[6]Letters!$C$6 -> 0.90245715
C35: OSS Reject Rates
D36: Finalized | F36: USPS-FY08-10 | G36: =[7]Letters!C9 -> 0.92692925
D37: ISS Refeeds | F37: USPS-FY08-10 | G37: =[7]Letters!C10 -> 0.025509608
D38: OSS Refeeds | F38: USPS-FY08-10 | G38: =[7]Letters!C11 -> 0.014130933
D39: LMLM | F39: USPS-FY08-10 | G39: =[7]Letters!C12 -> 0.0020846134
D40: Manual | F40: USPS-FY08-10 | G40: =[7]Letters!C13 -> 0.031345597
C41: Automation Outgoing Primary Acceptance Rate | F41: FY25 webEOR Data | G41: =[6]Letters!$C$15 -> 0.97250901
A43: 7.) | B43: Remote Barcoding System (RBCS) Data
C44: Remote Computer Read (RCR) Costs | F44: USPS-FY25-25, | G44: =1000*'[5]MP Piggybacks'!$B$75 -> 50188015
C45: RCR Images Processed | F45: FY19 RBCS Data | G45: =[8]RBCS!$S$5+[8]RBCS!$S$8 -> 17995281893
C46: ISS/RCR Finalization Rate | F46: FY25 RBCS Data | G46: 0.9798
...

Sheet BRM FEES SUMMARY
A1: B. BRM FEE SUMMARY
A5: Description | B5: Cost ($)
A7: Annual Permit Fee | B7: ='ANNUAL PERMIT'!I16 -> 148.77216
A9: Annual Accounting Fee | B9: ='ANNUAL ACCOUNTING '!J9 -> 368.19202
A11: QBRM Quarterly Fee | B11: ='QBRM QUARTERLY'!N17 -> 129.53125
A13: Non-Letter Size BRM Monthly Fee | B13: ='NONLETTER SIZE BRM MONTHLY '!M17 -> 451.78979
A16: Description | B16: Cost (Cents)
A18: High Volume QBRM Per-Piece Fee | B18: ='HI VOL QBRM '!K14 -> 0.89359852
A20: Basic QBRM Per-Piece Fee | B20: ='BASIC QBRM '!K20 -> 2.1288068
A22: High Volume BRM Per-Piece Fee | B22: ='HI VOL BRM'!K20 -> 4.1717454
A24: Basic BRM Per-Piece Fee | B24: ='BASIC BRM'!L42 -> 56.216948
A26: Non-Letter Size BRM Per-Piece Fee | B26: ='NONLETTER SIZE BRM'!I9 -> 0.30997547

Sheet ANNUAL PERMIT
A1: ANNUAL PERMIT FEE
C4: ="(1)" -> (1) | D4: ="(2)" -> (2) | E4: ="(3)" -> (3) | F4: ="(4)" -> (4) | G4: ="(5)" -> (5) | H4: ="(6)" -> (6) | I4: ="(7)" -> (7)
H6: Annual
E7: Annual | G7: Premium | H7: Premium | I7: Annual
C8: Minutes | D8: Wage | E8: Direct | F8: Piggyback | G8: Pay | H8: Pay | I8: Total
A9: Task | C9: Per Account | D9: Rate | E9: Cost | F9: Factor | G9: Factor | H9: Adjustment | I9: Cost
A10: Issuance | C10: 112.2 | D10: ='BRM FEE INPUTS'!H52 -> 50.107175 | E10: =C10/60*D10 -> 93.700416 | F10: ='BRM FEE INPUTS'!H59 -> 1.2907912 | G10: ='BRM FEE INPUTS'!H64 -> 1.0126008 | H10: =(G10-1)*E10 -> 1.1807047 | I10: =E10*F10+H10 -> 122.12838
A12: Literature | C12: ="---" -> --- | D12: ="---" -> --- | E12: ="---" -> --- | F12: ="---" -> --- | G12: ="---" -> --- | H12: ="---" -> --- | I12: 0.7813 | J12: ="(8)" -> (8)
A14: Revocations | C14: 23.76 | D14: ='BRM FEE INPUTS'!H52 -> 50.107175 | E14: =C14/60*D14 -> 19.842441 | F14: ='BRM FEE INPUTS'!H59 -> 1.2907912 | G14: ='BRM FEE INPUTS'!H64 -> 1.0126008 | H14: =(G14-1)*E14 -> 0.25003158 | I14: =E14*F14+H14 -> 25.86248
I16: =SUM(I10:I14) -> 148.77216 | J16: ="(9)" -> (9)
A19: ="(1)" -> (1) | B19: Docket No. R80-1, USPS LR-C-9, page 4
A20: ="(2)" -> (2) | B20: From "BRM FEE INPUTS" worksheet
A21: ="(3)" -> (3) | B21: (1) * (2) / (60 minutes per hour)
A22: ="(4)" -> (4) | B22: From "BRM FEE INPUTS" worksheet
A23: ="(5)" -> (5) | B23: From "BRM FEE INPUTS" worksheet
A24: ="(6)" -> (6) | B24: [ (5) - 1 ] * (3)
A25: ="(7)" -> (7) | B25: (3) * (4) + (6)
A26: ="(8)" -> (8) | B26: Annual per piece Literature costs from MDC, Topeka KS
A27: ="(9)" -> (9) | B27: Sum (7)

Sheet QBRM QUARTERLY
A1: QBRM QUARTERLY FEE (RATING AND BILLING ACTIVITIES)
C4: ="(1)" -> (1) | D4: ="(2)" -> (2) | E4: ="(3)" -> (3) | F4: ="(4)" -> (4) | G4: ="(5)" -> (5) | H4: ="(6)" -> (6) | I4: ="(7)" -> (7) | J4: ="(8)" -> (8) | K4: ="(9)" -> (9) | L4: ="(10)" -> (10) | M4: ="(11)" -> (11) | N4: ="(12)" -> (12)
D7: Daily | E7: Delivery | F7: Quarterly | G7: Quarterly | I7: Quarterly | K7: Premium | L7: Premium | M7: Quarterly | N7: Weighted
D8: Minutes Per | E8: Days Per | F8: Minutes Per | G8: Hours Per | H8: Wage | I8: Direct | J8: Piggyback | K8: Pay | L8: Pay | M8: Total | N8: Total
A9: Postage Due Method | C9: Volume % | D9: Account | E9: Year | F9: Account | G9: Account | H9: Rate | I9: Cost | J9: Factor | K9: Factor | L9: Adjustment | M9: Cost | N9: Cost
A12: PostalOne! Bill | C12: 0.761 | D12: ='BRM FEE INPUTS'!$H$27 -> 1.417418 | E12: 303 | F12: =D12*(E12/4) -> 107.36941 | G12: =F12/60 -> 1.7894902 | H12: ='BRM FEE INPUTS'!$H$52 -> 50.107175 | I12: =H12*G12 -> 89.666298 | J12: ='BRM FEE INPUTS'!$H$58 -> 1.2907912 | K12: ='BRM FEE INPUTS'!$H$64 -> 1.0126008 | L12: =(K12-1)*I12 -> 1.1298714 | M12: =I12*J12+L12 -> 116.87034 | N12: =M12*C12 -> 88.938329
A14: Manual Bill | C14: 0.239 | D14: ='BRM FEE INPUTS'!$H$28 -> 2.0598993 | E14: 303 | F14: =D14*(E14/4) -> 156.03737 | G14: =F14/60 -> 2.6006229 | H14: ='BRM FEE INPUTS'!$H$52 -> 50.107175 | I14: =H14*G14 -> 130.30986 | J14: ='BRM FEE INPUTS'!$H$58 -> 1.2907912 | K14: ='BRM FEE INPUTS'!$H$64 -> 1.0126008 | L14: =(K14-1)*I14 -> 1.6420147 | M14: =I14*J14+L14 -> 169.84484 | N14: =M14*C14 -> 40.592917
C17: =SUM(C10:C14) -> 1 | N17: =SUM(N10:N14) -> 129.53125 | O17: ="(13)" -> (13)
A20: ="(1)" -> (1) | B20: Docket No. R2006-1, USPS-LR-L-34
A21: ="(2)" -> (2) | B21: From "BRM FEE INPUTS" worksheet
A22: ="(3)" -> (3) | B22: RPW
A23: ="(4)" -> (4) | B23: (2) * [ (3) / 4 ]
A24: ="(5)" -> (5) | B24: (4) / 60
A25: ="(6)" -> (6) | B25: From "BRM FEE INPUTS" worksheet
A26: ="(7)" -> (7) | B26: (5) * (6)
A27: ="(8)" -> (8) | B27: From "BRM FEE INPUTS" worksheet
A28: ="(9)" -> (9) | B28: From "BRM FEE INPUTS" worksheet
A29: ="(10)" -> (10) | B29: [ (9) - 1 ] * (7)
A30: ="(11)" -> (11) | B30: (7) * (8) + (10)
A31: ="(12)" -> (12) | B31: (1) * (11)
A32: ="(13)" -> (13) | B32: Sum (12)
B56: `

Sheet ANNUAL ACCOUNTING 
A1: ANNUAL ACCOUNTING FEE (OVERSIGHT AND MAINTENANCE ACTIVITIES)
C3: ="(1)" -> (1) | D3: ="(2)" -> (2) | E3: ="(3)" -> (3) | F3: ="(4)" -> (4) | G3: ="(5)" -> (5) | H3: ="(6)" -> (6) | I3: ="(7)" -> (7) | J3: ="(8)" -> (8)
I5: Annual
C6: Weekly | D6: Annual | F6: Annual | H6: Premium | I6: Premium | J6: Annual
C7: Workhrs | D7: Workhrs | E7: Wage | F7: Direct | G7: Piggyback | H7: Pay | I7: Pay | J7: Total
A8: Task | C8: Per Account | D8: Per Account | E8: Rate | F8: Cost | G8: Factor | H8: Factor | I8: Adjustment | J8: Cost
A9: Account oversight and maintenance | C9: =6.505/60 -> 0.10841667 | D9: =C9*52 -> 5.6376667 | E9: ='BRM FEE INPUTS'!H52 -> 50.107175 | F9: =E9*D9 -> 282.48755 | G9: ='BRM FEE INPUTS'!H59 -> 1.2907912 | H9: ='BRM FEE INPUTS'!H64 -> 1.0126008 | I9: =(H9-1)*F9 -> 3.5595826 | J9: =F9*G9+I9 -> 368.19202
A12: ="(1)" -> (1) | B12: USPS-LR-L-34
A13: ="(2)" -> (2) | B13: (1) * 52
A14: ="(3)" -> (3) | B14: From "BRM FEE INPUTS" worksheet
A15: ="(4)" -> (4) | B15: (2) * (3)
A16: ="(5)" -> (5) | B16: From "BRM FEE INPUTS" worksheet
A17: ="(6)" -> (6) | B17: From "BRM FEE INPUTS" worksheet
A18: ="(7)" -> (7) | B18: [ (6) - 1 ] * (4)
A19: ="(8)" -> (8) | B19: (4) * (5) + (7)

Sheet NONLETTER SIZE BRM MONTHLY 
A1: NONLETTER-SIZE BRM MONTHLY FEE (BILLING AND SAMPLING)
C4: ="(1)" -> (1) | D4: ="(2)" -> (2) | E4: ="(3)" -> (3) | F4: ="(4)" -> (4) | G4: ="(5)" -> (5) | H4: ="(6)" -> (6) | I4: ="(7)" -> (7) | J4: ="(8)" -> (8) | K4: ="(9)" -> (9) | L4: ="(10)" -> (10) | M4: ="(11)" -> (11)
D7: Delivery | E7: Delivery | I7: Monthly | K7: Premium | L7: Premium | M7: Monthly
C8: Minutes | D8: Days Per | E8: Days Per | F8: Minutes | G8: Hours Per | H8: Wage | I8: Direct | J8: Piggyback | K8: Pay | L8: Pay | M8: Total
A9: Postage Due Method | C9: Per Day | D9: Year | E9: Month | F9: Per Month | G9: Month | H9: Rate | I9: Cost | J9: Factor | K9: Factor | L9: Adjustment | M9: Cost
A12: Billing Time | C12: ='BRM FEE INPUTS'!H31 -> 4.6037639 | D12: 303 | E12: =D12/12 -> 25.25 | F12: =C12*E12 -> 116.24504 | G12: =F12/60 -> 1.9374173 | H12: ='BRM FEE INPUTS'!$H$52 -> 50.107175 | I12: =G12*H12 -> 97.078506 | J12: ='BRM FEE INPUTS'!$H$58 -> 1.2907912 | K12: ='BRM FEE INPUTS'!$H$64 -> 1.0126008 | L12: =(K12-1)*I12 -> 1.2232715 | M12: =I12*J12+L12 -> 126.53135
A14: Sampling Time | C14: ='BRM FEE INPUTS'!H32 -> 49.80278 | D14: 303 | E14: 6 | F14: =C14*E14 -> 298.81668 | G14: =F14/60 -> 4.980278 | H14: ='BRM FEE INPUTS'!$H$52 -> 50.107175 | I14: =G14*H14 -> 249.54766 | J14: ='BRM FEE INPUTS'!$H$58 -> 1.2907912 | K14: ='BRM FEE INPUTS'!$H$64 -> 1.0126008 | L14: =(K14-1)*I14 -> 3.1445121 | M14: =I14*J14+L14 -> 325.25844
M17: =SUM(M12:M14) -> 451.78979 | N17: ="(12)" -> (12)
A21: ="(1)" -> (1) | B21: From "BRM FEE INPUTS" worksheet
A22: ="(2)" -> (2) | B22: RPW
A23: ="(3)" -> (3) | B23: Billing: (2) / 12
B24: Sampling: 6 Sampling Days (1 Week Per Month)
A25: ="(4)" -> (4) | B25: (1) * (3)
A26: ="(5)" -> (5) | B26: (4) / 60
A27: ="(6)" -> (6) | B27: From "BRM FEE INPUTS" worksheet
A28: ="(7)" -> (7) | B28: (5) * (6)
A29: ="(8)" -> (8) | B29: From "BRM FEE INPUTS" worksheet
A30: ="(9)" -> (9) | B30: From "BRM FEE INPUTS" worksheet
A31: ="(10)" -> (10) | B31: [ (9) - 1 ] * (7)
A32: ="(11)" -> (11) | B32: (7) * (8) + (10)
A33: ="(12)" -> (12) | B33: Sum (11)

Sheet HI VOL QBRM 
A1: HIGH VOLUME QBRM PER-PIECE FEE (COUNTING ACTIVITIES)
C4: ="(1)" -> (1) | D4: ="(2)" -> (2) | E4: ="(3)" -> (3) | F4: ="(4)" -> (4) | G4: ="(5)" -> (5) | H4: ="(6)" -> (6) | I4: ="(7)" -> (7) | J4: ="(8)" -> (8) | K4: ="(9)" -> (9)
F6: Direct | H6: Premium | I6: Premium | J6: Total | K6: Weighted
C7: Volume | D7: Marginal | E7: Wage | F7: Cents Per | G7: Piggyback | H7: Pay | I7: Pay | J7: Cents Per | K7: Cents Per
A8: Counting Method | C8: Percentage | D8: Productivity | E8: Rate | F8: Piece | G8: Factor | H8: Factor | I8: Adjustment | J8: Piece | K8: Piece
B9: WebBRMAS | C9: 0.034 | D9: ='BRM FEE INPUTS'!H7 -> 165386.68 | E9: ='BRM FEE INPUTS'!$H$52 -> 50.107175 | F9: =E9*100/D9 -> 0.030296983 | G9: ='BRM FEE INPUTS'!$H$58 -> 1.2907912 | H9: ='BRM FEE INPUTS'!$H$64 -> 1.0126008 | I9: =(H9-1)*F9 -> 0.00038176766 | J9: =F9*G9+I9 -> 0.039488846 | K9: =C9*J9 -> 0.0013426208
B10: WebEOR | C10: 0.454 | D10: ='BRM FEE INPUTS'!H8 -> 74266.664 | E10: ='BRM FEE INPUTS'!$H$52 -> 50.107175 | F10: =E10*100/D10 -> 0.067469268 | G10: ='BRM FEE INPUTS'!$H$58 -> 1.2907912 | H10: ='BRM FEE INPUTS'!$H$64 -> 1.0126008 | I10: =(H10-1)*F10 -> 0.00085016997 | J10: =F10*G10+I10 -> 0.087938908 | K10: =C10*J10 -> 0.039924264
B11: Counting Machine | C11: 0.1 | D11: ='BRM FEE INPUTS'!H9 -> 5767.5518 | E11: ='BRM FEE INPUTS'!$H$52 -> 50.107175 | F11: =E11*100/D11 -> 0.8687772 | G11: ='BRM FEE INPUTS'!$H$58 -> 1.2907912 | H11: ='BRM FEE INPUTS'!$H$64 -> 1.0126008 | I11: =(H11-1)*F11 -> 0.010947329 | J11: =F11*G11+I11 -> 1.1323573 | K11: =C11*J11 -> 0.11323573
B12: Manual | C12: 0.266 | D12: ='BRM FEE INPUTS'!H10 -> 2478.3084 | E12: ='BRM FEE INPUTS'!$H$52 -> 50.107175 | F12: =E12*100/D12 -> 2.0218296 | G12: ='BRM FEE INPUTS'!$H$58 -> 1.2907912 | H12: ='BRM FEE INPUTS'!$H$64 -> 1.0126008 | I12: =(H12-1)*F12 -> 0.025476768 | J12: =F12*G12+I12 -> 2.6352367 | K12: =C12*J12 -> 0.70097296
B13: Weight Averaging | C13: 0.146 | D13: ='BRM FEE INPUTS'!H11 -> 25011.595 | E13: ='BRM FEE INPUTS'!$H$52 -> 50.107175 | F13: =E13*100/D13 -> 0.20033578 | G13: ='BRM FEE INPUTS'!$H$58 -> 1.2907912 | H13: ='BRM FEE INPUTS'!$H$64 -> 1.0126008 | I13: =(H13-1)*F13 -> 0.0025244007 | J13: =F13*G13+I13 -> 0.26111606 | K13: =C13*J13 -> 0.038122945
C14: =SUM(C9:C13) -> 1 | K14: =SUM(K9:K13) -> 0.89359852 | L14: ="(10)" -> (10)
A17: ="(1)" -> (1) | B17: Docket No. R2006-1, USPS-LR-L-34
A18: ="(2)" -> (2) | B18: From "BRM FEE INPUTS" worksheet
A19: ="(3)" -> (3) | B19: From "BRM FEE INPUTS" worksheet
A20: ="(4)" -> (4) | B20: [ (3) * 100 ] / (2)
A21: ="(5)" -> (5) | B21: From "BRM FEE INPUTS" worksheet
A22: ="(6)" -> (6) | B22: From "BRM FEE INPUTS" worksheet
A23: ="(7)" -> (7) | B23: [ (6) - 1 ] * (4)
A24: ="(8)" -> (8) | B24: (4) * (5) + (7)
A25: ="(9)" -> (9) | B25: (1) * (8)
A26: ="(10)" -> (10) | B26: SUM (8)

Sheet BASIC QBRM 
A1: BASIC QBRM PER-PIECE FEE (COUNTING, RATING, AND BILLING ACTIVITIES)
C4: ="(1)" -> (1) | D4: ="(2)" -> (2) | E4: ="(3)" -> (3) | F4: ="(4)" -> (4) | G4: ="(5)" -> (5) | H4: ="(6)" -> (6) | I4: ="(7)" -> (7) | J4: ="(8)" -> (8) | K4: ="(9)" -> (9)
F6: Direct | H6: Premium | I6: Premium | J6: Total | K6: Weighted
C7: Volume | D7: Marginal | E7: Wage | F7: Cents Per | G7: Piggyback | H7: Pay | I7: Pay | J7: Cents Per | K7: Cents Per
A8: Counting Method | C8: Percentage | D8: Productivity | E8: Rate | F8: Piece | G8: Factor | H8: Factor | I8: Adjustment | J8: Piece | K8: Piece
B9: WebBRMAS | C9: =8.9%+5.8% -> 0.147 | D9: ='BRM FEE INPUTS'!H7 -> 165386.68 | E9: ='BRM FEE INPUTS'!$H$52 -> 50.107175 | F9: =E9*100/D9 -> 0.030296983 | G9: ='BRM FEE INPUTS'!$H$58 -> 1.2907912 | H9: ='BRM FEE INPUTS'!$H$64 -> 1.0126008 | I9: =(H9-1)*F9 -> 0.00038176766 | J9: =F9*G9+I9 -> 0.039488846 | K9: =C9*J9 -> 0.0058048604
B10: WebEOR | C10: 0.359 | D10: ='BRM FEE INPUTS'!H8 -> 74266.664 | E10: ='BRM FEE INPUTS'!$H$52 -> 50.107175 | F10: =E10*100/D10 -> 0.067469268 | G10: ='BRM FEE INPUTS'!$H$58 -> 1.2907912 | H10: ='BRM FEE INPUTS'!$H$64 -> 1.0126008 | I10: =(H10-1)*F10 -> 0.00085016997 | J10: =F10*G10+I10 -> 0.087938908 | K10: =C10*J10 -> 0.031570068
B11: Counting Machine | C11: 0.009 | D11: ='BRM FEE INPUTS'!H9 -> 5767.5518 | E11: ='BRM FEE INPUTS'!$H$52 -> 50.107175 | F11: =E11*100/D11 -> 0.8687772 | G11: ='BRM FEE INPUTS'!$H$58 -> 1.2907912 | H11: ='BRM FEE INPUTS'!$H$64 -> 1.0126008 | I11: =(H11-1)*F11 -> 0.010947329 | J11: =F11*G11+I11 -> 1.1323573 | K11: =C11*J11 -> 0.010191216
B12: Manual | C12: 0.434 | D12: ='BRM FEE INPUTS'!H10 -> 2478.3084 | E12: ='BRM FEE INPUTS'!$H$52 -> 50.107175 | F12: =E12*100/D12 -> 2.0218296 | G12: ='BRM FEE INPUTS'!$H$58 -> 1.2907912 | H12: ='BRM FEE INPUTS'!$H$64 -> 1.0126008 | I12: =(H12-1)*F12 -> 0.025476768 | J12: =F12*G12+I12 -> 2.6352367 | K12: =C12*J12 -> 1.1436927
B13: Weight Averaging | C13: 0.051 | D13: ='BRM FEE INPUTS'!$H$11 -> 25011.595 | E13: ='BRM FEE INPUTS'!$H$52 -> 50.107175 | F13: =E13*100/D13 -> 0.20033578 | G13: ='BRM FEE INPUTS'!$H$58 -> 1.2907912 | H13: ='BRM FEE INPUTS'!$H$64 -> 1.0126008 | I13: =(H13-1)*F13 -> 0.0025244007 | J13: =F13*G13+I13 -> 0.26111606 | K13: =C13*J13 -> 0.013316919
C14: =SUM(C9:C13) -> 1
A16: Rating/Billing Method
B17: PERMIT/Postage Due(PostalOne!) | C17: =81.6%+2.81% -> 0.8441 | D17: ='BRM FEE INPUTS'!H18 -> 9083.7825 | E17: ='BRM FEE INPUTS'!$H$52 -> 50.107175 | F17: =E17*100/D17 -> 0.55161134 | G17: ='BRM FEE INPUTS'!$H$58 -> 1.2907912 | H17: ='BRM FEE INPUTS'!$H$64 -> 1.0126008 | I17: =(H17-1)*F17 -> 0.0069507705 | J17: =F17*G17+I17 -> 0.71896584 | K17: =C17*J17 -> 0.60687907
B18: Manual | C18: =14.72%+0.0087 -> 0.1559 | D18: ='BRM FEE INPUTS'!H21 -> 3208.3364 | E18: ='BRM FEE INPUTS'!$H$52 -> 50.107175 | F18: =E18*100/D18 -> 1.5617806 | G18: ='BRM FEE INPUTS'!$H$58 -> 1.2907912 | H18: ='BRM FEE INPUTS'!$H$64 -> 1.0126008 | I18: =(H18-1)*F18 -> 0.019679759 | J18: =F18*G18+I18 -> 2.0356124 | K18: =C18*J18 -> 0.31735197
C19: =SUM(C17:C18) -> 1
K20: =SUM(K9:K18) -> 2.1288068 | L20: ="(10)" -> (10)
A25: ="(1)" -> (1) | B25: Docket No. R2006-1, USPS-LR-L-34
A26: ="(2)" -> (2) | B26: From "BRM FEE INPUTS" worksheet
A27: ="(3)" -> (3) | B27: From "BRM FEE INPUTS" worksheet
A28: ="(4)" -> (4) | B28: [ (3) * 100 ] / (2)
A29: ="(5)" -> (5) | B29: From "BRM FEE INPUTS" worksheet
A30: ="(6)" -> (6) | B30: From "BRM FEE INPUTS" worksheet
A31: ="(7)" -> (7) | B31: [ (6) - 1 ] * (4)
A32: ="(8)" -> (8) | B32: (4) * (5) + (7)
A33: ="(9)" -> (9) | B33: (1) * (8)
A34: ="(10)" -> (10) | B34: SUM (9)

Sheet HI VOL BRM
A1: HIGH VOLUME BRM PER-PIECE FEE (COUNTING, RATING, AND BILLING ACTIVITIES)
C4: ="(1)" -> (1) | D4: ="(2)" -> (2) | E4: ="(3)" -> (3) | F4: ="(4)" -> (4) | G4: ="(5)" -> (5) | H4: ="(6)" -> (6) | I4: ="(7)" -> (7) | J4: ="(8)" -> (8) | K4: ="(9)" -> (9)
F6: Direct | H6: Premium | I6: Premium | J6: Total | K6: Weighted
C7: Volume | D7: Marginal | E7: Wage | F7: Cents Per | G7: Piggyback | H7: Pay | I7: Pay | J7: Cents Per | K7: Cents Per
A8: Counting Method | C8: Percentage | D8: Productivity | E8: Rate | F8: Piece | G8: Factor | H8: Factor | I8: Adjustment | J8: Piece | K8: Piece
B9: WebBRMAS | C9: 0.0943 | D9: ='BRM FEE INPUTS'!H7 -> 165386.68 | E9: ='BRM FEE INPUTS'!$H$52 -> 50.107175 | F9: =E9*100/D9 -> 0.030296983 | G9: ='BRM FEE INPUTS'!$H$58 -> 1.2907912 | H9: ='BRM FEE INPUTS'!$H$64 -> 1.0126008 | I9: =(H9-1)*F9 -> 0.00038176766 | J9: =F9*G9+I9 -> 0.039488846 | K9: =C9*J9 -> 0.0037237982
B10: WebEOR | C10: 0.1221 | D10: ='BRM FEE INPUTS'!H8 -> 74266.664 | E10: ='BRM FEE INPUTS'!$H$52 -> 50.107175 | F10: =E10*100/D10 -> 0.067469268 | G10: ='BRM FEE INPUTS'!$H$58 -> 1.2907912 | H10: ='BRM FEE INPUTS'!$H$64 -> 1.0126008 | I10: =(H10-1)*F10 -> 0.00085016997 | J10: =F10*G10+I10 -> 0.087938908 | K10: =C10*J10 -> 0.010737341
B11: Counting Machine | C11: 0.0449 | D11: ='BRM FEE INPUTS'!$H$9 -> 5767.5518 | E11: ='BRM FEE INPUTS'!$H$52 -> 50.107175 | F11: =E11*100/D11 -> 0.8687772 | G11: ='BRM FEE INPUTS'!$H$58 -> 1.2907912 | H11: ='BRM FEE INPUTS'!$H$64 -> 1.0126008 | I11: =(H11-1)*F11 -> 0.010947329 | J11: =F11*G11+I11 -> 1.1323573 | K11: =C11*J11 -> 0.050842842
B12: Manual | C12: =72.75%+0.0052 -> 0.7327 | D12: ='BRM FEE INPUTS'!H10 -> 2478.3084 | E12: ='BRM FEE INPUTS'!$H$52 -> 50.107175 | F12: =E12*100/D12 -> 2.0218296 | G12: ='BRM FEE INPUTS'!$H$58 -> 1.2907912 | H12: ='BRM FEE INPUTS'!$H$64 -> 1.0126008 | I12: =(H12-1)*F12 -> 0.025476768 | J12: =F12*G12+I12 -> 2.6352367 | K12: =C12*J12 -> 1.9308379
B13: Weight averaging | C13: 0.006 | D13: ='BRM FEE INPUTS'!$H$11 -> 25011.595 | E13: ='BRM FEE INPUTS'!$H$52 -> 50.107175 | F13: =E13*100/D13 -> 0.20033578 | G13: ='BRM FEE INPUTS'!$H$58 -> 1.2907912 | H13: ='BRM FEE INPUTS'!$H$64 -> 1.0126008 | I13: =(H13-1)*F13 -> 0.0025244007 | J13: =F13*G13+I13 -> 0.26111606 | K13: =C13*J13 -> 0.0015666964
C14: =SUM(C9:C13) -> 1
A16: Rating/Billing Method
B17: PERMIT/Postage Due (PostalOne!) | C17: =71.86%+0.41% -> 0.7227 | D17: ='BRM FEE INPUTS'!H19 -> 4529.5799 | E17: ='BRM FEE INPUTS'!$H$52 -> 50.107175 | F17: =E17*100/D17 -> 1.1062212 | G17: ='BRM FEE INPUTS'!$H$58 -> 1.2907912 | H17: ='BRM FEE INPUTS'!$H$64 -> 1.0126008 | I17: =(H17-1)*F17 -> 0.013939325 | J17: =F17*G17+I17 -> 1.44184 | K17: =C17*J17 -> 1.0420177
B18: Manual | C18: =26.61%+0.0112 -> 0.2773 | D18: ='BRM FEE INPUTS'!H22 -> 1599.8199 | E18: ='BRM FEE INPUTS'!$H$52 -> 50.107175 | F18: =E18*100/D18 -> 3.1320509 | G18: ='BRM FEE INPUTS'!$H$58 -> 1.2907912 | H18: ='BRM FEE INPUTS'!$H$64 -> 1.0126008 | I18: =(H18-1)*F18 -> 0.039466496 | J18: =F18*G18+I18 -> 4.0822902 | K18: =C18*J18 -> 1.1320191
C19: =SUM(C17:C18) -> 1
K20: =SUM(K9:K18) -> 4.1717454 | L20: ="(10)" -> (10)
A24: ="(1)" -> (1) | B24: Docket No. R2006-1, USPS-LR-L-34
A25: ="(2)" -> (2) | B25: From "BRM FEE INPUTS" worksheet
A26: ="(3)" -> (3) | B26: From "BRM FEE INPUTS" worksheet
A27: ="(4)" -> (4) | B27: [ (3) * 100 ] / (2)
A28: ="(5)" -> (5) | B28: From "BRM FEE INPUTS" worksheet
A29: ="(6)" -> (6) | B29: From "BRM FEE INPUTS" worksheet
A30: ="(7)" -> (7) | B30: [ (6) - 1 ] * (4)
A31: ="(8)" -> (8) | B31: (4) * (5) + (7)
A32: ="(9)" -> (9) | B32: (1) * (8)
A33: ="(10)" -> (10) | B33: SUM (9)

Sheet BASIC BRM
A1: BASIC BRM PER-PIECE FEE (COUNTING, RATING, BILLING, COLLECTION, AND ACCOUNT MAINTENANCE ACTIVITIES)
D4: ="(1)" -> (1) | E4: ="(2)" -> (2) | F4: ="(3)" -> (3) | G4: ="(4)" -> (4) | H4: ="(5)" -> (5) | I4: ="(6)" -> (6) | J4: ="(7)" -> (7) | K4: ="(8)" -> (8) | L4: ="(9)" -> (9)
G6: Direct | I6: Premium | J6: Premium | K6: Total | L6: Weighted
D7: Volume | E7: Marginal | F7: Wage | G7: Cents Per | H7: Piggyback | I7: Pay | J7: Pay | K7: Cents Per | L7: Cents Per
A8: Counting Method | D8: Percentage | E8: Productivity | F8: Rate | G8: Piece | H8: Factor | I8: Factor | J8: Adjustment | K8: Piece | L8: Piece
B9: WebBRMAS | D9: 0.0088 | E9: ='BRM FEE INPUTS'!H7 -> 165386.68 | F9: ='BRM FEE INPUTS'!$H$52 -> 50.107175 | G9: =F9*100/E9 -> 0.030296983 | H9: ='BRM FEE INPUTS'!$H$58 -> 1.2907912 | I9: ='BRM FEE INPUTS'!$H$64 -> 1.0126008 | J9: =(I9-1)*G9 -> 0.00038176766 | K9: =G9*H9+J9 -> 0.039488846 | L9: =D9*K9 -> 0.00034750185
B10: WebEOR | D10: 0.0066 | E10: ='BRM FEE INPUTS'!H8 -> 74266.664 | F10: ='BRM FEE INPUTS'!$H$52 -> 50.107175 | G10: =F10*100/E10 -> 0.067469268 | H10: ='BRM FEE INPUTS'!$H$58 -> 1.2907912 | I10: ='BRM FEE INPUTS'!$H$64 -> 1.0126008 | J10: =(I10-1)*G10 -> 0.00085016997 | K10: =G10*H10+J10 -> 0.087938908 | L10: =D10*K10 -> 0.00058039679
B11: Counting Machine | D11: 0.0051 | E11: ='BRM FEE INPUTS'!$H$9 -> 5767.5518 | F11: ='BRM FEE INPUTS'!$H$52 -> 50.107175 | G11: =F11*100/E11 -> 0.8687772 | H11: ='BRM FEE INPUTS'!$H$58 -> 1.2907912 | I11: ='BRM FEE INPUTS'!$H$64 -> 1.0126008 | J11: =(I11-1)*G11 -> 0.010947329 | K11: =G11*H11+J11 -> 1.1323573 | L11: =D11*K11 -> 0.0057750222
B12: Manual | D12: 0.979 | E12: ='BRM FEE INPUTS'!H10 -> 2478.3084 | F12: ='BRM FEE INPUTS'!$H$52 -> 50.107175 | G12: =F12*100/E12 -> 2.0218296 | H12: ='BRM FEE INPUTS'!$H$58 -> 1.2907912 | I12: ='BRM FEE INPUTS'!$H$64 -> 1.0126008 | J12: =(I12-1)*G12 -> 0.025476768 | K12: =G12*H12+J12 -> 2.6352367 | L12: =D12*K12 -> 2.5798967
B13: Weight Averaging | D13: 0.0005 | E13: ='BRM FEE INPUTS'!$H$11 -> 25011.595 | F13: ='BRM FEE INPUTS'!$H$52 -> 50.107175 | G13: =F13*100/E13 -> 0.20033578 | H13: ='BRM FEE INPUTS'!$H$58 -> 1.2907912 | I13: ='BRM FEE INPUTS'!$H$64 -> 1.0126008 | J13: =(I13-1)*G13 -> 0.0025244007 | K13: =G13*H13+J13 -> 0.26111606 | L13: =D13*K13 -> 0.00013055803
D14: =SUM(D9:D13) -> 1
A16: Rating/Billing Method
B17: PERMITS/Postage Due (PostalOne!) | D17: =52.34%+0.2% -> 0.5254 | E17: ='BRM FEE INPUTS'!H20 -> 828.50826 | F17: ='BRM FEE INPUTS'!$H$52 -> 50.107175 | G17: =F17*100/E17 -> 6.0478787 | H17: ='BRM FEE INPUTS'!$H$58 -> 1.2907912 | I17: ='BRM FEE INPUTS'!$H$64 -> 1.0126008 | J17: =(I17-1)*G17 -> 0.076208399 | K17: =G17*H17+J17 -> 7.882757 | L17: =D17*K17 -> 4.1416005
B18: Manual | D18: =46.34%+0.0112 -> 0.4746 | E18: ='BRM FEE INPUTS'!H23 -> 292.62405 | F18: ='BRM FEE INPUTS'!$H$52 -> 50.107175 | G18: =F18*100/E18 -> 17.123396 | H18: ='BRM FEE INPUTS'!$H$58 -> 1.2907912 | I18: ='BRM FEE INPUTS'!$H$64 -> 1.0126008 | J18: =(I18-1)*G18 -> 0.2157693 | K18: =G18*H18+J18 -> 22.318498 | L18: =D18*K18 -> 10.592359
D19: =SUM(D17:D18) -> 1
A21: Collection Method
B22: Box Section Clerk
C23: Pickup BRM at Postage Due Unit | E23: ='BRM FEE INPUTS'!H36 -> 4026.4994 | F23: ='BRM FEE INPUTS'!$H$52 -> 50.107175 | G23: =F23*100/E23 -> 1.2444352 | H23: ='BRM FEE INPUTS'!$H$58 -> 1.2907912 | I23: ='BRM FEE INPUTS'!$H$64 -> 1.0126008 | J23: =(I23-1)*G23 -> 0.015680938 | K23: =G23*H23+J23 -> 1.6219869
C24: Examine and sign due bill (Form 3582-B) | E24: ='BRM FEE INPUTS'!H37 -> 306.46303 | F24: ='BRM FEE INPUTS'!$H$52 -> 50.107175 | G24: =F24*100/E24 -> 16.350153 | H24: ='BRM FEE INPUTS'!$H$58 -> 1.2907912 | I24: ='BRM FEE INPUTS'!$H$64 -> 1.0126008 | J24: =(I24-1)*G24 -> 0.20602579 | K24: =G24*H24+J24 -> 21.310659
C25: Prepare call slip and place in lock box | E25: ='BRM FEE INPUTS'!H38 -> 339.84019 | F25: ='BRM FEE INPUTS'!$H$52 -> 50.107175 | G25: =F25*100/E25 -> 14.744334 | H25: ='BRM FEE INPUTS'!$H$58 -> 1.2907912 | I25: ='BRM FEE INPUTS'!$H$64 -> 1.0126008 | J25: =(I25-1)*G25 -> 0.18579111 | K25: =G25*H25+J25 -> 19.217648
C26: Collect from customer | E26: ='BRM FEE INPUTS'!H39 -> 228.58299 | F26: ='BRM FEE INPUTS'!$H$52 -> 50.107175 | G26: =F26*100/E26 -> 21.92078 | H26: ='BRM FEE INPUTS'!$H$58 -> 1.2907912 | I26: ='BRM FEE INPUTS'!$H$64 -> 1.0126008 | J26: =(I26-1)*G26 -> 0.27622041 | K26: =G26*H26+J26 -> 28.571371
C27: Turn in postage | E27: ='BRM FEE INPUTS'!H40 -> 252.85729 | F27: ='BRM FEE INPUTS'!$H$52 -> 50.107175 | G27: =F27*100/E27 -> 19.816385 | H27: ='BRM FEE INPUTS'!$H$58 -> 1.2907912 | I27: ='BRM FEE INPUTS'!$H$64 -> 1.0126008 | J27: =(I27-1)*G27 -> 0.24970325 | K27: =G27*H27+J27 -> 25.828519
C28: Accept Collections | E28: ='BRM FEE INPUTS'!H41 -> 262.97158 | F28: ='BRM FEE INPUTS'!$H$52 -> 50.107175 | G28: =F28*100/E28 -> 19.054217 | H28: ='BRM FEE INPUTS'!$H$58 -> 1.2907912 | I28: ='BRM FEE INPUTS'!$H$64 -> 1.0126008 | J28: =(I28-1)*G28 -> 0.24009928 | K28: =G28*H28+J28 -> 24.835115
B29: Total Box Section Clerk | D29: 0.01 | K29: =SUM(K23:K28) -> 121.3853 | L29: =K29*D29 -> 1.213853
B31: Carrier
C32: Pickup BRM at Postage Due Unit | E32: ='BRM FEE INPUTS'!H44 -> 3114 | F32: ='BRM FEE INPUTS'!$H$53 -> 48.936478 | G32: =F32*100/E32 -> 1.571499 | H32: ='BRM FEE INPUTS'!$H$60 -> 1.2638248 | I32: ='BRM FEE INPUTS'!$H$64 -> 1.0126008 | J32: =(I32-1)*G32 -> 0.019802219 | K32: =G32*H32+J32 -> 2.0059016
C33: Examine and sign due bill (Form 3582-B) | E33: ='BRM FEE INPUTS'!H45 -> 315 | F33: ='BRM FEE INPUTS'!$H$53 -> 48.936478 | G33: =F33*100/E33 -> 15.53539 | H33: ='BRM FEE INPUTS'!$H$60 -> 1.2638248 | I33: ='BRM FEE INPUTS'!$H$64 -> 1.0126008 | J33: =(I33-1)*G33 -> 0.19575908 | K33: =G33*H33+J33 -> 19.82977
C34: Collect from customer | E34: ='BRM FEE INPUTS'!H46 -> 69 | F34: ='BRM FEE INPUTS'!$H$53 -> 48.936478 | G34: =F34*100/E34 -> 70.922432 | H34: ='BRM FEE INPUTS'!$H$60 -> 1.2638248 | I34: ='BRM FEE INPUTS'!$H$64 -> 1.0126008 | J34: =(I34-1)*G34 -> 0.89368276 | K34: =G34*H34+J34 -> 90.527213
C35: Turn in postage | E35: ='BRM FEE INPUTS'!H47 -> 265 | F35: ='BRM FEE INPUTS'!$H$53 -> 48.936478 | G35: =F35*100/E35 -> 18.466595 | H35: ='BRM FEE INPUTS'!$H$60 -> 1.2638248 | I35: ='BRM FEE INPUTS'!$H$64 -> 1.0126008 | J35: =(I35-1)*G35 -> 0.23269476 | K35: =G35*H35+J35 -> 23.571237
C36: Accept collections | E36: ='BRM FEE INPUTS'!H48 -> 260 | F36: ='BRM FEE INPUTS'!$H$53 -> 48.936478 | G36: =F36*100/E36 -> 18.821722 | H36: ='BRM FEE INPUTS'!$H$60 -> 1.2638248 | I36: ='BRM FEE INPUTS'!$H$64 -> 1.0126008 | J36: =(I36-1)*G36 -> 0.23716966 | K36: =G36*H36+J36 -> 24.02453
B37: Total Carrier | D37: 0.01 | K37: =SUM(K32:K36) -> 159.95865 | L37: =K37*D37 -> 1.5995865
A39: Account Oversight and Maintenance
B40: Postage Due Account (1,000 pcs/yr) | D40: 0.98 | K40: ='ANNUAL ACCOUNTING '!J9*100/1000 -> 36.819202 | L40: =K40*D40 -> 36.082818 | M40: ="(10)" -> (10)
D41: =SUM(D29:D40) -> 1
L42: =SUM(L9:L40) -> 56.216948 | M42: ="(11)" -> (11)
A46: ="(1)" -> (1) | B46: Docket No. R2006-1, USPS-LR-L-34
A47: ="(2)" -> (2) | B47: From "BRM FEE INPUTS" worksheet
A48: ="(3)" -> (3) | B48: From "BRM FEE INPUTS" worksheet
A49: ="(4)" -> (4) | B49: [ (3) * 100 ] / (2)
A50: ="(5)" -> (5) | B50: From "BRM FEE INPUTS" worksheet
...

Sheet NONLETTER SIZE BRM
A1: NONLETTER-SIZE BRM PER-PIECE FEE (COUNTING ACTIVITIES)
C4: ="(1)" -> (1) | D4: ="(2)" -> (2) | E4: ="(3)" -> (3) | F4: ="(4)" -> (4) | G4: ="(5)" -> (5) | H4: ="(6)" -> (6) | I4: ="(7)" -> (7)
E6: Direct | G6: Premium | H6: Premium | I6: Total
C7: Marginal | D7: Wage | E7: Cents Per | F7: Piggyback | G7: Pay | H7: Pay | I7: Cents Per
A8: Counting Method | C8: Productivity | D8: Rate | E8: Piece | F8: Factor | G8: Factor | H8: Adjustment | I8: Piece
B9: Weight Averaging | C9: ='BRM FEE INPUTS'!H14 -> 21069.181 | D9: ='BRM FEE INPUTS'!$H$52 -> 50.107175 | E9: =D9*100/C9 -> 0.23782212 | F9: ='BRM FEE INPUTS'!$H$58 -> 1.2907912 | G9: ='BRM FEE INPUTS'!$H$64 -> 1.0126008 | H9: =(G9-1)*E9 -> 0.0029967604 | I9: =E9*F9+H9 -> 0.30997547
A13: ="(1)" -> (1) | B13: From "BRM FEE INPUTS" worksheet
A14: ="(2)" -> (2) | B14: From "BRM FEE INPUTS" worksheet
A15: ="(3)" -> (3) | B15: [ (2) * 100 ] / (1)
A16: ="(4)" -> (4) | B16: From "BRM FEE INPUTS" worksheet
A17: ="(5)" -> (5) | B17: From "BRM FEE INPUTS" worksheet
A18: ="(6)" -> (6) | B18: [ (5) - 1 ] * (3)
A19: ="(7)" -> (7) | B19: (3) * (4) + (6)

Sheet BRM FEE INPUTS
A1: BRM FEE COST MODEL INPUTS
E2: ="(1)" -> (1) | F2: ="(2)" -> (2) | G2: ="(3)" -> (3) | H2: ="(4)" -> (4)
C3: Daily | G3: Volume
C4: Minutes | D4: Accounts | E4: Pieces | F4: Overhead | G4: Variability | H4: Marginal
A5: Productivity | C5: Per Account | D5: Per Hour | E5: Per Hour | F5: Factor | G5: Factor | H5: Pcs/Hr
B6: Counting
B7: WebBRMAS Counting | E7: 193036.74 | F7: =$H$67 -> 1.1805242 | G7: =H$70 -> 0.9887 | H7: =E7/F7/G7 -> 165386.68
B8: WebEOR Counting | E8: 86682.883 | F8: =$H$67 -> 1.1805242 | G8: =H$70 -> 0.9887 | H8: =E8/F8/G8 -> 74266.664
B9: Counting Machine | E9: 6731.7958 | F9: =$H$67 -> 1.1805242 | G9: =H$70 -> 0.9887 | H9: =E9/F9/G9 -> 5767.5518
B10: Manual Counting | E10: 2892.6426 | F10: =$H$67 -> 1.1805242 | G10: =H$70 -> 0.9887 | H10: =E10/F10/G10 -> 2478.3084
B11: Weight Averaging (letters) | E11: 29193.141 | F11: =$H$67 -> 1.1805242 | G11: =H$70 -> 0.9887 | H11: =E11/F11/G11 -> 25011.595
B12: Weight Averaging (flats) | E12: 24591.617 | F12: =$H$67 -> 1.1805242 | G12: =H$70 -> 0.9887 | H12: =E12/F12/G12 -> 21069.181
B13: Weight Averaging (parcels) | E13: 6162.7407 | F13: =$H$67 -> 1.1805242 | G13: =H$70 -> 0.9887 | H13: =E13/F13/G13 -> 5280.0066
B14: Weight Averaging (flats and parcels aggregate) | E14: =H74*E12+H75*E13 -> 24591.617 | F14: =$H$67 -> 1.1805242 | G14: =H$70 -> 0.9887 | H14: =E14/F14/G14 -> 21069.181
D16: ="(5)" -> (5) | E16: ="(6)" -> (6) | F16: ="(7)" -> (7) | G16: ="(8)" -> (8) | H16: ="(9)" -> (9)
B17: Rating/Billing
B18: PERMIT/Postage Due (Basic QBRM) | D18: 97.852212 | E18: =D18*H80 -> 10602.448 | F18: =$H$67 -> 1.1805242 | G18: =H$70 -> 0.9887 | H18: =E18/F18/G18 -> 9083.7825
B19: PERMIT/Postage Due (High Vol BRM) | D19: 97.852212 | E19: =D19*H81 -> 5286.8545 | F19: =$H$67 -> 1.1805242 | G19: =H$70 -> 0.9887 | H19: =E19/F19/G19 -> 4529.5799
B20: PERMIT/Postage Due (Basic BRM) | D20: 97.852212 | E20: =D20*H82 -> 967.02181 | F20: =$H$67 -> 1.1805242 | G20: =H$70 -> 0.9887 | H20: =E20/F20/G20 -> 828.50826
B21: Manual rating/billing (Basic QBRM) | D21: 34.560803 | E21: =D21*H80 -> 3744.7198 | F21: =$H$67 -> 1.1805242 | G21: =H$70 -> 0.9887 | H21: =E21/F21/G21 -> 3208.3364
B22: Manual rating/billing (Hi Vol BRM) | D22: 34.560803 | E22: =D22*H81 -> 1867.2847 | F22: =$H$67 -> 1.1805242 | G22: =H$70 -> 0.9887 | H22: =E22/F22/G22 -> 1599.8199
B23: Manual rating/billing (Basic BRM) | D23: 34.560803 | E23: =D23*H82 -> 341.54619 | F23: =$H$67 -> 1.1805242 | G23: =H$70 -> 0.9887 | H23: =E23/F23/G23 -> 292.62405
C25: ="(10)" -> (10) | F25: ="(11)" -> (11) | G25: ="(12)" -> (12) | H25: ="(13)" -> (13)
B26: QBRM Rating / Billing
B27: PostalOne! Billing | C27: 1.2143909 | F27: =$H$67 -> 1.1805242 | G27: =H$70 -> 0.9887 | H27: =C27*F27*G27 -> 1.417418
B28: Manual Billing | C28: 1.764845 | F28: =$H$67 -> 1.1805242 | G28: =H$70 -> 0.9887 | H28: =C28*F28*G28 -> 2.0598993
B30: Nonletter Size BRM
B31: Billing | C31: 3.9443333 | F31: =$H$67 -> 1.1805242 | G31: =H$70 -> 0.9887 | H31: =C31*F31*G31 -> 4.6037639
B32: Sampling | C32: 42.669167 | F32: =$H$67 -> 1.1805242 | G32: =H$70 -> 0.9887 | H32: =C32*F32*G32 -> 49.80278
E34: ="(14)" -> (14) | G34: ="(15)" -> (15) | H34: ="(16)" -> (16)
B35: Collection - Box Section
B36: Pickup BRM at Postage Due Unit | E36: 3981 | G36: =H$70 -> 0.9887 | H36: =E36/G36 -> 4026.4994
B37: Examine and sign due bill (Form 3582-B) | E37: 303 | G37: =H$70 -> 0.9887 | H37: =E37/G37 -> 306.46303
B38: Prepare call slip and place in lock box | E38: 336 | G38: =H$70 -> 0.9887 | H38: =E38/G38 -> 339.84019
B39: Collect from customer | E39: 226 | G39: =H$70 -> 0.9887 | H39: =E39/G39 -> 228.58299
B40: Turn in postage | E40: 250 | G40: =H$70 -> 0.9887 | H40: =E40/G40 -> 252.85729
B41: Accept Collections | E41: 260 | G41: =H$70 -> 0.9887 | H41: =E41/G41 -> 262.97158
B43: Collection - Carriers
B44: Pickup BRM at Postage Due Unit | E44: 3114 | G44: ="---" -> --- | H44: =E44 -> 3114
B45: Examine and sign due bill (Form 3582-B) | E45: 315 | G45: ="---" -> --- | H45: =E45 -> 315
...
