Workbook

Sheet Summary
A1: Summary of BPM Cost Savings Estimates
A5: Cost Savings of DNDC (compared to non-dropship) | B5: 1/ | C5: =+DB_2!D19 -> 0.20927606
A6: Cost Savings of DSCF (compared to DNDC) | B6: 2/ | C6: =+DNDC!G47-DSCF!G36 -> 0.51318247
A7: Cost Savings of DDU (compared to DSCF) | B7: 3/ | C7: =DSCF!G36-DSCF!G26 -> 0.73543244
A8: Cost Savings of carrier route presort (compared to Basic Presort) | B8: 4/ | C8: =+'Carrier Route'!F17 -> 0.22123353
A9: Cost difference of parcels compared to flats | B9: 5/ | C9: =+'Flat - Parcel'!F12 -> 0.28458777
A10: Barcode Savings Estimate | B10: 6/ | C10: ='Barcode Savings'!F8 -> 0.050566819
A14: Row 1/: Page 9
A15: Row 2/: DNDC model cost (page 6) - DSCF model cost (page 7).
A16: Row 3/: DSCF total model cost (page 7) - DSCF delivery unit model cost (page 7)
A17: Row 4/: Page 10
A18: Row 5/: Page 11
A19: Row 6/: Page 12

Sheet Productivities
B1: Productivities and Variability Factors for Direct Labor Operations
D3: Marginal
B4: UNLOADING | D4: Units/Wkhr
B5: Unload sacked machinable parcels to extended conveyor | D5: =176.9/D39 -> 199.00056 | E5: 1/
B6: Unload non-machinable parcels to IHC only (proxy for sacks) | D6: =145.779/D39 -> 163.99154 | E6: 1/
B7: Unload wheeled containers | D7: =19.7/D39 -> 22.16117 | E7: 1/
B8: Unload pallet/pallet box | D8: =11.606/D39 -> 13.055967 | E8: 1/
B10: DUMPING & SACK HANDLING
B11: Dump Containers | D11: =6.33/D40 -> 6.9452852 | E11: 1/
B12: Manually dump sacks | D12: =99.4/D40 -> 109.06182 | E12: 2/
B13: SSM | D13: ='[1]Table FY25'!$I$10/D42 -> 3068.1109 | E13: 3/
B15: PARCEL SORTING MACHINE DISTRIBUTION
B16: PPSM | D16: ='[1]Table FY25'!$I$8/D41 -> 409.68278 | E16: 3/
B17: SPSM | D17: ='[1]Table FY25'!$I$9/D41 -> 331.3648 | E17: 3/
B19: NONMACHINABLE OUTSIDES DISTRIBUTION
B20: NMO Distribution | D20: ='[1]Table FY25'!$I$11/D43 -> 52.808722 | E20: 3/
B21: NMO Distribution at SCFs | D21: ='[2]FY25 Table'!$I$57/D45 -> 47.99469 | E21: 3/
B23: OTHER OPERATIONS
B24: Tend container loader/sweep runouts (Destinating NDC - OTR) | D24: =5.3/D40 -> 5.8151677 | E24: 1/
B25: Crossdock | D25: =6.659/D39 -> 7.4909256 | E25: 1/
B26: Move containers from DU dock to parcel sorting area | D26: =28.99/D46 -> 31.292492 | E26: 7/
B28: LOADING
B29: Bedload Sacked Machinables | D29: =172.682/D39 -> 194.2556 | E29: 1/
B30: Load wheeled containers | D30: =9.849/D39 -> 11.07946 | E30: 1/
B31: Load Pallet/Pallet boxes | D31: =12.671/D39 -> 14.25402 | E31: 1/
B33: For Carrier Route
B34: Sorting BPM flats to carrier route | D34: ='[3]FY25 F4 Manual Productivity'!$D$4/D48 -> 675.91285 | E34: 1/
B35: Sorting BPM parcels to carrier route | D35: ='[3]FY25 F4 Manual Productivity'!$D$6/D47 -> 307.66823 | E35: 4/
B36: Sorting at carrier station | D36: =4090/D47 -> 4253.6708 | E36: 5/
B38: Variability Factors
B39: NDC Platform | D39: ='[4]8 MP Cost Pool Variabilities'!$E$66 -> 0.88894222 | E39: 6/
B40: NDC Other | D40: ='[4]8 MP Cost Pool Variabilities'!$E$65 -> 0.91140966 | E40: 6/
B41: PSM | D41: ='[4]8 MP Cost Pool Variabilities'!$E$67 -> 0.9584975 | E41: 6/
B42: SSM | D42: ='[4]8 MP Cost Pool Variabilities'!$E$69 -> 0.928342 | E42: 6/
B43: NMO Distribution at NDCs | D43: ='[4]8 MP Cost Pool Variabilities'!$E$64 -> 0.91586806 | E43: 6/
B44: Platform Non-NDC MODS | D44: ='[4]8 MP Cost Pool Variabilities'!$E$38 -> 0.91687625 | E44: 6/
B45: Non-NDC MODS Manual Parcel Sort | D45: ='[4]8 MP Cost Pool Variabilities'!$E$22 -> 0.97225878 | E45: 6/
B46: Non-NDC Non-MODS Platform | D46: ='[4]8 MP Cost Pool Variabilities'!$E$77 -> 0.92642031 | E46: 6/
B47: Non-NDC Non-MODS Manual Parcel Sort | D47: ='[4]8 MP Cost Pool Variabilities'!$E$86 -> 0.96152246 | E47: 6/
B48: Non-NDC Non-MODS Manual Flat Sort | D48: ='[4]8 MP Cost Pool Variabilities'!$E$84 -> 0.97377163 | E48: 6/
...

Sheet Arrival - Dispatch Profile
B1: Arrival and Dispatch Profiles
B4: Mail Flow Arrival at Destinating NDCs for BPM
B5: Machinable Parcels Arriving on Pallets/Pallet Boxes at DNDC | D5: 0.9955 | E5: 1/
B6: Machinable Parcels Arriving in Sacks at DNDC | D6: =1-D5 -> 0.0045 | E6: 1/
B8: Mail Flow Dispatch Profiles From NDCs to Service Area
B9: Machinable Parcels Dispatched in Bedloaded Sacks to Service Area | D9: 0.2384 | E9: 2/
B10: Machinable Parcels Dispatched loose in OTRs to Service Area | D10: 0.6025 | E10: 2/
B11: Machinable Parcels Dispatched sacked in OTRs to Service Area | D11: 0.0289 | E11: 2/
B12: Machinable Parcels Dispatched in Hampers/APC/OWC (OWC) to Service Area | D12: 0.1302 | E12: 2/
B14: Mail Flow Dispatch Profiles to Delivery Unit
B15: Machinable Parcels Dispatched in Bedloaded Sacks to Delivery Unit | D15: =+D11+D9 -> 0.2673 | E15: 2/
B16: Machinable Parcels Dispatched loose in OTRs to Service Area to Delivery Unit | D16: =+D10 -> 0.6025 | E16: 2/
B17: Machinable Parcels Dispatched in OWC to Delivery Unit | D17: =+D12 -> 0.1302 | E17: 2/
B19: DSCF
B20: Machinable Parcels | D20: 0.49449103 | E20: 3/
B21: Flats/IPPS | D21: =1-D20 -> 0.50550897 | E21: 3/
B23: Proportion of DSCF dropped at NDCs | D23: 0.123 | E23: 4/
B25: Proportion of DSCF using requirements
B26: Sacks | D26: =1-D27 -> 0.0536 | E26: 5/
B27: Pallet and Pallet Boxes | D27: 0.9464 | E27: 5/
B29: Percent Flats | D29: ='Flat - Parcel'!$C$5/'Flat - Parcel'!$E$5 -> 0.3158539 | E29: 6/
B31: Sources
B32: 1/: Docket R2000-1, USPS LR-I-109, BPM Mail Characteristics Study.
B33: 2/: Docket No. R97-1, USPS LR-H-131, Table 1.
B34: 3/: Docket No. R2000-1, LR-I-109, BPM Mail Characteristics Study - BPM Profile (Mach parcels/ all BPM).
B35: 4/: USPS LR-PCR-40, page 64.
B36: 5/: Docket No. R2000-1, USPS LR-I-109, BPM Mail Characteristics Study - DSCF Presort Profile.
B37: (Bedloaded Bundles excluded because assumed they will not be allowed in Test Year.)
B38: 6/: Page 11

Sheet Other Inputs
B1: Other Inputs
B4: Wage Rate with Premium Pay Factor Applied | D4: =D5*D6 -> 49.053814 | E4: 1/
B5: Premium Pay Factor | D5: ='[5]V-3. Premium Pay Adj'!$S$28*'Arrival - Dispatch Profile'!$D$29+'[5]V-3. Premium Pay Adj'!$S$29*(1-'Arrival - Dispatch Profile'!$D$29) -> 0.97897786 | E5: 2/
B6: Other Mail Processing Wage Rate | D6: ='[6]FY25 table viii '!$D$12 -> 50.107175 | E6: 3/
B8: Mail Processing Operation Specific Piggyback Factors
B9: NMO Sorting at NDC | D9: ='[7]MP Piggybacks'!$J$39 -> 1.4774317 | E9: 4/
B10: Other Operations at NDCs | D10: ='[7]MP Piggybacks'!$J$40 -> 1.5176144 | E10: 4/
B11: Platform NDC | D11: ='[7]MP Piggybacks'!$J$41 -> 1.3860239 | E11: 4/
B12: Primary Parcel Sorting Machine | D12: ='[7]MP Piggybacks'!$J$63 -> 1.9204979 | E12: 4/
B13: Secondary Parcel Sorting Machine | D13: ='[7]MP Piggybacks'!$J$64 -> 2.0700178 | E13: 4/
B14: Sack Sorting Machine - NDC | D14: ='[7]MP Piggybacks'!$J$44 -> 1.6196175 | E14: 4/
B15: Manual Parcel Sort at MODS Plant | D15: ='[7]MP Piggybacks'!$J$16 -> 1.3208756 | E15: 4/
B16: Platform MODS Plant | D16: ='[7]MP Piggybacks'!$J$25 -> 1.3606062 | E16: 4/
B17: Platform Non-MODS Facility | D17: ='[7]MP Piggybacks'!$J$46 -> 1.6214861 | E17: 4/
B18: Manual Parcel Sort at Non-MODS Facility | D18: ='[7]MP Piggybacks'!$J$55 -> 1.4957787 | E18: 4/
B19: Manual Flats Sort at Non-MODS Facility | D19: ='[7]MP Piggybacks'!$J$53 -> 1.5675507 | E19: 4/
B21: City carrier (BPM) piggyback factor | D21: =[8]PBRatios!$M$31*'Arrival - Dispatch Profile'!D29+[8]PBRatios!$M$32*(1-'Arrival - Dispatch Profile'!D29) -> 1.2660192 | E21: 5/
B23: Mail Flow Operating Assumptions
B24: Percent with direct transportation to destinating delivery unit from NDC | D24: =+'Arrival - Dispatch Profile'!D23 -> 0.123 | E24: 6/
B25: Probability of Intra-NDC and DNDC parcels going to PPSM | D25: 1 | E25: 6/
B26: Probability of Intra-NDC and DNDC parcels going to the SPSM | D26: 0.79907653 | E26: 6/
B28: Sources
B29: 1/: 2/ * 3/
B30: 2/: USPS-FY25-7, Part 5 (weighted average of flats and parcels factors)
B31: 3/: USPS-FY25-7, Part 8
B32: 4/: USPS-FY25-25
B33: 5/: USPS-FY25-24 (weighted average of flats and parcels factors)
B34: 6/: Page 5

Sheet Conversion Factors
A1: Conversion Factor Calculations
C3: [1] | E3: [2] | G3: [3] | I3: [4] | K3: [5] | M3: [6]
C4: Outside Dim. | E4: Inside Dim. | G4: Cubic Feet | I4: Effective | K4: Capacity at | M4: Average
A5: Container Type | C5: Per Container | E5: Per Container | G5: Per Container | I5: Parcel Capacity | K5: Average Fullness | M5: % FULL
A6: Machinable
A7: Pallet | C7: 48x40x48 | E7: 48x40x48 | G7: =48/12*40/12*48/12 -> 53.333333 | I7: =G7/($E$26*1) -> 436.88517 | K7: =I7*M7 -> 371.35239 | M7: 0.85
A8: Pallet Box | C8: 48x40x69 | E8: 46.5x38.5x69 | G8: =46.5/12*38.5/12*69/12 -> 71.485677 | I8: =G8/($E$26*1.1) -> 532.34714 | K8: =I8*M8 -> 452.49507 | M8: 0.85
A9: Sacks on In-house Container | C9: 65x41.5x36 | E9: 65x41.5x36 | G9: =65/12*41.5/12*36/12 -> 56.197917 | I9: =G9/($E$26*1.1) -> 418.50062 | K9: =I9*M9 -> 355.72553 | M9: 0.85
A10: Presorted pieces per sack | K10: =0.5*10+0.5*E16 -> 22.452033
C13: [7] | E13: [8]
A14: Pieces Per | C14: Parcel Post | E14: BPM
A15: Container | C15: FY82 | E15: ACR Fiscal Year
A16: Sack | C16: 7.92 | E16: =C16*$C$27/$E$26 -> 34.904067
A17: Sack in OTR | C17: 126.7 | E17: =C17*$C$27/$E$26 -> 558.37693
A18: OTR | C18: 106.9 | E18: =C18*$C$27/$E$26 -> 471.11676
A19: APC | C19: 55.2 | E19: =C19*$C$27/$E$26 -> 243.27077
A20: Hamper | C20: 35.6 | E20: =C20*$C$27/$E$26 -> 156.89202
C22: [9] | E22: [10] | G22: [11]
C23: Cubic feet/piece
C24: Form 22 (PP) | E24: CRA | G24: No. of Sacks
C25: CRA | E25: BPM | G25: on IHC
A26: ACR Fiscal Year | E26: ='[9]TRACS CRA Surface Densities'!$G$50 -> 0.12207632 | G26: =+$K$9/$K$10 -> 15.8438
A27: FY82 | C27: 0.538
A30: Sources
A31: Column [1]: Container Methods, Handbook PO-502 (September 1992) USPS LR-H-133/R97-1.
A32: Column [2]: Container Methods, Handbook PO-502 (September 1992) USPS LR-H-133/R97-1.
A33: Column [3]: (Length * width * height) / (12*12*12).
A34: Column [4]: (Column [3]) / ((column [10]) * air factor), to account for "effective cube."
A35: Air factor =1 for pallets, and 1.1 for all else.
A36: Column [5]: Effective cubic capacity (column [4]) * average % fullness (column [6]).
A37: Column [6]: Pallets, postal paks and IHCs should be as full as practicable before dispatch so it is reasonable to assume these containers will be at least 85% full.
A38: Column [7]: Docket No. R84-1, Exhibit USPS-14I.
A39: Column [8]: Pieces per container in Docket No. R84-1 (column [7]) * FY82 cubic feet per piece (column [9]) / cubic feet per piece for BPM (column [10]).
A40: Column [9]: FY82 cubic feet per piece (consistent with column [7]).
A41: Column [10]: USPS-FY25-1 and USPS-FY25-36
A42: Column [11]: # of sacks = (# of pieces in IHC) / (# of presorted pieces per sack).

Sheet DNDC
A2: Bound Printed Matter DNDC Model Cost Summary
B4: [1] | C4: [2] | D4: [3] | E4: [4] | F4: [5] | G4: [6]
B5: # handlings | C5: units/hr | D5: conversion | E5: piggyback | F5: $ per oper. | G5: $ per facility
A6: Destination NDC | G6: =SUM(G7:G16) -> 0.5256853
A7: Unload Pallets/Pallet Boxes | B7: =+'Arrival - Dispatch Profile'!D5 -> 0.9955 | C7: =+Productivities!D$8 -> 13.055967 | D7: =+'Conversion Factors'!K$7*0.5+'Conversion Factors'!K$8*0.5 -> 411.92373 | E7: ='Other Inputs'!$D$11 -> 1.3860239 | F7: ='Other Inputs'!$D$4*E7/(C7*D7) -> 0.012642055 | G7: =F7*B7 -> 0.012585165
A8: Unload Bedload Sacks | B8: ='Arrival - Dispatch Profile'!D6 -> 0.0045 | C8: =+Productivities!D5 -> 199.00056 | D8: ='Conversion Factors'!K$10 -> 22.452033 | E8: =E7 -> 1.3860239 | F8: ='Other Inputs'!$D$4*E8/(C8*D8) -> 0.015217157 | G8: =F8*B8 -> 6.8477207e-05
A9: Dump Pallets/Pallet Boxes | B9: =+B7 -> 0.9955 | C9: =+Productivities!D$11 -> 6.9452852 | D9: =+'Conversion Factors'!K$7*0.5+'Conversion Factors'!K$8*0.5 -> 411.92373 | E9: =E8 -> 1.3860239 | F9: ='Other Inputs'!$D$4*E9/(C9*D9) -> 0.023764934 | G9: =F9*B9 -> 0.023657992
A10: SSM | B10: =B8 -> 0.0045 | C10: =Productivities!D13 -> 3068.1109 | D10: =D8 -> 22.452033 | E10: ='Other Inputs'!D14 -> 1.6196175 | F10: ='Other Inputs'!$D$4*E10/(C10*D10) -> 0.001153343 | G10: =F10*B10 -> 5.1900437e-06
A11: PPSM | B11: =+'Other Inputs'!D25 -> 1 | C11: =+Productivities!D16 -> 409.68278 | D11: 1 | E11: ='Other Inputs'!$D$12 -> 1.9204979 | F11: ='Other Inputs'!D$4*E11/(C11*D11) -> 0.22995291 | G11: =F11*B11 -> 0.22995291
A12: SPSM | B12: =+'Other Inputs'!D26 -> 0.79907653 | C12: =Productivities!D17 -> 331.3648 | D12: 1 | E12: ='Other Inputs'!D13 -> 2.0700178 | F12: ='Other Inputs'!D$4*E12/(C12*D12) -> 0.3064365 | G12: =+F12*B12 -> 0.24486621
A13: Bedload Sacks | B13: ='Arrival - Dispatch Profile'!$D$9 -> 0.2384 | C13: =Productivities!$D$29 -> 194.2556 | D13: =+'Conversion Factors'!E16 -> 34.904067 | E13: ='Other Inputs'!D11 -> 1.3860239 | F13: ='Other Inputs'!D4*E13/(C13*D13) -> 0.010027529 | G13: =F13*B13 -> 0.002390563
A14: Load OTRs w/ sacks | B14: ='Arrival - Dispatch Profile'!$D$11 -> 0.0289 | C14: =Productivities!$D$30 -> 11.07946 | D14: =+'Conversion Factors'!E17 -> 558.37693 | E14: ='Other Inputs'!$D$11 -> 1.3860239 | F14: ='Other Inputs'!D4*E14/(C14*D14) -> 0.010989993 | G14: =F14*B14 -> 0.00031761081
A15: Load OTRs w/ loose | B15: ='Arrival - Dispatch Profile'!$D$10 -> 0.6025 | C15: =Productivities!$D$30 -> 11.07946 | D15: =+'Conversion Factors'!E$18 -> 471.11676 | E15: ='Other Inputs'!$D$11 -> 1.3860239 | F15: ='Other Inputs'!D4*E15/(C15*D15) -> 0.013025558 | G15: =F15*B15 -> 0.0078478988
A16: Load Hampers/OWC | B16: ='Arrival - Dispatch Profile'!$D$12 -> 0.1302 | C16: =Productivities!$D$30 -> 11.07946 | D16: =+'Conversion Factors'!E$19*0.5+0.5*'Conversion Factors'!E$20 -> 200.08139 | E16: ='Other Inputs'!$D$11 -> 1.3860239 | F16: ='Other Inputs'!D4*E16/(C16*D16) -> 0.030670312 | G16: =F16*B16 -> 0.0039932747
A17: Destination SCF | G17: =SUM(G18:G36) -> 0.72630688
A18: Unload Bedload Sacks | B18: =$B$13*((1-'Other Inputs'!$D$24)*'Arrival - Dispatch Profile'!$D$20+'Arrival - Dispatch Profile'!$D$21) -> 0.22389994 | C18: =Productivities!$D$6 -> 163.99154 | D18: =+'Conversion Factors'!E16 -> 34.904067 | E18: ='Other Inputs'!$D$16 -> 1.3606062 | F18: ='Other Inputs'!D4*E18/(C18*D18) -> 0.011660247 | G18: =F18*B18 -> 0.0026107287
A19: Unload Sacks in OTR | B19: =$B$14*((1-'Other Inputs'!$D$24)*'Arrival - Dispatch Profile'!$D$20+'Arrival - Dispatch Profile'!$D$21) -> 0.027142233 | C19: =Productivities!$D$7 -> 22.16117 | D19: =+'Conversion Factors'!E$17 -> 558.37693 | E19: ='Other Inputs'!$D$16 -> 1.3606062 | F19: ='Other Inputs'!D4*E19/(C19*D19) -> 0.0053936787 | G19: =F19*B19 -> 0.00014639648
A20: Unload loose in OTR | B20: =$B$15*((1-'Other Inputs'!$D$24)*'Arrival - Dispatch Profile'!$D$20+'Arrival - Dispatch Profile'!$D$21) -> 0.56585451 | C20: =Productivities!$D$7 -> 22.16117 | D20: =+'Conversion Factors'!E$18 -> 471.11676 | E20: ='Other Inputs'!$D$16 -> 1.3606062 | F20: ='Other Inputs'!D4*E20/(C20*D20) -> 0.0063926949 | G20: =F20*B20 -> 0.0036173352
A21: Unload OWC | B21: =$B$16*((1-'Other Inputs'!$D$24)*'Arrival - Dispatch Profile'!$D$20+'Arrival - Dispatch Profile'!$D$21) -> 0.12228092 | C21: =Productivities!$D$7 -> 22.16117 | D21: =+'Conversion Factors'!E$19*0.5+0.5*'Conversion Factors'!E$20 -> 200.08139 | E21: ='Other Inputs'!$D$16 -> 1.3606062 | F21: ='Other Inputs'!D4*E21/(C21*D21) -> 0.015052403 | G21: =F21*B21 -> 0.0018406217
A22: Crossdock Bedload Sacks | B22: =$B$13*(1-'Other Inputs'!$D$24)*'Arrival - Dispatch Profile'!$D$20 -> 0.1033866 | C22: =Productivities!$D$25 -> 7.4909256 | D22: =+'Conversion Factors'!K9 -> 355.72553 | E22: ='Other Inputs'!$D$16 -> 1.3606062 | F22: ='Other Inputs'!D4*E22/(C22*D22) -> 0.025046942 | G22: =F22*B22 -> 0.0025895183
A23: Crossdock Sacks in OTR | B23: =$B$14*(1-'Other Inputs'!$D$24)*'Arrival - Dispatch Profile'!$D$20 -> 0.012533024 | C23: =Productivities!$D$25 -> 7.4909256 | D23: =+'Conversion Factors'!E$17 -> 558.37693 | E23: ='Other Inputs'!$D$16 -> 1.3606062 | F23: ='Other Inputs'!D4*E23/(C23*D23) -> 0.015956671 | G23: =F23*B23 -> 0.00019998533
A24: Crossdock loose in OTR | B24: =$B$15*(1-'Other Inputs'!$D$24)*'Arrival - Dispatch Profile'!$D$20 -> 0.26128535 | C24: =Productivities!$D$25 -> 7.4909256 | D24: =+'Conversion Factors'!E$18 -> 471.11676 | E24: ='Other Inputs'!$D$16 -> 1.3606062 | F24: ='Other Inputs'!D4*E24/(C24*D24) -> 0.018912162 | G24: =F24*B24 -> 0.0049414711
A25: Crossdock OWC | B25: =$B$16*(1-'Other Inputs'!$D$24)*'Arrival - Dispatch Profile'!$D$20 -> 0.056463657 | C25: =Productivities!$D$25 -> 7.4909256 | D25: =+'Conversion Factors'!E$19*0.5+0.5*'Conversion Factors'!E$20 -> 200.08139 | E25: ='Other Inputs'!$D$16 -> 1.3606062 | F25: ='Other Inputs'!D$4*E25/(C25*D25) -> 0.044531061 | G25: =F25*B25 -> 0.0025143865
A26: Move IHC with sacks | B26: =+'Arrival - Dispatch Profile'!D21*DNDC!B13 -> 0.12051334 | C26: =+Productivities!D$25*2 -> 14.981851 | D26: =+'Conversion Factors'!K$9 -> 355.72553 | E26: ='Other Inputs'!$D$16 -> 1.3606062 | F26: ='Other Inputs'!D$4*E26/(C26*D26) -> 0.012523471 | G26: =F26*B26 -> 0.0015092453
A27: Move Sacks in OTR | B27: =+'Arrival - Dispatch Profile'!D21*DNDC!B14 -> 0.014609209 | C27: =+Productivities!D$25*2 -> 14.981851 | D27: =+'Conversion Factors'!E17 -> 558.37693 | E27: ='Other Inputs'!$D$16 -> 1.3606062 | F27: ='Other Inputs'!D$4*E27/(C27*D27) -> 0.0079783353 | G27: =F27*B27 -> 0.00011655717
A28: Move loose in OTR | B28: =+'Arrival - Dispatch Profile'!D21*DNDC!B15 -> 0.30456915 | C28: =+Productivities!D$25*2 -> 14.981851 | D28: =+'Conversion Factors'!E$18 -> 471.11676 | E28: ='Other Inputs'!$D$16 -> 1.3606062 | F28: ='Other Inputs'!D$4*E28/(C28*D28) -> 0.0094560812 | G28: =F28*B28 -> 0.0028800306
A29: Move OWC | B29: =+'Arrival - Dispatch Profile'!D21*DNDC!B16 -> 0.065817267 | C29: =+Productivities!D$25*2 -> 14.981851 | D29: =+'Conversion Factors'!E$19*0.5+0.5*'Conversion Factors'!E$20 -> 200.08139 | E29: ='Other Inputs'!$D$16 -> 1.3606062 | F29: ='Other Inputs'!D$4*E29/(C29*D29) -> 0.022265531 | G29: =F29*B29 -> 0.0014654564
A30: Manual Sort | B30: =SUM(B26:B29) -> 0.50550897 | C30: =+Productivities!D21 -> 47.99469 | D30: 1 | E30: =+'Other Inputs'!D15 -> 1.3208756 | F30: ='Other Inputs'!D$4*E30/(C30*D30) -> 1.3500241 | G30: =F30*B30 -> 0.68244927
A31: Move IHCs with sacks | B31: =+B30*'Arrival - Dispatch Profile'!D15 -> 0.13512255 | C31: =+Productivities!D$25*2 -> 14.981851 | D31: =+'Conversion Factors'!K$9 -> 355.72553 | E31: ='Other Inputs'!$D$16 -> 1.3606062 | F31: ='Other Inputs'!D$4*E31/(C31*D31) -> 0.012523471 | G31: =F31*B31 -> 0.0016922033
A32: Move OTRs | B32: =+B30*'Arrival - Dispatch Profile'!D16 -> 0.30456915 | C32: =+Productivities!D$25*2 -> 14.981851 | D32: =+'Conversion Factors'!E$18 -> 471.11676 | E32: ='Other Inputs'!$D$16 -> 1.3606062 | F32: ='Other Inputs'!D$4*E32/(C32*D32) -> 0.0094560812 | G32: =F32*B32 -> 0.0028800306
A33: Move OWCs | B33: =+B30*'Arrival - Dispatch Profile'!D17 -> 0.065817267 | C33: =+Productivities!D$25*2 -> 14.981851 | D33: =+'Conversion Factors'!E$19*0.5+0.5*'Conversion Factors'!E$20 -> 200.08139 | E33: ='Other Inputs'!$D$16 -> 1.3606062 | F33: ='Other Inputs'!D$4*E33/(C33*D33) -> 0.022265531 | G33: =F33*B33 -> 0.0014654564
A34: Bedload Sacks | B34: =(B22+B23)+B31 -> 0.25104217 | C34: =Productivities!$D$29 -> 194.2556 | D34: =+'Conversion Factors'!E$16 -> 34.904067 | E34: ='Other Inputs'!$D$16 -> 1.3606062 | F34: ='Other Inputs'!D$4*E34/(C34*D34) -> 0.0098436386 | G34: =F34*B34 -> 0.0024711684
A35: Load OTRs w/ loose | B35: =B24+B32 -> 0.56585451 | C35: =Productivities!$D$30 -> 11.07946 | D35: =+'Conversion Factors'!E$18 -> 471.11676 | E35: ='Other Inputs'!$D$16 -> 1.3606062 | F35: ='Other Inputs'!D$4*E35/(C35*D35) -> 0.012786688 | G35: =F35*B35 -> 0.007235405
A36: Load Hampers/OWC | B36: =B25+B33 -> 0.12228092 | C36: =Productivities!$D$30 -> 11.07946 | D36: =+'Conversion Factors'!E$19*0.5+0.5*'Conversion Factors'!E$20 -> 200.08139 | E36: ='Other Inputs'!$D$16 -> 1.3606062 | F36: ='Other Inputs'!D$4*E36/(C36*D36) -> 0.030107862 | G36: =F36*B36 -> 0.0036816172
A37: Destination Delivery Unit | G37: =SUM(G38:G45) -> 0.22324158
A38: Unload Bedload Sack | B38: =+B13*('Arrival - Dispatch Profile'!D20*'Arrival - Dispatch Profile'!D23)+DNDC!B34 -> 0.26554223 | C38: =Productivities!$D$6 -> 163.99154 | D38: =+'Conversion Factors'!E$16 -> 34.904067 | E38: ='Other Inputs'!$D$17 -> 1.6214861 | F38: ='Other Inputs'!D4*E38/(C38*D38) -> 0.013895959 | G38: =F38*B38 -> 0.0036899641
A39: Unload OTR w/ sacks | B39: =B14*'Arrival - Dispatch Profile'!D23*'Arrival - Dispatch Profile'!D20 -> 0.0017577673 | C39: =Productivities!D7 -> 22.16117 | D39: ='Conversion Factors'!E17 -> 558.37693 | E39: ='Other Inputs'!$D$17 -> 1.6214861 | F39: ='Other Inputs'!D4*E39/(C39*D39) -> 0.0064278517 | G39: =F39*B39 -> 1.1298667e-05
A40: Unload loose in OTR | B40: =+B15*('Arrival - Dispatch Profile'!D20*'Arrival - Dispatch Profile'!D23)+DNDC!B35 -> 0.6025 | C40: =Productivities!$D$7 -> 22.16117 | D40: =+'Conversion Factors'!E$18 -> 471.11676 | E40: ='Other Inputs'!$D$17 -> 1.6214861 | F40: ='Other Inputs'!D4*E40/(C40*D40) -> 0.0076184173 | G40: =F40*B40 -> 0.0045900964
A41: Unload OWC | B41: =+B16*('Arrival - Dispatch Profile'!D20*'Arrival - Dispatch Profile'!D23)+DNDC!B36 -> 0.1302 | C41: =Productivities!$D$7 -> 22.16117 | D41: =+'Conversion Factors'!E$19*0.5+0.5*'Conversion Factors'!E$20 -> 200.08139 | E41: ='Other Inputs'!$D$17 -> 1.6214861 | F41: ='Other Inputs'!D4*E41/(C41*D41) -> 0.01793852 | G41: =F41*B41 -> 0.0023355953
A42: Dump Sacks | B42: =B38+B39 -> 0.2673 | C42: =Productivities!$D$12 -> 109.06182 | D42: ='Conversion Factors'!$E$16 -> 34.904067 | E42: ='Other Inputs'!$D$17 -> 1.6214861 | F42: ='Other Inputs'!D4*E42/(C42*D42) -> 0.020894752 | G42: =F42*B42 -> 0.0055851671
...

Sheet DSCF
A2: Bound Printed Matter DSCF Model Cost Summary
B4: [1] | C4: [2] | D4: [3] | E4: [4] | F4: [5] | G4: [6]
B5: # handlings | C5: units/hr | D5: conversion | E5: piggyback | F5: $ per oper. | G5: $ per facility
A6: Destination NDC | G6: =SUM(G7:G9) -> 0.0031207349
A7: Unload Pallets | B7: =+'Arrival - Dispatch Profile'!D23*'Arrival - Dispatch Profile'!D20 -> 0.060822397 | C7: =+Productivities!D8 -> 13.055967 | D7: =+'Conversion Factors'!K$7 -> 371.35239 | E7: =+'Other Inputs'!D11 -> 1.3860239 | F7: =+('Other Inputs'!D$4*E7)/(C7*D7) -> 0.014023236 | G7: =+F7*B7 -> 0.00085292683
A8: Cross dock pallets | B8: =+B7 -> 0.060822397 | C8: =+Productivities!D$25 -> 7.4909256 | D8: =+'Conversion Factors'!K$7 -> 371.35239 | E8: =E7 -> 1.3860239 | F8: =+('Other Inputs'!D$4*E8)/(C8*D8) -> 0.024441159 | G8: =+F8*B8 -> 0.0014865699
A9: Load Pallets | B9: =+B8 -> 0.060822397 | C9: =+Productivities!D$31 -> 14.25402 | D9: =+'Conversion Factors'!K$7 -> 371.35239 | E9: =E8 -> 1.3860239 | F9: =+('Other Inputs'!D$4*E9)/(C9*D9) -> 0.01284458 | G9: =+F9*B9 -> 0.00078123817
A10: Destination SCF | G10: =SUM(G11:G25) -> 0.73231171
A11: Unload Pallet | B11: =+'Arrival - Dispatch Profile'!D27-B7 -> 0.8855776 | C11: =+Productivities!D8 -> 13.055967 | D11: =+'Conversion Factors'!K$7 -> 371.35239 | E11: =+'Other Inputs'!D$16 -> 1.3606062 | F11: =+('Other Inputs'!D$4*E11)/(C11*D11) -> 0.01376607 | G11: =+F11*B11 -> 0.012190923
A12: Unload Bedloaded Sacks to IHC | B12: =+'Arrival - Dispatch Profile'!D26 -> 0.0536 | C12: =+Productivities!D6 -> 163.99154 | D12: =+'Conversion Factors'!K$10 -> 22.452033 | E12: =+'Other Inputs'!D$16 -> 1.3606062 | F12: =+('Other Inputs'!D$4*E12)/(C12*D12) -> 0.018127091 | G12: =+F12*B12 -> 0.00097161208
A13: Crossdock Pallets | B13: =+'Arrival - Dispatch Profile'!D20*'Arrival - Dispatch Profile'!D27-DSCF!B7 -> 0.40716392 | C13: =+Productivities!D$25 -> 7.4909256 | D13: =+'Conversion Factors'!K$7 -> 371.35239 | E13: =+'Other Inputs'!D$16 -> 1.3606062 | F13: =+('Other Inputs'!D$4*E13)/(C13*D13) -> 0.023992943 | G13: =+F13*B13 -> 0.0097690606
A14: Crossdock bedloaded sacks | B14: =+B12*'Arrival - Dispatch Profile'!D20 -> 0.026504719 | C14: =+Productivities!D$25 -> 7.4909256 | D14: =+'Conversion Factors'!K$10*'Conversion Factors'!G$26 -> 355.72553 | E14: =+'Other Inputs'!D$16 -> 1.3606062 | F14: =+('Other Inputs'!D$4*E14)/(C14*D14) -> 0.025046942 | G14: =+F14*B14 -> 0.00066386218
A15: Move Pallet | B15: =+'Arrival - Dispatch Profile'!D21*'Arrival - Dispatch Profile'!D27 -> 0.47841368 | C15: =Productivities!D25*2 -> 14.981851 | D15: =+'Conversion Factors'!K$7 -> 371.35239 | E15: =+'Other Inputs'!D$16 -> 1.3606062 | F15: =+('Other Inputs'!D$4*E15)/(C15*D15) -> 0.011996471 | G15: =+F15*B15 -> 0.0057392761
A16: Move IHC | B16: =+'Arrival - Dispatch Profile'!D21*DSCF!B12 -> 0.027095281 | C16: =Productivities!D25*2 -> 14.981851 | D16: =+'Conversion Factors'!K$10*'Conversion Factors'!G$26 -> 355.72553 | E16: =+'Other Inputs'!D$16 -> 1.3606062 | F16: =+('Other Inputs'!D$4*E16)/(C16*D16) -> 0.012523471 | G16: =+F16*B16 -> 0.00033932696
A17: Dump Sacks | B17: =B16 -> 0.027095281 | C17: =Productivities!D12 -> 109.06182 | D17: =+'Conversion Factors'!K$10 -> 22.452033 | E17: =+'Other Inputs'!D$16 -> 1.3606062 | F17: =+('Other Inputs'!D$4*E17)/(C17*D17) -> 0.027256921 | G17: =+F17*B17 -> 0.00073853391
A18: Sort to 5-digit | B18: =B16+B15 -> 0.50550897 | C18: =+Productivities!D21 -> 47.99469 | D18: 1 | E18: =+'Other Inputs'!D15 -> 1.3208756 | F18: =+('Other Inputs'!D$4*E18)/(C18*D18) -> 1.3500241 | G18: =+F18*B18 -> 0.68244927
A19: Move IHCs with sacks | B19: =B18*'Arrival - Dispatch Profile'!D15 -> 0.13512255 | C19: =Productivities!D25*2 -> 14.981851 | D19: =+'Conversion Factors'!K$7 -> 371.35239 | E19: =+'Other Inputs'!D$16 -> 1.3606062 | F19: =+('Other Inputs'!D$4*E19)/(C19*D19) -> 0.011996471 | G19: =+F19*B19 -> 0.0016209938
A20: Move OTRs | B20: =+B18*'Arrival - Dispatch Profile'!D16 -> 0.30456915 | C20: =Productivities!D25*2 -> 14.981851 | D20: =+'Conversion Factors'!$E$18 -> 471.11676 | E20: =+'Other Inputs'!D$16 -> 1.3606062 | F20: =+('Other Inputs'!D$4*E20)/(C20*D20) -> 0.0094560812 | G20: =+F20*B20 -> 0.0028800306
A21: Move OWCs | B21: =+B18*'Arrival - Dispatch Profile'!D17 -> 0.065817267 | C21: =Productivities!D25*2 -> 14.981851 | D21: =+'Conversion Factors'!$E$19*0.5+'Conversion Factors'!$E$20*0.5 -> 200.08139 | E21: =+'Other Inputs'!D$16 -> 1.3606062 | F21: =+('Other Inputs'!D$4*E21)/(C21*D21) -> 0.022265531 | G21: =+F21*B21 -> 0.0014654564
A22: Load OTRs | B22: =+B20 -> 0.30456915 | C22: =Productivities!D30 -> 11.07946 | D22: =+'Conversion Factors'!$E$18 -> 471.11676 | E22: =+'Other Inputs'!D$16 -> 1.3606062 | F22: =+('Other Inputs'!D$4*E22)/(C22*D22) -> 0.012786688 | G22: =+F22*B22 -> 0.0038944307
A23: Load OWCs | B23: =+B21 -> 0.065817267 | C23: =Productivities!D30 -> 11.07946 | D23: =+'Conversion Factors'!$E$19*0.5+'Conversion Factors'!$E$20*0.5 -> 200.08139 | E23: =+'Other Inputs'!D$16 -> 1.3606062 | F23: =+('Other Inputs'!D$4*E23)/(C23*D23) -> 0.030107862 | G23: =+F23*B23 -> 0.0019816172
A24: Load Pallets | B24: =+B13 -> 0.40716392 | C24: =+Productivities!D$31 -> 14.25402 | D24: =+'Conversion Factors'!K$7 -> 371.35239 | E24: =+'Other Inputs'!D$16 -> 1.3606062 | F24: =+('Other Inputs'!D$4*E24)/(C24*D24) -> 0.012609029 | G24: =+F24*B24 -> 0.0051339416
A25: Bedload Sacks | B25: =+B19+B14 -> 0.16162727 | C25: =+Productivities!D29 -> 194.2556 | D25: =+'Conversion Factors'!K$10 -> 22.452033 | E25: =+'Other Inputs'!D$16 -> 1.3606062 | F25: =+('Other Inputs'!D$4*E25)/(C25*D25) -> 0.01530298 | G25: =+F25*B25 -> 0.0024733788
A26: Destination Delivery Unit | G26: =SUM(G27:G34) -> 0.22661885
A27: Unload OTRs | B27: =+B22 -> 0.30456915 | C27: =+Productivities!D7 -> 22.16117 | D27: =+'Conversion Factors'!E18 -> 471.11676 | E27: ='Other Inputs'!$D$17 -> 1.6214861 | F27: =+('Other Inputs'!D$4*E27)/(C27*D27) -> 0.0076184173 | G27: =+F27*B27 -> 0.0023203349
A28: Unload OWCs | B28: =+B23 -> 0.065817267 | C28: =+Productivities!D7 -> 22.16117 | D28: =+'Conversion Factors'!E20*0.5+'Conversion Factors'!E19*0.5 -> 200.08139 | E28: ='Other Inputs'!$D$17 -> 1.6214861 | F28: =+('Other Inputs'!D$4*E28)/(C28*D28) -> 0.01793852 | G28: =+F28*B28 -> 0.0011806644
A29: Unload Pallets | B29: =+B24+B9 -> 0.46798632 | C29: =+Productivities!D8 -> 13.055967 | D29: =+'Conversion Factors'!K7 -> 371.35239 | E29: ='Other Inputs'!$D$17 -> 1.6214861 | F29: =+('Other Inputs'!D$4*E29)/(C29*D29) -> 0.016405548 | G29: =+F29*B29 -> 0.007677572
A30: Unload Bedloaded Sacks | B30: =+B25 -> 0.16162727 | C30: =+Productivities!D6 -> 163.99154 | D30: =+'Conversion Factors'!K$10 -> 22.452033 | E30: ='Other Inputs'!$D$17 -> 1.6214861 | F30: =+('Other Inputs'!D$4*E30)/(C30*D30) -> 0.021602743 | G30: =+F30*B30 -> 0.0034915922
A31: Dump Sacks | B31: =B30 -> 0.16162727 | C31: =Productivities!$D$12 -> 109.06182 | D31: ='Conversion Factors'!$K$10 -> 22.452033 | E31: ='Other Inputs'!$D$17 -> 1.6214861 | F31: =+('Other Inputs'!D$4*E31)/(C31*D31) -> 0.032483107 | G31: =+F31*B31 -> 0.0052501558
A32: Move containers from dock | B32: 1 | C32: =Productivities!D26 -> 31.292492 | D32: =SUMPRODUCT(B27:B30,D27:D30) -> 334.07314 | E32: ='Other Inputs'!$D$17 -> 1.6214861 | F32: =+('Other Inputs'!D$4*E32)/(C32*D32) -> 0.007608592 | G32: =+F32*B32 -> 0.007608592
A33: Sort Flats | B33: ='Arrival - Dispatch Profile'!D29 -> 0.3158539 | C33: =Productivities!D34 -> 675.91285 | D33: 1 | E33: ='Other Inputs'!D19 -> 1.5675507 | F33: =+('Other Inputs'!D$4*E33)/(C33*D33) -> 0.11376369 | G33: =+F33*B33 -> 0.035932705
A34: Sort Parcels | B34: =1-'Arrival - Dispatch Profile'!D29 -> 0.6841461 | C34: =Productivities!D35 -> 307.66823 | D34: 1 | E34: ='Other Inputs'!D18 -> 1.4957787 | F34: =+('Other Inputs'!D$4*E34)/(C34*D34) -> 0.23848302 | G34: =+F34*B34 -> 0.16315723
E36: Modeled Cost | G36: =+G26+G10+G6 -> 0.96205129
A37: Sources
A38: [1]: Pages 3 and 4
A39: [2]: Page 2
A40: [3]: Page 5
A41: [4]: Page 4
A42: [5]: ( wage rate * [4] ) / ( [2] * [3] )
A43: [6]: [1] * [5]

Sheet DB_1
B1: Calculation of the Percent of outgoing costs DNDC Parcels Avoid
B5: Total BPM pieces going through Origin NDC | F5: =SUM(F6:F8) -> 0.29162273 | G5: 1/
B6: origin AO | F6: 0.027070495 | G6: 2/
B7: Origin SCF | F7: 0.055626948 | G7: 3/
B8: Origin NDC/ASF | F8: 0.20892529 | G8: 4/
B9: Total Pieces through destinating NDC (not origin NDC) | F9: =SUM(F10:F11) -> 0.46397709 | G9: 5/
B10: BPM entered at the destination NDC/ASF | F10: 0.41782202 | G10: 6/
B11: Entered at the NDC Service Area | F11: 0.046155068 | G11: 7/
B12: Total Pieces going through one or more NDCS | F12: =+F5+F9 -> 0.75559981 | G12: 8/
B14: Inter-NDC [1] | C14: Origin NDC | E14: Destination NDC
C15: out | D15: out | E15: in | F15: in
B16: Percent of total volume | C16: =+F5 -> 0.29162273 | D16: =+F5 -> 0.29162273 | E16: =+F5 -> 0.29162273 | F16: =+E16 -> 0.29162273 | G16: 9/
B17: Percent of volume that goes through one or more NDCS | C17: =+C16/F12 -> 0.38594865 | D17: =+D16/F12 -> 0.38594865 | E17: =+E16/F12 -> 0.38594865 | F17: =+F16/F12 -> 0.38594865 | G17: 10/
B18: Percent of outgoing costs | C18: =+C17/(C17+D17+E23) -> 0.27847255 | D18: =+D17/(C17+D17+E23) -> 0.27847255 | E18: n/a | F18: n/a | G18: 11/
B20: Intra-NDC/DNDC [2] | E20: Destination NDC
E21: out | F21: in
B22: Percent of total volume | E22: =+F9 -> 0.46397709 | F22: =+E22 -> 0.46397709 | G22: 12/
B23: Percent of volume that goes through one or more NDCS | E23: =+E22/F12 -> 0.61405135 | F23: =+F22/F12 -> 0.61405135 | G23: 13/
B24: Percent of outgoing costs | E24: =+E23/(C17+D17+E23) -> 0.44305491 | F24: n/a | G24: 14/
B28: Percent of NDC- outgoing Costs avoided by DNDC | F28: =+(C18+D18) -> 0.55694509 | G28: 15/
B31: Sources
B32: 1/: 2/ + 3/ + 4/
B33: 2/, 3/, 4/, 6/ & 7/: Docket No. R2000-1, USPS-T-27, Attachment H, revised 4/14/00.
B34: 5/: 6/ + 7/
B35: 8/: 1/ + 5/
B36: 9/: 1/
B37: 10/: 9/ divided by 8/
B38: 11/: Percent of outgoing costs in each column of 10/ divided by total percent of outgoing costs [38.6 / (38.6+ 38.6 + 61.4)].
B39: 12/: 5/
B40: 13/: 12/ divided by 8/
B41: 14/: Percent of outgoing costs in each column of 13/ divided by total percent of outgoing costs [61.4 / (38.6 + 38.6 + 61.4)].
B42: 15/: Percent of outgoing costs that DNDC avoids (27.8 + 27.8).
... B46: [2]: For intra-NDC and DNDC the first leg at destination NDC is outgoing and second leg is incoming.

Sheet DB_2
B2: Calculation of Bound Printed Matter DNDC Cost Savings
B6: Proportion of outgoing NDC costs avoided by DNDC | D6: =+DB_1!F28 -> 0.55694509 | E6: 1/
B7: NDC Outgoing costs (excluding platform acceptance) | D7: ='[10]Summary Flats+Parcels'!$F$66 -> 1779.9385 | E7: 2/
B8: Non-NDC Outgoing costs not including ASFs (excluding platform acceptance) | D8: ='[10]Summary Flats+Parcels'!$F$67 -> 19090.108 | E8: 3/
B9: ASF Outgoing Costs | D9: ='[10]Summary Flats+Parcels'!$H$64 -> 81.917621 | E9: 4/
B10: Percent of Volume ASF acts like NDC | D10: 0.361 | E10: 5/
B11: NDC Outgoing costs (including percent of ASF) | D11: =+D7+D10*D9 -> 1809.5107 | E11: 6/
B12: Non-NDC Outgoing costs (including percent of ASFs) | D12: =+D8+(1-D10)*D9 -> 19142.453 | E12: 7/
B13: BPM volume (000) | D13: =+'Flat - Parcel'!E5 -> 330171.47 | E13: 8/
B14: Proportion of volume deposited upstream of the DNDC | D14: =+DB_1!F5 -> 0.29162273 | E14: 9/
B15: Total costs avoided by DNDC entered BPM | D15: =D6*D11+D12 -> 20150.251 | E15: 10/
B16: Total volume of pieces deposited upstream of DNDC | D16: =+D13*D14 -> 96285.506 | E16: 11/
B19: Total estimated DNDC cost savings | D19: =D15/D16 -> 0.20927606 | E19: 12/
B21: Sources
B22: 1/: Page 8
B23: 2/: USPS-FY25-22
B24: 3/: USPS-FY25-22
B25: 4/: USPS-FY25-22
B26: 5/: Docket No. R2000-1, USPS-T-26, Attachment Y, page 2.
B27: 6/: 2/ + 4/ * 5/
B28: 7/: 3/ + ( 1 - 4/ )* 5/
B29: 8/: Page 11
B30: 9/: Page 8
B31: 10/: 1/ * 6/ + 7/
B32: 11/: 8/ * 9/
B33: 12/: 10/ divided by 11/

Sheet Carrier Route
A3: Mail Processing Costs Avoided By Carrier Route
A4: Presorted Bound Printed Matter
A6: Non-Carrier Route
A7: Wage Rate | E7: 1/ | F7: =+'Other Inputs'!D4 -> 49.053814
A8: Productivity | E8: 2/ | F8: =+Productivities!D35 -> 307.66823
A9: Unit Cost | E9: 3/ | F9: =+F7/F8 -> 0.15943737
A11: Carrier Route
A12: Productivity | E12: 4/ | F12: =+Productivities!D36 -> 4253.6708
A13: Unit Cost | E13: 5/ | F13: =+F7/F12 -> 0.011532114
A15: Piggyback Factor | E15: 6/ | F15: =+'Other Inputs'!D18 -> 1.4957787
A17: Total carrier route presort savings | E17: 7/ | F17: =+(F9-F13)*F15 -> 0.22123353
A20: Sources
A21: 1/: Page 4
A22: 2/: Page 2
A23: 3/: 1/ divided by 2/
A24: 4/: Page 2
A25: 5/: 1/ divided by 4/
A26: 6/: Page 4
A27: 7/: ( 3/ - 5/ ) * 6/

Sheet Flat - Parcel
B1: Calculation of Bound Printed Matter Flat/Parcel Delivery Cost Differential
C4: Flats | D4: Parcels | E4: Total
B5: Volumes (000s) | C5: ='[11]Adjusted RPW Rpt'!$G$44 -> 104285.95 | D5: ='[11]Adjusted RPW Rpt'!$G$45 -> 225885.53 | E5: =C5+D5 -> 330171.47 | G5: 1/
B6: Delivery Activities Costs | C6: =[12]CS07!$G$31 -> 1466.7021 | D6: =[12]CS07!$G$32 -> 53953.591 | E6: =SUM(C6:D6) -> 55420.293 | G6: 2/
B7: Piggyback Factor | C7: ='Other Inputs'!D21 -> 1.2660192 | D7: ='Other Inputs'!D21 -> 1.2660192 | G7: 3/
B8: Allocated Costs | C8: =C6*C7 -> 1856.873 | D8: =D6*D7 -> 68306.283 | G8: 4/
B9: Unit Costs | C9: =+C8/C5 -> 0.017805592 | D9: =+D8/D5 -> 0.30239336 | G9: 5/
B12: Unit Cost Difference Between Flats and Parcels | F12: =+D9-C9 -> 0.28458777 | G12: 6/
B15: Sources
B16: 1/: USPS-FY25-1
B17: 2/: USPS-FY25-2, CS 7.2
B18: 3/: Page 4
B19: 7/: 2/ * 3/
B20: 8/: 4/ divided by 1/
B21: 9/: Unit cost of parcels in 5/ - unit cost of flats in 5/

Sheet Barcode Savings
A1: Bound Printed Matter Barcode Savings Estimate
A4: [1] | B4: [2] | C4: [3] | D4: [4] | E4: [5] | F4: [6] | G4: [7]
A5: Time | B5: Vol Var | C5: Wage | D5: Direct | E5: Piggyback | F5: Total | G5: Total
A6: (Hours) | B6: Factor | C6: Rate | D6: Cost | E6: Factor | F6: Cost | G6: Cost (Cents)
A8: 0.00056 | B8: =Productivities!D41 -> 0.9584975 | C8: ='Other Inputs'!D4 -> 49.053814 | D8: =A8*B8*C8 -> 0.026330057 | E8: ='Other Inputs'!D12 -> 1.9204979 | F8: =D8*E8 -> 0.050566819 | G8: =F8*100 -> 5.0566819
A11: [1]: MTM-4M time estimate for keying 5-digit ZIP Code (USPS-FY08-15)
A12: [2]: Page 2
A13: [3]: Page 4
A14: [4]: [1] * [2] * [3]
A15: [5]: Page 4
A16: [6]: [4] * [5]
A17: [7]: [6] * 100 cents/dollar
