Workbook

Sheet SUMMARY
A1: MARKETING MAIL PRESORT LETTERS SUMMARY
A2: USPS-FY25-10
B4: [1]
B5: TOTAL MAIL
B6: PROCESSING
A7: PRICE CATEGORY | B7: UNIT COST
B8: (CENTS)
A9: Nonautomation Nonmachinable MADC Presort Letters | B9: ='PRESORT LETTERS SUM'!$G$35 -> 33.911953
A10: Nonautomation Nonmachinable ADC Presort Letters | B10: ='PRESORT LETTERS SUM'!$G$36 -> 24.478645
A11: Nonautomation Nonmachinable 3-Digit Presort Letters | B11: ='PRESORT LETTERS SUM'!$G$37 -> 21.675496
A12: Nonautomation Nonmachinable 5-Digit Presort Letters | B12: ='PRESORT LETTERS SUM'!$G$38 -> 12.887537
A13: Nonautomation Machinable MAADC Presort Letters | B13: ='PRESORT LETTERS SUM'!$G$39 -> 11.184447
A14: Nonautomation Machinable AADC Presort Letters | B14: ='PRESORT LETTERS SUM'!$G$40 -> 8.3010104
A15: Automation MAADC Presort Letters | B15: ='PRESORT LETTERS SUM'!$G$41 -> 10.466289
A16: ='PRESORT LETTERS SUM'!A21 -> Nonauto MAADC BC-Benchmark | B16: ='PRESORT LETTERS SUM'!G42 -> 10.827815
A17: Automation AADC Presort Letters | B17: ='PRESORT LETTERS SUM'!$G$43 -> 8.3652523
A18: Automation 3-Digit Presort Letters | B18: ='PRESORT LETTERS SUM'!$G$44 -> 7.2367202
A19: Automation 5-Digit Presort Letters | B19: ='PRESORT LETTERS SUM'!$G$45 -> 5.0844657
A22: Sources:
A23: [1]: from 'PRESORT LETTERS SUM'

Sheet PRESORT LETTERS SUM
A1: MARKETING MAIL PRESORT LETTERS MAIL PROCESSING UNIT COST SUMMARY
B2: =SUMMARY!A2 -> USPS-FY25-10
A5: Table 1: CRA Mail Processing Unit Costs
A6: Proportional Cost Pools | C6: 1/ | D6: ='CRA - PRESORT LETTERS'!E77 -> 4.5029068
A7: Fixed Cost Pools | C7: 2/ | D7: ='CRA - PRESORT LETTERS'!G77 -> 1.2543772
A8: Total | C8: 3/ | D8: =SUM(D6:D7) -> 5.757284
A11: Table 2: CRA Proportional Adjustment Factor
D12: Model Cost | E12: Volume | F12: Volume %
A13: Base Model Costs | D13: [1] | E13: ="[2]" -> [2] | F13: [3]
A14: Nonautomation Nonmachinable MADC | D14: ='NMACH MADC COST'!L44 -> 22.936282 | E14: ='MCS LETTERS'!E23 -> 749092 | F14: =E14/$E$25 -> 1.9755981e-05
A15: Nonautomation Nonmachinable ADC | D15: ='NMACH ADC COST'!L44 -> 16.311019 | E15: ='MCS LETTERS'!E33 -> 564492 | F15: =E15/$E$25 -> 1.4887481e-05
A16: Nonautomation Nonmachinable 3-Digit | D16: ='NMACH 3-DIGIT COST'!L44 -> 14.342293 | E16: ='MCS LETTERS'!E40 -> 1694020 | F16: =E16/$E$25 -> 4.4676792e-05
A17: Nonautomation Nonmachinable 5-Digit | D17: ='NMACH 5-DIGIT COST'!L44 -> 8.1702765 | E17: ='MCS LETTERS'!E46 -> 1302844 | F17: =E17/$E$25 -> 3.4360214e-05
A18: Nonautomation Machinable MAADC | D18: ='MACH MAADC COST'!L44 -> 6.9741514 | E18: ='MCS LETTERS'!E7 -> 160965393 | F18: =E18/$E$25 -> 0.0042451785
A19: Nonautomation Machinable AADC | D19: ='MACH AADC COST'!L44 -> 4.9490374 | E19: ='MCS LETTERS'!E14 -> 323862051 | F19: =E19/$E$25 -> 0.0085412907
A20: Automation MAADC | D20: =+'AUTO MAADC COST'!L44 -> 6.4697696 | E20: ='MCS LETTERS'!E50 -> 9.7280613e+08 | F20: =E20/$E$25 -> 0.025656047
A21: Nonauto MAADC BC-Benchmark | D21: ='MACH MAADC BC-BENCH COST '!L44 -> 6.7236795 | E21: NA | F21: NA
A22: Automation AADC | D22: =+'AUTO AADC COST'!L44 -> 4.9941562 | E22: ='MCS LETTERS'!E51 -> 5.5417778e+09 | F22: =E22/$E$25 -> 0.14615462
A23: Automation 3-Digit | D23: =+'AUTO 3-DIGIT COST'!L44 -> 4.2015581 | E23: ='MCS LETTERS'!E52 -> 57876.221 | F23: =E23/$E$25 -> 1.5263833e-06
A24: Automation 5-Digit | D24: =+'AUTO 5-DIGIT COST'!L44 -> 2.6899728 | E24: ='MCS LETTERS'!E53 -> 3.0913446e+10 | F24: =E24/$E$25 -> 0.81528765
A25: Total Weighted Model Cost | C25: 4/ | D25: =SUMPRODUCT(D14:D24,F14:F24) -> 3.1625109 | E25: =SUM(E14:E24) -> 3.7917226e+10 | F25: =SUM(F14:F24) -> 1
A27: CRA Proportional Adjustment | C27: 5/ | D27: =+D6/D25 -> 1.4238392
GN28: .
A30: Table 3: Adjusted Letter Unit Mail Processing Costs
E31: CRA | F31: Fixed | G31: Total
D32: Model | E32: Adjusted | F32: Cost Pool | G32: Mail Proc
D33: Unit Cost | E33: Unit Cost | F33: Unit Cost | G33: Unit Cost
A34: Price Category | D34: [4] | E34: [5] | F34: [6] | G34: [7]
A35: Nonautomation Nonmachinable MADC | D35: =D14 -> 22.936282 | E35: =+D35*$D$27 -> 32.657576 | F35: =+$D$7 -> 1.2543772 | G35: =+F35+E35 -> 33.911953
A36: Nonautomation Nonmachinable ADC | D36: =D15 -> 16.311019 | E36: =+D36*$D$27 -> 23.224268 | F36: =+$D$7 -> 1.2543772 | G36: =+F36+E36 -> 24.478645
A37: Nonautomation Nonmachinable 3-Digit | D37: =D16 -> 14.342293 | E37: =+D37*$D$27 -> 20.421119 | F37: =+$D$7 -> 1.2543772 | G37: =+F37+E37 -> 21.675496
A38: Nonautomation Nonmachinable 5-Digit | D38: =D17 -> 8.1702765 | E38: =+D38*$D$27 -> 11.63316 | F38: =+$D$7 -> 1.2543772 | G38: =+F38+E38 -> 12.887537
A39: Nonautomation Machinable MAADC | D39: =D18 -> 6.9741514 | E39: =+D39*$D$27 -> 9.9300698 | F39: =+$D$7 -> 1.2543772 | G39: =+F39+E39 -> 11.184447
A40: Nonautomation Machinable AADC | D40: =D19 -> 4.9490374 | E40: =+D40*$D$27 -> 7.0466332 | F40: =+$D$7 -> 1.2543772 | G40: =+F40+E40 -> 8.3010104
A41: Automation MAADC | D41: =+D20 -> 6.4697696 | E41: =+D41*$D$27 -> 9.2119114 | F41: =+$D$7 -> 1.2543772 | G41: =+F41+E41 -> 10.466289
A42: =A21 -> Nonauto MAADC BC-Benchmark | D42: =D21 -> 6.7236795 | E42: =+D42*$D$27 -> 9.5734381 | F42: =+$D$7 -> 1.2543772 | G42: =+F42+E42 -> 10.827815
A43: Automation AADC | D43: =+D22 -> 4.9941562 | E43: =+D43*$D$27 -> 7.1108751 | F43: =+$D$7 -> 1.2543772 | G43: =+F43+E43 -> 8.3652523
A44: Automation 3-Digit | D44: =+D23 -> 4.2015581 | E44: =+D44*$D$27 -> 5.982343 | F44: =+$D$7 -> 1.2543772 | G44: =+F44+E44 -> 7.2367202
A45: Automation 5-Digit | D45: =+D24 -> 2.6899728 | E45: =+D45*$D$27 -> 3.8300885 | F45: =+$D$7 -> 1.2543772 | G45: =+F45+E45 -> 5.0844657
A48: Sources:
...

Sheet CRA - PRESORT LETTERS
A1: MARKETING MAIL PRESORT LETTERS
A2: CRA MAIL PROCESSING COSTS
A3: Source: USPS-FY25-26
A4: Source - Worksheet LTTR Unit Costs Final Adj.
E5: Worksharing-Related
A6: Cost Pools | C6: Total (Cents) | E6: Proportional (Cents) | G6: Fixed (Cents) | K6: Key | L6: Treatment
A7: MODS 11 | B7: D/BCS | C7: ='[1]LTTR Unit Costs Final Adj.'!$J$6 -> 2.6022915 | E7: =+C7 -> 2.6022915 | K7: Piece Sorting | L7: Proportional
A8: MODS 12 | B8: AFSM100 | C8: ='[1]LTTR Unit Costs Final Adj.'!$J$7 -> 0.15318384 | E8: =IF($M$10=1,$C8*E$80,0) -> 0.11980867 | G8: =IF($M$10=1,$C8*G$80,0) -> 0.033375166 | K8: Fwd/Accept/Cust.Srv. | L8: WS Fixed
K9: Non-WS | L9: Non WS
A10: MODS 12 | B10: FSS | C10: 0 | E10: =IF($M$10=1,$C10*E$80,0) -> 0 | G10: =IF($M$10=1,$C10*G$80,0) -> 0 | K10: Unexpected | L10: =IF(M10=1,"Piggybacked","Non WS") -> Piggybacked | M10: 1
A12: MODS 13 | B12: APBS BUNDLE | C12: ='[1]LTTR Unit Costs Final Adj.'!J9 -> 0.0030796966 | E12: =IF($M$10=1,$C12*E$80,0) -> 0.0024087029 | G12: =IF($M$10=1,$C12*G$80,0) -> 0.00067099368 | K12: Allied/Support | L12: Piggybacked
A13: MODS 13 | B13: APBSPRIO | C13: ='[1]LTTR Unit Costs Final Adj.'!J10 -> 0.044134805 | E13: =IF($M$10=1,$C13*E$80,0) -> 0.034518866 | G13: =IF($M$10=1,$C13*G$80,0) -> 0.0096159391
A14: MODS 16 | B14: LCUS-SSM | C14: ='[1]LTTR Unit Costs Final Adj.'!J11 -> 0.0071404652 | E14: =IF($M$10=1,$C14*E$80,0) -> 0.0055847253 | G14: =IF($M$10=1,$C14*G$80,0) -> 0.0015557399 | K14: Note: OPBULK, OPPREF and Pouching
A15: MODS 16 | B15: 1TRAYSRT | C15: ='[1]LTTR Unit Costs Final Adj.'!J12 -> 0.42395533 | E15: =IF($M$10=1,$C15*E$80,0) -> 0.33158541 | G15: =IF($M$10=1,$C15*G$80,0) -> 0.092369926 | K15: were WS related fixed in 3 column system,
A16: MODS 14 | B16: MANF | C16: ='[1]LTTR Unit Costs Final Adj.'!J13 -> 0.0085569915 | E16: =IF($M$10=1,$C16*E$80,0) -> 0.0066926237 | G16: =IF($M$10=1,$C16*G$80,0) -> 0.0018643678 | K16: are grouped with prep and accept
A17: MODS 14 | B17: MANL | C17: ='[1]LTTR Unit Costs Final Adj.'!J14 -> 0.093758368 | E17: =+C17 -> 0.093758368
A18: MODS 14 | B18: MANP | C18: ='[1]LTTR Unit Costs Final Adj.'!J15 -> 0.00045205948 | E18: =IF($M$10=1,$C18*E$80,0) -> 0.00035356632 | G18: =IF($M$10=1,$C18*G$80,0) -> 9.849316e-05
A19: MODS 14 | B19: PRIORITY | C19: ='[1]LTTR Unit Costs Final Adj.'!J16 -> 0.019743508 | E19: =IF($M$10=1,$C19*E$80,0) -> 0.01544186 | G19: =IF($M$10=1,$C19*G$80,0) -> 0.0043016474
A20: MODS 15 | B20: LD15 | C20: ='[1]LTTR Unit Costs Final Adj.'!J17 -> 0.02218547 | E20: =+C20 -> 0.02218547
A21: MODS 17 | B21: 1CANCEL | C21: ='[1]LTTR Unit Costs Final Adj.'!J18 -> 0.08608814 | G21: =C21 -> 0.08608814
A22: MODS 17 | B22: 1DSPATCH | C22: ='[1]LTTR Unit Costs Final Adj.'!J19 -> 0.039376403 | E22: =IF($M$10=1,$C22*E$80,0) -> 0.030797208 | G22: =IF($M$10=1,$C22*G$80,0) -> 0.008579195
A24: MODS 17 | B24: 1MTRPREP | C24: ='[1]LTTR Unit Costs Final Adj.'!J20 -> 0 | G24: =C24 -> 0
A25: MODS 17 | B25: 1OPBULK | C25: ='[1]LTTR Unit Costs Final Adj.'!J21 -> 0.033370231 | G25: =C25 -> 0.033370231
A26: MODS 17 | B26: 1OPPREF | C26: ='[1]LTTR Unit Costs Final Adj.'!J22 -> 0.08217979 | G26: =C26 -> 0.08217979
A27: MODS 17 | B27: 1OPTRANS | C27: ='[1]LTTR Unit Costs Final Adj.'!J23 -> 0.011218315 | E27: =IF($M$10=1,$C27*E$80,0) -> 0.0087741076 | G27: =IF($M$10=1,$C27*G$80,0) -> 0.0024442079
A28: MODS 17 | B28: 1PLATFRM | C28: ='[1]LTTR Unit Costs Final Adj.'!J24 -> 0.65124533 | G28: =C28 -> 0.65124533
A29: MODS 17 | B29: 1POUCHNG | C29: ='[1]LTTR Unit Costs Final Adj.'!J25 -> 0.0024506864 | G29: =C29 -> 0.0024506864
A30: MODS 17 | B30: 1PRESORT | C30: ='[1]LTTR Unit Costs Final Adj.'!J26 -> 0.0079116241 | E30: =IF($M$10=1,$C30*E$80,0) -> 0.0061878667 | G30: =IF($M$10=1,$C30*G$80,0) -> 0.0017237574
A31: MODS 17 | B31: 1SACKS_H | C31: ='[1]LTTR Unit Costs Final Adj.'!J27 -> 0.0030909372 | E31: =IF($M$10=1,$C31*E$80,0) -> 0.0024174945 | G31: =IF($M$10=1,$C31*G$80,0) -> 0.00067344275
A32: MODS 17 | B32: 1SCAN | C32: ='[1]LTTR Unit Costs Final Adj.'!J28 -> 0.02225935 | E32: =IF($M$10=1,$C32*E$80,0) -> 0.017409559 | G32: =IF($M$10=1,$C32*G$80,0) -> 0.0048497904
A33: MODS 18 | B33: BUSREPLY | C33: ='[1]LTTR Unit Costs Final Adj.'!J29 -> 0.00066310084 | G33: =C33 -> 0.00066310084
A34: MODS 18 | B34: EXPRESS | C34: ='[1]LTTR Unit Costs Final Adj.'!J30 -> 0.002571013 | E34: =IF($M$10=1,$C34*E$80,0) -> 0.0020108495 | G34: =IF($M$10=1,$C34*G$80,0) -> 0.00056016345
A35: MODS 18 | B35: REGISTRY | C35: ='[1]LTTR Unit Costs Final Adj.'!J31 -> 0.0023272979 | G35: =C35 -> 0.0023272979
A36: MODS 18 | B36: REWRAP | C36: ='[1]LTTR Unit Costs Final Adj.'!J32 -> 0.0027783631 | E36: =IF($M$10=1,$C36*E$80,0) -> 0.0021730229 | G36: =IF($M$10=1,$C36*G$80,0) -> 0.00060534016
A37: MODS 18 | B37: 1EEQMT | C37: ='[1]LTTR Unit Costs Final Adj.'!J33 -> 0.045165054 | E37: =IF($M$10=1,$C37*E$80,0) -> 0.035324648 | G37: =IF($M$10=1,$C37*G$80,0) -> 0.0098404063
A38: MODS 18 | B38: 1MISC | C38: ='[1]LTTR Unit Costs Final Adj.'!J34 -> 0.0234384 | E38: =IF($M$10=1,$C38*E$80,0) -> 0.018331722 | G38: =IF($M$10=1,$C38*G$80,0) -> 0.0051066778
A39: MODS 18 | B39: 1SUPPORT | C39: ='[1]LTTR Unit Costs Final Adj.'!J35 -> 0.017635839 | E39: =IF($M$10=1,$C39*E$80,0) -> 0.013793403 | G39: =IF($M$10=1,$C39*G$80,0) -> 0.0038424357
A40: MODS 19 | B40: INTL ISC | C40: ='[1]LTTR Unit Costs Final Adj.'!J36 -> 0.00059656028 | E40: =IF($M$10=1,$C40*E$80,0) -> 0.00046658378 | G40: =IF($M$10=1,$C40*G$80,0) -> 0.0001299765
A51: MODS Subtotal | C51: =SUM(C7:C50) -> 4.4128485 | E51: =SUM(E7:E50) -> 3.3723163 | G51: =SUM(G7:G50) -> 1.0405322
A52: NDCS | B52: FSS | C52: 0 | E52: =IF($M$10=1,$C52*E$80,0) -> 0 | G52: =IF($M$10=1,$C52*G$80,0) -> 0
...

Sheet AUTO MAADC COST
A1: MARKETING MAIL AUTOMATION MAADC PRESORTED LETTERS
A2: COST SHEET
A3: Total Pieces | C3: =+'AUTO MAADC MODEL'!N4 -> 10000
C6: [1] | E6: [2] | G6: [3] | H6: [4] | I6: [5] | J6: [6] | K6: [7] | L6: [8]
H7: Direct | I7: Premium | K7: Total | L7: Weighted
E8: Pieces | G8: Wage | H8: Cents | I8: Pay | J8: Piggyback | K8: Cents | L8: Cents
C9: TPH | E9: Per Hour | G9: Rate | H9: Per Piece | I9: Adjust | J9: Factor | K9: Per Piece | L9: Per Piece
A10: Entry Activities
B11: Package Sorting
A12: Outgoing RBCS
B13: ISS | C13: =+'AUTO MAADC MODEL'!G18 -> 0 | E13: =+PRODUCTIVITY!I7 -> 6833.2327 | G13: =+'WAGE RATE - PIGGYBACK FACTORS'!$D$5 -> 50.107175 | H13: =+G13/E13*100 -> 0.73328652 | I13: =+H13*('WAGE RATE - PIGGYBACK FACTORS'!$D$6-1) -> -0.019000285 | J13: =+'WAGE RATE - PIGGYBACK FACTORS'!D19 -> 1.6888485 | K13: =+H13*J13+I13 -> 1.2194096 | L13: =+(K13*C13/10000) -> 0
B14: RCR | C14: =+'AUTO MAADC MODEL'!G25 -> 0 | E14: -- | G14: -- | H14: -- | I14: -- | J14: -- | K14: =+MISC!$E$7 -> 0.27889541 | L14: =+K14*C14/10000 -> 0
B15: REC | C15: =+'AUTO MAADC MODEL'!G32 -> 0 | E15: =+PRODUCTIVITY!I9 -> 846.86663 | G15: =+'WAGE RATE - PIGGYBACK FACTORS'!$D$4 -> 54.14236 | H15: =+G15/E15*100 -> 6.393257 | I15: =+H15*('WAGE RATE - PIGGYBACK FACTORS'!$D$6-1) -> -0.16565654 | J15: =+'WAGE RATE - PIGGYBACK FACTORS'!D20 -> 1.2615773 | K15: =+H15*J15+I15 -> 7.8999315 | L15: =+(K15*C15/10000) -> 0
B16: OSS | C16: =+'AUTO MAADC MODEL'!G39 -> 0 | E16: =+PRODUCTIVITY!I11 -> 6833.2327 | G16: =+'WAGE RATE - PIGGYBACK FACTORS'!$D$5 -> 50.107175 | H16: =+G16/E16*100 -> 0.73328652 | I16: =+H16*('WAGE RATE - PIGGYBACK FACTORS'!$D$6-1) -> -0.019000285 | J16: =+'WAGE RATE - PIGGYBACK FACTORS'!D21 -> 1.6888485 | K16: =+H16*J16+I16 -> 1.2194096 | L16: =+(K16*C16/10000) -> 0
B17: LCREM | C17: =+'AUTO MAADC MODEL'!C32 -> 0 | E17: =+PRODUCTIVITY!I10 -> 1983.2154 | G17: =+'WAGE RATE - PIGGYBACK FACTORS'!$D$5 -> 50.107175 | H17: =+G17/E17*100 -> 2.5265624 | I17: =+H17*('WAGE RATE - PIGGYBACK FACTORS'!$D$6-1) -> -0.065466096 | J17: =+'WAGE RATE - PIGGYBACK FACTORS'!D22 -> 3.4396835 | K17: =+H17*J17+I17 -> 8.6251087 | L17: =+(K17*C17/10000) -> 0
A18: Outgoing Primary
B19: Automation | C19: =+'AUTO MAADC MODEL'!S16 -> 10006.365 | E19: =+PRODUCTIVITY!I13 -> 6833.2327 | G19: =+'WAGE RATE - PIGGYBACK FACTORS'!$D$5 -> 50.107175 | H19: =+G19/E19*100 -> 0.73328652 | I19: =+H19*('WAGE RATE - PIGGYBACK FACTORS'!$D$6-1) -> -0.019000285 | J19: =+'WAGE RATE - PIGGYBACK FACTORS'!D23 -> 1.6888485 | K19: =+H19*J19+I19 -> 1.2194096 | L19: =+(K19*C19/10000) -> 1.2201857
B20: Manual | C20: =+'AUTO MAADC MODEL'!AA16 -> 274.90987 | E20: =+PRODUCTIVITY!I20 -> 631.32213 | G20: =+'WAGE RATE - PIGGYBACK FACTORS'!$D$5 -> 50.107175 | H20: =+G20/E20*100 -> 7.9368633 | I20: =+H20*('WAGE RATE - PIGGYBACK FACTORS'!$D$6-1) -> -0.20565313 | J20: =+'WAGE RATE - PIGGYBACK FACTORS'!D24 -> 1.2988119 | K20: =+H20*J20+I20 -> 10.10284 | L20: =+(K20*C20/10000) -> 0.27773703
A21: Outgoing Secondary | K21: =+H21*J21+I21 -> 0 | L21: =+(K21*C21/10000) -> 0
B22: Automation | C22: =+'AUTO MAADC MODEL'!S24 -> 93.7885 | E22: =+PRODUCTIVITY!I14 -> 5441.4416 | G22: =+'WAGE RATE - PIGGYBACK FACTORS'!$D$5 -> 50.107175 | H22: =+G22/E22*100 -> 0.92084374 | I22: =+H22*('WAGE RATE - PIGGYBACK FACTORS'!$D$6-1) -> -0.023860106 | J22: =+'WAGE RATE - PIGGYBACK FACTORS'!D25 -> 1.6888485 | K22: =+H22*J22+I22 -> 1.5313055 | L22: =+(K22*C22/10000) -> 0.014361884
B23: Manual | C23: =+'AUTO MAADC MODEL'!AA24 -> 50.269122 | E23: =+PRODUCTIVITY!I21 -> 1087.9987 | G23: =+'WAGE RATE - PIGGYBACK FACTORS'!$D$5 -> 50.107175 | H23: =+G23/E23*100 -> 4.6054442 | I23: =+H23*('WAGE RATE - PIGGYBACK FACTORS'!$D$6-1) -> -0.11933228 | J23: =+'WAGE RATE - PIGGYBACK FACTORS'!D26 -> 1.2988119 | K23: =+H23*J23+I23 -> 5.8622736 | L23: =+(K23*C23/10000) -> 0.029469134
A24: Incoming RBCS
B25: ISS | C25: =+'AUTO MAADC MODEL'!G51 -> 0 | E25: =+PRODUCTIVITY!I8 -> 5815.8678 | G25: =+'WAGE RATE - PIGGYBACK FACTORS'!$D$5 -> 50.107175 | H25: =+G25/E25*100 -> 0.86155972 | I25: =+H25*('WAGE RATE - PIGGYBACK FACTORS'!$D$6-1) -> -0.022323989 | J25: =+'WAGE RATE - PIGGYBACK FACTORS'!D27 -> 1.6888485 | K25: =+H25*J25+I25 -> 1.4327199 | L25: =+(K25*C25/10000) -> 0
B26: RCR | C26: =+'AUTO MAADC MODEL'!G58 -> 0 | E26: -- | G26: -- | H26: -- | I26: -- | J26: -- | K26: =+MISC!$E$7 -> 0.27889541 | L26: =+(K26*C26/10000) -> 0
B27: REC | C27: =+'AUTO MAADC MODEL'!G65 -> 0 | E27: =+PRODUCTIVITY!I9 -> 846.86663 | G27: =+'WAGE RATE - PIGGYBACK FACTORS'!$D$4 -> 54.14236 | H27: =+G27/E27*100 -> 6.393257 | I27: =+H27*('WAGE RATE - PIGGYBACK FACTORS'!$D$6-1) -> -0.16565654 | J27: =+'WAGE RATE - PIGGYBACK FACTORS'!D28 -> 1.2615773 | K27: =+H27*J27+I27 -> 7.8999315 | L27: =+(K27*C27/10000) -> 0
B28: OSS | C28: =+'AUTO MAADC MODEL'!G72 -> 0 | E28: =+PRODUCTIVITY!I12 -> 5815.8678 | G28: =+'WAGE RATE - PIGGYBACK FACTORS'!$D$5 -> 50.107175 | H28: =+G28/E28*100 -> 0.86155972 | I28: =+H28*('WAGE RATE - PIGGYBACK FACTORS'!$D$6-1) -> -0.022323989 | J28: =+'WAGE RATE - PIGGYBACK FACTORS'!D29 -> 1.6888485 | K28: =+H28*J28+I28 -> 1.4327199 | L28: =+(K28*C28/10000) -> 0
B29: LCREM | C29: =+'AUTO MAADC MODEL'!C65 -> 0 | E29: =+PRODUCTIVITY!I10 -> 1983.2154 | G29: =+'WAGE RATE - PIGGYBACK FACTORS'!$D$5 -> 50.107175 | H29: =+G29/E29*100 -> 2.5265624 | I29: =+H29*('WAGE RATE - PIGGYBACK FACTORS'!$D$6-1) -> -0.065466096 | J29: =+'WAGE RATE - PIGGYBACK FACTORS'!D30 -> 3.4396835 | K29: =+H29*J29+I29 -> 8.6251087 | L29: =+(K29*C29/10000) -> 0
A30: Incoming MMP
B31: Automation AADC | C31: =+'AUTO MAADC MODEL'!S32 -> 5567.7046 | E31: =+PRODUCTIVITY!I15 -> 5271.1402 | G31: =+'WAGE RATE - PIGGYBACK FACTORS'!$D$5 -> 50.107175 | H31: =+G31/E31*100 -> 0.95059461 | I31: =+H31*('WAGE RATE - PIGGYBACK FACTORS'!$D$6-1) -> -0.024630984 | J31: =+'WAGE RATE - PIGGYBACK FACTORS'!D31 -> 1.6888485 | K31: =+H31*J31+I31 -> 1.5807793 | L31: =+(K31*C31/10000) -> 0.88013123
B32: Manual ADC | C32: =+'AUTO MAADC MODEL'!AA32 -> 333.64366 | E32: =+PRODUCTIVITY!I22 -> 1213.9421 | G32: =+'WAGE RATE - PIGGYBACK FACTORS'!$D$5 -> 50.107175 | H32: =+G32/E32*100 -> 4.1276414 | I32: =+H32*('WAGE RATE - PIGGYBACK FACTORS'!$D$6-1) -> -0.10695187 | J32: =+'WAGE RATE - PIGGYBACK FACTORS'!D32 -> 1.2988119 | K32: =+H32*J32+I32 -> 5.254078 | L32: =+(K32*C32/10000) -> 0.17529898
A33: Incoming SCF/Primary
B34: Automation | C34: =+'AUTO MAADC MODEL'!S40 -> 4661.5696 | E34: =+PRODUCTIVITY!I16 -> 10175.777 | G34: =+'WAGE RATE - PIGGYBACK FACTORS'!$D$5 -> 50.107175 | H34: =+G34/E34*100 -> 0.49241622 | I34: =+H34*('WAGE RATE - PIGGYBACK FACTORS'!$D$6-1) -> -0.012759063 | J34: =+'WAGE RATE - PIGGYBACK FACTORS'!D33 -> 1.6888485 | K34: =+H34*J34+I34 -> 0.81885733 | L34: =+(K34*C34/10000) -> 0.38171604
B35: Manual | C35: =+'AUTO MAADC MODEL'!AA40 -> 621.01557 | E35: =+PRODUCTIVITY!I23 -> 1107.0494 | G35: =+'WAGE RATE - PIGGYBACK FACTORS'!$D$5 -> 50.107175 | H35: =+G35/E35*100 -> 4.5261912 | I35: =+H35*('WAGE RATE - PIGGYBACK FACTORS'!$D$6-1) -> -0.11727875 | J35: =+'WAGE RATE - PIGGYBACK FACTORS'!D34 -> 1.2988119 | K35: =+H35*J35+I35 -> 5.7613924 | L35: =+(K35*C35/10000) -> 0.35779144
A36: Incoming Secondaries
B37: Auto Carrier Route | C37: =+'AUTO MAADC MODEL'!W49 -> 323.22806 | E37: =+PRODUCTIVITY!I17 -> 13094.299 | G37: =+'WAGE RATE - PIGGYBACK FACTORS'!$D$5 -> 50.107175 | H37: =+G37/E37*100 -> 0.38266404 | I37: =+H37*('WAGE RATE - PIGGYBACK FACTORS'!$D$6-1) -> -0.0099152592 | J37: =+'WAGE RATE - PIGGYBACK FACTORS'!D35 -> 1.6888485 | K37: =+H37*J37+I37 -> 0.63634633 | L37: =+(K37*C37/10000) -> 0.020568499
B38: Auto 3-Pass DPS | C38: =+'AUTO MAADC MODEL'!W56 -> 0 | E38: =+PRODUCTIVITY!I19 -> 0 | G38: =+'WAGE RATE - PIGGYBACK FACTORS'!$D$5 -> 50.107175 | H38: 0 | I38: =+H38*('WAGE RATE - PIGGYBACK FACTORS'!$D$6-1) -> 0 | J38: =+'WAGE RATE - PIGGYBACK FACTORS'!D36 -> 0 | K38: =+H38*J38+I38 -> 0 | L38: =+(K38*C38/10000) -> 0
B39: Auto 2-Pass DPS | C39: =+'AUTO MAADC MODEL'!W63 -> 17608.085 | E39: =+PRODUCTIVITY!I18 -> 6910.0702 | G39: =+'WAGE RATE - PIGGYBACK FACTORS'!$D$5 -> 50.107175 | H39: =+G39/E39*100 -> 0.72513264 | I39: =+H39*('WAGE RATE - PIGGYBACK FACTORS'!$D$6-1) -> -0.018789009 | J39: =+'WAGE RATE - PIGGYBACK FACTORS'!D37 -> 1.6888485 | K39: =+H39*J39+I39 -> 1.2058502 | L39: =+(K39*C39/10000) -> 2.1232712
B40: Man Inc Sec Final At DU | C40: =+'AUTO MAADC MODEL'!AA74*(1-MISC!E9) -> 1041.2543 | E40: =+PRODUCTIVITY!I24 -> 810.31043 | G40: =+'WAGE RATE - PIGGYBACK FACTORS'!$D$5 -> 50.107175 | H40: =+G40/E40*100 -> 6.183701 | I40: =+H40*('WAGE RATE - PIGGYBACK FACTORS'!$D$6-1) -> -0.1602267 | J40: =+'WAGE RATE - PIGGYBACK FACTORS'!D39 -> 1.2988119 | K40: =+H40*J40+I40 -> 7.8712379 | L40: =+(K40*C40/10000) -> 0.81959602
B41: Box Section Sort, DPS | C41: =+MISC!E10*('AUTO MAADC MODEL'!AE64+'AUTO MAADC MODEL'!AE57) -> 396.65829 | E41: =+PRODUCTIVITY!I25 -> 1955.1935 | G41: =+'WAGE RATE - PIGGYBACK FACTORS'!$D$5 -> 50.107175 | H41: =+G41/E41*100 -> 2.5627732 | I41: =+H41*('WAGE RATE - PIGGYBACK FACTORS'!$D$6-1) -> -0.066404359 | J41: =+'WAGE RATE - PIGGYBACK FACTORS'!D40 -> 1.2988119 | K41: =+H41*J41+I41 -> 3.262156 | L41: =+(K41*C41/10000) -> 0.12939612
B42: Box Section Sort, Other | C42: =+MISC!E10*('AUTO MAADC MODEL'!AE75+'AUTO MAADC MODEL'!AE50) -> 61.686713 | E42: =+PRODUCTIVITY!I26 -> 977.59674 | G42: =+'WAGE RATE - PIGGYBACK FACTORS'!$D$5 -> 50.107175 | H42: =+G42/E42*100 -> 5.1255464 | I42: =+H42*('WAGE RATE - PIGGYBACK FACTORS'!$D$6-1) -> -0.13280872 | J42: =+'WAGE RATE - PIGGYBACK FACTORS'!D41 -> 1.2988119 | K42: =+H42*J42+I42 -> 6.5243121 | L42: =+(K42*C42/10000) -> 0.040246337
...

Sheet AUTO MAADC MODEL
B1: MARKETING MAIL AUTOMATION MAADC PRESORTED LETTERS
B2: MAIL FLOW MODEL
B4: PCS IN = | E4: 10000 | K4: PCS OUT = | N4: =AE50+AE57+AE64+AE75 -> 10000
B6: ENTRY POINTS:
B7: Out ISS | E7: 0 | H7: Inc ISS/RCR | K7: 0 | N7: Inc ADC Man | Q7: 0
B8: Out RCR | E8: 0 | H8: Inc MMP Auto | K8: 0 | N8: Inc SCF/Prim Man | Q8: 0
B9: Out Prim Auto | E9: =10000 -> 10000 | H9: Inc SCF/Prim Auto | K9: 0 | N9: Inc Sec Man | Q9: 0
B10: Out Sec Auto | E10: 0 | H10: Inc Sec Auto | K10: 0
B11: Out Prim Man | E11: 0
B12: Out Sec Man | E12: 0
B14: OUTGOING RBCS | S14: Out Prim Auto | V14: =+T16*(1-ACCEPT!C15) -> 274.90987 | W14: Rejects to Out Prim Man | AA14: Out Prim Man
I15: =+H18*ACCEPT!$C$5 -> 0 | K15: =+I15+I16 -> 0 | N15: =+(K15)*DENSITY!C7 -> 0 | O15: Out Prim Auto | AD15: =+AB16*DENSITY!D14 -> 47.859411 | AE15: Out Sec Man
G16: Out ISS | I16: =+(C20+E27)*(ACCEPT!$C$5) -> 0 | N16: =+(K15)*DENSITY!D7 -> 0 | O16: Out Sec Auto | S16: =+T16*(1+DENSITY!B9) -> 10006.365 | T16: =+E9+N15+N41 -> 10000 | W16: =+V17*DENSITY!D9 -> 93.529059 | X16: Out Sec Auto | AA16: =+AB16 -> 274.90987 | AB16: =+E11+N31+N39+V14 -> 274.90987 | AD16: =+AB16*DENSITY!E14 -> 48.980717 | AE16: Inc ADC Man
N17: =+(K15)*DENSITY!E7 -> 0 | O17: Inc MMP Auto | V17: =+T16*ACCEPT!C15 -> 9725.0901 | W17: =+V17*DENSITY!E9 -> 5480.645 | X17: Inc MMP Auto | AD17: =+AB16*DENSITY!F14 -> 178.06975 | AE17: Inc Prim Man
G18: =+H18*(1+DENSITY!B7)+C20+E27 -> 0 | H18: =+E7 -> 0 | N18: =+(K15)*DENSITY!F7 -> 0 | O18: Inc SCF/Prim Auto | W18: =+V17*DENSITY!F9 -> 4150.9161 | X18: Inc SCF/Prim Auto | AD18: =+AB16*DENSITY!G14 -> 0 | AE18: Inc Sec Man
N19: =+(K15)*DENSITY!G7 -> 0 | O19: Inc Sec Auto | W19: =+V17*DENSITY!G9 -> 0 | X19: Inc Sec Auto
C20: =+C32 -> 0
G21: =+(C20+E27)*(1-ACCEPT!C5) -> 0 | H21: =+H18*(1-ACCEPT!C5) -> 0
S22: Out Sec Auto | V22: =+T24*(1-ACCEPT!C16) -> 2.4097103 | W22: Rejects to Out Sec Man | AA22: Out Sec Man
G23: Out RCR
S24: =+T24*(1+DENSITY!B10) -> 93.7885 | T24: =+E10+N16+N42+W16 -> 93.529059 | W24: =+V25*DENSITY!E10 -> 52.371312 | X24: Inc MMP Auto | AA24: =+AB24 -> 50.269122 | AB24: =+E12+V22+AD15 -> 50.269122 | AD24: =+AB24*DENSITY!E15 -> 40.692831 | AE24: Inc ADC Man
G25: =+G21+H25 -> 0 | H25: =+H21+E8 -> 0 | I25: (to out OSS) | V25: =+T24*ACCEPT!C16 -> 91.119349 | W25: =+V25*DENSITY!F10 -> 38.748037 | X25: Inc SCF/Prim Auto | AD25: =+AB24*DENSITY!F15 -> 9.5762904 | AE25: Inc Prim Man
W26: =+V25*DENSITY!G10 -> 0 | X26: Inc Sec Auto | AD26: =+AB24*DENSITY!G15 -> 0 | AE26: Inc Sec Man
E27: =+H39*ACCEPT!C10 -> 0 | G27: (image) | I27: (mail | J27: piece)
G28: =+I28 -> 0 | H28: =+J28 -> 0 | I28: =+G21-K29 -> 0 | J28: =+H25-L29 -> 0
K29: =+G21*MISC!E6 -> 0 | L29: =+H25*(MISC!E6) -> 0
C30: Out LCREM | G30: Out REC | S30: Inc MMP Auto | V30: =+T32*(1-ACCEPT!C17) -> 243.97011 | W30: Rejects to Inc ADC Man | AA30: Inc ADC Man
M31: =+J28*MISC!E5 -> 0 | N31: =+M31+M32 -> 0 | O31: Leakage to Out Prim Man
C32: =+D36+C36 -> 0 | D32: =+D36 -> 0 | G32: =+I28+H32 -> 0 | H32: =+J28 -> 0 | M32: =+I28*MISC!E5 -> 0 | S32: =+T32*(1+DENSITY!B13) -> 5567.7046 | T32: =+K8+N17+N43+N48+N75+W17+W24 -> 5533.0163 | AA32: =+AB32 -> 333.64366 | AB32: =+Q7+N64+N72+V30+AD16+AD24 -> 333.64366
V33: =+T32*ACCEPT!C17 -> 5289.0462 | W33: =+V33*DENSITY!$G$13 -> 4817.1408 | X33: Inc Sec Auto | AD33: =+AB32*DENSITY!F16 -> 146.1175 | AE33: Inc Prim Man
G34: (image) | I34: (mail | J34: piece) | W34: =+V33*DENSITY!$F$13 -> 471.9054 | X34: Inc SCF/Prim Auto | AD34: =+AB32*DENSITY!G16 -> 187.52616 | AE34: Inc Sec Man
G35: =+I35 -> 0 | H35: =+J35 -> 0 | I35: =+I28-M32 -> 0 | J35: =+J28-M31 -> 0
D36: =+H39*ACCEPT!C12 -> 0
G37: Out OSS
D38: ID Tag Error | S38: Inc SCF/Prim Auto | V38: =+T40*(1-ACCEPT!C18) -> 287.25203 | W38: Rejects to Inc Prim Man | AA38: Inc Prim Man
G39: =+H39+E40+I35+K29 -> 0 | H39: =+J35+L29 -> 0 | L39: =+H39*ACCEPT!C13 -> 0 | N39: =+L39+L40 -> 0 | O39: Rejects to Out Prim Man
E40: =+H39*ACCEPT!C11 -> 0 | L40: =+(G39-H39)*(1-ACCEPT!C9) -> 0 | S40: =+T40 -> 4661.5696 | T40: =+K9+N18+N44+N49+N76+W18+W25+W34 -> 4661.5696 | AA40: =+AB40 -> 621.01557 | AB40: =+Q8+V38+AD33+AD25+AD17 -> 621.01557
F41: OSS Refeeds | N41: =+J42*DENSITY!C8 -> 0 | O41: Out Prim Auto | V41: =+T40*(ACCEPT!C18) -> 4374.3175 | W41: Inc Sec Auto | AD41: =+AB40 -> 621.01557 | AE41: Inc Sec Man
H42: =+H39*ACCEPT!C9 -> 0 | J42: =+H42+H43 -> 0 | N42: =+J42*DENSITY!D8 -> 0 | O42: Out Sec Auto
H43: =+(G39-H39)*ACCEPT!C9 -> 0 | N43: =+J42*DENSITY!E8 -> 0 | O43: Inc MMP Auto
...

Sheet MACH MAADC BC-BENCH COST 
A1: MARKETING MAIL MACHINABLE MAADC PRESORTED LETTERS
A2: COST SHEET
A3: Total Pieces | C3: =+'MACH MAADC MODEL'!N4 -> 10000
C6: [1] | E6: [2] | G6: [3] | H6: [4] | I6: [6] | J6: [5] | K6: [7] | L6: [8]
H7: Direct | I7: Premium | K7: Total | L7: Weighted
E8: Pieces | G8: Wage | H8: Cents | I8: Pay | J8: Piggyback | K8: Cents | L8: Cents
C9: TPH | E9: Per Hour | G9: Rate | H9: Per Piece | I9: Adjust | J9: Factor | K9: Per Piece | L9: Per Piece
A10: Entry Activities
B11: Package Sorting
A12: Outgoing RBCS
B13: ISS | C13: =+'MACH MAADC BC-BENCH MODEL '!G18 -> 10113.242 | E13: =+PRODUCTIVITY!I7 -> 6833.2327 | G13: =+'WAGE RATE - PIGGYBACK FACTORS'!$D$5 -> 50.107175 | H13: =+G13/E13*100 -> 0.73328652 | I13: =+H13*('WAGE RATE - PIGGYBACK FACTORS'!$D$6-1) -> -0.019000285 | J13: =+'WAGE RATE - PIGGYBACK FACTORS'!D19 -> 1.6888485 | K13: =+H13*J13+I13 -> 1.2194096 | L13: =+(K13*C13/10000) -> 1.2332184
B14: RCR | C14: =+'MACH MAADC BC-BENCH MODEL '!G25 -> 663.7513 | E14: -- | G14: -- | H14: -- | I14: -- | J14: -- | K14: =+MISC!$E$7 -> 0.27889541 | L14: =+K14*C14/10000 -> 0.018511719
B15: REC | C15: =+'MACH MAADC BC-BENCH MODEL '!G32 -> 13.407776 | E15: =+PRODUCTIVITY!I9 -> 846.86663 | G15: =+'WAGE RATE - PIGGYBACK FACTORS'!$D$4 -> 54.14236 | H15: =+G15/E15*100 -> 6.393257 | I15: =+H15*('WAGE RATE - PIGGYBACK FACTORS'!$D$6-1) -> -0.16565654 | J15: =+'WAGE RATE - PIGGYBACK FACTORS'!D20 -> 1.2615773 | K15: =+H15*J15+I15 -> 7.8999315 | L15: =+(K15*C15/10000) -> 0.010592051
B16: OSS | C16: =+'MACH MAADC BC-BENCH MODEL '!G39 -> 671.98311 | E16: =+PRODUCTIVITY!I11 -> 6833.2327 | G16: =+'WAGE RATE - PIGGYBACK FACTORS'!$D$5 -> 50.107175 | H16: =+G16/E16*100 -> 0.73328652 | I16: =+H16*('WAGE RATE - PIGGYBACK FACTORS'!$D$6-1) -> -0.019000285 | J16: =+'WAGE RATE - PIGGYBACK FACTORS'!D21 -> 1.6888485 | K16: =+H16*J16+I16 -> 1.2194096 | L16: =+(K16*C16/10000) -> 0.081942263
B17: LCREM | C17: =+'MACH MAADC BC-BENCH MODEL '!C32 -> 1.3776555 | E17: =+PRODUCTIVITY!I10 -> 1983.2154 | G17: =+'WAGE RATE - PIGGYBACK FACTORS'!$D$5 -> 50.107175 | H17: =+G17/E17*100 -> 2.5265624 | I17: =+H17*('WAGE RATE - PIGGYBACK FACTORS'!$D$6-1) -> -0.065466096 | J17: =+'WAGE RATE - PIGGYBACK FACTORS'!D22 -> 3.4396835 | K17: =+H17*J17+I17 -> 8.6251087 | L17: =+(K17*C17/10000) -> 0.0011882428
A18: Outgoing Primary
B19: Automation | C19: =+'MACH MAADC BC-BENCH MODEL '!S16 -> 0 | E19: =+PRODUCTIVITY!I13 -> 6833.2327 | G19: =+'WAGE RATE - PIGGYBACK FACTORS'!$D$5 -> 50.107175 | H19: =+G19/E19*100 -> 0.73328652 | I19: =+H19*('WAGE RATE - PIGGYBACK FACTORS'!$D$6-1) -> -0.019000285 | J19: =+'WAGE RATE - PIGGYBACK FACTORS'!D23 -> 1.6888485 | K19: =+H19*J19+I19 -> 1.2194096 | L19: =+(K19*C19/10000) -> 0
B20: Manual | C20: =+'MACH MAADC BC-BENCH MODEL '!AA16 -> 336.09032 | E20: =+PRODUCTIVITY!I20 -> 631.32213 | G20: =+'WAGE RATE - PIGGYBACK FACTORS'!$D$5 -> 50.107175 | H20: =+G20/E20*100 -> 7.9368633 | I20: =+H20*('WAGE RATE - PIGGYBACK FACTORS'!$D$6-1) -> -0.20565313 | J20: =+'WAGE RATE - PIGGYBACK FACTORS'!D24 -> 1.2988119 | K20: =+H20*J20+I20 -> 10.10284 | L20: =+(K20*C20/10000) -> 0.33954666
A21: Outgoing Secondary
B22: Automation | C22: =+'MACH MAADC BC-BENCH MODEL '!S24 -> 93.198478 | E22: =+PRODUCTIVITY!I14 -> 5441.4416 | G22: =+'WAGE RATE - PIGGYBACK FACTORS'!$D$5 -> 50.107175 | H22: =+G22/E22*100 -> 0.92084374 | I22: =+H22*('WAGE RATE - PIGGYBACK FACTORS'!$D$6-1) -> -0.023860106 | J22: =+'WAGE RATE - PIGGYBACK FACTORS'!D25 -> 1.6888485 | K22: =+H22*J22+I22 -> 1.5313055 | L22: =+(K22*C22/10000) -> 0.014271534
B23: Manual | C23: =+'MACH MAADC BC-BENCH MODEL '!AA24 -> 60.904944 | E23: =+PRODUCTIVITY!I21 -> 1087.9987 | G23: =+'WAGE RATE - PIGGYBACK FACTORS'!$D$5 -> 50.107175 | H23: =+G23/E23*100 -> 4.6054442 | I23: =+H23*('WAGE RATE - PIGGYBACK FACTORS'!$D$6-1) -> -0.11933228 | J23: =+'WAGE RATE - PIGGYBACK FACTORS'!D26 -> 1.2988119 | K23: =+H23*J23+I23 -> 5.8622736 | L23: =+(K23*C23/10000) -> 0.035704145
A24: Incoming RBCS
B25: ISS | C25: =+'MACH MAADC BC-BENCH MODEL '!G51 -> 0 | E25: =+PRODUCTIVITY!I8 -> 5815.8678 | G25: =+'WAGE RATE - PIGGYBACK FACTORS'!$D$5 -> 50.107175 | H25: =+G25/E25*100 -> 0.86155972 | I25: =+H25*('WAGE RATE - PIGGYBACK FACTORS'!$D$6-1) -> -0.022323989 | J25: =+'WAGE RATE - PIGGYBACK FACTORS'!D27 -> 1.6888485 | K25: =+H25*J25+I25 -> 1.4327199 | L25: =+(K25*C25/10000) -> 0
B26: RCR | C26: =+'MACH MAADC BC-BENCH MODEL '!G58 -> 0 | E26: -- | G26: -- | H26: -- | I26: -- | J26: -- | K26: =+MISC!$E$7 -> 0.27889541 | L26: =+(K26*C26/10000) -> 0
B27: REC | C27: =+'MACH MAADC BC-BENCH MODEL '!G65 -> 0 | E27: =+PRODUCTIVITY!I9 -> 846.86663 | G27: =+'WAGE RATE - PIGGYBACK FACTORS'!$D$4 -> 54.14236 | H27: =+G27/E27*100 -> 6.393257 | I27: =+H27*('WAGE RATE - PIGGYBACK FACTORS'!$D$6-1) -> -0.16565654 | J27: =+'WAGE RATE - PIGGYBACK FACTORS'!D28 -> 1.2615773 | K27: =+H27*J27+I27 -> 7.8999315 | L27: =+(K27*C27/10000) -> 0
B28: OSS | C28: =+'MACH MAADC BC-BENCH MODEL '!G72 -> 0 | E28: =+PRODUCTIVITY!I12 -> 5815.8678 | G28: =+'WAGE RATE - PIGGYBACK FACTORS'!$D$5 -> 50.107175 | H28: =+G28/E28*100 -> 0.86155972 | I28: =+H28*('WAGE RATE - PIGGYBACK FACTORS'!$D$6-1) -> -0.022323989 | J28: =+'WAGE RATE - PIGGYBACK FACTORS'!D29 -> 1.6888485 | K28: =+H28*J28+I28 -> 1.4327199 | L28: =+(K28*C28/10000) -> 0
B29: LCREM | C29: =+'MACH MAADC BC-BENCH MODEL '!C65 -> 0 | E29: =+PRODUCTIVITY!I10 -> 1983.2154 | G29: =+'WAGE RATE - PIGGYBACK FACTORS'!$D$5 -> 50.107175 | H29: =+G29/E29*100 -> 2.5265624 | I29: =+H29*('WAGE RATE - PIGGYBACK FACTORS'!$D$6-1) -> -0.065466096 | J29: =+'WAGE RATE - PIGGYBACK FACTORS'!D30 -> 3.4396835 | K29: =+H29*J29+I29 -> 8.6251087 | L29: =+(K29*C29/10000) -> 0
A30: Incoming MMP
B31: Automation AADC | C31: =+'MACH MAADC BC-BENCH MODEL '!S32 -> 5532.6782 | E31: =+PRODUCTIVITY!I15 -> 5271.1402 | G31: =+'WAGE RATE - PIGGYBACK FACTORS'!$D$5 -> 50.107175 | H31: =+G31/E31*100 -> 0.95059461 | I31: =+H31*('WAGE RATE - PIGGYBACK FACTORS'!$D$6-1) -> -0.024630984 | J31: =+'WAGE RATE - PIGGYBACK FACTORS'!D31 -> 1.6888485 | K31: =+H31*J31+I31 -> 1.5807793 | L31: =+(K31*C31/10000) -> 0.87459433
B32: Manual ADC | C32: =+'MACH MAADC BC-BENCH MODEL '!AA32 -> 351.61907 | E32: =+PRODUCTIVITY!I22 -> 1213.9421 | G32: =+'WAGE RATE - PIGGYBACK FACTORS'!$D$5 -> 50.107175 | H32: =+G32/E32*100 -> 4.1276414 | I32: =+H32*('WAGE RATE - PIGGYBACK FACTORS'!$D$6-1) -> -0.10695187 | J32: =+'WAGE RATE - PIGGYBACK FACTORS'!D32 -> 1.2988119 | K32: =+H32*J32+I32 -> 5.254078 | L32: =+(K32*C32/10000) -> 0.1847434
A33: Incoming SCF/Primary
B34: Automation | C34: =+'MACH MAADC BC-BENCH MODEL '!S40 -> 4632.2437 | E34: =+PRODUCTIVITY!I16 -> 10175.777 | G34: =+'WAGE RATE - PIGGYBACK FACTORS'!$D$5 -> 50.107175 | H34: =+G34/E34*100 -> 0.49241622 | I34: =+H34*('WAGE RATE - PIGGYBACK FACTORS'!$D$6-1) -> -0.012759063 | J34: =+'WAGE RATE - PIGGYBACK FACTORS'!D33 -> 1.6888485 | K34: =+H34*J34+I34 -> 0.81885733 | L34: =+(K34*C34/10000) -> 0.37931467
B35: Manual | C35: =+'MACH MAADC BC-BENCH MODEL '!AA40 -> 668.73577 | E35: =+PRODUCTIVITY!I23 -> 1107.0494 | G35: =+'WAGE RATE - PIGGYBACK FACTORS'!$D$5 -> 50.107175 | H35: =+G35/E35*100 -> 4.5261912 | I35: =+H35*('WAGE RATE - PIGGYBACK FACTORS'!$D$6-1) -> -0.11727875 | J35: =+'WAGE RATE - PIGGYBACK FACTORS'!D34 -> 1.2988119 | K35: =+H35*J35+I35 -> 5.7613924 | L35: =+(K35*C35/10000) -> 0.38528492
A36: Incoming Secondaries
B37: Auto Carrier Route | C37: =+'MACH MAADC BC-BENCH MODEL '!W49 -> 321.19464 | E37: =+PRODUCTIVITY!I17 -> 13094.299 | G37: =+'WAGE RATE - PIGGYBACK FACTORS'!$D$5 -> 50.107175 | H37: =+G37/E37*100 -> 0.38266404 | I37: =+H37*('WAGE RATE - PIGGYBACK FACTORS'!$D$6-1) -> -0.0099152592 | J37: =+'WAGE RATE - PIGGYBACK FACTORS'!D35 -> 1.6888485 | K37: =+H37*J37+I37 -> 0.63634633 | L37: =+(K37*C37/10000) -> 0.020439103
B38: Auto 3-Pass DPS | C38: =+'MACH MAADC BC-BENCH MODEL '!W56 -> 0 | E38: =+PRODUCTIVITY!I19 -> 0 | G38: =+'WAGE RATE - PIGGYBACK FACTORS'!$D$5 -> 50.107175 | H38: 0 | I38: =+H38*('WAGE RATE - PIGGYBACK FACTORS'!$D$6-1) -> 0 | J38: =+'WAGE RATE - PIGGYBACK FACTORS'!D36 -> 0 | K38: =+H38*J38+I38 -> 0 | L38: =+(K38*C38/10000) -> 0
B39: Auto 2-Pass DPS | C39: =+'MACH MAADC BC-BENCH MODEL '!W63 -> 17497.312 | E39: =+PRODUCTIVITY!I18 -> 6910.0702 | G39: =+'WAGE RATE - PIGGYBACK FACTORS'!$D$5 -> 50.107175 | H39: =+G39/E39*100 -> 0.72513264 | I39: =+H39*('WAGE RATE - PIGGYBACK FACTORS'!$D$6-1) -> -0.018789009 | J39: =+'WAGE RATE - PIGGYBACK FACTORS'!D37 -> 1.6888485 | K39: =+H39*J39+I39 -> 1.2058502 | L39: =+(K39*C39/10000) -> 2.1099137
B40: Man Inc Sec Final At DU | C40: =+'MACH MAADC BC-BENCH MODEL '!AA74*(1-MISC!E9) -> 1097.6137 | E40: =+PRODUCTIVITY!I24 -> 810.31043 | G40: =+'WAGE RATE - PIGGYBACK FACTORS'!$D$5 -> 50.107175 | H40: =+G40/E40*100 -> 6.183701 | I40: =+H40*('WAGE RATE - PIGGYBACK FACTORS'!$D$6-1) -> -0.1602267 | J40: =+'WAGE RATE - PIGGYBACK FACTORS'!D39 -> 1.2988119 | K40: =+H40*J40+I40 -> 7.8712379 | L40: =+(K40*C40/10000) -> 0.86395783
B41: Box Section Sort, DPS | C41: =+MISC!E10*('MACH MAADC BC-BENCH MODEL '!AE64+'MACH MAADC BC-BENCH MODEL '!AE57) -> 394.16292 | E41: =+PRODUCTIVITY!I25 -> 1955.1935 | G41: =+'WAGE RATE - PIGGYBACK FACTORS'!$D$5 -> 50.107175 | H41: =+G41/E41*100 -> 2.5627732 | I41: =+H41*('WAGE RATE - PIGGYBACK FACTORS'!$D$6-1) -> -0.066404359 | J41: =+'WAGE RATE - PIGGYBACK FACTORS'!D40 -> 1.2988119 | K41: =+H41*J41+I41 -> 3.262156 | L41: =+(K41*C41/10000) -> 0.12858209
B42: Box Section Sort, Other | C42: =+MISC!E10*('MACH MAADC BC-BENCH MODEL '!AE75+'MACH MAADC BC-BENCH MODEL '!AE50) -> 64.182087 | E42: =+PRODUCTIVITY!I26 -> 977.59674 | G42: =+'WAGE RATE - PIGGYBACK FACTORS'!$D$5 -> 50.107175 | H42: =+G42/E42*100 -> 5.1255464 | I42: =+H42*('WAGE RATE - PIGGYBACK FACTORS'!$D$6-1) -> -0.13280872 | J42: =+'WAGE RATE - PIGGYBACK FACTORS'!D41 -> 1.2988119 | K42: =+H42*J42+I42 -> 6.5243121 | L42: =+(K42*C42/10000) -> 0.041874396
...

Sheet MACH MAADC BC-BENCH MODEL 
B1: MARKETING MAIL MACHINABLE MAADC PRESORTED LETTERS
B2: MAIL FLOW MODEL
B4: PCS IN = | E4: 10000 | K4: PCS OUT = | N4: =AE50+AE57+AE64+AE75 -> 10000
B6: ENTRY POINTS:
B7: Out ISS | E7: =E4 -> 10000 | H7: Inc ISS/RCR | K7: 0 | N7: Inc ADC Man | Q7: 0
B8: Out RCR | E8: 0 | H8: Inc MMP Auto | K8: 0 | N8: Inc SCF/Prim Man | Q8: 0
B9: Out Prim Auto | E9: 0 | H9: Inc SCF/Prim Auto | K9: 0 | N9: Inc Sec Man | Q9: 0
B10: Out Sec Auto | E10: 0 | H10: Inc Sec Auto | K10: 0
B11: Out Prim Man | E11: 0
B12: Out Sec Man | E12: 0
B14: OUTGOING RBCS | S14: Out Prim Auto | V14: =+T16*(1-ACCEPT!C15) -> 0 | W14: Rejects to Out Prim Man | AA14: Out Prim Man
I15: =+H18*ACCEPT!$C$5 -> 9024.5715 | K15: =+I15+I16 -> 9041.0289 | N15: 0 | O15: Out Prim Auto | AD15: =+AB16*DENSITY!D14 -> 58.510394 | AE15: Out Sec Man
G16: Out ISS | I16: =+(C20+E27)*(ACCEPT!$C$5) -> 16.457348 | N16: =+(K15)*DENSITY!D9 -> 86.950241 | O16: Out Sec Auto | S16: =+T16*(1+DENSITY!B9) -> 0 | T16: =+E9+N15+N41 -> 0 | W16: =+V17*DENSITY!D9 -> 0 | X16: Out Sec Auto | AA16: =+AB16 -> 336.09032 | AB16: =+E11+N31+N39+V14 -> 336.09032 | AD16: =+AB16*DENSITY!E14 -> 59.881243 | AE16: Inc ADC Man
N17: =+(K15)*DENSITY!E9 -> 5095.1373 | O17: Inc MMP Auto | V17: =+T16*ACCEPT!C15 -> 0 | W17: =+V17*DENSITY!E9 -> 0 | X17: Inc MMP Auto | AD17: =+AB16*DENSITY!F14 -> 217.69869 | AE17: Inc Prim Man
G18: =+H18*(1+DENSITY!B7)+C20+E27 -> 10113.242 | H18: =+E7 -> 10000 | N18: =+(K15)*DENSITY!F9 -> 3858.9414 | O18: Inc SCF/Prim Auto | W18: =+V17*DENSITY!F9 -> 0 | X18: Inc SCF/Prim Auto | AD18: =+AB16*DENSITY!G14 -> 0 | AE18: Inc Sec Man
N19: =+(K15)*DENSITY!G9 -> 0 | O19: Inc Sec Auto | W19: =+V17*DENSITY!G9 -> 0 | X19: Inc Sec Auto
C20: =+C32 -> 1.3776555
G21: =+(C20+E27)*(1-ACCEPT!C5) -> 1.7788064 | H21: =+H18*ACCEPT!F6 -> 661.97249
S22: Out Sec Auto | V22: =+T24*(1-ACCEPT!C16) -> 2.3945508 | W22: Rejects to Out Sec Man | AA22: Out Sec Man
G23: Out RCR
S24: =+T24*(1+DENSITY!B10) -> 93.198478 | T24: =+E10+N16+N42+W16 -> 92.940669 | W24: =+V25*DENSITY!E10 -> 52.041844 | X24: Inc MMP Auto | AA24: =+AB24 -> 60.904944 | AB24: =+E12+V22+AD15 -> 60.904944 | AD24: =+AB24*DENSITY!E15 -> 49.302525 | AE24: Inc ADC Man
G25: =+G21+H25 -> 663.7513 | H25: =+H21+E8 -> 661.97249 | I25: (to out OSS) | V25: =+T24*ACCEPT!C16 -> 90.546118 | W25: =+V25*DENSITY!F10 -> 38.504274 | X25: Inc SCF/Prim Auto | AD25: =+AB24*DENSITY!F15 -> 11.602419 | AE25: Inc Prim Man
W26: =+V25*DENSITY!G10 -> 0 | X26: Inc Sec Auto | AD26: =+AB24*DENSITY!G15 -> 0 | AE26: Inc Sec Man
E27: =+H39*ACCEPT!C10 -> 16.858498 | G27: (image) | I27: (mail | J27: piece)
G28: =+I28 -> 0.035931889 | H28: =+J28 -> 13.371844 | I28: =+G21-K29 -> 0.035931889 | J28: =+H25-L29 -> 13.371844
K29: =+G21*MISC!E6 -> 1.7428745 | L29: =+H25*(MISC!E6) -> 648.60065
C30: Out LCREM | G30: Out REC | S30: Inc MMP Auto | V30: =+T32*(1-ACCEPT!C17) -> 242.4353 | W30: Rejects to Inc ADC Man | AA30: Inc ADC Man
M31: =+J28*MISC!E5 -> 1.1039155 | N31: =+M31+M32 -> 1.1068819 | O31: Leakage to Out Prim Man
C32: =+D36+C36 -> 1.3776555 | D32: =+D36 -> 1.3776555 | G32: =+I28+H32 -> 13.407776 | H32: =+J28 -> 13.371844 | M32: =+I28*MISC!E5 -> 0.0029663649 | S32: =+T32*(1+DENSITY!B13) -> 5532.6782 | T32: =+K8+N17+N43+N48+N75+W17+W24 -> 5498.2081 | AA32: =+AB32 -> 351.61907 | AB32: =+Q7+N64+N72+V30+AD16+AD24 -> 351.61907
V33: =+T32*ACCEPT!C17 -> 5255.7728 | W33: =+V33*DENSITY!$G$13 -> 4786.8362 | X33: Inc Sec Auto | AD33: =+AB32*DENSITY!F16 -> 153.98974 | AE33: Inc Prim Man
G34: (image) | I34: (mail | J34: piece) | W34: =+V33*DENSITY!$F$13 -> 468.93665 | X34: Inc SCF/Prim Auto | AD34: =+AB32*DENSITY!G16 -> 197.62933 | AE34: Inc Sec Man
G35: =+I35 -> 0.032965524 | H35: =+J35 -> 12.267929 | I35: =+I28-M32 -> 0.032965524 | J35: =+J28-M31 -> 12.267929
D36: =+H39*ACCEPT!C12 -> 1.3776555
G37: Out OSS
D38: ID Tag Error | S38: Inc SCF/Prim Auto | V38: =+T40*(1-ACCEPT!C18) -> 285.44493 | W38: Rejects to Inc Prim Man | AA38: Inc Prim Man
G39: =+H39+E40+I35+K29 -> 671.98311 | H39: =+J35+L29 -> 660.86858 | L39: =+H39*ACCEPT!C13 -> 20.71532 | N39: =+L39+L40+H18*ACCEPT!G6 -> 334.98344 | O39: Rejects to Out Prim Man
E40: =+H39*ACCEPT!C11 -> 9.3386895 | L40: =+(G39-H39)*(1-ACCEPT!C9) -> 0.81214703 | S40: =+T40 -> 4632.2437 | T40: =+K9+N18+N44+N49+N76+W18+W25+W34 -> 4632.2437 | AA40: =+AB40 -> 668.73577 | AB40: =+Q8+V38+AD33+AD25+AD17 -> 668.73577
F41: OSS Refeeds | N41: =+J42*DENSITY!C9 -> 0 | O41: Out Prim Auto | V41: =+T40*(ACCEPT!C18) -> 4346.7987 | W41: Inc Sec Auto | AD41: =+AB40 -> 668.73577 | AE41: Inc Sec Man
H42: =+H39*ACCEPT!C9 -> 612.57841 | J42: =+H42+H43 -> 622.8808 | N42: =+J42*DENSITY!D9 -> 5.9904283 | O42: Out Sec Auto
H43: =+(G39-H39)*ACCEPT!C9 -> 10.302382 | N43: =+J42*DENSITY!E9 -> 351.02898 | O43: Inc MMP Auto
...

Sheet ACCEPT
A1: ACCEPTANCE RATE SUMMARY
A3: Operation | C3: Percent
A5: DIOSS Accept Rate | C5: =[2]Letters!C6 -> 0.90245715 | D5: 2/ | E5: DIOSS Rejects | F5: To OSS | G5: To Man
E6: =1-C5 -> 0.097542847 | F6: =E6-C13 -> 0.066197249 | G6: =C13 -> 0.031345597
A8: OSS Reject Rates
B9: Finalized | C9: =[2]Letters!C9 -> 0.92692925 | D9: 1/
B10: ISS Refeeds | C10: =[2]Letters!C10 -> 0.025509608 | D10: 1/
B11: OSS Refeeds | C11: =[2]Letters!C11 -> 0.014130933 | D11: 1/
B12: LCREM | C12: =[2]Letters!C12 -> 0.0020846134 | D12: 1/
B13: Manual | C13: =[2]Letters!C13 -> 0.031345597 | D13: 1/
A15: Out Prim Auto | C15: =[2]Letters!C15 -> 0.97250901 | D15: 2/
A16: Out Sec Auto | C16: =[2]Letters!C16 -> 0.97423571 | D16: 2/
A17: Inc MMP Auto | C17: =[2]Letters!C17 -> 0.95590649 | D17: 2/
A18: Inc SCF/Prim Auto | C18: =[2]Letters!C18 -> 0.93837869 | D18: 2/
A19: Inc Sec 1 Pass Auto | C19: =[2]Letters!C19 -> 0.94237909 | D19: 2/
A20: Inc Sec 2 Pass Auto - Pass 1 | C20: =[2]Letters!C20 -> 0.98552409 | D20: 2/
A21: Inc Sec 2 Pass Auto - Pass 2 | C21: =[2]Letters!C21 -> 0.99019295 | D21: 2/
A25: Sources:
A26: 1/: USPS-FY08-10 density results.xls 'RBCS RESULTS'
A27: 2/: WebEOR data extract FY25

Sheet MACH MAADC COST
A1: MARKETING MAIL MACHINABLE MAADC PRESORTED LETTERS
A2: COST SHEET
A3: Total Pieces | C3: =+'MACH MAADC MODEL'!N4 -> 10000
C6: [1] | E6: [2] | G6: [3] | H6: [4] | I6: [6] | J6: [5] | K6: [7] | L6: [8]
H7: Direct | I7: Premium | K7: Total | L7: Weighted
E8: Pieces | G8: Wage | H8: Cents | I8: Pay | J8: Piggyback | K8: Cents | L8: Cents
C9: TPH | E9: Per Hour | G9: Rate | H9: Per Piece | I9: Adjust | J9: Factor | K9: Per Piece | L9: Per Piece
A10: Entry Activities
B11: Package Sorting
A12: Outgoing RBCS
B13: ISS | C13: =+'MACH MAADC MODEL'!G18 -> 10113.242 | E13: =+PRODUCTIVITY!I7 -> 6833.2327 | G13: =+'WAGE RATE - PIGGYBACK FACTORS'!$D$5 -> 50.107175 | H13: =+G13/E13*100 -> 0.73328652 | I13: =+H13*('WAGE RATE - PIGGYBACK FACTORS'!$D$6-1) -> -0.019000285 | J13: =+'WAGE RATE - PIGGYBACK FACTORS'!D19 -> 1.6888485 | K13: =+H13*J13+I13 -> 1.2194096 | L13: =+(K13*C13/10000) -> 1.2332184
B14: RCR | C14: =+'MACH MAADC MODEL'!G25 -> 663.7513 | E14: -- | G14: -- | H14: -- | I14: -- | J14: -- | K14: =+MISC!$E$7 -> 0.27889541 | L14: =+K14*C14/10000 -> 0.018511719
B15: REC | C15: =+'MACH MAADC MODEL'!G32 -> 13.407776 | E15: =+PRODUCTIVITY!I9 -> 846.86663 | G15: =+'WAGE RATE - PIGGYBACK FACTORS'!$D$4 -> 54.14236 | H15: =+G15/E15*100 -> 6.393257 | I15: =+H15*('WAGE RATE - PIGGYBACK FACTORS'!$D$6-1) -> -0.16565654 | J15: =+'WAGE RATE - PIGGYBACK FACTORS'!D20 -> 1.2615773 | K15: =+H15*J15+I15 -> 7.8999315 | L15: =+(K15*C15/10000) -> 0.010592051
B16: OSS | C16: =+'MACH MAADC MODEL'!G39 -> 671.98311 | E16: =+PRODUCTIVITY!I11 -> 6833.2327 | G16: =+'WAGE RATE - PIGGYBACK FACTORS'!$D$5 -> 50.107175 | H16: =+G16/E16*100 -> 0.73328652 | I16: =+H16*('WAGE RATE - PIGGYBACK FACTORS'!$D$6-1) -> -0.019000285 | J16: =+'WAGE RATE - PIGGYBACK FACTORS'!D21 -> 1.6888485 | K16: =+H16*J16+I16 -> 1.2194096 | L16: =+(K16*C16/10000) -> 0.081942263
B17: LCREM | C17: =+'MACH MAADC MODEL'!C32 -> 1.3776555 | E17: =+PRODUCTIVITY!I10 -> 1983.2154 | G17: =+'WAGE RATE - PIGGYBACK FACTORS'!$D$5 -> 50.107175 | H17: =+G17/E17*100 -> 2.5265624 | I17: =+H17*('WAGE RATE - PIGGYBACK FACTORS'!$D$6-1) -> -0.065466096 | J17: =+'WAGE RATE - PIGGYBACK FACTORS'!D22 -> 3.4396835 | K17: =+H17*J17+I17 -> 8.6251087 | L17: =+(K17*C17/10000) -> 0.0011882428
A18: Outgoing Primary
B19: Automation | C19: =+'MACH MAADC MODEL'!S16 -> 149.25926 | E19: =+PRODUCTIVITY!I13 -> 6833.2327 | G19: =+'WAGE RATE - PIGGYBACK FACTORS'!$D$5 -> 50.107175 | H19: =+G19/E19*100 -> 0.73328652 | I19: =+H19*('WAGE RATE - PIGGYBACK FACTORS'!$D$6-1) -> -0.019000285 | J19: =+'WAGE RATE - PIGGYBACK FACTORS'!D23 -> 1.6888485 | K19: =+H19*J19+I19 -> 1.2194096 | L19: =+(K19*C19/10000) -> 0.018200816
B20: Manual | C20: =+'MACH MAADC MODEL'!AA16 -> 340.191 | E20: =+PRODUCTIVITY!I20 -> 631.32213 | G20: =+'WAGE RATE - PIGGYBACK FACTORS'!$D$5 -> 50.107175 | H20: =+G20/E20*100 -> 7.9368633 | I20: =+H20*('WAGE RATE - PIGGYBACK FACTORS'!$D$6-1) -> -0.20565313 | J20: =+'WAGE RATE - PIGGYBACK FACTORS'!D24 -> 1.2988119 | K20: =+H20*J20+I20 -> 10.10284 | L20: =+(K20*C20/10000) -> 0.3436895
A21: Outgoing Secondary | K21: =+H21*J21+I21 -> 0 | L21: =+(K21*C21/10000) -> 0
B22: Automation | C22: =+'MACH MAADC MODEL'!S24 -> 1846.479 | E22: =+PRODUCTIVITY!I14 -> 5441.4416 | G22: =+'WAGE RATE - PIGGYBACK FACTORS'!$D$5 -> 50.107175 | H22: =+G22/E22*100 -> 0.92084374 | I22: =+H22*('WAGE RATE - PIGGYBACK FACTORS'!$D$6-1) -> -0.023860106 | J22: =+'WAGE RATE - PIGGYBACK FACTORS'!D25 -> 1.6888485 | K22: =+H22*J22+I22 -> 1.5313055 | L22: =+(K22*C22/10000) -> 0.28275234
B23: Manual | C23: =+'MACH MAADC MODEL'!AA24 -> 106.66592 | E23: =+PRODUCTIVITY!I21 -> 1087.9987 | G23: =+'WAGE RATE - PIGGYBACK FACTORS'!$D$5 -> 50.107175 | H23: =+G23/E23*100 -> 4.6054442 | I23: =+H23*('WAGE RATE - PIGGYBACK FACTORS'!$D$6-1) -> -0.11933228 | J23: =+'WAGE RATE - PIGGYBACK FACTORS'!D26 -> 1.2988119 | K23: =+H23*J23+I23 -> 5.8622736 | L23: =+(K23*C23/10000) -> 0.062530478
A24: Incoming RBCS
B25: ISS | C25: =+'MACH MAADC MODEL'!G51 -> 0 | E25: =+PRODUCTIVITY!I8 -> 5815.8678 | G25: =+'WAGE RATE - PIGGYBACK FACTORS'!$D$5 -> 50.107175 | H25: =+G25/E25*100 -> 0.86155972 | I25: =+H25*('WAGE RATE - PIGGYBACK FACTORS'!$D$6-1) -> -0.022323989 | J25: =+'WAGE RATE - PIGGYBACK FACTORS'!D27 -> 1.6888485 | K25: =+H25*J25+I25 -> 1.4327199 | L25: =+(K25*C25/10000) -> 0
B26: RCR | C26: =+'MACH MAADC MODEL'!G58 -> 0 | E26: -- | G26: -- | H26: -- | I26: -- | J26: -- | K26: =+MISC!$E$7 -> 0.27889541 | L26: =+(K26*C26/10000) -> 0
B27: REC | C27: =+'MACH MAADC MODEL'!G65 -> 0 | E27: =+PRODUCTIVITY!I9 -> 846.86663 | G27: =+'WAGE RATE - PIGGYBACK FACTORS'!$D$4 -> 54.14236 | H27: =+G27/E27*100 -> 6.393257 | I27: =+H27*('WAGE RATE - PIGGYBACK FACTORS'!$D$6-1) -> -0.16565654 | J27: =+'WAGE RATE - PIGGYBACK FACTORS'!D28 -> 1.2615773 | K27: =+H27*J27+I27 -> 7.8999315 | L27: =+(K27*C27/10000) -> 0
B28: OSS | C28: =+'MACH MAADC MODEL'!G72 -> 0 | E28: =+PRODUCTIVITY!I12 -> 5815.8678 | G28: =+'WAGE RATE - PIGGYBACK FACTORS'!$D$5 -> 50.107175 | H28: =+G28/E28*100 -> 0.86155972 | I28: =+H28*('WAGE RATE - PIGGYBACK FACTORS'!$D$6-1) -> -0.022323989 | J28: =+'WAGE RATE - PIGGYBACK FACTORS'!D29 -> 1.6888485 | K28: =+H28*J28+I28 -> 1.4327199 | L28: =+(K28*C28/10000) -> 0
B29: LCREM | C29: =+'MACH MAADC MODEL'!C65 -> 0 | E29: =+PRODUCTIVITY!I10 -> 1983.2154 | G29: =+'WAGE RATE - PIGGYBACK FACTORS'!$D$5 -> 50.107175 | H29: =+G29/E29*100 -> 2.5265624 | I29: =+H29*('WAGE RATE - PIGGYBACK FACTORS'!$D$6-1) -> -0.065466096 | J29: =+'WAGE RATE - PIGGYBACK FACTORS'!D30 -> 3.4396835 | K29: =+H29*J29+I29 -> 8.6251087 | L29: =+(K29*C29/10000) -> 0
A30: Incoming MMP
B31: Automation AADC | C31: =+'MACH MAADC MODEL'!S32 -> 3975.9793 | E31: =+PRODUCTIVITY!I15 -> 5271.1402 | G31: =+'WAGE RATE - PIGGYBACK FACTORS'!$D$5 -> 50.107175 | H31: =+G31/E31*100 -> 0.95059461 | I31: =+H31*('WAGE RATE - PIGGYBACK FACTORS'!$D$6-1) -> -0.024630984 | J31: =+'WAGE RATE - PIGGYBACK FACTORS'!D31 -> 1.6888485 | K31: =+H31*J31+I31 -> 1.5807793 | L31: =+(K31*C31/10000) -> 0.62851458
B32: Manual ADC | C32: =+'MACH MAADC MODEL'!AA32 -> 321.1805 | E32: =+PRODUCTIVITY!I22 -> 1213.9421 | G32: =+'WAGE RATE - PIGGYBACK FACTORS'!$D$5 -> 50.107175 | H32: =+G32/E32*100 -> 4.1276414 | I32: =+H32*('WAGE RATE - PIGGYBACK FACTORS'!$D$6-1) -> -0.10695187 | J32: =+'WAGE RATE - PIGGYBACK FACTORS'!D32 -> 1.2988119 | K32: =+H32*J32+I32 -> 5.254078 | L32: =+(K32*C32/10000) -> 0.16875074
A33: Incoming SCF/Primary
B34: Automation | C34: =+'MACH MAADC MODEL'!S40 -> 5998.1541 | E34: =+PRODUCTIVITY!I16 -> 10175.777 | G34: =+'WAGE RATE - PIGGYBACK FACTORS'!$D$5 -> 50.107175 | H34: =+G34/E34*100 -> 0.49241622 | I34: =+H34*('WAGE RATE - PIGGYBACK FACTORS'!$D$6-1) -> -0.012759063 | J34: =+'WAGE RATE - PIGGYBACK FACTORS'!D33 -> 1.6888485 | K34: =+H34*J34+I34 -> 0.81885733 | L34: =+(K34*C34/10000) -> 0.49116324
B35: Manual | C35: =+'MACH MAADC MODEL'!AA40 -> 750.9482 | E35: =+PRODUCTIVITY!I23 -> 1107.0494 | G35: =+'WAGE RATE - PIGGYBACK FACTORS'!$D$5 -> 50.107175 | H35: =+G35/E35*100 -> 4.5261912 | I35: =+H35*('WAGE RATE - PIGGYBACK FACTORS'!$D$6-1) -> -0.11727875 | J35: =+'WAGE RATE - PIGGYBACK FACTORS'!D34 -> 1.2988119 | K35: =+H35*J35+I35 -> 5.7613924 | L35: =+(K35*C35/10000) -> 0.43265073
A36: Incoming Secondaries
B37: Auto Carrier Route | C37: =+'MACH MAADC MODEL'!W49 -> 318.90517 | E37: =+PRODUCTIVITY!I17 -> 13094.299 | G37: =+'WAGE RATE - PIGGYBACK FACTORS'!$D$5 -> 50.107175 | H37: =+G37/E37*100 -> 0.38266404 | I37: =+H37*('WAGE RATE - PIGGYBACK FACTORS'!$D$6-1) -> -0.0099152592 | J37: =+'WAGE RATE - PIGGYBACK FACTORS'!D35 -> 1.6888485 | K37: =+H37*J37+I37 -> 0.63634633 | L37: =+(K37*C37/10000) -> 0.020293414
B38: Auto 3-Pass DPS | C38: =+'MACH MAADC MODEL'!W56 -> 0 | E38: =+PRODUCTIVITY!I19 -> 0 | G38: =+'WAGE RATE - PIGGYBACK FACTORS'!$D$5 -> 50.107175 | H38: 0 | I38: =+H38*('WAGE RATE - PIGGYBACK FACTORS'!$D$6-1) -> 0 | J38: =+'WAGE RATE - PIGGYBACK FACTORS'!D36 -> 0 | K38: =+H38*J38+I38 -> 0 | L38: =+(K38*C38/10000) -> 0
B39: Auto 2-Pass DPS | C39: =+'MACH MAADC MODEL'!W63 -> 17372.592 | E39: =+PRODUCTIVITY!I18 -> 6910.0702 | G39: =+'WAGE RATE - PIGGYBACK FACTORS'!$D$5 -> 50.107175 | H39: =+G39/E39*100 -> 0.72513264 | I39: =+H39*('WAGE RATE - PIGGYBACK FACTORS'!$D$6-1) -> -0.018789009 | J39: =+'WAGE RATE - PIGGYBACK FACTORS'!D37 -> 1.6888485 | K39: =+H39*J39+I39 -> 1.2058502 | L39: =+(K39*C39/10000) -> 2.0948743
B40: Man Inc Sec Final At DU | C40: =+'MACH MAADC MODEL'!AA74*(1-MISC!E9) -> 1161.0696 | E40: =+PRODUCTIVITY!I24 -> 810.31043 | G40: =+'WAGE RATE - PIGGYBACK FACTORS'!$D$5 -> 50.107175 | H40: =+G40/E40*100 -> 6.183701 | I40: =+H40*('WAGE RATE - PIGGYBACK FACTORS'!$D$6-1) -> -0.1602267 | J40: =+'WAGE RATE - PIGGYBACK FACTORS'!D39 -> 1.2988119 | K40: =+H40*J40+I40 -> 7.8712379 | L40: =+(K40*C40/10000) -> 0.91390551
B41: Box Section Sort, DPS | C41: =+MISC!E10*('MACH MAADC MODEL'!AE64+'MACH MAADC MODEL'!AE57) -> 391.35334 | E41: =+PRODUCTIVITY!I25 -> 1955.1935 | G41: =+'WAGE RATE - PIGGYBACK FACTORS'!$D$5 -> 50.107175 | H41: =+G41/E41*100 -> 2.5627732 | I41: =+H41*('WAGE RATE - PIGGYBACK FACTORS'!$D$6-1) -> -0.066404359 | J41: =+'WAGE RATE - PIGGYBACK FACTORS'!D40 -> 1.2988119 | K41: =+H41*J41+I41 -> 3.262156 | L41: =+(K41*C41/10000) -> 0.12766556
B42: Box Section Sort, Other | C42: =+MISC!E10*('MACH MAADC MODEL'!AE75+'MACH MAADC MODEL'!AE50) -> 66.991668 | E42: =+PRODUCTIVITY!I26 -> 977.59674 | G42: =+'WAGE RATE - PIGGYBACK FACTORS'!$D$5 -> 50.107175 | H42: =+G42/E42*100 -> 5.1255464 | I42: =+H42*('WAGE RATE - PIGGYBACK FACTORS'!$D$6-1) -> -0.13280872 | J42: =+'WAGE RATE - PIGGYBACK FACTORS'!D41 -> 1.2988119 | K42: =+H42*J42+I42 -> 6.5243121 | L42: =+(K42*C42/10000) -> 0.043707455
...

Sheet MACH MAADC MODEL
B1: MARKETING MAIL MACHINABLE MAADC PRESORTED LETTERS
B2: MAIL FLOW MODEL
B4: PCS IN = | E4: 10000 | K4: PCS OUT = | N4: =AE50+AE57+AE64+AE75 -> 10000
B6: ENTRY POINTS:
B7: Out ISS | E7: =E4 -> 10000 | H7: Inc ISS/RCR | K7: 0 | N7: Inc ADC Man | Q7: 0
B8: Out RCR | E8: 0 | H8: Inc MMP Auto | K8: 0 | N8: Inc SCF/Prim Man | Q8: 0
B9: Out Prim Auto | E9: 0 | H9: Inc SCF/Prim Auto | K9: 0 | N9: Inc Sec Man | Q9: 0
B10: Out Sec Auto | E10: 0 | H10: Inc Sec Auto | K10: 0
B11: Out Prim Man | E11: 0
B12: Out Sec Man | E12: 0
B14: OUTGOING RBCS | S14: Out Prim Auto | V14: =+T16*(1-ACCEPT!C15) -> 4.1006742 | W14: Rejects to Out Prim Man | AA14: Out Prim Man
I15: =+H18*ACCEPT!$C$5 -> 9024.5715 | K15: =+I15+I16 -> 9041.0289 | N15: =+(K15)*DENSITY!C7 -> 134.54379 | O15: Out Prim Auto | AD15: =+AB16*DENSITY!D14 -> 59.224285 | AE15: Out Sec Man
G16: Out ISS | I16: =+(C20+E27)*(ACCEPT!$C$5) -> 16.457348 | N16: =+(K15)*DENSITY!D7 -> 1787.7062 | O16: Out Sec Auto | S16: =+T16*(1+DENSITY!B9) -> 149.25926 | T16: =+E9+N15+N41 -> 149.16431 | W16: =+V17*DENSITY!D9 -> 1.3951198 | X16: Out Sec Auto | AA16: =+AB16 -> 340.191 | AB16: =+E11+N31+N39+V14 -> 340.191 | AD16: =+AB16*DENSITY!E14 -> 60.61186 | AE16: Inc ADC Man
N17: =+(K15)*DENSITY!E7 -> 2616.8623 | O17: Inc MMP Auto | V17: =+T16*ACCEPT!C15 -> 145.06364 | W17: =+V17*DENSITY!E9 -> 81.751663 | X17: Inc MMP Auto | AD17: =+AB16*DENSITY!F14 -> 220.35485 | AE17: Inc Prim Man
G18: =+H18*(1+DENSITY!B7)+C20+E27 -> 10113.242 | H18: =+E7 -> 10000 | N18: =+(K15)*DENSITY!F7 -> 4501.9167 | O18: Inc SCF/Prim Auto | W18: =+V17*DENSITY!F9 -> 61.916855 | X18: Inc SCF/Prim Auto | AD18: =+AB16*DENSITY!G14 -> 0 | AE18: Inc Sec Man
N19: =+(K15)*DENSITY!G7 -> 0 | O19: Inc Sec Auto | W19: =+V17*DENSITY!G9 -> 0 | X19: Inc Sec Auto
C20: =+C32 -> 1.3776555
G21: =+(C20+E27)*(1-ACCEPT!C5) -> 1.7788064 | H21: =+H18*ACCEPT!F6 -> 661.97249
S22: Out Sec Auto | V22: =+T24*(1-ACCEPT!C16) -> 47.441631 | W22: Rejects to Out Sec Man | AA22: Out Sec Man
G23: Out RCR
S24: =+T24*(1+DENSITY!B10) -> 1846.479 | T24: =+E10+N16+N42+W16 -> 1841.3712 | W24: =+V25*DENSITY!E10 -> 1031.0702 | X24: Inc MMP Auto | AA24: =+AB24 -> 106.66592 | AB24: =+E12+V22+AD15 -> 106.66592 | AD24: =+AB24*DENSITY!E15 -> 86.346011 | AE24: Inc ADC Man
G25: =+G21+H25 -> 663.7513 | H25: =+H21+E8 -> 661.97249 | I25: (to out OSS) | V25: =+T24*ACCEPT!C16 -> 1793.9296 | W25: =+V25*DENSITY!F10 -> 762.85938 | X25: Inc SCF/Prim Auto | AD25: =+AB24*DENSITY!F15 -> 20.319905 | AE25: Inc Prim Man
W26: =+V25*DENSITY!G10 -> 0 | X26: Inc Sec Auto | AD26: =+AB24*DENSITY!G15 -> 0 | AE26: Inc Sec Man
E27: =+H39*ACCEPT!C10 -> 16.858498 | G27: (image) | I27: (mail | J27: piece)
G28: =+I28 -> 0.035931889 | H28: =+J28 -> 13.371844 | I28: =+G21-K29 -> 0.035931889 | J28: =+H25-L29 -> 13.371844
K29: =+G21*MISC!E6 -> 1.7428745 | L29: =+H25*(MISC!E6) -> 648.60065
C30: Out LCREM | G30: Out REC | S30: Inc MMP Auto | V30: =+T32*(1-ACCEPT!C17) -> 174.22263 | W30: Rejects to Inc ADC Man | AA30: Inc ADC Man
M31: =+J28*MISC!E5 -> 1.1039155 | N31: =+M31+M32 -> 1.1068819 | O31: Leakage to Out Prim Man
C32: =+D36+C36 -> 1.3776555 | D32: =+D36 -> 1.3776555 | G32: =+I28+H32 -> 13.407776 | H32: =+J28 -> 13.371844 | M32: =+I28*MISC!E5 -> 0.0029663649 | S32: =+T32*(1+DENSITY!B13) -> 3975.9793 | T32: =+K8+N17+N43+N48+N75+W17+W24 -> 3951.2079 | AA32: =+AB32 -> 321.1805 | AB32: =+Q7+N64+N72+V30+AD16+AD24 -> 321.1805
V33: =+T32*ACCEPT!C17 -> 3776.9852 | W33: =+V33*DENSITY!$G$13 -> 3439.9907 | X33: Inc Sec Auto | AD33: =+AB32*DENSITY!F16 -> 140.65933 | AE33: Inc Prim Man
G34: (image) | I34: (mail | J34: piece) | W34: =+V33*DENSITY!$F$13 -> 336.99455 | X34: Inc SCF/Prim Auto | AD34: =+AB32*DENSITY!G16 -> 180.52117 | AE34: Inc Sec Man
G35: =+I35 -> 0.032965524 | H35: =+J35 -> 12.267929 | I35: =+I28-M32 -> 0.032965524 | J35: =+J28-M31 -> 12.267929
D36: =+H39*ACCEPT!C12 -> 1.3776555
G37: Out OSS
D38: ID Tag Error | S38: Inc SCF/Prim Auto | V38: =+T40*(1-ACCEPT!C18) -> 369.61412 | W38: Rejects to Inc Prim Man | AA38: Inc Prim Man
G39: =+H39+E40+I35+K29 -> 671.98311 | H39: =+J35+L29 -> 660.86858 | L39: =+H39*ACCEPT!C13 -> 20.71532 | N39: =+L39+L40+H18*ACCEPT!G6 -> 334.98344 | O39: Rejects to Out Prim Man
E40: =+H39*ACCEPT!C11 -> 9.3386895 | L40: =+(G39-H39)*(1-ACCEPT!C9) -> 0.81214703 | S40: =+T40 -> 5998.1541 | T40: =+K9+N18+N44+N49+N76+W18+W25+W34 -> 5998.1541 | AA40: =+AB40 -> 750.9482 | AB40: =+Q8+V38+AD33+AD25+AD17 -> 750.9482
F41: OSS Refeeds | N41: =+J42*DENSITY!C8 -> 14.620519 | O41: Out Prim Auto | V41: =+T40*(ACCEPT!C18) -> 5628.5399 | W41: Inc Sec Auto | AD41: =+AB40 -> 750.9482 | AE41: Inc Sec Man
H42: =+H39*ACCEPT!C9 -> 612.57841 | J42: =+H42+H43 -> 622.8808 | N42: =+J42*DENSITY!D8 -> 52.269928 | O42: Out Sec Auto
H43: =+(G39-H39)*ACCEPT!C9 -> 10.302382 | N43: =+J42*DENSITY!E8 -> 221.52373 | O43: Inc MMP Auto
...

Sheet AUTO AADC COST
A1: MARKETING MAIL AUTOMATION AADC PRESORTED LETTERS
A2: COST SHEET
A3: Total Pieces | C3: =+'AUTO AADC MODEL'!N4 -> 10000
C6: [1] | E6: [2] | G6: [3] | H6: [4] | I6: [6] | J6: [5] | K6: [7] | L6: [8]
H7: Direct | I7: Premium | K7: Total | L7: Weighted
E8: Pieces | G8: Wage | H8: Cents | I8: Pay | J8: Piggyback | K8: Cents | L8: Cents
C9: TPH | E9: Per Hour | G9: Rate | H9: Per Piece | I9: Adjust | J9: Factor | K9: Per Piece | L9: Per Piece
A10: Entry Activities
B11: Package Sorting
A12: Outgoing RBCS
B13: ISS | C13: =+'AUTO AADC MODEL'!G18 -> 0 | E13: =+PRODUCTIVITY!I7 -> 6833.2327 | G13: =+'WAGE RATE - PIGGYBACK FACTORS'!$D$5 -> 50.107175 | H13: =+G13/E13*100 -> 0.73328652 | I13: =+H13*('WAGE RATE - PIGGYBACK FACTORS'!$D$6-1) -> -0.019000285 | J13: =+'WAGE RATE - PIGGYBACK FACTORS'!D19 -> 1.6888485 | K13: =+H13*J13+I13 -> 1.2194096 | L13: =+(K13*C13/10000) -> 0
B14: RCR | C14: =+'AUTO AADC MODEL'!G25 -> 0 | E14: -- | G14: -- | H14: -- | I14: -- | J14: -- | K14: =+MISC!$E$7 -> 0.27889541 | L14: =+K14*C14/10000 -> 0
B15: REC | C15: =+'AUTO AADC MODEL'!G32 -> 0 | E15: =+PRODUCTIVITY!I9 -> 846.86663 | G15: =+'WAGE RATE - PIGGYBACK FACTORS'!$D$4 -> 54.14236 | H15: =+G15/E15*100 -> 6.393257 | I15: =+H15*('WAGE RATE - PIGGYBACK FACTORS'!$D$6-1) -> -0.16565654 | J15: =+'WAGE RATE - PIGGYBACK FACTORS'!D20 -> 1.2615773 | K15: =+H15*J15+I15 -> 7.8999315 | L15: =+(K15*C15/10000) -> 0
B16: OSS | C16: =+'AUTO AADC MODEL'!G39 -> 0 | E16: =+PRODUCTIVITY!I11 -> 6833.2327 | G16: =+'WAGE RATE - PIGGYBACK FACTORS'!$D$5 -> 50.107175 | H16: =+G16/E16*100 -> 0.73328652 | I16: =+H16*('WAGE RATE - PIGGYBACK FACTORS'!$D$6-1) -> -0.019000285 | J16: =+'WAGE RATE - PIGGYBACK FACTORS'!D21 -> 1.6888485 | K16: =+H16*J16+I16 -> 1.2194096 | L16: =+(K16*C16/10000) -> 0
B17: LCREM | C17: =+'AUTO AADC MODEL'!C32 -> 0 | E17: =+PRODUCTIVITY!I10 -> 1983.2154 | G17: =+'WAGE RATE - PIGGYBACK FACTORS'!$D$5 -> 50.107175 | H17: =+G17/E17*100 -> 2.5265624 | I17: =+H17*('WAGE RATE - PIGGYBACK FACTORS'!$D$6-1) -> -0.065466096 | J17: =+'WAGE RATE - PIGGYBACK FACTORS'!D22 -> 3.4396835 | K17: =+H17*J17+I17 -> 8.6251087 | L17: =+(K17*C17/10000) -> 0
A18: Outgoing Primary
B19: Automation | C19: =+'AUTO AADC MODEL'!S16 -> 0 | E19: =+PRODUCTIVITY!I13 -> 6833.2327 | G19: =+'WAGE RATE - PIGGYBACK FACTORS'!$D$5 -> 50.107175 | H19: =+G19/E19*100 -> 0.73328652 | I19: =+H19*('WAGE RATE - PIGGYBACK FACTORS'!$D$6-1) -> -0.019000285 | J19: =+'WAGE RATE - PIGGYBACK FACTORS'!D23 -> 1.6888485 | K19: =+H19*J19+I19 -> 1.2194096 | L19: =+(K19*C19/10000) -> 0
B20: Manual | C20: =+'AUTO AADC MODEL'!AA16 -> 0 | E20: =+PRODUCTIVITY!I20 -> 631.32213 | G20: =+'WAGE RATE - PIGGYBACK FACTORS'!$D$5 -> 50.107175 | H20: =+G20/E20*100 -> 7.9368633 | I20: =+H20*('WAGE RATE - PIGGYBACK FACTORS'!$D$6-1) -> -0.20565313 | J20: =+'WAGE RATE - PIGGYBACK FACTORS'!D24 -> 1.2988119 | K20: =+H20*J20+I20 -> 10.10284 | L20: =+(K20*C20/10000) -> 0
A21: Outgoing Secondary | K21: =+H21*J21+I21 -> 0 | L21: =+(K21*C21/10000) -> 0
B22: Automation | C22: =+'AUTO AADC MODEL'!S24 -> 0 | E22: =+PRODUCTIVITY!I14 -> 5441.4416 | G22: =+'WAGE RATE - PIGGYBACK FACTORS'!$D$5 -> 50.107175 | H22: =+G22/E22*100 -> 0.92084374 | I22: =+H22*('WAGE RATE - PIGGYBACK FACTORS'!$D$6-1) -> -0.023860106 | J22: =+'WAGE RATE - PIGGYBACK FACTORS'!D25 -> 1.6888485 | K22: =+H22*J22+I22 -> 1.5313055 | L22: =+(K22*C22/10000) -> 0
B23: Manual | C23: =+'AUTO AADC MODEL'!AA24 -> 0 | E23: =+PRODUCTIVITY!I21 -> 1087.9987 | G23: =+'WAGE RATE - PIGGYBACK FACTORS'!$D$5 -> 50.107175 | H23: =+G23/E23*100 -> 4.6054442 | I23: =+H23*('WAGE RATE - PIGGYBACK FACTORS'!$D$6-1) -> -0.11933228 | J23: =+'WAGE RATE - PIGGYBACK FACTORS'!D26 -> 1.2988119 | K23: =+H23*J23+I23 -> 5.8622736 | L23: =+(K23*C23/10000) -> 0
A24: Incoming RBCS
B25: ISS | C25: =+'AUTO AADC MODEL'!G51 -> 0 | E25: =+PRODUCTIVITY!I8 -> 5815.8678 | G25: =+'WAGE RATE - PIGGYBACK FACTORS'!$D$5 -> 50.107175 | H25: =+G25/E25*100 -> 0.86155972 | I25: =+H25*('WAGE RATE - PIGGYBACK FACTORS'!$D$6-1) -> -0.022323989 | J25: =+'WAGE RATE - PIGGYBACK FACTORS'!D27 -> 1.6888485 | K25: =+H25*J25+I25 -> 1.4327199 | L25: =+(K25*C25/10000) -> 0
B26: RCR | C26: =+'AUTO AADC MODEL'!G58 -> 0 | E26: -- | G26: -- | H26: -- | I26: -- | J26: -- | K26: =+MISC!$E$7 -> 0.27889541 | L26: =+(K26*C26/10000) -> 0
