Workbook

Sheet MP Summary
A1: USPS MARKETING MAIL PARCEL
A2: MAIL PROCESSING UNIT COST SUMMARY
C4: [1] | D4: [2] | E4: [3]
A5: Parcels | B5: Entry | D5: Volume | E5: Adjusted
A6: Price Category | B6: Level | C6: Volume | D6: Percent | E6: Unit Cost | H6: FY 2025 | J6: FY 2014 | K6: FY 2015 | L6: FY 2016 | M6: FY 2017 | N6: FY 2018 | O6: FY 2019 | P6: FY 2020 | Q6: FY 2021 | R6: FY 2022 | S6: FY 2023 | T6: FY 2024 | U6: FY2025
A8: Machinable
A9: Machinable MNDC | B9: None | C9: ='Vol Data'!$I$20 -> 670396 | D9: =C9/$C$42 -> 0.057269253 | E9: ='MP Cost Adjustments'!$H$15 -> 1.3228001 | G9: None | H9: =C9+C10+C19+C20+C31+C32 -> 5795330 | J9: ='[1]MP Summary'!$I$9 -> 0.25566517 | K9: ='[2]MP Summary'!$I$9 -> 0.25305123 | L9: ='[3]MP Summary'!$I$9 -> 0.30656361 | M9: ='[4]MP Summary'!$I$9 -> 0.28799236 | N9: ='[5]MP Summary'!$I$9 -> 0.35479901 | O9: ='[6]MP Summary'!$I$9 -> 0.40556063 | P9: ='[7]MP Summary'!$I$9 -> 0.40129629 | Q9: ='[8]MP Summary'!$P$9 -> 0.39086773 | R9: ='[9]MP Summary'!$Q$9 -> 0.37313655 | S9: ='[10]MP Summary'!$R$9 -> 0.38815074 | T9: ='[11]MP Summary'!$T$9 -> 0.43662908 | U9: =H9/$H$13 -> 0.5208754
A10: Machinable NDC | B10: None | C10: ='Vol Data'!$I$21 -> 400984 | D10: =C10/$C$42 -> 0.034254462 | E10: ='MP Cost Adjustments'!$H$16 -> 0.96968742 | G10: DNDC | H10: =C11+C12+C21+C22+C25+C33+C34+C37 -> 2901013 | J10: ='[1]MP Summary'!$I$10 -> 0.26055708 | K10: ='[2]MP Summary'!$I$10 -> 0.23088463 | L10: ='[3]MP Summary'!$I$10 -> 0.19211897 | M10: ='[4]MP Summary'!$I$10 -> 0.22782286 | N10: ='[5]MP Summary'!$I$10 -> 0.23086444 | O10: ='[6]MP Summary'!$I$10 -> 0.20361308 | P10: ='[7]MP Summary'!$I$10 -> 0.18787059 | Q10: ='[8]MP Summary'!$P$10 -> 0.1743996 | R10: ='[9]MP Summary'!$Q$10 -> 0.19317385 | S10: ='[10]MP Summary'!$R$10 -> 0.24338289 | T10: ='[11]MP Summary'!$T$10 -> 0.27132454 | U10: =H10/$H$13 -> 0.26073861
A11: Machinable NDC | B11: DNDC | C11: ='Vol Data'!$I$22 -> 1729284 | D11: =C11/$C$42 -> 0.14772583 | E11: ='MP Cost Adjustments'!$H$17 -> 0.95314039 | G11: DSCF | H11: =C13+C26+C27+C38+C39 -> 2424346 | J11: ='[1]MP Summary'!$I$11 -> 0.29034166 | K11: ='[2]MP Summary'!$I$11 -> 0.30771953 | L11: ='[3]MP Summary'!$I$11 -> 0.37537139 | M11: ='[4]MP Summary'!$I$11 -> 0.32715847 | N11: ='[5]MP Summary'!$I$11 -> 0.30624084 | O11: ='[6]MP Summary'!$I$11 -> 0.25308584 | P11: ='[7]MP Summary'!$I$11 -> 0.26129558 | Q11: ='[8]MP Summary'!$P$11 -> 0.28927368 | R11: ='[9]MP Summary'!$Q$11 -> 0.25193691 | S11: ='[10]MP Summary'!$R$11 -> 0.18580454 | T11: ='[11]MP Summary'!$T$11 -> 0.16281449 | U11: =H11/$H$13 -> 0.21789651
A12: Machinable 5-Digit | B12: DNDC | C12: ='Vol Data'!$I$23 -> 6159 | D12: =C12/$C$42 -> 0.00052613878 | E12: ='MP Cost Adjustments'!$H$18 -> 0.4326447 | G12: DDU | H12: =C14+C28+C40 -> 5446 | J12: ='[1]MP Summary'!$I$12 -> 0.19343609 | K12: ='[2]MP Summary'!$I$12 -> 0.20834461 | L12: ='[3]MP Summary'!$I$12 -> 0.12594602 | M12: ='[4]MP Summary'!$I$12 -> 0.15702631 | N12: ='[5]MP Summary'!$I$12 -> 0.10809571 | O12: ='[6]MP Summary'!$I$12 -> 0.13774044 | P12: ='[7]MP Summary'!$I$12 -> 0.14953754 | Q12: ='[8]MP Summary'!$P$12 -> 0.14545899 | R12: ='[9]MP Summary'!$Q$12 -> 0.18175269 | S12: ='[10]MP Summary'!$R$12 -> 0.18266183 | T12: ='[11]MP Summary'!$T$12 -> 0.1292319 | U12: =H12/$H$13 -> 0.00048947815
A13: Machinable 5-Digit | B13: DSCF | C13: ='Vol Data'!$I$24 -> 32567 | D13: =C13/$C$42 -> 0.0027820688 | E13: ='MP Cost Adjustments'!$H$19 -> 0.41239554 | H13: =SUM(H9:H12) -> 11126135 | J13: =SUM(J9:J12) -> 1 | K13: =SUM(K9:K12) -> 1 | L13: =SUM(L9:L12) -> 1 | M13: =SUM(M9:M12) -> 1 | N13: =SUM(N9:N12) -> 1 | O13: =SUM(O9:O12) -> 1 | P13: =SUM(P9:P12) -> 1 | Q13: =SUM(Q9:Q12) -> 1 | ... T13: =SUM(T9:T12) -> 1 | U13: 1
A14: Machinable 5-Digit | B14: DDU | C14: ='Vol Data'!$I$25 -> 5446 | D14: =C14/$C$42 -> 0.00046523003 | E14: ='MP Cost Adjustments'!$H$20 -> 0.35921618
A15: Machinable 5-Digit Aggregate | E15: =SUMPRODUCT(C12:C14,E12:E14)/SUM(C12:C14) -> 0.4086624
G17: MNDC Presort | H17: =C9+C19+C31 -> 4144045 | J17: ='[1]MP Summary'!$I$15 -> 0.21284506 | K17: ='[2]MP Summary'!$I$15 -> 0.21299023 | L17: ='[3]MP Summary'!$I$15 -> 0.24918609 | M17: ='[4]MP Summary'!$I$15 -> 0.23236796 | N17: ='[5]MP Summary'!$I$15 -> 0.2540127 | O17: ='[6]MP Summary'!$I$15 -> 0.2649827 | P17: ='[7]MP Summary'!$I$15 -> 0.27654605 | Q17: ='[8]MP Summary'!$P$15 -> 0.29495501 | R17: ='[9]MP Summary'!$P$15 -> 0.29495501 | S17: ='[10]MP Summary'!$R$15 -> 0.26865797 | T17: ='[11]MP Summary'!$T$15 -> 0.29457256 | U17: =H17/$H$21 -> 0.37246043
A18: Nonstandard | G18: NDC Presort | H18: =C10+C11+C20+C21+C32+C33 -> 3986149 | J18: ='[1]MP Summary'!$I$16 -> 0.1925705 | K18: ='[2]MP Summary'!$I$16 -> 0.15191309 | L18: ='[3]MP Summary'!$I$16 -> 0.1708215 | M18: ='[4]MP Summary'!$I$16 -> 0.18081533 | N18: ='[5]MP Summary'!$I$16 -> 0.24325175 | O18: ='[6]MP Summary'!$I$16 -> 0.28661586 | P18: ='[7]MP Summary'!$I$16 -> 0.27354413 | Q18: ='[8]MP Summary'!$P$16 -> 0.23194789 | R18: ='[9]MP Summary'!$P$16 -> 0.23194789 | S18: ='[10]MP Summary'!$R$16 -> 0.32586789 | T18: ='[11]MP Summary'!$T$16 -> 0.37233789 | U18: =H18/$H$21 -> 0.35826898
A19: Nonstandard MNDC | B19: None | C19: ='Vol Data'!$I$9 -> 1347699 | D19: =C19/$C$42 -> 0.11512854 | E19: =('MP Cost Adjustments'!$D$23*'MP Cost Adjustments'!$H$23+'MP Cost Adjustments'!$D$33*'MP Cost Adjustments'!$H$33)/('MP Cost Adjustments'!$D$23+'MP Cost Adjustments'!$D$33) -> 1.4786327 | G19: SCF Presort | H19: =C22+C26+C34+C38 -> 2512374 | J19: ='[1]MP Summary'!$I$17 -> 0.17148004 | K19: ='[2]MP Summary'!$I$17 -> 0.21245376 | L19: ='[3]MP Summary'!$I$17 -> 0.26815547 | M19: ='[4]MP Summary'!$I$17 -> 0.19538321 | N19: ='[5]MP Summary'!$I$17 -> 0.16803137 | O19: ='[6]MP Summary'!$I$17 -> 0.10662493 | P19: ='[7]MP Summary'!$I$17 -> 0.10549834 | Q19: ='[8]MP Summary'!$P$17 -> 0.13995598 | R19: ='[9]MP Summary'!$P$17 -> 0.13995598 | S19: ='[10]MP Summary'!$R$17 -> 0.073261673 | T19: ='[11]MP Summary'!$T$17 -> 0.057009281 | U19: =H19/$H$21 -> 0.22580833
A20: Nonstandard NDC | B20: None | C20: ='Vol Data'!$I$10 -> 405562 | D20: =C20/$C$42 -> 0.034645542 | E20: =('MP Cost Adjustments'!$D$24*'MP Cost Adjustments'!$H$24+'MP Cost Adjustments'!$D$34*'MP Cost Adjustments'!$H$34)/('MP Cost Adjustments'!$D$24+'MP Cost Adjustments'!$D$34) -> 1.3870348 | G20: 5-Digit Presort | H20: =C12+C13+C14+C25+C27+C28+C37+C39+C40 -> 483567 | J20: ='[1]MP Summary'!$I$18 -> 0.4231044 | K20: ='[2]MP Summary'!$I$18 -> 0.42264291 | L20: ='[3]MP Summary'!$I$18 -> 0.31183694 | M20: ='[4]MP Summary'!$I$18 -> 0.3914335 | N20: ='[5]MP Summary'!$I$18 -> 0.33470417 | O20: ='[6]MP Summary'!$I$18 -> 0.34177652 | P20: ='[7]MP Summary'!$I$18 -> 0.34441148 | Q20: ='[8]MP Summary'!$P$18 -> 0.33314113 | R20: ='[9]MP Summary'!$P$18 -> 0.33314113 | S20: ='[10]MP Summary'!$R$18 -> 0.33221246 | T20: ='[11]MP Summary'!$T$18 -> 0.27608027 | U20: =H20/$H$21 -> 0.043462263
A21: Nonstandard NDC | B21: DNDC | C21: ='Vol Data'!$I$11 -> 468927 | D21: =C21/$C$42 -> 0.040058561 | E21: =('MP Cost Adjustments'!$D$25*'MP Cost Adjustments'!$H$25+'MP Cost Adjustments'!$D$35*'MP Cost Adjustments'!$H$35)/('MP Cost Adjustments'!$D$25+'MP Cost Adjustments'!$D$35) -> 1.3784601 | H21: =SUM(H17:H20) -> 11126135 | J21: =SUM(J17:J20) -> 1 | K21: =SUM(K17:K20) -> 1 | L21: =SUM(L17:L20) -> 1 | M21: =SUM(M17:M20) -> 1 | N21: =SUM(N17:N20) -> 1 | O21: =SUM(O17:O20) -> 1 | P21: =SUM(P17:P20) -> 1 | Q21: =SUM(Q17:Q20) -> 1 | ... T21: =SUM(T17:T20) -> 1 | U21: 1
A22: Nonstandard SCF | B22: None/DNDC | C22: ='Vol Data'!$I$13+'Vol Data'!I12 -> 388379 | D22: =C22/$C$42 -> 0.033177667 | E22: =('MP Cost Adjustments'!$D$26*'MP Cost Adjustments'!$H$26+'MP Cost Adjustments'!$D$36*'MP Cost Adjustments'!$H$36)/('MP Cost Adjustments'!$D$26+'MP Cost Adjustments'!$D$36) -> 1.1498791
A23: Nonstandard SCF | B23: DSCF | C23: ='Vol Data'!$I$15 -> 453672 | D23: =C23/$C$42 -> 0.038755387 | E23: =('MP Cost Adjustments'!$D$28*'MP Cost Adjustments'!$H$28+'MP Cost Adjustments'!$D$38*'MP Cost Adjustments'!$H$38)/('MP Cost Adjustments'!$D$28+'MP Cost Adjustments'!$D$38) -> 1.1461197
A24: Nonstandard SCF Aggregate | E24: =SUMPRODUCT(C22:C23,E22:E23)/SUM(C22:C23) -> 1.1478537
A25: Nonstandard 5-Digit | B25: DNDC | C25: ='Vol Data'!$I$14 -> 111340 | D25: =C25/$C$42 -> 0.0095113316 | E25: =('MP Cost Adjustments'!$D$27*'MP Cost Adjustments'!$H$27+'MP Cost Adjustments'!$D$37*'MP Cost Adjustments'!$H$37)/('MP Cost Adjustments'!$D$27+'MP Cost Adjustments'!$D$37) -> 0.41445109
A26: Nonstandard 5-Digit | B26: DSCF | C26: ='Vol Data'!$I$16 -> 111784 | D26: =C26/$C$42 -> 0.0095492608 | E26: =('MP Cost Adjustments'!$D$29*'MP Cost Adjustments'!$H$29+'MP Cost Adjustments'!$D$39*'MP Cost Adjustments'!$H$39)/('MP Cost Adjustments'!$D$29+'MP Cost Adjustments'!$D$39) -> 0.39145625 | G26: Machinable | H26: =SUM(C9:C14) -> 2844836 | J26: =SUM('[1]MP Summary'!$D$9:$D$14) -> 0.15032548 | K26: =SUM('[2]MP Summary'!$D$9:$D$14) -> 0.14022772 | L26: =SUM('[3]MP Summary'!$D$9:$D$14) -> 0.13582223 | M26: =SUM('[4]MP Summary'!$D$9:$D$14) -> 0.16126364 | N26: =SUM('[5]MP Summary'!$D$9:$D$14) -> 0.19976711 | O26: =SUM('[6]MP Summary'!$D$9:$D$14) -> 0.18849858 | P26: =SUM('[7]MP Summary'!$D$9:$D$14) -> 0.216614 | Q26: ='[8]MP Summary'!$P$22 -> 0.19831926 | R26: ='[9]MP Summary'!$P$22 -> 0.19831926 | S26: ='[10]MP Summary'!$R$22 -> 0.25642046 | T26: ='[11]MP Summary'!$T$22 -> 0.27539304 | U26: 0.24576646
A27: Nonstandard 5-Digit | B27: DDU | C27: ='Vol Data'!$I$17 -> 2877 | D27: =C27/$C$42 -> 0.00024577062 | E27: =('MP Cost Adjustments'!$D$30*'MP Cost Adjustments'!$H$30+'MP Cost Adjustments'!$D$40*'MP Cost Adjustments'!$H$40)/('MP Cost Adjustments'!$D$30+'MP Cost Adjustments'!$D$40) -> 0.35894376 | G27: Irregular | H27: =SUM(C19:C28) -> 3290240 | J27: =SUM('[1]MP Summary'!$D$17:$D$24) -> 0.10722376 | K27: =SUM('[2]MP Summary'!$D$17:$D$24) -> 0.10702189 | L27: =SUM('[3]MP Summary'!$D$17:$D$24) -> 0.15373909 | M27: =SUM('[4]MP Summary'!$D$17:$D$24) -> 0.14044821 | N27: =SUM('[5]MP Summary'!$D$17:$D$24) -> 0.16275013 | O27: =SUM('[6]MP Summary'!$D$17:$D$24) -> 0.13547176 | P27: =SUM('[7]MP Summary'!$D$17:$D$24) -> 0.15088468 | Q27: ='[8]MP Summary'!$P$23 -> 0.15412881 | R27: ='[9]MP Summary'!$P$23 -> 0.15412881 | S27: ='[10]MP Summary'!$R$23 -> 0.16235617 | T27: ='[11]MP Summary'!$T$23 -> 0.18991485 | U27: 0.27437273
A28: Nonstandard 5-Digit Aggregate | E28: =SUMPRODUCT(C25:C27,E25:E27)/SUM(C25:C27) -> 0.40237083 | G28: Marketing | H28: =SUM(C31:C40) -> 5570961 | J28: =SUM('[1]MP Summary'!$D$27:$D$34) -> 0.74245076 | K28: =SUM('[2]MP Summary'!$D$27:$D$34) -> 0.75275038 | L28: =SUM('[3]MP Summary'!$D$27:$D$34) -> 0.71043867 | M28: =SUM('[4]MP Summary'!$D$27:$D$34) -> 0.69828814 | N28: =SUM('[5]MP Summary'!$D$27:$D$34) -> 0.63748275 | O28: =SUM('[6]MP Summary'!$D$27:$D$34) -> 0.67602966 | P28: =SUM('[7]MP Summary'!$D$27:$D$34) -> 0.63250132 | Q28: ='[8]MP Summary'!$P$24 -> 0.64755193 | R28: ='[9]MP Summary'!$P$24 -> 0.64755193 | S28: ='[10]MP Summary'!$R$24 -> 0.58122336 | T28: ='[11]MP Summary'!$T$24 -> 0.5346921 | U28: 0.4798608
H29: =SUM(H26:H28) -> 11706037 | J29: =SUM(J26:J28) -> 1 | K29: =SUM(K26:K28) -> 1 | L29: =SUM(L26:L28) -> 1 | M29: =SUM(M26:M28) -> 1 | N29: =SUM(N26:N28) -> 1 | O29: =SUM(O26:O28) -> 1 | P29: =SUM(P26:P28) -> 1 | Q29: =SUM(Q26:Q28) -> 1 | ... T29: =SUM(T26:T28) -> 1 | U29: 1
A30: Marketing
A31: Marketing MNDC | B31: None | C31: ='Vol Data'!$I$30 -> 2125950 | D31: =C31/$C$42 -> 0.18161142 | E31: =('MP Cost Adjustments'!$D$43*'MP Cost Adjustments'!$H$43+'MP Cost Adjustments'!$D$53*'MP Cost Adjustments'!$H$53)/('MP Cost Adjustments'!$D$43+'MP Cost Adjustments'!$D$53) -> 1.3304765 | G31: USPS-FY25-26 | J31: ='[1]Cost Pool Data'!$F$77/100 -> 1.0565508 | K31: ='[2]Cost Pool Data'!$F$77/100 -> 0.89565652 | L31: ='[3]Cost Pool Data'!$F$77/100 -> 1.2418517 | M31: ='[4]Cost Pool Data'!$F$77/100 -> 1.1281294 | N31: ='[5]Cost Pool Data'!$F$63/100 -> 1.3768074 | O31: ='[6]Cost Pool Data'!$F$63/100 -> 1.5182103 | P31: ='[7]Cost Pool Data'!$F$63/100 -> 1.1494665 | Q31: ='[8]Cost Pool Data'!$F$63/100 -> 1.4488566 | R31: ='[9]Cost Pool Data'!$F$63/100 -> 1.4518395 | S31: 1.2992236 | T31: ='[11]MP Summary'!$T$27 -> 1.5434505 | U31: ='Cost Pool Data'!F63/100 -> 1.0373367
A32: Marketing NDC | B32: None | C32: ='Vol Data'!$I$31 -> 844739 | D32: =C32/$C$42 -> 0.07216268 | E32: =('MP Cost Adjustments'!$D$44*'MP Cost Adjustments'!$H$44+'MP Cost Adjustments'!$D$54*'MP Cost Adjustments'!$H$54)/('MP Cost Adjustments'!$D$44+'MP Cost Adjustments'!$D$54) -> 1.0858395 | G32: MP Unit Cost
A33: Marketing NDC | B33: DNDC | C33: ='Vol Data'!$I$32 -> 136653 | D33: =C33/$C$42 -> 0.01167372 | E33: =('MP Cost Adjustments'!$D$45*'MP Cost Adjustments'!$H$45+'MP Cost Adjustments'!$D$55*'MP Cost Adjustments'!$H$55)/('MP Cost Adjustments'!$D$45+'MP Cost Adjustments'!$D$55) -> 1.0822498
A34: Marketing SCF | B34: None/DNDC | C34: ='Vol Data'!$I$34+'Vol Data'!I33 -> 29535 | D34: =C34/$C$42 -> 0.0025230571 | E34: =('MP Cost Adjustments'!$D$46*'MP Cost Adjustments'!$H$46+'MP Cost Adjustments'!$D$56*'MP Cost Adjustments'!$H$56)/('MP Cost Adjustments'!$D$46+'MP Cost Adjustments'!$D$56) -> 1.0387448 | G34: Percent Difference | K34: =(K31-J31)/J31 -> -0.15228257 | L34: =(L31-K31)/K31 -> 0.38652677 | M34: =(M31-L31)/L31 -> -0.091574798 | N34: =(N31-M31)/M31 -> 0.22043393 | O34: =(O31-N31)/N31 -> 0.10270349 | P34: =(P31-O31)/O31 -> -0.24288059 | Q34: =(Q31-P31)/P31 -> 0.26046001 | R34: =(R31-Q31)/Q31 -> 0.0020588504 | ... U34: =(U31-T31)/T31 -> -0.32791061
A35: Marketing SCF | B35: DSCF | C35: ='Vol Data'!$I$36 -> 126230 | D35: =C35/$C$42 -> 0.010783325 | E35: =('MP Cost Adjustments'!$D$48*'MP Cost Adjustments'!$H$48+'MP Cost Adjustments'!$D$58*'MP Cost Adjustments'!$H$58)/('MP Cost Adjustments'!$D$48+'MP Cost Adjustments'!$D$58) -> 1.0372022
A36: Marketing SCF Aggregate | E36: =SUMPRODUCT(C34:C35,E34:E35)/SUM(C34:C35) -> 1.0374947
A37: Marketing 5-Digit | B37: DNDC | C37: ='Vol Data'!I35 -> 30736 | D37: =C37/$C$42 -> 0.0026256538 | E37: =('MP Cost Adjustments'!$D$47*'MP Cost Adjustments'!$H$47+'MP Cost Adjustments'!$D$57*'MP Cost Adjustments'!$H$57)/('MP Cost Adjustments'!$D$47+'MP Cost Adjustments'!$D$57) -> 0.40988981
A38: Marketing 5-Digit | B38: DSCF | C38: ='Vol Data'!$I$37 -> 1982676 | D38: =C38/$C$42 -> 0.16937209 | E38: =('MP Cost Adjustments'!$D$49*'MP Cost Adjustments'!$H$49+'MP Cost Adjustments'!$D$59*'MP Cost Adjustments'!$H$59)/('MP Cost Adjustments'!$D$49+'MP Cost Adjustments'!$D$59) -> 0.38770436 | G38: CRA Prop. | J38: ='[1]MP Cost Adjustments'!$D$7 -> 2.3407223 | K38: ='[2]MP Cost Adjustments'!$D$7 -> 2.0172629 | L38: ='[3]MP Cost Adjustments'!$D$7 -> 2.3522076 | M38: ='[4]MP Cost Adjustments'!$D$7 -> 2.129463 | N38: ='[5]MP Cost Adjustments'!$D$7 -> 2.5005134 | O38: ='[6]MP Cost Adjustments'!$D$7 -> 2.7532281 | P38: ='[7]MP Cost Adjustments'!$D$7 -> 1.7184008 | Q38: ='[8]MP Cost Adjustments'!$D$7 -> 2.2645775 | R38: ='[9]MP Cost Adjustments'!$D$7 -> 2.1552933 | S38: ='[10]MP Cost Adjustments'!$D$7 -> 1.6520831 | T38: ='[11]MP Summary'!$T$32 -> 1.6279592 | U38: ='MP Cost Adjustments'!D7 -> 1.2422848
A39: Marketing 5-Digit | B39: DDU | C39: ='Vol Data'!$I$38 -> 294442 | D39: =C39/$C$42 -> 0.025153004 | E39: =('MP Cost Adjustments'!$D$50*'MP Cost Adjustments'!$H$50+'MP Cost Adjustments'!$D$60*'MP Cost Adjustments'!$H$60)/('MP Cost Adjustments'!$D$50+'MP Cost Adjustments'!$D$60) -> 0.35810078 | G39: Adjustment Factor
A40: Marketing 5-Digit Aggregate | E40: =SUMPRODUCT(C37:C39,E37:E39)/SUM(C37:C39) -> 0.38422293
G41: Percent Difference | K41: =(K38-J38)/J38 -> -0.13818787 | L41: =(L38-K38)/K38 -> 0.1660392 | M41: =(M38-L38)/L38 -> -0.09469597 | N41: =(N38-M38)/M38 -> 0.17424598 | O41: =(O38-N38)/N38 -> 0.10106515 | P41: =(P38-O38)/O38 -> -0.37585963 | Q41: =(Q38-P38)/P38 -> 0.31784008 | R41: =(R38-Q38)/Q38 -> -0.048258096 | ... U41: =(U38-T38)/T38 -> -0.23690667
A42: Total / Aggregate | C42: =SUM(C9:C40) -> 11706037 | D42: =SUM(D9:D40) -> 1 | E42: =SUMPRODUCT(D9:D40,E9:E40) -> 1.0373367
E44: ="[4]" -> [4]
...

Sheet MP Cost Adjustments
A1: USPS MARKETING MAIL PARCEL MAIL PROCESSING COST ADJUSTMENTS
A5: Aggregate Weighted Model Cost | D5: =SUMPRODUCT(C15:C60,E15:E60) -> 0.78718151 | E5: [1]
A6: CRA Proportional Costs | D6: ='Cost Pool Data'!G63/100 -> 0.97790362 | E6: [2]
A7: CRA Proportional Adjustment Factor | D7: =D6/D5 -> 1.2422848 | E7: [3]
A8: CRA Fixed Costs | D8: ='Cost Pool Data'!H63/100 -> 0.059433111 | E8: [4]
C10: [5] | D10: [6] | E10: [7] | F10: [8] | G10: [9] | H10: [10]
A11: Parcels | B11: Entry | C11: Model | E11: Volume | F11: Proportional | G11: Fixed | H11: Adjusted
A12: Price Category | B12: Discount | C12: Cost | D12: Volume | E12: Percent | F12: Adjustment | G12: Adjustment | H12: Unit Cost
A14: Machinable
A15: Machinable MNDC | B15: None | C15: ='M-NONE-MNDC'!J89 -> 1.0169705 | D15: ='Vol Data'!$I$20 -> 670396 | E15: =D15/$D$62 -> 0.057269253 | F15: =$D$7 -> 1.2422848 | G15: =$D$8 -> 0.059433111 | H15: =C15*F15+G15 -> 1.3228001
A16: Machinable NDC | B16: None | C16: ='M-NONE-NDC'!J84 -> 0.73272595 | D16: ='Vol Data'!$I$21 -> 400984 | E16: =D16/$D$62 -> 0.034254462 | F16: =$D$7 -> 1.2422848 | G16: =$D$8 -> 0.059433111 | H16: =C16*F16+G16 -> 0.96968742
A17: Machinable NDC | B17: DNDC | C17: ='M-DNDC-NDC'!J56 -> 0.71940612 | D17: ='Vol Data'!$I$22 -> 1729284 | E17: =D17/$D$62 -> 0.14772583 | F17: =$D$7 -> 1.2422848 | G17: =$D$8 -> 0.059433111 | H17: =C17*F17+G17 -> 0.95314039
A18: Machinable 5-Digit | B18: DNDC | C18: ='M-DNDC-5D'!J39 -> 0.30042353 | D18: ='Vol Data'!$I$23 -> 6159 | E18: =D18/$D$62 -> 0.00052613878 | F18: =$D$7 -> 1.2422848 | G18: =$D$8 -> 0.059433111 | H18: =C18*F18+G18 -> 0.4326447
A19: Machinable 5-Digit | B19: DSCF | C19: ='M-DSCF-5D'!J24 -> 0.2841236 | D19: ='Vol Data'!$I$24 -> 32567 | E19: =D19/$D$62 -> 0.0027820688 | F19: =$D$7 -> 1.2422848 | G19: =$D$8 -> 0.059433111 | H19: =C19*F19+G19 -> 0.41239554
A20: Machinable 5-Digit | B20: DDU | C20: ='M-DDU-5D'!J15 -> 0.2413159 | D20: ='Vol Data'!$I$25 -> 5446 | E20: =D20/$D$62 -> 0.00046523003 | F20: =$D$7 -> 1.2422848 | G20: =$D$8 -> 0.059433111 | H20: =C20*F20+G20 -> 0.35921618
A22: Nonstandard Rolls
A23: Nonstandard MNDC | B23: None | C23: ='IR-NONE-MNDC'!J49 -> 1.8728046 | D23: ='Vol Data'!$D$47*'Vol Data'!$I9 -> 141056.91 | E23: =D23/$D$62 -> 0.012049928 | F23: =$D$7 -> 1.2422848 | G23: =$D$8 -> 0.059433111 | H23: =C23*F23+G23 -> 2.3859898
A24: Nonstandard NDC | B24: None | C24: ='IR-NONE-NDC'!J49 -> 1.7986898 | D24: ='Vol Data'!$D$47*'Vol Data'!$I$10 -> 42448.144 | E24: =D24/$D$62 -> 0.0036261754 | F24: =$D$7 -> 1.2422848 | G24: =$D$8 -> 0.059433111 | H24: =C24*F24+G24 -> 2.2939181
A25: Nonstandard NDC | B25: DNDC | C25: ='IR-DNDC-NDC'!J21 -> 1.7905114 | D25: ='Vol Data'!$D$47*'Vol Data'!$I$11 -> 49080.241 | E25: =D25/$D$62 -> 0.004192729 | F25: =$D$7 -> 1.2422848 | G25: =$D$8 -> 0.059433111 | H25: =C25*F25+G25 -> 2.2837583
A26: Nonstandard SCF | B26: None/DNDC | C26: ='IR-DNDC-SCF'!J25 -> 1.6057618 | D26: ='Vol Data'!$D$47*('Vol Data'!$I$13+'Vol Data'!I12) -> 40649.685 | E26: =D26/$D$62 -> 0.0034725403 | F26: =$D$7 -> 1.2422848 | G26: =$D$8 -> 0.059433111 | H26: =C26*F26+G26 -> 2.0542466
A27: Nonstandard 5-Digit | B27: DNDC | C27: ='IR-DNDC-5D'!J31 -> 0.28790722 | D27: ='Vol Data'!$D$47*'Vol Data'!$I$14 -> 11653.4 | E27: =D27/$D$62 -> 0.00099550346 | F27: =$D$7 -> 1.2422848 | G27: =$D$8 -> 0.059433111 | H27: =C27*F27+G27 -> 0.41709587
A28: Nonstandard SCF | B28: DSCF | C28: ='IR-DSCF-SCF'!J18 -> 1.6022401 | D28: ='Vol Data'!$D$47*'Vol Data'!$I$15 -> 47483.577 | E28: =D28/$D$62 -> 0.0040563324 | F28: =$D$7 -> 1.2422848 | G28: =$D$8 -> 0.059433111 | H28: =C28*F28+G28 -> 2.0498716
A29: Nonstandard 5-Digit | B29: DSCF | C29: ='IR-DSCF-5D'!J24 -> 0.26893969 | D29: ='Vol Data'!$D$47*'Vol Data'!$I$16 -> 11699.872 | E29: =D29/$D$62 -> 0.00099947331 | F29: =$D$7 -> 1.2422848 | G29: =$D$8 -> 0.059433111 | H29: =C29*F29+G29 -> 0.39353279
A30: Nonstandard 5-Digit | B30: DDU | C30: ='IR -DDU-5D'!J15 -> 0.24148946 | D30: ='Vol Data'!$D$47*'Vol Data'!$I$17 -> 301.12118 | E30: =D30/$D$62 -> 2.572358e-05 | F30: =$D$7 -> 1.2422848 | G30: =$D$8 -> 0.059433111 | H30: =C30*F30+G30 -> 0.35943179
A32: Nonstandard Other
A33: Nonstandard MNDC | B33: None | C33: ='IO-NONE-MNDC'!J51 -> 1.0570275 | D33: =(1-'Vol Data'!$D$47)*'Vol Data'!$I$9 -> 1206642.1 | E33: =D33/$D$62 -> 0.10307862 | F33: =$D$7 -> 1.2422848 | G33: =$D$8 -> 0.059433111 | H33: =C33*F33+G33 -> 1.3725623
A34: Nonstandard NDC | B34: None | C34: ='IO-NONE-NDC'!J51 -> 0.98333871 | D34: =(1-'Vol Data'!$D$47)*'Vol Data'!$I$10 -> 363113.86 | E34: =D34/$D$62 -> 0.031019367 | F34: =$D$7 -> 1.2422848 | G34: =$D$8 -> 0.059433111 | H34: =C34*F34+G34 -> 1.2810198
A35: Nonstandard NDC | B35: DNDC | C35: ='IO-DNDC-NDC'!J23 -> 0.97658553 | D35: =(1-'Vol Data'!$D$47)*'Vol Data'!$I$11 -> 419846.76 | E35: =D35/$D$62 -> 0.035865832 | F35: =$D$7 -> 1.2422848 | G35: =$D$8 -> 0.059433111 | H35: =C35*F35+G35 -> 1.2726305
A36: Nonstandard SCF | B36: None/DNDC | C36: ='IO-DNDC-SCF'!J27 -> 0.79267257 | D36: =(1-'Vol Data'!$D$47)*('Vol Data'!$I$13+'Vol Data'!I12) -> 347729.31 | E36: =D36/$D$62 -> 0.029705127 | F36: =$D$7 -> 1.2422848 | G36: =$D$8 -> 0.059433111 | H36: =C36*F36+G36 -> 1.0441582
A37: Nonstandard 5-Digit | B37: DNDC | C37: ='IO-DNDC-5D'!J31 -> 0.28552937 | D37: =(1-'Vol Data'!$D$47)*'Vol Data'!$I$14 -> 99686.6 | E37: =D37/$D$62 -> 0.0085158282 | F37: =$D$7 -> 1.2422848 | G37: =$D$8 -> 0.059433111 | H37: =C37*F37+G37 -> 0.41414191
A38: Nonstandard SCF | B38: DSCF | C38: ='IO-DSCF-SCF'!J20 -> 0.78970434 | D38: =(1-'Vol Data'!$D$47)*'Vol Data'!$I$15 -> 406188.42 | E38: =D38/$D$62 -> 0.034699055 | F38: =$D$7 -> 1.2422848 | G38: =$D$8 -> 0.059433111 | H38: =C38*F38+G38 -> 1.0404708
A39: Nonstandard 5-Digit | B39: DSCF | C39: ='IO-DSCF-5D'!J24 -> 0.26707273 | D39: =(1-'Vol Data'!$D$47)*'Vol Data'!$I$16 -> 100084.13 | E39: =D39/$D$62 -> 0.0085497875 | F39: =$D$7 -> 1.2422848 | G39: =$D$8 -> 0.059433111 | H39: =C39*F39+G39 -> 0.3912135
A40: Nonstandard 5-Digit | B40: DDU | C40: ='IO-DDU-5D'!J15 -> 0.24105068 | D40: =(1-'Vol Data'!$D$47)*'Vol Data'!$I$17 -> 2575.8788 | E40: =D40/$D$62 -> 0.00022004704 | F40: =$D$7 -> 1.2422848 | G40: =$D$8 -> 0.059433111 | H40: =C40*F40+G40 -> 0.35888671
A42: Marketing Other
A43: Marketing MNDC | B43: None | C43: ='MO-NONE-MNDC'!J51 -> 1.0484017 | D43: =(1-'Vol Data'!$C$46)*'Vol Data'!$I$30 -> 929617.4 | E43: =D43/$D$62 -> 0.079413503 | F43: =$D$7 -> 1.2422848 | G43: =$D$8 -> 0.059433111 | H43: =C43*F43+G43 -> 1.3618466
A44: Marketing NDC | B44: None | C44: ='MO-NONE-NDC'!J51 -> 0.97539283 | D44: =(1-'Vol Data'!$C$46)*'Vol Data'!$I$31 -> 369380.31 | E44: =D44/$D$62 -> 0.031554685 | F44: =$D$7 -> 1.2422848 | G44: =$D$8 -> 0.059433111 | H44: =C44*F44+G44 -> 1.2711488
A45: Marketing NDC | B45: DNDC | C45: ='MO-DNDC-NDC'!J23 -> 0.97185654 | D45: =(1-'Vol Data'!$C$46)*'Vol Data'!$I$32 -> 59754.466 | E45: =D45/$D$62 -> 0.0051045854 | F45: =$D$7 -> 1.2422848 | G45: =$D$8 -> 0.059433111 | H45: =C45*F45+G45 -> 1.2667557
A46: Marketing SCF | B46: None/DNDC | C46: ='MO-DNDC-SCF'!J27 -> 0.78831495 | D46: =(1-'Vol Data'!$C$46)*('Vol Data'!$I$34+'Vol Data'!$I$33) -> 12914.815 | E46: =D46/$D$62 -> 0.001103261 | F46: =$D$7 -> 1.2422848 | G46: =$D$8 -> 0.059433111 | H46: =C46*F46+G46 -> 1.0387448
A47: Marketing 5-Digit | B47: DNDC | C47: ='MO-DNDC-5D'!J31 -> 0.28210657 | D47: =(1-'Vol Data'!$C$46)*'Vol Data'!$I$35 -> 13439.978 | E47: =D47/$D$62 -> 0.0011481236 | F47: =$D$7 -> 1.2422848 | G47: =$D$8 -> 0.059433111 | H47: =C47*F47+G47 -> 0.40988981
A48: Marketing SCF | B48: DSCF | C48: ='MO-DSCF-SCF'!J20 -> 0.78707323 | D48: =(1-'Vol Data'!$C$46)*'Vol Data'!$I$36 -> 55196.785 | E48: =D48/$D$62 -> 0.0047152409 | F48: =$D$7 -> 1.2422848 | G48: =$D$8 -> 0.059433111 | H48: =C48*F48+G48 -> 1.0372022
...

Sheet Cost Pool Data
A1: USPS MARKETING MAIL PARCEL MAIL PROCESSING COST POOL DATA
F4: [1] | G4: [2] | H4: [3] | I4: [4] | J4: [5] | K4: [6]
A5: Cost | I5: Volume
A6: Pool | C6: Cost Pool | D6: Proportional | E6: Fixed | F6: Total | G6: Proportional | H6: Fixed | I6: Variability | J6: Overhead | K6: Piggyback
A7: No. | B7: Source | C7: Abbreviation | D7: Costs | E7: Costs | F7: (Cents) | G7: (Cents) | H7: (Cents) | I7: Factors | J7: Factors | K7: Factors
A9: 1 | B9: MODS 11 & 15 | C9: D/BCS | E9: X | F9: ='[12]PARCEL Unit Costs W Final Adj.'!$F$6 -> 9.5842082 | G9: =F9*$G$69 -> 9.0350911 | H9: =F9*$H$69 -> 0.54911708 | I9: ='[13]8 MP Cost Pool Variabilities'!$E$9 -> 0.98913372 | J9: ='[14]VII-3a. ovhead factors-MODS1&2'!$G$9 -> 1.3893525 | K9: ='[15]MP Piggybacks'!$J$7 -> 1.7543598
A10: =A9+1 -> 2 | B10: MODS 12 & 17 | C10: AFSM100 | E10: X | F10: ='[12]PARCEL Unit Costs W Final Adj.'!$F$7 -> 0.29633707 | G10: =F10*$G$69 -> 0.27935876 | H10: =F10*$H$69 -> 0.016978319 | I10: ='[13]8 MP Cost Pool Variabilities'!$E$12 -> 0.97340818 | J10: ='[14]VII-3a. ovhead factors-MODS1&2'!$G$12 -> 1.4309838 | K10: ='[15]MP Piggybacks'!$J$8 -> 1.6305774 | L10: APBS
A11: =A10+1 -> 3 | B11: MODS 12 & 17 | C11: FSS | E11: X | F11: ='[12]PARCEL Unit Costs W Final Adj.'!$F$8 -> 0 | G11: =F11*$G$69 -> 0 | H11: =F11*$H$69 -> 0 | I11: ='[13]8 MP Cost Pool Variabilities'!$E$13 -> 0 | J11: ='[14]VII-3a. ovhead factors-MODS1&2'!$G$15 -> 0 | K11: ='[15]MP Piggybacks'!$J$9 -> 0 | L11: ='[15]MP Piggybacks'!$J$78 -> 1.6056413
A12: =A11+1 -> 4 | B12: MODS 13 | C12: APBS OTH | D12: X | F12: ='[12]PARCEL Unit Costs W Final Adj.'!$F$9 -> 3.5336098 | G12: =F12 -> 3.5336098 | I12: ='[13]8 MP Cost Pool Variabilities'!$E$16 -> 0.96403554 | J12: ='[14]VII-3a. ovhead factors-MODS1&2'!$G$18 -> 1.4847804 | K12: ='[15]MP Piggybacks'!$J$10 -> 1.6595873
A13: =A12+1 -> 5 | B13: MODS 13 | C13: APBSPRIO | D13: X | F13: ='[12]PARCEL Unit Costs W Final Adj.'!$F$10 -> 13.343898 | G13: =F13 -> 13.343898 | I13: ='[13]8 MP Cost Pool Variabilities'!$E$17 -> 0.96805898 | J13: ='[14]VII-3a. ovhead factors-MODS1&2'!$G$21 -> 1.5054165 | K13: ='[15]MP Piggybacks'!$J$11 -> 1.6636637
A14: =A13+1 -> 6 | B14: MODS 14 | C14: MANF | E14: X | F14: ='[12]PARCEL Unit Costs W Final Adj.'!$F$13 -> 0.07320992 | G14: =F14*$G$69 -> 0.069015435 | H14: =F14*$H$69 -> 0.004194485 | I14: ='[13]8 MP Cost Pool Variabilities'!$E$20 -> 0.9675812 | J14: ='[14]VII-3a. ovhead factors-MODS1&2'!$G$24 -> 1.4612893 | K14: ='[15]MP Piggybacks'!$J$14 -> 1.3622907 | L14: ='[15]MP Piggybacks'!$J$84 -> 1.8052502
A15: =A14+1 -> 7 | B15: MODS 14 | C15: MANL | E15: X | F15: ='[12]PARCEL Unit Costs W Final Adj.'!$F$14 -> 0.00047377307 | G15: =F15*$G$69 -> 0.00044662874 | H15: =F15*$H$69 -> 2.7144327e-05 | I15: ='[13]8 MP Cost Pool Variabilities'!$E$21 -> 0.97238125 | J15: ='[14]VII-3a. ovhead factors-MODS1&2'!$G$27 -> 1.3647592 | K15: ='[15]MP Piggybacks'!$J$15 -> 1.2988119 | L15: APPS (WITH REC COSTS AS INDIRECT)
A16: =A15+1 -> 8 | B16: MODS 14 | C16: MANP | D16: X | F16: ='[12]PARCEL Unit Costs W Final Adj.'!$F$15 -> 0 | G16: =F16 -> 0 | I16: ='[13]8 MP Cost Pool Variabilities'!$E$22 -> 0.97225878 | J16: ='[14]VII-3a. ovhead factors-MODS1&2'!$G$30 -> 1.4652042 | K16: ='[15]MP Piggybacks'!$J$16 -> 1.3208756
A17: =A16+1 -> 9 | B17: MODS 14 | C17: PRIORITY | E17: X | F17: ='[12]PARCEL Unit Costs W Final Adj.'!$F$16 -> 3.5705299 | G17: =F17*$G$69 -> 3.3659602 | H17: =F17*$H$69 -> 0.20456974 | I17: ='[13]8 MP Cost Pool Variabilities'!$E$23 -> 0.9614871 | J17: ='[14]VII-3a. ovhead factors-MODS1&2'!$G$33 -> 1.583582 | K17: ='[15]MP Piggybacks'!$J$17 -> 1.3673172
A18: =A17+1 -> 10 | B18: MODS 15 | C18: LD15 | E18: X | F18: ='[12]PARCEL Unit Costs W Final Adj.'!$F$17 -> 0 | G18: =F18*$G$69 -> 0 | H18: =F18*$H$69 -> 0 | I18: ='[13]8 MP Cost Pool Variabilities'!$E$25 -> 0.87303 | J18: NA | K18: ='[15]MP Piggybacks'!$J$18 -> 1.3915843
A19: =A18+1 -> 11 | B19: MODS 16 | C19: LCUS-SSM | D19: X | F19: ='[12]PARCEL Unit Costs W Final Adj.'!$F$11 -> 0.0019283303 | G19: =F19*$G$69 -> 0.0018178487 | H19: =F19*$H$69 -> 0.00011048165 | I19: ='[13]8 MP Cost Pool Variabilities'!$E$28 -> 0.95929236 | J19: ='[14]VII-3a. ovhead factors-MODS1&2'!$G$36 -> 1.4332178 | K19: ='[15]MP Piggybacks'!$J$12 -> 1.5773008
A20: =A19+1 -> 12 | B20: MODS 16 | C20: 1TRAYSRT | E20: X | F20: ='[12]PARCEL Unit Costs W Final Adj.'!$F$12 -> 0.30732048 | G20: =F20*$G$69 -> 0.28971288 | H20: =F20*$H$69 -> 0.017607602 | I20: ='[13]8 MP Cost Pool Variabilities'!$E$29 -> 0.94974595 | J20: ='[14]VII-3a. ovhead factors-MODS1&2'!$G$39 -> 1.577485 | K20: ='[15]MP Piggybacks'!$J$13 -> 1.5358045
A21: =A20+1 -> 13 | B21: MODS 17 | C21: 1CANCEL | E21: X | F21: ='[12]PARCEL Unit Costs W Final Adj.'!$F$18 -> 0.16556736 | H21: =F21 -> 0.16556736 | I21: ='[13]8 MP Cost Pool Variabilities'!$E$32 -> 0.97853723 | J21: ='[14]VII-3a. ovhead factors-MODS1&2'!$G$42 -> 1.4757547 | K21: ='[15]MP Piggybacks'!$J$19 -> 2.1937318
A22: =A21+1 -> 14 | B22: MODS 17 | C22: 1DSPATCH | E22: X | F22: ='[12]PARCEL Unit Costs W Final Adj.'!$F$19 -> 0.21112398 | H22: =F22 -> 0.21112398 | I22: ='[13]8 MP Cost Pool Variabilities'!$E$33 -> 0.96402406 | J22: ='[14]VII-3a. ovhead factors-MODS1&2'!$G$45 -> 1.6294675 | K22: ='[15]MP Piggybacks'!$J$20 -> 1.996303
A23: =A22+1 -> 15 | B23: MODS 17 | C23: 1MTRPREP | E23: X | F23: ='[12]PARCEL Unit Costs W Final Adj.'!$F$20 -> 0 | G23: =F23*$G$69 -> 0 | H23: =F23*$H$69 -> 0 | I23: ='[13]8 MP Cost Pool Variabilities'!$E$34 -> 0.95316198 | J23: ='[14]VII-3a. ovhead factors-MODS1&2'!$G$48 -> 1.35665 | K23: ='[15]MP Piggybacks'!$J$21 -> 1.4592078
A24: =A23+1 -> 16 | B24: MODS 17 | C24: 1OPBULK | E24: X | F24: ='[12]PARCEL Unit Costs W Final Adj.'!$F$21 -> 0.018926324 | G24: =F24*$G$69 -> 0.01784196 | H24: =F24*$H$69 -> 0.0010843637 | I24: ='[13]8 MP Cost Pool Variabilities'!$E$35 -> 0.98981851 | J24: ='[14]VII-3a. ovhead factors-MODS1&2'!$G$51 -> 1.5382885 | K24: ='[15]MP Piggybacks'!$J$22 -> 1.5480484
A25: =A24+1 -> 17 | B25: MODS 17 | C25: 1OPPREF | E25: X | F25: ='[12]PARCEL Unit Costs W Final Adj.'!$F$22 -> 0.18282581 | G25: =F25*$G$69 -> 0.172351 | H25: =F25*$H$69 -> 0.010474811 | I25: ='[13]8 MP Cost Pool Variabilities'!$E$36 -> 0.96735625 | J25: ='[14]VII-3a. ovhead factors-MODS1&2'!$G$54 -> 1.5365022 | K25: ='[15]MP Piggybacks'!$J$23 -> 1.3297825
A26: =A25+1 -> 18 | B26: MODS 17 | C26: 1OPTRANS | E26: X | F26: ='[12]PARCEL Unit Costs W Final Adj.'!$F$23 -> 0.11753503 | G26: =F26*$G$69 -> 0.11080099 | H26: =F26*$H$69 -> 0.0067340456 | I26: ='[13]8 MP Cost Pool Variabilities'!$E$37 -> 0.92643886 | J26: ='[14]VII-3a. ovhead factors-MODS1&2'!$G$57 -> 1.6313963 | K26: ='[15]MP Piggybacks'!$J$24 -> 1.3430299
A27: =A26+1 -> 19 | B27: MODS 17 | C27: 1PLATFRM | D27: X | F27: ='[12]PARCEL Unit Costs W Final Adj.'!$F$24 -> 15.888003 | G27: =F27*$G$69 -> 14.977716 | H27: =F27*$H$69 -> 0.91028632 | I27: ='[13]8 MP Cost Pool Variabilities'!$E$38 -> 0.91687625 | J27: ='[14]VII-3a. ovhead factors-MODS1&2'!$G$60 -> 1.4478255 | K27: ='[15]MP Piggybacks'!$J$25 -> 1.3606062
A28: =A27+1 -> 20 | B28: MODS 17 | C28: 1POUCHNG | D28: X | F28: ='[12]PARCEL Unit Costs W Final Adj.'!$F$25 -> 0.011427104 | G28: =F28*$G$69 -> 0.0107724 | H28: =F28*$H$69 -> 0.00065470385 | I28: ='[13]8 MP Cost Pool Variabilities'!$E$39 -> 0.94237641 | J28: ='[14]VII-3a. ovhead factors-MODS1&2'!$G$63 -> 1.3718328 | K28: ='[15]MP Piggybacks'!$J$26 -> 1.5985379
A29: =A28+1 -> 21 | B29: MODS 17 | C29: 1PRESORT | E29: X | F29: ='[12]PARCEL Unit Costs W Final Adj.'!$F$26 -> 0.011481221 | G29: =F29*$G$69 -> 0.010823417 | H29: =F29*$H$69 -> 0.00065780444 | I29: ='[13]8 MP Cost Pool Variabilities'!$E$40 -> 0.95326085 | J29: ='[14]VII-3a. ovhead factors-MODS1&2'!$G$66 -> 1.3920854 | K29: ='[15]MP Piggybacks'!$J$27 -> 1.3835778
A30: =A29+1 -> 22 | B30: MODS 17 | C30: 1SACKS_H | D30: X | F30: ='[12]PARCEL Unit Costs W Final Adj.'!$F$27 -> 0.050567053 | G30: =F30*$G$69 -> 0.047669867 | H30: =F30*$H$69 -> 0.0028971859 | I30: ='[13]8 MP Cost Pool Variabilities'!$E$41 -> 0.9460562 | J30: ='[14]VII-3a. ovhead factors-MODS1&2'!$G$69 -> 1.6529864 | K30: ='[15]MP Piggybacks'!$J$28 -> 1.2805163
A31: =A30+1 -> 23 | B31: MODS 17 | C31: 1SCAN | E31: X | F31: ='[12]PARCEL Unit Costs W Final Adj.'!$F$28 -> 0.24846401 | G31: =F31*$G$69 -> 0.23422853 | H31: =F31*$H$69 -> 0.014235483 | I31: ='[13]8 MP Cost Pool Variabilities'!$E$42 -> 0.98882842 | J31: ='[14]VII-3a. ovhead factors-MODS1&2'!$G$72 -> 1.5133584 | K31: ='[15]MP Piggybacks'!$J$29 -> 1.7604648
A32: =A31+1 -> 24 | B32: MODS 18 | C32: BUSREPLY | E32: X | F32: ='[12]PARCEL Unit Costs W Final Adj.'!$F$29 -> 0 | H32: =F32 -> 0 | I32: ='[13]8 MP Cost Pool Variabilities'!$E$45 -> 0.98872015 | J32: ='[14]VII-3a. ovhead factors-MODS1&2'!$G$75 -> 1.1470045 | K32: ='[15]MP Piggybacks'!$J$30 -> 1.2907912
A33: =A32+1 -> 25 | B33: MODS 18 | C33: EXPRESS | E33: X | F33: ='[12]PARCEL Unit Costs W Final Adj.'!$F$30 -> 0.00093944502 | G33: =F33*$G$69 -> 0.00088562051 | H33: =F33*$H$69 -> 5.3824509e-05 | I33: ='[13]8 MP Cost Pool Variabilities'!$E$46 -> 0.89440665 | J33: ='[14]VII-3a. ovhead factors-MODS1&2'!$G$78 -> 1.5379311 | K33: ='[15]MP Piggybacks'!$J$31 -> 1.3454732
A34: =A33+1 -> 26 | B34: MODS 18 | C34: REGISTRY | E34: X | F34: ='[12]PARCEL Unit Costs W Final Adj.'!$F$31 -> 0.0040357607 | H34: =F34 -> 0.0040357607 | I34: ='[13]8 MP Cost Pool Variabilities'!$E$47 -> 0.45629614 | J34: ='[14]VII-3a. ovhead factors-MODS1&2'!$G$81 -> 1.6743714 | K34: ='[15]MP Piggybacks'!$J$32 -> 1.4574115
A35: =A34+1 -> 27 | B35: MODS 18 | C35: REWRAP | E35: X | F35: ='[12]PARCEL Unit Costs W Final Adj.'!$F$32 -> 0.0017455899 | G35: =F35*$G$69 -> 0.0016455781 | H35: =F35*$H$69 -> 0.00010001173 | I35: ='[13]8 MP Cost Pool Variabilities'!$E$48 -> 0.96803836 | J35: ='[14]VII-3a. ovhead factors-MODS1&2'!$G$84 -> 1.4335549 | K35: ='[15]MP Piggybacks'!$J$33 -> 1.3190104
A36: =A35+1 -> 28 | B36: MODS 18 | C36: 1EEQMT | E36: X | F36: ='[12]PARCEL Unit Costs W Final Adj.'!$F$33 -> 0.37797183 | G36: =F36*$G$69 -> 0.35631633 | H36: =F36*$H$69 -> 0.021655496 | I36: ='[13]8 MP Cost Pool Variabilities'!$E$49 -> 0.98854348 | J36: ='[14]VII-3a. ovhead factors-MODS1&2'!$G$87 -> 2.8909569 | K36: ='[15]MP Piggybacks'!$J$34 -> 1.7174724
A37: =A36+1 -> 29 | B37: MODS 18 | C37: 1MISC | E37: X | F37: ='[12]PARCEL Unit Costs W Final Adj.'!$F$34 -> 0.1231653 | G37: =F37*$G$69 -> 0.11610867 | H37: =F37*$H$69 -> 0.0070566257 | I37: ='[13]8 MP Cost Pool Variabilities'!$E$50 -> 0.94447461 | J37: ='[14]VII-3a. ovhead factors-MODS1&2'!$G$90 -> 1.5458015 | K37: ='[15]MP Piggybacks'!$J$35 -> 1.2712452
A38: =A37+1 -> 30 | B38: MODS 18 | C38: 1SUPPORT | E38: X | F38: ='[12]PARCEL Unit Costs W Final Adj.'!$F$35 -> 0.13783212 | G38: =F38*$G$69 -> 0.12993517 | H38: =F38*$H$69 -> 0.0078969455 | I38: ='[13]8 MP Cost Pool Variabilities'!$E$51 -> 0.80783515 | J38: ='[14]VII-3a. ovhead factors-MODS1&2'!$G$93 -> 1.5748499 | K38: ='[15]MP Piggybacks'!$J$36 -> 1.2900243
A39: =A38+1 -> 31 | B39: All LDCs | C39: INTL ISC | E39: X | F39: ='[12]PARCEL Unit Costs W Final Adj.'!$F$36 -> 0 | H39: =F39 -> 0 | I39: ='[13]8 MP Cost Pool Variabilities'!$E$53 -> 0.91490899 | J39: ='[14]VII-3a. ovhead factors-MODS1&2'!$G$96 -> 1.4057199 | K39: ='[15]MP Piggybacks'!$J$37 -> 1.5816647
A40: =A39+1 -> 32 | B40: NDCS 12 & 17 | C40: FSS | E40: X | F40: ='[12]PARCEL Unit Costs W Final Adj.'!$F$37 -> 0 | G40: =F40*$G$69 -> 0 | H40: =F40*$H$69 -> 0 | I40: ='[13]8 MP Cost Pool Variabilities'!$E$63 -> 0 | J40: ='[14]VII-3c. Ovhead Factors NDCs'!$H$8 -> 0 | K40: ='[15]MP Piggybacks'!$J$38 -> 0
A41: =A40+1 -> 33 | B41: NDCS 14 | C41: MANP | D41: X | F41: ='[12]PARCEL Unit Costs W Final Adj.'!$F$38 -> 0.006059402 | G41: =F41 -> 0.006059402 | I41: ='[13]8 MP Cost Pool Variabilities'!$E$64 -> 0.91586806 | J41: ='[14]VII-3c. Ovhead Factors NDCs'!$H$11 -> 1.5946397 | K41: ='[15]MP Piggybacks'!$J$39 -> 1.4774317
A42: =A41+1 -> 34 | B42: NDCS All LDCs | C42: OTHR | D42: X | F42: ='[12]PARCEL Unit Costs W Final Adj.'!$F$39 -> 0.099326253 | G42: =F42 -> 0.099326253 | I42: ='[13]8 MP Cost Pool Variabilities'!$E$65 -> 0.91140966 | J42: ='[14]VII-3c. Ovhead Factors NDCs'!$H$14 -> 1.5517735 | K42: ='[15]MP Piggybacks'!$J$40 -> 1.5176144 | L42: PPSM
A43: =A42+1 -> 35 | B43: NDCS 17 | C43: PLA | D43: X | F43: ='[12]PARCEL Unit Costs W Final Adj.'!$F$40 -> 1.4548415 | G43: =F43 -> 1.4548415 | I43: ='[13]8 MP Cost Pool Variabilities'!$E$66 -> 0.88894222 | J43: ='[14]VII-3c. Ovhead Factors NDCs'!$H$17 -> 1.4041376 | K43: ='[15]MP Piggybacks'!$J$41 -> 1.3860239 | L43: ='[15]MP Piggybacks'!$J$63 -> 1.9204979
...

Sheet Vol Data
A1: USPS MARKETING MAIL PARCEL VOLUME DATA
C3: [1] | D3: [2] | E3: [3] | F3: [4] | G3: [5] | H3: [6] | I3: [7]
C5: Commercial | D5: Commercial | E5: Commercial | F5: Non Profit | G5: Non Profit | H5: Non Profit | I5: Grand
B6: Entry | C6: Piece-Rated | D6: Pound-Rated | E6: Total | F6: Piece-Rated | G6: Pound-Rated | H6: Total | I6: Total
A7: Price Category | B7: Discount | C7: Volume | D7: Volume | E7: Volume | F7: Volume | G7: Volume | H7: Volume | I7: Volume
A9: Nonstandard MNDC | B9: None | C9: 0 | D9: 0 | E9: =C9+D9 -> 0 | F9: =[16]Parcels!$E$113 -> 244203 | G9: =[16]Parcels!$E$130 -> 1103496 | H9: =F9+G9 -> 1347699 | I9: =E9+H9 -> 1347699
A10: Nonstandard NDC | B10: None | C10: 0 | D10: 0 | E10: =C10+D10 -> 0 | F10: =[16]Parcels!$E$115 -> 4087 | G10: =[16]Parcels!$E$132 -> 401475 | H10: =F10+G10 -> 405562 | I10: =E10+H10 -> 405562
A11: Nonstandard NDC | B11: DNDC | C11: 0 | D11: 0 | E11: =C11+D11 -> 0 | F11: =[16]Parcels!$E$116 -> 18753 | G11: =[16]Parcels!$E$133 -> 450174 | H11: =F11+G11 -> 468927 | I11: =E11+H11 -> 468927
A12: Nonstandard SCF | B12: None | C12: 0 | D12: 0 | E12: =C12+D12 -> 0 | F12: =[16]Parcels!$E$118 -> 9 | G12: =[16]Parcels!$E$135 -> 114267 | H12: =F12+G12 -> 114276 | I12: =E12+H12 -> 114276
A13: Nonstandard SCF | B13: DNDC | C13: 0 | D13: 0 | E13: =C13+D13 -> 0 | F13: =[16]Parcels!$E$119 -> 28 | G13: =[16]Parcels!$E$136 -> 274075 | H13: =F13+G13 -> 274103 | I13: =E13+H13 -> 274103
A14: Nonstandard 5-Digit | B14: DNDC | C14: 0 | D14: 0 | E14: =C14+D14 -> 0 | F14: =[16]Parcels!$E$122 -> 711 | G14: =[16]Parcels!$E$139 -> 110629 | H14: =F14+G14 -> 111340 | I14: =E14+H14 -> 111340
A15: Nonstandard SCF | B15: DSCF | C15: 0 | D15: 0 | E15: =C15+D15 -> 0 | F15: =[16]Parcels!$E$120 -> 4687 | G15: =[16]Parcels!$E$137 -> 448985 | H15: =F15+G15 -> 453672 | I15: =E15+H15 -> 453672
A16: Nonstandard 5-Digit | B16: DSCF | C16: 0 | D16: 0 | E16: =C16+D16 -> 0 | F16: =[16]Parcels!$E$123 -> 738 | G16: =[16]Parcels!$E$140 -> 111046 | H16: =F16+G16 -> 111784 | I16: =E16+H16 -> 111784
A17: Nonstandard 5-Digit | B17: DDU | C17: 0 | D17: 0 | E17: =C17+D17 -> 0 | F17: =[16]Parcels!$E$124 -> 1650 | G17: =[16]Parcels!$E$141 -> 1227 | H17: =F17+G17 -> 2877 | I17: =E17+H17 -> 2877
C18: =SUM(C9:C17) -> 0 | D18: =SUM(D9:D17) -> 0 | E18: =SUM(E9:E17) -> 0 | F18: =SUM(F9:F17) -> 274866 | G18: =SUM(G9:G17) -> 3015374 | H18: =SUM(H9:H17) -> 3290240 | I18: =SUM(I9:I17) -> 3290240
A20: Machinable MNDC | B20: None | C20: 0 | D20: 0 | E20: =C20+D20 -> 0 | F20: 0 | G20: =[16]Parcels!$E$100 -> 670396 | H20: =F20+G20 -> 670396 | I20: =E20+H20 -> 670396
A21: Machinable NDC | B21: None | C21: 0 | D21: 0 | E21: =C21+D21 -> 0 | F21: 0 | G21: =[16]Parcels!$E$102 -> 400984 | H21: =F21+G21 -> 400984 | I21: =E21+H21 -> 400984
A22: Machinable NDC | B22: DNDC | C22: 0 | D22: 0 | E22: =C22+D22 -> 0 | F22: 0 | G22: =[16]Parcels!$E$103 -> 1729284 | H22: =F22+G22 -> 1729284 | I22: =E22+H22 -> 1729284
A23: Machinable 5-Digit | B23: DNDC | C23: 0 | D23: 0 | E23: =C23+D23 -> 0 | F23: 0 | G23: =[16]Parcels!$E$105 -> 6159 | H23: =F23+G23 -> 6159 | I23: =E23+H23 -> 6159
A24: Machinable 5-Digit | B24: DSCF | C24: 0 | D24: 0 | E24: =C24+D24 -> 0 | F24: 0 | G24: =[16]Parcels!$E$106 -> 32567 | H24: =F24+G24 -> 32567 | I24: =E24+H24 -> 32567
A25: Machinable 5-Digit | B25: DDU | C25: 0 | D25: 0 | E25: =C25+D25 -> 0 | F25: 0 | G25: =[16]Parcels!$E$107 -> 5446 | H25: =F25+G25 -> 5446 | I25: =E25+H25 -> 5446
C26: =SUM(C20:C25) -> 0 | D26: =SUM(D20:D25) -> 0 | E26: =SUM(E20:E25) -> 0 | F26: =SUM(F20:F25) -> 0 | G26: =SUM(G20:G25) -> 2844836 | H26: =SUM(H20:H25) -> 2844836 | I26: =SUM(I20:I25) -> 2844836
A28: Total Parcels | C28: =C26+C18 -> 0 | D28: =D26+D18 -> 0 | E28: =E26+E18 -> 0 | F28: =F26+F18 -> 274866 | G28: =G26+G18 -> 5860210 | H28: =H26+H18 -> 6135076 | I28: =I26+I18 -> 6135076
A30: Marketing MNDC | B30: None | C30: =[16]Parcels!$E$7 -> 451593 | D30: =[16]Parcels!$E$41 -> 1119890 | E30: =C30+D30 -> 1571483 | F30: =[16]Parcels!$E$24 -> 118623 | G30: =[16]Parcels!$E$58 -> 435844 | H30: =F30+G30 -> 554467 | I30: =E30+H30 -> 2125950
A31: Marketing NDC | B31: None | C31: =[16]Parcels!$E$9 -> 92446 | D31: =[16]Parcels!$E$43 -> 642181 | E31: =C31+D31 -> 734627 | F31: =[16]Parcels!$E$26 -> 7295 | G31: =[16]Parcels!$E$60 -> 102817 | H31: =F31+G31 -> 110112 | I31: =E31+H31 -> 844739
A32: Marketing NDC | B32: DNDC | C32: =[16]Parcels!$E$10 -> 72762 | D32: =[16]Parcels!$E$44 -> 46921 | E32: =C32+D32 -> 119683 | F32: =[16]Parcels!$E$27 -> 2145 | G32: =[16]Parcels!$E$61 -> 14825 | H32: =F32+G32 -> 16970 | I32: =E32+H32 -> 136653
A33: Marketing SCF | B33: None | C33: =[16]Parcels!$E$12 -> 0 | D33: =[16]Parcels!$E$46 -> 8726 | E33: =C33+D33 -> 8726 | F33: =[16]Parcels!$E$29 -> 218 | G33: =[16]Parcels!$E$63 -> 7454 | H33: =F33+G33 -> 7672 | I33: =E33+H33 -> 16398
A34: Marketing SCF | B34: DNDC | C34: =[16]Parcels!$E$13 -> 7219 | D34: =[16]Parcels!$E$47 -> 5738 | E34: =C34+D34 -> 12957 | F34: =[16]Parcels!$E$30 -> 0 | G34: =[16]Parcels!$E$64 -> 180 | H34: =F34+G34 -> 180 | I34: =E34+H34 -> 13137
A35: Marketing 5-Digit | B35: DNDC | C35: =[16]Parcels!$E$16 -> 5413 | D35: =[16]Parcels!$E$50 -> 17426 | E35: =C35+D35 -> 22839 | F35: =[16]Parcels!$E$33 -> 5179 | G35: =[16]Parcels!$E$67 -> 2718 | H35: =F35+G35 -> 7897 | I35: =E35+H35 -> 30736
A36: Marketing SCF | B36: DSCF | C36: =[16]Parcels!$E$14 -> 43751 | D36: =[16]Parcels!$E$48 -> 63030 | E36: =C36+D36 -> 106781 | F36: =[16]Parcels!$E$31 -> 7190 | G36: =[16]Parcels!$E$65 -> 12259 | H36: =F36+G36 -> 19449 | I36: =E36+H36 -> 126230
A37: Marketing 5-Digit | B37: DSCF | C37: =[16]Parcels!$E$17 -> 1363639 | D37: =[16]Parcels!$E$51 -> 603421 | E37: =C37+D37 -> 1967060 | F37: =[16]Parcels!$E$34 -> 5859 | G37: =[16]Parcels!$E$68 -> 9757 | H37: =F37+G37 -> 15616 | I37: =E37+H37 -> 1982676
A38: Marketing 5-Digit | B38: DDU | C38: =[16]Parcels!$E$18 -> 193234 | D38: =[16]Parcels!$E$52 -> 92232 | E38: =C38+D38 -> 285466 | F38: =[16]Parcels!$E$35 -> 1116 | G38: =[16]Parcels!$E$69 -> 7860 | H38: =F38+G38 -> 8976 | I38: =E38+H38 -> 294442
A39: Total Mktg Parcels | C39: =SUM(C30:C38) -> 2230057 | D39: =SUM(D30:D38) -> 2599565 | E39: =SUM(E30:E38) -> 4829622 | F39: =SUM(F30:F38) -> 147625 | G39: =SUM(G30:G38) -> 593714 | H39: =SUM(H30:H38) -> 741339 | I39: =SUM(I30:I38) -> 5570961
A42: Grand Total | C42: =C28+C39 -> 2230057 | D42: =D28+D39 -> 2599565 | E42: =E28+E39 -> 4829622 | F42: =F28+F39 -> 422491 | G42: =G28+G39 -> 6453924 | H42: =H28+H39 -> 6876415 | I42: =I28+I39 -> 11706037
C44: [8] | D44: [9] | E44: [10]
B46: Mktg > 6 Oz Percentage | C46: =[17]MarketingMail2025!$J$77 -> 0.56272847
B47: Irregular Rolls Percentage | D47: ='[18]Miscellaneous Data'!$B$3 -> 0.10466499
B48: Marketing Mail Parcel Pounds (000s) | E48: ='[19]Adjusted RPW Rpt'!$I$32 -> 4941.206
A51: Sources:
A52: [1]: USPS-FY25-4 (The Irregular MNDC volume includes Standard Mail paid at First-Class Mail rates)
...

Sheet Productivity Data
A1: USPS MARKETING MAIL PARCEL PRODUCTIVITY ESTIMATES
C4: [1] | D4: [2] | E4: [3] | F4: [4] | G4: [5] | H4: [6] | I4: [7]
H6: Volume
A7: Operation | B7: Facility | C7: MODS | D7: eFlash | E7: Field Study | F7: Overhead | G7: Adjusted | H7: Variability | I7: Marginal
A8: Description | B8: Type | C8: Productivity | D8: Productivity | E8: Productivity | F8: Factor | G8: Productivity | H8: Factor | I8: Productivity
A10: APPS incoming primary sort | B10: P&DC/F | C10: ='[20]FY25 Table'!$I$62 -> 236.38446 | D10: ="---" -> --- | E10: ="---" -> --- | F10: ="---" -> --- | G10: ="---" -> --- | H10: ='Cost Pool Data'!$I$12 -> 0.96403554 | I10: =C10/H10 -> 245.20306
A11: APBS / LIPS incoming primary sort | B11: P&DC/F | C11: =('[20]FY25 Table'!$F$59+'[20]FY25 Table'!$F$60)/('[20]FY25 Table'!$H$59+'[20]FY25 Table'!$H$60) -> 183.94301 | D11: ="---" -> --- | E11: ="---" -> --- | F11: ="---" -> --- | G11: ="---" -> --- | H11: ='Cost Pool Data'!$I$12 -> 0.96403554 | I11: =C11/H11 -> 190.80521
A12: Outgoing Tray Sort | B12: P&DC/F | C12: ='[20]FY25 Table'!$I$11 -> 85.837148 | D12: ="---" -> --- | E12: ="---" -> --- | F12: ="---" -> --- | G12: ="---" -> --- | H12: ='Cost Pool Data'!$I$20 -> 0.94974595 | I12: =C12/H12 -> 90.379062
A13: Incoming Tray Sort | B13: P&DC/F | C13: ='[20]FY25 Table'!$I$12 -> 60.943313 | D13: ="---" -> --- | E13: ="---" -> --- | F13: ="---" -> --- | G13: ="---" -> --- | H13: ='Cost Pool Data'!$I$20 -> 0.94974595 | I13: =C13/H13 -> 64.168016
A14: Sack Manual Sort | B14: P&DC/F | C14: ='[20]FY25 Table'!$I$57 -> 46.663259 | D14: ="---" -> --- | E14: ="---" -> --- | F14: ="---" -> --- | G14: ="---" -> --- | H14: ='Cost Pool Data'!$I$30 -> 0.9460562 | I14: =C14/H14 -> 49.323982
A15: NMO Manual Sort | B15: P&DC/F | C15: ='[20]FY25 Table'!$I$57 -> 46.663259 | D15: ="---" -> --- | E15: ="---" -> --- | F15: ="---" -> --- | G15: ="---" -> --- | H15: ='Cost Pool Data'!$I$16 -> 0.97225878 | I15: =C15/H15 -> 47.99469
A16: IPP Manual Sort | B16: P&DC/F | C16: ='[20]FY25 Table'!$I$57 -> 46.663259 | D16: ="---" -> --- | E16: ="---" -> --- | F16: ="---" -> --- | G16: ="---" -> --- | H16: ='Cost Pool Data'!$I$16 -> 0.97225878 | I16: =C16/H16 -> 47.99469
A17: Primary Parcel Sorting Machine (PPSM) | B17: NDC | C17: ='[21]Table FY25'!$I$8 -> 392.67992 | D17: ="---" -> --- | E17: ="---" -> --- | F17: ="---" -> --- | G17: ="---" -> --- | H17: ='Cost Pool Data'!$I$44 -> 0.9584975 | I17: =C17/H17 -> 409.68278
A18: Secondary Parcel Sorting Machine (SPSM) | B18: NDC | C18: ='[21]Table FY25'!$I$9 -> 317.61234 | D18: ="---" -> --- | E18: ="---" -> --- | F18: ="---" -> --- | G18: ="---" -> --- | H18: ='Cost Pool Data'!$I$44 -> 0.9584975 | I18: =C18/H18 -> 331.3648
A19: Sack Sorting Machine (SSM) | B19: NDC | C19: ='[21]Table FY25'!$I$10 -> 2848.2562 | D19: ="---" -> --- | E19: ="---" -> --- | F19: ="---" -> --- | G19: ="---" -> --- | H19: ='Cost Pool Data'!$I$46 -> 0.928342 | I19: =C19/H19 -> 3068.1109
A20: NMO Manual Sort | B20: NDC | C20: ='[21]Table FY25'!$I$11 -> 48.365822 | D20: ="---" -> --- | E20: ="---" -> --- | F20: ="---" -> --- | G20: ="---" -> --- | H20: ='Cost Pool Data'!$I$41 -> 0.91586806 | I20: =C20/H20 -> 52.808722
A21: IPP manual sort | B21: NDC | C21: ='[21]Table FY25'!$I$12 -> 368.91057 | D21: ="---" -> --- | E21: ="---" -> --- | F21: ="---" -> --- | G21: ="---" -> --- | H21: ='Cost Pool Data'!$I$41 -> 0.91586806 | I21: =C21/H21 -> 402.79881
A22: Incoming Secondary Parcel Sort | B22: DU | C22: ="---" -> --- | D22: ='[22]FY25 F4 Manual Productivity'!$D$6 -> 295.82991 | E22: ="---" -> --- | F22: ="---" -> --- | G22: ="---" -> --- | H22: ='Cost Pool Data'!$I$57 -> 0.96152246 | I22: =D22/H22 -> 307.66823
A23: Load Rolling Stock | B23: DU | C23: ="---" -> --- | D23: ="---" -> --- | E23: ='[23]Productivity Summary'!$E$7 -> 104.16918 | F23: ='Cost Pool Data'!$J$48 -> 1.6399656 | G23: =E23/F23 -> 63.519123 | H23: ='Cost Pool Data'!$I$48 -> 0.92642031 | I23: =G23/H23 -> 68.564044
A24: Load Pallet / Pallet Box | B24: DU | C24: ="---" -> --- | D24: ="---" -> --- | E24: ='[23]Productivity Summary'!$E$8 -> 65.538639 | F24: ='Cost Pool Data'!$J$48 -> 1.6399656 | G24: =E24/F24 -> 39.963423 | H24: ='Cost Pool Data'!$I$48 -> 0.92642031 | I24: =G24/H24 -> 43.137464
A25: Unload Rolling Stock | B25: DU | C25: ="---" -> --- | D25: ="---" -> --- | E25: ='[23]Productivity Summary'!$E$9 -> 91.663152 | F25: ='Cost Pool Data'!$J$48 -> 1.6399656 | G25: =E25/F25 -> 55.893338 | H25: ='Cost Pool Data'!$I$48 -> 0.92642031 | I25: =G25/H25 -> 60.332591
A26: Unload Pallet / Pallet Box | B26: DU | C26: ="---" -> --- | D26: ="---" -> --- | E26: ='[23]Productivity Summary'!$E$10 -> 73.807993 | F26: ='Cost Pool Data'!$J$48 -> 1.6399656 | G26: =E26/F26 -> 45.005818 | H26: ='Cost Pool Data'!$I$48 -> 0.92642031 | I26: =G26/H26 -> 48.580344
A27: Unload Rolling Stock | B27: P&DC/F | C27: ="---" -> --- | D27: ="---" -> --- | E27: ='[23]Productivity Summary'!$E$12 -> 108.68527 | F27: ='Cost Pool Data'!$J$27 -> 1.4478255 | G27: =E27/F27 -> 75.067934 | H27: ='Cost Pool Data'!$I$27 -> 0.91687625 | I27: =G27/H27 -> 81.873572
A28: Unload Pallet / Pallet Box | B28: P&DC/F | C28: ="---" -> --- | D28: ="---" -> --- | E28: ='[23]Productivity Summary'!$E$13 -> 77.202049 | F28: ='Cost Pool Data'!$J$27 -> 1.4478255 | G28: =E28/F28 -> 53.322759 | H28: ='Cost Pool Data'!$I$27 -> 0.91687625 | I28: =G28/H28 -> 58.156985
A29: Crossdock Rolling Stock | B29: P&DC/F | C29: ="---" -> --- | D29: ="---" -> --- | E29: ='[23]Productivity Summary'!$E$14 -> 67.388557 | F29: ='Cost Pool Data'!$J$27 -> 1.4478255 | G29: =E29/F29 -> 46.544668 | H29: ='Cost Pool Data'!$I$27 -> 0.91687625 | I29: =G29/H29 -> 50.764395
A30: Crossdock Pallet / Pallet box | B30: P&DC/F | C30: ="---" -> --- | D30: ="---" -> --- | E30: ='[23]Productivity Summary'!$E$15 -> 52.96533 | F30: ='Cost Pool Data'!$J$27 -> 1.4478255 | G30: =E30/F30 -> 36.582676 | H30: ='Cost Pool Data'!$I$27 -> 0.91687625 | I30: =G30/H30 -> 39.899251
A31: Load Rolling Stock | B31: P&DC/F | C31: ="---" -> --- | D31: ="---" -> --- | E31: ='[23]Productivity Summary'!$E$16 -> 120.89542 | F31: ='Cost Pool Data'!$J$27 -> 1.4478255 | G31: =E31/F31 -> 83.501376 | H31: ='Cost Pool Data'!$I$27 -> 0.91687625 | I31: =G31/H31 -> 91.071588
A32: Load Pallet / Pallet Box | B32: P&DC/F | C32: ="---" -> --- | D32: ="---" -> --- | E32: ='[23]Productivity Summary'!$E$17 -> 81.943084 | F32: ='Cost Pool Data'!$J$27 -> 1.4478255 | G32: =E32/F32 -> 56.597349 | H32: ='Cost Pool Data'!$I$27 -> 0.91687625 | I32: =G32/H32 -> 61.728449
A33: Unload Rolling Stock | B33: ASF | C33: ="---" -> --- | D33: ="---" -> --- | E33: ='[23]Productivity Summary'!$E$18 -> 99.080107 | F33: ='Cost Pool Data'!$J$27 -> 1.4478255 | G33: =E33/F33 -> 68.433736 | H33: ='Cost Pool Data'!$I$27 -> 0.91687625 | I33: =G33/H33 -> 74.63792
A34: Unload Pallet / Pallet Box | B34: ASF | C34: ="---" -> --- | D34: ="---" -> --- | E34: ='[23]Productivity Summary'!$E$19 -> 78.22115 | F34: ='Cost Pool Data'!$J$27 -> 1.4478255 | G34: =E34/F34 -> 54.026643 | H34: ='Cost Pool Data'!$I$27 -> 0.91687625 | I34: =G34/H34 -> 58.924683
A35: Load Rolling Stock | B35: ASF | C35: ="---" -> --- | D35: ="---" -> --- | E35: ='[23]Productivity Summary'!$E$20 -> 108.93754 | F35: ='Cost Pool Data'!$J$27 -> 1.4478255 | G35: =E35/F35 -> 75.242174 | H35: ='Cost Pool Data'!$I$27 -> 0.91687625 | I35: =G35/H35 -> 82.063609
A36: Load Pallet / Pallet Box | B36: ASF | C36: ="---" -> --- | D36: ="---" -> --- | E36: ='[23]Productivity Summary'!$E$21 -> 76.602997 | F36: ='Cost Pool Data'!$J$27 -> 1.4478255 | G36: =E36/F36 -> 52.908999 | H36: ='Cost Pool Data'!$I$27 -> 0.91687625 | I36: =G36/H36 -> 57.705714
A37: Unload Rolling Stock | B37: NDC | C37: ="---" -> --- | D37: ="---" -> --- | E37: ='[23]Productivity Summary'!$E$22 -> 69.89497 | F37: ='Cost Pool Data'!$J$43 -> 1.4041376 | G37: =E37/F37 -> 49.777864 | H37: ='Cost Pool Data'!$I$43 -> 0.88894222 | I37: =G37/H37 -> 55.996737
A38: Unload Pallet / Pallet Box | B38: NDC | C38: ="---" -> --- | D38: ="---" -> --- | E38: ='[23]Productivity Summary'!$E$23 -> 58.010029 | F38: ='Cost Pool Data'!$J$43 -> 1.4041376 | G38: =E38/F38 -> 41.313636 | H38: ='Cost Pool Data'!$I$43 -> 0.88894222 | I38: =G38/H38 -> 46.475052
A39: Unload Postal Pak | B39: NDC | C39: ="---" -> --- | D39: ="---" -> --- | E39: ='[23]Productivity Summary'!$E$24 -> 66.337249 | F39: ='Cost Pool Data'!$J$43 -> 1.4041376 | G39: =E39/F39 -> 47.244123 | H39: ='Cost Pool Data'!$I$43 -> 0.88894222 | I39: =G39/H39 -> 53.14645
A40: Induct Rolling Stock | B40: NDC | C40: ="---" -> --- | D40: ="---" -> --- | E40: ='[23]Productivity Summary'!$E$25 -> 32.62217 | F40: ='Cost Pool Data'!$J$42 -> 1.5517735 | G40: =E40/F40 -> 21.022507 | H40: ='Cost Pool Data'!$I$42 -> 0.91140966 | I40: =G40/H40 -> 23.065925
A41: Induct Pallet / Pallet Box | B41: NDC | C41: ="---" -> --- | D41: ="---" -> --- | E41: ='[23]Productivity Summary'!$E$26 -> 23.313312 | F41: ='Cost Pool Data'!$J$42 -> 1.5517735 | G41: =E41/F41 -> 15.023656 | H41: ='Cost Pool Data'!$I$42 -> 0.91140966 | I41: =G41/H41 -> 16.483977
A42: Induct Postal Pak | B42: NDC | C42: ="---" -> --- | D42: ="---" -> --- | E42: ='[23]Productivity Summary'!$E$27 -> 23.543443 | F42: ='Cost Pool Data'!$J$42 -> 1.5517735 | G42: =E42/F42 -> 15.171958 | H42: ='Cost Pool Data'!$I$42 -> 0.91140966 | I42: =G42/H42 -> 16.646694
A43: Sack Shake Out | B43: NDC | C43: ="---" -> --- | D43: ="---" -> --- | E43: ='[23]Productivity Summary'!$E$28 -> 207.56223 | F43: ='Cost Pool Data'!$J$42 -> 1.5517735 | G43: =E43/F43 -> 133.75807 | H43: ='Cost Pool Data'!$I$42 -> 0.91140966 | I43: =G43/H43 -> 146.75955
A44: Load Rolling Stock | B44: NDC | C44: ="---" -> --- | D44: ="---" -> --- | E44: ='[23]Productivity Summary'!$E$29 -> 88.133733 | F44: ='Cost Pool Data'!$J$43 -> 1.4041376 | G44: =E44/F44 -> 62.767163 | H44: ='Cost Pool Data'!$I$43 -> 0.88894222 | I44: =G44/H44 -> 70.608822
...

Sheet Wage Data
A1: USPS MARKETING MAIL PARCEL WAGE DATA
B3: [1] | C3: [2]
A5: Description | B5: Value | C5: Value
A7: Other Mail Processing Wage Rate | B7: ='[24]Disaggregated wage rates'!$C$8 -> 50.107175
A9: Premium Pay Factor | B9: ='[24]Premium Pay Fctrs'!$D$22 -> 0.98098316
A11: Adjusted Mail Processing Wage Rate | C11: =B7*B9 -> 49.154295
A14: Sources:
A15: [1]: USPS-FY25-7, Part 8 (wage rate) and Part 5 (premium Pay factor)
A16: [2]: Other Mail Processing Wage Rate * Premium Pay Factor

Sheet Mailer Arrival Profile
A1: USPS MARKETING MAIL PARCEL MAILER CONTAINER ARRIVAL PROFILE
C4: [1] | D4: [2] | E4: [3] | F4: [4] | G4: [5] | I4: [6]
A5: Standard Parcels | B5: Entry | C5: Pallet Box | D5: Pallet (Pieces) | E5: Pallet (Sacks) | F5: Sack | G5: Total | I5: Pieces Per
A6: Price Category | B6: Discount | C6: Percent | D6: Percent | E6: Percent | F6: Percent | G6: Percent | I6: Sack
A8: Machinable MNDC | B8: None | C8: ='[18]Arrival Profile Summary'!$C$36 -> 0.026058632 | D8: ='[18]Arrival Profile Summary'!$D$36 -> 0.97394137 | E8: ='[18]Arrival Profile Summary'!$E$36 -> 0 | F8: ='[18]Arrival Profile Summary'!$F$36 -> 0 | G8: =SUM(C8:F8) -> 1 | I8: ="---" -> ---
A9: Machinable NDC | B9: None | C9: ='[18]Arrival Profile Summary'!$C$37 -> 1 | D9: ='[18]Arrival Profile Summary'!$D$37 -> 0 | E9: ='[18]Arrival Profile Summary'!$E$37 -> 0 | F9: ='[18]Arrival Profile Summary'!$F$37 -> 0 | G9: =SUM(C9:F9) -> 1 | I9: ="---" -> ---
A10: Machinable NDC | B10: DNDC | C10: ='[18]Arrival Profile Summary'!$C$38 -> 0.49310796 | D10: ='[18]Arrival Profile Summary'!$D$38 -> 0.46621265 | E10: ='[18]Arrival Profile Summary'!$E$38 -> 0.012311105 | F10: ='[18]Arrival Profile Summary'!$F$38 -> 0.028368278 | G10: =SUM(C10:F10) -> 1 | I10: ='[18]Sack Pieces Summary'!$C$10 -> 17.04918
A11: Machinable 5-Digit | B11: DNDC | C11: ='[18]Arrival Profile Summary'!$C$39 -> 0 | D11: ='[18]Arrival Profile Summary'!$D$39 -> 0.045113611 | E11: ='[18]Arrival Profile Summary'!$E$39 -> 0.95488639 | F11: ='[18]Arrival Profile Summary'!$F$39 -> 0 | G11: =SUM(C11:F11) -> 1 | I11: ='[18]Sack Pieces Summary'!$C$11 -> 33.104839
A12: Machinable 5-Digit | B12: DSCF | C12: ='[18]Arrival Profile Summary'!$C$40 -> 0.094705277 | D12: ='[18]Arrival Profile Summary'!$D$40 -> 0.03893837 | E12: ='[18]Arrival Profile Summary'!$E$40 -> 0.83717495 | F12: ='[18]Arrival Profile Summary'!$F$40 -> 0.029181399 | G12: =SUM(C12:F12) -> 1 | I12: ='[18]Sack Pieces Summary'!$C$12 -> 33.104839
A13: Machinable 5-Digit | B13: DDU | C13: ='[18]Arrival Profile Summary'!$C$41 -> 0 | D13: ='[18]Arrival Profile Summary'!$D$41 -> 0.5384801 | E13: ='[18]Arrival Profile Summary'!$E$41 -> 0 | F13: ='[18]Arrival Profile Summary'!$F$41 -> 0.4615199 | G13: =SUM(C13:F13) -> 1 | I13: ='[18]Sack Pieces Summary'!$C$13 -> 22.77381
A15: Nonstandard MNDC | B15: None | C15: ='[18]Arrival Profile Summary'!$C$43 -> 0.39277926 | D15: ='[18]Arrival Profile Summary'!$D$43 -> 0.55270172 | E15: ='[18]Arrival Profile Summary'!$E$43 -> 0 | F15: ='[18]Arrival Profile Summary'!$F$43 -> 0.054519021 | G15: =SUM(C15:F15) -> 1 | I15: ='[18]Sack Pieces Summary'!$C$15 -> 45
A16: Nonstandard NDC | B16: None | C16: ='[18]Arrival Profile Summary'!$C$44 -> 0.16173007 | D16: ='[18]Arrival Profile Summary'!$D$44 -> 0.68745985 | E16: ='[18]Arrival Profile Summary'!$E$44 -> 0.096709728 | F16: ='[18]Arrival Profile Summary'!$F$44 -> 0.05410035 | G16: =SUM(C16:F16) -> 1 | I16: ='[18]Sack Pieces Summary'!$C$16 -> 50.533333
A17: Nonstandard NDC | B17: DNDC | C17: ='[18]Arrival Profile Summary'!$C$45 -> 0.16173007 | D17: ='[18]Arrival Profile Summary'!$D$45 -> 0.68745985 | E17: ='[18]Arrival Profile Summary'!$E$45 -> 0.096709728 | F17: ='[18]Arrival Profile Summary'!$F$45 -> 0.05410035 | G17: =SUM(C17:F17) -> 1 | I17: ='[18]Sack Pieces Summary'!$C$17 -> 50.533333
A18: Nonstandard SCF | B18: DNDC | C18: ='[18]Arrival Profile Summary'!$C$46 -> 0 | D18: ='[18]Arrival Profile Summary'!$D$46 -> 0 | E18: ='[18]Arrival Profile Summary'!$E$46 -> 1 | F18: ='[18]Arrival Profile Summary'!$F$46 -> 0 | G18: =SUM(C18:F18) -> 1 | I18: ='[18]Sack Pieces Summary'!$C$18 -> 78.272727
A19: Nonstandard 5-Digit | B19: DNDC | C19: ='[18]Arrival Profile Summary'!$C$47 -> 0 | D19: ='[18]Arrival Profile Summary'!$D$47 -> 0 | E19: ='[18]Arrival Profile Summary'!$E$47 -> 0.77812317 | F19: ='[18]Arrival Profile Summary'!$F$47 -> 0.22187683 | G19: =SUM(C19:F19) -> 1 | I19: ='[18]Sack Pieces Summary'!$C$19 -> 36.926829
A20: Nonstandard SCF | B20: DSCF | C20: ='[18]Arrival Profile Summary'!$C$48 -> 0.039651767 | D20: ='[18]Arrival Profile Summary'!$D$48 -> 0.047479699 | E20: ='[18]Arrival Profile Summary'!$E$48 -> 0 | F20: ='[18]Arrival Profile Summary'!$F$48 -> 0.91286853 | G20: =SUM(C20:F20) -> 1 | I20: ='[18]Sack Pieces Summary'!$C$20 -> 89.82684
A21: Nonstandard 5-Digit | B21: DSCF | C21: ='[18]Arrival Profile Summary'!$C$49 -> 0 | D21: ='[18]Arrival Profile Summary'!$D$49 -> 0 | E21: ='[18]Arrival Profile Summary'!$E$49 -> 0.77812317 | F21: ='[18]Arrival Profile Summary'!$F$49 -> 0.22187683 | G21: =SUM(C21:F21) -> 1 | I21: ='[18]Sack Pieces Summary'!$C$21 -> 66.275974
A22: Nonstandard 5-Digit | B22: DDU | C22: ='[18]Arrival Profile Summary'!$C$50 -> 0 | D22: ='[18]Arrival Profile Summary'!$D$50 -> 0 | E22: ='[18]Arrival Profile Summary'!$E$50 -> 0 | F22: ='[18]Arrival Profile Summary'!$F$50 -> 1 | G22: =SUM(C22:F22) -> 1 | I22: ='[18]Sack Pieces Summary'!$C$22 -> 36.926829
A24: Marketing MNDC | B24: None | C24: ='[18]Arrival Profile Summary'!$C$52 -> 0.024763879 | D24: ='[18]Arrival Profile Summary'!$D$52 -> 0.81674729 | E24: ='[18]Arrival Profile Summary'!$E$52 -> 0.11011288 | F24: ='[18]Arrival Profile Summary'!$F$52 -> 0.04837595 | G24: =SUM(C24:F24) -> 1 | I24: ='[18]Sack Pieces Summary'!$C$24 -> 45
A25: Marketing NDC | B25: None | C25: ='[18]Arrival Profile Summary'!$C$53 -> 0.10645613 | D25: ='[18]Arrival Profile Summary'!$D$53 -> 0.86712085 | E25: ='[18]Arrival Profile Summary'!$E$53 -> 0 | F25: ='[18]Arrival Profile Summary'!$F$53 -> 0.026423023 | G25: =SUM(C25:F25) -> 1 | I25: ='[18]Sack Pieces Summary'!$C$25 -> 50.533333
A26: Marketing NDC | B26: DNDC | C26: ='[18]Arrival Profile Summary'!$C$54 -> 0.011095126 | D26: ='[18]Arrival Profile Summary'!$D$54 -> 0.86038451 | E26: ='[18]Arrival Profile Summary'!$E$54 -> 0.0014822565 | F26: ='[18]Arrival Profile Summary'!$F$54 -> 0.1270381 | G26: =SUM(C26:F26) -> 1 | I26: ='[18]Sack Pieces Summary'!$C$26 -> 50.533333
A27: Marketing SCF | B27: DNDC | C27: ='[18]Arrival Profile Summary'!$C$55 -> 0 | D27: ='[18]Arrival Profile Summary'!$D$55 -> 1 | E27: ='[18]Arrival Profile Summary'!$E$55 -> 0 | F27: ='[18]Arrival Profile Summary'!$F$55 -> 0 | G27: =SUM(C27:F27) -> 1 | I27: ="---" -> ---
