Workbook
Name factor: #REF!
Name wfact: #REF!

Sheet Summary
A1: USPS MARKETING MAIL DESTINATION ENTRY
A2: COST AVOIDANCE SUMMARY
D5: [1] | E5: [2] | F5: [3] | G5: [4]
D6: Letter | E6: Flat | F6: Parcel | G6: Total
A7: Cost Element | D7: Cost Per Pound | E7: Cost Per Pound | F7: Cost Per Pound | G7: Cost Per Pound
A10: Transportation
B11: DDU | D11: ='Results Trans'!$C$39 -> 0.57444248 | E11: ='Results Trans'!$E$39 -> 0.50166223 | F11: ='Results Trans'!$G$39 -> 0.62960288 | G11: =D11*('CS Data By Shape'!$B$7/'CS Data By Shape'!$E$7)+E11*('CS Data By Shape'!$C$7/'CS Data By Shape'!$E$7)+F11*('CS Data By Shape'!$D$7/'CS Data By Shape'!$E$7) -> 0.53868426
B12: DSCF | D12: ='Results Trans'!$C$40 -> 0.50461148 | E12: ='Results Trans'!$E$40 -> 0.42055949 | F12: ='Results Trans'!$G$40 -> 0.51091495 | G12: =D12*('CS Data By Shape'!$B$7/'CS Data By Shape'!$E$7)+E12*('CS Data By Shape'!$C$7/'CS Data By Shape'!$E$7)+F12*('CS Data By Shape'!$D$7/'CS Data By Shape'!$E$7) -> 0.46324428
B13: DNDC | D13: ='Results Trans'!$C$41 -> 0.50359296 | E13: ='Results Trans'!$E$41 -> 0.42012477 | F13: ='Results Trans'!$G$41 -> 0.51164627 | G13: =D13*('CS Data By Shape'!$B$7/'CS Data By Shape'!$E$7)+E13*('CS Data By Shape'!$C$7/'CS Data By Shape'!$E$7)+F13*('CS Data By Shape'!$D$7/'CS Data By Shape'!$E$7) -> 0.4625153
A16: Non-Transportation
B17: DDU | D17: ='Results NonTrans'!$C$39 -> 0.030234896 | E17: ='Results NonTrans'!$E$39 -> 0.013404121 | F17: ='Results NonTrans'!$G$39 -> 0.072668501 | G17: =D17*('CS Data By Shape'!$B$7/'CS Data By Shape'!$E$7)+E17*('CS Data By Shape'!$C$7/'CS Data By Shape'!$E$7)+F17*('CS Data By Shape'!$D$7/'CS Data By Shape'!$E$7) -> 0.022002341
B18: DSCF | D18: ='Results NonTrans'!$C$40 -> 0.019033424 | E18: ='Results NonTrans'!$E$40 -> 0.007419257 | F18: ='Results NonTrans'!$G$40 -> 0.01065229 | G18: =D18*('CS Data By Shape'!$B$7/'CS Data By Shape'!$E$7)+E18*('CS Data By Shape'!$C$7/'CS Data By Shape'!$E$7)+F18*('CS Data By Shape'!$D$7/'CS Data By Shape'!$E$7) -> 0.01330593
B19: DNDC | D19: ='Results NonTrans'!$C$41 -> 0.011113123 | E19: ='Results NonTrans'!$E$41 -> 0.0049799662 | F19: ='Results NonTrans'!$G$41 -> 0.006621564 | G19: =D19*('CS Data By Shape'!$B$7/'CS Data By Shape'!$E$7)+E19*('CS Data By Shape'!$C$7/'CS Data By Shape'!$E$7)+F19*('CS Data By Shape'!$D$7/'CS Data By Shape'!$E$7) -> 0.0080884924
A22: Total
B23: DDU | D23: =D11+D17 -> 0.60467737 | E23: =E11+E17 -> 0.51506635 | F23: =F11+F17 -> 0.70227138 | G23: =G11+G17 -> 0.56068661
B24: DSCF | D24: =D12+D18 -> 0.5236449 | E24: =E12+E18 -> 0.42797875 | F24: =F12+F18 -> 0.52156724 | G24: =G12+G18 -> 0.47655021
B25: DNDC | D25: =D13+D19 -> 0.51470608 | E25: =E13+E19 -> 0.42510473 | F25: =F13+F19 -> 0.51826784 | G25: =G13+G19 -> 0.47060379
D29: [5] | E29: [6] | F29: [7] | G29: [8] | I29: [9] | J29: [10] | K29: [11] | L29: [12]
D30: Letter | E30: Flat | F30: Parcel | G30: Total | I30: Flat | J30: Flat | K30: Parcel | L30: Parcel
A31: Cost Element | D31: Cost Per Piece | E31: Cost Per Piece | F31: Cost Per Piece | G31: Cost Per Piece | I31: Cost Per Piece | J31: Cost Per Piece | K31: Cost Per Piece | L31: Cost Per Piece
I32: <= 4 oz | J32: > 4 oz | K32: <= 3.3 oz | L32: > 3.3 oz
A34: Transportation
B35: DDU | D35: =D11*('CS Data By Shape'!$B$7/'CS Data By Shape'!$B$6) -> 0.026460205 | E35: =E11*('CS Data By Shape'!$C$7/'CS Data By Shape'!$C$6) -> 0.080384047 | F35: =F11*('CS Data By Shape'!$D$7/'CS Data By Shape'!$D$6) -> 0.2657601 | G35: =G11*('CS Data By Shape'!$E$7/'CS Data By Shape'!$E$6) -> 0.038282918 | I35: =E11*('CS Data By Shape'!$C$17/'CS Data By Shape'!$C$9) -> 0.056481372 | J35: =E11*('CS Data By Shape'!$C$18/'CS Data By Shape'!$C$10) -> 0.20887159 | K35: =F11*('CS Data By Shape'!$D$19/'CS Data By Shape'!$D$11) -> 0.087536967 | L35: =F11*('CS Data By Shape'!$D$20/'CS Data By Shape'!$D$12) -> 0.31797125
B36: DSCF | D36: =D12*('CS Data By Shape'!$B$7/'CS Data By Shape'!$B$6) -> 0.02324362 | E36: =E12*('CS Data By Shape'!$C$7/'CS Data By Shape'!$C$6) -> 0.067388517 | F36: =F12*('CS Data By Shape'!$D$7/'CS Data By Shape'!$D$6) -> 0.21566103 | G36: =G12*('CS Data By Shape'!$E$7/'CS Data By Shape'!$E$6) -> 0.03292159 | I36: =E12*('CS Data By Shape'!$C$17/'CS Data By Shape'!$C$9) -> 0.04735014 | J36: =E12*('CS Data By Shape'!$C$18/'CS Data By Shape'!$C$10) -> 0.17510374 | K36: =F12*('CS Data By Shape'!$D$19/'CS Data By Shape'!$D$11) -> 0.071035165 | L36: =F12*('CS Data By Shape'!$D$20/'CS Data By Shape'!$D$12) -> 0.25802973
B37: DNDC | D37: =D13*('CS Data By Shape'!$B$7/'CS Data By Shape'!$B$6) -> 0.023196705 | E37: =E13*('CS Data By Shape'!$C$7/'CS Data By Shape'!$C$6) -> 0.067318859 | F37: =F13*('CS Data By Shape'!$D$7/'CS Data By Shape'!$D$6) -> 0.21596973 | G37: =G13*('CS Data By Shape'!$E$7/'CS Data By Shape'!$E$6) -> 0.032869783 | I37: =E13*('CS Data By Shape'!$C$17/'CS Data By Shape'!$C$9) -> 0.047301195 | J37: =E13*('CS Data By Shape'!$C$18/'CS Data By Shape'!$C$10) -> 0.17492273 | K37: =F13*('CS Data By Shape'!$D$19/'CS Data By Shape'!$D$11) -> 0.071136846 | L37: =F13*('CS Data By Shape'!$D$20/'CS Data By Shape'!$D$12) -> 0.25839908
A40: Non-Transportation
B41: DDU | D41: =D17*('CS Data By Shape'!$B$7/'CS Data By Shape'!$B$6) -> 0.0013926921 | E41: =E17*('CS Data By Shape'!$C$7/'CS Data By Shape'!$C$6) -> 0.0021478146 | F41: =F17*('CS Data By Shape'!$D$7/'CS Data By Shape'!$D$6) -> 0.030673919 | G41: =G17*('CS Data By Shape'!$E$7/'CS Data By Shape'!$E$6) -> 0.0015636503 | I41: =E17*('CS Data By Shape'!$C$17/'CS Data By Shape'!$C$9) -> 0.0015091492 | J41: =E17*('CS Data By Shape'!$C$18/'CS Data By Shape'!$C$10) -> 0.0055809266 | K41: =F17*('CS Data By Shape'!$D$19/'CS Data By Shape'!$D$11) -> 0.01010348 | L41: =F17*('CS Data By Shape'!$D$20/'CS Data By Shape'!$D$12) -> 0.036700109
B42: DSCF | D42: =D18*('CS Data By Shape'!$B$7/'CS Data By Shape'!$B$6) -> 0.00087672535 | E42: =E18*('CS Data By Shape'!$C$7/'CS Data By Shape'!$C$6) -> 0.0011888276 | F42: =F18*('CS Data By Shape'!$D$7/'CS Data By Shape'!$D$6) -> 0.0044964115 | G42: =G18*('CS Data By Shape'!$E$7/'CS Data By Shape'!$E$6) -> 0.00094561852 | I42: =E18*('CS Data By Shape'!$C$17/'CS Data By Shape'!$C$9) -> 0.00083532263 | J42: =E18*('CS Data By Shape'!$C$18/'CS Data By Shape'!$C$10) -> 0.0030890745 | K42: =F18*('CS Data By Shape'!$D$19/'CS Data By Shape'!$D$11) -> 0.0014810434 | L42: =F18*('CS Data By Shape'!$D$20/'CS Data By Shape'!$D$12) -> 0.0053797752
B43: DNDC | D43: =D19*('CS Data By Shape'!$B$7/'CS Data By Shape'!$B$6) -> 0.0005118972 | E43: =E19*('CS Data By Shape'!$C$7/'CS Data By Shape'!$C$6) -> 0.00079796686 | F43: =F19*('CS Data By Shape'!$D$7/'CS Data By Shape'!$D$6) -> 0.0027950118 | G43: =G19*('CS Data By Shape'!$E$7/'CS Data By Shape'!$E$6) -> 0.00057482854 | I43: =E19*('CS Data By Shape'!$C$17/'CS Data By Shape'!$C$9) -> 0.00056068666 | J43: =E19*('CS Data By Shape'!$C$18/'CS Data By Shape'!$C$10) -> 0.0020734538 | K43: =F19*('CS Data By Shape'!$D$19/'CS Data By Shape'!$D$11) -> 0.00092063052 | L43: =F19*('CS Data By Shape'!$D$20/'CS Data By Shape'!$D$12) -> 0.003344119
A46: Total
B47: DDU | D47: =D35+D41 -> 0.027852897 | E47: =E35+E41 -> 0.082531862 | F47: =F35+F41 -> 0.29643401 | G47: =G35+G41 -> 0.039846568 | I47: =I35+I41 -> 0.057990521 | J47: =J35+J41 -> 0.21445252 | K47: =K35+K41 -> 0.097640447 | L47: =L35+L41 -> 0.35467136
B48: DSCF | D48: =D36+D42 -> 0.024120346 | E48: =E36+E42 -> 0.068577345 | F48: =F36+F42 -> 0.22015744 | G48: =G36+G42 -> 0.033867209 | I48: =I36+I42 -> 0.048185463 | J48: =J36+J42 -> 0.17819281 | K48: =K36+K42 -> 0.072516209 | L48: =L36+L42 -> 0.26340951
B49: DNDC | D49: =D37+D43 -> 0.023708602 | E49: =E37+E43 -> 0.068116826 | F49: =F37+F43 -> 0.21876474 | G49: =G37+G43 -> 0.033444612 | I49: =I37+I43 -> 0.047861882 | J49: =J37+J43 -> 0.17699619 | K49: =K37+K43 -> 0.072057476 | L49: =L37+L43 -> 0.2617432
A52: Sources:
A53: [1]: Pages 2 (transportation) and 8 (non-transportation)
A54: [2]: Pages 2 (transportation) and 8 (non-transportation)
A55: [3]: Pages 2 (transportation) and 8 (non-transportation)
A56: [4]: Weighted Average of [1], [2], and [3] using weight and volume data from Page 37
A57: [5]: [1] * [ Letter Pounds (Page 37) / Letter Pieces (Page 37) ]
A58: [6]: [2] * [ Flat Pounds (Page 37) / Flat Pieces (Page 37) ]
...

Sheet Results Trans
A1: USPS MARKETING MAIL TRANSPORTATION EQUATION AND RESULTS
A6: Transportation Equation: | D6: (Yorigin * Xorigin) + (YDNDC * XDNDC) + (YDSCF * XDSCF) = ZT | J6: 1/
B8: Yorigin: | C8: Percentage of mail that is dropshipped to non-destination facilities or plantloaded to all facilities
B9: Xorigin: | C9: Cost per pound to the Postal Service of transporting Yorigin to the destination delivery unit
B11: YDNDC: | C11: Percentage of mail that is dropshipped to a destination NDC
B12: XDNDC: | C12: Cost per pound to the Postal Service of transporting YDNDC to the destination delivery unit
B14: YDSCF: | C14: Percentage of mail that is dropshipped to a destination SCF
B15: XDSCF: | C15: Cost per pound to the Postal Service of transporting YDSCF to the destination delivery unit
B17: ZT: | C17: Cost per pound to the Postal Service of transporting all USPS Marketing Mail to the destination delivery unit
A19: Solving the Equation:
C21: Letter | E21: Flat | G21: Parcel
B23: Yorigin: | C23: ='Entry Profile L&F'!$G$8+'Entry Profile L&F'!$G$9+'Entry Profile L&F'!$G$10 -> 0.16020909 | E23: ='Entry Profile L&F'!$I$8+'Entry Profile L&F'!$I$9+'Entry Profile L&F'!$I$10 -> 0.12675166 | G23: ='Entry Profile P'!$G$23+'Entry Profile P'!$G$24+'Entry Profile P'!$G$25 -> 0.4950719 | J23: 2/
B24: Xorigin: | C24: Solve For X | E24: Solve For X | G24: Solve For X | J24: 3/
B26: YDNDC: | C26: ='Entry Profile L&F'!$G$11 -> 0.067539307 | E26: ='Entry Profile L&F'!$I$11 -> 0.050900412 | G26: ='Entry Profile P'!$G$26 -> 0.24782196 | J26: 4/
B27: XDNDC: | C27: ='Flow Trans CPP'!$D$10+('Flow Proportions'!$E$48*'Flow Trans CPP'!$D$11) -> 0.070849521 | E27: ='Flow Trans CPP'!$D$16+('Flow Proportions'!$E$48*'Flow Trans CPP'!$D$17) -> 0.081537466 | G27: ='Flow Trans CPP'!$D$22+('Flow Proportions'!$E$48*'Flow Trans CPP'!$D$23) -> 0.1179566 | J27: 5/
B29: YDSCF: | C29: ='Entry Profile L&F'!$G$12 -> 0.75042884 | E29: ='Entry Profile L&F'!$I$12 -> 0.55529926 | G29: ='Entry Profile P'!$G$27 -> 0.23124214 | J29: 6/
B30: XDSCF: | C30: ='Flow Trans CPP'!$D$11 -> 0.069831 | E30: ='Flow Trans CPP'!$D$17 -> 0.081102739 | G30: ='Flow Trans CPP'!$D$23 -> 0.11868793 | J30: 7/
B32: ZT: | C32: ='Trans CPP'!$C$19 -> 0.14921923 | E32: ='Trans CPP'!$E$19 -> 0.1127731 | G32: ='Trans CPP'!$G$19 -> 0.36837658 | J32: 8/
B34: Xorigin: | C34: =(C32-(C26*C27)-(C29*C30))/C23 -> 0.57444248 | E34: =(E32-(E26*E27)-(E29*E30))/E23 -> 0.50166223 | G34: =(G32-(G26*G27)-(G29*G30))/G23 -> 0.62960288 | J34: 9/
A37: Cost Avoidances:
B39: DDU | C39: =C34 -> 0.57444248 | E39: =E34 -> 0.50166223 | G39: =G34 -> 0.62960288 | J39: 10/
B40: DSCF | C40: =C34-C30 -> 0.50461148 | E40: =E34-E30 -> 0.42055949 | G40: =G34-G30 -> 0.51091495 | J40: 11/
B41: DNDC | C41: =C34-C27 -> 0.50359296 | E41: =E34-E27 -> 0.42012477 | G41: =G34-G27 -> 0.51164627 | J41: 12/
A44: Sources:
A45: 1/: | B45: Docket No. MC95-1, USPS-T-9, page 3
A46: 2/: | B46: Pages 35 and 36
A47: 3/: | B47: This variable is unknown and the equation will be solved to find Xorigin
A48: 4/: | B48: Pages 35 and 36
A49: 5/: | B49: Intra-NDC cost per pound (page 4) + Flow Proportion (page 33) * Intra-SCF cost per pound (page 4)
A50: 6/: | B50: Pages 35 and 36
A51: 7/: | B51: Intra-SCF cost per pound (page 4)
A52: 8/: | B52: Cost per pound for transporting mail to DDU (page 3)
A53: 9/: | B53: ( Row 8 - ( Row 4 * Row 5) - (Row 6 * Row 7) ) / Row 2
A54: 10/: | B54: Row 9
A55: 11/: | B55: Row 9 - Row 7
A56: 12/: | B56: Row 9 - Row 5

Sheet Trans CPP
A1: AVERAGE USPS MARKETING MAIL TRANSPORTATION COST PER POUND
A4: Transportation Costs
C6: Letter | E6: Flat | G6: Parcel
B8: Other | C8: ='Trans Costs'!$I$45 -> 162765.91 | E8: ='Trans Costs'!$L$45 -> 104237.73 | G8: ='Trans Costs'!$O$45 -> 1161.6935 | I8: 1/
B9: Intra-NDC | C9: ='Trans Costs'!$G$45 -> 1998.3001 | E9: ='Trans Costs'!$J$45 -> 1404.3953 | G9: ='Trans Costs'!$M$45 -> 11.551305 | I9: 2/
B10: Intra-SCF | C10: ='Trans Costs'!$H$45 -> 137232.23 | E10: ='Trans Costs'!$K$45 -> 116170.25 | G10: ='Trans Costs'!$N$45 -> 646.97976 | I10: 3/
B11: Total | C11: =SUM(C8:C10) -> 301996.44 | E11: =SUM(E8:E10) -> 221812.37 | G11: =SUM(G8:G10) -> 1820.2246 | I11: 4/
A13: Pieces per Pound
B15: Pieces | C15: ='CS Data By Shape'!$B$6 -> 43936998 | E15: ='CS Data By Shape'!$C$6 -> 12275007 | G15: ='CS Data By Shape'!$D$6 -> 11706.037 | I15: 5/
B16: Pounds | C16: ='CS Data By Shape'!$B$7 -> 2023844 | E16: ='CS Data By Shape'!$C$7 -> 1966890.7 | G16: ='CS Data By Shape'!$D$7 -> 4941.206 | I16: 6/
B17: Pieces Per Pound | C17: =C15/C16 -> 21.709676 | E17: =E15/E16 -> 6.2408183 | G17: =G15/G16 -> 2.3690648 | I17: 7/
A19: Cost per Pound | C19: =C11/C16 -> 0.14921923 | E19: =E11/E16 -> 0.1127731 | G19: =G11/G16 -> 0.36837658 | I19: 8/
A21: Sources:
A22: 1/: | B22: Page 6
A23: 2/: | B23: Page 6
A24: 3/: | B24: Page 6
A25: 4/: | B25: Row 1 + Row 2 + Row 3
A26: 5/: | B26: Page 37
A27: 6/: | B27: Page 37
A28: 7/: | B28: Row 5 / Row 6
A29: 8/: | B29: Row 4 / Row 6

Sheet Flow Trans CPP
A1: USPS MARKETING MAIL COST PER POUND BY TRANSPORTATION CATEGORY
B5: [1] | C5: [2] | D5: [3]
A7: Letter
A8: Inter-Facility Transportation Category | B8: Total Pounds (000) | C8: Total Costs (000) | D8: Cost/Pound
A9: Other | B9: ='Flow Pounds'!$C$9 -> 223839.3 | C9: ='Trans Costs'!$I$45 -> 162765.91 | D9: =C9/B9 -> 0.72715518
A10: Intra-NDC | B10: ='Flow Pounds'!$C$8 -> 622287.97 | C10: ='Trans Costs'!$G$45 -> 1998.3001 | D10: =C10/B10 -> 0.0032112144
A11: Intra-SCF | B11: ='Flow Pounds'!$C$7 -> 1965205 | C11: ='Trans Costs'!$H$45 -> 137232.23 | D11: =C11/B11 -> 0.069831
A13: Flat
A14: Inter-Facility Transportation Category | B14: Total Pounds (000) | C14: Total Costs (000) | D14: Cost/Pound
A15: Other | B15: ='Flow Pounds'!$C$14 -> 172216.95 | C15: ='Trans Costs'!$L$45 -> 104237.73 | D15: =C15/B15 -> 0.60526984
A16: Intra-NDC | B16: ='Flow Pounds'!$C$13 -> 471059.81 | C16: ='Trans Costs'!$J$45 -> 1404.3953 | D16: =C16/B16 -> 0.0029813523
A17: Intra-SCF | B17: ='Flow Pounds'!$C$12 -> 1432383.7 | C17: ='Trans Costs'!$K$45 -> 116170.25 | D17: =C17/B17 -> 0.081102739
A19: Parcel
A20: Inter-Facility Transportation Category | B20: Total Pounds (000) | C20: Total Costs (000) | D20: Cost/Pound
A21: Other | B21: ='Flow Pounds'!$C$19 -> 1715.2475 | C21: ='Trans Costs'!$O$45 -> 1161.6935 | D21: =C21/B21 -> 0.67727457
A22: Intra-NDC | B22: ='Flow Pounds'!$C$18 -> 3856.2554 | C22: ='Trans Costs'!$M$45 -> 11.551305 | D22: =C22/B22 -> 0.0029954719
A23: Intra-SCF | B23: ='Flow Pounds'!$C$17 -> 5451.0998 | C23: ='Trans Costs'!$N$45 -> 646.97976 | D23: =C23/B23 -> 0.11868793
A26: Sources:
A27: [1]: Page 5
A28: [2]: Page 6
A29: [3]: Column 2 / Column 1

Sheet Flow Pounds
A1: SUMMARY OF TOTAL USPS MARKETING MAIL POUNDS BY TRANSPORTATION CATEGORIES
A4: Total Pounds per Transportation Category
B6: Inter-Facility Transportation Category | C6: Total Pounds in Each Category
A7: Letter | B7: Intra-SCF | C7: =SUM('Handling Costs'!$J$12:$J$14,'Handling Costs'!$J$24) -> 1965205 | D7: 1/
B8: Intra-NDC | C8: =SUM('Handling Costs'!$J$15:$J$18,'Handling Costs'!$J$22:$J$23) -> 622287.97 | D8: 2/
B9: Other | C9: =SUM('Handling Costs'!$J$19:$J$21) -> 223839.3 | D9: 3/
B10: Total | C10: =SUM(C7:C9) -> 2811332.3 | D10: 4/
A12: Flat | B12: Intra-SCF | C12: =SUM('Handling Costs'!$J$29:$J$31,'Handling Costs'!$J$41) -> 1432383.7 | D12: 1/
B13: Intra-NDC | C13: =SUM('Handling Costs'!$J$32:$J$35,'Handling Costs'!$J$39:$J$40) -> 471059.81 | D13: 2/
B14: Other | C14: =SUM('Handling Costs'!$J$36:$J$38) -> 172216.95 | D14: 3/
B15: Total | C15: =SUM(C12:C14) -> 2075660.5 | D15: 4/
A17: Parcel | B17: Intra-SCF | C17: =SUM('Handling Costs'!$J$47:$J$49,'Handling Costs'!$J$59) -> 5451.0998 | D17: 1/
B18: Intra-NDC | C18: =SUM('Handling Costs'!$J$50:$J$53,'Handling Costs'!$J$57:$J$58) -> 3856.2554 | D18: 2/
B19: Other | C19: =SUM('Handling Costs'!$J$54:$J$56) -> 1715.2475 | D19: 3/
B20: Total | C20: =SUM(C17:C19) -> 11022.603 | D20: 4/
A23: Sources:
A24: 1/: Sum of Flows 1-3 and Flow 13 on page 10
A25: 2/: Sum of Flows 4-7 and Flows 11-12 on page 10
A26: 3/: Sum of Flows 8-10 on page 10
A27: 4/: 1/ + 2/ + 3/

Sheet Trans Costs
A1: DIVISION OF USPS MARKETING MAIL ADJUSTED TRANSPORTATION COSTS INTO INTER-FACILITY TRANSPORTATION CATEGORIES
H5: Letter | K5: Flat | N5: Parcel
C7: [1] | D7: [2] | E7: [3] | G7: [4] | H7: [5] | I7: [6] | J7: [7] | K7: [8] | L7: [9] | M7: [10] | N7: [11] | O7: [12]
C8: Letter Costs | D8: Flat Costs | E8: Parcel Costs | G8: Intra-NDC | H8: Intra-SCF | I8: Other | J8: Intra-NDC | K8: Intra-SCF | L8: Other | M8: Intra-NDC | N8: Intra-SCF | O8: Other
A9: Domestic Airmail
B10: Passenger Air | C10: ='CS Data By Shape'!$B$26 -> 457.9562 | D10: ='CS Data By Shape'!$C$26 -> 264.2566 | E10: ='CS Data By Shape'!$D$26 -> 73.8668 | I10: =C10 -> 457.9562 | L10: =D10 -> 264.2566 | O10: =E10 -> 73.8668
B11: Intra-Alaska Preferential | C11: ='CS Data By Shape'!$B$27 -> 3390.7984 | D11: ='CS Data By Shape'!$C$27 -> 1836.4826 | E11: ='CS Data By Shape'!$D$27 -> 26.377623 | I11: =C11 -> 3390.7984 | L11: =D11 -> 1836.4826 | O11: =E11 -> 26.377623
B12: Intra-Alaska Non-preferential | C12: ='CS Data By Shape'!$B$28 -> 165.72064 | D12: ='CS Data By Shape'!$C$28 -> 95.518756 | E12: ='CS Data By Shape'!$D$28 -> 1.4672117 | I12: =C12 -> 165.72064 | L12: =D12 -> 95.518756 | O12: =E12 -> 1.4672117
B13: Intra-Hawaii | C13: ='CS Data By Shape'!$B$29 -> 4392.1077 | D13: ='CS Data By Shape'!$C$29 -> 2487.968 | E13: ='CS Data By Shape'!$D$29 -> 41.596637 | I13: =C13 -> 4392.1077 | L13: =D13 -> 2487.968 | O13: =E13 -> 41.596637
B14: FedEx | C14: ='CS Data By Shape'!$B$30 -> 145.44923 | D14: ='CS Data By Shape'!$C$30 -> 57.300423 | E14: ='CS Data By Shape'!$D$30 -> 0.12392772 | I14: =C14 -> 145.44923 | L14: =D14 -> 57.300423 | O14: =E14 -> 0.12392772
B15: UPS | C15: ='CS Data By Shape'!$B$31 -> 24259.307 | D15: ='CS Data By Shape'!$C$31 -> 11815.886 | E15: ='CS Data By Shape'!$D$31 -> 243.78595 | I15: =C15 -> 24259.307 | L15: =D15 -> 11815.886 | O15: =E15 -> 243.78595
B16: Peak | C16: ='CS Data By Shape'!$B$32 -> 6.6269096 | D16: ='CS Data By Shape'!$C$32 -> 4.2392403 | E16: ='CS Data By Shape'!$D$32 -> 0.2707993 | I16: =C16 -> 6.6269096 | L16: =D16 -> 4.2392403 | O16: =E16 -> 0.2707993
B17: Air Taxi | C17: ='CS Data By Shape'!$B$33 -> 2752.5921 | D17: ='CS Data By Shape'!$C$33 -> 1535.6748 | E17: ='CS Data By Shape'!$D$33 -> 23.375591 | I17: =C17 -> 2752.5921 | L17: =D17 -> 1535.6748 | O17: =E17 -> 23.375591
A18: Total Domestic Airmail | C18: =SUM(C10:C17) -> 35570.559 | D18: =SUM(D10:D17) -> 18097.327 | E18: =SUM(E10:E17) -> 410.86454 | G18: =SUM(G10:G17) -> 0 | H18: =SUM(H10:H17) -> 0 | I18: =SUM(I10:I17) -> 35570.559 | J18: =SUM(J10:J17) -> 0 | K18: =SUM(K10:K17) -> 0 | L18: =SUM(L10:L17) -> 18097.327 | M18: =SUM(M10:M17) -> 0 | N18: =SUM(N10:N17) -> 0 | O18: =SUM(O10:O17) -> 410.86454
A21: Highway Service
B22: Intra-SCF | C22: ='Trans Cost Adj'!$E$7 -> 75834.194 | D22: ='Trans Cost Adj'!$E$10 -> 56104.879 | E22: ='Trans Cost Adj'!$E$13 -> 424.81037 | F22: 1/ | H22: =C22 -> 75834.194 | K22: =D22 -> 56104.879 | N22: =E22 -> 424.81037
B23: Intra-NDC | C23: ='CS Data By Shape'!$B$37 -> 0 | D23: ='CS Data By Shape'!$C$37 -> 0 | E23: ='CS Data By Shape'!$D$37 -> 0 | G23: =C23 -> 0 | J23: =D23 -> 0 | M23: =E23 -> 0
B24: Inter-SCF | C24: ='CS Data By Shape'!$B$38 -> 119082.17 | D24: ='CS Data By Shape'!$C$38 -> 79354.664 | E24: ='CS Data By Shape'!$D$38 -> 724.05242 | I24: =C24 -> 119082.17 | L24: =D24 -> 79354.664 | O24: =E24 -> 724.05242
B25: Inter-NDC | C25: ='CS Data By Shape'!$B$39 -> 0 | D25: ='CS Data By Shape'!$C$39 -> 0 | E25: ='CS Data By Shape'!$D$39 -> 0 | I25: =C25 -> 0 | L25: =D25 -> 0 | O25: =E25 -> 0
B26: Postal-Owned Vehicle Costs | C26: ='Trans Cost Adj'!$E$8 -> 58917.942 | D26: ='Trans Cost Adj'!$E$11 -> 57708.316 | E26: ='Trans Cost Adj'!$E$14 -> 216.06331 | F26: 2/ | H26: =C26 -> 58917.942 | K26: =D26 -> 57708.316 | N26: =E26 -> 216.06331
B27: Plant-loaded | C27: ='CS Data By Shape'!$B$40 -> 1374.9472 | D27: ='CS Data By Shape'!$C$40 -> 958.30325 | E27: ='CS Data By Shape'!$D$40 -> 9.4044653 | I27: =C27 -> 1374.9472 | L27: =D27 -> 958.30325 | O27: =E27 -> 9.4044653
B28: Alaskan Highway Service | C28: ='CS Data By Shape'!$B$43 -> 0 | D28: ='CS Data By Shape'!$C$43 -> 0 | E28: ='CS Data By Shape'!$D$43 -> 0 | G28: =C28 -> 0 | J28: =D28 -> 0 | M28: =E28 -> 0
B29: Contract Terminal and Van Damage | C29: ='CS Data By Shape'!$B$41 -> 174.26447 | D29: ='CS Data By Shape'!$C$41 -> 121.18593 | E29: ='CS Data By Shape'!$D$41 -> 0.9983421 | G29: =$C$29*G32 -> 0 | H29: =$C$29*H32 -> 67.324457 | I29: =C29*I32 -> 106.94001 | J29: =$D$29*J32 -> 0 | K29: =$D$29*K32 -> 49.840414 | L29: =D29*L32 -> 71.345516 | M29: =$E$29*M32 -> 0 | N29: =$E$29*N32 -> 0.36615563 | O29: =E29*O32 -> 0.63218647
B30: Empty Equipment | C30: ='CS Data By Shape'!$B$42 -> 6245.2786 | D30: ='CS Data By Shape'!$C$42 -> 5609.9328 | E30: ='CS Data By Shape'!$D$42 -> 15.650177 | G30: =$C$30*G33 -> 0 | H30: =$C$30*H33 -> 2412.7695 | I30: =C30*I33 -> 3832.5092 | J30: =$D$30*J33 -> 0 | K30: =$D$30*K33 -> 2307.2099 | L30: =D30*L33 -> 3302.7229 | M30: =$E$30*M33 -> 0 | N30: =$E$30*N33 -> 5.7399166 | O30: =E30*O33 -> 9.9102602
A31: Total Highway Service | C31: =SUM(C22:C30) -> 261628.79 | D31: =SUM(D22:D30) -> 199857.28 | E31: =SUM(E22:E30) -> 1390.9791 | G31: =SUM(G22:G30) -> 0 | H31: =SUM(H22:H30) -> 137232.23 | I31: =SUM(I22:I30) -> 124396.56 | J31: =SUM(J22:J30) -> 0 | K31: =SUM(K22:K30) -> 116170.25 | L31: =SUM(L22:L30) -> 83687.036 | M31: =SUM(M22:M30) -> 0 | N31: =SUM(N22:N30) -> 646.97976 | O31: =SUM(O22:O30) -> 743.99933
A32: Contract Terminal and Van Damage | C32: =SUM(C22:C25)+C27 -> 196291.31 | D32: =SUM(D22:D25)+D27 -> 136417.85 | E32: =SUM(E22:E25)+E27 -> 1158.2673 | G32: =G23/SUM(C22:C25,C27) -> 0 | H32: =H22/SUM(C22:C25,C27) -> 0.38633496 | I32: =SUM(I24,I25,I27)/SUM(C22:C25,C27) -> 0.61366504 | J32: =J23/SUM(D22:D25,D27) -> 0 | K32: =K22/SUM(D22:D25,D27) -> 0.41127228 | L32: =SUM(L24,L25,L27)/SUM(D22:D25,D27) -> 0.58872772 | M32: =M23/SUM(E22:E25,E27) -> 0 | N32: =N22/SUM(E22:E25,E27) -> 0.36676369 | O32: =SUM(O24,O25,O27)/SUM(E22:E25,E27) -> 0.63323631
A33: Empty Equipment | C33: =SUM(C22:C25)+C27+C28+C29 -> 196465.57 | D33: =SUM(D22:D25)+D27+D28+D29 -> 136539.03 | E33: =SUM(E22:E25)+E27+E28+E29 -> 1159.2656 | G33: =SUM(G23,G28,G29)/SUM(C22:C25,C27:C29) -> 0 | H33: =SUM(H22,H29)/SUM(C22:C25,C27:C29) -> 0.38633496 | I33: =SUM(I24,I25,I27,I29)/SUM(C22:C25,C27:C29) -> 0.61366504 | J33: =SUM(J23,J28,J29)/SUM(D22:D25,D27:D29) -> 0 | K33: =SUM(K22,K29)/SUM(D22:D25,D27:D29) -> 0.41127228 | L33: =SUM(L24,L25,L27,L29)/SUM(D22:D25,D27:D29) -> 0.58872772 | M33: =SUM(M23,M28,M29)/SUM(E22:E25,E27:E29) -> 0 | N33: =SUM(N22,N29)/SUM(E22:E25,E27:E29) -> 0.36676369 | O33: =SUM(O24,O25,O27,O29)/SUM(E22:E25,E27:E29) -> 0.63323631
A34: Railroad Service
B35: Freight Rail | C35: ='CS Data By Shape'!$B$46 -> 0 | D35: ='CS Data By Shape'!$C$46 -> 0 | E35: ='CS Data By Shape'!$D$46 -> 0 | I35: =C35 -> 0 | L35: =D35 -> 0 | O35: =E35 -> 0
B36: Plant-loaded | C36: ='CS Data By Shape'!$B$47 -> -5.3060918 | D36: ='CS Data By Shape'!$C$47 -> -3.9719136 | E36: ='CS Data By Shape'!$D$47 -> -0.026659642 | I36: =C36 -> -5.3060918 | L36: =D36 -> -3.9719136 | O36: =E36 -> -0.026659642
B37: Damage and Empty Equipment | C37: ='CS Data By Shape'!$B$48 -> 2804.0932 | D37: ='CS Data By Shape'!$C$48 -> 2457.3347 | E37: ='CS Data By Shape'!$D$48 -> 6.8562965 | I37: =C37 -> 2804.0932 | L37: =D37 -> 2457.3347 | O37: =E37 -> 6.8562965
A38: Total Railroad Service | C38: =SUM(C35:C37) -> 2798.7871 | D38: =SUM(D35:D37) -> 2453.3628 | E38: =SUM(E35:E37) -> 6.8296369 | G38: =SUM(G35:G37) -> 0 | H38: =SUM(H35:H37) -> 0 | I38: =SUM(I35:I37) -> 2798.7871 | J38: =SUM(J35:J37) -> 0 | K38: =SUM(K35:K37) -> 0 | L38: =SUM(L35:L37) -> 2453.3628 | M38: =SUM(M35:M37) -> 0 | N38: =SUM(N35:N37) -> 0 | O38: =SUM(O35:O37) -> 6.8296369
A40: Domestic Water
B41: Inland | C41: ='CS Data By Shape'!$B$51 -> 155.31331 | D41: ='CS Data By Shape'!$C$51 -> 113.83861 | E41: ='CS Data By Shape'!$D$51 -> 0.85073634 | G41: =C41 -> 155.31331 | J41: =D41 -> 113.83861 | M41: =E41 -> 0.85073634
B42: Offshore | C42: ='CS Data By Shape'!$B$52 -> 1842.9868 | D42: ='CS Data By Shape'!$C$52 -> 1290.5567 | E42: ='CS Data By Shape'!$D$52 -> 10.700568 | G42: =C42 -> 1842.9868 | J42: =D42 -> 1290.5567 | M42: =E42 -> 10.700568
A43: Total Domestic Water | C43: =+C42+C41 -> 1998.3001 | D43: =+D42+D41 -> 1404.3953 | E43: =+E42+E41 -> 11.551305 | G43: =+G42+G41 -> 1998.3001 | H43: =SUM(H42:H42) -> 0 | I43: =SUM(I42:I42) -> 0 | J43: =+J42+J41 -> 1404.3953 | K43: =SUM(K42:K42) -> 0 | L43: =SUM(L42:L42) -> 0 | M43: =+M42+M41 -> 11.551305 | N43: =SUM(N42:N42) -> 0 | O43: =SUM(O42:O42) -> 0
A45: Total - All Modes | C45: =C43+C38+C31+C18 -> 301996.44 | D45: =D43+D38+D31+D18 -> 221812.37 | E45: =E43+E38+E31+E18 -> 1820.2246 | G45: =G43+G38+G31+G18 -> 1998.3001 | H45: =H43+H38+H31+H18 -> 137232.23 | I45: =I43+I38+I31+I18 -> 162765.91 | J45: =J43+J38+J31+J18 -> 1404.3953 | K45: =K43+K38+K31+K18 -> 116170.25 | L45: =L43+L38+L31+L18 -> 104237.73 | M45: =M43+M38+M31+M18 -> 11.551305 | N45: =N43+N38+N31+N18 -> 646.97976 | O45: =O43+O38+O31+O18 -> 1161.6935
A48: Sources:
A49: 1/: | B49: Page 7
A50: 2/: | B50: Page 7
...

Sheet Trans Cost Adj
A1: USPS MARKETING MAIL INTRA-SCF and POV HIGHWAY TRANSPORTATION COST ADJUSTMENTS
C4: [1] | D4: [2] | E4: [3]
C5: Costs (000) | D5: Adjustment Factor | E5: Adjusted Costs (000s)
A7: Letter | B7: Intra-SCF | C7: ='CS Data By Shape'!$B$36 -> 90743.322 | D7: ='Other Inputs'!$G$22 -> 0.8357 | E7: =C7*D7 -> 75834.194
B8: POV | C8: ='CS Data By Shape'!$B$55*'Piggyback Factors'!$D$63 -> 70501.306 | D8: ='Other Inputs'!$G$22 -> 0.8357 | E8: =C8*D8 -> 58917.942
A10: Flat | B10: Intra-SCF | C10: ='CS Data By Shape'!$C$36 -> 67135.191 | D10: ='Other Inputs'!$G$22 -> 0.8357 | E10: =C10*D10 -> 56104.879
B11: POV | C11: ='CS Data By Shape'!$C$55*'Piggyback Factors'!$D$63 -> 69053.866 | D11: ='Other Inputs'!$G$22 -> 0.8357 | E11: =C11*D11 -> 57708.316
A13: Parcel | B13: Intra-SCF | C13: ='CS Data By Shape'!$D$36 -> 508.32879 | D13: ='Other Inputs'!$G$22 -> 0.8357 | E13: =C13*D13 -> 424.81037
B14: POV | C14: ='CS Data By Shape'!$D$55*'Piggyback Factors'!$D$63 -> 258.54172 | D14: ='Other Inputs'!$G$22 -> 0.8357 | E14: =C14*D14 -> 216.06331
A16: Total | B16: Intra-SCF | C16: =C7+C10+C13 -> 158386.84
B17: POV | C17: =C8+C11+C14 -> 139813.71
A20: Sources:
A21: [1]: Intra-SCF costs (page 37)
A22: POV costs (page 37) * piggyback factor (page 40)
A23: [2]: Page 42
A24: [3]: [1] * [2]

Sheet NonTrans CPP
A1: USPS MARKETING MAIL NON-TRANSPORTATION UNIT COSTS
A4: Letter
A6: Pounds | F6: ='CS Data By Shape'!$B$7 -> 2023844 | G6: 1/
A8: Handling Costs | F8: ='Handling Costs'!$L$26 -> 29429.29 | G8: 2/
A10: Average Non-Transportation Cost per Pound | F10: =F8/F6 -> 0.014541284 | G10: 3/
A12: Flat
A14: Pounds | F14: ='CS Data By Shape'!$C$7 -> 1966890.7 | G14: 1/
A16: Handling Costs | F16: ='Handling Costs'!$L$43 -> 10721.871 | G16: 2/
A18: Average Non-Transportation Cost per Pound | F18: =F16/F14 -> 0.0054511781 | G18: 3/
A20: Parcel
A22: Pounds | F22: ='CS Data By Shape'!$D$7 -> 4941.206 | G22: 1/
A24: Handling Costs | F24: ='Handling Costs'!$L$61 -> 329.50321 | G24: 2/
A26: Average Non-Transportation Cost per Pound | F26: =F24/F22 -> 0.066684775 | G26: 3/
A29: Sources:
A30: 1/: Page 37
A31: 2/: Page 10
A32: 3/: Row 2 / Row 1

Sheet Results NonTrans
A1: USPS MARKETING MAIL NON-TRANSPORTATION EQUATION AND RESULTS
A6: Non-transportation Equation: | D6: (Yorigin * Xorigin) + (YDNDC * XDNDC) + (YDSCF * XDSCF) = ZT | K6: 1/
B8: Yorigin: | C8: Percentage of mail that is dropshipped or plantloaded to non-destination facilities
B9: Xorigin: | C9: Cost per pound to the Postal Service of crossdocking Yorigin before it reaches the destination delivery unit
B11: YDNDC: | C11: Percentage of mail that is dropshipped or plantloaded to a destination NDC
B12: XDNDC: | C12: Cost per pound to the Postal Service of crossdocking YDNDC before it reaches the destination delivery unit
B14: YDSCF: | C14: Percentage of mail that is dropshipped or plantloaded to a destination SCF
B15: XDSCF: | C15: Cost per pound to the Postal Service of crossdocking YDSCF before it reaches the destination delivery unit
B17: ZT: | C17: Cost per pound to the Postal Service of crossdocking all USPS Marketing Mail before it reaches the destination delivery unit
A19: Solving the Equation:
C21: Letter | E21: Flat | G21: Parcel
B23: Yorigin: | C23: ='Entry Profile L&F'!$G$8+'Entry Profile L&F'!$G$9+'Entry Profile L&F'!$G$10 -> 0.16020909 | E23: ='Entry Profile L&F'!$I$8+'Entry Profile L&F'!$I$9+'Entry Profile L&F'!$I$10 -> 0.12675166 | G23: ='Entry Profile P'!$G$23+'Entry Profile P'!$G$24+'Entry Profile P'!$G$25 -> 0.4950719 | K23: 2/
B24: Xorigin: | C24: Solve For X | E24: Solve For X | G24: Solve For X | K24: 3/
B26: YDNDC: | C26: ='Entry Profile L&F'!$G$11 -> 0.067539307 | E26: ='Entry Profile L&F'!$I$11 -> 0.050900412 | G26: ='Entry Profile P'!$G$26 -> 0.24782196 | K26: 4/
B27: XDNDC: | C27: ='Facility NonTrans CPP'!$B$40+'Flow Proportions'!$E$48*'Facility NonTrans CPP'!$B$49 -> 0.019121773 | E27: ='Facility NonTrans CPP'!$F$40+'Flow Proportions'!$E$48*'Facility NonTrans CPP'!$F$49 -> 0.0084241547 | G27: ='Facility NonTrans CPP'!$J$40+'Flow Proportions'!$E$48*'Facility NonTrans CPP'!$J$49 -> 0.066046937 | K27: 5/
B29: YDSCF: | C29: ='Entry Profile L&F'!$G$12 -> 0.75042884 | E29: ='Entry Profile L&F'!$I$12 -> 0.55529926 | G29: ='Entry Profile P'!$G$27 -> 0.23124214 | K29: 6/
B30: XDSCF: | C30: ='Facility NonTrans CPP'!$B$49 -> 0.011201472 | E30: ='Facility NonTrans CPP'!$F$49 -> 0.005984864 | G30: ='Facility NonTrans CPP'!$J$49 -> 0.062016211 | K30: 7/
B32: ZT: | C32: ='NonTrans CPP'!$F$10 -> 0.014541284 | E32: ='NonTrans CPP'!$F$18 -> 0.0054511781 | G32: ='NonTrans CPP'!$F$26 -> 0.066684775 | K32: 8/
B34: Xorigin: | C34: =(C32-(C26*C27)-(C29*C30))/C23 -> 0.030234896 | E34: =(E32-(E26*E27)-(E29*E30))/E23 -> 0.013404121 | G34: =(G32-(G26*G27)-(G29*G30))/G23 -> 0.072668501 | K34: 9/
A37: Cost Avoidances:
B39: DDU | C39: =C34 -> 0.030234896 | E39: =E34 -> 0.013404121 | G39: =G34 -> 0.072668501 | K39: 10/
B40: DSCF | C40: =C34-C30 -> 0.019033424 | E40: =E34-E30 -> 0.007419257 | G40: =G34-G30 -> 0.01065229 | K40: 11/
B41: DNDC | C41: =C34-C27 -> 0.011113123 | E41: =E34-E27 -> 0.0049799662 | G41: =G34-G27 -> 0.006621564 | K41: 12/
A44: Sources:
A45: 1/: | B45: Docket No. MC95-1, USPS-T-9
A46: 2/: | B46: Pages 35 and 36
A47: 3/: | B47: This variable is unknown and the equation will be solved to find Xorigin
A48: 4/: | B48: Pages 35 and 36
A49: 5/: | B49: DNDC cost per pound (page 11) + Flow Proportion (page 33) * DSCF cost per pound (page 11)
A50: 6/: | B50: Page 35 and 36
A51: 7/: | B51: DSCF cost per pound (page 11)
A52: 8/: | B52: Cost per pound for handling mail to DDU (page 9)
A53: 9/: | B53: ( Row 8 - ( Row 4 * Row 5 ) - ( Row 6 * Row 7 ) ) / Row 2
A54: 10/: | B54: Row 9
A55: 11/: | B55: Row 9 - Row 7
A56: 12/: | B56: Row 9 - Row 5

Sheet Handling Costs
A1: HANDLING COSTS BY MAIL FLOW
C3: [1]
A4: Total Pounds | C4: ='CS Data By Shape'!$E$7 -> 3995675.9
A5: Letter Pounds | C5: ='CS Data By Shape'!$B$7 -> 2023844
A6: Flat Pounds | C6: ='CS Data By Shape'!$C$7 -> 1966890.7
A7: Parcel Pounds | C7: ='CS Data By Shape'!$D$7 -> 4941.206
C9: [2] | D9: [3] | E9: [4] | G9: [5] | I9: [6] | J9: [7] | K9: [8] | L9: [9]
A10: Letter
A11: Flow Number | B11: Origin | C11: Percent of Volume Entered at Origin | D11: Pounds Entered at Origin | E11: Additional Pounds from Combining Flows | G11: Pounds Processed | H11: Type of Transportation | I11: Proportion of Volume from the Origin | J11: Total Pounds Transported on Each Flow | K11: Weighted Avg Cost of Crossdocking | L11: Total Handling Costs (000s)
A12: 1 | B12: ODU | C12: ='Entry Profile L&F'!$G$8 -> 0 | D12: =C12*$C$5 -> 0 | E12: 0 | G12: =D12+E12 -> 0 | H12: Intra-SCF | I12: ='Flow Proportions'!$E$30 -> 0.0158256 | J12: =I12*G12 -> 0 | K12: ='Facility NonTrans CPP'!$B$13 -> 0 | L12: =J12*K12 -> 0
A13: 2 | B13: ODU | C13: ='Entry Profile L&F'!$G$8 -> 0 | D13: =C13*$C$5 -> 0 | E13: 0 | G13: =D13+E13 -> 0 | H13: Intra-SCF | I13: ='Flow Proportions'!$E$31 -> 0.4881744 | J13: =I13*G13 -> 0 | K13: ='Facility NonTrans CPP'!$B$13 -> 0 | L13: =J13*K13 -> 0
A14: 3 | B14: ODU | C14: ='Entry Profile L&F'!$G$8 -> 0 | D14: =C14*$C$5 -> 0 | E14: 0 | G14: =D14+E14 -> 0 | H14: Intra-SCF | I14: ='Flow Proportions'!$E$32 -> 0.496 | J14: =I14*G14 -> 0 | K14: ='Facility NonTrans CPP'!$B$13 -> 0 | L14: =J14*K14 -> 0
A15: 4 | B15: ODU | C15: ='Entry Profile L&F'!$G$8 -> 0 | D15: =C15*$C$5 -> 0 | E15: 0 | G15: =D15+E15 -> 0 | H15: Intra-NDC | I15: ='Flow Proportions'!$E$33 -> 0 | J15: =I15*G15 -> 0 | K15: ='Facility NonTrans CPP'!$B$13 -> 0 | L15: =J15*K15 -> 0
A16: 5 | B16: ODU | C16: ='Entry Profile L&F'!$G$8 -> 0 | D16: =C16*$C$5 -> 0 | E16: 0 | G16: =D16+E16 -> 0 | H16: Intra-NDC | I16: ='Flow Proportions'!$E$34 -> 0 | J16: =I16*G16 -> 0 | K16: ='Facility NonTrans CPP'!$B$13 -> 0 | L16: =J16*K16 -> 0
A17: 6 | B17: OSCF | C17: ='Entry Profile L&F'!$G$9 -> 0.15268066 | D17: =C17*$C$5 -> 309001.83 | E17: =J14 -> 0 | G17: =D17+E17 -> 309001.83 | H17: Intra-NDC | I17: ='Flow Proportions'!$E$38 -> 0.32491359 | J17: =I17*G17 -> 100398.89 | K17: ='Facility NonTrans CPP'!$B$22 -> 0.0095770432 | L17: =J17*K17 -> 961.52455
A18: 7 | B18: OSCF | C18: ='Entry Profile L&F'!$G$9 -> 0.15268066 | D18: =C18*$C$5 -> 309001.83 | E18: =J14 -> 0 | G18: =D18+E18 -> 309001.83 | H18: Intra-NDC | I18: ='Flow Proportions'!$E$39 -> 0.43618641 | J18: =I18*G18 -> 134782.4 | K18: ='Facility NonTrans CPP'!$B$22 -> 0.0095770432 | L18: =J18*K18 -> 1290.8169
A19: 8 | B19: OSCF | C19: ='Entry Profile L&F'!$G$9 -> 0.15268066 | D19: =C19*$C$5 -> 309001.83 | E19: =J14 -> 0 | G19: =D19+E19 -> 309001.83 | H19: Inter-SCF | I19: ='Flow Proportions'!$E$40 -> 0.23139854 | J19: =I19*G19 -> 71502.573 | K19: ='Facility NonTrans CPP'!$B$22 -> 0.0095770432 | L19: =J19*K19 -> 684.78323
A20: 9 | B20: OSCF | C20: ='Entry Profile L&F'!$G$9 -> 0.15268066 | D20: =C20*$C$5 -> 309001.83 | E20: =J14 -> 0 | G20: =D20+E20 -> 309001.83 | H20: Inter-SCF | I20: ='Flow Proportions'!$E$41 -> 0.00750146 | J20: =I20*G20 -> 2317.9649 | K20: ='Facility NonTrans CPP'!$B$22 -> 0.0095770432 | L20: =J20*K20 -> 22.19925
A21: 10 | B21: ONDC | C21: ='Entry Profile L&F'!$G$10 -> 0.0075284272 | D21: =C21*$C$5 -> 15236.362 | E21: =J15+J18 -> 134782.4 | G21: =D21+E21 -> 150018.76 | H21: Inter-NDC | I21: ='Flow Proportions'!$E$45 -> 1 | J21: =I21*G21 -> 150018.76 | K21: ='Facility NonTrans CPP'!$B$31 -> 0.0083630901 | L21: =J21*K21 -> 1254.6204
A22: 11 | B22: DNDC | C22: ='Entry Profile L&F'!$G$11 -> 0.067539307 | D22: =C22*$C$5 -> 136689.02 | E22: =J16+J17+J21 -> 250417.66 | G22: =D22+E22 -> 387106.68 | H22: Intra-NDC | I22: ='Flow Proportions'!$E$48 -> 0.9686 | J22: =I22*G22 -> 374951.53 | K22: ='Facility NonTrans CPP'!$B$40 -> 0.0082720274 | L22: =J22*K22 -> 3101.6093
A23: 12 | B23: DNDC | C23: ='Entry Profile L&F'!$G$11 -> 0.067539307 | D23: =C23*$C$5 -> 136689.02 | E23: =J16+J17+J21 -> 250417.66 | G23: =D23+E23 -> 387106.68 | H23: Intra-NDC | I23: ='Flow Proportions'!$E$49 -> 0.0314 | J23: =I23*G23 -> 12155.15 | K23: ='Facility NonTrans CPP'!$B$40 -> 0.0082720274 | L23: =J23*K23 -> 100.54773
A24: 13 | B24: DSCF | C24: ='Entry Profile L&F'!$G$12 -> 0.75042884 | D24: =C24*$C$5 -> 1518750.9 | E24: =J13+J19+J22 -> 446454.1 | G24: =D24+E24 -> 1965205 | H24: Intra-SCF | I24: ='Flow Proportions'!$E$53 -> 1 | J24: =I24*G24 -> 1965205 | K24: ='Facility NonTrans CPP'!$B$49 -> 0.011201472 | L24: =J24*K24 -> 22013.188
L26: =SUM(L12:L24) -> 29429.29
A27: Flat
A28: Flow Number | B28: Origin | C28: Percent of Volume Entered at Origin | D28: Pounds Entered at Origin | E28: Additional Pounds from Combining Flows | G28: Pounds Processed | H28: Type of Transportation | I28: Proportion of Volume from the Origin | J28: Total Pounds Transported on Each Flow | K28: Weighted Avg Cost of Crossdocking | L28: Total Handling Costs (000s)
A29: 1 | B29: ODU | C29: ='Entry Profile L&F'!$I$8 -> 0.00087470934 | D29: =C29*$C$6 -> 1720.4577 | E29: 0 | G29: =D29+E29 -> 1720.4577 | H29: Intra-SCF | I29: ='Flow Proportions'!$E$30 -> 0.0158256 | J29: =I29*G29 -> 27.227275 | K29: ='Facility NonTrans CPP'!$F$13 -> 0 | L29: =J29*K29 -> 0
A30: 2 | B30: ODU | C30: ='Entry Profile L&F'!$I$8 -> 0.00087470934 | D30: =C30*$C$6 -> 1720.4577 | E30: 0 | G30: =D30+E30 -> 1720.4577 | H30: Intra-SCF | I30: ='Flow Proportions'!$E$31 -> 0.4881744 | J30: =I30*G30 -> 839.88338 | K30: ='Facility NonTrans CPP'!$F$13 -> 0 | L30: =J30*K30 -> 0
A31: 3 | B31: ODU | C31: ='Entry Profile L&F'!$I$8 -> 0.00087470934 | D31: =C31*$C$6 -> 1720.4577 | E31: 0 | G31: =D31+E31 -> 1720.4577 | H31: Intra-SCF | I31: ='Flow Proportions'!$E$32 -> 0.496 | J31: =I31*G31 -> 853.347 | K31: ='Facility NonTrans CPP'!$F$13 -> 0 | L31: =J31*K31 -> 0
A32: 4 | B32: ODU | C32: ='Entry Profile L&F'!$I$8 -> 0.00087470934 | D32: =C32*$C$6 -> 1720.4577 | E32: 0 | G32: =D32+E32 -> 1720.4577 | H32: Intra-NDC | I32: ='Flow Proportions'!$E$33 -> 0 | J32: =I32*G32 -> 0 | K32: ='Facility NonTrans CPP'!$F$13 -> 0 | L32: =J32*K32 -> 0
A33: 5 | B33: ODU | C33: ='Entry Profile L&F'!$I$8 -> 0.00087470934 | D33: =C33*$C$6 -> 1720.4577 | E33: 0 | G33: =D33+E33 -> 1720.4577 | H33: Intra-NDC | I33: ='Flow Proportions'!$E$34 -> 0 | J33: =I33*G33 -> 0 | K33: ='Facility NonTrans CPP'!$F$13 -> 0 | L33: =J33*K33 -> 0
A34: 6 | B34: OSCF | C34: ='Entry Profile L&F'!$I$9 -> 0.11883737 | D34: =C34*$C$6 -> 233740.12 | E34: =J31 -> 853.347 | G34: =D34+E34 -> 234593.47 | H34: Intra-NDC | I34: ='Flow Proportions'!$E$38 -> 0.32491359 | J34: =I34*G34 -> 76222.605 | K34: ='Facility NonTrans CPP'!$F$22 -> 0.004115173 | L34: =J34*K34 -> 313.66921
A35: 7 | B35: OSCF | C35: ='Entry Profile L&F'!$I$9 -> 0.11883737 | D35: =C35*$C$6 -> 233740.12 | E35: =J31 -> 853.347 | G35: =D35+E35 -> 234593.47 | H35: Intra-NDC | I35: ='Flow Proportions'!$E$39 -> 0.43618641 | J35: =I35*G35 -> 102326.48 | K35: ='Facility NonTrans CPP'!$F$22 -> 0.004115173 | L35: =J35*K35 -> 421.09118
A36: 8 | B36: OSCF | C36: ='Entry Profile L&F'!$I$9 -> 0.11883737 | D36: =C36*$C$6 -> 233740.12 | E36: =J31 -> 853.347 | G36: =D36+E36 -> 234593.47 | H36: Inter-SCF | I36: ='Flow Proportions'!$E$40 -> 0.23139854 | J36: =I36*G36 -> 54284.586 | K36: ='Facility NonTrans CPP'!$F$22 -> 0.004115173 | L36: =J36*K36 -> 223.39046
A37: 9 | B37: OSCF | C37: ='Entry Profile L&F'!$I$9 -> 0.11883737 | D37: =C37*$C$6 -> 233740.12 | E37: =J31 -> 853.347 | G37: =D37+E37 -> 234593.47 | H37: Inter-SCF | I37: ='Flow Proportions'!$E$41 -> 0.00750146 | J37: =I37*G37 -> 1759.7935 | K37: ='Facility NonTrans CPP'!$F$22 -> 0.004115173 | L37: =J37*K37 -> 7.2418547
A38: 10 | B38: ONDC | C38: ='Entry Profile L&F'!$I$10 -> 0.0070395814 | D38: =C38*$C$6 -> 13846.087 | E38: =J32+J35 -> 102326.48 | G38: =D38+E38 -> 116172.57 | H38: Inter-NDC | I38: ='Flow Proportions'!$E$45 -> 1 | J38: =I38*G38 -> 116172.57 | K38: ='Facility NonTrans CPP'!$F$31 -> 0.0036640733 | L38: =J38*K38 -> 425.66481
A39: 11 | B39: DNDC | C39: ='Entry Profile L&F'!$I$11 -> 0.050900412 | D39: =C39*$C$6 -> 100115.55 | E39: =J33+J34+J38 -> 192395.17 | G39: =D39+E39 -> 292510.72 | H39: Intra-NDC | I39: ='Flow Proportions'!$E$48 -> 0.9686 | J39: =I39*G39 -> 283325.88 | K39: ='Facility NonTrans CPP'!$F$40 -> 0.0026272155 | L39: =J39*K39 -> 744.35816
A40: 12 | B40: DNDC | C40: ='Entry Profile L&F'!$I$11 -> 0.050900412 | D40: =C40*$C$6 -> 100115.55 | E40: =J33+J34+J38 -> 192395.17 | G40: =D40+E40 -> 292510.72 | H40: Intra-NDC | I40: ='Flow Proportions'!$E$49 -> 0.0314 | J40: =I40*G40 -> 9184.8367 | K40: ='Facility NonTrans CPP'!$F$40 -> 0.0026272155 | L40: =J40*K40 -> 24.130545
A41: 13 | B41: DSCF | C41: ='Entry Profile L&F'!$I$12 -> 0.55529926 | D41: =C41*$C$6 -> 1092212.9 | E41: =J30+J36+J39 -> 338450.35 | G41: =D41+E41 -> 1430663.3 | H41: Intra-SCF | I41: ='Flow Proportions'!$E$53 -> 1 | J41: =I41*G41 -> 1430663.3 | K41: ='Facility NonTrans CPP'!$F$49 -> 0.005984864 | L41: =J41*K41 -> 8562.3251
L43: =SUM(L29:L41) -> 10721.871
A45: Parcel
...

Sheet Facility NonTrans CPP
A1: USPS MARKETING MAIL NON-TRANSPORTATION COSTS
A2: By Container Type and By Facility
C4: Letter | G4: Flat | K4: Parcel
B6: [1] | C6: [2] | D6: [3] | F6: [1] | G6: [2] | H6: [3] | J6: [1] | K6: [2] | L6: [3]
B7: Cost Per | F7: Cost Per | J7: Cost Per
A8: ODU Container Type | B8: Pound | C8: Pounds | D8: Percent | F8: Pound | G8: Pounds | H8: Percent | J8: Pound | K8: Pounds | L8: Percent
A9: Sack | B9: 0 | C9: 0 | D9: =IF(C9>0,C9/$C$12,0) -> 0 | F9: ='ODU-S'!$K$10 -> 0.0006422096 | G9: ='Entry Profile L&F'!$H$33 -> 837578.7 | H9: =IF(G9>0,G9/$G$12,0) -> 0.48919827 | J9: ='ODU-S'!$K$12 -> 0.00084877891 | K9: ='Entry Profile P'!$E$23 -> 27.434691 | L9: =K9/$K$12 -> 0.036435981
A10: Tray | B10: ='ODU-T'!$K$10 -> 0 | C10: ='Entry Profile L&F'!$D$33 -> 0 | D10: =IF(C10>0,C10/$C$12,0) -> 0 | F10: 0 | G10: 0 | H10: =IF(G10>0,G10/$G$12,0) -> 0 | J10: 0 | K10: 0 | L10: =K10/$K$12 -> 0
A11: Pallet | B11: ='ODU-P'!$J$10 -> 0 | C11: ='Entry Profile L&F'!$B$33 -> 0 | D11: =IF(C11>0,C11/$C$12,0) -> 0 | F11: ='ODU-P'!$J$12 -> 0.00096016564 | G11: ='Entry Profile L&F'!$F$33 -> 874566.97 | H11: =IF(G11>0,G11/$G$12,0) -> 0.51080173 | J11: ='ODU-P'!$J$14 -> 0.002393525 | K11: ='Entry Profile P'!$B$23+'Entry Profile P'!$C$23+'Entry Profile P'!$D$23 -> 725.52132 | L11: =K11/$K$12 -> 0.96356402
A12: Total | C12: =SUM(C9:C11) -> 0 | D12: =IF(OR(C9>0,C10>0,C11>0),SUM(D9:D11),0) -> 0 | G12: =SUM(G9:G11) -> 1712145.7 | H12: =IF(OR(G9>0,G10>0,G11>0),SUM(H9:H11),0) -> 1 | K12: =SUM(K9:K11) -> 752.95601 | L12: =SUM(L9:L11) -> 1
A13: Weighted Average | B13: =IF(AND(C9>0,C10>0,C11>0),SUMPRODUCT(B9:B11,C9:C11)/SUM(C9:C11),0) -> 0 | F13: =IF(AND(G9>0,G10>0,G11>0),SUMPRODUCT(F9:F11,G9:G11)/SUM(G9:G11),0) -> 0 | J13: =SUMPRODUCT(J9:J11,K9:K11)/SUM(K9:K11) -> 0.0023372407
B16: Cost Per | F16: Cost Per | J16: Cost Per
A17: OSCF Container Type | B17: Pound | C17: Pounds | D17: Percent | F17: Pound | G17: Pounds | H17: Percent | J17: Pound | K17: Pounds | L17: Percent
A18: Sack | B18: 0 | C18: 0 | D18: =C18/$C$21 -> 0 | F18: ='OSCF-S'!$K$13 -> 0.0027322689 | G18: ='Entry Profile L&F'!$H$34+'Entry Profile L&F'!$H$35 -> 25115540 | H18: =G18/$G$21 -> 0.10797234 | J18: ='OSCF-S'!$K$18 -> 0.022264583 | K18: ='Entry Profile P'!$E$24 -> 27.699196 | L18: =K18/$K$21 -> 0.039100742
A19: Tray | B19: ='OSCF-T'!$K$13 -> 0.0031172924 | C19: ='Entry Profile L&F'!$D$34+'Entry Profile L&F'!$D$35 -> 59949359 | D19: =C19/$C$21 -> 0.1931054 | F19: 0 | G19: 0 | H19: =G19/$G$21 -> 0 | J19: 0 | K19: 0 | L19: =K19/$K$21 -> 0
A20: Pallet | B20: ='OSCF-P'!$J$13 -> 0.011122986 | C20: ='Entry Profile L&F'!$B$34+'Entry Profile L&F'!$B$35 -> 2.5049954e+08 | D20: =C20/$C$21 -> 0.8068946 | F20: ='OSCF-P'!$J$18 -> 0.0042825618 | G20: ='Entry Profile L&F'!F34+'Entry Profile L&F'!F35 -> 2.0749532e+08 | H20: =G20/$G$21 -> 0.89202766 | J20: ='OSCF-P'!$J$23 -> 0.0080500247 | K20: ='Entry Profile P'!$B$24+'Entry Profile P'!$C$24+'Entry Profile P'!$D$24 -> 680.70669 | L20: =K20/$K$21 -> 0.96089926
A21: Total | C21: =SUM(C18:C20) -> 3.104489e+08 | D21: =SUM(D18:D20) -> 1 | G21: =SUM(G18:G20) -> 2.3261086e+08 | H21: =SUM(H18:H20) -> 1 | K21: =SUM(K18:K20) -> 708.40589 | L21: =SUM(L18:L20) -> 1
A22: Weighted Average | B22: =SUMPRODUCT(B18:B20,C18:C20)/SUM(C18:C20) -> 0.0095770432 | F22: =SUMPRODUCT(F18:F20,G18:G20)/SUM(G18:G20) -> 0.004115173 | J22: =SUMPRODUCT(J18:J20,K18:K20)/SUM(K18:K20) -> 0.0086058245
B25: Cost Per | F25: Cost Per | J25: Cost Per
A26: ONDC Container Type | B26: Pound | C26: Pounds | D26: Percent | F26: Pound | G26: Pounds | H26: Percent | J26: Pound | K26: Pounds | L26: Percent
A27: Sack | B27: 0 | C27: 0 | D27: =C27/$C$30 -> 0 | F27: ='ONDC-S'!$K$14 -> 0.033787643 | G27: ='Entry Profile L&F'!$H$36 -> 200079.12 | H27: =G27/$G$30 -> 0.01452038 | J27: ='ONDC-S'!$K$20 -> 0.020989502 | K27: ='Entry Profile P'!$E$25 -> 37.975297 | L27: =K27/$K$30 -> 0.038557893
A28: Tray | B28: ='ONDC-T'!$K$13 -> 0.10900923 | C28: ='Entry Profile L&F'!$D$36 -> 157099.03 | D28: =C28/$C$30 -> 0.010262736 | F28: 0 | G28: 0 | H28: =G28/$G$30 -> 0 | J28: 0 | K28: 0 | L28: =K28/$K$30 -> 0
A29: Pallet | B29: ='ONDC-P'!$J$12 -> 0.007319475 | C29: ='Entry Profile L&F'!$B$36 -> 15150615 | D29: =C29/$C$30 -> 0.98973726 | F29: ='ONDC-P'!$J$16 -> 0.0032202227 | G29: ='Entry Profile L&F'!$F$36 -> 13579114 | H29: =G29/$G$30 -> 0.98547962 | J29: ='ONDC-P'!$J$20 -> 0.0055421713 | K29: ='Entry Profile P'!$B$25+'Entry Profile P'!$C$25+'Entry Profile P'!$D$25 -> 946.91506 | L29: =K29/$K$30 -> 0.96144211
A30: Total | C30: =SUM(C27:C29) -> 15307715 | D30: =SUM(D27:D29) -> 1 | G30: =SUM(G27:G29) -> 13779193 | H30: =SUM(H27:H29) -> 1 | K30: =SUM(K27:K29) -> 984.89036 | L30: =SUM(L27:L29) -> 1
A31: Weighted Average | B31: =SUMPRODUCT(B27:B29,C27:C29)/SUM(C27:C29) -> 0.0083630901 | F31: =SUMPRODUCT(F27:F29,G27:G29)/SUM(G27:G29) -> 0.0036640733 | J31: =SUMPRODUCT(J27:J29,K27:K29)/SUM(K27:K29) -> 0.0061377878
B34: Cost Per | F34: Cost Per | J34: Cost Per
A35: DNDC Container Type | B35: Pound | C35: Pounds | D35: Percent | F35: Pound | G35: Pounds | H35: Percent | J35: Pound | K35: Pounds | L35: Percent
A36: Sack | B36: 0 | C36: 0 | D36: =C36/$C$39 -> 0 | F36: ='DNDC-S'!$K$16 -> 0.029197689 | G36: ='Entry Profile L&F'!$H$37+'Entry Profile L&F'!$H$38 -> 104979.67 | H36: =G36/$G$39 -> 0.0010536261 | J36: ='DNDC-S'!$K$24 -> 0.016396735 | K36: ='Entry Profile P'!$E$26 -> 49.17123 | L36: =K36/$K$39 -> 0.04015488
A37: Tray | B37: ='DNDC-T'!$K$13 -> 0.13565427 | C37: ='Entry Profile L&F'!$D$37+'Entry Profile L&F'!$D$38 -> 1375787 | D37: =C37/$C$39 -> 0.010017862 | F37: 0 | G37: 0 | H37: =G37/$G$39 -> 0 | J37: 0 | K37: 0 | L37: =K37/$K$39 -> 0
A38: Pallet | B38: ='DNDC-P'!$J$12 -> 0.0069830165 | C38: ='Entry Profile L&F'!$B$37+'Entry Profile L&F'!$B$38 -> 1.3595761e+08 | D38: =C38/$C$39 -> 0.98998214 | F38: ='DNDC-P'!$J$16 -> 0.0025991906 | G38: ='Entry Profile L&F'!F37+'Entry Profile L&F'!F38 -> 99531569 | H38: =G38/$G$39 -> 0.99894637 | J38: ='DNDC-P'!$J$20 -> 0.0055421713 | K38: ='Entry Profile P'!$B$26+'Entry Profile P'!$C$26+'Entry Profile P'!$D$26 -> 1175.3681 | L38: =K38/$K$39 -> 0.95984512
A39: Total | C39: =SUM(C36:C38) -> 1.373334e+08 | D39: =SUM(D36:D38) -> 1 | G39: =SUM(G36:G38) -> 99636549 | H39: =SUM(H36:H38) -> 1 | K39: =SUM(K36:K38) -> 1224.5393 | L39: =SUM(L36:L38) -> 1
A40: Weighted Average | B40: =SUMPRODUCT(B36:B38,C36:C38)/SUM(C36:C38) -> 0.0082720274 | F40: =SUMPRODUCT(F36:F38,G36:G38)/SUM(G36:G38) -> 0.0026272155 | J40: =SUMPRODUCT(J36:J38,K36:K38)/SUM(K36:K38) -> 0.005978035
B43: Cost Per | F43: Cost Per | J43: Cost Per
A44: DSCF Container Type | B44: Pound | C44: Pounds | D44: Percent | F44: Pound | G44: Pounds | H44: Percent | J44: Pound | K44: Pounds | L44: Percent
A45: Sack | B45: 0 | C45: 0 | D45: =C45/$C$48 -> 0 | F45: ='DSCF-S'!$K$13 -> 0.11871403 | G45: ='Entry Profile L&F'!$H$39 -> 10531183 | H45: =G45/$G$48 -> 0.0096889116 | J45: ='DSCF-S'!$K$18 -> 0.065364269 | K45: ='Entry Profile P'!$E$27 -> 1075.8682 | L45: =K45/$K$48 -> 0.94158418
A46: Tray | B46: ='DSCF-T'!$K$13 -> 0.11159983 | C46: ='Entry Profile L&F'!$D$39 -> 27113157 | D46: =C46/$C$48 -> 0.01776911 | F46: 0 | G46: 0 | H46: =G46/$G$48 -> 0 | J46: 0 | K46: 0 | L46: =K46/$K$48 -> 0
A47: Pallet | B47: ='DSCF-P'!$J$13 -> 0.0093852089 | C47: ='Entry Profile L&F'!$B$39 -> 1.4987458e+09 | D47: =C47/$C$48 -> 0.98223089 | F47: ='DSCF-P'!$J$18 -> 0.004881955 | G47: ='Entry Profile L&F'!$F$39 -> 1.0764003e+09 | H47: =G47/$G$48 -> 0.99031109 | J47: ='DSCF-P'!$J$23 -> 0.0080500247 | K47: ='Entry Profile P'!$B$27+'Entry Profile P'!$C$27+'Entry Profile P'!$D$27 -> 66.746793 | L47: =K47/$K$48 -> 0.058415819
A48: Total | C48: =SUM(C45:C47) -> 1.525859e+09 | D48: =SUM(D45:D47) -> 1 | G48: =SUM(G45:G47) -> 1.0869315e+09 | H48: =SUM(H45:H47) -> 1 | K48: =SUM(K45:K47) -> 1142.615 | L48: =SUM(L45:L47) -> 1
A49: Weighted Average | B49: =SUMPRODUCT(B45:B47,C45:C47)/SUM(C45:C47) -> 0.011201472 | F49: =SUMPRODUCT(F45:F47,G45:G47)/SUM(G45:G47) -> 0.005984864 | J49: =SUMPRODUCT(J45:J47,K45:K47)/SUM(K45:K47) -> 0.062016211
A51: [1] Pages 12-26
...

Sheet ODU-S
A1: ORIGINATING DELIVERY UNIT SACKS
C4: [1] | D4: [2] | E4: [3] | F4: [4] | G4: [5] | H4: [6] | I4: [7] | J4: [8] | K4: [9]
H5: Adjusted | J5: Pieces | K5: Cost
E6: Sacks Per | F6: Pieces | G6: Units | H6: Wage | I6: Piggyback | J6: Per | K6: Per
A7: Facility | B7: Operation | C7: Probability | D7: Shape | E7: Container | F7: Per Sack | G7: Per Hour | H7: Rate | I7: Factor | J7: Pound | K7: Pound
A10: ODU | B10: Load APC | C10: =SUM('Sack Inputs F'!$F$17:$F$21) -> 1 | D10: Flat | E10: ='Entry Profile P'!$B$39 -> 14.820735 | F10: ='Other Inputs'!$G$14 -> 150.62976 | G10: =Productivity!$C$14 -> 307.66823 | H10: ='Other Inputs'!$G$7 -> 48.864673 | I10: ='Piggyback Factors'!$D$48 -> 1.6214861 | J10: ='Entry Profile L&F'!$I$33 -> 5.567135 | K10: =(C10*H10*I10*J10)/(E10*F10*G10) -> 0.0006422096
A12: ODU | B12: Load APC | C12: =SUM('Sack Inputs P'!$F$17:$F$21) -> 1 | D12: Parcel | E12: ='Entry Profile P'!$B$39 -> 14.820735 | F12: ='Entry Profile P'!$E$31 -> 48.787028 | G12: =Productivity!$C$14 -> 307.66823 | H12: ='Other Inputs'!$G$8 -> 49.154263 | I12: ='Piggyback Factors'!$D$48 -> 1.6214861 | J12: ='CS Data By Shape'!$D$6/'CS Data By Shape'!$D$7 -> 2.3690648 | K12: =(C12*H12*I12*J12)/(E12*F12*G12) -> 0.00084877891
A15: Sources:
A16: [1]: Pages 27 and 28
A17: [2]: Mail Piece Shape
A18: [3]: Page 36
A19: [4]: Pages 36 and 42
A20: [5]: Page 41
A21: [6]: Page 42
A22: [7]: Page 40
A23: [8]: Pages 35 and 37
A24: [9]: ( [1] * [6] * [7] * [8] ) / ( [3] * [4] * [5] )

Sheet ODU-T
A1: ORIGINATING DELIVERY UNIT TRAYS
C4: [1] | D4: [2] | E4: [3] | F4: [4] | G4: [5] | H4: [6] | I4: [7] | J4: [8] | K4: [9]
H5: Adjusted | J5: Pieces | K5: Cost
E6: Trays Per | F6: Pieces | G6: Units | H6: Wage | I6: Piggyback | J6: Per | K6: Per
A7: Facility | B7: Operation | C7: Probability | D7: Shape | E7: Container | F7: Per Tray | G7: Per Hour | H7: Rate | I7: Factor | J7: Pound | K7: Pound
A10: ODU | B10: Load APC | C10: =SUM('Tray Inputs L'!$F$16:$F$20) -> 1 | D10: Letter | E10: ='Other Inputs'!$G$20 -> 24 | F10: ='Other Inputs'!$G$15 -> 315.12979 | G10: =Productivity!$C$14 -> 307.66823 | H10: ='Other Inputs'!$G$6 -> 48.808841 | I10: ='Piggyback Factors'!$D$48 -> 1.6214861 | J10: ='Entry Profile L&F'!$E$33 -> 0 | K10: =(C10*H10*I10*J10)/(E10*F10*G10) -> 0
A13: Sources:
A14: [1]: Page 29
A15: [2]: Mail Piece Shape
A16: [3]: Page 42
A17: [4]: Page 42
A18: [5]: Page 41
A19: [6]: Page 42
A20: [7]: Page 40
A21: [8]: Page 35
A22: [9]: ( [1] * [6] * [7] * [8] ) / ( [3] * [4] * [5] )

Sheet ODU-P
A1: ORIGINATING DELIVERY UNIT PALLETS
C4: [1] | D4: [2] | E4: [3] | F4: [4] | G4: [5] | H4: [6] | I4: [7] | J4: [8]
G5: Adjusted | I5: Pieces | J5: Cost
E6: Pieces | F6: Units | G6: Wage | H6: Piggyback | I6: Per | J6: Per
A7: Facility | B7: Operation | C7: Probability | D7: Shape | E7: Per Pallet | F7: Per Hour | G7: Rate | H7: Factor | I7: Pound | J7: Pound
A10: ODU | B10: Load Pallet | C10: =SUM('Pallet Inputs L'!$F$16:$F$20) -> 1 | D10: Letter | E10: ='Other Inputs'!$G$16 -> 8651.6571 | F10: =Productivity!$C$15 -> 68.564044 | G10: ='Other Inputs'!$G$6 -> 48.808841 | H10: ='Piggyback Factors'!$D$48 -> 1.6214861 | I10: ='Entry Profile L&F'!$C$33 -> 0 | J10: =(C10*G10*H10*I10)/(E10*F10) -> 0
A12: ODU | B12: Load Pallet | C12: =SUM('Pallet Inputs F'!$F$16:$F$20) -> 1 | D12: Flat | E12: ='Other Inputs'!$G$17 -> 4487.1819 | F12: =Productivity!$C$15 -> 68.564044 | G12: ='Other Inputs'!$G$7 -> 48.864673 | H12: ='Piggyback Factors'!$D$48 -> 1.6214861 | I12: ='Entry Profile L&F'!$G$33 -> 3.7282759 | J12: =(C12*G12*H12*I12)/(E12*F12) -> 0.00096016564
A14: ODU | B14: Load Pallet | C14: =SUM('Pallet Inputs P'!$F$16:$F$20) -> 1 | D14: Parcel | E14: ='Entry Profile P'!$C$34 -> 1150.5803 | F14: =Productivity!$C$15 -> 68.564044 | G14: ='Other Inputs'!$G$8 -> 49.154263 | H14: ='Piggyback Factors'!$D$48 -> 1.6214861 | I14: ='CS Data By Shape'!$D$6/'CS Data By Shape'!$D$7 -> 2.3690648 | J14: =(C14*G14*H14*I14)/(E14*F14) -> 0.002393525
A17: Sources:
A18: [1]: Pages 30, 31, and 32
A19: [2]: Mail Piece Shape
A20: [3]: Pages 36 and 42
A21: [4]: Page 41
A22: [5]: Page 42
A23: [6]: Page 40
A24: [7]: Page 35 and 37
A25: [8]: ( [1] * [5] * [6] * [7] ) / ( [3] * [4] )

Sheet OSCF-S
A1: ORIGINATING SCF SACKS
C4: [1] | D4: [2] | E4: [3] | F4: [4] | G4: [5] | H4: [6] | I4: [7] | J4: [8] | K4: [9]
H5: Adjusted | J5: Pieces | K5: Cost
E6: Sacks Per | F6: Pieces | G6: Units | H6: Wage | I6: Piggyback | J6: Per | K6: Per
A7: Facility | B7: Operation | C7: Probability | D7: Shape | E7: Container | F7: Per Sack | G7: Per Hour | H7: Rate | I7: Factor | J7: Pound | K7: Pound
A10: OSCF | B10: Load APC | C10: ='Sack Inputs F'!$F$41 -> 0.98372804 | D10: Flat | E10: ='Entry Profile P'!$B$39 -> 14.820735 | F10: ='Other Inputs'!$G$14 -> 150.62976 | G10: =Productivity!$C$19 -> 91.071588 | H10: ='Other Inputs'!$G$7 -> 48.864673 | I10: ='Piggyback Factors'!$D$27 -> 1.3606062 | J10: =('Entry Profile L&F'!$H$20+'Entry Profile L&F'!$H$21)/('Entry Profile L&F'!$H$34+'Entry Profile L&F'!$H$35) -> 5.9355037 | K10: =(C10*H10*I10*J10)/(E10*F10*G10) -> 0.0019093988
A11: OSCF | B11: Sort Sacks | C11: ='Sack Inputs F'!$F$42 -> 0.016271959 | D11: Flat | E11: 1 | F11: ='Other Inputs'!$G$14 -> 150.62976 | G11: =Productivity!$C$12 -> 50.702917 | H11: ='Other Inputs'!$G$7 -> 48.864673 | I11: ='Piggyback Factors'!$D$30 -> 1.2805163 | J11: =('Entry Profile L&F'!$H$20+'Entry Profile L&F'!$H$21)/('Entry Profile L&F'!$H$34+'Entry Profile L&F'!$H$35) -> 5.9355037 | K11: =(C11*H11*I11*J11)/(E11*F11*G11) -> 0.00079128657
A12: OSCF | B12: Load APC | C12: ='Sack Inputs F'!$F$42 -> 0.016271959 | D12: Flat | E12: ='Entry Profile P'!$B$39 -> 14.820735 | F12: ='Other Inputs'!$G$14 -> 150.62976 | G12: =Productivity!$C$19 -> 91.071588 | H12: ='Other Inputs'!$G$7 -> 48.864673 | I12: ='Piggyback Factors'!$D$27 -> 1.3606062 | J12: =('Entry Profile L&F'!$H$20+'Entry Profile L&F'!$H$21)/('Entry Profile L&F'!$H$34+'Entry Profile L&F'!$H$35) -> 5.9355037 | K12: =(C12*H12*I12*J12)/(E12*F12*G12) -> 3.1583584e-05
K13: =SUM(K10:K12) -> 0.0027322689
A15: OSCF | B15: Load APC | C15: ='Sack Inputs P'!$F$41 -> 0.67057226 | D15: Parcel | E15: ='Entry Profile P'!$B$39 -> 14.820735 | F15: ='Entry Profile P'!$E$31 -> 48.787028 | G15: =Productivity!$C$19 -> 91.071588 | H15: ='Other Inputs'!$G$8 -> 49.154263 | I15: ='Piggyback Factors'!$D$27 -> 1.3606062 | J15: ='CS Data By Shape'!$D$6/'CS Data By Shape'!$D$7 -> 2.3690648 | K15: =(C15*H15*I15*J15)/(E15*F15*G15) -> 0.0016134634
A16: OSCF | B16: Sort Sacks | C16: ='Sack Inputs P'!$F$42 -> 0.32942774 | D16: Parcel | E16: 1 | F16: ='Entry Profile P'!$E$31 -> 48.787028 | G16: =Productivity!$C$12 -> 50.702917 | H16: ='Other Inputs'!$G$8 -> 49.154263 | I16: ='Piggyback Factors'!$D$30 -> 1.2805163 | J16: ='CS Data By Shape'!$D$6/'CS Data By Shape'!$D$7 -> 2.3690648 | K16: =(C16*H16*I16*J16)/(E16*F16*G16) -> 0.019858484
A17: OSCF | B17: Load APC | C17: ='Sack Inputs P'!$F$42 -> 0.32942774 | D17: Parcel | E17: ='Entry Profile P'!$B$39 -> 14.820735 | F17: ='Entry Profile P'!$E$31 -> 48.787028 | G17: =Productivity!$C$19 -> 91.071588 | H17: ='Other Inputs'!$G$8 -> 49.154263 | I17: ='Piggyback Factors'!$D$27 -> 1.3606062 | J17: ='CS Data By Shape'!$D$6/'CS Data By Shape'!$D$7 -> 2.3690648 | K17: =(C17*H17*I17*J17)/(E17*F17*G17) -> 0.00079263586
K18: =SUM(K15:K17) -> 0.022264583
A21: Sources:
A22: [1]: Pages 27 and 28
A23: [2]: Mail Piece Shape
A24: [3]: Page 36
A25: [4]: Pages 36 and 42
A26: [5]: Page 41
A27: [6]: Page 42
A28: [7]: Page 40
A29: [8]: Pages 35 and 37
A30: [9]: ( [1] * [6] * [7] * [8] ) / ( [3] * [4] * [5] )

Sheet OSCF-T
A1: ORIGINATING SCF TRAYS
C4: [1] | D4: [2] | E4: [3] | F4: [4] | G4: [5] | H4: [6] | I4: [7] | J4: [8] | K4: [9]
H5: Adjusted | J5: Pieces | K5: Cost
E6: Trays Per | F6: Pieces | G6: Units | H6: Wage | I6: Piggyback | J6: Per | K6: Per
A7: Facility | B7: Operation | C7: Probability | D7: Shape | E7: Container | F7: Per Tray | G7: Per Hour | H7: Rate | I7: Factor | J7: Pound | K7: Pound
A10: OSCF | B10: Unload APC | C10: ='Tray Inputs L'!$F$40 -> 1 | D10: Letter | E10: ='Other Inputs'!$G$20 -> 24 | F10: ='Other Inputs'!$G$15 -> 315.12979 | G10: =Productivity!$C$16 -> 81.873572 | H10: ='Other Inputs'!$G$6 -> 48.808841 | I10: ='Piggyback Factors'!$D$27 -> 1.3606062 | J10: =('Entry Profile L&F'!$D$20+'Entry Profile L&F'!$D$21)/('Entry Profile L&F'!$D$34+'Entry Profile L&F'!$D$35) -> 29.066387 | K10: =(C10*H10*I10*J10)/(E10*F10*G10) -> 0.0031172924
A11: OSCF | B11: Sort Trays | C11: ='Tray Inputs L'!$F$41 -> 0 | D11: Letter | E11: 1 | F11: ='Other Inputs'!$G$15 -> 315.12979 | G11: =Productivity!C10 -> 92.988321 | H11: ='Other Inputs'!$G$6 -> 48.808841 | I11: ='Piggyback Factors'!$D$20 -> 1.5358045 | J11: =('Entry Profile L&F'!$D$20+'Entry Profile L&F'!$D$21)/('Entry Profile L&F'!$D$34+'Entry Profile L&F'!$D$35) -> 29.066387 | K11: =(C11*H11*I11*J11)/(E11*F11*G11) -> 0
A12: OSCF | B12: Load APC | C12: ='Tray Inputs L'!$F$41 -> 0 | D12: Letter | E12: ='Other Inputs'!$G$20 -> 24 | F12: ='Other Inputs'!$G$15 -> 315.12979 | G12: =Productivity!$C$19 -> 91.071588 | H12: ='Other Inputs'!$G$6 -> 48.808841 | I12: ='Piggyback Factors'!$D$27 -> 1.3606062 | J12: =('Entry Profile L&F'!$D$20+'Entry Profile L&F'!$D$21)/('Entry Profile L&F'!$D$34+'Entry Profile L&F'!$D$35) -> 29.066387 | K12: =(C12*H12*I12*J12)/(E12*F12*G12) -> 0
K13: =SUM(K10:K12) -> 0.0031172924
A16: Sources:
A17: [1]: Page 29
A18: [2]: Mail Piece Shape
A19: [3]: Page 42
A20: [4]: Page 42
A21: [5]: Page 41
A22: [6]: Page 42
A23: [7]: Page 40
A24: [8]: Page 35
A25: [9]: ( [1] * [6] * [7] * [8] ) / ( [3] * [4] * [5] )

Sheet OSCF-P
A1: ORIGINATING SCF PALLETS
C4: [1] | D4: [2] | E4: [3] | F4: [4] | G4: [5] | H4: [6] | I4: [7] | J4: [8]
G5: Adjusted | I5: Pieces | J5: Cost
E6: Pieces | F6: Units | G6: Wage | H6: Piggyback | I6: Per | J6: Per
A7: Facility | B7: Operation | C7: Probability | D7: Shape | E7: Per Pallet | F7: Per Hour | G7: Rate | H7: Factor | I7: Pound | J7: Pound
A10: OSCF | B10: Unload Pallet | C10: =SUM('Pallet Inputs L'!$F$22:$F$25) -> 1 | D10: Letter | E10: ='Other Inputs'!$G$16 -> 8651.6571 | F10: =Productivity!$C$17 -> 58.156985 | G10: ='Other Inputs'!$G$6 -> 48.808841 | H10: ='Piggyback Factors'!$D$27 -> 1.3606062 | I10: =('Entry Profile L&F'!$B$20+'Entry Profile L&F'!$B$21)/('Entry Profile L&F'!$B$34+'Entry Profile L&F'!$B$35) -> 24.788266 | J10: =(C10*G10*H10*I10)/(E10*F10) -> 0.0032717183
A11: OSCF | B11: Crossdock Pallet | C11: =SUM('Pallet Inputs L'!$F$22:$F$25) -> 1 | D11: Letter | E11: ='Other Inputs'!$G$16 -> 8651.6571 | F11: =Productivity!$C$18 -> 39.899251 | G11: ='Other Inputs'!$G$6 -> 48.808841 | H11: ='Piggyback Factors'!$D$27 -> 1.3606062 | I11: =('Entry Profile L&F'!$B$20+'Entry Profile L&F'!$B$21)/('Entry Profile L&F'!$B$34+'Entry Profile L&F'!$B$35) -> 24.788266 | J11: =(C11*G11*H11*I11)/(E11*F11) -> 0.0047688432
A12: OSCF | B12: Load Pallet | C12: =SUM('Pallet Inputs L'!$F$22:$F$25) -> 1 | D12: Letter | E12: ='Other Inputs'!$G$16 -> 8651.6571 | F12: =Productivity!$C$20 -> 61.728449 | G12: ='Other Inputs'!$G$6 -> 48.808841 | H12: ='Piggyback Factors'!$D$27 -> 1.3606062 | I12: =('Entry Profile L&F'!$B$20+'Entry Profile L&F'!$B$21)/('Entry Profile L&F'!$B$34+'Entry Profile L&F'!$B$35) -> 24.788266 | J12: =(C12*G12*H12*I12)/(E12*F12) -> 0.0030824243
J13: =SUM(J10:J12) -> 0.011122986
