Workbook

Sheet CRA ADJ UNIT COSTS-Hardcoded 
A1: FIRST-CLASS PRESORT FLATS MAIL PROCESSING UNIT COST SUMMARY
A2: This sheet contains identical but harcoded data from the 'CRA ADJ UNIT COSTS' to prevent any errors while linking to other spreadsheets.
A3: While linking, click File -> Options -> Formulas -> and check the radio button for "Enable Iterative Calculation".
A5: CRA FLATS MAIL PROCESSING UNIT COSTS
B7: Proportional Worksharing Related Cost Pools | F7: 62.274536 | G7: (1)
B8: Worksharing Related Fixed Cost Pools | F8: 9.3384898 | G8: (2)
B9: Non Worksharing Related Fixed Costs | F9: 0.13683503 | G9: (3)
B10: Total | F10: 71.749861 | G10: (4)
A12: CRA PROPORTIONAL ADJUSTMENT FACTOR
D14: (5) | E14: (6) | F14: (7)
E16: FY | F16: FY
B17: Base Model Costs | D17: Model Cost | E17: Volume | F17: Volume %
C18: Nonauto Presort | D18: 20.544372 | E18: 7939550 | F18: 0.018344708
C19: Mixed ADC Auto Presort | D19: 21.187227 | E19: 42124580 | F19: 0.097330847
C20: ADC Auto Presort | D20: 16.431415 | E20: 35262554 | F20: 0.08147581
C21: 3-Digit Auto Presort | D21: 12.925919 | E21: 1.7220086e+08 | F21: 0.39787829
C22: 5-Digit Auto Presort | D22: 8.2198461 | E22: 1.7527029e+08 | F22: 0.40497035
A23: (8) | B23: Total Weighted Model Cost | D23: 12.249551 | E23: 4.3279784e+08 | F23: 1
B25: CRA Proportional Adjustment | F25: 5.0838221 | G25: (9)
IN26: .
A27: ADJUSTED FLATS MAIL PROCESSING UNIT COSTS (CENTS)
D29: (10) | E29: (11) | F29: (12) | G29: (13) | H29: (14) | I29: (15)
F30: WS Related | G30: Total WS Rel. | H30: NonWS Rel | I30: Total
D31: Model | E31: Proportional | F31: Fixed | G31: Mail Proc | H31: Mail Proc | I31: Mail Proc
B32: Rate Category | D32: Unit Cost | E32: Unit Cost | F32: Unit Cost | G32: Unit Cost | H32: Unit Cost | I32: Unit Cost
B34: Nonauto Presort | D34: 20.544372 | E34: 104.44393 | F34: 9.3384898 | G34: 113.78242 | H34: 0.13683503 | I34: 113.91926
B36: Mixed ADC Auto Presort | D36: 21.187227 | E36: 107.71209 | F36: 9.3384898 | G36: 117.05058 | H36: 0.13683503 | I36: 117.18742
B38: ADC Auto Presort | D38: 16.431415 | E38: 83.534393 | F38: 9.3384898 | G38: 92.872882 | H38: 0.13683503 | I38: 93.009717
B40: 3-Digit Auto Presort | D40: 12.925919 | E40: 65.713073 | F40: 9.3384898 | G40: 75.051563 | H40: 0.13683503 | I40: 75.188398
B42: 5-Digit Auto Presort | D42: 8.2198461 | E42: 41.788235 | F42: 9.3384898 | G42: 51.126725 | H42: 0.13683503 | I42: 51.26356
A45: Source:
A46: (1) | B46: Sum of proportional cost pools on 'CRA PRESORT FLATS' worksheet
A47: (2) | B47: Sum of worksharing related fixed cost pools on 'CRA PRESORT FLATS' worksheet
A48: (3) | B48: Sum of non-worksharing related fixed cost pools on 'CRA PRESORT FLATS' worksheet
A49: (4) | B49: (1) + (2) + (3)
A50: (5) | B50: Model costs from respective rate category "COST" spreadsheets
A51: (6) | B51: FY mail volumes from 'FY VOLUME NONAUTO' and 'FY VOLUME AUTO' worksheets
A52: (7) | B52: Rate Category (6) / Total (6)
A53: (8) | B53: Sum [ Rate Category (5) * (7) ]
A54: (9) | B54: (1) / (8)
...

Sheet CRA ADJ UNIT COSTS
A1: FIRST-CLASS PRESORT FLATS MAIL PROCESSING UNIT COST SUMMARY
A5: CRA FLATS MAIL PROCESSING UNIT COSTS
B7: Proportional Worksharing Related Cost Pools | F7: ='CRA PRESORT FLATS'!G80 -> 62.274536 | G7: ="(1)" -> (1)
B8: Worksharing Related Fixed Cost Pools | F8: ='CRA PRESORT FLATS'!H80 -> 9.3384898 | G8: ="(2)" -> (2)
B9: Non Worksharing Related Fixed Costs | F9: ='CRA PRESORT FLATS'!I80 -> 0.13683503 | G9: ="(3)" -> (3)
B10: Total | F10: =SUM(F7:F9) -> 71.749861 | G10: ="(4)" -> (4)
A12: CRA PROPORTIONAL ADJUSTMENT FACTOR
D14: ="(5)" -> (5) | E14: ="(6)" -> (6) | F14: ="(7)" -> (7)
E16: FY | F16: FY
B17: Base Model Costs | D17: Model Cost | E17: Volume | F17: Volume %
C18: Nonauto Presort | D18: ='NONAUTO COST'!K77 -> 20.544372 | E18: ='FY VOLUME NONAUTO'!E35 -> 7939550 | F18: =E18/E23 -> 0.018344708
C19: Mixed ADC Auto Presort | D19: ='MADC AUTO COST'!$K$77 -> 21.187227 | E19: ='FY VOLUME AUTO'!E12 -> 42124580 | F19: =E19/E23 -> 0.097330847
C20: ADC Auto Presort | D20: ='ADC AUTO COST'!$K$77 -> 16.431415 | E20: ='FY VOLUME AUTO'!E23 -> 35262554 | F20: =E20/E23 -> 0.08147581
C21: 3-Digit Auto Presort | D21: ='3D AUTO COST'!$K$77 -> 12.925919 | E21: ='FY VOLUME AUTO'!E36 -> 1.7220086e+08 | F21: =E21/E23 -> 0.39787829
C22: 5-Digit Auto Presort | D22: ='5D AUTO COST'!$K$77 -> 8.2198461 | E22: ='FY VOLUME AUTO'!E51 -> 1.7527029e+08 | F22: =E22/E23 -> 0.40497035
A23: ="(8)" -> (8) | B23: Total Weighted Model Cost | D23: =D18*F18+D19*F19+D20*F20+D21*F21+D22*F22 -> 12.249551 | E23: =SUM(E18:E22) -> 4.3279784e+08 | F23: =SUM(F18:F22) -> 1
B25: CRA Proportional Adjustment | F25: =F7/D23 -> 5.0838221 | G25: ="(9)" -> (9)
IN26: .
A27: ADJUSTED FLATS MAIL PROCESSING UNIT COSTS (CENTS)
D29: ="(10)" -> (10) | E29: ="(11)" -> (11) | F29: ="(12)" -> (12) | G29: ="(13)" -> (13) | H29: ="(14)" -> (14) | I29: ="(15)" -> (15)
F30: WS Related | G30: Total WS Rel. | H30: NonWS Rel | I30: Total
D31: Model | E31: Proportional | F31: Fixed | G31: Mail Proc | H31: Mail Proc | I31: Mail Proc
B32: Rate Category | D32: Unit Cost | E32: Unit Cost | F32: Unit Cost | G32: Unit Cost | H32: Unit Cost | I32: Unit Cost
B34: =C18 -> Nonauto Presort | D34: =D18 -> 20.544372 | E34: =$F$25*D34 -> 104.44393 | F34: =$F$8 -> 9.3384898 | G34: =E34+F34 -> 113.78242 | H34: =$F$9 -> 0.13683503 | I34: =G34+H34 -> 113.91926
B36: =C19 -> Mixed ADC Auto Presort | D36: =D19 -> 21.187227 | E36: =$F$25*D36 -> 107.71209 | F36: =$F$8 -> 9.3384898 | G36: =E36+F36 -> 117.05058 | H36: =$F$9 -> 0.13683503 | I36: =G36+H36 -> 117.18742
B38: =C20 -> ADC Auto Presort | D38: =D20 -> 16.431415 | E38: =$F$25*D38 -> 83.534393 | F38: =$F$8 -> 9.3384898 | G38: =E38+F38 -> 92.872882 | H38: =$F$9 -> 0.13683503 | I38: =G38+H38 -> 93.009717
B40: =C21 -> 3-Digit Auto Presort | D40: =D21 -> 12.925919 | E40: =$F$25*D40 -> 65.713073 | F40: =$F$8 -> 9.3384898 | G40: =E40+F40 -> 75.051563 | H40: =$F$9 -> 0.13683503 | I40: =G40+H40 -> 75.188398
B42: =C22 -> 5-Digit Auto Presort | D42: =D22 -> 8.2198461 | E42: =$F$25*D42 -> 41.788235 | F42: =$F$8 -> 9.3384898 | G42: =E42+F42 -> 51.126725 | H42: =$F$9 -> 0.13683503 | I42: =G42+H42 -> 51.26356
A45: Source:
A46: ="(1)" -> (1) | B46: Sum of proportional cost pools on 'CRA PRESORT FLATS' worksheet
A47: ="(2)" -> (2) | B47: Sum of worksharing related fixed cost pools on 'CRA PRESORT FLATS' worksheet
A48: ="(3)" -> (3) | B48: Sum of non-worksharing related fixed cost pools on 'CRA PRESORT FLATS' worksheet
A49: ="(4)" -> (4) | B49: (1) + (2) + (3)
A50: ="(5)" -> (5) | B50: Model costs from respective rate category "COST" spreadsheets
A51: ="(6)" -> (6) | B51: FY mail volumes from 'FY VOLUME NONAUTO' and 'FY VOLUME AUTO' worksheets
A52: ="(7)" -> (7) | B52: Rate Category (6) / Total (6)
A53: ="(8)" -> (8) | B53: Sum [ Rate Category (5) * (7) ]
A54: ="(9)" -> (9) | B54: (1) / (8)
A55: ="(10)" -> (10) | B55: Model costs from respective rate category "COST" spreadsheets
A56: ="(11)" -> (11) | B56: (9) * (10)
...

Sheet PRESORT LEVELS HELD CONSTANT
A1: FIRST-CLASS PRESORT FLATS MAIL PROCESSING UNIT COST SUMMARY
A2: PRESORT LEVELS HELD CONSTANT
A5: ADJUSTED FLATS MAIL PROCESSING UNIT COSTS (CENTS)
D7: ="(1)" -> (1) | E7: ="(2)" -> (2) | F7: ="(3)" -> (3) | G7: ="(4)" -> (4) | H7: (5) | I7: (6)
F8: WS related | G8: Total WS rel. | H8: NonWS Rel | I8: Total
D9: Model | E9: Proportional | F9: Fixed | G9: Mail Proc | H9: Mail Proc | I9: Mail Proc
B10: Rate Category | D10: Unit Cost | E10: Unit Cost | F10: Unit Cost | G10: Unit Cost | H10: Unit Cost | I10: Unit Cost
B12: Mixed ADC Nonauto Presort | D12: ='MADC NONAUTO COST'!$K$77 -> 23.111559 | E12: =D12*'CRA ADJ UNIT COSTS'!$F$25 -> 117.49505 | F12: ='CRA ADJ UNIT COSTS'!$F$8 -> 9.3384898 | G12: =E12+F12 -> 126.83354 | H12: ='CRA ADJ UNIT COSTS'!$F$9 -> 0.13683503 | I12: =G12+H12 -> 126.97038
B14: ADC Nonauto Presort | D14: ='ADC NONAUTO COST'!$K$77 -> 18.275515 | E14: =D14*'CRA ADJ UNIT COSTS'!$F$25 -> 92.909468 | F14: ='CRA ADJ UNIT COSTS'!$F$8 -> 9.3384898 | G14: =E14+F14 -> 102.24796 | H14: ='CRA ADJ UNIT COSTS'!$F$9 -> 0.13683503 | I14: =G14+H14 -> 102.38479
B16: 3-Digit Nonauto Presort | D16: ='3D NONAUTO COST'!$K$77 -> 14.858897 | E16: =D16*'CRA ADJ UNIT COSTS'!$F$25 -> 75.539987 | F16: ='CRA ADJ UNIT COSTS'!$F$8 -> 9.3384898 | G16: =E16+F16 -> 84.878477 | H16: ='CRA ADJ UNIT COSTS'!$F$9 -> 0.13683503 | I16: =G16+H16 -> 85.015312
B18: 5-Digit Nonauto Presort | D18: ='5D NONAUTO COST'!$K$77 -> 9.9702587 | E18: =D18*'CRA ADJ UNIT COSTS'!$F$25 -> 50.687022 | F18: ='CRA ADJ UNIT COSTS'!$F$8 -> 9.3384898 | G18: =E18+F18 -> 60.025512 | H18: ='CRA ADJ UNIT COSTS'!$F$9 -> 0.13683503 | I18: =G18+H18 -> 60.162347
B20: ='CRA ADJ UNIT COSTS'!C19 -> Mixed ADC Auto Presort | D20: ='CRA ADJ UNIT COSTS'!D19 -> 21.187227 | E20: =D20*'CRA ADJ UNIT COSTS'!$F$25 -> 107.71209 | F20: ='CRA ADJ UNIT COSTS'!$F$8 -> 9.3384898 | G20: =E20+F20 -> 117.05058 | H20: ='CRA ADJ UNIT COSTS'!$F$9 -> 0.13683503 | I20: =G20+H20 -> 117.18742
B22: ='CRA ADJ UNIT COSTS'!C20 -> ADC Auto Presort | D22: ='CRA ADJ UNIT COSTS'!D20 -> 16.431415 | E22: =D22*'CRA ADJ UNIT COSTS'!$F$25 -> 83.534393 | F22: ='CRA ADJ UNIT COSTS'!$F$8 -> 9.3384898 | G22: =E22+F22 -> 92.872882 | H22: ='CRA ADJ UNIT COSTS'!$F$9 -> 0.13683503 | I22: =G22+H22 -> 93.009717
B24: ='CRA ADJ UNIT COSTS'!C21 -> 3-Digit Auto Presort | D24: ='CRA ADJ UNIT COSTS'!D21 -> 12.925919 | E24: =D24*'CRA ADJ UNIT COSTS'!$F$25 -> 65.713073 | F24: ='CRA ADJ UNIT COSTS'!$F$8 -> 9.3384898 | G24: =E24+F24 -> 75.051563 | H24: ='CRA ADJ UNIT COSTS'!$F$9 -> 0.13683503 | I24: =G24+H24 -> 75.188398
B26: ='CRA ADJ UNIT COSTS'!C22 -> 5-Digit Auto Presort | D26: ='CRA ADJ UNIT COSTS'!D22 -> 8.2198461 | E26: =D26*'CRA ADJ UNIT COSTS'!$F$25 -> 41.788235 | F26: ='CRA ADJ UNIT COSTS'!$F$8 -> 9.3384898 | G26: =E26+F26 -> 51.126725 | H26: ='CRA ADJ UNIT COSTS'!$F$9 -> 0.13683503 | I26: =G26+H26 -> 51.26356
A29: ="(1)" -> (1) | B29: Model costs from respective rate category "COST" spreadsheets
A30: ="(2)" -> (2) | B30: (1) * [ (8) from 'CRA ADJ UNIT COSTS' ]
A31: ="(3)" -> (3) | B31: (2) from 'CRA ADJ UNIT COSTS'
A32: ="(4)" -> (4) | B32: (2) + (3)
A33: (5) | B33: Sum of Non-worksharing related Fixed costs.
A34: (6) | B34: (4)+(5)

Sheet OUT TRAY SORT FC C&L&F
A1: OUTGOING LETTER TRAY/FLAT TUB SORTING UNIT COST AVOIDANCE
D4: [1] | E4: [2] | F4: [3] | G4: [4] | H4: [5] | I4: [6] | J4: [7] | K4: [8] | L4: [9] | M4: [10] | N4: [11]
G5: Marginal
D6: Pieces | E6: Trays | F6: Volume | G6: Trays | I6: Direct | K6: Premium | L6: Premium | M6: Total | N6: Total
D7: Per | E7: Per | F7: Variability | G7: Per | H7: Wage | I7: Cents | J7: Piggyback | K7: Pay | L7: Pay | M7: Cents | N7: Cents
A8: Operation | C8: Product | D8: Tray/Tub | E8: Hour | F8: Factor | G8: Hour | H8: Rate | I8: Per Tray | J8: Factor | K8: Factor | L8: Adjust | M8: Per Tray | N8: Per Piece
A10: Outgoing Letter Tray Sort | C10: First-Class Mail Presort Cards | D10: =SUM('[1]FCM PCS PER TRAY'!$B$18:$B$20)/SUM('[1]FCM PCS PER TRAY'!$C$18:$C$20) -> 509.10861 | E10: =PRODUCTIVITIES!$C$7 -> 85.837148 | F10: =PRODUCTIVITIES!$B$7 -> 0.9497 | G10: =E10/F10 -> 90.383435 | H10: ='WAGE RATES'!$D$6 -> 50.107175 | I10: =H10*100/G10 -> 55.438449 | J10: =PIGGYBACKS!$B$14 -> 1.5358045 | K10: ='WAGE RATES'!C8 -> 1.0126974 | L10: =I10*(K10-1) -> 0.70392662 | M10: =I10*J10+L10 -> 85.846544 | N10: =M10/D10 -> 0.16862128
A11: Outgoing Letter Tray Sort | C11: First-Class Mail Presort Letters | D11: =SUM('[1]FCM PCS PER TRAY'!$B$10:$B$12)/SUM('[1]FCM PCS PER TRAY'!$C$10:$C$12) -> 247.3455 | E11: =PRODUCTIVITIES!$C$7 -> 85.837148 | F11: =PRODUCTIVITIES!$B$7 -> 0.9497 | G11: =E11/F11 -> 90.383435 | H11: ='WAGE RATES'!$D$6 -> 50.107175 | I11: =H11*100/G11 -> 55.438449 | J11: =PIGGYBACKS!$B$14 -> 1.5358045 | K11: ='WAGE RATES'!C9 -> 1.0210632 | L11: =I11*(K11-1) -> 1.167711 | M11: =I11*J11+L11 -> 86.310328 | N11: =M11/D11 -> 0.34894642
A12: Outgoing Flat Tub Sort | C12: First-Class Mail Presort Flats | D12: =SUM('[1]FCM PCS PER TRAY'!$C$30:$C$38)/SUM('[1]FCM PCS PER TRAY'!$D$30:$D$38) -> 51.222968 | E12: =PRODUCTIVITIES!$C$7 -> 85.837148 | F12: =PRODUCTIVITIES!$B$7 -> 0.9497 | G12: =E12/F12 -> 90.383435 | H12: ='WAGE RATES'!$D$6 -> 50.107175 | I12: =H12*100/G12 -> 55.438449 | J12: =PIGGYBACKS!$B$14 -> 1.5358045 | K12: ='WAGE RATES'!C10 -> 1.0289187 | L12: =I12*(K12-1) -> 1.6032098 | M12: =I12*J12+L12 -> 86.745827 | N12: =M12/D12 -> 1.6934948
A15: Sources:
A16: [1] | B16: USPS-FY25-14 Table MCS-16
A17: [2] | B17: Tab " PRODUCTIVITIES"
A18: [3] | B18: Tab 'WAGE RATES - PIGGYBACK FACTORS'
A19: [4] | B19: [2] / [3]
A20: [5] | B20: Tab 'WAGE RATES - PIGGYBACK FACTORS'
A21: [6] | B21: [5] * 100 / [4]
A22: [7] | B22: USPS-FY25-25
A23: [8] | B23: Tab 'WAGE RATES - PIGGYBACK FACTORS'
A24: [9] | B24: [6] * ( [8] - 1 )
A25: [10] | B25: [6] * [7] + [9]
A26: [11] | B26: [10] / [1]

Sheet CRA PRESORT FLATS
A1: CRA FIRST-CLASS PRESORT FLATS MAIL PROCESSING UNIT COSTS
A2: USPS-FY25-26
E5: Total
A6: Cost | E6: MP
A7: Pool | C7: Cost Pool | E7: Unit | G7: Work-sharing-Related
A8: No. | B8: Source | C8: Abbreviation | E8: Costs | G8: Proportional (Cents) | H8: Fixed (Cents) | I8: Non-WS Related (Cents) | K8: Key | L8: Treatment
E9: (1) | J9: 1 | K9: Piece Sorting | L9: Proportional
J10: 2 | K10: Fwd/Accept/Cust.Srv. | L10: WS Fixed
A11: 1 | B11: MODS 11 | C11: D/BCS | D11: =IF($M$12=1,4,3) -> 4 | E11: ='[2]FLAT Unit Costs W Final Adj'!$E$6 -> 1.1272592 | G11: =IF($M$12=1,$E11*G$83,0) -> 0.97839275 | H11: =IF($M$12=1,$E11*H$83,0) -> 0.14671664 | I11: =IF($M$12=1,$E11*I$83,E11) -> 0.0021498096 | J11: 3 | K11: Non-WS | L11: Non WS
J12: 4 | K12: Unexpected | L12: =IF(M12=1,"Piggybacked","Non WS") -> Piggybacked | M12: 1
A13: 3 | B13: MODS 12 | C13: AFSM100 | D13: 1 | E13: ='[2]FLAT Unit Costs W Final Adj'!$E$7 -> 30.215422 | G13: =E13 -> 30.215422 | J13: 5 | K13: Allied/Support | L13: Piggybacked
A14: 4 | B14: MODS 12 | C14: FSS | D14: 1 | E14: 0 | G14: =E14 -> 0
A17: 7 | B17: MODS 13 | C17: APBS BUNDLE | D17: 1 | E17: ='[2]FLAT Unit Costs W Final Adj'!E9 -> 0.2062359 | G17: =E17 -> 0.2062359 | K17: Note: OPBULK, OPPREF and Pouching
A18: 8 | B18: MODS 13 | C18: APBSPRIO | D18: 1 | E18: ='[2]FLAT Unit Costs W Final Adj'!E10 -> 1.2154889 | G18: =E18 -> 1.2154889 | K18: were WS related fixed in 3 column system,
A19: 9 | B19: MODS 16 | C19: LCUS-SSM | D19: 5 | E19: ='[2]FLAT Unit Costs W Final Adj'!E11 -> 0.70835712 | G19: =$E19*G$83 -> 0.6148111 | H19: =$E19*H$83 -> 0.092195102 | I19: =$E19*I$83 -> 0.0013509164 | K19: are grouped with prep and accept
A20: 10 | B20: MODS 16 | C20: 1TRAYSRT | D20: 5 | E20: ='[2]FLAT Unit Costs W Final Adj'!E12 -> 2.3674793 | G20: =$E20*G$83 -> 2.0548287 | H20: =$E20*H$83 -> 0.30813553 | I20: =$E20*I$83 -> 0.0045150484
A21: 11 | B21: MODS 14 | C21: MANF | D21: 1 | E21: ='[2]FLAT Unit Costs W Final Adj'!E13 -> 3.2575517 | G21: =E21 -> 3.2575517
A22: 12 | B22: MODS 14 | C22: MANL | D22: =IF($M$12=1,4,3) -> 4 | E22: ='[2]FLAT Unit Costs W Final Adj'!E14 -> 0.41846347 | G22: =IF($M$12=1,$E22*G$83,0) -> 0.36320096 | H22: =IF($M$12=1,$E22*H$83,0) -> 0.054464452 | I22: =IF($M$12=1,$E22*I$83,E22) -> 0.00079805675
A23: 13 | B23: MODS 14 | C23: MANP | D23: =IF($M$12=1,4,3) -> 4 | E23: ='[2]FLAT Unit Costs W Final Adj'!E15 -> 0.0014324584 | G23: =IF($M$12=1,$E23*G$83,0) -> 0.0012432872 | H23: =IF($M$12=1,$E23*H$83,0) -> 0.00018643936 | I23: =IF($M$12=1,$E23*I$83,E23) -> 2.7318587e-06
A24: 14 | B24: MODS 14 | C24: PRIORITY | D24: =IF($M$12=1,4,3) -> 4 | E24: ='[2]FLAT Unit Costs W Final Adj'!E16 -> 0.33800046 | G24: =IF($M$12=1,$E24*G$83,0) -> 0.29336394 | H24: =IF($M$12=1,$E24*H$83,0) -> 0.043991916 | I24: =IF($M$12=1,$E24*I$83,E24) -> 0.00064460477
A25: 15 | B25: MODS 15 | C25: LD15 | D25: =IF($M$12=1,4,3) -> 4 | E25: ='[2]FLAT Unit Costs W Final Adj'!E17 -> 0.10180843 | G25: =IF($M$12=1,$E25*G$83,0) -> 0.088363554 | H25: =IF($M$12=1,$E25*H$83,0) -> 0.013250715 | I25: =IF($M$12=1,$E25*I$83,E25) -> 0.00019416009
A26: 16 | B26: MODS 17 | C26: 1CANCEL | D26: 2 | E26: ='[2]FLAT Unit Costs W Final Adj'!E18 -> 1.7467164 | H26: =E26 -> 1.7467164
A27: 17 | B27: MODS 17 | C27: 1DSPATCH | D27: 2 | E27: ='[2]FLAT Unit Costs W Final Adj'!E19 -> 0.26912676 | H27: =E27 -> 0.26912676
A29: 19 | B29: MODS 17 | C29: 1MTRPREP | D29: 2 | E29: ='[2]FLAT Unit Costs W Final Adj'!E20 -> 0 | H29: =E29 -> 0
A30: 20 | B30: MODS 17 | C30: 1OPBULK | D30: 2 | E30: ='[2]FLAT Unit Costs W Final Adj'!E21 -> 0.12579919 | H30: =E30 -> 0.12579919
A31: 21 | B31: MODS 17 | C31: 1OPPREF | D31: 2 | E31: ='[2]FLAT Unit Costs W Final Adj'!E22 -> 1.7180085 | H31: =E31 -> 1.7180085
A32: 22 | B32: MODS 17 | C32: 1OPTRANS | D32: 5 | E32: ='[2]FLAT Unit Costs W Final Adj'!E23 -> 0.065282666 | G32: =$E32*G$83 -> 0.056661402 | H32: =$E32*H$83 -> 0.0084967622 | I32: =$E32*I$83 -> 0.00012450136
A33: 23 | B33: MODS 17 | C33: 1PLATFRM | D33: 5 | E33: ='[2]FLAT Unit Costs W Final Adj'!E24 -> 9.6866678 | G33: =$E33*G$83 -> 8.4074413 | H33: =$E33*H$83 -> 1.2607529 | I33: =$E33*I$83 -> 0.018473561
A34: 24 | B34: MODS 17 | C34: 1POUCHNG | D34: 2 | E34: ='[2]FLAT Unit Costs W Final Adj'!E25 -> 0.083184343 | H34: =E34 -> 0.083184343
A35: 25 | B35: MODS 17 | C35: 1PRESORT | D35: 5 | E35: ='[2]FLAT Unit Costs W Final Adj'!E26 -> 0.063063595 | G35: =$E35*G$83 -> 0.054735383 | H35: =$E35*H$83 -> 0.0082079425 | I35: =$E35*I$83 -> 0.00012026934
A36: 26 | B36: MODS 17 | C36: 1SACKS_H | D36: 5 | E36: ='[2]FLAT Unit Costs W Final Adj'!E27 -> 0.03793679 | G36: =$E36*G$83 -> 0.032926837 | H36: =$E36*H$83 -> 0.0049376029 | I36: =$E36*I$83 -> 7.234971e-05
A37: 27 | B37: MODS 17 | C37: 1SCAN | D37: 2 | E37: ='[2]FLAT Unit Costs W Final Adj'!E28 -> 0.35322378 | H37: =E37 -> 0.35322378
A38: 28 | B38: MODS 18 | C38: BUSREPLY | D38: 3 | E38: ='[2]FLAT Unit Costs W Final Adj'!E29 -> 0.063474976 | I38: =E38 -> 0.063474976
A39: 29 | B39: MODS 18 | C39: EXPRESS | D39: =IF($M$12=1,4,3) -> 4 | E39: ='[2]FLAT Unit Costs W Final Adj'!E30 -> 0.25146952 | G39: =IF($M$12=1,$E39*G$83,0) -> 0.21826032 | H39: =IF($M$12=1,$E39*H$83,0) -> 0.032729618 | I39: =IF($M$12=1,$E39*I$83,E39) -> 0.00047958056
A41: 31 | B41: MODS 18 | C41: REGISTRY | D41: 3 | E41: ='[2]FLAT Unit Costs W Final Adj'!E31 -> 0.026764577 | I41: =E41 -> 0.026764577
A42: 32 | B42: MODS 18 | C42: REWRAP | D42: 2 | E42: ='[2]FLAT Unit Costs W Final Adj'!E32 -> 0.045210846 | H42: =E42 -> 0.045210846
A43: 33 | B43: MODS 18 | C43: 1EEQMT | D43: 5 | E43: ='[2]FLAT Unit Costs W Final Adj'!E33 -> 0.34043531 | G43: =$E43*G$83 -> 0.29547725 | H43: =$E43*H$83 -> 0.044308821 | I43: =$E43*I$83 -> 0.0006492483
A44: 34 | B44: MODS 18 | C44: 1MISC | D44: 5 | E44: ='[2]FLAT Unit Costs W Final Adj'!E34 -> 0.1366616 | G44: =$E44*G$83 -> 0.118614 | H44: =$E44*H$83 -> 0.017786975 | I44: =$E44*I$83 -> 0.00026062899
A45: 35 | B45: MODS 18 | C45: 1SUPPORT | D45: 5 | E45: ='[2]FLAT Unit Costs W Final Adj'!E35 -> 0.15321664 | G45: =$E45*G$83 -> 0.13298277 | H45: =$E45*H$83 -> 0.01994167 | I45: =$E45*I$83 -> 0.00029220131
A46: 36 | B46: MODS 19 | C46: INTL ISC | D46: =IF($M$12=1,4,3) -> 4 | E46: ='[2]FLAT Unit Costs W Final Adj'!E36 -> 0 | G46: =IF($M$12=1,$E46*G$83,0) -> 0 | H46: =IF($M$12=1,$E46*H$83,0) -> 0 | I46: =IF($M$12=1,$E46*I$83,E46) -> 0
...

Sheet BUNDLE OPS SUMMARY
A1: FIRST-CLASS MAIL PARCEL ADDITIONAL MAIL PROCESSING UNIT COST SUMMARY
G2: Parcel Cost Proxy
B3: ="(1)" -> (1) | C3: ="(2)" -> (2) | E3: ="(3)" -> (3) | G3: ="(4)" -> (4) | H3: ="(5)" -> (5) | J3: Note: Column J data was removed as it provided MP costs of FCM parcels which are classified as Competitive products this year. This column is not needed for pricing this year and is therefore redundant.
E4: Average | G4: Bundle Operations | H4: Additional
B5: FY | C5: FY | E5: First-Class Mail | G5: Piece Distribution | H5: Unit Cost
A6: Rate Category | B6: Volume | C6: Volume (%) | E6: Flat (Cents) | G6: (Cents) | H6: (Cents)
A8: Nonautomation | B8: ='FY VOLUME NONAUTO'!E35 -> 7939550 | C8: =B8/$B$18 -> 0.018344708 | E8: ='CRA ADJ UNIT COSTS'!$G$34 -> 113.78242 | G8: =(((SUM('FY VOLUME NONAUTO'!E7:E11)+SUM('FY VOLUME NONAUTO'!E21:E25))*'OP BUNDLE OPS'!K33+(SUM('FY VOLUME NONAUTO'!E12:E15)+SUM('FY VOLUME NONAUTO'!E26:E29))*'MMP BUNDLE OPS'!K33+(SUM('FY VOLUME NONAUTO'!E16:E18)+SUM('FY VOLUME NONAUTO'!E30:E32))*'3D BUNDLE OPS'!K33+(SUM('FY VOLUME NONAUTO'!E19:E20)+SUM('FY VOLUME NONAUTO'!E33:E34))*'5D BUNDLE OPS'!K33)/'FY VOLUME NONAUTO'!E35)*'CRA ADJ UNIT COSTS'!F25+'CRA ADJ UNIT COSTS'!F8 -> 661.48614 | H8: =G8-E8 -> 547.70371
A10: Automation MADC | B10: ='FY VOLUME AUTO'!E12 -> 42124580 | C10: =B10/$B$18 -> 0.097330847 | E10: ='CRA ADJ UNIT COSTS'!G36 -> 117.05058 | G10: ='OP BUNDLE OPS'!K33*'CRA ADJ UNIT COSTS'!F25+'CRA ADJ UNIT COSTS'!F8 -> 739.40159 | H10: =G10-E10 -> 622.35101
A12: Automation ADC | B12: ='FY VOLUME AUTO'!E23 -> 35262554 | C12: =B12/$B$18 -> 0.08147581 | E12: ='CRA ADJ UNIT COSTS'!G38 -> 92.872882 | G12: ='MMP BUNDLE OPS'!K33*'CRA ADJ UNIT COSTS'!F25+'CRA ADJ UNIT COSTS'!F8 -> 515.96646 | H12: =G12-E12 -> 423.09358
A14: Automation 3-Digit | B14: ='FY VOLUME AUTO'!E36 -> 1.7220086e+08 | C14: =B14/$B$18 -> 0.39787829 | E14: ='CRA ADJ UNIT COSTS'!G40 -> 75.051563 | G14: ='3D BUNDLE OPS'!K33*'CRA ADJ UNIT COSTS'!F25+'CRA ADJ UNIT COSTS'!F8 -> 381.91494 | H14: =G14-E14 -> 306.86338
A16: Automation 5-Digit | B16: ='FY VOLUME AUTO'!E51 -> 1.7527029e+08 | C16: =B16/$B$18 -> 0.40497035 | E16: ='CRA ADJ UNIT COSTS'!G42 -> 51.126725 | G16: ='5D BUNDLE OPS'!K33*'CRA ADJ UNIT COSTS'!F25+'CRA ADJ UNIT COSTS'!F8 -> 269.54384 | H16: =G16-E16 -> 218.41712
A18: Total / Aggregate | B18: =SUM(B8:B16) -> 4.3279784e+08 | C18: =SUM(C8:C16) -> 1 | E18: =SUMPRODUCT(C8:C16,E8:E16) -> 71.613026 | G18: =SUMPRODUCT(C8:C16,G8:G16) -> 387.25307 | H18: =G18-E18 -> 315.64004
A21: (1) FY mail volumes from 'FY VOLUME NONAUTO' and 'FY VOLUME AUTO' worksheets
A22: (2) Rate Category (1) / Total (1)
A23: (3) Average CRA-adjusted flats mail processing unit cost estimate by rate category from page 1
A24: (4) Model costs (pages 5 through 8) * proportional CRA adjustment factor (page 1) + fixed CRA adjustment factor (page 1)
A25: Note: The nonautomation model cost is the weighted average of models costs on pages 5 through 8 using
A26: FY mail volume data from 'FY VOLUME NONAUTO' worksheets
A27: (5) (4) - (3)

Sheet OP BUNDLE OPS
A1: OUTGOING PRIMARY (BUNDLE OPS PIECE DISTRIBUTION)
A2: COST SHEET
C4: ="(1)" -> (1) | D4: ="(2)" -> (2) | E4: ="(3)" -> (3) | F4: ="(4)" -> (4) | G4: ="(5)" -> (5) | H4: ="(6)" -> (6) | I4: ="(7)" -> (7) | J4: ="(8)" -> (8) | K4: ="(9)" -> (9)
D6: Bundles | F6: Direct | H6: Premium | I6: Premium | J6: Total | K6: Weighted
D7: or Pieces | E7: Wage | F7: Cents | G7: Piggyback | H7: Pay | I7: Pay | J7: Cents | K7: Cents
A8: Operation | C8: Volume | D8: Per Hour | E8: Rate | F8: Per Piece | G8: Factor | H8: Factor | I8: Adjust | J8: Per Piece | K8: Per Piece
A10: Outgoing Primary (Bundle Ops)
B11: APPS | C11: =10000*'COVERAGE FACTORS'!C7 -> 4132.2615 | D11: =PRODUCTIVITIES!$E$8 -> 175.66894 | E11: ='WAGE RATES'!$D$6 -> 50.107175 | F11: =E11*100/D11 -> 28.523639 | G11: =PIGGYBACKS!$B$5 -> 1.8052502 | H11: ='WAGE RATES'!$D$10 -> 1.0285306 | I11: =(H11-1)*F11 -> 0.81379702 | J11: =F11*G11+I11 -> 52.306103 | K11: =C11*J11/10000 -> 21.614249
B12: APBS / LIPS | C12: =10000*'COVERAGE FACTORS'!C9 -> 5795.3241 | D12: =PRODUCTIVITIES!$E$10 -> 194.60203 | E12: ='WAGE RATES'!$D$6 -> 50.107175 | F12: =E12*100/D12 -> 25.748537 | G12: =PIGGYBACKS!$B$6 -> 1.6056413 | H12: ='WAGE RATES'!$D$10 -> 1.0285306 | I12: =(H12-1)*F12 -> 0.73462165 | J12: =F12*G12+I12 -> 42.077535 | K12: =C12*J12/10000 -> 24.385295
B13: Manual | C13: =10000*'COVERAGE FACTORS'!C11 -> 72.414474 | D13: =PRODUCTIVITIES!$E$12 -> 388.77899 | E13: ='WAGE RATES'!$D$6 -> 50.107175 | F13: =E13*100/D13 -> 12.888344 | G13: =PIGGYBACKS!$B$7 -> 1.5985379 | H13: ='WAGE RATES'!$D$10 -> 1.0285306 | I13: =(H13-1)*F13 -> 0.36771242 | J13: =F13*G13+I13 -> 20.970219 | K13: =C13*J13/10000 -> 0.15185474
A15: Incoming MMP (Bundle Ops)
B16: APPS | C16: =SUM($C$11:$C$13)*'BUNDLE DENSITIES'!$K$8*'COVERAGE FACTORS'!C31 -> 4161.3205 | D16: =PRODUCTIVITIES!$E$9 -> 204.15275 | E16: ='WAGE RATES'!$D$6 -> 50.107175 | F16: =E16*100/D16 -> 24.543962 | G16: =PIGGYBACKS!$B$5 -> 1.8052502 | H16: ='WAGE RATES'!$D$10 -> 1.0285306 | I16: =(H16-1)*F16 -> 0.70025439 | J16: =F16*G16+I16 -> 45.008248 | K16: =C16*J16/10000 -> 18.729375
B17: APBS / LIPS | C17: =SUM($C$11:$C$13)*'BUNDLE DENSITIES'!$K$8*'COVERAGE FACTORS'!C33 -> 5049.042 | D17: =PRODUCTIVITIES!$E$11 -> 163.71091 | E17: ='WAGE RATES'!$D$6 -> 50.107175 | F17: =E17*100/D17 -> 30.607108 | G17: =PIGGYBACKS!$B$6 -> 1.6056413 | H17: ='WAGE RATES'!$D$10 -> 1.0285306 | I17: =(H17-1)*F17 -> 0.87323969 | J17: =F17*G17+I17 -> 50.017276 | K17: =C17*J17/10000 -> 25.253932
B18: Manual | C18: =SUM($C$11:$C$13)*'BUNDLE DENSITIES'!$K$8*'COVERAGE FACTORS'!C35 -> 292.55904 | D18: =PRODUCTIVITIES!$E$13 -> 388.77899 | E18: ='WAGE RATES'!$D$6 -> 50.107175 | F18: =E18*100/D18 -> 12.888344 | G18: =PIGGYBACKS!$B$7 -> 1.5985379 | H18: ='WAGE RATES'!$D$10 -> 1.0285306 | I18: =(H18-1)*F18 -> 0.36771242 | J18: =F18*G18+I18 -> 20.970219 | K18: =C18*J18/10000 -> 0.61350272
A20: Incoming Primary (Bundle Ops)
B21: APPS | C21: =(SUM($C$11:$C$13)*'BUNDLE DENSITIES'!$K$9+SUM($C$16:$C$18)*'BUNDLE DENSITIES'!$K$16)*'COVERAGE FACTORS'!C31 -> 331.62639 | D21: =PRODUCTIVITIES!$E$9 -> 204.15275 | E21: ='WAGE RATES'!$D$6 -> 50.107175 | F21: =E21*100/D21 -> 24.543962 | G21: =PIGGYBACKS!$B$5 -> 1.8052502 | H21: ='WAGE RATES'!$D$10 -> 1.0285306 | I21: =(H21-1)*F21 -> 0.70025439 | J21: =F21*G21+I21 -> 45.008248 | K21: =C21*J21/10000 -> 1.4925923
B22: APBS / LIPS | C22: =(SUM($C$11:$C$13)*'BUNDLE DENSITIES'!$K$9+SUM($C$16:$C$18)*'BUNDLE DENSITIES'!$K$16)*'COVERAGE FACTORS'!C33 -> 402.37122 | D22: =PRODUCTIVITIES!$E$11 -> 163.71091 | E22: ='WAGE RATES'!$D$6 -> 50.107175 | F22: =E22*100/D22 -> 30.607108 | G22: =PIGGYBACKS!$B$6 -> 1.6056413 | H22: ='WAGE RATES'!$D$10 -> 1.0285306 | I22: =(H22-1)*F22 -> 0.87323969 | J22: =F22*G22+I22 -> 50.017276 | K22: =C22*J22/10000 -> 2.0125512
B23: Manual | C23: =(SUM($C$11:$C$13)*'BUNDLE DENSITIES'!$K$9+SUM($C$16:$C$18)*'BUNDLE DENSITIES'!$K$16)*'COVERAGE FACTORS'!C35 -> 23.314787 | D23: =PRODUCTIVITIES!$E$14 -> 388.77899 | E23: ='WAGE RATES'!$D$6 -> 50.107175 | F23: =E23*100/D23 -> 12.888344 | G23: =PIGGYBACKS!$B$7 -> 1.5985379 | H23: ='WAGE RATES'!$D$10 -> 1.0285306 | I23: =(H23-1)*F23 -> 0.36771242 | J23: =F23*G23+I23 -> 20.970219 | K23: =C23*J23/10000 -> 0.048891619
A25: Incoming Secondary (Bundle Ops)
B26: APPS | C26: =(SUM($C$11:$C$13)*'BUNDLE DENSITIES'!$K$10+SUM($C$16:$C$18)*'BUNDLE DENSITIES'!$K$17+SUM($C$21:$C$23)*'BUNDLE DENSITIES'!$K$23)*'BUNDLE DATA'!$D$44*'COVERAGE FACTORS'!$C$31/('COVERAGE FACTORS'!$C$31+'COVERAGE FACTORS'!$C$33) -> 0 | D26: =PRODUCTIVITIES!$E$9 -> 204.15275 | E26: ='WAGE RATES'!$D$6 -> 50.107175 | F26: =E26*100/D26 -> 24.543962 | G26: =PIGGYBACKS!$B$5 -> 1.8052502 | H26: ='WAGE RATES'!$D$10 -> 1.0285306 | I26: =(H26-1)*F26 -> 0.70025439 | J26: =F26*G26+I26 -> 45.008248 | K26: =C26*J26/10000 -> 0
B27: APBS / LIPS | C27: =(SUM($C$11:$C$13)*'BUNDLE DENSITIES'!$K$10+SUM($C$16:$C$18)*'BUNDLE DENSITIES'!$K$17+SUM($C$21:$C$23)*'BUNDLE DENSITIES'!$K$23)*'BUNDLE DATA'!$D$44*'COVERAGE FACTORS'!$C$33/('COVERAGE FACTORS'!$C$31+'COVERAGE FACTORS'!$C$33) -> 0 | D27: =PRODUCTIVITIES!$E$11 -> 163.71091 | E27: ='WAGE RATES'!$D$6 -> 50.107175 | F27: =E27*100/D27 -> 30.607108 | G27: =PIGGYBACKS!$B$6 -> 1.6056413 | H27: ='WAGE RATES'!$D$10 -> 1.0285306 | I27: =(H27-1)*F27 -> 0.87323969 | J27: =F27*G27+I27 -> 50.017276 | K27: =C27*J27/10000 -> 0
B28: Manual | C28: =(SUM($C$11:$C$13)*'BUNDLE DENSITIES'!$K$10+SUM($C$16:$C$18)*'BUNDLE DENSITIES'!$K$17+SUM($C$21:$C$23)*'BUNDLE DENSITIES'!$K$23)*(1-'BUNDLE DATA'!$D$44) -> 9356.2845 | D28: =PRODUCTIVITIES!E15 -> 279.1383 | E28: ='WAGE RATES'!$D$6 -> 50.107175 | F28: =E28*100/D28 -> 17.950663 | G28: =PIGGYBACKS!$B$7 -> 1.5985379 | H28: ='WAGE RATES'!$D$10 -> 1.0285306 | I28: =(H28-1)*F28 -> 0.51214348 | J28: =F28*G28+I28 -> 29.206957 | K28: =C28*J28/10000 -> 27.32686
A30: Incoming Secondary (Piece Ops) | C30: 10000 | D30: =PRODUCTIVITIES!E48 -> 307.67541 | E30: ='WAGE RATES'!D6 -> 50.107175 | F30: =E30*100/D30 -> 16.285726 | G30: =PIGGYBACKS!B13 -> 1.3208756 | H30: ='WAGE RATES'!$D$10 -> 1.0285306 | I30: =(H30-1)*F30 -> 0.46464181 | J30: =F30*G30+I30 -> 21.97606 | K30: =C30*J30/10000 -> 21.97606
K32: ="(10)" -> (10)
J33: MODEL COST = | K33: =SUM(K11:K30) -> 143.60516
A35: ="(1)" -> (1) | B35: Bundle data', 'Bundle densities' and 'Coverage factors' | F35: ="(6)" -> (6) | G35: Values From 'Wage Rates' worksheet
B36: used to flow 10,000 pieces through model | F36: ="(7)" -> (7) | G36: [ (6) - 1 ] * (4)
A37: ="(2)" -> (2) | B37: Values From 'Productivities' worksheet | F37: ="(8)" -> (8) | G37: (4) * (5) + (7)
A38: ="(3)" -> (3) | B38: Values From 'Wage Rates' worksheet | F38: ="(9)" -> (9) | G38: (1) * (8) / 10,000 Pieces
A39: ="(4)" -> (4) | B39: [ (3) * (100 cents/dollar) ] / (2) | F39: ="(10)" -> (10) | G39: Sum (9)
A40: ="(5)" -> (5) | B40: Values From 'Piggybacks' worksheet

Sheet MMP BUNDLE OPS
A1: INCOMING MMP (BUNDLE OPS PIECE DISTRIBUTION)
A2: COST SHEET
C4: ="(1)" -> (1) | D4: ="(2)" -> (2) | E4: ="(3)" -> (3) | F4: ="(4)" -> (4) | G4: ="(5)" -> (5) | H4: ="(6)" -> (6) | I4: ="(7)" -> (7) | J4: ="(8)" -> (8) | K4: ="(9)" -> (9)
D6: Bundles | F6: Direct | H6: Premium | I6: Premium | J6: Total | K6: Weighted
D7: or Pieces | E7: Wage | F7: Cents | G7: Piggyback | H7: Pay | I7: Pay | J7: Cents | K7: Cents
A8: Operation | C8: Volume | D8: Per Hour | E8: Rate | F8: Per Piece | G8: Factor | H8: Factor | I8: Adjust | J8: Per Piece | K8: Per Piece
A10: Outgoing Primary (Bundle Ops)
B11: APPS | C11: 0 | D11: =PRODUCTIVITIES!$E$8 -> 175.66894 | E11: ='WAGE RATES'!$D$6 -> 50.107175 | F11: =E11*100/D11 -> 28.523639 | G11: =PIGGYBACKS!$B$5 -> 1.8052502 | H11: ='WAGE RATES'!$D$10 -> 1.0285306 | I11: =(H11-1)*F11 -> 0.81379702 | J11: =F11*G11+I11 -> 52.306103 | K11: =C11*J11/10000 -> 0
B12: APBS / LIPS | C12: 0 | D12: =PRODUCTIVITIES!$E$10 -> 194.60203 | E12: ='WAGE RATES'!$D$6 -> 50.107175 | F12: =E12*100/D12 -> 25.748537 | G12: =PIGGYBACKS!$B$6 -> 1.6056413 | H12: ='WAGE RATES'!$D$10 -> 1.0285306 | I12: =(H12-1)*F12 -> 0.73462165 | J12: =F12*G12+I12 -> 42.077535 | K12: =C12*J12/10000 -> 0
B13: Manual | C13: 0 | D13: =PRODUCTIVITIES!$E$12 -> 388.77899 | E13: ='WAGE RATES'!$D$6 -> 50.107175 | F13: =E13*100/D13 -> 12.888344 | G13: =PIGGYBACKS!$B$7 -> 1.5985379 | H13: ='WAGE RATES'!$D$10 -> 1.0285306 | I13: =(H13-1)*F13 -> 0.36771242 | J13: =F13*G13+I13 -> 20.970219 | K13: =C13*J13/10000 -> 0
A15: Incoming MMP (Bundle Ops)
B16: APPS | C16: =10000*'COVERAGE FACTORS'!$C$31 -> 4378.9907 | D16: =PRODUCTIVITIES!$E$9 -> 204.15275 | E16: ='WAGE RATES'!$D$6 -> 50.107175 | F16: =E16*100/D16 -> 24.543962 | G16: =PIGGYBACKS!$B$5 -> 1.8052502 | H16: ='WAGE RATES'!$D$10 -> 1.0285306 | I16: =(H16-1)*F16 -> 0.70025439 | J16: =F16*G16+I16 -> 45.008248 | K16: =C16*J16/10000 -> 19.70907
B17: APBS / LIPS | C17: =10000*'COVERAGE FACTORS'!$C$33 -> 5313.1471 | D17: =PRODUCTIVITIES!$E$11 -> 163.71091 | E17: ='WAGE RATES'!$D$6 -> 50.107175 | F17: =E17*100/D17 -> 30.607108 | G17: =PIGGYBACKS!$B$6 -> 1.6056413 | H17: ='WAGE RATES'!$D$10 -> 1.0285306 | I17: =(H17-1)*F17 -> 0.87323969 | J17: =F17*G17+I17 -> 50.017276 | K17: =C17*J17/10000 -> 26.574914
B18: Manual | C18: =10000*'COVERAGE FACTORS'!$C$35 -> 307.86221 | D18: =PRODUCTIVITIES!$E$13 -> 388.77899 | E18: ='WAGE RATES'!$D$6 -> 50.107175 | F18: =E18*100/D18 -> 12.888344 | G18: =PIGGYBACKS!$B$7 -> 1.5985379 | H18: ='WAGE RATES'!$D$10 -> 1.0285306 | I18: =(H18-1)*F18 -> 0.36771242 | J18: =F18*G18+I18 -> 20.970219 | K18: =C18*J18/10000 -> 0.6455938
A20: Incoming Primary (Bundle Ops)
B21: APPS | C21: =SUM($C$16:$C$18)*'BUNDLE DENSITIES'!$K$16*'COVERAGE FACTORS'!$C$31 -> 305.55572 | D21: =PRODUCTIVITIES!$E$9 -> 204.15275 | E21: ='WAGE RATES'!$D$6 -> 50.107175 | F21: =E21*100/D21 -> 24.543962 | G21: =PIGGYBACKS!$B$5 -> 1.8052502 | H21: ='WAGE RATES'!$D$10 -> 1.0285306 | I21: =(H21-1)*F21 -> 0.70025439 | J21: =F21*G21+I21 -> 45.008248 | K21: =C21*J21/10000 -> 1.3752528
B22: APBS / LIPS | C22: =SUM($C$16:$C$18)*'BUNDLE DENSITIES'!$K$16*'COVERAGE FACTORS'!$C$33 -> 370.73897 | D22: =PRODUCTIVITIES!$E$11 -> 163.71091 | E22: ='WAGE RATES'!$D$6 -> 50.107175 | F22: =E22*100/D22 -> 30.607108 | G22: =PIGGYBACKS!$B$6 -> 1.6056413 | H22: ='WAGE RATES'!$D$10 -> 1.0285306 | I22: =(H22-1)*F22 -> 0.87323969 | J22: =F22*G22+I22 -> 50.017276 | K22: =C22*J22/10000 -> 1.8543353
B23: Manual | C23: =SUM($C$16:$C$18)*'BUNDLE DENSITIES'!$K$16*'COVERAGE FACTORS'!$C$35 -> 21.481905 | D23: =PRODUCTIVITIES!$E$14 -> 388.77899 | E23: ='WAGE RATES'!$D$6 -> 50.107175 | F23: =E23*100/D23 -> 12.888344 | G23: =PIGGYBACKS!$B$7 -> 1.5985379 | H23: ='WAGE RATES'!$D$10 -> 1.0285306 | I23: =(H23-1)*F23 -> 0.36771242 | J23: =F23*G23+I23 -> 20.970219 | K23: =C23*J23/10000 -> 0.045048025
A25: Incoming Secondary (Bundle Ops)
B26: APPS | C26: =(SUM($C$16:$C$18)*'BUNDLE DENSITIES'!$K$17+SUM($C$21:$C$23)*'BUNDLE DENSITIES'!$K$23)*'BUNDLE DATA'!$D$44*'COVERAGE FACTORS'!$C$31/('COVERAGE FACTORS'!$C$31+'COVERAGE FACTORS'!$C$33) -> 0 | D26: =PRODUCTIVITIES!$E$9 -> 204.15275 | E26: ='WAGE RATES'!$D$6 -> 50.107175 | F26: =E26*100/D26 -> 24.543962 | G26: =PIGGYBACKS!$B$5 -> 1.8052502 | H26: ='WAGE RATES'!$D$10 -> 1.0285306 | I26: =(H26-1)*F26 -> 0.70025439 | J26: =F26*G26+I26 -> 45.008248 | K26: =C26*J26/10000 -> 0
B27: APBS / LIPS | C27: =(SUM($C$16:$C$18)*'BUNDLE DENSITIES'!$K$17+SUM($C$21:$C$23)*'BUNDLE DENSITIES'!$K$23)*'BUNDLE DATA'!$D$44*'COVERAGE FACTORS'!$C$33/('COVERAGE FACTORS'!$C$31+'COVERAGE FACTORS'!$C$33) -> 0 | D27: =PRODUCTIVITIES!$E$11 -> 163.71091 | E27: ='WAGE RATES'!$D$6 -> 50.107175 | F27: =E27*100/D27 -> 30.607108 | G27: =PIGGYBACKS!$B$6 -> 1.6056413 | H27: ='WAGE RATES'!$D$10 -> 1.0285306 | I27: =(H27-1)*F27 -> 0.87323969 | J27: =F27*G27+I27 -> 50.017276 | K27: =C27*J27/10000 -> 0
B28: Manual | C28: =(SUM($C$16:$C$18)*'BUNDLE DENSITIES'!$K$17+SUM($C$21:$C$23)*'BUNDLE DENSITIES'!$K$23)*(1-'BUNDLE DATA'!$D$44) -> 9406.8899 | D28: =PRODUCTIVITIES!E15 -> 279.1383 | E28: ='WAGE RATES'!$D$6 -> 50.107175 | F28: =E28*100/D28 -> 17.950663 | G28: =PIGGYBACKS!$B$7 -> 1.5985379 | H28: ='WAGE RATES'!$D$10 -> 1.0285306 | I28: =(H28-1)*F28 -> 0.51214348 | J28: =F28*G28+I28 -> 29.206957 | K28: =C28*J28/10000 -> 27.474663
A30: Incoming Secondary (Piece Ops) | C30: 10000 | D30: =PRODUCTIVITIES!E48 -> 307.67541 | E30: ='WAGE RATES'!D6 -> 50.107175 | F30: =E30*100/D30 -> 16.285726 | G30: =PIGGYBACKS!B13 -> 1.3208756 | H30: ='WAGE RATES'!$D$10 -> 1.0285306 | I30: =(H30-1)*F30 -> 0.46464181 | J30: =F30*G30+I30 -> 21.97606 | K30: =C30*J30/10000 -> 21.97606
K32: ="(10)" -> (10)
J33: MODEL COST = | K33: =SUM(K11:K30) -> 99.654937
A35: ="(1)" -> (1) | B35: Bundle data', 'Bundle densities' and 'Coverage factors' | F35: ="(6)" -> (6) | G35: Values From 'Wage Rates' worksheet
B36: used to flow 10,000 pieces through model | F36: ="(7)" -> (7) | G36: [ (6) - 1 ] * (4)
A37: ="(2)" -> (2) | B37: Values From 'Productivities' worksheet | F37: ="(8)" -> (8) | G37: (4) * (5) + (7)
A38: ="(3)" -> (3) | B38: Values From 'Wage Rates' worksheet | F38: ="(9)" -> (9) | G38: (1) * (8) / 10,000 Pieces
A39: ="(4)" -> (4) | B39: [ (3) * (100 cents/dollar) ] / (2) | F39: ="(10)" -> (10) | G39: Sum (9)
A40: ="(5)" -> (5) | B40: Values From 'Piggybacks' worksheet

Sheet 3D BUNDLE OPS
A1: INCOMING PRIMARY (BUNDLE OPS PIECE DISTRIBUTION)
A2: COST SHEET
C4: ="(1)" -> (1) | D4: ="(2)" -> (2) | E4: ="(3)" -> (3) | F4: ="(4)" -> (4) | G4: ="(5)" -> (5) | H4: ="(6)" -> (6) | I4: ="(7)" -> (7) | J4: ="(8)" -> (8) | K4: ="(9)" -> (9)
D6: Bundles | F6: Direct | H6: Premium | I6: Premium | J6: Total | K6: Weighted
D7: or Pieces | E7: Wage | F7: Cents | G7: Piggyback | H7: Pay | I7: Pay | J7: Cents | K7: Cents
A8: Operation | C8: Volume | D8: Per Hour | E8: Rate | F8: Per Piece | G8: Factor | H8: Factor | I8: Adjust | J8: Per Piece | K8: Per Piece
A10: Outgoing Primary (Bundle Ops)
B11: APPS | C11: 0 | D11: =PRODUCTIVITIES!$E$8 -> 175.66894 | E11: ='WAGE RATES'!$D$6 -> 50.107175 | F11: =E11*100/D11 -> 28.523639 | G11: =PIGGYBACKS!$B$5 -> 1.8052502 | H11: ='WAGE RATES'!$D$10 -> 1.0285306 | I11: =(H11-1)*F11 -> 0.81379702 | J11: =F11*G11+I11 -> 52.306103 | K11: =C11*J11/10000 -> 0
B12: APBS / LIPS | C12: 0 | D12: =PRODUCTIVITIES!$E$10 -> 194.60203 | E12: ='WAGE RATES'!$D$6 -> 50.107175 | F12: =E12*100/D12 -> 25.748537 | G12: =PIGGYBACKS!$B$6 -> 1.6056413 | H12: ='WAGE RATES'!$D$10 -> 1.0285306 | I12: =(H12-1)*F12 -> 0.73462165 | J12: =F12*G12+I12 -> 42.077535 | K12: =C12*J12/10000 -> 0
B13: Manual | C13: 0 | D13: =PRODUCTIVITIES!$E$12 -> 388.77899 | E13: ='WAGE RATES'!$D$6 -> 50.107175 | F13: =E13*100/D13 -> 12.888344 | G13: =PIGGYBACKS!$B$7 -> 1.5985379 | H13: ='WAGE RATES'!$D$10 -> 1.0285306 | I13: =(H13-1)*F13 -> 0.36771242 | J13: =F13*G13+I13 -> 20.970219 | K13: =C13*J13/10000 -> 0
A15: Incoming MMP (Bundle Ops)
B16: APPS | C16: 0 | D16: =PRODUCTIVITIES!$E$9 -> 204.15275 | E16: ='WAGE RATES'!$D$6 -> 50.107175 | F16: =E16*100/D16 -> 24.543962 | G16: =PIGGYBACKS!$B$5 -> 1.8052502 | H16: ='WAGE RATES'!$D$10 -> 1.0285306 | I16: =(H16-1)*F16 -> 0.70025439 | J16: =F16*G16+I16 -> 45.008248 | K16: =C16*J16/10000 -> 0
B17: APBS / LIPS | C17: 0 | D17: =PRODUCTIVITIES!$E$11 -> 163.71091 | E17: ='WAGE RATES'!$D$6 -> 50.107175 | F17: =E17*100/D17 -> 30.607108 | G17: =PIGGYBACKS!$B$6 -> 1.6056413 | H17: ='WAGE RATES'!$D$10 -> 1.0285306 | I17: =(H17-1)*F17 -> 0.87323969 | J17: =F17*G17+I17 -> 50.017276 | K17: =C17*J17/10000 -> 0
B18: Manual | C18: 0 | D18: =PRODUCTIVITIES!$E$13 -> 388.77899 | E18: ='WAGE RATES'!$D$6 -> 50.107175 | F18: =E18*100/D18 -> 12.888344 | G18: =PIGGYBACKS!$B$7 -> 1.5985379 | H18: ='WAGE RATES'!$D$10 -> 1.0285306 | I18: =(H18-1)*F18 -> 0.36771242 | J18: =F18*G18+I18 -> 20.970219 | K18: =C18*J18/10000 -> 0
A20: Incoming Primary (Bundle Ops)
B21: APPS | C21: =10000*'COVERAGE FACTORS'!$C$31 -> 4378.9907 | D21: =PRODUCTIVITIES!$E$9 -> 204.15275 | E21: ='WAGE RATES'!$D$6 -> 50.107175 | F21: =E21*100/D21 -> 24.543962 | G21: =PIGGYBACKS!$B$5 -> 1.8052502 | H21: ='WAGE RATES'!$D$10 -> 1.0285306 | I21: =(H21-1)*F21 -> 0.70025439 | J21: =F21*G21+I21 -> 45.008248 | K21: =C21*J21/10000 -> 19.70907
B22: APBS / LIPS | C22: =10000*'COVERAGE FACTORS'!$C$33 -> 5313.1471 | D22: =PRODUCTIVITIES!$E$11 -> 163.71091 | E22: ='WAGE RATES'!$D$6 -> 50.107175 | F22: =E22*100/D22 -> 30.607108 | G22: =PIGGYBACKS!$B$6 -> 1.6056413 | H22: ='WAGE RATES'!$D$10 -> 1.0285306 | I22: =(H22-1)*F22 -> 0.87323969 | J22: =F22*G22+I22 -> 50.017276 | K22: =C22*J22/10000 -> 26.574914
B23: Manual | C23: =10000*'COVERAGE FACTORS'!$C$35 -> 307.86221 | D23: =PRODUCTIVITIES!$E$14 -> 388.77899 | E23: ='WAGE RATES'!$D$6 -> 50.107175 | F23: =E23*100/D23 -> 12.888344 | G23: =PIGGYBACKS!$B$7 -> 1.5985379 | H23: ='WAGE RATES'!$D$10 -> 1.0285306 | I23: =(H23-1)*F23 -> 0.36771242 | J23: =F23*G23+I23 -> 20.970219 | K23: =C23*J23/10000 -> 0.6455938
A25: Incoming Secondary (Bundle Ops)
B26: APPS | C26: =SUM($C$21:$C$23)*'BUNDLE DENSITIES'!$K$23*'BUNDLE DATA'!$D$44*'COVERAGE FACTORS'!$C$31/('COVERAGE FACTORS'!$C$31+'COVERAGE FACTORS'!$C$33) -> 0 | D26: =PRODUCTIVITIES!$E$9 -> 204.15275 | E26: ='WAGE RATES'!$D$6 -> 50.107175 | F26: =E26*100/D26 -> 24.543962 | G26: =PIGGYBACKS!$B$5 -> 1.8052502 | H26: ='WAGE RATES'!$D$10 -> 1.0285306 | I26: =(H26-1)*F26 -> 0.70025439 | J26: =F26*G26+I26 -> 45.008248 | K26: =C26*J26/10000 -> 0
B27: APBS / LIPS | C27: =SUM($C$21:$C$23)*'BUNDLE DENSITIES'!$K$23*'BUNDLE DATA'!$D$44*'COVERAGE FACTORS'!$C$33/('COVERAGE FACTORS'!$C$31+'COVERAGE FACTORS'!$C$33) -> 0 | D27: =PRODUCTIVITIES!$E$11 -> 163.71091 | E27: ='WAGE RATES'!$D$6 -> 50.107175 | F27: =E27*100/D27 -> 30.607108 | G27: =PIGGYBACKS!$B$6 -> 1.6056413 | H27: ='WAGE RATES'!$D$10 -> 1.0285306 | I27: =(H27-1)*F27 -> 0.87323969 | J27: =F27*G27+I27 -> 50.017276 | K27: =C27*J27/10000 -> 0
B28: Manual | C28: =SUM($C$21:$C$23)*'BUNDLE DENSITIES'!$K$23*(1-'BUNDLE DATA'!$D$44) -> 1500 | D28: =PRODUCTIVITIES!E15 -> 279.1383 | E28: ='WAGE RATES'!$D$6 -> 50.107175 | F28: =E28*100/D28 -> 17.950663 | G28: =PIGGYBACKS!$B$7 -> 1.5985379 | H28: ='WAGE RATES'!$D$10 -> 1.0285306 | I28: =(H28-1)*F28 -> 0.51214348 | J28: =F28*G28+I28 -> 29.206957 | K28: =C28*J28/10000 -> 4.3810436
A30: Incoming Secondary (Piece Ops) | C30: 10000 | D30: =PRODUCTIVITIES!E48 -> 307.67541 | E30: ='WAGE RATES'!D6 -> 50.107175 | F30: =E30*100/D30 -> 16.285726 | G30: =PIGGYBACKS!B13 -> 1.3208756 | H30: ='WAGE RATES'!$D$10 -> 1.0285306 | I30: =(H30-1)*F30 -> 0.46464181 | J30: =F30*G30+I30 -> 21.97606 | K30: =C30*J30/10000 -> 21.97606
K32: ="(10)" -> (10)
J33: MODEL COST = | K33: =SUM(K11:K30) -> 73.286682
A35: ="(1)" -> (1) | B35: Bundle data', 'Bundle densities' and 'Coverage factors' | F35: ="(6)" -> (6) | G35: Values From 'Wage Rates' worksheet
B36: used to flow 10,000 pieces through model | F36: ="(7)" -> (7) | G36: [ (6) - 1 ] * (4)
A37: ="(2)" -> (2) | B37: Values From 'Productivities' worksheet | F37: ="(8)" -> (8) | G37: (4) * (5) + (7)
A38: ="(3)" -> (3) | B38: Values From 'Wage Rates' worksheet | F38: ="(9)" -> (9) | G38: (1) * (8) / 10,000 Pieces
A39: ="(4)" -> (4) | B39: [ (3) * (100 cents/dollar) ] / (2) | F39: ="(10)" -> (10) | G39: Sum (9)
A40: ="(5)" -> (5) | B40: Values From 'Piggybacks' worksheet

Sheet 5D BUNDLE OPS
A1: INCOMING SECONDARY (BUNDLE OPS PIECE DISTRIBUTION)
A2: COST SHEET
C4: ="(1)" -> (1) | D4: ="(2)" -> (2) | E4: ="(3)" -> (3) | F4: ="(4)" -> (4) | G4: ="(5)" -> (5) | H4: ="(6)" -> (6) | I4: ="(7)" -> (7) | J4: ="(8)" -> (8) | K4: ="(9)" -> (9)
D6: Bundles | F6: Direct | H6: Premium | I6: Premium | J6: Total | K6: Weighted
D7: or Pieces | E7: Wage | F7: Cents | G7: Piggyback | H7: Pay | I7: Pay | J7: Cents | K7: Cents
A8: Operation | C8: Volume | D8: Per Hour | E8: Rate | F8: Per Piece | G8: Factor | H8: Factor | I8: Adjust | J8: Per Piece | K8: Per Piece
A10: Outgoing Primary (Bundle Ops)
B11: APPS | C11: 0 | D11: =PRODUCTIVITIES!$E$8 -> 175.66894 | E11: ='WAGE RATES'!$D$6 -> 50.107175 | F11: =E11*100/D11 -> 28.523639 | G11: =PIGGYBACKS!$B$5 -> 1.8052502 | H11: ='WAGE RATES'!$D$10 -> 1.0285306 | I11: =(H11-1)*F11 -> 0.81379702 | J11: =F11*G11+I11 -> 52.306103 | K11: =C11*J11/10000 -> 0
B12: APBS / LIPS | C12: 0 | D12: =PRODUCTIVITIES!$E$10 -> 194.60203 | E12: ='WAGE RATES'!$D$6 -> 50.107175 | F12: =E12*100/D12 -> 25.748537 | G12: =PIGGYBACKS!$B$6 -> 1.6056413 | H12: ='WAGE RATES'!$D$10 -> 1.0285306 | I12: =(H12-1)*F12 -> 0.73462165 | J12: =F12*G12+I12 -> 42.077535 | K12: =C12*J12/10000 -> 0
B13: Manual | C13: 0 | D13: =PRODUCTIVITIES!$E$12 -> 388.77899 | E13: ='WAGE RATES'!$D$6 -> 50.107175 | F13: =E13*100/D13 -> 12.888344 | G13: =PIGGYBACKS!$B$7 -> 1.5985379 | H13: ='WAGE RATES'!$D$10 -> 1.0285306 | I13: =(H13-1)*F13 -> 0.36771242 | J13: =F13*G13+I13 -> 20.970219 | K13: =C13*J13/10000 -> 0
A15: Incoming MMP (Bundle Ops)
B16: APPS | C16: 0 | D16: =PRODUCTIVITIES!$E$9 -> 204.15275 | E16: ='WAGE RATES'!$D$6 -> 50.107175 | F16: =E16*100/D16 -> 24.543962 | G16: =PIGGYBACKS!$B$5 -> 1.8052502 | H16: ='WAGE RATES'!$D$10 -> 1.0285306 | I16: =(H16-1)*F16 -> 0.70025439 | J16: =F16*G16+I16 -> 45.008248 | K16: =C16*J16/10000 -> 0
B17: APBS / LIPS | C17: 0 | D17: =PRODUCTIVITIES!$E$11 -> 163.71091 | E17: ='WAGE RATES'!$D$6 -> 50.107175 | F17: =E17*100/D17 -> 30.607108 | G17: =PIGGYBACKS!$B$6 -> 1.6056413 | H17: ='WAGE RATES'!$D$10 -> 1.0285306 | I17: =(H17-1)*F17 -> 0.87323969 | J17: =F17*G17+I17 -> 50.017276 | K17: =C17*J17/10000 -> 0
B18: Manual | C18: 0 | D18: =PRODUCTIVITIES!$E$13 -> 388.77899 | E18: ='WAGE RATES'!$D$6 -> 50.107175 | F18: =E18*100/D18 -> 12.888344 | G18: =PIGGYBACKS!$B$7 -> 1.5985379 | H18: ='WAGE RATES'!$D$10 -> 1.0285306 | I18: =(H18-1)*F18 -> 0.36771242 | J18: =F18*G18+I18 -> 20.970219 | K18: =C18*J18/10000 -> 0
A20: Incoming Primary (Bundle Ops)
B21: APPS | C21: 0 | D21: =PRODUCTIVITIES!$E$9 -> 204.15275 | E21: ='WAGE RATES'!$D$6 -> 50.107175 | F21: =E21*100/D21 -> 24.543962 | G21: =PIGGYBACKS!$B$5 -> 1.8052502 | H21: ='WAGE RATES'!$D$10 -> 1.0285306 | I21: =(H21-1)*F21 -> 0.70025439 | J21: =F21*G21+I21 -> 45.008248 | K21: =C21*J21/10000 -> 0
B22: APBS / LIPS | C22: 0 | D22: =PRODUCTIVITIES!$E$11 -> 163.71091 | E22: ='WAGE RATES'!$D$6 -> 50.107175 | F22: =E22*100/D22 -> 30.607108 | G22: =PIGGYBACKS!$B$6 -> 1.6056413 | H22: ='WAGE RATES'!$D$10 -> 1.0285306 | I22: =(H22-1)*F22 -> 0.87323969 | J22: =F22*G22+I22 -> 50.017276 | K22: =C22*J22/10000 -> 0
B23: Manual | C23: 0 | D23: =PRODUCTIVITIES!$E$14 -> 388.77899 | E23: ='WAGE RATES'!$D$6 -> 50.107175 | F23: =E23*100/D23 -> 12.888344 | G23: =PIGGYBACKS!$B$7 -> 1.5985379 | H23: ='WAGE RATES'!$D$10 -> 1.0285306 | I23: =(H23-1)*F23 -> 0.36771242 | J23: =F23*G23+I23 -> 20.970219 | K23: =C23*J23/10000 -> 0
A25: Incoming Secondary (Bundle Ops)
B26: APPS | C26: =10000*'BUNDLE DATA'!$D$44*'COVERAGE FACTORS'!$C$31/('COVERAGE FACTORS'!$C$31+'COVERAGE FACTORS'!$C$33) -> 0 | D26: =PRODUCTIVITIES!$E$9 -> 204.15275 | E26: ='WAGE RATES'!$D$6 -> 50.107175 | F26: =E26*100/D26 -> 24.543962 | G26: =PIGGYBACKS!$B$5 -> 1.8052502 | H26: ='WAGE RATES'!$D$10 -> 1.0285306 | I26: =(H26-1)*F26 -> 0.70025439 | J26: =F26*G26+I26 -> 45.008248 | K26: =C26*J26/10000 -> 0
B27: APBS / LIPS | C27: =10000*'BUNDLE DATA'!$D$44*'COVERAGE FACTORS'!$C$33/('COVERAGE FACTORS'!$C$31+'COVERAGE FACTORS'!$C$33) -> 0 | D27: =PRODUCTIVITIES!$E$11 -> 163.71091 | E27: ='WAGE RATES'!$D$6 -> 50.107175 | F27: =E27*100/D27 -> 30.607108 | G27: =PIGGYBACKS!$B$6 -> 1.6056413 | H27: ='WAGE RATES'!$D$10 -> 1.0285306 | I27: =(H27-1)*F27 -> 0.87323969 | J27: =F27*G27+I27 -> 50.017276 | K27: =C27*J27/10000 -> 0
B28: Manual | C28: =10000*(1-'BUNDLE DATA'!$D$44) -> 10000 | D28: =PRODUCTIVITIES!E15 -> 279.1383 | E28: ='WAGE RATES'!$D$6 -> 50.107175 | F28: =E28*100/D28 -> 17.950663 | G28: =PIGGYBACKS!$B$7 -> 1.5985379 | H28: ='WAGE RATES'!$D$10 -> 1.0285306 | I28: =(H28-1)*F28 -> 0.51214348 | J28: =F28*G28+I28 -> 29.206957 | K28: =C28*J28/10000 -> 29.206957
A30: Incoming Secondary (Piece Ops) | C30: 10000 | D30: =PRODUCTIVITIES!E48 -> 307.67541 | E30: ='WAGE RATES'!D6 -> 50.107175 | F30: =E30*100/D30 -> 16.285726 | G30: =PIGGYBACKS!B13 -> 1.3208756 | H30: ='WAGE RATES'!$D$10 -> 1.0285306 | I30: =(H30-1)*F30 -> 0.46464181 | J30: =F30*G30+I30 -> 21.97606 | K30: =C30*J30/10000 -> 21.97606
K32: ="(10)" -> (10)
J33: MODEL COST = | K33: =SUM(K11:K30) -> 51.183017
A35: ="(1)" -> (1) | B35: Bundle data', 'Bundle densities' and 'Coverage factors' | F35: ="(6)" -> (6) | G35: Values From 'Wage Rates' worksheet
B36: used to flow 10,000 pieces through model | F36: ="(7)" -> (7) | G36: [ (6) - 1 ] * (4)
A37: ="(2)" -> (2) | B37: Values From 'Productivities' worksheet | F37: ="(8)" -> (8) | G37: (4) * (5) + (7)
A38: ="(3)" -> (3) | B38: Values From 'Wage Rates' worksheet | F38: ="(9)" -> (9) | G38: (1) * (8) / 10,000 Pieces
A39: ="(4)" -> (4) | B39: [ (3) * (100 cents/dollar) ] / (2) | F39: ="(10)" -> (10) | G39: Sum (9)
A40: ="(5)" -> (5) | B40: Values From 'Piggybacks' worksheet

Sheet NONAUTO COST
A1: NONAUTO PRESORT
A2: COST SHEET
C4: ="(1)" -> (1) | D4: ="(2)" -> (2) | E4: ="(3)" -> (3) | F4: ="(4)" -> (4) | G4: ="(5)" -> (5) | H4: ="(6)" -> (6) | I4: ="(7)" -> (7) | J4: ="(8)" -> (8) | K4: ="(9)" -> (9)
D6: Bundles | F6: Direct | H6: Premium | I6: Premium | J6: Total | K6: Weighted
D7: or Pieces | E7: Wage | F7: Cents | G7: Piggyback | H7: Pay | I7: Pay | J7: Cents | K7: Cents
A8: Operation | C8: Volume | D8: Per Hour | E8: Rate | F8: Per Piece | G8: Factor | H8: Factor | I8: Adjust | J8: Per Piece | K8: Per Piece
A10: Outgoing Primary (Bundles)
B11: APPS | C11: ='BUNDLE SORT'!$F$34*('COVERAGE FACTORS'!$C$7/('COVERAGE FACTORS'!$C$7+'COVERAGE FACTORS'!$C$9)) -> 0 | D11: =PRODUCTIVITIES!$E$8 -> 175.66894 | E11: ='WAGE RATES'!$D$6 -> 50.107175 | F11: =E11*100/D11 -> 28.523639 | G11: =PIGGYBACKS!$B$5 -> 1.8052502 | H11: ='WAGE RATES'!$D$10 -> 1.0285306 | I11: =(H11-1)*F11 -> 0.81379702 | J11: =F11*G11+I11 -> 52.306103 | K11: =C11*$J11/'NONAUTO MODEL'!$G$6 -> 0
B12: APBS / LIPS | C12: ='BUNDLE SORT'!$F$34*('COVERAGE FACTORS'!$C$9/('COVERAGE FACTORS'!$C$7+'COVERAGE FACTORS'!$C$9)) -> 0 | D12: =PRODUCTIVITIES!$E$10 -> 194.60203 | E12: ='WAGE RATES'!$D$6 -> 50.107175 | F12: =E12*100/D12 -> 25.748537 | G12: =PIGGYBACKS!$B$6 -> 1.6056413 | H12: ='WAGE RATES'!$D$10 -> 1.0285306 | I12: =(H12-1)*F12 -> 0.73462165 | J12: =F12*G12+I12 -> 42.077535 | K12: =C12*$J12/'NONAUTO MODEL'!$G$6 -> 0
B13: Manual | C13: ='BUNDLE SORT'!$G$34 -> 64.731693 | D13: =PRODUCTIVITIES!$E$12 -> 388.77899 | E13: ='WAGE RATES'!$D$6 -> 50.107175 | F13: =E13*100/D13 -> 12.888344 | G13: =PIGGYBACKS!$B$7 -> 1.5985379 | H13: ='WAGE RATES'!$D$10 -> 1.0285306 | I13: =(H13-1)*F13 -> 0.36771242 | J13: =F13*G13+I13 -> 20.970219 | K13: =C13*$J13/'NONAUTO MODEL'!$G$6 -> 0.13574378
A15: Incoming MMP (Bundles)
B16: APPS | C16: ='BUNDLE SORT'!$J$34*('COVERAGE FACTORS'!$C$31/('COVERAGE FACTORS'!$C$31+'COVERAGE FACTORS'!$C$33)) -> 27.865706 | D16: =PRODUCTIVITIES!$E$9 -> 204.15275 | E16: ='WAGE RATES'!$D$6 -> 50.107175 | F16: =E16*100/D16 -> 24.543962 | G16: =PIGGYBACKS!$B$5 -> 1.8052502 | H16: ='WAGE RATES'!$D$10 -> 1.0285306 | I16: =(H16-1)*F16 -> 0.70025439 | J16: =F16*G16+I16 -> 45.008248 | K16: =C16*$J16/'NONAUTO MODEL'!$G$6 -> 0.12541866
B17: APBS / LIPS | C17: ='BUNDLE SORT'!$J$34*('COVERAGE FACTORS'!$C$33/('COVERAGE FACTORS'!$C$31+'COVERAGE FACTORS'!$C$33)) -> 33.81021 | D17: =PRODUCTIVITIES!$E$11 -> 163.71091 | E17: ='WAGE RATES'!$D$6 -> 50.107175 | F17: =E17*100/D17 -> 30.607108 | G17: =PIGGYBACKS!$B$6 -> 1.6056413 | H17: ='WAGE RATES'!$D$10 -> 1.0285306 | I17: =(H17-1)*F17 -> 0.87323969 | J17: =F17*G17+I17 -> 50.017276 | K17: =C17*$J17/'NONAUTO MODEL'!$G$6 -> 0.16910946
B18: Manual | C18: ='BUNDLE SORT'!$K$34 -> 0 | D18: =PRODUCTIVITIES!$E$13 -> 388.77899 | E18: ='WAGE RATES'!$D$6 -> 50.107175 | F18: =E18*100/D18 -> 12.888344 | G18: =PIGGYBACKS!$B$7 -> 1.5985379 | H18: ='WAGE RATES'!$D$10 -> 1.0285306 | I18: =(H18-1)*F18 -> 0.36771242 | J18: =F18*G18+I18 -> 20.970219 | K18: =C18*$J18/'NONAUTO MODEL'!$G$6 -> 0
A20: Incoming Primary (Bundles)
B21: APPS | C21: ='BUNDLE SORT'!$N$34*('COVERAGE FACTORS'!$C$31/('COVERAGE FACTORS'!$C$31+'COVERAGE FACTORS'!$C$33)) -> 20.212886 | D21: =PRODUCTIVITIES!$E$9 -> 204.15275 | E21: ='WAGE RATES'!$D$6 -> 50.107175 | F21: =E21*100/D21 -> 24.543962 | G21: =PIGGYBACKS!$B$5 -> 1.8052502 | H21: ='WAGE RATES'!$D$10 -> 1.0285306 | I21: =(H21-1)*F21 -> 0.70025439 | J21: =F21*G21+I21 -> 45.008248 | K21: =C21*$J21/'NONAUTO MODEL'!$G$6 -> 0.090974661
B22: APBS / LIPS | C22: ='BUNDLE SORT'!$N$34*('COVERAGE FACTORS'!$C$33/('COVERAGE FACTORS'!$C$31+'COVERAGE FACTORS'!$C$33)) -> 24.524838 | D22: =PRODUCTIVITIES!$E$11 -> 163.71091 | E22: ='WAGE RATES'!$D$6 -> 50.107175 | F22: =E22*100/D22 -> 30.607108 | G22: =PIGGYBACKS!$B$6 -> 1.6056413 | H22: ='WAGE RATES'!$D$10 -> 1.0285306 | I22: =(H22-1)*F22 -> 0.87323969 | J22: =F22*G22+I22 -> 50.017276 | K22: =C22*$J22/'NONAUTO MODEL'!$G$6 -> 0.12266656
B23: Manual | C23: ='BUNDLE SORT'!$O$34 -> 1.4210544 | D23: =PRODUCTIVITIES!$E$14 -> 388.77899 | E23: ='WAGE RATES'!$D$6 -> 50.107175 | F23: =E23*100/D23 -> 12.888344 | G23: =PIGGYBACKS!$B$7 -> 1.5985379 | H23: ='WAGE RATES'!$D$10 -> 1.0285306 | I23: =(H23-1)*F23 -> 0.36771242 | J23: =F23*G23+I23 -> 20.970219 | K23: =C23*$J23/'NONAUTO MODEL'!$G$6 -> 0.0029799822
A25: Incoming Secondary (Bundles)
B26: APPS | C26: ='BUNDLE SORT'!$R$34*('COVERAGE FACTORS'!$C$31/('COVERAGE FACTORS'!$C$31+'COVERAGE FACTORS'!$C$33)) -> 0 | D26: =PRODUCTIVITIES!$E$9 -> 204.15275 | E26: ='WAGE RATES'!$D$6 -> 50.107175 | F26: =E26*100/D26 -> 24.543962 | G26: =PIGGYBACKS!$B$5 -> 1.8052502 | H26: ='WAGE RATES'!$D$10 -> 1.0285306 | I26: =(H26-1)*F26 -> 0.70025439 | J26: =F26*G26+I26 -> 45.008248 | K26: =C26*$J26/'NONAUTO MODEL'!$G$6 -> 0
B27: APBS / LIPS | C27: ='BUNDLE SORT'!$R$34*('COVERAGE FACTORS'!$C$33/('COVERAGE FACTORS'!$C$31+'COVERAGE FACTORS'!$C$33)) -> 0 | D27: =PRODUCTIVITIES!$E$11 -> 163.71091 | E27: ='WAGE RATES'!$D$6 -> 50.107175 | F27: =E27*100/D27 -> 30.607108 | G27: =PIGGYBACKS!$B$6 -> 1.6056413 | H27: ='WAGE RATES'!$D$10 -> 1.0285306 | I27: =(H27-1)*F27 -> 0.87323969 | J27: =F27*G27+I27 -> 50.017276 | K27: =C27*$J27/'NONAUTO MODEL'!$G$6 -> 0
B28: Manual | C28: ='BUNDLE SORT'!$S$34 -> 0 | D28: =PRODUCTIVITIES!E15 -> 279.1383 | E28: ='WAGE RATES'!$D$6 -> 50.107175 | F28: =E28*100/D28 -> 17.950663 | G28: =PIGGYBACKS!$B$7 -> 1.5985379 | H28: ='WAGE RATES'!$D$10 -> 1.0285306 | I28: =(H28-1)*F28 -> 0.51214348 | J28: =F28*G28+I28 -> 29.206957 | K28: =C28*$J28/'NONAUTO MODEL'!$G$6 -> 0
A30: Outgoing Primary (Piece)
B31: AFSM100 Auto | C31: =SUM('NONAUTO MODEL'!$B$25:$B$29) -> 7613.0475 | D31: =PRODUCTIVITIES!$E$23*'COVERAGE FACTORS'!$C$25+PRODUCTIVITIES!$E$17*(1-'COVERAGE FACTORS'!$C$25) -> 1572.5271 | E31: ='WAGE RATES'!$D$6 -> 50.107175 | F31: =E31*100/D31 -> 3.1864109 | G31: =PIGGYBACKS!$B$8 -> 1.6305774 | H31: ='WAGE RATES'!$D$10 -> 1.0285306 | I31: =(H31-1)*F31 -> 0.09091027 | J31: =F31*G31+I31 -> 5.2865999 | K31: =C31*$J31/'NONAUTO MODEL'!$G$6 -> 4.0247137
B32: REC Keying | C32: =SUM('NONAUTO MODEL'!$A$25:$A$29) -> 2007.4406 | D32: =PRODUCTIVITIES!$E$16 -> 888.01171 | E32: ='WAGE RATES'!$D$5 -> 54.14236 | F32: =E32*100/D32 -> 6.0970322 | G32: =PIGGYBACKS!$B$9 -> 1.2615773 | H32: ='WAGE RATES'!$D$10 -> 1.0285306 | I32: =(H32-1)*F32 -> 0.17395209 | J32: =F32*G32+I32 -> 7.8658297 | K32: =C32*$J32/'NONAUTO MODEL'!$G$6 -> 1.5790186
B33: UFSM1000 Auto | C33: =SUM('NONAUTO MODEL'!$H$25:$H$29) -> 0 | D33: =PRODUCTIVITIES!$E$30 -> 1.0273269 | E33: ='WAGE RATES'!$D$6 -> 50.107175 | F33: =E33*100/D33 -> 4877.4324 | G33: =PIGGYBACKS!$B$10 -> 1.6305774 | H33: ='WAGE RATES'!$D$10 -> 1.0285306 | I33: =(H33-1)*F33 -> 139.15616 | J33: =F33*G33+I33 -> 8092.1873 | K33: =C33*$J33/'NONAUTO MODEL'!$G$6 -> 0
B34: UFSM1000 Keying | C34: =SUM('NONAUTO MODEL'!$G$25:$G$29) -> 0 | D34: =PRODUCTIVITIES!$E$36 -> 1.0273269 | E34: ='WAGE RATES'!$D$6 -> 50.107175 | F34: =E34*100/D34 -> 4877.4324 | G34: =PIGGYBACKS!$B$10 -> 1.6305774 | H34: ='WAGE RATES'!$D$10 -> 1.0285306 | I34: =(H34-1)*F34 -> 139.15616 | J34: =F34*G34+I34 -> 8092.1873 | K34: =C34*$J34/'NONAUTO MODEL'!$G$6 -> 0
B35: Manual | C35: =SUM('NONAUTO MODEL'!$M$25:$M$29) -> 462.91873 | D35: =PRODUCTIVITIES!$E$42 -> 620.26372 | E35: ='WAGE RATES'!$D$6 -> 50.107175 | F35: =E35*100/D35 -> 8.0783662 | G35: =PIGGYBACKS!$B$12 -> 1.3622907 | H35: ='WAGE RATES'!$D$10 -> 1.0285306 | I35: =(H35-1)*F35 -> 0.23048077 | J35: =F35*G35+I35 -> 11.235564 | K35: =C35*$J35/'NONAUTO MODEL'!$G$6 -> 0.5201153
A37: Outgoing Secondary (Piece)
B38: AFSM100 Auto | C38: =SUM('NONAUTO MODEL'!$B$38:$B$42) -> 925.12849 | D38: =PRODUCTIVITIES!$E$24*'COVERAGE FACTORS'!$C$25+PRODUCTIVITIES!$E$18*(1-'COVERAGE FACTORS'!$C$25) -> 2267.7698 | E38: ='WAGE RATES'!$D$6 -> 50.107175 | F38: =E38*100/D38 -> 2.2095353 | G38: =PIGGYBACKS!$B$8 -> 1.6305774 | H38: ='WAGE RATES'!$D$10 -> 1.0285306 | I38: =(H38-1)*F38 -> 0.063039405 | J38: =F38*G38+I38 -> 3.6658578 | K38: =C38*$J38/'NONAUTO MODEL'!$G$6 -> 0.33913894
B39: REC Keying | C39: =SUM('NONAUTO MODEL'!$A$38:$A$42) -> 56.71006 | D39: =PRODUCTIVITIES!$E$16 -> 888.01171 | E39: ='WAGE RATES'!$D$5 -> 54.14236 | F39: =E39*100/D39 -> 6.0970322 | G39: =PIGGYBACKS!$B$9 -> 1.2615773 | H39: ='WAGE RATES'!$D$10 -> 1.0285306 | I39: =(H39-1)*F39 -> 0.17395209 | J39: =F39*G39+I39 -> 7.8658297 | K39: =C39*$J39/'NONAUTO MODEL'!$G$6 -> 0.044607167
B40: UFSM1000 Auto | C40: =SUM('NONAUTO MODEL'!$H$38:$H$42) -> 0 | D40: =PRODUCTIVITIES!$E$31 -> 1.0273269 | E40: ='WAGE RATES'!$D$6 -> 50.107175 | F40: =E40*100/D40 -> 4877.4324 | G40: =PIGGYBACKS!$B$10 -> 1.6305774 | H40: ='WAGE RATES'!$D$10 -> 1.0285306 | I40: =(H40-1)*F40 -> 139.15616 | J40: =F40*G40+I40 -> 8092.1873 | K40: =C40*$J40/'NONAUTO MODEL'!$G$6 -> 0
B41: UFSM1000 Keying | C41: =SUM('NONAUTO MODEL'!$G$38:$G$42) -> 0 | D41: =PRODUCTIVITIES!$E$37 -> 1.0273269 | E41: ='WAGE RATES'!$D$6 -> 50.107175 | F41: =E41*100/D41 -> 4877.4324 | G41: =PIGGYBACKS!$B$10 -> 1.6305774 | H41: ='WAGE RATES'!$D$10 -> 1.0285306 | I41: =(H41-1)*F41 -> 139.15616 | J41: =F41*G41+I41 -> 8092.1873 | K41: =C41*$J41/'NONAUTO MODEL'!$G$6 -> 0
B42: Manual | C42: =SUM('NONAUTO MODEL'!$M$38:$M$42) -> 125.25091 | D42: =PRODUCTIVITIES!$E$43 -> 490.62129 | E42: ='WAGE RATES'!$D$6 -> 50.107175 | F42: =E42*100/D42 -> 10.213005 | G42: =PIGGYBACKS!$B$12 -> 1.3622907 | H42: ='WAGE RATES'!$D$10 -> 1.0285306 | I42: =(H42-1)*F42 -> 0.29138332 | J42: =F42*G42+I42 -> 14.204465 | K42: =C42*$J42/'NONAUTO MODEL'!$G$6 -> 0.17791221
A44: Incoming MMP (Piece)
B45: AFSM100 Auto | C45: =SUM('NONAUTO MODEL'!$B$53:$B$57) -> 4927.0829 | D45: =PRODUCTIVITIES!$E$25*'COVERAGE FACTORS'!$C$25+PRODUCTIVITIES!$E$19*(1-'COVERAGE FACTORS'!$C$25) -> 1572.9754 | E45: ='WAGE RATES'!$D$6 -> 50.107175 | F45: =E45*100/D45 -> 3.1855028 | G45: =PIGGYBACKS!$B$8 -> 1.6305774 | H45: ='WAGE RATES'!$D$10 -> 1.0285306 | I45: =(H45-1)*F45 -> 0.090884361 | J45: =F45*G45+I45 -> 5.2850933 | K45: =C45*$J45/'NONAUTO MODEL'!$G$6 -> 2.6040093
B46: REC Keying | C46: =SUM('NONAUTO MODEL'!$A$53:$A$57) -> 418.05339 | D46: =PRODUCTIVITIES!$E$16 -> 888.01171 | E46: ='WAGE RATES'!$D$5 -> 54.14236 | F46: =E46*100/D46 -> 6.0970322 | G46: =PIGGYBACKS!$B$9 -> 1.2615773 | H46: ='WAGE RATES'!$D$10 -> 1.0285306 | I46: =(H46-1)*F46 -> 0.17395209 | J46: =F46*G46+I46 -> 7.8658297 | K46: =C46*$J46/'NONAUTO MODEL'!$G$6 -> 0.32883367
B47: UFSM1000 Auto | C47: =SUM('NONAUTO MODEL'!$H$53:$H$57) -> 0 | D47: =PRODUCTIVITIES!$E$32 -> 1.0273269 | E47: ='WAGE RATES'!$D$6 -> 50.107175 | F47: =E47*100/D47 -> 4877.4324 | G47: =PIGGYBACKS!$B$10 -> 1.6305774 | H47: ='WAGE RATES'!$D$10 -> 1.0285306 | I47: =(H47-1)*F47 -> 139.15616 | J47: =F47*G47+I47 -> 8092.1873 | K47: =C47*$J47/'NONAUTO MODEL'!$G$6 -> 0
B48: UFSM1000 Keying | C48: =SUM('NONAUTO MODEL'!$G$53:$G$57) -> 0 | D48: =PRODUCTIVITIES!$E$38 -> 1.0273269 | E48: ='WAGE RATES'!$D$6 -> 50.107175 | F48: =E48*100/D48 -> 4877.4324 | G48: =PIGGYBACKS!$B$10 -> 1.6305774 | H48: ='WAGE RATES'!$D$10 -> 1.0285306 | I48: =(H48-1)*F48 -> 139.15616 | J48: =F48*G48+I48 -> 8092.1873 | K48: =C48*$J48/'NONAUTO MODEL'!$G$6 -> 0
B49: Manual | C49: =SUM('NONAUTO MODEL'!$M$53:$M$57) -> 749.05994 | D49: =PRODUCTIVITIES!$E$44 -> 692.96374 | E49: ='WAGE RATES'!$D$6 -> 50.107175 | F49: =E49*100/D49 -> 7.2308508 | G49: =PIGGYBACKS!$B$12 -> 1.3622907 | H49: ='WAGE RATES'!$D$10 -> 1.0285306 | I49: =(H49-1)*F49 -> 0.20630064 | J49: =F49*G49+I49 -> 10.056822 | K49: =C49*$J49/'NONAUTO MODEL'!$G$6 -> 0.75331622
...

Sheet NONAUTO MODEL
A1: ='NONAUTO COST'!A1 -> NONAUTO PRESORT
A2: MAIL FLOW MODEL
A6: PCS IN = | C6: =SUM(C11:C16)+SUM(G11:G16)+SUM(K11:K16)+SUM(O11:O16) -> 10000 | E6: PCS OUT = | G6: =D88+J88+O88+D100+D127 -> 10000
A10: PIECE ENTRY POINTS:
B11: BC Mach Out Prim | C11: 0 | F11: Non-BC Mach Out Prim | G11: ='ENTRY PROFILE'!H6+'ENTRY PROFILE'!H7+'ENTRY PROFILE'!H8+'ENTRY PROFILE'!H9+'ENTRY PROFILE'!I6+'ENTRY PROFILE'!X10 -> 7517.5565 | J11: BC Nonmach Out Prim | K11: 0 | N11: Non-BC Nonmach Out Prim | O11: ='ENTRY PROFILE'!H20+'ENTRY PROFILE'!H21+'ENTRY PROFILE'!H22+'ENTRY PROFILE'!H23+'ENTRY PROFILE'!I20+'ENTRY PROFILE'!X24 -> 0
B12: BC Mach Out Sec | C12: 0 | F12: Non-BC Mach Out Sec | G12: 0 | J12: BC Nonmach Out Sec | K12: 0 | N12: Non-BC Nonmach Out Sec | O12: 0
B13: BC Mach Inc MMP | C13: 0 | F13: Non-BC Mach Inc MMP | G13: ='ENTRY PROFILE'!I7+'ENTRY PROFILE'!L7+'ENTRY PROFILE'!L8+'ENTRY PROFILE'!L9+'ENTRY PROFILE'!L11+'ENTRY PROFILE'!L12+'ENTRY PROFILE'!L13+'ENTRY PROFILE'!M7+'ENTRY PROFILE'!M11+'ENTRY PROFILE'!X14 -> 570.58224 | J13: BC Nonmach Inc MMP | K13: 0 | N13: Non-BC Nonmach Inc MMP | O13: ='ENTRY PROFILE'!I21+'ENTRY PROFILE'!L21+'ENTRY PROFILE'!L22+'ENTRY PROFILE'!L23+'ENTRY PROFILE'!L25+'ENTRY PROFILE'!L26+'ENTRY PROFILE'!L27+'ENTRY PROFILE'!M21+'ENTRY PROFILE'!M25+'ENTRY PROFILE'!X28 -> 0
