Workbook
Name e: 'COVERAGE FACTORS'!#REF!

Sheet CRA ADJ UNIT COSTS-hardcoded
A1: MARKETING MAIL FLATS MAIL PROCESSING UNIT COST SUMMARY
A2: This sheet contains identical but harcoded data from the 'CRA ADJ UNIT COSTS' to prevent any errors while linking to other spreadsheets.
A3: While linking, click File -> Options -> Formulas -> and check the radio button for "Enable Iterative Calculation".
A5: CRA FLATS MAIL PROCESSING UNIT COSTS
B7: Modeled Worksharing Related (Proportional) Cost Pools | F7: 37.296696 | G7: (1)
B8: Non-Worksharing Related (Fixed) Cost Pools | F8: 14.327695 | G8: (2)
B10: Total | F10: 51.624391 | G10: (3)
A12: CRA PROPORTIONAL ADJUSTMENT FACTOR
D14: (4) | E14: (5) | F14: (6) | H14: (7) | I14: (8)
E16: FY | F16: FY
B17: Base Model Costs | D17: Model Cost | E17: Volume | F17: Volume % | H17: Total Modeled Cost | I17: FSS Volume @ 5D Cost
C18: Nonauto MADC | D18: 32.578093 | E18: 11145516 | F18: 0.0067025536 | H18: 3.6309966e+08
C19: Nonauto ADC | D19: 24.475449 | E19: 4844309.7 | F19: 0.0029132115 | H19: 1.1856665e+08
C20: Nonauto 3-Digit | D20: 20.739663 | E20: 28153334 | F20: 0.016930506 | H20: 5.8389067e+08
C21: Nonauto 5-Digit | D21: 11.602841 | E21: 31525903 | F21: 0.018958661 | H21: 3.6579005e+08
C22: Nonauto FSS Other
C23: Nonauto FSS Scheme
C24: Auto MADC | D24: 32.870687 | E24: 42904653 | F24: 0.025801473 | H24: 1.4103054e+09
C25: Auto ADC | D25: 27.648044 | E25: 34213504 | F25: 0.020574897 | H25: 9.4593647e+08
C26: Auto 3-Digit | D26: 20.683031 | E26: 4.400862e+08 | F26: 0.26465363 | H26: 9.1023166e+09
C27: Auto 5-Digit | D27: 10.045315 | E27: 1.0700027e+09 | F27: 0.64346507 | H27: 1.0748513e+10
C28: Auto FSS Other
C29: Auto FSS Scheme
A30: (9) | B30: Total Weighted Model Cost | D30: 14.215382 | E30: 1.6628761e+09 | F30: 1
B32: CRA Proportional Adjustment | F32: 2.6236858 | G32: (10)
IM33: .
A34: ADJUSTED FLATS MAIL PROCESSING UNIT COSTS (CENTS)
D36: (11) | E36: (12) | F36: (13) | G36: (14)
G37: Total
D38: Model | E38: Proportional | F38: Fixed | G38: Mail Proc
B39: Rate Category | D39: Unit Cost | E39: Unit Cost | F39: Unit Cost | G39: Unit Cost
B41: Nonauto MADC | D41: 32.578093 | E41: 85.474679 | F41: 14.327695 | G41: 99.802374
B43: Nonauto ADC | D43: 24.475449 | E43: 64.215886 | F43: 14.327695 | G43: 78.543581
B45: Nonauto 3-Digit | D45: 20.739663 | E45: 54.41436 | F45: 14.327695 | G45: 68.742055
C47: FSS Zone
C48: Non-FSS Zone | D48: 20.739663 | E48: 54.41436 | F48: 14.327695 | G48: 68.742055
B50: Nonauto 5-Digit | D50: 11.602841 | E50: 30.442209 | F50: 14.327695 | G50: 44.769904
B52: Nonauto FSS Other
B54: Nonauto FSS Scheme
B56: Auto MADC | D56: 32.870687 | E56: 86.242353 | F56: 14.327695 | G56: 100.57005
...

Sheet CRA ADJ UNIT COSTS
A1: MARKETING MAIL FLATS MAIL PROCESSING UNIT COST SUMMARY
A5: CRA FLATS MAIL PROCESSING UNIT COSTS
B7: Modeled Worksharing Related (Proportional) Cost Pools | F7: ='CRA FLATS'!G81 -> 37.296696 | G7: ="(1)" -> (1)
B8: Non-Worksharing Related (Fixed) Cost Pools | F8: ='CRA FLATS'!H81 -> 14.327695 | G8: ="(2)" -> (2)
B10: Total | F10: =SUM(F7:F8) -> 51.624391 | G10: ="(3)" -> (3)
A12: CRA PROPORTIONAL ADJUSTMENT FACTOR
D14: ="(4)" -> (4) | E14: ="(5)" -> (5) | F14: ="(6)" -> (6) | H14: ="(7)" -> (7) | I14: ="(8)" -> (8)
E16: FY | F16: FY
B17: Base Model Costs | D17: Model Cost | E17: Volume | F17: Volume % | H17: Total Modeled Cost | I17: FSS Volume @ 5D Cost
C18: Nonauto MADC | D18: ='MADC NONAUTO COST'!$K$79 -> 32.578093 | E18: ='FY VOLUME NONAUTO'!H13 -> 11145516 | F18: =E18/$E$30 -> 0.0067025536 | H18: =D18*E18 -> 3.6309966e+08
C19: Nonauto ADC | D19: ='ADC NONAUTO COST'!$K$79 -> 24.475449 | E19: ='FY VOLUME NONAUTO'!H25 -> 4844309.7 | F19: =E19/$E$30 -> 0.0029132115 | H19: =D19*E19 -> 1.1856665e+08
C20: Nonauto 3-Digit | D20: ='3D NONAUTO COST'!$K$79 -> 20.739663 | E20: ='FY VOLUME NONAUTO'!H34 -> 28153334 | F20: =E20/$E$30 -> 0.016930506 | H20: =D20*E20 -> 5.8389067e+08
C21: Nonauto 5-Digit | D21: ='5D NONAUTO COST'!$K$79 -> 11.602841 | E21: ='FY VOLUME NONAUTO'!H43 -> 31525903 | F21: =E21/$E$30 -> 0.018958661 | H21: =D21*E21 -> 3.6579005e+08
C22: =B52 -> Nonauto FSS Other
C23: =B54 -> Nonauto FSS Scheme
C24: Auto MADC | D24: ='MADC AUTO COST'!$K$79 -> 32.870687 | E24: ='FY VOLUME AUTO'!H10 -> 42904653 | F24: =E24/$E$30 -> 0.025801473 | H24: =D24*E24 -> 1.4103054e+09
C25: Auto ADC | D25: ='ADC AUTO COST'!$K$79 -> 27.648044 | E25: ='FY VOLUME AUTO'!H18 -> 34213504 | F25: =E25/$E$30 -> 0.020574897 | H25: =D25*E25 -> 9.4593647e+08
C26: Auto 3-Digit | D26: ='3D AUTO COST'!$K$79 -> 20.683031 | E26: ='FY VOLUME AUTO'!H26 -> 4.400862e+08 | F26: =E26/$E$30 -> 0.26465363 | H26: =D26*E26 -> 9.1023166e+09
C27: Auto 5-Digit | D27: ='5D AUTO COST'!$K$79 -> 10.045315 | E27: ='FY VOLUME AUTO'!H35 -> 1.0700027e+09 | F27: =E27/$E$30 -> 0.64346507 | H27: =D27*E27 -> 1.0748513e+10
C28: Auto FSS Other
C29: Auto FSS Scheme
A30: ="(9)" -> (9) | B30: Total Weighted Model Cost | D30: =SUMPRODUCT(D18:D29,F18:F29) -> 14.215382 | E30: =SUM(E18:E29) -> 1.6628761e+09 | F30: =SUM(F18:F29) -> 1
B32: CRA Proportional Adjustment | F32: =F7/D30 -> 2.6236858 | G32: ="(10)" -> (10)
IM33: .
A34: ADJUSTED FLATS MAIL PROCESSING UNIT COSTS (CENTS)
D36: ="(11)" -> (11) | E36: ="(12)" -> (12) | F36: ="(13)" -> (13) | G36: ="(14)" -> (14)
G37: Total
D38: Model | E38: Proportional | F38: Fixed | G38: Mail Proc
B39: Rate Category | D39: Unit Cost | E39: Unit Cost | F39: Unit Cost | G39: Unit Cost
B41: =C18 -> Nonauto MADC | D41: =D18 -> 32.578093 | E41: =D41*$F$32 -> 85.474679 | F41: =$F$8 -> 14.327695 | G41: =E41+F41 -> 99.802374
B43: =C19 -> Nonauto ADC | D43: =D19 -> 24.475449 | E43: =D43*$F$32 -> 64.215886 | F43: =$F$8 -> 14.327695 | G43: =E43+F43 -> 78.543581
B45: =C20 -> Nonauto 3-Digit | D45: =D20 -> 20.739663 | E45: =D45*$F$32 -> 54.41436 | F45: =$F$8 -> 14.327695 | G45: =E45+F45 -> 68.742055
C47: FSS Zone
C48: Non-FSS Zone | D48: ='3D NONAUTO COST NONFSS'!K79 -> 20.739663 | E48: =D48*$F$32 -> 54.41436 | F48: =$F$8 -> 14.327695 | G48: =E48+F48 -> 68.742055
B50: =C21 -> Nonauto 5-Digit | D50: =D21 -> 11.602841 | E50: =D50*$F$32 -> 30.442209 | F50: =$F$8 -> 14.327695 | G50: =E50+F50 -> 44.769904
B52: Nonauto FSS Other
B54: Nonauto FSS Scheme
B56: =C24 -> Auto MADC | D56: =D24 -> 32.870687 | E56: =D56*$F$32 -> 86.242353 | F56: =$F$8 -> 14.327695 | G56: =E56+F56 -> 100.57005
B58: =C25 -> Auto ADC | D58: =D25 -> 27.648044 | E58: =D58*$F$32 -> 72.53978 | F58: =$F$8 -> 14.327695 | G58: =E58+F58 -> 86.867475
B60: =C26 -> Auto 3-Digit | D60: =D26 -> 20.683031 | E60: =D60*$F$32 -> 54.265775 | F60: =$F$8 -> 14.327695 | G60: =E60+F60 -> 68.59347
...

Sheet CR CRA ADJ UNIT COSTS-Hardcoded
A1: MARKETING MAIL CARRIER ROUTE FLATS MAIL PROCESSING UNIT COST SUMMARY
A2: This sheet contains identical but harcoded data from the 'CRA ADJ UNIT COSTS' to prevent any errors while linking to other spreadsheets.
A3: While linking, click File -> Options -> Formulas -> and check the radio button for "Enable Iterative Calculation".
A5: CRA FLATS MAIL PROCESSING UNIT COSTS
B7: Modeled Worksharing Related (Proportional) Cost Pools | F7: 5.4869526 | G7: (1)
B8: Non-Worksharing Related (Fixed) Cost Pools | F8: 3.5850616 | G8: (2)
B10: Total | F10: 9.0720142 | G10: (3)
A12: CRA PROPORTIONAL ADJUSTMENT FACTOR
D14: (4) | E14: (5) | F14: (6)
E16: FY | F16: FY
B17: Base Model Costs | D17: Model Cost | E17: Volume | F17: Volume %
C18: Carrier Route | D18: 3.8137251 | E18: 2.4253198e+09 | F18: 0.8869647
C19: Carrier Route - CRTS Pallet | D19: 0.95032668 | E19: 3.0908416e+08 | F19: 0.1130353
C20: Carrier Route - FSS Other
C21: Carrier Route FSS Scheme
A22: (7) | B22: Total Weighted Model Cost | D22: 3.49006 | E22: 2.734404e+09 | F22: 1
B24: CRA Proportional Adjustment | F24: 1.5721657 | G24: (8)
IO25: .
A26: ADJUSTED FLATS MAIL PROCESSING UNIT COSTS (CENTS)
D28: (9) | E28: (10) | F28: (11) | G28: (12)
G29: Total
D30: Model | E30: Proportional | F30: Fixed | G30: Mail Proc
B31: Rate Category | D31: Unit Cost | E31: Unit Cost | F31: Unit Cost | G31: Unit Cost
B33: Carrier Route | D33: 3.8137251 | E33: 5.9958078 | F33: 3.5850616 | G33: 9.5808694
B35: Carrier Route - CRTS Pallet | D35: 0.95032668 | E35: 1.494071 | F35: 3.5850616 | G35: 5.0791326
B37: Carrier Route - FSS Other
B39: Carrier Route FSS Scheme
A42: Source:
A43: (1) | B43: Sum of proportional cost pools on 'CRA CARRIER ROUTE' sheet
A44: (2) | B44: Sum of fixed cost pools on 'CRA CARRIER ROUTE' sheet
A45: (3) | B45: (1) + (2)
A46: (4) | B46: Model costs from respective rate category "COST" spreadsheets
A47: (5) | B47: FY volumes from tab 'FY VOLUME CARRIER ROUTE'
A48: (6) | B48: Rate Category (5) / sum of (5)
A49: (7) | B49: Sum [ Rate Category (4) * (6) ]
A50: (8) | B50: (1) / (7)
A51: (9) | B51: Model costs from respective rate category "COST" spreadsheets
A52: (10) | B52: (9) * (8)
A53: (11) | B53: (2)
A54: (12) | B54: (10) + (11)

Sheet CR CRA ADJ UNIT COSTS
A1: MARKETING MAIL CARRIER ROUTE FLATS MAIL PROCESSING UNIT COST SUMMARY
A5: CRA FLATS MAIL PROCESSING UNIT COSTS
B7: Modeled Worksharing Related (Proportional) Cost Pools | F7: ='CRA CR'!G81 -> 5.4869526 | G7: ="(1)" -> (1)
B8: Non-Worksharing Related (Fixed) Cost Pools | F8: ='CRA CR'!H81 -> 3.5850616 | G8: ="(2)" -> (2)
B10: Total | F10: =SUM(F7:F8) -> 9.0720142 | G10: ="(3)" -> (3)
A12: CRA PROPORTIONAL ADJUSTMENT FACTOR
D14: ="(4)" -> (4) | E14: ="(5)" -> (5) | F14: ="(6)" -> (6)
E16: FY | F16: FY
B17: Base Model Costs | D17: Model Cost | E17: Volume | F17: Volume %
C18: Carrier Route | D18: ='CR COST'!K79 -> 3.8137251 | E18: ='FY VOLUME CR'!H13 -> 2.4253198e+09 | F18: =E18/$E$22 -> 0.8869647
C19: Carrier Route - CRTS Pallet | D19: ='CR PALLET COST'!K79 -> 0.95032668 | E19: ='FY VOLUME CR'!H19 -> 3.0908416e+08 | F19: =E19/$E$22 -> 0.1130353
C20: Carrier Route - FSS Other
C21: Carrier Route FSS Scheme
A22: ="(7)" -> (7) | B22: Total Weighted Model Cost | D22: =SUMPRODUCT(D18:D21,F18:F21) -> 3.49006 | E22: =SUM(E18:E21) -> 2.734404e+09 | F22: =SUM(F18:F21) -> 1
B24: CRA Proportional Adjustment | F24: =F7/D22 -> 1.5721657 | G24: ="(8)" -> (8)
IO25: .
A26: ADJUSTED FLATS MAIL PROCESSING UNIT COSTS (CENTS)
D28: ="(9)" -> (9) | E28: ="(10)" -> (10) | F28: ="(11)" -> (11) | G28: ="(12)" -> (12)
G29: Total
D30: Model | E30: Proportional | F30: Fixed | G30: Mail Proc
B31: Rate Category | D31: Unit Cost | E31: Unit Cost | F31: Unit Cost | G31: Unit Cost
B33: =C18 -> Carrier Route | D33: =D18 -> 3.8137251 | E33: =D33*$F$24 -> 5.9958078 | F33: =$F$8 -> 3.5850616 | G33: =E33+F33 -> 9.5808694
B35: =C19 -> Carrier Route - CRTS Pallet | D35: =D19 -> 0.95032668 | E35: =D35*$F$24 -> 1.494071 | F35: =$F$8 -> 3.5850616 | G35: =E35+F35 -> 5.0791326
B37: Carrier Route - FSS Other
B39: Carrier Route FSS Scheme
A42: Source:
A43: (1) | B43: Sum of proportional cost pools on 'CRA CARRIER ROUTE' sheet
A44: (2) | B44: Sum of fixed cost pools on 'CRA CARRIER ROUTE' sheet
A45: (3) | B45: (1) + (2)
A46: (4) | B46: Model costs from respective rate category "COST" spreadsheets
A47: (5) | B47: FY volumes from tab 'FY VOLUME CARRIER ROUTE'
A48: (6) | B48: Rate Category (5) / sum of (5)
A49: (7) | B49: Sum [ Rate Category (4) * (6) ]
A50: (8) | B50: (1) / (7)
A51: (9) | B51: Model costs from respective rate category "COST" spreadsheets
A52: (10) | B52: (9) * (8)
A53: (11) | B53: (2)
A54: (12) | B54: (10) + (11)

Sheet PRESORT LEVELS HELD CONST
A1: MARKETING MAIL FLATS MAIL PROCESSING UNIT COST SUMMARY
A2: PRESORT LEVELS HELD CONSTANT
A5: ADJUSTED FLATS MAIL PROCESSING UNIT COSTS (CENTS)
D7: ="(1)" -> (1) | E7: ="(2)" -> (2) | F7: ="(3)" -> (3) | G7: ="(4)" -> (4)
G8: Total
D9: Model | E9: Proportional | F9: Fixed | G9: Mail Proc
B10: Rate Category | D10: Unit Cost | E10: Unit Cost | F10: Unit Cost | G10: Unit Cost
B12: ='CRA ADJ UNIT COSTS'!C18 -> Nonauto MADC | D12: ='CRA ADJ UNIT COSTS'!D18 -> 32.578093 | E12: =D12*'CRA ADJ UNIT COSTS'!$F$32 -> 85.474679 | F12: ='CRA ADJ UNIT COSTS'!$F$8 -> 14.327695 | G12: =E12+F12 -> 99.802374
B14: ='CRA ADJ UNIT COSTS'!C19 -> Nonauto ADC | D14: ='CRA ADJ UNIT COSTS'!D19 -> 24.475449 | E14: =D14*'CRA ADJ UNIT COSTS'!$F$32 -> 64.215886 | F14: ='CRA ADJ UNIT COSTS'!$F$8 -> 14.327695 | G14: =E14+F14 -> 78.543581
B16: ='CRA ADJ UNIT COSTS'!C20 -> Nonauto 3-Digit | D16: ='CRA ADJ UNIT COSTS'!D20 -> 20.739663 | E16: =D16*'CRA ADJ UNIT COSTS'!$F$32 -> 54.41436 | F16: ='CRA ADJ UNIT COSTS'!$F$8 -> 14.327695 | G16: =E16+F16 -> 68.742055
B18: ='CRA ADJ UNIT COSTS'!C21 -> Nonauto 5-Digit | D18: ='CRA ADJ UNIT COSTS'!D21 -> 11.602841 | E18: =D18*'CRA ADJ UNIT COSTS'!$F$32 -> 30.442209 | F18: ='CRA ADJ UNIT COSTS'!$F$8 -> 14.327695 | G18: =E18+F18 -> 44.769904
B20: Nonauto FSS Other
B22: Nonauto FSS Scheme
B24: Auto MADC Rev | D24: ='MADC AUTO COST REV'!$K$79 -> 30.846267 | E24: =D24*'CRA ADJ UNIT COSTS'!$F$32 -> 80.930911 | F24: ='CRA ADJ UNIT COSTS'!$F$8 -> 14.327695 | G24: =E24+F24 -> 95.258607
B26: Auto ADC Rev | D26: ='ADC AUTO COST REV'!$K$79 -> 22.745121 | E26: =D26*'CRA ADJ UNIT COSTS'!$F$32 -> 59.676051 | F26: ='CRA ADJ UNIT COSTS'!$F$8 -> 14.327695 | G26: =E26+F26 -> 74.003746
B28: Auto 3-Digit Rev | D28: ='3D AUTO COST REV'!$K$79 -> 18.966299 | E28: =D28*'CRA ADJ UNIT COSTS'!$F$32 -> 49.761609 | F28: ='CRA ADJ UNIT COSTS'!$F$8 -> 14.327695 | G28: =E28+F28 -> 64.089305 | I28: FSS Share of 3D
C30: FSS Zones | I30: FSS Cost
C31: Non-FSS Zones | D31: ='3D AUTO COST REV NONFSS'!K79 -> 18.966299 | E31: =D31*'CRA ADJ UNIT COSTS'!$F$32 -> 49.761609 | F31: ='CRA ADJ UNIT COSTS'!$F$8 -> 14.327695 | G31: =E31+F31 -> 64.089305 | I31: 3D Avoided FSS
I32: 3D Avoided NonFSS | J32: =G31-G33 -> 23.533746
B33: Auto 5-Digit Rev | D33: ='5D AUTO COST REV'!$K$79 -> 9.9965719 | E33: =D33*'CRA ADJ UNIT COSTS'!$F$32 -> 26.227863 | F33: ='CRA ADJ UNIT COSTS'!$F$8 -> 14.327695 | G33: =E33+F33 -> 40.555559
I34: Weighted Avoided 3D Cost | J34: =J31*J28+(1-J28)*J32 -> 23.533746
B35: Auto FSS Other Rev
B37: Auto FSS Scheme Rev
A40: ="(1)" -> (1) | B40: Model costs from respective rate category "COST" spreadsheets
A41: ="(2)" -> (2) | B41: (1) * [ (8) from 'CRA ADJ UNIT COSTS' ]
A42: ="(3)" -> (3) | B42: (2) from 'CRA ADJ UNIT COSTS'
A43: ="(4)" -> (4) | B43: (2) + (3)

Sheet CR AVOIDED COST CALC
B2: ADJUSTED FLATS MAIL PROCESSING UNIT COSTS (CENTS)
E4: Modeled
E5: Mail Proc
C6: Rate Category | E6: Unit Cost
C8: Carrier Route
D9: Non FSS | E9: ='CR CRA ADJ UNIT COSTS'!G33 -> 9.5808694
D10: FSS Other
C12: Carrier Route - CRTS Pallet
D13: Non FSS | E13: ='CR CRA ADJ UNIT COSTS'!G35 -> 5.0791326
D14: FSS Scheme | E14: ='CR CRA ADJ UNIT COSTS'!G39 -> 0
B17: Avioded Costs Calculation | E17: Avoided Cost | F17: Weight
D18: Non-FSS | E18: =E9-E13 -> 4.5017368 | F18: =('CR CRA ADJ UNIT COSTS'!E18+'CR CRA ADJ UNIT COSTS'!E19)/'CR CRA ADJ UNIT COSTS'!E22 -> 1
D19: FSS | F19: =1-F18 -> 0
D21: Weighted | E21: =E18*F18+E19*F19 -> 4.5017368

Sheet CRA FLATS
A1: CRA MARKETING MAIL FLATS PROCESSING UNIT COSTS
A2: Source: USPS-FY25-26
E5: Total
E6: MP
C7: Cost Pool | E7: Unit | G7: Workshaing-Related
B8: Source | C8: Abbreviation | E8: Costs | G8: Proportional (Cents) | H8: Fixed (Cents) | J8: Key | K8: Treatment
I10: 1 | J10: Piece Sorting | K10: Proportional
B11: MODS 11 | C11: D/BCS | D11: =IF($L$12=1,3,2) -> 3 | E11: ='[1]FLAT Unit Costs W Final Adj'!$I$6 -> 0.46456847 | G11: =IF($L$12=1,$E11*G$84,"") -> 0.33563338 | H11: =IF($L$12=1,$E11*H$84,"") -> 0.12893509 | I11: 2 | J11: Non-WS | K11: Fixed
I12: 3 | J12: Unexpected | K12: =IF(L12=1,"Piggybacked","Non WS") -> Piggybacked | L12: 1
B13: MODS 12 | C13: AFSM100 | D13: 1 | E13: ='[1]FLAT Unit Costs W Final Adj'!I7 -> 17.34727 | G13: =E13 -> 17.34727 | I13: 4 | J13: Allied/Support | K13: Piggybacked
B14: MODS 12 | C14: FSS | D14: 1 | E14: 0 | G14: =E14 -> 0
B17: MODS 13 | C17: APBS BUNDLE | D17: 1 | E17: ='[1]FLAT Unit Costs W Final Adj'!I9 -> 1.2796003 | G17: =E17 -> 1.2796003 | J17: Note: OPBULK, OPPREF and Pouching
B18: MODS 13 | C18: APBSPRIO | D18: 1 | E18: ='[1]FLAT Unit Costs W Final Adj'!I10 -> 1.4458046 | G18: =E18 -> 1.4458046 | J18: were WS related fixed in 3 column system,
B19: MODS 16 | C19: LCUS-SSM | D19: 4 | E19: ='[1]FLAT Unit Costs W Final Adj'!I11 -> 0.17689944 | G19: =$E19*G$84 -> 0.12780325 | H19: =$E19*H$84 -> 0.049096198 | J19: are grouped with prep and accept
B20: MODS 16 | C20: 1TRAYSRT | D20: 4 | E20: ='[1]FLAT Unit Costs W Final Adj'!I12 -> 1.0619542 | G20: =$E20*G$84 -> 0.76722224 | H20: =$E20*H$84 -> 0.29473191
B21: MODS 14 | C21: MANF | D21: 1 | E21: ='[1]FLAT Unit Costs W Final Adj'!I13 -> 1.8117015 | G21: =E21 -> 1.8117015
B22: MODS 14 | C22: MANL | D22: =IF($L$12=1,3,2) -> 3 | E22: ='[1]FLAT Unit Costs W Final Adj'!I14 -> 0.19266398 | G22: =IF($L$12=1,$E22*G$84,"") -> 0.13919254 | H22: =IF($L$12=1,$E22*H$84,"") -> 0.053471445
B23: MODS 14 | C23: MANP | D23: =IF($L$12=1,3,2) -> 3 | E23: ='[1]FLAT Unit Costs W Final Adj'!I15 -> 0.00067393582 | G23: =IF($L$12=1,$E23*G$84,"") -> 0.00048689348 | H23: =IF($L$12=1,$E23*H$84,"") -> 0.00018704234
B24: MODS 14 | C24: PRIORITY | D24: =IF($L$12=1,3,2) -> 3 | E24: ='[1]FLAT Unit Costs W Final Adj'!I16 -> 0.34872984 | G24: =IF($L$12=1,$E24*G$84,"") -> 0.2519443 | H24: =IF($L$12=1,$E24*H$84,"") -> 0.096785546
B25: MODS 15 | C25: LD15 | D25: =IF($L$12=1,3,2) -> 3 | E25: ='[1]FLAT Unit Costs W Final Adj'!I17 -> 0.06804888 | G25: =IF($L$12=1,$E25*G$84,"") -> 0.049162776 | H25: =IF($L$12=1,$E25*H$84,"") -> 0.018886104
B26: MODS 17 | C26: 1CANCEL | D26: 2 | E26: ='[1]FLAT Unit Costs W Final Adj'!I18 -> 0.46011989 | H26: =E26 -> 0.46011989
B27: MODS 17 | C27: 1DSPATCH | D27: 2 | E27: ='[1]FLAT Unit Costs W Final Adj'!I19 -> 0.4131396 | H27: =E27 -> 0.4131396
B29: MODS 17 | C29: 1MTRPREP | D29: 2 | E29: ='[1]FLAT Unit Costs W Final Adj'!I20 -> 0 | H29: =E29 -> 0
B30: MODS 17 | C30: 1OPBULK | D30: 2 | E30: ='[1]FLAT Unit Costs W Final Adj'!I21 -> 0.090130784 | H30: =E30 -> 0.090130784
B31: MODS 17 | C31: 1OPPREF | D31: 2 | E31: ='[1]FLAT Unit Costs W Final Adj'!I22 -> 0.55123464 | H31: =E31 -> 0.55123464
B32: MODS 17 | C32: 1OPTRANS | D32: 4 | E32: ='[1]FLAT Unit Costs W Final Adj'!I23 -> 0.059631311 | G32: =$E32*G$84 -> 0.043081396 | H32: =$E32*H$84 -> 0.016549914
B33: MODS 17 | C33: 1PLATFRM | D33: 2 | E33: ='[1]FLAT Unit Costs W Final Adj'!I24 -> 5.1884201 | H33: =E33 -> 5.1884201
B34: MODS 17 | C34: 1POUCHNG | D34: 2 | E34: ='[1]FLAT Unit Costs W Final Adj'!I25 -> 0.036359332 | H34: =E34 -> 0.036359332
B35: MODS 17 | C35: 1PRESORT | D35: 4 | E35: ='[1]FLAT Unit Costs W Final Adj'!I26 -> 0.033927873 | G35: =$E35*G$84 -> 0.024511622 | H35: =$E35*H$84 -> 0.0094162511
B36: MODS 17 | C36: 1SACKS_H | D36: 4 | E36: ='[1]FLAT Unit Costs W Final Adj'!I27 -> 0.064927969 | G36: =$E36*G$84 -> 0.046908034 | H36: =$E36*H$84 -> 0.018019935
B37: MODS 17 | C37: 1SCAN | D37: 2 | E37: ='[1]FLAT Unit Costs W Final Adj'!I28 -> 0.21035643 | H37: =E37 -> 0.21035643
B38: MODS 18 | C38: BUSREPLY | D38: 2 | E38: ='[1]FLAT Unit Costs W Final Adj'!I29 -> 0 | H38: =E38 -> 0
B39: MODS 18 | C39: EXPRESS | D39: 4 | E39: ='[1]FLAT Unit Costs W Final Adj'!I30 -> 0.053706311 | G39: =IF($L$12=1,$E39*G$84,"") -> 0.038800805 | H39: =IF($L$12=1,$E39*H$84,"") -> 0.014905506
B41: MODS 18 | C41: REGISTRY | D41: 4 | E41: ='[1]FLAT Unit Costs W Final Adj'!I31 -> 0.0078509153 | G41: =IF($L$12=1,$E41*G$84,"") -> 0.0056719933 | H41: =IF($L$12=1,$E41*H$84,"") -> 0.002178922
B42: MODS 18 | C42: REWRAP | D42: 2 | E42: ='[1]FLAT Unit Costs W Final Adj'!I32 -> 0.035919261 | H42: =E42 -> 0.035919261
B43: MODS 18 | C43: 1EEQMT | D43: 4 | E43: ='[1]FLAT Unit Costs W Final Adj'!I33 -> 0.38218406 | G43: =$E43*G$84 -> 0.27611372 | H43: =$E43*H$84 -> 0.10607034
B44: MODS 18 | C44: 1MISC | D44: 4 | E44: ='[1]FLAT Unit Costs W Final Adj'!I34 -> 0.14869315 | G44: =$E44*G$84 -> 0.10742525 | H44: =$E44*H$84 -> 0.0412679
B45: MODS 18 | C45: 1SUPPORT | D45: 4 | E45: ='[1]FLAT Unit Costs W Final Adj'!I35 -> 0.16668771 | G45: =$E45*G$84 -> 0.12042565 | H45: =$E45*H$84 -> 0.04626206
B46: MODS 19 | C46: INTL ISC | D46: =IF($L$12=1,3,2) -> 3 | E46: ='[1]FLAT Unit Costs W Final Adj'!I36 -> 0.019088869 | G46: =IF($L$12=1,$E46*G$84,"") -> 0.013790996 | H46: =IF($L$12=1,$E46*H$84,"") -> 0.0052978736
B58: NDCS | C58: FSS | D58: 1 | E58: 0 | G58: =E58 -> 0
...

Sheet CRA CR
A1: CRA MARKETING MAIL CARRIER ROUTE FLATS PROCESSING UNIT COSTS
A2: Source: USPS-FY25-26
E5: Total
E6: MP
C7: Cost Pool | E7: Unit | G7: Work-sharing-Related
B8: Source | C8: Abbreviation | E8: Costs | G8: Proportional (Cents) | H8: Fixed (Cents) | J8: Key | K8: Treatment
I10: 1 | J10: Piece Sorting | K10: Proportional
B11: MODS 11 | C11: D/BCS | D11: =IF($L$12=1,3,2) -> 3 | E11: ='[1]FLAT Unit Costs W Final Adj'!$H$6 -> 0.011443387 | G11: =IF($L$12=1,$E11*G$84,"") -> 0.0069212109 | H11: =IF($L$12=1,$E11*H$84,"") -> 0.0045221764 | I11: 2 | J11: Non-WS | K11: Fixed
I12: 3 | J12: Unexpected | K12: =IF(L12=1,"Piggybacked","Non WS") -> Piggybacked | L12: 1
B13: MODS 12 | C13: AFSM100 | D13: 1 | E13: ='[1]FLAT Unit Costs W Final Adj'!$H$7 -> 1.3070078 | G13: =E13 -> 1.3070078 | I13: 4 | J13: Allied/Support | K13: Piggybacked
B14: MODS 12 | C14: FSS | D14: 1 | E14: 0 | G14: =E14 -> 0
B17: MODS 13 | C17: APBS OTH | D17: 1 | E17: ='[1]FLAT Unit Costs W Final Adj'!H9 -> 0.74495243 | G17: =E17 -> 0.74495243 | J17: Note: OPBULK, OPPREF and Pouching
B18: MODS 13 | C18: APBSPRIO | D18: 1 | E18: ='[1]FLAT Unit Costs W Final Adj'!H10 -> 0.695384 | G18: =E18 -> 0.695384 | J18: were WS related fixed in 3 column system,
B19: MODS 16 | C19: LCUS-SSM | D19: 4 | E19: ='[1]FLAT Unit Costs W Final Adj'!H11 -> 0.0022468973 | G19: =$E19*G$84 -> 0.0013589726 | H19: =$E19*H$84 -> 0.00088792467 | J19: are grouped with prep and accept
B20: MODS 16 | C20: 1TRAYSRT | D20: 4 | E20: ='[1]FLAT Unit Costs W Final Adj'!H12 -> 0.12865338 | G20: =$E20*G$84 -> 0.077812381 | H20: =$E20*H$84 -> 0.050841004
B21: MODS 14 | C21: MANF | D21: 1 | E21: ='[1]FLAT Unit Costs W Final Adj'!H13 -> 0.10956702 | G21: =E21 -> 0.10956702
B22: MODS 14 | C22: MANL | D22: =IF($L$12=1,3,2) -> 3 | E22: ='[1]FLAT Unit Costs W Final Adj'!H14 -> 0.052613481 | G22: =IF($L$12=1,$E22*G$84,"") -> 0.031821784 | H22: =IF($L$12=1,$E22*H$84,"") -> 0.020791697
B23: MODS 14 | C23: MANP | D23: =IF($L$12=1,3,2) -> 3 | E23: ='[1]FLAT Unit Costs W Final Adj'!H15 -> 3.6863505e-05 | G23: =IF($L$12=1,$E23*G$84,"") -> 2.2295854e-05 | H23: =IF($L$12=1,$E23*H$84,"") -> 1.4567651e-05
B24: MODS 14 | C24: PRIORITY | D24: =IF($L$12=1,3,2) -> 3 | E24: ='[1]FLAT Unit Costs W Final Adj'!H16 -> 0.048633922 | G24: =IF($L$12=1,$E24*G$84,"") -> 0.02941486 | H24: =IF($L$12=1,$E24*H$84,"") -> 0.019219063
B25: MODS 15 | C25: LD15 | D25: =IF($L$12=1,3,2) -> 3 | E25: ='[1]FLAT Unit Costs W Final Adj'!H17 -> 0.014416814 | G25: =IF($L$12=1,$E25*G$84,"") -> 0.0087196045 | H25: =IF($L$12=1,$E25*H$84,"") -> 0.0056972096
B26: MODS 17 | C26: 1CANCEL | D26: 2 | E26: ='[1]FLAT Unit Costs W Final Adj'!H18 -> 0.077719036 | H26: =E26 -> 0.077719036
B27: MODS 17 | C27: 1DSPATCH | D27: 2 | E27: ='[1]FLAT Unit Costs W Final Adj'!H19 -> 0.059274669 | H27: =E27 -> 0.059274669
B29: MODS 17 | C29: 1MTRPREP | D29: 2 | E29: 0 | H29: =E29 -> 0
B30: MODS 17 | C30: 1OPBULK | D30: 2 | E30: ='[1]FLAT Unit Costs W Final Adj'!H21 -> 0.0037340783 | H30: =E30 -> 0.0037340783
B31: MODS 17 | C31: 1OPPREF | D31: 2 | E31: ='[1]FLAT Unit Costs W Final Adj'!H22 -> 0.10314338 | H31: =E31 -> 0.10314338
B32: MODS 17 | C32: 1OPTRANS | D32: 4 | E32: ='[1]FLAT Unit Costs W Final Adj'!H23 -> 0.034883983 | G32: =$E32*G$84 -> 0.021098596 | H32: =$E32*H$84 -> 0.013785387
B33: MODS 17 | C33: 1PLATFRM | D33: 2 | E33: ='[1]FLAT Unit Costs W Final Adj'!H24 -> 1.0317588 | H33: =E33 -> 1.0317588
B34: MODS 17 | C34: 1POUCHNG | D34: 2 | E34: ='[1]FLAT Unit Costs W Final Adj'!H25 -> 0.00039743777 | H34: =E34 -> 0.00039743777
B35: MODS 17 | C35: 1PRESORT | D35: 4 | E35: ='[1]FLAT Unit Costs W Final Adj'!H26 -> 0.012584608 | G35: =$E35*G$84 -> 0.0076114464 | H35: =$E35*H$84 -> 0.004973162
B36: MODS 17 | C36: 1SACKS_H | D36: 4 | E36: ='[1]FLAT Unit Costs W Final Adj'!H27 -> 0.0030474473 | G36: =$E36*G$84 -> 0.0018431628 | H36: =$E36*H$84 -> 0.0012042845
B37: MODS 17 | C37: 1SCAN | D37: 2 | E37: ='[1]FLAT Unit Costs W Final Adj'!H28 -> 0.010067842 | H37: =E37 -> 0.010067842
B38: MODS 18 | C38: BUSREPLY | D38: 2 | E38: ='[1]FLAT Unit Costs W Final Adj'!H29 -> 0 | H38: =E38 -> 0
B39: MODS 18 | C39: EXPRESS | D39: 4 | E39: ='[1]FLAT Unit Costs W Final Adj'!H30 -> 0.010536222 | G39: =IF($L$12=1,$E39*G$84,"") -> 0.0063725376 | H39: =IF($L$12=1,$E39*H$84,"") -> 0.0041636845
B41: MODS 18 | C41: REGISTRY | D41: 4 | E41: ='[1]FLAT Unit Costs W Final Adj'!H31 -> 0.00089858329 | G41: =IF($L$12=1,$E41*G$84,"") -> 0.00054348283 | H41: =IF($L$12=1,$E41*H$84,"") -> 0.00035510046
B42: MODS 18 | C42: REWRAP | D42: 2 | E42: ='[1]FLAT Unit Costs W Final Adj'!H32 -> 0.0012997133 | H42: =E42 -> 0.0012997133
B43: MODS 18 | C43: 1EEQMT | D43: 4 | E43: ='[1]FLAT Unit Costs W Final Adj'!H33 -> 0.04169935 | G43: =$E43*G$84 -> 0.025220679 | H43: =$E43*H$84 -> 0.016478671
B44: MODS 18 | C44: 1MISC | D44: 4 | E44: ='[1]FLAT Unit Costs W Final Adj'!H34 -> 0.029678161 | G44: =$E44*G$84 -> 0.017950001 | H44: =$E44*H$84 -> 0.01172816
B45: MODS 18 | C45: 1SUPPORT | D45: 4 | E45: ='[1]FLAT Unit Costs W Final Adj'!H35 -> 0.011847013 | G45: =$E45*G$84 -> 0.0071653326 | H45: =$E45*H$84 -> 0.0046816804
B46: MODS 19 | C46: INTL ISC | D46: =IF($L$12=1,3,2) -> 3 | E46: ='[1]FLAT Unit Costs W Final Adj'!H36 -> 0.010674659 | G46: =IF($L$12=1,$E46*G$84,"") -> 0.0064562672 | H46: =IF($L$12=1,$E46*H$84,"") -> 0.0042183918
B47: Intentionally blank
...

Sheet MADC NONAUTO COST
A1: MADC NONAUTO PRESORT
A2: COST SHEET
C4: ="(1)" -> (1) | D4: ="(2)" -> (2) | E4: (3) | F4: ="(4)" -> (4) | G4: ="(5)" -> (5) | H4: ="(6)" -> (6) | I4: ="(7)" -> (7) | J4: ="(8)" -> (8) | K4: ="(9)" -> (9)
D6: Bundles | F6: Direct | H6: Premium | I6: Premium | J6: Total | K6: Weighted
D7: or Pieces | E7: Wage | F7: Cents | G7: Piggyback | H7: Pay | I7: Pay | J7: Cents | K7: Cents
A8: Operation | C8: Volume | D8: Per Hour | E8: Rate | F8: Per Piece | G8: Factor | H8: Factor | I8: Adjust | J8: Per Piece | K8: Per Piece
A10: Outgoing Primary (Bundles)
B11: APPS | C11: ='BUNDLE SORT'!$I$10*('COVERAGE FACTORS'!$E$6/('COVERAGE FACTORS'!$E$6+'COVERAGE FACTORS'!$E$8)) -> 0 | D11: =PRODUCTIVITIES!$E$8 -> 206.82029 | E11: ='WAGE RATES'!$C$6 -> 50.107175 | F11: =E11*100/D11 -> 24.227398 | G11: =PIGGYBACKS!$B$5 -> 1.8052502 | H11: ='WAGE RATES'!$C$9 -> 0.97520312 | I11: =(H11-1)*F11 -> -0.60076381 | J11: =F11*G11+I11 -> 43.135752 | K11: =C11*$J11/'MADC NONAUTO MODEL'!$G$6 -> 0
B12: APBS / LIPS | C12: ='BUNDLE SORT'!$I$10*('COVERAGE FACTORS'!$E$8/('COVERAGE FACTORS'!$E$6+'COVERAGE FACTORS'!$E$8)) -> 0 | D12: =PRODUCTIVITIES!$E$10 -> 218.50114 | E12: ='WAGE RATES'!$C$6 -> 50.107175 | F12: =E12*100/D12 -> 22.932226 | G12: =PIGGYBACKS!$B$6 -> 1.6056413 | H12: ='WAGE RATES'!$C$9 -> 0.97520312 | I12: =(H12-1)*F12 -> -0.56864758 | J12: =F12*G12+I12 -> 36.25228 | K12: =C12*$J12/'MADC NONAUTO MODEL'!$G$6 -> 0
B13: Manual | C13: ='BUNDLE SORT'!$J$10 -> 687.2042 | D13: =PRODUCTIVITIES!$E$12 -> 388.77899 | E13: ='WAGE RATES'!$C$6 -> 50.107175 | F13: =E13*100/D13 -> 12.888344 | G13: =PIGGYBACKS!$B$7 -> 1.5985379 | H13: ='WAGE RATES'!$C$9 -> 0.97520312 | I13: =(H13-1)*F13 -> -0.31959069 | J13: =F13*G13+I13 -> 20.282916 | K13: =C13*$J13/'MADC NONAUTO MODEL'!$G$6 -> 1.3938505
A15: Incoming MMP (Bundles)
B16: APPS | C16: ='BUNDLE SORT'!$M$10*('COVERAGE FACTORS'!$E$30/('COVERAGE FACTORS'!$E$30+'COVERAGE FACTORS'!$E$32)) -> 129.00897 | D16: =PRODUCTIVITIES!$E$9 -> 236.2304 | E16: ='WAGE RATES'!$C$6 -> 50.107175 | F16: =E16*100/D16 -> 21.211146 | G16: =PIGGYBACKS!$B$5 -> 1.8052502 | H16: ='WAGE RATES'!$C$9 -> 0.97520312 | I16: =(H16-1)*F16 -> -0.52597017 | J16: =F16*G16+I16 -> 37.765456 | K16: =C16*$J16/'MADC NONAUTO MODEL'!$G$6 -> 0.48720825
B17: APBS / LIPS | C17: ='BUNDLE SORT'!$M$10*('COVERAGE FACTORS'!$E$32/('COVERAGE FACTORS'!$E$30+'COVERAGE FACTORS'!$E$32)) -> 155.95082 | D17: =PRODUCTIVITIES!$E$11 -> 181.33504 | E17: ='WAGE RATES'!$C$6 -> 50.107175 | F17: =E17*100/D17 -> 27.632373 | G17: =PIGGYBACKS!$B$6 -> 1.6056413 | H17: ='WAGE RATES'!$C$9 -> 0.97520312 | I17: =(H17-1)*F17 -> -0.68519655 | J17: =F17*G17+I17 -> 43.682481 | K17: =C17*$J17/'MADC NONAUTO MODEL'!$G$6 -> 0.68123187
B18: Manual | C18: ='BUNDLE SORT'!$N$10 -> 0 | D18: =PRODUCTIVITIES!$E$13 -> 388.77899 | E18: ='WAGE RATES'!$C$6 -> 50.107175 | F18: =E18*100/D18 -> 12.888344 | G18: =PIGGYBACKS!$B$7 -> 1.5985379 | H18: ='WAGE RATES'!$C$9 -> 0.97520312 | I18: =(H18-1)*F18 -> -0.31959069 | J18: =F18*G18+I18 -> 20.282916 | K18: =C18*$J18/'MADC NONAUTO MODEL'!$G$6 -> 0
A20: Incoming Primary (Bundles)
B21: APPS | C21: ='BUNDLE SORT'!$Q$10*('COVERAGE FACTORS'!$E$30/('COVERAGE FACTORS'!$E$30+'COVERAGE FACTORS'!$E$32)) -> 52.394201 | D21: =PRODUCTIVITIES!$E$9 -> 236.2304 | E21: ='WAGE RATES'!$C$6 -> 50.107175 | F21: =E21*100/D21 -> 21.211146 | G21: =PIGGYBACKS!$B$5 -> 1.8052502 | H21: ='WAGE RATES'!$C$9 -> 0.97520312 | I21: =(H21-1)*F21 -> -0.52597017 | J21: =F21*G21+I21 -> 37.765456 | K21: =C21*$J21/'MADC NONAUTO MODEL'!$G$6 -> 0.19786909
B22: APBS / LIPS | C22: ='BUNDLE SORT'!$Q$10*('COVERAGE FACTORS'!$E$32/('COVERAGE FACTORS'!$E$30+'COVERAGE FACTORS'!$E$32)) -> 63.33605 | D22: =PRODUCTIVITIES!$E$11 -> 181.33504 | E22: ='WAGE RATES'!$C$6 -> 50.107175 | F22: =E22*100/D22 -> 27.632373 | G22: =PIGGYBACKS!$B$6 -> 1.6056413 | H22: ='WAGE RATES'!$C$9 -> 0.97520312 | I22: =(H22-1)*F22 -> -0.68519655 | J22: =F22*G22+I22 -> 43.682481 | K22: =C22*$J22/'MADC NONAUTO MODEL'!$G$6 -> 0.27666758
B23: Manual | C23: ='BUNDLE SORT'!$R$10 -> 3.3375287 | D23: =PRODUCTIVITIES!$E$14 -> 388.77899 | E23: ='WAGE RATES'!$C$6 -> 50.107175 | F23: =E23*100/D23 -> 12.888344 | G23: =PIGGYBACKS!$B$7 -> 1.5985379 | H23: ='WAGE RATES'!$C$9 -> 0.97520312 | I23: =(H23-1)*F23 -> -0.31959069 | J23: =F23*G23+I23 -> 20.282916 | K23: =C23*$J23/'MADC NONAUTO MODEL'!$G$6 -> 0.0067694813
A25: Incoming Secondary (Bundles)
B26: APPS | C26: ='BUNDLE SORT'!$U$10*('COVERAGE FACTORS'!$E$30/('COVERAGE FACTORS'!$E$30+'COVERAGE FACTORS'!$E$32)) -> 0.00069469344 | D26: =PRODUCTIVITIES!$E$9 -> 236.2304 | E26: ='WAGE RATES'!$C$6 -> 50.107175 | F26: =E26*100/D26 -> 21.211146 | G26: =PIGGYBACKS!$B$5 -> 1.8052502 | H26: ='WAGE RATES'!$C$9 -> 0.97520312 | I26: =(H26-1)*F26 -> -0.52597017 | J26: =F26*G26+I26 -> 37.765456 | K26: =C26*$J26/'MADC NONAUTO MODEL'!$G$6 -> 2.6235414e-06
B27: APBS / LIPS | C27: ='BUNDLE SORT'!$U$10*('COVERAGE FACTORS'!$E$32/('COVERAGE FACTORS'!$E$30+'COVERAGE FACTORS'!$E$32)) -> 0.00083977115 | D27: =PRODUCTIVITIES!$E$11 -> 181.33504 | E27: ='WAGE RATES'!$C$6 -> 50.107175 | F27: =E27*100/D27 -> 27.632373 | G27: =PIGGYBACKS!$B$6 -> 1.6056413 | H27: ='WAGE RATES'!$C$9 -> 0.97520312 | I27: =(H27-1)*F27 -> -0.68519655 | J27: =F27*G27+I27 -> 43.682481 | K27: =C27*$J27/'MADC NONAUTO MODEL'!$G$6 -> 3.6683287e-06
B28: Manual | C28: ='BUNDLE SORT'!$V$10 -> 0.15191199 | D28: =PRODUCTIVITIES!E15 -> 279.1383 | E28: ='WAGE RATES'!$C$6 -> 50.107175 | F28: =E28*100/D28 -> 17.950663 | G28: =PIGGYBACKS!$B$7 -> 1.5985379 | H28: ='WAGE RATES'!$C$9 -> 0.97520312 | I28: =(H28-1)*F28 -> -0.44512037 | J28: =F28*G28+I28 -> 28.249693 | K28: =C28*$J28/'MADC NONAUTO MODEL'!$G$6 -> 0.00042914673
A30: Outgoing Primary (Piece)
B31: AFSM100 Auto | C31: =SUM('MADC NONAUTO MODEL'!$B$25:$B$29) -> 5161.4651 | D31: =PRODUCTIVITIES!$E$23*'COVERAGE FACTORS'!$E$24+PRODUCTIVITIES!$E$17*(1-'COVERAGE FACTORS'!$E$24) -> 1572.5271 | E31: ='WAGE RATES'!$C$6 -> 50.107175 | F31: =E31*100/D31 -> 3.1864109 | G31: =PIGGYBACKS!$B$8 -> 1.6305774 | H31: ='WAGE RATES'!$C$9 -> 0.97520312 | I31: =(H31-1)*F31 -> -0.07901304 | J31: =F31*G31+I31 -> 5.1166766 | K31: =C31*$J31/'MADC NONAUTO MODEL'!$G$6 -> 2.6409548
B32: REC Keying | C32: =SUM('MADC NONAUTO MODEL'!$A$25:$A$29) -> 1360.997 | D32: =PRODUCTIVITIES!$E$16 -> 888.01171 | E32: ='WAGE RATES'!$C$5 -> 54.14236 | F32: =E32*100/D32 -> 6.0970322 | G32: =PIGGYBACKS!$B$9 -> 1.2615773 | H32: ='WAGE RATES'!$C$9 -> 0.97520312 | I32: =(H32-1)*F32 -> -0.15118736 | J32: =F32*G32+I32 -> 7.5406902 | K32: =C32*$J32/'MADC NONAUTO MODEL'!$G$6 -> 1.0262857
B33: UFSM1000 Auto | C33: =SUM('MADC NONAUTO MODEL'!$H$25:$H$29) -> 0 | D33: =PRODUCTIVITIES!$E$30 -> 1.0273269 | E33: ='WAGE RATES'!$C$6 -> 50.107175 | F33: =E33*100/D33 -> 4877.4324 | G33: =PIGGYBACKS!$B$10 -> 1.6305774 | H33: ='WAGE RATES'!$C$9 -> 0.97520312 | I33: =(H33-1)*F33 -> -120.94509 | J33: =F33*G33+I33 -> 7832.086 | K33: =C33*$J33/'MADC NONAUTO MODEL'!$G$6 -> 0
B34: UFSM1000 Keying | C34: =SUM('MADC NONAUTO MODEL'!$G$25:$G$29) -> 0 | D34: =PRODUCTIVITIES!$E$36 -> 1.0273269 | E34: ='WAGE RATES'!$C$6 -> 50.107175 | F34: =E34*100/D34 -> 4877.4324 | G34: =PIGGYBACKS!$B$10 -> 1.6305774 | H34: ='WAGE RATES'!$C$9 -> 0.97520312 | I34: =(H34-1)*F34 -> -120.94509 | J34: =F34*G34+I34 -> 7832.086 | K34: =C34*$J34/'MADC NONAUTO MODEL'!$G$6 -> 0
B35: Manual | C35: =SUM('MADC NONAUTO MODEL'!$M$25:$M$29) -> 325.38965 | D35: =PRODUCTIVITIES!$E$42 -> 620.26372 | E35: ='WAGE RATES'!$C$6 -> 50.107175 | F35: =E35*100/D35 -> 8.0783662 | G35: =PIGGYBACKS!$B$12 -> 1.3622907 | H35: ='WAGE RATES'!$C$9 -> 0.97520312 | I35: =(H35-1)*F35 -> -0.20031825 | J35: =F35*G35+I35 -> 10.804765 | K35: =C35*$J35/'MADC NONAUTO MODEL'!$G$6 -> 0.35157588
A37: Outgoing Secondary (Piece)
B38: AFSM100 Auto | C38: =SUM('MADC NONAUTO MODEL'!$B$38:$B$42) -> 626.85582 | D38: =PRODUCTIVITIES!$E$24*'COVERAGE FACTORS'!$E$24+PRODUCTIVITIES!$E$18*(1-'COVERAGE FACTORS'!$E$24) -> 2267.7698 | E38: ='WAGE RATES'!$C$6 -> 50.107175 | F38: =E38*100/D38 -> 2.2095353 | G38: =PIGGYBACKS!$B$8 -> 1.6305774 | H38: ='WAGE RATES'!$C$9 -> 0.97520312 | I38: =(H38-1)*F38 -> -0.054789575 | J38: =F38*G38+I38 -> 3.5480288 | K38: =C38*$J38/'MADC NONAUTO MODEL'!$G$6 -> 0.22241025
B39: REC Keying | C39: =SUM('MADC NONAUTO MODEL'!$A$38:$A$42) -> 38.426047 | D39: =PRODUCTIVITIES!$E$16 -> 888.01171 | E39: ='WAGE RATES'!$C$5 -> 54.14236 | F39: =E39*100/D39 -> 6.0970322 | G39: =PIGGYBACKS!$B$9 -> 1.2615773 | H39: ='WAGE RATES'!$C$9 -> 0.97520312 | I39: =(H39-1)*F39 -> -0.15118736 | J39: =F39*G39+I39 -> 7.5406902 | K39: =C39*$J39/'MADC NONAUTO MODEL'!$G$6 -> 0.028975892
B40: UFSM1000 Auto | C40: =SUM('MADC NONAUTO MODEL'!$H$38:$H$42) -> 0 | D40: =PRODUCTIVITIES!$E$31 -> 1.0273269 | E40: ='WAGE RATES'!$C$6 -> 50.107175 | F40: =E40*100/D40 -> 4877.4324 | G40: =PIGGYBACKS!$B$10 -> 1.6305774 | H40: ='WAGE RATES'!$C$9 -> 0.97520312 | I40: =(H40-1)*F40 -> -120.94509 | J40: =F40*G40+I40 -> 7832.086 | K40: =C40*$J40/'MADC NONAUTO MODEL'!$G$6 -> 0
B41: UFSM1000 Keying | C41: =SUM('MADC NONAUTO MODEL'!$G$38:$G$42) -> 0 | D41: =PRODUCTIVITIES!$E$37 -> 1.0273269 | E41: ='WAGE RATES'!$C$6 -> 50.107175 | F41: =E41*100/D41 -> 4877.4324 | G41: =PIGGYBACKS!$B$10 -> 1.6305774 | H41: ='WAGE RATES'!$C$9 -> 0.97520312 | I41: =(H41-1)*F41 -> -120.94509 | J41: =F41*G41+I41 -> 7832.086 | K41: =C41*$J41/'MADC NONAUTO MODEL'!$G$6 -> 0
B42: Manual | C42: =SUM('MADC NONAUTO MODEL'!$M$38:$M$42) -> 87.219996 | D42: =PRODUCTIVITIES!$E$43 -> 490.62129 | E42: ='WAGE RATES'!$C$6 -> 50.107175 | F42: =E42*100/D42 -> 10.213005 | G42: =PIGGYBACKS!$B$12 -> 1.3622907 | H42: ='WAGE RATES'!$C$9 -> 0.97520312 | I42: =(H42-1)*F42 -> -0.25325062 | J42: =F42*G42+I42 -> 13.659831 | K42: =C42*$J42/'MADC NONAUTO MODEL'!$G$6 -> 0.11914104
A44: Incoming MMP (Piece)
B45: AFSM100 Auto | C45: =SUM('MADC NONAUTO MODEL'!$B$53:$B$57) -> 4498.7075 | D45: =PRODUCTIVITIES!$E$25*'COVERAGE FACTORS'!$E$24+PRODUCTIVITIES!$E$19*(1-'COVERAGE FACTORS'!$E$24) -> 1572.9754 | E45: ='WAGE RATES'!$C$6 -> 50.107175 | F45: =E45*100/D45 -> 3.1855028 | G45: =PIGGYBACKS!$B$8 -> 1.6305774 | H45: ='WAGE RATES'!$C$9 -> 0.97520312 | I45: =(H45-1)*F45 -> -0.078990522 | J45: =F45*G45+I45 -> 5.1152184 | K45: =C45*$J45/'MADC NONAUTO MODEL'!$G$6 -> 2.3011872
B46: REC Keying | C46: =SUM('MADC NONAUTO MODEL'!$A$53:$A$57) -> 589.37598 | D46: =PRODUCTIVITIES!$E$16 -> 888.01171 | E46: ='WAGE RATES'!$C$5 -> 54.14236 | F46: =E46*100/D46 -> 6.0970322 | G46: =PIGGYBACKS!$B$9 -> 1.2615773 | H46: ='WAGE RATES'!$C$9 -> 0.97520312 | I46: =(H46-1)*F46 -> -0.15118736 | J46: =F46*G46+I46 -> 7.5406902 | K46: =C46*$J46/'MADC NONAUTO MODEL'!$G$6 -> 0.44443017
B47: UFSM1000 Auto | C47: =SUM('MADC NONAUTO MODEL'!$H$53:$H$57) -> 0 | D47: =PRODUCTIVITIES!$E$32 -> 1.0273269 | E47: ='WAGE RATES'!$C$6 -> 50.107175 | F47: =E47*100/D47 -> 4877.4324 | G47: =PIGGYBACKS!$B$10 -> 1.6305774 | H47: ='WAGE RATES'!$C$9 -> 0.97520312 | I47: =(H47-1)*F47 -> -120.94509 | J47: =F47*G47+I47 -> 7832.086 | K47: =C47*$J47/'MADC NONAUTO MODEL'!$G$6 -> 0
B48: UFSM1000 Keying | C48: =SUM('MADC NONAUTO MODEL'!$G$53:$G$57) -> 0 | D48: =PRODUCTIVITIES!$E$38 -> 1.0273269 | E48: ='WAGE RATES'!$C$6 -> 50.107175 | F48: =E48*100/D48 -> 4877.4324 | G48: =PIGGYBACKS!$B$10 -> 1.6305774 | H48: ='WAGE RATES'!$C$9 -> 0.97520312 | I48: =(H48-1)*F48 -> -120.94509 | J48: =F48*G48+I48 -> 7832.086 | K48: =C48*$J48/'MADC NONAUTO MODEL'!$G$6 -> 0
B49: Manual | C49: =SUM('MADC NONAUTO MODEL'!$M$53:$M$57) -> 626.27317 | D49: =PRODUCTIVITIES!$E$44 -> 692.96374 | E49: ='WAGE RATES'!$C$6 -> 50.107175 | F49: =E49*100/D49 -> 7.2308508 | G49: =PIGGYBACKS!$B$12 -> 1.3622907 | H49: ='WAGE RATES'!$C$9 -> 0.97520312 | I49: =(H49-1)*F49 -> -0.17930252 | J49: =F49*G49+I49 -> 9.6712185 | K49: =C49*$J49/'MADC NONAUTO MODEL'!$G$6 -> 0.60568247
...

Sheet MADC NONAUTO MODEL
A1: ='MADC NONAUTO COST'!A1 -> MADC NONAUTO PRESORT
A2: MAIL FLOW MODEL
A6: PCS IN = | C6: =SUM(C11:C16)+SUM(G11:G16)+SUM(K11:K16)+SUM(O11:O16) -> 10000 | E6: PCS OUT = | G6: =D88+J88+O88+D100+D127 -> 10000
A10: PIECE ENTRY POINTS:
B11: BC Mach Out Prim | C11: 0 | F11: Non-BC Mach Out Prim | G11: ='ENTRY PROFILE'!K5+'ENTRY PROFILE'!K6+'ENTRY PROFILE'!K7+'ENTRY PROFILE'!K8+'ENTRY PROFILE'!K9+'ENTRY PROFILE'!L5+'ENTRY PROFILE'!L9 -> 5105.5264 | J11: BC Nonmach Out Prim | K11: 0 | N11: Non-BC Nonmach Out Prim | O11: 0
B12: BC Mach Out Sec | C12: 0 | F12: Non-BC Mach Out Sec | G12: 0 | J12: BC Nonmach Out Sec | K12: 0 | N12: Non-BC Nonmach Out Sec | O12: 0
B13: BC Mach Inc MMP | C13: 0 | F13: Non-BC Mach Inc MMP | G13: ='ENTRY PROFILE'!L6+'ENTRY PROFILE'!O6+'ENTRY PROFILE'!O7+'ENTRY PROFILE'!O8+'ENTRY PROFILE'!P6 -> 1542.1623 | J13: BC Nonmach Inc MMP | K13: 0 | N13: Non-BC Nonmach Inc MMP | O13: 0
B14: BC Mach Inc SCF | C14: 0 | F14: Non-BC Mach Inc SCF | G14: ='ENTRY PROFILE'!L7+'ENTRY PROFILE'!P7+'ENTRY PROFILE'!S7+'ENTRY PROFILE'!S8+'ENTRY PROFILE'!T7 -> 2733.1477 | J14: BC Nonmach Inc SCF | K14: 0 | N14: Non-BC Nonmach Inc SCF | O14: 0
B15: BC Mach Inc Prim | C15: 0 | F15: Non-BC Mach Inc Prim | G15: 0 | J15: BC Nonmach Inc Prim | K15: 0 | N15: Non-BC Nonmach Inc Prim | O15: 0
B16: BC Mach Inc Sec | C16: 0 | F16: Non-BC Mach Inc sec | G16: ='ENTRY PROFILE'!L8+'ENTRY PROFILE'!P8+'ENTRY PROFILE'!T8+'ENTRY PROFILE'!W8+'ENTRY PROFILE'!X8 -> 619.16355 | J16: BC Nonmach Inc Sec | K16: 0 | N16: Non-BC Nonmach Inc sec | O16: 0
C21: MACHINABLE OUTGOING | L21: NONMACHINABLE OUTGOING
D23: =SUM(A25:A29)*(1-'ACCEPT RATES'!G14)+SUM(B25:B29)*SUM('ACCEPT RATES'!I14:J14) -> 316.56424 | E23: Rejects | J23: =SUM(G25:G29)*(1-'ACCEPT RATES'!E19) -> 0 | K23: Rejects
A24: REC | B24: Out Prim AFSM100 | E24: Out Prim | G24: Keyed | H24: Out Prim UFSM1000 | K24: Out Prim | M24: Out Prim Manual
A25: =B25*(1-'ACCEPT RATES'!C14) -> 0 | B25: =C25*(1+'ACCEPT RATES'!F14) -> 0 | C25: =C11*('COVERAGE FACTORS'!E14+'COVERAGE FACTORS'!E18) -> 0 | E25: Manual | G25: =H25*(1-'ACCEPT RATES'!C19) -> 0 | H25: =I25 -> 0 | I25: =C11*'COVERAGE FACTORS'!E16 -> 0 | K25: Manual | M25: =N25 -> 0 | N25: =C11*'COVERAGE FACTORS'!E20 -> 0
A26: =B26*(1-'ACCEPT RATES'!D14) -> 1360.997 | B26: =C26*(1+'ACCEPT RATES'!F14) -> 5161.4651 | C26: =G11*('COVERAGE FACTORS'!E14+'COVERAGE FACTORS'!E18) -> 5096.701 | G26: =H26*(1-'ACCEPT RATES'!D19) -> 0 | H26: =I26 -> 0 | I26: =G11*'COVERAGE FACTORS'!E16 -> 0 | M26: =N26 -> 8.8254127 | N26: =G11*'COVERAGE FACTORS'!E20 -> 8.8254127
G27: =H27*(1-'ACCEPT RATES'!C19) -> 0 | H27: =I27 -> 0 | I27: =K11*('COVERAGE FACTORS'!E16+'COVERAGE FACTORS'!E18) -> 0 | M27: =N27 -> 0 | N27: =K11*(1-('COVERAGE FACTORS'!E16+'COVERAGE FACTORS'!E18)) -> 0
G28: =H28*(1-'ACCEPT RATES'!D19) -> 0 | H28: =I28 -> 0 | I28: =O11*('COVERAGE FACTORS'!E16+'COVERAGE FACTORS'!E18) -> 0 | M28: =N28 -> 0 | N28: =O11*(1-('COVERAGE FACTORS'!E16+'COVERAGE FACTORS'!E18)) -> 0
M29: =N29 -> 316.56424 | N29: =D23+J23 -> 316.56424
D30: =(SUM(C25:C29)-D23)*'PIECE DENSITIES'!C6 -> 612.09771 | E30: Out Sec Mach | J30: =(SUM(I25:I29)-J23)*'PIECE DENSITIES'!C11 -> 0 | K30: Out Sec Nonmach | O30: =SUM(N25:N29)*'PIECE DENSITIES'!C16 -> 29.115127 | P30: Out Sec Manual
D31: =(SUM(C25:C29)-D23)*'PIECE DENSITIES'!D6 -> 2477.5885 | E31: Inc MMP Mach | J31: =(SUM(I25:I29)-J23)*'PIECE DENSITIES'!D11 -> 0 | K31: Inc MMP Nonmach | O31: =SUM(N25:N29)*'PIECE DENSITIES'!D16 -> 188.93808 | P31: Inc MMP Manual
D32: =(SUM(C25:C29)-D23)*'PIECE DENSITIES'!E6 -> 1338.0738 | E32: Inc SCF Mach | J32: =(SUM(I25:I29)-J23)*'PIECE DENSITIES'!E11 -> 0 | K32: Inc SCF Nonmach | O32: =SUM(N25:N29)*'PIECE DENSITIES'!E16 -> 83.236973 | P32: Inc SCF Manual
D33: =(SUM(C25:C29)-D23)*'PIECE DENSITIES'!F6 -> 352.37671 | E33: Inc Prim Mach | J33: =(SUM(I25:I29)-J23)*'PIECE DENSITIES'!F11 -> 0 | K33: Inc Prim Nonmach | O33: =SUM(N25:N29)*'PIECE DENSITIES'!F16 -> 24.099476 | P33: Inc Prim Manual
D34: =(SUM(C25:C29)-D23)*'PIECE DENSITIES'!G6 -> 0 | E34: Inc Sec Mach | J34: =(SUM(I25:I29)-J23)*'PIECE DENSITIES'!G11 -> 0 | K34: Inc Sec Nonmach | O34: =SUM(N25:N29)*'PIECE DENSITIES'!G16 -> 0 | P34: Inc Sec Manual
D36: =SUM(A38:A42)*(1-'ACCEPT RATES'!G15)+SUM(B38:B42)*SUM('ACCEPT RATES'!I15:J15) -> 58.104868 | E36: Rejects | J36: =SUM(G38:G42)*(1-'ACCEPT RATES'!E20) -> 0 | K36: Rejects
A37: REC | B37: Out Sec AFSM100 | E37: Out Sec | G37: Keyed | H37: Out Sec UFSM1000 | K37: Out Sec | M37: Out Sec Manual
A38: =B38*(1-'ACCEPT RATES'!C15) -> 0 | B38: =C38*(1+'ACCEPT RATES'!F15+'PIECE DENSITIES'!C7) -> 0 | C38: =C12*('COVERAGE FACTORS'!E14+'COVERAGE FACTORS'!E18) -> 0 | E38: Manual | G38: =H38*(1-'ACCEPT RATES'!C20) -> 0 | H38: =I38*(1+'PIECE DENSITIES'!C12) -> 0 | I38: =C12*'COVERAGE FACTORS'!E16 -> 0 | K38: Manual | M38: =N38 -> 0 | N38: =C12*'COVERAGE FACTORS'!E20 -> 0
A39: =B39*(1-'ACCEPT RATES'!D15) -> 0 | B39: =C39*(1+'ACCEPT RATES'!F15+'PIECE DENSITIES'!C7) -> 0 | C39: =G12*('COVERAGE FACTORS'!E14+'COVERAGE FACTORS'!E18) -> 0 | G39: =H39*(1-'ACCEPT RATES'!D20) -> 0 | H39: =I39*(1+'PIECE DENSITIES'!C12) -> 0 | I39: =G12*'COVERAGE FACTORS'!E16 -> 0 | M39: =N39 -> 0 | N39: =G12*'COVERAGE FACTORS'!E20 -> 0
G40: =H40*(1-'ACCEPT RATES'!C20) -> 0 | H40: =I40*(1+'PIECE DENSITIES'!C12) -> 0 | I40: =K12*('COVERAGE FACTORS'!E16+'COVERAGE FACTORS'!E18) -> 0 | M40: =N40 -> 0 | N40: =K12*(1-('COVERAGE FACTORS'!E16+'COVERAGE FACTORS'!E18)) -> 0
G41: =H41*(1-'ACCEPT RATES'!D20) -> 0 | H41: =I41*(1+'PIECE DENSITIES'!C12) -> 0 | I41: =O12*('COVERAGE FACTORS'!E16+'COVERAGE FACTORS'!E18) -> 0 | M41: =N41 -> 0 | N41: =O12*(1-('COVERAGE FACTORS'!E16+'COVERAGE FACTORS'!E18)) -> 0
A42: =B42*(1-'ACCEPT RATES'!C15) -> 38.426047 | B42: =C42*(1+'ACCEPT RATES'!F15+'PIECE DENSITIES'!C7) -> 626.85582 | C42: =D30 -> 612.09771 | G42: =IF(SUM(C11:C16)>0,H42*(1-'ACCEPT RATES'!C20),H42*(1-'ACCEPT RATES'!D20)) -> 0 | H42: =I42*(1+'PIECE DENSITIES'!C12) -> 0 | I42: =J30 -> 0 | M42: =N42 -> 87.219996 | N42: =D36+J36+O30 -> 87.219996
D43: =(SUM(C38:C42)-D36)*'PIECE DENSITIES'!D7 -> 457.48379 | E43: Inc MMP Mach | J43: =(SUM(I38:I42)-J36)*'PIECE DENSITIES'!D12 -> 0 | K43: Inc MMP Nonmach | O43: =SUM(N38:N42)*'PIECE DENSITIES'!D17 -> 61.738117 | P43: Inc MMP Manual
D44: =(SUM(C38:C42)-D36)*'PIECE DENSITIES'!E7 -> 38.234025 | E44: Inc SCF Mach | J44: =(SUM(I38:I42)-J36)*'PIECE DENSITIES'!E12 -> 0 | K44: Inc SCF Nonmach | O44: =SUM(N38:N42)*'PIECE DENSITIES'!E17 -> 0.27066437 | P44: Inc SCF Manual
D45: =(SUM(C38:C42)-D36)*'PIECE DENSITIES'!F7 -> 4.0726215 | E45: Inc Prim Mach | J45: =(SUM(I38:I42)-J36)*'PIECE DENSITIES'!F12 -> 0 | K45: Inc Prim Nonmach | O45: =SUM(N38:N42)*'PIECE DENSITIES'!F17 -> 1.7326782 | P45: Inc Prim Manual
D46: =(SUM(C38:C42)-D36)*'PIECE DENSITIES'!G7 -> 54.202408 | E46: Inc Sec Mach | J46: =(SUM(I38:I42)-J36)*'PIECE DENSITIES'!G12 -> 0 | K46: Inc Sec Nonmach | O46: =SUM(N38:N42)*'PIECE DENSITIES'!G17 -> 23.478536 | P46: Inc Sec Manual
C49: MACHINABLE INCOMING | L49: NONMACHINABLE INCOMING
D51: =SUM(A53:A57)*(1-'ACCEPT RATES'!G16)+SUM(B53:B57)*SUM('ACCEPT RATES'!I16:J16) -> 348.86192 | E51: Rejects | J51: =SUM(G53:G57)*(1-'ACCEPT RATES'!E21) -> 0 | K51: Rejects
A52: REC | B52: Inc MMP AFSM100 | E52: Inc MMP | G52: Keyed | H52: Inc MMP UFSM1000 | K52: Inc MMP | M52: Inc MMP Manual
A53: =B53*(1-'ACCEPT RATES'!C16) -> 0 | B53: =C53*(1+'ACCEPT RATES'!F16+'PIECE DENSITIES'!D8) -> 0 | C53: =C13*('COVERAGE FACTORS'!E38+'COVERAGE FACTORS'!E42) -> 0 | E53: Manual | G53: =H53*(1-'ACCEPT RATES'!C21) -> 0 | H53: =I53*(1+'PIECE DENSITIES'!D13) -> 0 | I53: =C13*'COVERAGE FACTORS'!E40 -> 0 | K53: Manual | M53: =N53 -> 0 | N53: =C13*'COVERAGE FACTORS'!E44 -> 0
A54: =B54*(1-'ACCEPT RATES'!D16) -> 408.59416 | B54: =C54*(1+'ACCEPT RATES'!F16+'PIECE DENSITIES'!D8) -> 1549.5586 | C54: =G13*('COVERAGE FACTORS'!E38+'COVERAGE FACTORS'!E42) -> 1532.9536 | G54: =H54*(1-'ACCEPT RATES'!D21) -> 0 | H54: =I54*(1+'PIECE DENSITIES'!D13) -> 0 | I54: =G13*'COVERAGE FACTORS'!E40 -> 0 | M54: =N54 -> 9.2087653 | N54: =G13*'COVERAGE FACTORS'!E44 -> 9.2087653
G55: =H55*(1-'ACCEPT RATES'!C21) -> 0 | H55: =I55*(1+'PIECE DENSITIES'!D13) -> 0 | I55: =K13*('COVERAGE FACTORS'!E40+'COVERAGE FACTORS'!E42) -> 0 | M55: =N55 -> 0 | N55: =K13*(1-('COVERAGE FACTORS'!E40+'COVERAGE FACTORS'!E42)) -> 0
...

Sheet ADC NONAUTO COST
A1: ADC NONAUTO PRESORT
A2: COST SHEET
C4: ="(1)" -> (1) | D4: ="(2)" -> (2) | E4: (3) | F4: ="(4)" -> (4) | G4: ="(5)" -> (5) | H4: ="(6)" -> (6) | I4: ="(7)" -> (7) | J4: ="(8)" -> (8) | K4: ="(9)" -> (9)
D6: Bundles | F6: Direct | H6: Premium | I6: Premium | J6: Total | K6: Weighted
D7: or Pieces | E7: Wage | F7: Cents | G7: Piggyback | H7: Pay | I7: Pay | J7: Cents | K7: Cents
A8: Operation | C8: Volume | D8: Per Hour | E8: Rate | F8: Per Piece | G8: Factor | H8: Factor | I8: Adjust | J8: Per Piece | K8: Per Piece
A10: Outgoing Primary (Bundles)
B11: APPS | C11: ='BUNDLE SORT'!$I$22*('COVERAGE FACTORS'!$E$6/('COVERAGE FACTORS'!$E$6+'COVERAGE FACTORS'!$E$8)) -> 0 | D11: =PRODUCTIVITIES!$E$8 -> 206.82029 | E11: ='WAGE RATES'!$C$6 -> 50.107175 | F11: =E11*100/D11 -> 24.227398 | G11: =PIGGYBACKS!$B$5 -> 1.8052502 | H11: ='WAGE RATES'!$C$9 -> 0.97520312 | I11: =(H11-1)*F11 -> -0.60076381 | J11: =F11*G11+I11 -> 43.135752 | K11: =C11*$J11/'ADC NONAUTO MODEL'!$G$6 -> 0
B12: APBS / LIPS | C12: ='BUNDLE SORT'!$I$22*('COVERAGE FACTORS'!$E$8/('COVERAGE FACTORS'!$E$6+'COVERAGE FACTORS'!$E$8)) -> 0 | D12: =PRODUCTIVITIES!$E$10 -> 218.50114 | E12: ='WAGE RATES'!$C$6 -> 50.107175 | F12: =E12*100/D12 -> 22.932226 | G12: =PIGGYBACKS!$B$6 -> 1.6056413 | H12: ='WAGE RATES'!$C$9 -> 0.97520312 | I12: =(H12-1)*F12 -> -0.56864758 | J12: =F12*G12+I12 -> 36.25228 | K12: =C12*$J12/'ADC NONAUTO MODEL'!$G$6 -> 0
B13: Manual | C13: ='BUNDLE SORT'!$J$22 -> 139.01438 | D13: =PRODUCTIVITIES!$E$12 -> 388.77899 | E13: ='WAGE RATES'!$C$6 -> 50.107175 | F13: =E13*100/D13 -> 12.888344 | G13: =PIGGYBACKS!$B$7 -> 1.5985379 | H13: ='WAGE RATES'!$C$9 -> 0.97520312 | I13: =(H13-1)*F13 -> -0.31959069 | J13: =F13*G13+I13 -> 20.282916 | K13: =C13*$J13/'ADC NONAUTO MODEL'!$G$6 -> 0.28196169
A15: Incoming MMP (Bundles)
B16: APPS | C16: ='BUNDLE SORT'!$M$22*('COVERAGE FACTORS'!$E$30/('COVERAGE FACTORS'!$E$30+'COVERAGE FACTORS'!$E$32)) -> 226.23388 | D16: =PRODUCTIVITIES!$E$9 -> 236.2304 | E16: ='WAGE RATES'!$C$6 -> 50.107175 | F16: =E16*100/D16 -> 21.211146 | G16: =PIGGYBACKS!$B$5 -> 1.8052502 | H16: ='WAGE RATES'!$C$9 -> 0.97520312 | I16: =(H16-1)*F16 -> -0.52597017 | J16: =F16*G16+I16 -> 37.765456 | K16: =C16*$J16/'ADC NONAUTO MODEL'!$G$6 -> 0.85438256
B17: APBS / LIPS | C17: ='BUNDLE SORT'!$M$22*('COVERAGE FACTORS'!$E$32/('COVERAGE FACTORS'!$E$30+'COVERAGE FACTORS'!$E$32)) -> 273.47989 | D17: =PRODUCTIVITIES!$E$11 -> 181.33504 | E17: ='WAGE RATES'!$C$6 -> 50.107175 | F17: =E17*100/D17 -> 27.632373 | G17: =PIGGYBACKS!$B$6 -> 1.6056413 | H17: ='WAGE RATES'!$C$9 -> 0.97520312 | I17: =(H17-1)*F17 -> -0.68519655 | J17: =F17*G17+I17 -> 43.682481 | K17: =C17*$J17/'ADC NONAUTO MODEL'!$G$6 -> 1.194628
B18: Manual | C18: ='BUNDLE SORT'!$N$22 -> 0 | D18: =PRODUCTIVITIES!$E$13 -> 388.77899 | E18: ='WAGE RATES'!$C$6 -> 50.107175 | F18: =E18*100/D18 -> 12.888344 | G18: =PIGGYBACKS!$B$7 -> 1.5985379 | H18: ='WAGE RATES'!$C$9 -> 0.97520312 | I18: =(H18-1)*F18 -> -0.31959069 | J18: =F18*G18+I18 -> 20.282916 | K18: =C18*$J18/'ADC NONAUTO MODEL'!$G$6 -> 0
A20: Incoming Primary (Bundles)
B21: APPS | C21: ='BUNDLE SORT'!$Q$22*('COVERAGE FACTORS'!$E$30/('COVERAGE FACTORS'!$E$30+'COVERAGE FACTORS'!$E$32)) -> 84.719994 | D21: =PRODUCTIVITIES!$E$9 -> 236.2304 | E21: ='WAGE RATES'!$C$6 -> 50.107175 | F21: =E21*100/D21 -> 21.211146 | G21: =PIGGYBACKS!$B$5 -> 1.8052502 | H21: ='WAGE RATES'!$C$9 -> 0.97520312 | I21: =(H21-1)*F21 -> -0.52597017 | J21: =F21*G21+I21 -> 37.765456 | K21: =C21*$J21/'ADC NONAUTO MODEL'!$G$6 -> 0.31994892
B22: APBS / LIPS | C22: ='BUNDLE SORT'!$Q$22*('COVERAGE FACTORS'!$E$32/('COVERAGE FACTORS'!$E$30+'COVERAGE FACTORS'!$E$32)) -> 102.41267 | D22: =PRODUCTIVITIES!$E$11 -> 181.33504 | E22: ='WAGE RATES'!$C$6 -> 50.107175 | F22: =E22*100/D22 -> 27.632373 | G22: =PIGGYBACKS!$B$6 -> 1.6056413 | H22: ='WAGE RATES'!$C$9 -> 0.97520312 | I22: =(H22-1)*F22 -> -0.68519655 | J22: =F22*G22+I22 -> 43.682481 | K22: =C22*$J22/'ADC NONAUTO MODEL'!$G$6 -> 0.44736394
B23: Manual | C23: ='BUNDLE SORT'!$R$22 -> 5.3966929 | D23: =PRODUCTIVITIES!$E$14 -> 388.77899 | E23: ='WAGE RATES'!$C$6 -> 50.107175 | F23: =E23*100/D23 -> 12.888344 | G23: =PIGGYBACKS!$B$7 -> 1.5985379 | H23: ='WAGE RATES'!$C$9 -> 0.97520312 | I23: =(H23-1)*F23 -> -0.31959069 | J23: =F23*G23+I23 -> 20.282916 | K23: =C23*$J23/'ADC NONAUTO MODEL'!$G$6 -> 0.010946067
A25: Incoming Secondary (Bundles)
B26: APPS | C26: ='BUNDLE SORT'!$U$22*('COVERAGE FACTORS'!$E$30/('COVERAGE FACTORS'!$E$30+'COVERAGE FACTORS'!$E$32)) -> 0.002118956 | D26: =PRODUCTIVITIES!$E$9 -> 236.2304 | E26: ='WAGE RATES'!$C$6 -> 50.107175 | F26: =E26*100/D26 -> 21.211146 | G26: =PIGGYBACKS!$B$5 -> 1.8052502 | H26: ='WAGE RATES'!$C$9 -> 0.97520312 | I26: =(H26-1)*F26 -> -0.52597017 | J26: =F26*G26+I26 -> 37.765456 | K26: =C26*$J26/'ADC NONAUTO MODEL'!$G$6 -> 8.0023339e-06
B27: APBS / LIPS | C27: ='BUNDLE SORT'!$U$22*('COVERAGE FACTORS'!$E$32/('COVERAGE FACTORS'!$E$30+'COVERAGE FACTORS'!$E$32)) -> 0.0025614725 | D27: =PRODUCTIVITIES!$E$11 -> 181.33504 | E27: ='WAGE RATES'!$C$6 -> 50.107175 | F27: =E27*100/D27 -> 27.632373 | G27: =PIGGYBACKS!$B$6 -> 1.6056413 | H27: ='WAGE RATES'!$C$9 -> 0.97520312 | I27: =(H27-1)*F27 -> -0.68519655 | J27: =F27*G27+I27 -> 43.682481 | K27: =C27*$J27/'ADC NONAUTO MODEL'!$G$6 -> 1.1189147e-05
B28: Manual | C28: ='BUNDLE SORT'!$V$22 -> 0.46336242 | D28: =PRODUCTIVITIES!E15 -> 279.1383 | E28: ='WAGE RATES'!$C$6 -> 50.107175 | F28: =E28*100/D28 -> 17.950663 | G28: =PIGGYBACKS!$B$7 -> 1.5985379 | H28: ='WAGE RATES'!$C$9 -> 0.97520312 | I28: =(H28-1)*F28 -> -0.44512037 | J28: =F28*G28+I28 -> 28.249693 | K28: =C28*$J28/'ADC NONAUTO MODEL'!$G$6 -> 0.0013089846
A30: Outgoing Primary (Piece)
B31: AFSM100 Auto | C31: =SUM('ADC NONAUTO MODEL'!$B$25:$B$29) -> 12.899233 | D31: =PRODUCTIVITIES!$E$23*'COVERAGE FACTORS'!$E$24+PRODUCTIVITIES!$E$17*(1-'COVERAGE FACTORS'!$E$24) -> 1572.5271 | E31: ='WAGE RATES'!$C$6 -> 50.107175 | F31: =E31*100/D31 -> 3.1864109 | G31: =PIGGYBACKS!$B$8 -> 1.6305774 | H31: ='WAGE RATES'!$C$9 -> 0.97520312 | I31: =(H31-1)*F31 -> -0.07901304 | J31: =F31*G31+I31 -> 5.1166766 | K31: =C31*$J31/'ADC NONAUTO MODEL'!$G$6 -> 0.0066001206
B32: REC Keying | C32: =SUM('ADC NONAUTO MODEL'!$A$25:$A$29) -> 3.4013244 | D32: =PRODUCTIVITIES!$E$16 -> 888.01171 | E32: ='WAGE RATES'!$C$5 -> 54.14236 | F32: =E32*100/D32 -> 6.0970322 | G32: =PIGGYBACKS!$B$9 -> 1.2615773 | H32: ='WAGE RATES'!$C$9 -> 0.97520312 | I32: =(H32-1)*F32 -> -0.15118736 | J32: =F32*G32+I32 -> 7.5406902 | K32: =C32*$J32/'ADC NONAUTO MODEL'!$G$6 -> 0.0025648334
B33: UFSM1000 Auto | C33: =SUM('ADC NONAUTO MODEL'!$H$25:$H$29) -> 0 | D33: =PRODUCTIVITIES!$E$30 -> 1.0273269 | E33: ='WAGE RATES'!$C$6 -> 50.107175 | F33: =E33*100/D33 -> 4877.4324 | G33: =PIGGYBACKS!$B$10 -> 1.6305774 | H33: ='WAGE RATES'!$C$9 -> 0.97520312 | I33: =(H33-1)*F33 -> -120.94509 | J33: =F33*G33+I33 -> 7832.086 | K33: =C33*$J33/'ADC NONAUTO MODEL'!$G$6 -> 0
B34: UFSM1000 Keying | C34: =SUM('ADC NONAUTO MODEL'!$G$25:$G$29) -> 0 | D34: =PRODUCTIVITIES!$E$36 -> 1.0273269 | E34: ='WAGE RATES'!$C$6 -> 50.107175 | F34: =E34*100/D34 -> 4877.4324 | G34: =PIGGYBACKS!$B$10 -> 1.6305774 | H34: ='WAGE RATES'!$C$9 -> 0.97520312 | I34: =(H34-1)*F34 -> -120.94509 | J34: =F34*G34+I34 -> 7832.086 | K34: =C34*$J34/'ADC NONAUTO MODEL'!$G$6 -> 0
B35: Manual | C35: =SUM('ADC NONAUTO MODEL'!$M$25:$M$29) -> 0.81319489 | D35: =PRODUCTIVITIES!$E$42 -> 620.26372 | E35: ='WAGE RATES'!$C$6 -> 50.107175 | F35: =E35*100/D35 -> 8.0783662 | G35: =PIGGYBACKS!$B$12 -> 1.3622907 | H35: ='WAGE RATES'!$C$9 -> 0.97520312 | I35: =(H35-1)*F35 -> -0.20031825 | J35: =F35*G35+I35 -> 10.804765 | K35: =C35*$J35/'ADC NONAUTO MODEL'!$G$6 -> 0.00087863798
A37: Outgoing Secondary (Piece)
B38: AFSM100 Auto | C38: =SUM('ADC NONAUTO MODEL'!$B$38:$B$42) -> 1.5666016 | D38: =PRODUCTIVITIES!$E$24*'COVERAGE FACTORS'!$E$24+PRODUCTIVITIES!$E$18*(1-'COVERAGE FACTORS'!$E$24) -> 2267.7698 | E38: ='WAGE RATES'!$C$6 -> 50.107175 | F38: =E38*100/D38 -> 2.2095353 | G38: =PIGGYBACKS!$B$8 -> 1.6305774 | H38: ='WAGE RATES'!$C$9 -> 0.97520312 | I38: =(H38-1)*F38 -> -0.054789575 | J38: =F38*G38+I38 -> 3.5480288 | K38: =C38*$J38/'ADC NONAUTO MODEL'!$G$6 -> 0.00055583475
B39: REC Keying | C39: =SUM('ADC NONAUTO MODEL'!$A$38:$A$42) -> 0.096032141 | D39: =PRODUCTIVITIES!$E$16 -> 888.01171 | E39: ='WAGE RATES'!$C$5 -> 54.14236 | F39: =E39*100/D39 -> 6.0970322 | G39: =PIGGYBACKS!$B$9 -> 1.2615773 | H39: ='WAGE RATES'!$C$9 -> 0.97520312 | I39: =(H39-1)*F39 -> -0.15118736 | J39: =F39*G39+I39 -> 7.5406902 | K39: =C39*$J39/'ADC NONAUTO MODEL'!$G$6 -> 7.2414863e-05
B40: UFSM1000 Auto | C40: =SUM('ADC NONAUTO MODEL'!$H$38:$H$42) -> 0 | D40: =PRODUCTIVITIES!$E$31 -> 1.0273269 | E40: ='WAGE RATES'!$C$6 -> 50.107175 | F40: =E40*100/D40 -> 4877.4324 | G40: =PIGGYBACKS!$B$10 -> 1.6305774 | H40: ='WAGE RATES'!$C$9 -> 0.97520312 | I40: =(H40-1)*F40 -> -120.94509 | J40: =F40*G40+I40 -> 7832.086 | K40: =C40*$J40/'ADC NONAUTO MODEL'!$G$6 -> 0
B41: UFSM1000 Keying | C41: =SUM('ADC NONAUTO MODEL'!$G$38:$G$42) -> 0 | D41: =PRODUCTIVITIES!$E$37 -> 1.0273269 | E41: ='WAGE RATES'!$C$6 -> 50.107175 | F41: =E41*100/D41 -> 4877.4324 | G41: =PIGGYBACKS!$B$10 -> 1.6305774 | H41: ='WAGE RATES'!$C$9 -> 0.97520312 | I41: =(H41-1)*F41 -> -120.94509 | J41: =F41*G41+I41 -> 7832.086 | K41: =C41*$J41/'ADC NONAUTO MODEL'!$G$6 -> 0
B42: Manual | C42: =SUM('ADC NONAUTO MODEL'!$M$38:$M$42) -> 0.21797514 | D42: =PRODUCTIVITIES!$E$43 -> 490.62129 | E42: ='WAGE RATES'!$C$6 -> 50.107175 | F42: =E42*100/D42 -> 10.213005 | G42: =PIGGYBACKS!$B$12 -> 1.3622907 | H42: ='WAGE RATES'!$C$9 -> 0.97520312 | I42: =(H42-1)*F42 -> -0.25325062 | J42: =F42*G42+I42 -> 13.659831 | K42: =C42*$J42/'ADC NONAUTO MODEL'!$G$6 -> 0.00029775035
A44: Incoming MMP (Piece)
B45: AFSM100 Auto | C45: =SUM('ADC NONAUTO MODEL'!$B$53:$B$57) -> 3748.8246 | D45: =PRODUCTIVITIES!$E$25*'COVERAGE FACTORS'!$E$24+PRODUCTIVITIES!$E$19*(1-'COVERAGE FACTORS'!$E$24) -> 1572.9754 | E45: ='WAGE RATES'!$C$6 -> 50.107175 | F45: =E45*100/D45 -> 3.1855028 | G45: =PIGGYBACKS!$B$8 -> 1.6305774 | H45: ='WAGE RATES'!$C$9 -> 0.97520312 | I45: =(H45-1)*F45 -> -0.078990522 | J45: =F45*G45+I45 -> 5.1152184 | K45: =C45*$J45/'ADC NONAUTO MODEL'!$G$6 -> 1.9176057
B46: REC Keying | C46: =SUM('ADC NONAUTO MODEL'!$A$53:$A$57) -> 987.01428 | D46: =PRODUCTIVITIES!$E$16 -> 888.01171 | E46: ='WAGE RATES'!$C$5 -> 54.14236 | F46: =E46*100/D46 -> 6.0970322 | G46: =PIGGYBACKS!$B$9 -> 1.2615773 | H46: ='WAGE RATES'!$C$9 -> 0.97520312 | I46: =(H46-1)*F46 -> -0.15118736 | J46: =F46*G46+I46 -> 7.5406902 | K46: =C46*$J46/'ADC NONAUTO MODEL'!$G$6 -> 0.74427689
B47: UFSM1000 Auto | C47: =SUM('ADC NONAUTO MODEL'!$H$53:$H$57) -> 0 | D47: =PRODUCTIVITIES!$E$32 -> 1.0273269 | E47: ='WAGE RATES'!$C$6 -> 50.107175 | F47: =E47*100/D47 -> 4877.4324 | G47: =PIGGYBACKS!$B$10 -> 1.6305774 | H47: ='WAGE RATES'!$C$9 -> 0.97520312 | I47: =(H47-1)*F47 -> -120.94509 | J47: =F47*G47+I47 -> 7832.086 | K47: =C47*$J47/'ADC NONAUTO MODEL'!$G$6 -> 0
B48: UFSM1000 Keying | C48: =SUM('ADC NONAUTO MODEL'!$G$53:$G$57) -> 0 | D48: =PRODUCTIVITIES!$E$38 -> 1.0273269 | E48: ='WAGE RATES'!$C$6 -> 50.107175 | F48: =E48*100/D48 -> 4877.4324 | G48: =PIGGYBACKS!$B$10 -> 1.6305774 | H48: ='WAGE RATES'!$C$9 -> 0.97520312 | I48: =(H48-1)*F48 -> -120.94509 | J48: =F48*G48+I48 -> 7832.086 | K48: =C48*$J48/'ADC NONAUTO MODEL'!$G$6 -> 0
B49: Manual | C49: =SUM('ADC NONAUTO MODEL'!$M$53:$M$57) -> 349.39865 | D49: =PRODUCTIVITIES!$E$44 -> 692.96374 | E49: ='WAGE RATES'!$C$6 -> 50.107175 | F49: =E49*100/D49 -> 7.2308508 | G49: =PIGGYBACKS!$B$12 -> 1.3622907 | H49: ='WAGE RATES'!$C$9 -> 0.97520312 | I49: =(H49-1)*F49 -> -0.17930252 | J49: =F49*G49+I49 -> 9.6712185 | K49: =C49*$J49/'ADC NONAUTO MODEL'!$G$6 -> 0.33791107
...

Sheet ADC NONAUTO MODEL
A1: ='ADC NONAUTO COST'!A1 -> ADC NONAUTO PRESORT
A2: MAIL FLOW MODEL
A6: PCS IN = | C6: =SUM(C11:C16)+SUM(G11:G16)+SUM(K11:K16)+SUM(O11:O16) -> 10000 | E6: PCS OUT = | G6: =D88+J88+O88+D100+D127 -> 10000
A10: PIECE ENTRY POINTS:
B11: BC Mach Out Prim | C11: 0 | F11: Non-BC Mach Out Prim | G11: ='ENTRY PROFILE'!K15 -> 12.759434 | J11: BC Nonmach Out Prim | K11: 0 | N11: Non-BC Nonmach Out Prim | O11: 0
B12: BC Mach Out Sec | C12: 0 | F12: Non-BC Mach Out Sec | G12: 0 | J12: BC Nonmach Out Sec | K12: 0 | N12: Non-BC Nonmach Out Sec | O12: 0
B13: BC Mach Inc MMP | C13: 0 | F13: Non-BC Mach Inc MMP | G13: ='ENTRY PROFILE'!L15+'ENTRY PROFILE'!O15+'ENTRY PROFILE'!O16+'ENTRY PROFILE'!O17+'ENTRY PROFILE'!O18+'ENTRY PROFILE'!P15+'ENTRY PROFILE'!P16 -> 3723.5958 | J13: BC Nonmach Inc MMP | K13: 0 | N13: Non-BC Nonmach Inc MMP | O13: 0
B14: BC Mach Inc SCF | C14: 0 | F14: Non-BC Mach Inc SCF | G14: ='ENTRY PROFILE'!P17+'ENTRY PROFILE'!S17+'ENTRY PROFILE'!S18+'ENTRY PROFILE'!S19+'ENTRY PROFILE'!S20+'ENTRY PROFILE'!S21+'ENTRY PROFILE'!T17+'ENTRY PROFILE'!T19+'ENTRY PROFILE'!T20 -> 3982.6648 | J14: BC Nonmach Inc SCF | K14: 0 | N14: Non-BC Nonmach Inc SCF | O14: 0
B15: BC Mach Inc Prim | C15: 0 | F15: Non-BC Mach Inc Prim | G15: 0 | J15: BC Nonmach Inc Prim | K15: 0 | N15: Non-BC Nonmach Inc Prim | O15: 0
B16: BC Mach Inc Sec | C16: 0 | F16: Non-BC Mach Inc sec | G16: ='ENTRY PROFILE'!P18+'ENTRY PROFILE'!T18+'ENTRY PROFILE'!T21+'ENTRY PROFILE'!W18+'ENTRY PROFILE'!W21+'ENTRY PROFILE'!X18+'ENTRY PROFILE'!X21 -> 2280.98 | J16: BC Nonmach Inc Sec | K16: 0 | N16: Non-BC Nonmach Inc sec | O16: 0
C21: MACHINABLE OUTGOING | L21: NONMACHINABLE OUTGOING
D23: =SUM(A25:A29)*(1-'ACCEPT RATES'!G14)+SUM(B25:B29)*SUM('ACCEPT RATES'!I14:J14) -> 0.79113893 | E23: Rejects | J23: =SUM(G25:G29)*(1-'ACCEPT RATES'!E19) -> 0 | K23: Rejects
A24: REC | B24: Out Prim AFSM100 | E24: Out Prim | G24: Keyed | H24: Out Prim UFSM1000 | K24: Out Prim | M24: Out Prim Manual
A25: =B25*(1-'ACCEPT RATES'!C14) -> 0 | B25: =C25*(1+'ACCEPT RATES'!F14) -> 0 | C25: =C11*('COVERAGE FACTORS'!E14+'COVERAGE FACTORS'!E18) -> 0 | E25: Manual | G25: =H25*(1-'ACCEPT RATES'!C19) -> 0 | H25: =I25 -> 0 | I25: =C11*'COVERAGE FACTORS'!E16 -> 0 | K25: Manual | M25: =N25 -> 0 | N25: =C11*'COVERAGE FACTORS'!E20 -> 0
