Workbook

Sheet SUMMARY
A1: FIRST-CLASS MAIL CARDS / LETTERS SUMMARY
A2: USPS-FY25-10
B4: [1] | C4: [2] | D4: [3] | E4: [4] | F4: [5] | G4: [6] | H4: [7] | I4: [8] | J4: [9]
I5: Incremental | J5: Cummulative
B6: TOTAL MAIL | C6: Mail Processing | D6: Delivery | E6: Collection | F6: Total | G6: Incremental | H6: Cummulative | I6: WS Related | J6: WS Related
B7: PROCESSING | C7: WS Related | D7: WS Related | E7: Mail | F7: WS Related | G7: WS Related | H7: WS Related | I7: Unit Cost Savings | J7: Unit Cost Savings
A8: PRICE CATEGORY | B8: UNIT COST | C8: Unit Cost | D8: Unit Cost | E8: Unit Cost | F8: Unit Cost | G8: Unit Cost Savings | H8: Unit Cost Savings | I8: (cents) | J8: (cents)
B9: (CENTS) | C9: (cents) | D9: (cents) | E9: (cents) | F9: (cents) | G9: (cents) | H9: (cents) | I9: (rounded to mils) | J9: (rounded to mils)
A10: Letters:
A11: Machinable Metered Letters | B11: ='PRESORT LETTERS SUM'!I52 -> 20.114653 | C11: ='PRESORT LETTERS SUM'!G52 -> 19.989927 | D11: =B45 -> 7.2605039 | E11: ='[1]1.Table 1'!$E$77 -> 1.4767609 | F11: =C11+D11+E11 -> 28.727192
A12: Nonmachinable Metered Letters | B12: ='PRESORT LETTERS SUM'!I53 -> 64.504313 | C12: ='PRESORT LETTERS SUM'!G53 -> 64.379587 | D12: =B41 -> 28.420198 | E12: =E11 -> 1.4767609 | F12: =C12+D12+E12 -> 94.276546
A13: ='PRESORT LETTERS SUM'!A54 -> Nonautomation Nonmachinable Mixed ADC Letters | B13: ='PRESORT LETTERS SUM'!I54 -> 51.222549 | C13: ='PRESORT LETTERS SUM'!G54 -> 51.187916 | D13: =B41 -> 28.420198 | E13: 0 | F13: =C13+D13+E13 -> 79.608114 | G13: =F12-F13 -> 14.668432 | H13: =G13 -> 14.668432 | I13: =ROUND(G13,1) -> 14.7 | J13: =ROUND(H13,1) -> 14.7
A14: ='PRESORT LETTERS SUM'!A55 -> Nonautomation Nonmachinable ADC Letters | B14: ='PRESORT LETTERS SUM'!I55 -> 34.621178 | C14: ='PRESORT LETTERS SUM'!G55 -> 34.586545 | D14: =B42 -> 0 | E14: 0 | F14: =C14+D14+E14 -> 34.586545 | G14: =F13-F14 -> 45.021569
A15: ='PRESORT LETTERS SUM'!A56 -> Nonautomation Nonmachinable 3-Digit Letters | B15: ='PRESORT LETTERS SUM'!I56 -> 33.913493 | C15: ='PRESORT LETTERS SUM'!G56 -> 33.878859 | D15: =B43 -> 28.420198 | E15: 0 | F15: =C15+D15+E15 -> 62.299058 | G15: =F14-F15 -> -27.712512
A16: ='PRESORT LETTERS SUM'!A57 -> Nonautomation Nonmachinable 5-Digit Letters | B16: ='PRESORT LETTERS SUM'!I57 -> 18.127846 | C16: ='PRESORT LETTERS SUM'!G57 -> 18.093213 | D16: =B44 -> 28.420198 | E16: 0 | F16: =C16+D16+E16 -> 46.513411 | G16: =F15-F16 -> 15.785647
A17: ='PRESORT LETTERS SUM'!A58 -> Nonautomation Machinable Mixed AADC Letters | B17: ='PRESORT LETTERS SUM'!I58 -> 15.498421 | C17: ='PRESORT LETTERS SUM'!G58 -> 15.463787 | D17: =B45 -> 7.2605039 | E17: 0 | F17: =C17+D17+E17 -> 22.724291 | G17: =F11-F17 -> 6.0029008 | H17: =G17 -> 6.0029008 | I17: =ROUND(G17,1) -> 6 | J17: =ROUND(H17,1) -> 6
A18: ='PRESORT LETTERS SUM'!A59 -> Nonautomation Machinable AADC Letters | B18: ='PRESORT LETTERS SUM'!I59 -> 11.225482 | C18: ='PRESORT LETTERS SUM'!G59 -> 11.190849 | D18: =B46 -> 6.0594173 | E18: 0 | F18: =C18+D18+E18 -> 17.250266 | G18: =F17-F18 -> 5.4740252
A19: ='PRESORT LETTERS SUM'!A60 -> Nonautomation Machinable 3-Digit Letters | B19: ='PRESORT LETTERS SUM'!I60 -> 11.225482 | C19: ='PRESORT LETTERS SUM'!G60 -> 11.190849 | D19: =B47 -> 0 | E19: 0 | F19: =C19+D19+E19 -> 11.190849
A20: ='PRESORT LETTERS SUM'!A61 -> Nonautomation Machinable 5-Digit Letters | B20: ='PRESORT LETTERS SUM'!I61 -> 11.225482 | C20: ='PRESORT LETTERS SUM'!G61 -> 11.190849 | D20: =B48 -> 0 | E20: 0 | F20: =C20+D20+E20 -> 11.190849
A21: ='PRESORT LETTERS SUM'!A62 -> Average Nonautomation Machinable Letters | B21: ='PRESORT LETTERS SUM'!I62 -> 12.648778 | C21: ='PRESORT LETTERS SUM'!G62 -> 12.614145 | D21: =B49 -> 6.4594937 | E21: 0 | F21: =C21+D21+E21 -> 19.073639
A22: Automation MAADC Presort Letters | B22: ='PRESORT LETTERS SUM'!I63 -> 14.438736 | C22: ='PRESORT LETTERS SUM'!G63 -> 14.404103 | D22: =B50 -> 6.9939801 | E22: 0 | F22: =C22+D22+E22 -> 21.398083 | G22: =F17-F22 -> 1.3262081 | H22: =F$11-F22 -> 7.329109 | I22: =ROUND(G22,1) -> 1.3 | J22: =ROUND(H22,1) -> 7.3
A23: Automation AADC Presort Letters | B23: ='PRESORT LETTERS SUM'!I64 -> 11.303488 | C23: ='PRESORT LETTERS SUM'!G64 -> 11.268855 | D23: =B51 -> 6.2344184 | E23: 0 | F23: =C23+D23+E23 -> 17.503273 | G23: =(F22-F23) -> 3.8948096 | H23: =F$11-F23 -> 11.223919 | I23: =ROUND(G23,1) -> 3.9 | J23: =ROUND(H23,1) -> 11.2
A24: Automation 3-Digit Presort Letters | B24: ='PRESORT LETTERS SUM'!I65 -> 9.6582358 | C24: ='PRESORT LETTERS SUM'!G65 -> 9.6236025 | E24: 0 | F24: =C24+D24+E24 -> 9.6236025 | G24: =(F23-F24) -> 7.879671 | H24: =F$11-F24 -> 19.10359 | I24: =ROUND(G24,1) -> 7.9 | J24: =ROUND(H24,1) -> 19.1
A25: Weight-Averaged AADC & 3D Letters | E25: 0 | F25: =((F23*'PRESORT LETTERS SUM'!E25)+('PRESORT LETTERS SUM'!E26*SUMMARY!F24))/('PRESORT LETTERS SUM'!E25+'PRESORT LETTERS SUM'!E26) -> 17.503273 | H25: =F$11-F25 -> 11.223919 | J25: =ROUND(H25,1) -> 11.2
A26: Automation 5-Digit Presort Letters | B26: ='PRESORT LETTERS SUM'!I66 -> 6.4645107 | C26: ='PRESORT LETTERS SUM'!G66 -> 6.4298774 | D26: =B53 -> 5.0866988 | E26: 0 | F26: =C26+D26+E26 -> 11.516576 | G26: =F23-F26 -> 5.9866973 | H26: =F$11-F26 -> 17.210616 | I26: =ROUND(G26,1) -> 6 | J26: =ROUND(H26,1) -> 17.2
A27: Cards:
A28: Nonautomation Presort Cards | B28: ='PRESORT CARDS SUM'!J34 -> 5.1568724 | C28: ='PRESORT CARDS SUM'!H34 -> 5.1558466 | D28: =B55 -> 6.4762572 | E28: 0 | F28: =C28+D28+E28 -> 11.632104
A29: Nonautomation MAADC BC-Benchmark | B29: ='PRESORT CARDS SUM'!J35 -> 6.1190808 | C29: ='PRESORT CARDS SUM'!H35 -> 6.1180551 | D29: =D28 -> 6.4762572 | E29: 0 | F29: =C29+D29+E29 -> 12.594312
A30: Automation MAADC Presort Cards | B30: ='PRESORT CARDS SUM'!J36 -> 5.6993844 | C30: ='PRESORT CARDS SUM'!H36 -> 5.6983586 | D30: =B56 -> 6.2643686 | E30: 0 | F30: =C30+D30+E30 -> 11.962727 | G30: =(F29-F30) -> 0.63158506 | H30: =F$29-F30 -> 0.63158506 | I30: =ROUND(G30,1) -> 0.6 | J30: =ROUND(H30,1) -> 0.6
A31: Automation AADC Presort Cards | B31: ='PRESORT CARDS SUM'!J37 -> 4.4576444 | C31: ='PRESORT CARDS SUM'!H37 -> 4.4566186 | D31: =B57 -> 5.6605107 | E31: 0 | F31: =C31+D31+E31 -> 10.117129 | G31: =(F30-F31) -> 1.8455978 | H31: =F$28-F31 -> 1.5149745 | I31: =ROUND(G31,1) -> 1.8 | J31: =ROUND(H31,1) -> 1.5
A32: Automation 3-Digit Presort Cards | B32: ='PRESORT CARDS SUM'!J38 -> 3.806029 | C32: ='PRESORT CARDS SUM'!H38 -> 3.8050032 | D32: =B58 -> 0 | E32: 0 | F32: =C32+D32+E32 -> 3.8050032 | G32: =(F31-F32) -> 6.3121262 | H32: =F$28-F32 -> 7.8271006 | I32: =ROUND(G32,1) -> 6.3 | J32: =ROUND(H32,1) -> 7.8
A33: Weight-Averaged Automation AADC & 3D Presort Cards | F33: =((F31*'MCS CARDS'!E34)+('MCS CARDS'!E35*SUMMARY!F32))/('MCS CARDS'!E34+'MCS CARDS'!E35) -> 10.117129
A34: Automation 5-Digit Presort Cards | B34: ='PRESORT CARDS SUM'!J39 -> 2.5411286 | C34: ='PRESORT CARDS SUM'!H39 -> 2.5401029 | D34: =B59 -> 4.7480641 | E34: 0 | F34: =C34+D34+E34 -> 7.288167 | G34: =(F33-F34) -> 2.8289624 | H34: =F$28-F34 -> 4.3439369 | I34: =ROUND(G34,1) -> 2.8 | J34: =ROUND(H34,1) -> 4.3
A37: Nonautomation Presort Letters (all - Mach & Non) | B37: ='PRESORT LETTERS SUM'!J62 -> 12.906482
B39: [10]
B40: Delivery Costs
A41: Nonautomation -- Nonmach Mixed ADC | B41: ='[1]1.Table 1'!$C$14 -> 28.420198
A42: Nonautomation -- Nonmach ADC | B42: ='[1]1.Table 1'!$C$15 -> 0
A43: Nonautomation -- Nonmach 3-Digit | B43: ='[1]1.Table 1'!$C$18 -> 28.420198
A44: Nonautomation -- Nonmach 5-Digit | B44: ='[1]1.Table 1'!$C$19 -> 28.420198
...

Sheet PRESORT LETTERS SUM
A1: FIRST-CLASS PRESORT LETTERS MAIL PROCESSING UNIT COST SUMMARY
A5: Table 1: CRA Mail Processing Unit Costs | D5: Presort | E5: Metered
A6: Proportional Cost Pools | C6: 1/ | D6: ='CRA - PRESORT LETTERS'!E77 -> 7.1222227 | E6: ='CRA-METERED LETTERS'!E77 -> 16.551905
A7: WS Related Fixed Cost Pools | C7: 2/ | D7: ='CRA - PRESORT LETTERS'!G77 -> 0.7663823 | E7: ='CRA-METERED LETTERS'!G77 -> 3.5753142
A8: Non-WS Related Fixed Cost Pools | C8: 2/ | D8: ='CRA - PRESORT LETTERS'!H77 -> 0.034633267 | E8: ='CRA-METERED LETTERS'!H77 -> 0.12472578
A9: Total | C9: 3/ | D9: =SUM(D6:D8) -> 7.9232383 | E9: =SUM(E6:E8) -> 20.251945
A12: Table 2: CRA Proportional Adjustment Factor | G12: Volume % | H12: Volume %
D13: Model Cost | E13: Volume | F13: Volume % | G13: of Machinable | H13: of Total
A14: Base Model Costs | D14: [1] | E14: [2] | F14: [3] | G14: Nonauto | H14: Nonauto
A15: Nonautomation Nonmachinable Mixed ADC | D15: ='NMACH MADC COST'!L44 -> 24.650503 | E15: =SUM('MCS LETTERS'!E15:E19) -> 2226152 | F15: =E15/$E$29 -> 7.6422702e-05 | H15: =$E15/H$23 -> 0.0044425542
A16: Nonautomation Nonmachinable ADC | D16: ='NMACH ADC COST'!L44 -> 16.534285 | E16: 0 | F16: =E16/$E$29 -> 0 | H16: =$E16/H$23 -> 0
A17: Nonautomation Nonmachinable 3-Digit | D17: ='NMACH 3-DIGIT COST'!L44 -> 16.188306 | E17: =SUM('MCS LETTERS'!E24:E26) -> 1700815 | F17: =E17/$E$29 -> 5.8388141e-05 | H17: =$E17/H$23 -> 0.003394181
A18: Nonautomation Nonmachinable 5-Digit | D18: ='NMACH 5-DIGIT COST'!L44 -> 8.4708862 | E18: ='MCS LETTERS'!E27 -> 1295105 | F18: =E18/$E$29 -> 4.4460317e-05 | H18: =$E18/H$23 -> 0.0025845379
A19: Nonautomation Machinable Mixed AADC | D19: ='MACH MAADC COST'!L44 -> 7.1853907 | E19: ='MCS LETTERS'!E6 -> 1.6517378e+08 | F19: =E19/$E$29 -> 0.0056703346 | G19: =$E19/G$23 -> 0.33309544 | H19: =$E19/H$23 -> 0.32962416
A20: Nonautomation Machinable AADC | D20: ='MACH INCOMING COST'!L44 -> 5.0964007 | E20: ='MCS LETTERS'!E7 -> 3.3070146e+08 | F20: =E20/$E$29 -> 0.011352818 | G20: =$E20/G$23 -> 0.66690456 | H20: =$E20/H$23 -> 0.65995457
A21: Nonautomation Machinable 3-Digit | D21: ='MACH INCOMING COST'!L44 -> 5.0964007 | E21: ='MCS LETTERS'!E8 -> 0 | F21: =E21/$E$29 -> 0 | G21: =$E21/G$23 -> 0 | H21: =$E21/H$23 -> 0
A22: Nonautomation Machinable 5-Digit | D22: ='MACH INCOMING COST'!L44 -> 5.0964007 | E22: ='MCS LETTERS'!E9 -> 0 | F22: =E22/$E$29 -> 0 | G22: =$E22/G$23 -> 0 | H22: =$E22/H$23 -> 0
A23: Automation Mixed AADC | D23: =+'AUTO MAADC COST'!$L$43 -> 6.6673234 | E23: ='MCS LETTERS'!E33 -> 1.2718216e+09 | F23: =E23/$E$29 -> 0.043661008 | G23: =SUM($E19:$E22) -> 4.9587525e+08 | H23: =SUM($E15:$E22) -> 5.0109732e+08
A25: Automation AADC | D25: =+'AUTO AADC COST'!$L$44 -> 5.134537 | E25: ='MCS LETTERS'!E34 -> 6.0182342e+09 | F25: =E25/$E$29 -> 0.20660302
A26: Automation 3-Digit | D26: =+'AUTO 3-DIGIT COST'!$L$44 -> 4.3301922 | E26: ='MCS LETTERS'!E35 -> 0 | F26: =E26/$E$29 -> 0
A27: Automation 5-Digit Other | D27: ='AUTO 5-DIGIT OTHER COST'!L44 -> 2.8174484 | E27: ='MCS LETTERS'!E36*MISC!E18 -> 2.0587921e+10 | F27: =E27/$E$29 -> 0.70677318
A28: Automation 5-Digit Manual | D28: ='Auto 5-digit Manual Cost'!L44 -> 1.4345444 | E28: ='MCS LETTERS'!E36*(MISC!E15+MISC!E16+MISC!E17) -> 7.5038577e+08 | F28: =E28/$E$29 -> 0.025760374
A29: Total Weighted Model Cost | C29: 4/ | D29: =SUMPRODUCT(D15:D28,F15:F28) -> 3.481972 | E29: =SUM(E15:E28) -> 2.912946e+10 | F29: =SUM(F15:F28) -> 1
A31: CRA Proportional Adjustment | C31: 5/ | D31: =+D6/D29 -> 2.0454566
IQ32: .
A36: Table 2A: Metered Mail CRA Proportional Adjustment Factor
D37: Model Cost | E37: Volume | F37: Volume %
A38: Base Model Costs | D38: [1] | E38: [2] | F38: [3]
A39: Metered Machinable Letters | D39: ='METERED LETTERS COST'!L43 -> 7.1473715 | E39: =BMM_Volume!G21-BMM_Volume!G16-BMM_Volume!G17-BMM_Volume!G20 -> 3.3406468e+09 | F39: =E39/$E$41 -> 0.99690712
A40: Metered Nonmachinable Letters | D40: ='METERED LETTERS NONMACH_COST'!L43 -> 26.475843 | E40: =BMM_Volume!G16+BMM_Volume!G17+BMM_Volume!G20 -> 10364265 | F40: =E40/$E$41 -> 0.003092877
A41: Total Weighted Model Cost | C41: 4/ | D41: =SUMPRODUCT(D39:D40,F39:F40) -> 7.2071521 | E41: =SUM(E39:E40) -> 3.3510111e+09 | F41: =SUM(F39:F40) -> 1
A43: CRA Proportional Adjustment | C43: 5/ | D43: =E6/D41 -> 2.2965944
A47: Table 3: Adjusted Letter Mail Processing Unit Costs
E48: CRA | F48: WS Related | G48: Total | H48: Non-WS Related | I48: Total
D49: Model | E49: Adjusted | F49: Fixed | G49: WS Related | H49: Fixed | I49: Mail Proc
D50: Unit Cost | E50: Unit Cost | F50: Unit Cost | G50: Unit Cost | H50: Unit Cost | I50: Unit Cost
A51: Price Category | D51: [4] | E51: [5] | F51: [6] | G51: [7] | H51: [8] | I51: [9]
A52: Machinable Metered Letters | D52: ='METERED LETTERS COST'!L43 -> 7.1473715 | E52: =D39*D43 -> 16.414613 | F52: ='CRA-METERED LETTERS'!G77 -> 3.5753142 | G52: =E52+F52 -> 19.989927 | H52: ='CRA-METERED LETTERS'!H77 -> 0.12472578 | I52: =+F52+E52+H52 -> 20.114653
A53: Nonmachinable Metered Letters | D53: =D40 -> 26.475843 | E53: =D53*D43 -> 60.804273 | F53: =E7 -> 3.5753142 | G53: =E53+F53 -> 64.379587 | H53: =E8 -> 0.12472578 | I53: =+F53+E53+H53 -> 64.504313
A54: Nonautomation Nonmachinable Mixed ADC Letters | D54: =D15 -> 24.650503 | E54: =+D54*D$31 -> 50.421534 | F54: =+$D$7 -> 0.7663823 | G54: =E54+F54 -> 51.187916 | H54: =D$8 -> 0.034633267 | I54: =+F54+E54+H54 -> 51.222549
...

Sheet PRESORT CARDS SUM
A1: FIRST-CLASS PRESORT CARDS MAIL PROCESSING UNIT COST SUMMARY
B6: Table 1: CRA Mail Processing Unit Costs
B7: Proportional Cost Pools | D7: 1/ | E7: ='CRA - PRESORT CARDS'!E77 -> 3.2425787
B8: WS Related Fixed Cost Pools | D8: 2/ | E8: ='CRA - PRESORT CARDS'!G77 -> 0.29703041
B9: Non-WS Related Fixed Cost Pools | E9: ='CRA - PRESORT CARDS'!H77 -> 0.0010257482
B10: Total | D10: 3/ | E10: =SUM(E7:E8) -> 3.5396091
B13: Table 2: CRA Proportional Adjustment Factor
E14: Model Cost | F14: Volume | G14: Volume %
B15: Base Model Costs | E15: [1] | F15: [2] | G15: [3]
B16: NonAutomation | E16: =SUMPRODUCT('PRESORT LETTERS SUM'!D15:D22,'CARD-LETTER COST RATIO'!K10:K17)*'CARD-LETTER COST RATIO'!$E$33 -> 2.3696893 | F16: ='MCS CARDS'!E32 -> 80860526 | G16: =F16/F24 -> 0.03455136
B17: Nonautomation MAADC BC-Benchmark | E17: =+'PRESORT LETTERS SUM'!D19*'CARD-LETTER COST RATIO'!$E$33 -> 2.8389671 | F17: N/A | H17: Note:Volume of this category is part of the NonAutomation category above, model cost calculated for purposes of barcode cost avoidance analysis.
B18: Automation Mixed AADC | E18: =+'PRESORT LETTERS SUM'!D23*'CARD-LETTER COST RATIO'!$E$33 -> 2.6342773 | F18: ='MCS CARDS'!E33 -> 1.9147464e+08 | G18: =+F18/F$24 -> 0.081816301
B19: Automation AADC | E19: =+'PRESORT LETTERS SUM'!D25*'CARD-LETTER COST RATIO'!$E$33 -> 2.0286693 | F19: ='MCS CARDS'!E34 -> 7.9462297e+08 | G19: =+F19/F$24 -> 0.33953903
B20: Automation 3-Digit | E20: =+'PRESORT LETTERS SUM'!D26*'CARD-LETTER COST RATIO'!$E$33 -> 1.7108705 | F20: 0 | G20: =+F20/F$24 -> 0
B21: Automation 5-Digit Other | E21: =+'PRESORT LETTERS SUM'!D27*'CARD-LETTER COST RATIO'!$E$33 -> 1.1131814 | F21: ='MCS CARDS'!E36*(MISC!E18) -> 1.2285627e+09 | G21: =+F21/F$24 -> 0.52495965
B22: Automation 5-Digit Manual | E22: =+'PRESORT LETTERS SUM'!D28*'CARD-LETTER COST RATIO'!$E$33 -> 0.56679235 | F22: ='MCS CARDS'!E36*(MISC!E15+MISC!E16+MISC!E17) -> 44778490 | G22: =+F22/F$24 -> 0.019133659
B24: Total Weighted Model Cost | D24: 4/ | E24: =SUMPRODUCT(E16:E23,G16:G23) -> 1.5814354 | F24: =SUM(F16:F23) -> 2.3402994e+09 | G24: =SUM(G16:G23) -> 1
B26: CRA Proportional Adjustment | D26: 5/ | E26: =+E7/E24 -> 2.0504023
IR27: .
B29: Table 3: Adjusted Letter Unit Mail Processing Costs
F30: CRA | G30: WS Related | H30: Total | I30: Non-WS Related | J30: Total
E31: Model | F31: Adjusted | G31: Fixed | H31: WS Related | I31: Fixed | J31: Mail Proc
E32: Unit Cost | F32: Unit Cost | G32: Unit Cost | H32: Unit Cost | I32: Unit Cost | J32: Unit Cost
B33: Price Category | E33: [4] | F33: [5] | G33: [6] | H33: [7] | I33: [8] | J33: [9]
B34: Nonautomation | E34: =E16 -> 2.3696893 | F34: =+E34*$E$26 -> 4.8588162 | G34: =+$E$8 -> 0.29703041 | H34: =F34+G34 -> 5.1558466 | I34: =E$9 -> 0.0010257482 | J34: =+G34+F34+I34 -> 5.1568724
B35: =B17 -> Nonautomation MAADC BC-Benchmark | E35: =E17 -> 2.8389671 | F35: =+E35*$E$26 -> 5.8210247 | G35: =+$E$8 -> 0.29703041 | H35: =F35+G35 -> 6.1180551 | I35: =E$9 -> 0.0010257482 | J35: =+G35+F35+I35 -> 6.1190808
B36: =B18 -> Automation Mixed AADC | E36: =+E18 -> 2.6342773 | F36: =+E36*$E$26 -> 5.4013282 | G36: =+$E$8 -> 0.29703041 | H36: =F36+G36 -> 5.6983586 | I36: =E$9 -> 0.0010257482 | J36: =+G36+F36+I36 -> 5.6993844
B37: =B19 -> Automation AADC | E37: =+E19 -> 2.0286693 | F37: =+E37*$E$26 -> 4.1595882 | G37: =+$E$8 -> 0.29703041 | H37: =F37+G37 -> 4.4566186 | I37: =E$9 -> 0.0010257482 | J37: =+G37+F37+I37 -> 4.4576444
B38: =B20 -> Automation 3-Digit | E38: =+E20 -> 1.7108705 | F38: =+E38*$E$26 -> 3.5079728 | G38: =+$E$8 -> 0.29703041 | H38: =F38+G38 -> 3.8050032 | I38: =E$9 -> 0.0010257482 | J38: =+G38+F38+I38 -> 3.806029
B39: Automation 5-Digit | E39: =((E21*F21)+(E22*F22))/(F21+F22) -> 1.093967 | F39: =+E39*$E$26 -> 2.2430725 | G39: =+$E$8 -> 0.29703041 | H39: =F39+G39 -> 2.5401029 | I39: =E$9 -> 0.0010257482 | J39: =+G39+F39+I39 -> 2.5411286
B40: Automation 5-Digit Manual | E40: =E22 -> 0.56679235 | F40: =+E40*$E$26 -> 1.1621523 | G40: =+$E$8 -> 0.29703041 | H40: =F40+G40 -> 1.4591827 | I40: =E$9 -> 0.0010257482 | J40: =+G40+F40+I40 -> 1.4602085
B43: Sources
B44: [1]: Letter model cost estimates * Card-letter cost ratio
B45: [2]: Tab 'MCS CARDS'
B46: [3]: Volume in each row [2] divided by the total volume [2]
B47: [4]: [1]
B48: [5]: [4] * 5/
B49: [6]: 2/
B50: [7]: [5] + [6]
B51: [8]: 2/
...

Sheet OUT TRAY SORT FC C&L&F
A1: OUTGOING LETTER TRAY/FLAT TUB SORTING UNIT COST AVOIDANCE
D4: [1] | E4: [2] | F4: [3] | G4: [4] | H4: [5] | I4: [6] | J4: [7] | K4: [8] | L4: [9] | M4: [10] | N4: [11]
G5: Marginal
D6: Pieces | E6: Trays | F6: Volume | G6: Trays | I6: Direct | K6: Premium | L6: Premium | M6: Total | N6: Total
D7: Per | E7: Per | F7: Variability | G7: Per | H7: Wage | I7: Cents | J7: Piggyback | K7: Pay | L7: Pay | M7: Cents | N7: Cents
A8: Operation | C8: Product | D8: Tray/Tub | E8: Hour | F8: Factor | G8: Hour | H8: Rate | I8: Per Tray | J8: Factor | K8: Factor | L8: Adjust | M8: Per Tray | N8: Per Piece
A10: Outgoing Letter Tray Sort | C10: First-Class Mail Presort Cards | D10: =SUM('[2]FCM PCS PER TRAY'!$B$18:$B$20)/SUM('[2]FCM PCS PER TRAY'!$C$18:$C$20) -> 509.10861 | E10: =PRODUCTIVITY!$D$6 -> 85.837148 | F10: =PRODUCTIVITY!$G$6 -> 0.9497 | G10: =E10/F10 -> 90.383435 | H10: ='WAGE RATES - PIGGYBACK FACTORS'!$D$5 -> 50.107175 | I10: =H10*100/G10 -> 55.438449 | J10: ='WAGE RATES - PIGGYBACK FACTORS'!$D$16 -> 1.5358045 | K10: ='WAGE RATES - PIGGYBACK FACTORS'!D8 -> 1.0126974 | L10: =I10*(K10-1) -> 0.70392662 | M10: =I10*J10+L10 -> 85.846544 | N10: =M10/D10 -> 0.16862128
A11: Outgoing Letter Tray Sort | C11: First-Class Mail Presort Letters | D11: =SUM('[2]FCM PCS PER TRAY'!$B$10:$B$12)/SUM('[2]FCM PCS PER TRAY'!$C$10:$C$12) -> 247.3455 | E11: =PRODUCTIVITY!$D$6 -> 85.837148 | F11: =PRODUCTIVITY!$G$6 -> 0.9497 | G11: =E11/F11 -> 90.383435 | H11: ='WAGE RATES - PIGGYBACK FACTORS'!$D$5 -> 50.107175 | I11: =H11*100/G11 -> 55.438449 | J11: ='WAGE RATES - PIGGYBACK FACTORS'!$D$16 -> 1.5358045 | K11: ='WAGE RATES - PIGGYBACK FACTORS'!D9 -> 1.0210632 | L11: =I11*(K11-1) -> 1.167711 | M11: =I11*J11+L11 -> 86.310328 | N11: =M11/D11 -> 0.34894642
A12: Outgoing Flat Tub Sort | C12: First-Class Mail Presort Flats | D12: =SUM('[2]FCM PCS PER TRAY'!$C$30:$C$38)/SUM('[2]FCM PCS PER TRAY'!$D$30:$D$38) -> 51.222968 | E12: =PRODUCTIVITY!$D$6 -> 85.837148 | F12: =PRODUCTIVITY!$G$6 -> 0.9497 | G12: =E12/F12 -> 90.383435 | H12: ='WAGE RATES - PIGGYBACK FACTORS'!$D$5 -> 50.107175 | I12: =H12*100/G12 -> 55.438449 | J12: ='WAGE RATES - PIGGYBACK FACTORS'!$D$16 -> 1.5358045 | K12: ='WAGE RATES - PIGGYBACK FACTORS'!D10 -> 1.0289187 | L12: =I12*(K12-1) -> 1.6032098 | M12: =I12*J12+L12 -> 86.745827 | N12: =M12/D12 -> 1.6934948
A15: Sources:
A16: [1] | B16: USPS-FY25-14 Table MCS-16
A17: [2] | B17: USPS-FY25-23
A18: [3] | B18: Tab 'WAGE RATES - PIGGYBACK FACTORS'
A19: [4] | B19: [2] / [3]
A20: [5] | B20: Tab 'WAGE RATES - PIGGYBACK FACTORS'
A21: [6] | B21: [5] * 100 / [4]
A22: [7] | B22: USPS-FY25-25
A23: [8] | B23: Tab 'WAGE RATES - PIGGYBACK FACTORS'
A24: [9] | B24: [6] * ( [8] - 1 )
A25: [10] | B25: [6] * [7] + [9]
A26: [11] | B26: [10] / [1]

Sheet AADC_BENCH_COST
A1: FIRST-CLASS MACHINABLE BENCHMARK MACH AADC LETTERS
A2: COST SHEET
A3: Total Pieces | C3: =+'MACH INCOMING MODEL'!N4 -> 10000
H6: Direct | I6: Premium | K6: Total | L6: Weighted
E7: Pieces | G7: Wage | H7: Cents | I7: Pay | J7: Piggyback | K7: Cents | L7: Cents
C8: TPH | E8: Per Hour | G8: Rate | H8: Per Piece | I8: Adjust | J8: Factor | K8: Per Piece | L8: Per Piece
C9: [1] | E9: [2] | G9: [3] | H9: [4] | I9: [5] | J9: [6] | K9: [7] | L9: [8]
A10: Entry Activities
B11: Bundle Sorting
A12: Outgoing RBCS
B13: ISS | C13: =+AADC_BENCH_MODEL!G18 -> 0 | E13: =+PRODUCTIVITY!I7 -> 6833.2327 | G13: =+'WAGE RATES - PIGGYBACK FACTORS'!$D$5 -> 50.107175 | H13: =+G13/E13*100 -> 0.73328652 | I13: =+H13*('WAGE RATES - PIGGYBACK FACTORS'!$D$6-1) -> 0.015342425 | J13: =+'WAGE RATES - PIGGYBACK FACTORS'!D22 -> 1.6888485 | K13: =+H13*J13+I13 -> 1.2537523 | L13: =+(K13*C13/10000) -> 0
B14: RCR | C14: =+AADC_BENCH_MODEL!G25 -> 0 | E14: -- | F14: -- | G14: -- | H14: -- | I14: -- | J14: -- | K14: =+MISC!$E$7 -> 0.27889541 | L14: =+(K14*C14/10000) -> 0
B15: REC | C15: =+AADC_BENCH_MODEL!G32 -> 0 | E15: =+PRODUCTIVITY!I9 -> 846.86663 | G15: =+'WAGE RATES - PIGGYBACK FACTORS'!$D$4 -> 54.14236 | H15: =+G15/E15*100 -> 6.393257 | I15: =+H15*('WAGE RATES - PIGGYBACK FACTORS'!$D$6-1) -> 0.13376499 | J15: =+'WAGE RATES - PIGGYBACK FACTORS'!D23 -> 1.2615773 | K15: =+H15*J15+I15 -> 8.199353 | L15: =+(K15*C15/10000) -> 0
B16: OSS | C16: =+AADC_BENCH_MODEL!G39 -> 0 | E16: =+PRODUCTIVITY!I11 -> 6833.2327 | G16: =+'WAGE RATES - PIGGYBACK FACTORS'!$D$5 -> 50.107175 | H16: =+G16/E16*100 -> 0.73328652 | I16: =+H16*('WAGE RATES - PIGGYBACK FACTORS'!$D$6-1) -> 0.015342425 | J16: =+'WAGE RATES - PIGGYBACK FACTORS'!D24 -> 1.6888485 | K16: =+H16*J16+I16 -> 1.2537523 | L16: =+(K16*C16/10000) -> 0
B17: LCREM | C17: =+AADC_BENCH_MODEL!C32 -> 0 | E17: =+PRODUCTIVITY!I10 -> 1983.2154 | G17: =+'WAGE RATES - PIGGYBACK FACTORS'!$D$5 -> 50.107175 | H17: =+G17/E17*100 -> 2.5265624 | I17: =+H17*('WAGE RATES - PIGGYBACK FACTORS'!$D$6-1) -> 0.05286282 | J17: =+'WAGE RATES - PIGGYBACK FACTORS'!D25 -> 3.4396835 | K17: =+H17*J17+I17 -> 8.7434377 | L17: =+(K17*C17/10000) -> 0
A18: Outgoing Primary
B19: Automation | C19: =+AADC_BENCH_MODEL!S16 -> 0 | E19: =+PRODUCTIVITY!I13 -> 6833.2327 | G19: =+'WAGE RATES - PIGGYBACK FACTORS'!$D$5 -> 50.107175 | H19: =+G19/E19*100 -> 0.73328652 | I19: =+H19*('WAGE RATES - PIGGYBACK FACTORS'!$D$6-1) -> 0.015342425 | J19: =+'WAGE RATES - PIGGYBACK FACTORS'!D26 -> 1.6888485 | K19: =+H19*J19+I19 -> 1.2537523 | L19: =+(K19*C19/10000) -> 0
B20: Manual | C20: =+AADC_BENCH_MODEL!AA16 -> 0 | E20: =+PRODUCTIVITY!I20 -> 631.32213 | G20: =+'WAGE RATES - PIGGYBACK FACTORS'!$D$5 -> 50.107175 | H20: =+G20/E20*100 -> 7.9368633 | I20: =+H20*('WAGE RATES - PIGGYBACK FACTORS'!$D$6-1) -> 0.16606159 | J20: =+'WAGE RATES - PIGGYBACK FACTORS'!D27 -> 1.2988119 | K20: =+H20*J20+I20 -> 10.474554 | L20: =+(K20*C20/10000) -> 0
A21: Outgoing Secondary
B22: Automation | C22: =+AADC_BENCH_MODEL!S24 -> 0 | E22: =+PRODUCTIVITY!I14 -> 5441.4416 | G22: =+'WAGE RATES - PIGGYBACK FACTORS'!$D$5 -> 50.107175 | H22: =+G22/E22*100 -> 0.92084374 | I22: =+H22*('WAGE RATES - PIGGYBACK FACTORS'!$D$6-1) -> 0.019266652 | J22: =+'WAGE RATES - PIGGYBACK FACTORS'!D28 -> 1.6888485 | K22: =+H22*J22+I22 -> 1.5744322 | L22: =+(K22*C22/10000) -> 0
B23: Manual | C23: =+AADC_BENCH_MODEL!AA24 -> 0 | E23: =+PRODUCTIVITY!I21 -> 1087.9987 | G23: =+'WAGE RATES - PIGGYBACK FACTORS'!$D$5 -> 50.107175 | H23: =+G23/E23*100 -> 4.6054442 | I23: =+H23*('WAGE RATES - PIGGYBACK FACTORS'!$D$6-1) -> 0.096358899 | J23: =+'WAGE RATES - PIGGYBACK FACTORS'!D29 -> 1.2988119 | K23: =+H23*J23+I23 -> 6.0779647 | L23: =+(K23*C23/10000) -> 0
A24: Incoming RBCS
B25: ISS | C25: =+AADC_BENCH_MODEL!G51 -> 10045.165 | E25: =+PRODUCTIVITY!I8 -> 5815.8678 | G25: =+'WAGE RATES - PIGGYBACK FACTORS'!$D$5 -> 50.107175 | H25: =+G25/E25*100 -> 0.86155972 | I25: =+H25*('WAGE RATES - PIGGYBACK FACTORS'!$D$6-1) -> 0.018026263 | J25: =+'WAGE RATES - PIGGYBACK FACTORS'!D30 -> 1.6888485 | K25: =+H25*J25+I25 -> 1.4730701 | L25: =+(K25*C25/10000) -> 1.4797232
B26: RCR | C26: =+AADC_BENCH_MODEL!G58 -> 663.7513 | E26: -- | G26: -- | H26: -- | I26: -- | J26: -- | K26: =+MISC!$E$7 -> 0.27889541 | L26: =+(K26*C26/10000) -> 0.018511719
B27: REC | C27: =+AADC_BENCH_MODEL!G65 -> 13.407776 | E27: =+PRODUCTIVITY!I9 -> 846.86663 | G27: =+'WAGE RATES - PIGGYBACK FACTORS'!$D$4 -> 54.14236 | H27: =+G27/E27*100 -> 6.393257 | I27: =+H27*('WAGE RATES - PIGGYBACK FACTORS'!$D$6-1) -> 0.13376499 | J27: =+'WAGE RATES - PIGGYBACK FACTORS'!D31 -> 1.2615773 | K27: =+H27*J27+I27 -> 8.199353 | L27: =+(K27*C27/10000) -> 0.010993509
B28: OSS | C28: =+AADC_BENCH_MODEL!G72 -> 671.98311 | E28: =+PRODUCTIVITY!I12 -> 5815.8678 | G28: =+'WAGE RATES - PIGGYBACK FACTORS'!$D$5 -> 50.107175 | H28: =+G28/E28*100 -> 0.86155972 | I28: =+H28*('WAGE RATES - PIGGYBACK FACTORS'!$D$6-1) -> 0.018026263 | J28: =+'WAGE RATES - PIGGYBACK FACTORS'!D32 -> 1.6888485 | K28: =+H28*J28+I28 -> 1.4730701 | L28: =+(K28*C28/10000) -> 0.098987823
B29: LCREM | C29: =+AADC_BENCH_MODEL!C65 -> 1.3776555 | E29: =+PRODUCTIVITY!I10 -> 1983.2154 | G29: =+'WAGE RATES - PIGGYBACK FACTORS'!$D$5 -> 50.107175 | H29: =+G29/E29*100 -> 2.5265624 | I29: =+H29*('WAGE RATES - PIGGYBACK FACTORS'!$D$6-1) -> 0.05286282 | J29: =+'WAGE RATES - PIGGYBACK FACTORS'!D33 -> 3.4396835 | K29: =+H29*J29+I29 -> 8.7434377 | L29: =+(K29*C29/10000) -> 0.0012045445
A30: Incoming MMP
B31: Automation AADC | C31: =+AADC_BENCH_MODEL!S32 -> 0 | E31: =+PRODUCTIVITY!I15 -> 5271.1402 | G31: =+'WAGE RATES - PIGGYBACK FACTORS'!$D$5 -> 50.107175 | H31: =+G31/E31*100 -> 0.95059461 | I31: =+H31*('WAGE RATES - PIGGYBACK FACTORS'!$D$6-1) -> 0.019889124 | J31: =+'WAGE RATES - PIGGYBACK FACTORS'!D34 -> 1.6888485 | K31: =+H31*J31+I31 -> 1.6252994 | L31: =+(K31*C31/10000) -> 0
B32: Manual ADC | C32: =+AADC_BENCH_MODEL!AA32 -> 336.09032 | E32: =+PRODUCTIVITY!I22 -> 1213.9421 | G32: =+'WAGE RATES - PIGGYBACK FACTORS'!$D$5 -> 50.107175 | H32: =+G32/E32*100 -> 4.1276414 | I32: =+H32*('WAGE RATES - PIGGYBACK FACTORS'!$D$6-1) -> 0.086361915 | J32: =+'WAGE RATES - PIGGYBACK FACTORS'!D35 -> 1.2988119 | K32: =+H32*J32+I32 -> 5.4473918 | L32: =+(K32*C32/10000) -> 0.18308156
A33: Incoming SCF/Primary
B34: Automation | C34: =+AADC_BENCH_MODEL!S40 -> 835.74917 | E34: =+PRODUCTIVITY!I16 -> 10175.777 | G34: =+'WAGE RATES - PIGGYBACK FACTORS'!$D$5 -> 50.107175 | H34: =+G34/E34*100 -> 0.49241622 | I34: =+H34*('WAGE RATES - PIGGYBACK FACTORS'!$D$6-1) -> 0.010302738 | J34: =+'WAGE RATES - PIGGYBACK FACTORS'!D36 -> 1.6888485 | K34: =+H34*J34+I34 -> 0.84191913 | L34: =+(K34*C34/10000) -> 0.070363321
B35: Manual | C35: =+AADC_BENCH_MODEL!AA40 -> 198.68897 | E35: =+PRODUCTIVITY!I23 -> 1107.0494 | G35: =+'WAGE RATES - PIGGYBACK FACTORS'!$D$5 -> 50.107175 | H35: =+G35/E35*100 -> 4.5261912 | I35: =+H35*('WAGE RATES - PIGGYBACK FACTORS'!$D$6-1) -> 0.094700704 | J35: =+'WAGE RATES - PIGGYBACK FACTORS'!D37 -> 1.2988119 | K35: =+H35*J35+I35 -> 5.9733718 | L35: =+(K35*C35/10000) -> 0.11868431
A36: Incoming Secondaries
B37: Auto Carrier Route | C37: =+AADC_BENCH_MODEL!W49 -> 338.0313 | E37: =+PRODUCTIVITY!I17 -> 13094.299 | G37: =+'WAGE RATES - PIGGYBACK FACTORS'!$D$5 -> 50.107175 | H37: =+G37/E37*100 -> 0.38266404 | I37: =+H37*('WAGE RATES - PIGGYBACK FACTORS'!$D$6-1) -> 0.0080064124 | J37: =+'WAGE RATES - PIGGYBACK FACTORS'!D38 -> 1.6888485 | K37: =+H37*J37+I37 -> 0.654268 | L37: =+(K37*C37/10000) -> 0.022116306
B38: Auto 3-Pass DPS | C38: =+AADC_BENCH_MODEL!W56 -> 0 | E38: =+PRODUCTIVITY!I19 -> 0 | G38: =+'WAGE RATES - PIGGYBACK FACTORS'!$D$5 -> 50.107175 | H38: 0 | I38: =+H38*('WAGE RATES - PIGGYBACK FACTORS'!$D$6-1) -> 0 | J38: =+'WAGE RATES - PIGGYBACK FACTORS'!D39 -> 0 | K38: =+H38*J38+I38 -> 0 | L38: =+(K38*C38/10000) -> 0
B39: Auto 2-Pass DPS | C39: =+AADC_BENCH_MODEL!W63 -> 18414.502 | E39: =+PRODUCTIVITY!I18 -> 6910.0702 | G39: =+'WAGE RATES - PIGGYBACK FACTORS'!$D$5 -> 50.107175 | H39: =+G39/E39*100 -> 0.72513264 | I39: =+H39*('WAGE RATES - PIGGYBACK FACTORS'!$D$6-1) -> 0.015171823 | J39: =+'WAGE RATES - PIGGYBACK FACTORS'!D40 -> 1.6888485 | K39: =+H39*J39+I39 -> 1.239811 | L39: =+(K39*C39/10000) -> 2.2830502
B40: Man Inc Sec Final At DU | C40: =+AADC_BENCH_MODEL!AA74*(1-MISC!E9) -> 630.96064 | E40: =+PRODUCTIVITY!I24 -> 810.31043 | G40: =+'WAGE RATES - PIGGYBACK FACTORS'!$D$5 -> 50.107175 | H40: =+G40/E40*100 -> 6.183701 | I40: =+H40*('WAGE RATES - PIGGYBACK FACTORS'!$D$6-1) -> 0.12938049 | J40: =+'WAGE RATES - PIGGYBACK FACTORS'!D42 -> 1.2988119 | K40: =+H40*J40+I40 -> 8.1608451 | L40: =+(K40*C40/10000) -> 0.5149172
B41: Box Section Sort, DPS | C41: =+MISC!E10*(AADC_BENCH_MODEL!AE64+AADC_BENCH_MODEL!AE57) -> 414.82449 | E41: =+PRODUCTIVITY!I25 -> 1955.1935 | G41: =+'WAGE RATES - PIGGYBACK FACTORS'!$D$5 -> 50.107175 | H41: =+G41/E41*100 -> 2.5627732 | I41: =+H41*('WAGE RATES - PIGGYBACK FACTORS'!$D$6-1) -> 0.053620453 | J41: =+'WAGE RATES - PIGGYBACK FACTORS'!D43 -> 1.2988119 | K41: =+H41*J41+I41 -> 3.3821808 | L41: =+(K41*C41/10000) -> 0.14030115
B42: Box Section Sort, Other | C42: =+MISC!E10*(AADC_BENCH_MODEL!AE75+AADC_BENCH_MODEL!AE50) -> 43.520512 | E42: =+PRODUCTIVITY!I26 -> 977.59674 | G42: =+'WAGE RATES - PIGGYBACK FACTORS'!$D$5 -> 50.107175 | H42: =+G42/E42*100 -> 5.1255464 | I42: =+H42*('WAGE RATES - PIGGYBACK FACTORS'!$D$6-1) -> 0.10724091 | J42: =+'WAGE RATES - PIGGYBACK FACTORS'!D44 -> 1.2988119 | K42: =+H42*J42+I42 -> 6.7643617 | L42: =+(K42*C42/10000) -> 0.029438848
...

Sheet AADC_BENCH_MODEL
B1: FIRST-CLASS MACHINABLE INCOMING BENCHMARK AADC LETTERS
B2: MAIL FLOW MODEL
B4: PCS IN = | E4: 10000 | K4: PCS OUT = | N4: =AE50+AE57+AE64+AE75 -> 10000
B6: ENTRY POINTS:
B7: Out ISS | E7: 0 | H7: Inc ISS | K7: =E4 -> 10000 | N7: Inc ADC Man | Q7: 0
B8: Out RCR | E8: 0 | H8: Inc MMP Auto | K8: 0 | N8: Inc SCF/Prim Man | Q8: 0
B9: Out Prim Auto | E9: 0 | H9: Inc SCF/Prim Auto | K9: 0 | N9: Inc Sec Man | Q9: 0
B10: Out Sec Auto | E10: 0 | H10: Inc Sec Auto | K10: 0
B11: Out Prim Man | E11: 0
B12: Out Sec Man | E12: 0
B14: OUTGOING RBCS | S14: Out Prim Auto | V14: =+T16*(1-ACCEPT!C15) -> 0 | W14: Rejects to Out Prim Man | AA14: Out Prim Man
I15: =+H18*ACCEPT!$C$6 -> 0 | K15: =+I15+I16 -> 0 | N15: =+(K15)*DENSITY!C7 -> 0 | O15: Out Prim Auto | AD15: =+AB16*DENSITY!D14 -> 0 | AE15: Out Sec Man
G16: Out ISS | I16: =+(C20+E27)*(ACCEPT!$C$6) -> 0 | N16: =+(K15)*DENSITY!D7 -> 0 | O16: Out Sec Auto | S16: =+T16*(1+DENSITY!B9) -> 0 | T16: =+E9+N15+N41 -> 0 | W16: =+V17*DENSITY!D9 -> 0 | X16: Out Sec Auto | AA16: =+AB16 -> 0 | AB16: =+E11+N31+N39+V14 -> 0 | AD16: =+AB16*DENSITY!E14 -> 0 | AE16: Inc ADC Man
N17: =+(K15)*DENSITY!E7 -> 0 | O17: Inc MMP Auto | V17: =+T16*ACCEPT!C15 -> 0 | W17: =+V17*DENSITY!E9 -> 0 | X17: Inc MMP Auto | AD17: =+AB16*DENSITY!F14 -> 0 | AE17: Inc Prim Man
G18: =+H18*(1+DENSITY!B7)+C20+E27 -> 0 | H18: =+E7 -> 0 | N18: =+(K15)*DENSITY!F7 -> 0 | O18: Inc SCF/Prim Auto | W18: =+V17*DENSITY!F9 -> 0 | X18: Inc SCF/Prim Auto | AD18: =+AB16*DENSITY!G14 -> 0 | AE18: Inc Sec Man
N19: =+(K15)*DENSITY!G7 -> 0 | O19: Inc Sec Auto | W19: =+V17*DENSITY!G9 -> 0 | X19: Inc Sec Auto
C20: =+C32 -> 0
G21: =+(C20+E27)*(1-ACCEPT!C6) -> 0 | H21: =+H18*(1-ACCEPT!C6) -> 0
S22: Out Sec Auto | V22: =+T24*(1-ACCEPT!C16) -> 0 | W22: Rejects to Out Sec Man | AA22: Out Sec Man
G23: Out RCR
S24: =+T24*(1+DENSITY!B10) -> 0 | T24: =+E10+N16+N42+W16 -> 0 | W24: =+V25*DENSITY!E10 -> 0 | X24: Inc MMP Auto | AA24: =+AB24 -> 0 | AB24: =+E12+V22+AD15 -> 0 | AD24: =+AB24*DENSITY!E15 -> 0 | AE24: Inc ADC Man
G25: =+H25+G21 -> 0 | H25: =+H21+E8 -> 0 | I25: (finalized on RCR, to out OSS) | V25: =+T24*ACCEPT!C16 -> 0 | W25: =+V25*DENSITY!F10 -> 0 | X25: Inc SCF/Prim Auto | AD25: =+AB24*DENSITY!F15 -> 0 | AE25: Inc Prim Man
W26: =+V25*DENSITY!G10 -> 0 | X26: Inc Sec Auto | AD26: =+AB24*DENSITY!G15 -> 0 | AE26: Inc Sec Man
E27: =+H39*ACCEPT!C10 -> 0 | G27: (image) | I27: (mail | J27: piece)
G28: =+I28 -> 0 | H28: =+J28 -> 0 | I28: =+G21-K29 -> 0 | J28: =+H25-L29 -> 0
K29: =+G21*MISC!E6 -> 0 | L29: =+H25*(MISC!E6) -> 0
C30: Out LCREM | G30: Out REC | S30: Inc MMP Auto | V30: =+T32*(1-ACCEPT!C17) -> 0 | W30: Rejects to Inc ADC Man | AA30: Inc ADC Man
M31: =+J28*MISC!E5 -> 0 | N31: =+M31+M32 -> 0 | O31: Leakage to Out Prim Man
C32: =+D36+C36 -> 0 | D32: =+D36 -> 0 | G32: =+I28+H32 -> 0 | H32: =+J28 -> 0 | M32: =+I28*MISC!E5 -> 0 | S32: =+T32*(1+DENSITY!B13) -> 0 | T32: =+K8+N17+N43+N48+N75+W17+W24 -> 0 | AA32: =+AB32 -> 336.09032 | AB32: =+Q7+N64+N72+V30+AD16+AD24 -> 336.09032
V33: =+T32*ACCEPT!C17 -> 0 | W33: =+V33*DENSITY!$F$13 -> 0 | X33: Inc SCF/Prim Auto | AD33: =+AB32*DENSITY!F16 -> 147.18901 | AE33: Inc Prim Man
G34: (image) | I34: (mail | J34: piece) | W34: =+V33*DENSITY!$G$13 -> 0 | X34: Inc Sec Auto | AD34: =+AB32*DENSITY!G16 -> 188.90132 | AE34: Inc Sec Man
G35: =+I35 -> 0 | H35: =+J35 -> 0 | I35: =+I28-M32 -> 0 | J35: =+J28-M31 -> 0
D36: =+H39*ACCEPT!C12 -> 0
G37: Out OSS
D38: ID Tag Error | S38: Inc SCF/Prim Auto | V38: =+T40*(1-ACCEPT!C18) -> 51.499959 | W38: Rejects to Inc Prim Man | AA38: Inc Prim Man
G39: =+H39+E40+I35+K29 -> 0 | H39: =+J35+L29 -> 0 | L39: =+H39*ACCEPT!C13 -> 0 | N39: =+L39+L40 -> 0 | O39: Rejects to Out Prim Man
E40: =+H39*ACCEPT!C11 -> 0 | L40: =+(G39-H39)*(1-ACCEPT!C9) -> 0 | S40: =+T40 -> 835.74917 | T40: =+K9+N18+N44+N49+N76+W18+W25+W33 -> 835.74917 | AA40: =+AB40 -> 198.68897 | AB40: =+Q8+V38+AD33+AD25+AD17 -> 198.68897
F41: OSS Refeeds | N41: =+J42*DENSITY!C8 -> 0 | O41: Out Prim Auto | V41: =+T40*(ACCEPT!C18) -> 784.24921 | W41: Inc Sec Auto | AD41: =+AB40 -> 198.68897 | AE41: Inc Sec Man
H42: =+H39*ACCEPT!C9 -> 0 | J42: =+H42+H43 -> 0 | N42: =+J42*DENSITY!D8 -> 0 | O42: Out Sec Auto
H43: =+(G39-H39)*ACCEPT!C9 -> 0 | N43: =+J42*DENSITY!E8 -> 0 | O43: Inc MMP Auto
...

Sheet CRA-METERED LETTERS
A1: FIRST CLASS BULK METERED LETTERS
A2: CRA MAIL PROCESSING COSTS
A3: Source: USPS-FY25-26
A4: Source - Worksheet: LTTR Unit Costs Final Adj.
E5: Worksharing-Related
A6: Cost Pools | C6: Total (Cents) | E6: Proportional (Cents) | G6: Fixed (Cents) | H6: Non-WS Related (Cents) | L6: Key | M6: Treatment
A7: MODS 11 | B7: D/BCS | C7: ='[3]LTTR Unit Costs Final Adj.'!$O$6 -> 6.797475 | E7: =+C7 -> 6.797475 | L7: Piece Sorting | M7: Proportional
A8: MODS 12 | B8: AFSM100 | C8: ='[3]LTTR Unit Costs Final Adj.'!$O$7 -> 0.30217283 | E8: =+C8 -> 0.30217283 | L8: Fwd/Accept/Cust.Srv. | M8: WS Fixed
L9: Non-WS | M9: Non WS
A10: MODS 12 | B10: FSS | C10: 0 | E10: =+C10 -> 0 | L10: Unexpected | M10: =IF(N10=1,"Piggybacked","Non WS") -> Piggybacked | N10: 1
A12: MODS 13 | B12: APBS BUNDLE | C12: ='[3]LTTR Unit Costs Final Adj.'!O9 -> 0.028966308 | E12: =IF($N$10=1,$C12*E$80,0) -> 0.02367415 | G12: =IF($N$10=1,$C12*G$80,0) -> 0.0051137634 | H12: =IF($N$10=1,$C12*H$80,C12) -> 0.00017839498 | L12: Allied/Support | M12: Piggybacked
A13: MODS 13 | B13: APBSPRIO | C13: ='[3]LTTR Unit Costs Final Adj.'!O10 -> 0.17373524 | E13: =IF($N$10=1,$C13*E$80,0) -> 0.14199373 | G13: =IF($N$10=1,$C13*G$80,0) -> 0.030671526 | H13: =IF($N$10=1,$C13*H$80,C13) -> 0.0010699843
A14: MODS 16 | B14: LCUS-SSM | C14: ='[3]LTTR Unit Costs Final Adj.'!O11 -> 0.00090960557 | E14: =IF($N$10=1,$C14*E$80,0) -> 0.0007434202 | G14: =IF($N$10=1,$C14*G$80,0) -> 0.00016058338 | H14: =IF($N$10=1,$C14*H$80,C14) -> 5.6019934e-06 | L14: Note: OPBULK, OPPREF and Pouching
A15: MODS 16 | B15: 1TRAYSRT | C15: ='[3]LTTR Unit Costs Final Adj.'!O12 -> 1.0911943 | E15: =IF($N$10=1,$C15*E$80,0) -> 0.89183258 | G15: =IF($N$10=1,$C15*G$80,0) -> 0.19264137 | H15: =IF($N$10=1,$C15*H$80,C15) -> 0.0067203451 | L15: were WS related fixed in 3 column system,
A16: MODS 14 | B16: MANF | C16: ='[3]LTTR Unit Costs Final Adj.'!O13 -> 0.068643616 | E16: =+C16 -> 0.068643616 | L16: are grouped with prep and accept
A17: MODS 14 | B17: MANL | C17: ='[3]LTTR Unit Costs Final Adj.'!O14 -> 1.8518907 | E17: =+C17 -> 1.8518907
A18: MODS 14 | B18: MANP | C18: ='[3]LTTR Unit Costs Final Adj.'!O15 -> 1.4802187e-05 | E18: =IF($N$10=1,$C18*E$80,0) -> 1.209782e-05 | G18: =IF($N$10=1,$C18*G$80,0) -> 2.6132043e-06 | H18: =IF($N$10=1,$C18*H$80,C18) -> 9.116232e-08
A19: MODS 14 | B19: PRIORITY | C19: ='[3]LTTR Unit Costs Final Adj.'!O16 -> 0.10663651 | E19: =IF($N$10=1,$C19*E$80,0) -> 0.087153972 | G19: =IF($N$10=1,$C19*G$80,0) -> 0.018825799 | H19: =IF($N$10=1,$C19*H$80,C19) -> 0.00065674295
A20: MODS 15 | B20: LD15 | C20: ='[3]LTTR Unit Costs Final Adj.'!O17 -> 0.13083004 | E20: =+C20 -> 0.13083004
A21: MODS 17 | B21: 1CANCEL | C21: ='[3]LTTR Unit Costs Final Adj.'!O18 -> 1.5326429 | G21: =C21 -> 1.5326429
A22: MODS 17 | B22: 1DSPATCH | C22: ='[3]LTTR Unit Costs Final Adj.'!O19 -> 0.17356089 | E22: =IF($N$10=1,$C22*E$80,0) -> 0.14185124 | G22: =IF($N$10=1,$C22*G$80,0) -> 0.030640748 | H22: =IF($N$10=1,$C22*H$80,C22) -> 0.0010689106
A24: MODS 17 | B24: 1MTRPREP | C24: ='[3]LTTR Unit Costs Final Adj.'!O20 -> 0.029613213 | G24: =C24 -> 0.029613213
A25: MODS 17 | B25: 1OPBULK | C25: ='[3]LTTR Unit Costs Final Adj.'!O21 -> 0.041993344 | E25: =IF($N$10=1,$C25*E$80,0) -> 0.03432114 | G25: =IF($N$10=1,$C25*G$80,0) -> 0.0074135793 | H25: =IF($N$10=1,$C25*H$80,C25) -> 0.00025862466
A26: MODS 17 | B26: 1OPPREF | C26: ='[3]LTTR Unit Costs Final Adj.'!O22 -> 0.28832889 | E26: =IF($N$10=1,$C26*E$80,0) -> 0.23565106 | G26: =IF($N$10=1,$C26*G$80,0) -> 0.050902093 | H26: =IF($N$10=1,$C26*H$80,C26) -> 0.0017757329
A27: MODS 17 | B27: 1OPTRANS | C27: ='[3]LTTR Unit Costs Final Adj.'!O23 -> 0.071737895 | E27: =IF($N$10=1,$C27*E$80,0) -> 0.058631347 | G27: =IF($N$10=1,$C27*G$80,0) -> 0.012664735 | H27: =IF($N$10=1,$C27*H$80,C27) -> 0.00044181262
A28: MODS 17 | B28: 1PLATFRM | C28: ='[3]LTTR Unit Costs Final Adj.'!O24 -> 2.4241711 | E28: =IF($N$10=1,$C28*E$80,0) -> 1.9812739 | G28: =IF($N$10=1,$C28*G$80,0) -> 0.42796746 | H28: =IF($N$10=1,$C28*H$80,C28) -> 0.014929757
A29: MODS 17 | B29: 1POUCHNG | C29: ='[3]LTTR Unit Costs Final Adj.'!O25 -> 0.012391828 | E29: =IF($N$10=1,$C29*E$80,0) -> 0.010127835 | G29: =IF($N$10=1,$C29*G$80,0) -> 0.0021876753 | H29: =IF($N$10=1,$C29*H$80,C29) -> 7.6317627e-05
A30: MODS 17 | B30: 1PRESORT | C30: ='[3]LTTR Unit Costs Final Adj.'!O26 -> 0.0075394889 | E30: =IF($N$10=1,$C30*E$80,0) -> 0.0061620207 | G30: =IF($N$10=1,$C30*G$80,0) -> 0.0013310347 | H30: =IF($N$10=1,$C30*H$80,C30) -> 4.6433497e-05
A31: MODS 17 | B31: 1SACKS_H | C31: ='[3]LTTR Unit Costs Final Adj.'!O27 -> 0.016650881 | E31: =IF($N$10=1,$C31*E$80,0) -> 0.013608757 | G31: =IF($N$10=1,$C31*G$80,0) -> 0.002939576 | H31: =IF($N$10=1,$C31*H$80,C31) -> 0.00010254788
A32: MODS 17 | B32: 1SCAN | C32: ='[3]LTTR Unit Costs Final Adj.'!O28 -> 0.05583777 | E32: =IF($N$10=1,$C32*E$80,0) -> 0.045636183 | G32: =IF($N$10=1,$C32*G$80,0) -> 0.0098576989 | H32: =IF($N$10=1,$C32*H$80,C32) -> 0.00034388842
A33: MODS 18 | B33: BUSREPLY | C33: ='[3]LTTR Unit Costs Final Adj.'!O29 -> 0.0072868962 | H33: =+C33 -> 0.0072868962
A34: MODS 18 | B34: EXPRESS | C34: ='[3]LTTR Unit Costs Final Adj.'!O30 -> 0.0099795638 | G34: =C34 -> 0.0099795638
A35: MODS 18 | B35: REGISTRY | C35: ='[3]LTTR Unit Costs Final Adj.'!O31 -> 0.037512332 | H35: =+C35 -> 0.037512332
A36: MODS 18 | B36: REWRAP | C36: ='[3]LTTR Unit Costs Final Adj.'!O32 -> 0.015667247 | G36: =C36 -> 0.015667247
A37: MODS 18 | B37: 1EEQMT | C37: ='[3]LTTR Unit Costs Final Adj.'!O33 -> 0.17963507 | E37: =IF($N$10=1,$C37*E$80,0) -> 0.14681566 | G37: =IF($N$10=1,$C37*G$80,0) -> 0.031713094 | H37: =IF($N$10=1,$C37*H$80,C37) -> 0.0011063196
A38: MODS 18 | B38: 1MISC | C38: ='[3]LTTR Unit Costs Final Adj.'!O34 -> 0.10912529 | G38: =C38 -> 0.10912529
A39: MODS 18 | B39: 1SUPPORT | C39: ='[3]LTTR Unit Costs Final Adj.'!O35 -> 0.066518678 | E39: =IF($N$10=1,$C39*E$80,0) -> 0.054365683 | G39: =IF($N$10=1,$C39*G$80,0) -> 0.011743325 | H39: =IF($N$10=1,$C39*H$80,C39) -> 0.00040966899
A40: MODS 19 | B40: INTL ISC | C40: ='[3]LTTR Unit Costs Final Adj.'!O36 -> 0.026627928 | E40: =IF($N$10=1,$C40*E$80,0) -> 0.021762993 | G40: =IF($N$10=1,$C40*G$80,0) -> 0.0047009416 | H40: =IF($N$10=1,$C40*H$80,C40) -> 0.00016399358
A51: MODS Subtotal | C51: =SUM(C7:C50) -> 15.65929 | E51: =SUM(E7:E50) -> 13.04663 | G51: =SUM(G7:G50) -> 2.5385058 | H51: =SUM(H7:H50) -> 0.074154397
A52: NDCS | B52: FSS | C52: 0 | E52: =+C52 -> 0
...

Sheet CRA - PRESORT LETTERS
A1: FIRST-CLASS MAIL PRESORT LETTERS
A2: CRA MAIL PROCESSING COSTS
A3: Source: USPS-FY25-26
A4: Source: Worksheet LTTR Unit Costs Final Adj.
E5: Worksharing-Related
A6: Cost Pools | C6: Total (Cents) | E6: Proportional (Cents) | G6: Fixed (Cents) | H6: Non-WS Related (Cents) | L6: Key | M6: Treatment
A7: MODS 11 | B7: D/BCS | C7: ='[3]LTTR Unit Costs Final Adj.'!$F$6 -> 3.5241512 | E7: =+C7 -> 3.5241512 | L7: Piece Sorting | M7: Proportional
A8: MODS 12 | B8: AFSM100 | C8: ='[3]LTTR Unit Costs Final Adj.'!$F$7 -> 0.049149652 | E8: =+C8 -> 0.049149652 | L8: Fwd/Accept/Cust.Srv. | M8: WS Fixed
L9: Non-WS | M9: Non WS
A10: MODS 12 | B10: FSS | C10: 0 | E10: =+C10 -> 0 | L10: Unexpected | M10: =IF(N10=1,"Piggybacked","Non WS") -> Piggybacked | N10: ='CRA-METERED LETTERS'!N10 -> 1
A12: MODS 13 | B12: APBS BUNDLE | C12: ='[3]LTTR Unit Costs Final Adj.'!F9 -> 0.0073973996 | E12: =IF($N$10=1,$C12*E$80,0) -> 0.0066495448 | G12: =IF($N$10=1,$C12*G$80,0) -> 0.00071552009 | H12: =IF($N$10=1,$C12*H$80,C12) -> 3.2334774e-05 | L12: Allied/Support | M12: Piggybacked
A13: MODS 13 | B13: APBSPRIO | C13: ='[3]LTTR Unit Costs Final Adj.'!F10 -> 0.045725942 | E13: =IF($N$10=1,$C13*E$80,0) -> 0.041103187 | G13: =IF($N$10=1,$C13*G$80,0) -> 0.0044228826 | H13: =IF($N$10=1,$C13*H$80,C13) -> 0.00019987267
A14: MODS 16 | B14: LCUS-SSM | C14: ='[3]LTTR Unit Costs Final Adj.'!F11 -> 0.011005714 | E14: =IF($N$10=1,$C14*E$80,0) -> 0.0098930696 | G14: =IF($N$10=1,$C14*G$80,0) -> 0.0010645375 | H14: =IF($N$10=1,$C14*H$80,C14) -> 4.8107078e-05 | L14: Note: OPBULK, OPPREF and Pouching
A15: MODS 16 | B15: 1TRAYSRT | C15: ='[3]LTTR Unit Costs Final Adj.'!F12 -> 0.55726082 | E15: =IF($N$10=1,$C15*E$80,0) -> 0.50092343 | G15: =IF($N$10=1,$C15*G$80,0) -> 0.053901551 | H15: =IF($N$10=1,$C15*H$80,C15) -> 0.0024358428 | L15: were WS related fixed in 3 column system,
A16: MODS 14 | B16: MANF | C16: ='[3]LTTR Unit Costs Final Adj.'!F13 -> 0.012106278 | E16: =+C16 -> 0.012106278 | L16: are grouped with prep and accept
A17: MODS 14 | B17: MANL | C17: ='[3]LTTR Unit Costs Final Adj.'!F14 -> 0.25835925 | E17: =+C17 -> 0.25835925
A18: MODS 14 | B18: MANP | C18: ='[3]LTTR Unit Costs Final Adj.'!F15 -> 4.9084535e-06 | E18: =IF($N$10=1,$C18*E$80,0) -> 4.4122236e-06 | G18: =IF($N$10=1,$C18*G$80,0) -> 4.7477455e-07 | H18: =IF($N$10=1,$C18*H$80,C18) -> 2.1455341e-08
A19: MODS 14 | B19: PRIORITY | C19: ='[3]LTTR Unit Costs Final Adj.'!F16 -> 0.017230257 | E19: =IF($N$10=1,$C19*E$80,0) -> 0.01548833 | G19: =IF($N$10=1,$C19*G$80,0) -> 0.001666612 | H19: =IF($N$10=1,$C19*H$80,C19) -> 7.5315178e-05
A20: MODS 15 | B20: LD15 | C20: ='[3]LTTR Unit Costs Final Adj.'!F17 -> 0.074743834 | E20: =+C20 -> 0.074743834
A21: MODS 17 | B21: 1CANCEL | C21: ='[3]LTTR Unit Costs Final Adj.'!F18 -> 0.15578953 | G21: =C21 -> 0.15578953
A22: MODS 17 | B22: 1DSPATCH | C22: ='[3]LTTR Unit Costs Final Adj.'!F19 -> 0.05766212 | E22: =IF($N$10=1,$C22*E$80,0) -> 0.051832653 | G22: =IF($N$10=1,$C22*G$80,0) -> 0.00557742 | H22: =IF($N$10=1,$C22*H$80,C22) -> 0.00025204689
A24: MODS 17 | B24: 1MTRPREP | C24: ='[3]LTTR Unit Costs Final Adj.'!F20 -> 0.0043873898 | G24: =C24 -> 0.0043873898
A25: MODS 17 | B25: 1OPBULK | C25: ='[3]LTTR Unit Costs Final Adj.'!F21 -> 0.031929443 | E25: =IF($N$10=1,$C25*E$80,0) -> 0.028701472 | G25: =IF($N$10=1,$C25*G$80,0) -> 0.0030884039 | H25: =IF($N$10=1,$C25*H$80,C25) -> 0.00013956679
A26: MODS 17 | B26: 1OPPREF | C26: ='[3]LTTR Unit Costs Final Adj.'!F22 -> 0.13747892 | E26: =IF($N$10=1,$C26*E$80,0) -> 0.12358022 | G26: =IF($N$10=1,$C26*G$80,0) -> 0.013297772 | H26: =IF($N$10=1,$C26*H$80,C26) -> 0.00060093413
A27: MODS 17 | B27: 1OPTRANS | C27: ='[3]LTTR Unit Costs Final Adj.'!F23 -> 0.011535497 | E27: =IF($N$10=1,$C27*E$80,0) -> 0.010369293 | G27: =IF($N$10=1,$C27*G$80,0) -> 0.0011157812 | H27: =IF($N$10=1,$C27*H$80,C27) -> 5.042281e-05
A28: MODS 17 | B28: 1PLATFRM | C28: ='[3]LTTR Unit Costs Final Adj.'!F24 -> 0.84964044 | E28: =IF($N$10=1,$C28*E$80,0) -> 0.76374435 | G28: =IF($N$10=1,$C28*G$80,0) -> 0.082182231 | H28: =IF($N$10=1,$C28*H$80,C28) -> 0.0037138634
A29: MODS 17 | B29: 1POUCHNG | C29: ='[3]LTTR Unit Costs Final Adj.'!F25 -> 0.0033723761 | E29: =IF($N$10=1,$C29*E$80,0) -> 0.003031439 | G29: =IF($N$10=1,$C29*G$80,0) -> 0.00032619609 | H29: =IF($N$10=1,$C29*H$80,C29) -> 1.4740993e-05
A30: MODS 17 | B30: 1PRESORT | C30: ='[3]LTTR Unit Costs Final Adj.'!F26 -> 0.0076336597 | E30: =IF($N$10=1,$C30*E$80,0) -> 0.0068619196 | G30: =IF($N$10=1,$C30*G$80,0) -> 0.00073837255 | H30: =IF($N$10=1,$C30*H$80,C30) -> 3.336749e-05
A31: MODS 17 | B31: 1SACKS_H | C31: ='[3]LTTR Unit Costs Final Adj.'!F27 -> 0.0045746014 | E31: =IF($N$10=1,$C31*E$80,0) -> 0.0041121229 | G31: =IF($N$10=1,$C31*G$80,0) -> 0.0004424824 | H31: =IF($N$10=1,$C31*H$80,C31) -> 1.999604e-05
A32: MODS 17 | B32: 1SCAN | C32: ='[3]LTTR Unit Costs Final Adj.'!F28 -> 0.034154825 | E32: =IF($N$10=1,$C32*E$80,0) -> 0.030701875 | G32: =IF($N$10=1,$C32*G$80,0) -> 0.0033036559 | H32: =IF($N$10=1,$C32*H$80,C32) -> 0.00014929416
A33: MODS 18 | B33: BUSREPLY | C33: ='[3]LTTR Unit Costs Final Adj.'!F29 -> 0.0042621495 | H33: =+C33 -> 0.0042621495
A34: MODS 18 | B34: EXPRESS | C34: ='[3]LTTR Unit Costs Final Adj.'!F30 -> 0.004208868 | G34: =C34 -> 0.004208868
A35: MODS 18 | B35: REGISTRY | C35: ='[3]LTTR Unit Costs Final Adj.'!F31 -> 0.0048605359 | H35: =+C35 -> 0.0048605359
A36: MODS 18 | B36: REWRAP | C36: ='[3]LTTR Unit Costs Final Adj.'!F32 -> 0.0049290547 | G36: =C36 -> 0.0049290547
A37: MODS 18 | B37: 1EEQMT | C37: ='[3]LTTR Unit Costs Final Adj.'!F33 -> 0.060033785 | E37: =IF($N$10=1,$C37*E$80,0) -> 0.05396455 | G37: =IF($N$10=1,$C37*G$80,0) -> 0.0058068215 | H37: =IF($N$10=1,$C37*H$80,C37) -> 0.00026241368
A38: MODS 18 | B38: 1MISC | C38: ='[3]LTTR Unit Costs Final Adj.'!F34 -> 0.030776402 | G38: =C38 -> 0.030776402
A39: MODS 18 | B39: 1SUPPORT | C39: ='[3]LTTR Unit Costs Final Adj.'!F35 -> 0.022841584 | E39: =IF($N$10=1,$C39*E$80,0) -> 0.020532369 | G39: =IF($N$10=1,$C39*G$80,0) -> 0.0022093727 | H39: =IF($N$10=1,$C39*H$80,C39) -> 9.984285e-05
A40: MODS 19 | B40: INTL ISC | C40: ='[3]LTTR Unit Costs Final Adj.'!F36 -> 0.0046988134 | E40: =IF($N$10=1,$C40*E$80,0) -> 0.0042237775 | G40: =IF($N$10=1,$C40*G$80,0) -> 0.00045449693 | H40: =IF($N$10=1,$C40*H$80,C40) -> 2.0538984e-05
A51: MODS Subtotal | C51: =SUM(C7:C50) -> 5.9919053 | E51: =SUM(E7:E50) -> 5.5942283 | G51: =SUM(G7:G50) -> 0.38040583 | H51: =SUM(H7:H50) -> 0.017271207
A52: NDCS | B52: FSS | C52: 0 | E52: =+C52 -> 0
...

Sheet CRA - PRESORT CARDS
A1: FIRST CLASS MAIL PRESORT CARDS
A2: CRA MAIL PROCESSING COSTS
A3: Source: USPS-FY25-26
A4: Source - Worksheet: LTTR Unit Costs Final Adj.
E5: Worksharing-Related
A6: Cost Pools | C6: Total (Cents) | E6: Proportional (Cents) | G6: Fixed (Cents) | H6: Non-WS Related (Cents) | L6: Key | M6: Treatment
A7: MODS 11 | B7: D/BCS | C7: ='[3]LTTR Unit Costs Final Adj.'!$G$6 -> 1.5496603 | E7: =+C7 -> 1.5496603 | L7: Piece Sorting | M7: Proportional
A8: MODS 12 | B8: AFSM100 | C8: ='[3]LTTR Unit Costs Final Adj.'!$G$7 -> 0.006257641 | E8: =+C8 -> 0.006257641 | L8: Fwd/Accept/Cust.Srv. | M8: WS Fixed
L9: Non-WS | M9: Non WS
A10: MODS 12 | B10: FSS | C10: ='[3]LTTR Unit Costs Final Adj.'!$G$8 -> 0 | E10: =+C10 -> 0 | L10: Unexpected | M10: =IF(N10=1,"Piggybacked","Non WS") -> Piggybacked | N10: 1
A12: MODS 13 | B12: APBS BUNDLE | C12: ='[3]LTTR Unit Costs Final Adj.'!G9 -> 0.00056705811 | E12: =IF($N$10=1,$C12*E$80,0) -> 0.00051932228 | G12: =IF($N$10=1,$C12*G$80,0) -> 4.7571554e-05 | H12: =IF($N$10=1,$C12*H$80,C12) -> 1.6428094e-07 | L12: Allied/Support | M12: Piggybacked
A13: MODS 13 | B13: APBSPRIO | C13: ='[3]LTTR Unit Costs Final Adj.'!G10 -> 0.041189701 | E13: =IF($N$10=1,$C13*E$80,0) -> 0.037722288 | G13: =IF($N$10=1,$C13*G$80,0) -> 0.0034554803 | H13: =IF($N$10=1,$C13*H$80,C13) -> 1.1932962e-05
A14: MODS 16 | B14: LCUS-SSM | C14: ='[3]LTTR Unit Costs Final Adj.'!G11 -> 5.4875269e-05 | E14: =IF($N$10=1,$C14*E$80,0) -> 5.0255783e-05 | G14: =IF($N$10=1,$C14*G$80,0) -> 4.6035879e-06 | H14: =IF($N$10=1,$C14*H$80,C14) -> 1.5897773e-08 | L14: Note: OPBULK, OPPREF and Pouching
A15: MODS 16 | B15: 1TRAYSRT | C15: ='[3]LTTR Unit Costs Final Adj.'!G12 -> 0.19321075 | E15: =IF($N$10=1,$C15*E$80,0) -> 0.17694597 | G15: =IF($N$10=1,$C15*G$80,0) -> 0.016208808 | H15: =IF($N$10=1,$C15*H$80,C15) -> 5.597459e-05 | L15: were WS related fixed in 3 column system,
A16: MODS 14 | B16: MANF | C16: ='[3]LTTR Unit Costs Final Adj.'!G13 -> 6.7115203e-05 | E16: =+C16 -> 6.7115203e-05 | L16: are grouped with prep and accept
A17: MODS 14 | B17: MANL | C17: ='[3]LTTR Unit Costs Final Adj.'!G14 -> 0.22018165 | E17: =+C17 -> 0.22018165
A18: MODS 14 | B18: MANP | C18: ='[3]LTTR Unit Costs Final Adj.'!G15 -> 2.8255468e-06 | E18: =IF($N$10=1,$C18*E$80,0) -> 2.5876879e-06 | G18: =IF($N$10=1,$C18*G$80,0) -> 2.3704035e-07 | H18: =IF($N$10=1,$C18*H$80,C18) -> 8.185819e-10
A19: MODS 14 | B19: PRIORITY | C19: ='[3]LTTR Unit Costs Final Adj.'!G16 -> 0.019030003 | E19: =IF($N$10=1,$C19*E$80,0) -> 0.017428028 | G19: =IF($N$10=1,$C19*G$80,0) -> 0.0015964622 | H19: =IF($N$10=1,$C19*H$80,C19) -> 5.5131332e-06
A20: MODS 15 | B20: LD15 | C20: ='[3]LTTR Unit Costs Final Adj.'!G17 -> 0.072981539 | E20: =+C20 -> 0.072981539
A21: MODS 17 | B21: 1CANCEL | C21: ='[3]LTTR Unit Costs Final Adj.'!G18 -> 0.078156685 | G21: =C21 -> 0.078156685
A22: MODS 17 | B22: 1DSPATCH | C22: ='[3]LTTR Unit Costs Final Adj.'!G19 -> 0.06490402 | E22: =IF($N$10=1,$C22*E$80,0) -> 0.059440299 | G22: =IF($N$10=1,$C22*G$80,0) -> 0.0054449184 | H22: =IF($N$10=1,$C22*H$80,C22) -> 1.8803176e-05
A24: MODS 17 | B24: 1MTRPREP | C24: ='[3]LTTR Unit Costs Final Adj.'!$G$20 -> 0 | G24: =C24 -> 0
A25: MODS 17 | B25: 1OPBULK | C25: ='[3]LTTR Unit Costs Final Adj.'!G21 -> 0.0031431898 | E25: =IF($N$10=1,$C25*E$80,0) -> 0.0028785912 | G25: =IF($N$10=1,$C25*G$80,0) -> 0.00026368801 | H25: =IF($N$10=1,$C25*H$80,C25) -> 9.1060543e-07
A26: MODS 17 | B26: 1OPPREF | C26: ='[3]LTTR Unit Costs Final Adj.'!G22 -> 0.056512807 | E26: =IF($N$10=1,$C26*E$80,0) -> 0.05175547 | G26: =IF($N$10=1,$C26*G$80,0) -> 0.0047409639 | H26: =IF($N$10=1,$C26*H$80,C26) -> 1.637218e-05
A27: MODS 17 | B27: 1OPTRANS | C27: ='[3]LTTR Unit Costs Final Adj.'!G23 -> 0.0034838672 | E27: =IF($N$10=1,$C27*E$80,0) -> 0.0031905898 | G27: =IF($N$10=1,$C27*G$80,0) -> 0.00029226807 | H27: =IF($N$10=1,$C27*H$80,C27) -> 1.0093022e-06
A28: MODS 17 | B28: 1PLATFRM | C28: ='[3]LTTR Unit Costs Final Adj.'!G24 -> 0.42175528 | E28: =IF($N$10=1,$C28*E$80,0) -> 0.38625126 | G28: =IF($N$10=1,$C28*G$80,0) -> 0.035381831 | H28: =IF($N$10=1,$C28*H$80,C28) -> 0.00012218564
A29: MODS 17 | B29: 1POUCHNG | C29: ='[3]LTTR Unit Costs Final Adj.'!G25 -> 0.00058451867 | E29: =IF($N$10=1,$C29*E$80,0) -> 0.00053531298 | G29: =IF($N$10=1,$C29*G$80,0) -> 4.9036353e-05 | H29: =IF($N$10=1,$C29*H$80,C29) -> 1.693394e-07
A30: MODS 17 | B30: 1PRESORT | C30: ='[3]LTTR Unit Costs Final Adj.'!G26 -> 0.0013024636 | E30: =IF($N$10=1,$C30*E$80,0) -> 0.0011928202 | G30: =IF($N$10=1,$C30*G$80,0) -> 0.00010926608 | H30: =IF($N$10=1,$C30*H$80,C30) -> 3.7733338e-07
A31: MODS 17 | B31: 1SACKS_H | C31: ='[3]LTTR Unit Costs Final Adj.'!G27 -> 0.0015793368 | E31: =IF($N$10=1,$C31*E$80,0) -> 0.0014463858 | G31: =IF($N$10=1,$C31*G$80,0) -> 0.00013249349 | H31: =IF($N$10=1,$C31*H$80,C31) -> 4.5754559e-07
A32: MODS 17 | B32: 1SCAN | C32: ='[3]LTTR Unit Costs Final Adj.'!G28 -> 0.025995889 | E32: =IF($N$10=1,$C32*E$80,0) -> 0.023807515 | G32: =IF($N$10=1,$C32*G$80,0) -> 0.0021808433 | H32: =IF($N$10=1,$C32*H$80,C32) -> 7.5312021e-06
A33: MODS 18 | B33: BUSREPLY | C33: ='[3]LTTR Unit Costs Final Adj.'!$G$29 -> 0 | H33: =+C33 -> 0
A34: MODS 18 | B34: EXPRESS | C34: ='[3]LTTR Unit Costs Final Adj.'!$G$30 -> 0.00021010163 | G34: =C34 -> 0.00021010163
A35: MODS 18 | B35: REGISTRY | C35: ='[3]LTTR Unit Costs Final Adj.'!G31 -> 0.0001635964 | H35: =+C35 -> 0.0001635964
A36: MODS 18 | B36: REWRAP | C36: ='[3]LTTR Unit Costs Final Adj.'!G32 -> 0.00032738108 | G36: =C36 -> 0.00032738108
A37: MODS 18 | B37: 1EEQMT | C37: ='[3]LTTR Unit Costs Final Adj.'!G33 -> 0.017471678 | E37: =IF($N$10=1,$C37*E$80,0) -> 0.016000885 | G37: =IF($N$10=1,$C37*G$80,0) -> 0.0014657314 | H37: =IF($N$10=1,$C37*H$80,C37) -> 5.0616749e-06
A38: MODS 18 | B38: 1MISC | C38: ='[3]LTTR Unit Costs Final Adj.'!G34 -> 0.0068145061 | G38: =C38 -> 0.0068145061
A39: MODS 18 | B39: 1SUPPORT | C39: ='[3]LTTR Unit Costs Final Adj.'!G35 -> 0.010507041 | E39: =IF($N$10=1,$C39*E$80,0) -> 0.0096225415 | G39: =IF($N$10=1,$C39*G$80,0) -> 0.00088145508 | H39: =IF($N$10=1,$C39*H$80,C39) -> 3.0439676e-06
A40: MODS 19 | B40: INTL ISC | C40: ='[3]LTTR Unit Costs Final Adj.'!$G$36 -> 0 | E40: =IF($N$10=1,$C40*E$80,0) -> 0 | G40: =IF($N$10=1,$C40*G$80,0) -> 0 | H40: =IF($N$10=1,$C40*H$80,C40) -> 0
A51: MODS Subtotal | C51: =SUM(C7:C50) -> 2.7961158 | E51: =SUM(E7:E50) -> 2.6379384 | G51: =SUM(G7:G50) -> 0.15776433 | H51: =SUM(H7:H50) -> 0.00041312004
A52: NDCS | B52: FSS | C52: ='[3]LTTR Unit Costs Final Adj.'!$G$37 -> 0 | E52: =+C52 -> 0
...

Sheet BMM_Volume
A2: First Class Mail
A3: Revenue Pieces and Weight
A4: By Weight Increment, Shape and Indicia
A5: Fiscal Year 2025
A7: Quarter | B7: (All)
A8: Regime | B8: (All)
A9: WGTI | B9: (All)
A10: Shape | B10: (All)
A12: Sum of Pieces | E12: Indicia
A13: Sum Code | B13: Sum Label | C13: RPW Cat | D13: Cat Label | E13: Metered | F13: PVI | G13: Grand Total
A14: 50 | B14: Single-Piece Letters | C14: 10010IAAM | D14: FCM SP LETTERS NON-PERMIT (OTHER THAN METER) | F14: 34098517 | G14: 34098517
C15: 10010IFAM | D15: FCM SP LETTERS NON-PERMIT (METER) | E15: 3.3002891e+09 | F15: -26849 | G15: 3.3002622e+09
C16: 10012IAAM | D16: FCM SP NONMACH LETTERS NON-PERMIT (OTHER THAN METER) | F16: 2393799 | G16: 2393799
C17: 10012IFAM | D17: FCM SP NONMACH LETTERS NON-PERMIT (METER) | E17: 7970348 | F17: 118 | G17: 7970466
C18: 101101 | D18: FCM RESIDUAL NONPRSRT LETTERS 2 OZ | E18: 6286054.3 | G18: 6286054.3
C19: 101105 | D19: FCM SP LETTERS PERMIT | E19: 0 | G19: 0
C20: 101106 | D20: FCM SP NONMACH LETTERS PERMIT | E20: 0 | G20: 0
A21: Grand Total | E21: 3.3145455e+09 | F21: 36465585 | G21: 3.3510111e+09

Sheet AUTO MAADC COST
A1: FIRST-CLASS AUTOMATION MIXED-AADC PRESORTED LETTERS
A2: COST SHEET
A3: Total Pieces | C3: =+'AUTO MAADC MODEL'!N4 -> 10000
H5: Direct | I5: Premium | K5: Total | L5: Weighted
E6: Pieces | G6: Wage | H6: Cents | I6: Pay | J6: Piggyback | K6: Cents | L6: Cents
C7: TPH | E7: Per Hour | G7: Rate | H7: Per Piece | I7: Adjust | J7: Factor | K7: Per Piece | L7: Per Piece
C8: [1] | E8: [2] | G8: [3] | H8: [4] | I8: [5] | J8: [6] | K8: [7] | L8: [8]
A9: Entry Activities
B10: Bundle Sorting
A11: Outgoing RBCS
B12: ISS | C12: =+'AUTO MAADC MODEL'!G18 -> 0 | E12: =+PRODUCTIVITY!I7 -> 6833.2327 | G12: =+'WAGE RATES - PIGGYBACK FACTORS'!$D$5 -> 50.107175 | H12: =+G12/E12*100 -> 0.73328652 | I12: =+H12*('WAGE RATES - PIGGYBACK FACTORS'!$D$6-1) -> 0.015342425 | J12: =+'WAGE RATES - PIGGYBACK FACTORS'!D22 -> 1.6888485 | K12: =+H12*J12+I12 -> 1.2537523 | L12: =+(K12*C12/10000) -> 0
B13: RCR | C13: =+'AUTO MAADC MODEL'!G25 -> 0 | E13: -- | F13: -- | G13: -- | H13: -- | I13: -- | J13: -- | K13: =+MISC!$E$7 -> 0.27889541 | L13: =+(K13*C13/10000) -> 0
B14: REC | C14: =+'AUTO MAADC MODEL'!G32 -> 0 | E14: =+PRODUCTIVITY!I9 -> 846.86663 | G14: =+'WAGE RATES - PIGGYBACK FACTORS'!$D$4 -> 54.14236 | H14: =+G14/E14*100 -> 6.393257 | I14: =+H14*('WAGE RATES - PIGGYBACK FACTORS'!$D$6-1) -> 0.13376499 | J14: =+'WAGE RATES - PIGGYBACK FACTORS'!D23 -> 1.2615773 | K14: =+H14*J14+I14 -> 8.199353 | L14: =+(K14*C14/10000) -> 0
B15: OSS | C15: =+'AUTO MAADC MODEL'!G39 -> 0 | E15: =+PRODUCTIVITY!I11 -> 6833.2327 | G15: =+'WAGE RATES - PIGGYBACK FACTORS'!$D$5 -> 50.107175 | H15: =+G15/E15*100 -> 0.73328652 | I15: =+H15*('WAGE RATES - PIGGYBACK FACTORS'!$D$6-1) -> 0.015342425 | J15: =+'WAGE RATES - PIGGYBACK FACTORS'!D24 -> 1.6888485 | K15: =+H15*J15+I15 -> 1.2537523 | L15: =+(K15*C15/10000) -> 0
B16: LCREM | C16: =+'AUTO MAADC MODEL'!C32 -> 0 | E16: =+PRODUCTIVITY!I10 -> 1983.2154 | G16: =+'WAGE RATES - PIGGYBACK FACTORS'!$D$5 -> 50.107175 | H16: =+G16/E16*100 -> 2.5265624 | I16: =+H16*('WAGE RATES - PIGGYBACK FACTORS'!$D$6-1) -> 0.05286282 | J16: =+'WAGE RATES - PIGGYBACK FACTORS'!D25 -> 3.4396835 | K16: =+H16*J16+I16 -> 8.7434377 | L16: =+(K16*C16/10000) -> 0
A17: Outgoing Primary
B18: Automation | C18: =+'AUTO MAADC MODEL'!S16 -> 10038.939 | E18: =+PRODUCTIVITY!I13 -> 6833.2327 | G18: =+'WAGE RATES - PIGGYBACK FACTORS'!$D$5 -> 50.107175 | H18: =+G18/E18*100 -> 0.73328652 | I18: =+H18*('WAGE RATES - PIGGYBACK FACTORS'!$D$6-1) -> 0.015342425 | J18: =+'WAGE RATES - PIGGYBACK FACTORS'!D26 -> 1.6888485 | K18: =+H18*J18+I18 -> 1.2537523 | L18: =+(K18*C18/10000) -> 1.2586342
B19: Manual | C19: =+'AUTO MAADC MODEL'!AA16 -> 274.90987 | E19: =+PRODUCTIVITY!I20 -> 631.32213 | G19: =+'WAGE RATES - PIGGYBACK FACTORS'!$D$5 -> 50.107175 | H19: =+G19/E19*100 -> 7.9368633 | I19: =+H19*('WAGE RATES - PIGGYBACK FACTORS'!$D$6-1) -> 0.16606159 | J19: =+'WAGE RATES - PIGGYBACK FACTORS'!D27 -> 1.2988119 | K19: =+H19*J19+I19 -> 10.474554 | L19: =+(K19*C19/10000) -> 0.28795584
A20: Outgoing Secondary
B21: Automation | C21: =+'AUTO MAADC MODEL'!S24 -> 274.71975 | E21: =+PRODUCTIVITY!I14 -> 5441.4416 | G21: =+'WAGE RATES - PIGGYBACK FACTORS'!$D$5 -> 50.107175 | H21: =+G21/E21*100 -> 0.92084374 | I21: =+H21*('WAGE RATES - PIGGYBACK FACTORS'!$D$6-1) -> 0.019266652 | J21: =+'WAGE RATES - PIGGYBACK FACTORS'!D28 -> 1.6888485 | K21: =+H21*J21+I21 -> 1.5744322 | L21: =+(K21*C21/10000) -> 0.043252762
B22: Manual | C22: =+'AUTO MAADC MODEL'!AA24 -> 54.793095 | E22: =+PRODUCTIVITY!I21 -> 1087.9987 | G22: =+'WAGE RATES - PIGGYBACK FACTORS'!$D$5 -> 50.107175 | H22: =+G22/E22*100 -> 4.6054442 | I22: =+H22*('WAGE RATES - PIGGYBACK FACTORS'!$D$6-1) -> 0.096358899 | J22: =+'WAGE RATES - PIGGYBACK FACTORS'!D29 -> 1.2988119 | K22: =+H22*J22+I22 -> 6.0779647 | L22: =+(K22*C22/10000) -> 0.03330305
A23: Incoming RBCS
B24: ISS | C24: =+'AUTO MAADC MODEL'!G51 -> 0 | E24: =+PRODUCTIVITY!I8 -> 5815.8678 | G24: =+'WAGE RATES - PIGGYBACK FACTORS'!$D$5 -> 50.107175 | H24: =+G24/E24*100 -> 0.86155972 | I24: =+H24*('WAGE RATES - PIGGYBACK FACTORS'!$D$6-1) -> 0.018026263 | J24: =+'WAGE RATES - PIGGYBACK FACTORS'!D30 -> 1.6888485 | K24: =+H24*J24+I24 -> 1.4730701 | L24: =+(K24*C24/10000) -> 0
B25: RCR | C25: =+'AUTO MAADC MODEL'!G58 -> 0 | E25: -- | F25: -- | G25: -- | H25: -- | I25: -- | J25: -- | K25: =+MISC!$E$7 -> 0.27889541 | L25: =+(K25*C25/10000) -> 0
B26: REC | C26: =+'AUTO MAADC MODEL'!G65 -> 0 | E26: =+PRODUCTIVITY!I9 -> 846.86663 | G26: =+'WAGE RATES - PIGGYBACK FACTORS'!$D$4 -> 54.14236 | H26: =+G26/E26*100 -> 6.393257 | I26: =+H26*('WAGE RATES - PIGGYBACK FACTORS'!$D$6-1) -> 0.13376499 | J26: =+'WAGE RATES - PIGGYBACK FACTORS'!D31 -> 1.2615773 | K26: =+H26*J26+I26 -> 8.199353 | L26: =+(K26*C26/10000) -> 0
B27: OSS | C27: =+'AUTO MAADC MODEL'!G72 -> 0 | E27: =+PRODUCTIVITY!I12 -> 5815.8678 | G27: =+'WAGE RATES - PIGGYBACK FACTORS'!$D$5 -> 50.107175 | H27: =+G27/E27*100 -> 0.86155972 | I27: =+H27*('WAGE RATES - PIGGYBACK FACTORS'!$D$6-1) -> 0.018026263 | J27: =+'WAGE RATES - PIGGYBACK FACTORS'!D32 -> 1.6888485 | K27: =+H27*J27+I27 -> 1.4730701 | L27: =+(K27*C27/10000) -> 0
B28: LCREM | C28: =+'AUTO MAADC MODEL'!C65 -> 0 | E28: =+PRODUCTIVITY!I10 -> 1983.2154 | G28: =+'WAGE RATES - PIGGYBACK FACTORS'!$D$5 -> 50.107175 | H28: =+G28/E28*100 -> 2.5265624 | I28: =+H28*('WAGE RATES - PIGGYBACK FACTORS'!$D$6-1) -> 0.05286282 | J28: =+'WAGE RATES - PIGGYBACK FACTORS'!D33 -> 3.4396835 | K28: =+H28*J28+I28 -> 8.7434377 | L28: =+(K28*C28/10000) -> 0
A29: Incoming MMP
