Workbook
Name PAGE1_2: #REF!
Name PAGE3: #REF!

Sheet Summary
A1: PERIODICALS DESTINATION ENTRY
A2: COST AVOIDANCE SUMMARY
D4: [1]
A5: Cost Element | D5: Cost Per Pound
A8: Non-Transportation
B9: DADC | D9: ='Cost Per Pound'!F11 -> 0.0047591305
B10: DSCF | D10: ='Cost Per Pound'!F13 -> 0.03118829
B11: DDU | D11: ='Cost Per Pound'!F15 -> 0.070905506
D14: [2]
A15: Cost Element | D15: Cost Per Piece
A18: Non-Transportation
B19: DADC | D19: =D9*(1/'Inputs 2'!$A$31) -> 0.0013595298
B20: DSCF | D20: =D10*(1/'Inputs 2'!$A$31) -> 0.0089094867
B21: DDU | D21: =D11*(1/'Inputs 2'!$A$31) -> 0.020255412
A24: Sources:
A25: [1]: Page 2
A26: [2]: [1] / Pieces Per Pound (Page 7)

Sheet Cost Per Pound
A1: Periodicals
A2: Handling Costs Avoided
A5: Facility Type | C5: Cost/Piece | F5: Cost/Pound
A7: SCF | C7: =SCF!$J$26 -> 0.0079989564 | D7: [1] | F7: =C7*'Inputs 2'!$A$17 -> 0.026440928 | G7: [2]
A9: NDC | C9: =NDC!$I$30 -> 0.0078855791 | D9: [3] | F9: =C9*'Inputs 2'!$A$17 -> 0.026066154 | G9: [4]
A11: Total Nontransportation Cost Savings-DADC Mail | C11: =+'Inputs 2'!$A$19*(C9-'Inputs 2'!$A$21*C7) -> 0.0014397406 | D11: [5] | F11: =C11*'Inputs 2'!$A$17 -> 0.0047591305 | G11: [6]
A13: Total Nontransportation Cost Savings-DSCF Mail | C13: =C9+('Inputs 2'!$A$19*'Inputs 2'!$A$22*C7) -> 0.0094351369 | D13: [7] | F13: =C13*'Inputs 2'!$A$17 -> 0.03118829 | G13: [8]
A15: Total Nontransportation Cost Savings-DDU Mail | C15: =C13+DU!$I$18+'Inputs 2'!$A$19*C7 -> 0.020255412 | D15: [9] | F15: =C15*'Inputs 2'!$A$31 -> 0.070905506 | G15: [10]
A18: Sources:
A19: [1]: Page 4
A20: [2]: [1] * pieces / pound (page 7)
A21: [3]: Page 3
A22: [4]: [3] * pieces / pound (page 7)
A23: [5]: Proportion of volume from DNDC to DDU via DSCF (Page 7) * ( [3] - Proportion of volume bypassing DADC (Page 7) * [1] )
A24: [6]: [5] * pieces / pound (page 7)
A25: [7]: [3] + Proportion of volume from DNDC to DDU via DSCF (Page 7) * Proportion of volume not bypassing DADC (page 7) * [1]
A26: [8]: [7] * pieces / pound (page 7)
A27: [9]: [7] + DDU Savings (page 5) + Proportion of volume from DNDC to DDU via DSCF (Page 7) * [1]
A28: [10]: [9] * pieces / pound (page 7).

Sheet NDC
A1: Periodicals
A2: Calculation of Crossdocking Costs at NDCs
D5: [1] | E5: [2] | G5: [3] | H5: [4] | I5: [5] | J5: [6] | K5: [7] | L5: [8] | M5: [9] | N5: [10]
D6: % Sack Flow from | E6: Productivity | G6: Pieces per | I6: Piggyback | J6: Premium | K6: NDC Realization | L6: Cost Per | M6: Pieces Per | N6: Cost Per
C7: Operation | D7: NDC Sack Sorters | E7: Containers/Hr | G7: Container | H7: Wage Rate | I7: Factor | J7: Pay Factor | K7: Factor | L7: Hour | M7: Hour | N7: Piece
A8: Sacks | B8: Manual | C8: Unload sacks to extendible conveyor | D8: N/A | E8: ='Inputs 1'!$C$18 -> 199.01968 | G8: ='Inputs 2'!$A$10 -> 44.632629 | H8: ='Inputs 2'!$A$9 -> 50.107175 | I8: ='Inputs 2'!$A$25 -> 1.3860239 | J8: ='Inputs 2'!$A$16 -> 1.0038569 | K8: ='Inputs 2'!$A$18 -> 0.9713 | L8: =K8*J8*I8*H8 -> 67.716709 | M8: =E8*G8 -> 8882.7718 | N8: =L8/M8 -> 0.007623376
C9: Load sacks to van from extendible conveyor | D9: ='Inputs 1'!$A$41 -> 0.7379 | E9: ='Inputs 1'!$C$19 -> 194.2556 | G9: ='Inputs 2'!$A$10 -> 44.632629 | H9: ='Inputs 2'!$A$9 -> 50.107175 | I9: ='Inputs 2'!$A$25 -> 1.3860239 | J9: ='Inputs 2'!$A$16 -> 1.0038569 | K9: ='Inputs 2'!$A$18 -> 0.9713 | L9: =K9*J9*I9*H9 -> 67.716709 | M9: =E9*G9 -> 8670.138 | N9: =L9/M9 -> 0.0078103381
C10: Load sacks from roller table to IHC | D10: ='Inputs 1'!$A$42 -> 0.1601 | E10: ='Inputs 1'!$C$21 -> 194.2556 | G10: ='Inputs 2'!$A$10 -> 44.632629 | H10: ='Inputs 2'!$A$9 -> 50.107175 | I10: ='Inputs 2'!$A$28 -> 1.3297825 | J10: ='Inputs 2'!$A$16 -> 1.0038569 | K10: ='Inputs 2'!$A$18 -> 0.9713 | L10: =K10*J10*I10*H10 -> 64.968931 | M10: =E10*G10 -> 8670.138 | N10: =L10/M10 -> 0.0074934137
C11: Load containers to van | D11: ='Inputs 1'!$A$42 -> 0.1601 | E11: ='Inputs 1'!$C$20*'Inputs 1'!$A$34 -> 440.97354 | F11: 1 | G11: ='Inputs 2'!$A$10 -> 44.632629 | H11: ='Inputs 2'!$A$9 -> 50.107175 | I11: ='Inputs 2'!$A$25 -> 1.3860239 | J11: ='Inputs 2'!$A$16 -> 1.0038569 | K11: ='Inputs 2'!$A$18 -> 0.9713 | L11: =K11*J11*I11*H11 -> 67.716709 | M11: =E11*G11 -> 19681.809 | N11: =L11/M11 -> 0.0034405735
C12: Load sacks from roller table to IHC | D12: ='Inputs 1'!$A$43 -> 0.102 | E12: ='Inputs 1'!$C$21 -> 194.2556 | G12: ='Inputs 2'!$A$10 -> 44.632629 | H12: ='Inputs 2'!$A$9 -> 50.107175 | I12: ='Inputs 2'!$A$28 -> 1.3297825 | J12: ='Inputs 2'!$A$16 -> 1.0038569 | K12: ='Inputs 2'!$A$18 -> 0.9713 | L12: =K12*J12*I12*H12 -> 64.968931 | M12: =E12*G12 -> 8670.138 | N12: =L12/M12 -> 0.0074934137
C13: Load sacks to van from IHC | D13: ='Inputs 1'!$A$43 -> 0.102 | E13: ='Inputs 1'!$C$11 -> 194.2556 | G13: ='Inputs 2'!$A$10 -> 44.632629 | H13: ='Inputs 2'!$A$9 -> 50.107175 | I13: ='Inputs 2'!$A$25 -> 1.3860239 | J13: ='Inputs 2'!$A$16 -> 1.0038569 | K13: ='Inputs 2'!$A$18 -> 0.9713 | L13: =K13*J13*I13*H13 -> 67.716709 | M13: =E13*G13 -> 8670.138 | N13: =L13/M13 -> 0.0078103381
C14: Sack sorter | D14: N/A | E14: ='Inputs 1'!$C$22 -> 3068.1109 | G14: ='Inputs 2'!$A$10 -> 44.632629 | H14: ='Inputs 2'!$A$9 -> 50.107175 | I14: ='Inputs 2'!A23 -> 1.6196175 | J14: ='Inputs 2'!$A$16 -> 1.0038569 | K14: ='Inputs 2'!$A$18 -> 0.9713 | L14: =K14*J14*I14*H14 -> 79.129346 | M14: =E14*G14 -> 136937.86 | N14: =L14/M14 -> 0.00057784857
A15: Pallets | B15: Manual | C15: Unload pallets | D15: N/A | E15: ='Inputs 1'!$C$15 -> 13.055967 | G15: ='Inputs 2'!$A$11 -> 2918.1814 | H15: ='Inputs 2'!$A$9 -> 50.107175 | I15: ='Inputs 2'!$A$25 -> 1.3860239 | J15: ='Inputs 2'!$A$16 -> 1.0038569 | K15: ='Inputs 2'!$A$18 -> 0.9713 | L15: =K15*J15*I15*H15 -> 67.716709 | M15: =E15*G15 -> 38099.679 | N15: =L15/M15 -> 0.0017773564
C16: Crossdock pallets | D16: N/A | E16: ='Inputs 1'!$C$23 -> 7.4909256 | G16: ='Inputs 2'!$A$11 -> 2918.1814 | H16: ='Inputs 2'!$A$9 -> 50.107175 | I16: ='Inputs 2'!A29 -> 1.5176144 | J16: ='Inputs 2'!$A$16 -> 1.0038569 | K16: ='Inputs 2'!$A$18 -> 0.9713 | L16: =K16*J16*I16*H16 -> 74.145799 | M16: =E16*G16 -> 21859.88 | N16: =L16/M16 -> 0.0033918668
C17: Load pallets to van | D17: N/A | E17: ='Inputs 1'!$C$17 -> 14.25402 | G17: ='Inputs 2'!$A$11 -> 2918.1814 | H17: ='Inputs 2'!$A$9 -> 50.107175 | I17: ='Inputs 2'!$A$25 -> 1.3860239 | J17: ='Inputs 2'!$A$16 -> 1.0038569 | K17: ='Inputs 2'!$A$18 -> 0.9713 | L17: =K17*J17*I17*H17 -> 67.716709 | M17: =E17*G17 -> 41595.815 | N17: =L17/M17 -> 0.0016279693
A20: Weighted Cost per Piece
C21: [11] | E21: [12] | G21: [13] | H21: [14] | I21: [15]
E22: Percent Vol. | G22: Percent | H22: Cost | I22: Weighted Cost
C23: Percent of Volume in Container Type | E23: In Operation | G23: Overall | H23: Per Piece | I23: Per Piece
A24: Sacks | C24: ='Inputs 2'!$A$14 -> 0.097226398 | D24: unload | E24: 1 | G24: =E24*C24 -> 0.097226398 | H24: =N8 -> 0.007623376 | I24: =H24*G24 -> 0.00074119339
D25: ext | E25: =D9 -> 0.7379 | G25: =E25*C24 -> 0.071743359 | H25: =N9 -> 0.0078103381 | I25: =H25*G25 -> 0.00056033989
D26: roller | E26: =D10 -> 0.1601 | G26: =E26*C24 -> 0.015565946 | H26: =N11+N10 -> 0.010933987 | I26: =H26*G26 -> 0.00017019786
D27: roller IHC | E27: =D12 -> 0.102 | G27: =E27*C24 -> 0.0099170926 | H27: =N12+N13 -> 0.015303752 | I27: =H27*G27 -> 0.00015176872
D28: SSM | E28: 1 | G28: =E28*C24 -> 0.097226398 | H28: =N14 -> 0.00057784857 | I28: =H28*G28 -> 5.6182136e-05
A29: Pallets | C29: ='Inputs 2'!$A$15 -> 0.91300888 | D29: Manual | E29: 1 | G29: =E29*C29 -> 0.91300888 | H29: =N17+N16+N15 -> 0.0067971925 | I29: =H29*G29 -> 0.0062058971
A30: Total | C30: =C29+C24 -> 1.0102353 | I30: =SUM(I24:I29) -> 0.0078855791
A32: Weighted Cost per Pound
A33: =I30*'Inputs 2'!A17 -> 0.026066154 | B33: 2
A35: 1 Includes a container conversion factor of 40 sacks per NDC container from page 118.
A36: 2 Weighted average cost per piece multiplied by test year pieces per pound from page 119.
A38: Sources:
A39: Column [1]: | B39: Page 6
A40: Column [2]: | B40: Page 6
A41: Column [3]: | B41: Page 7
A42: Column [4]: | B42: Page 7
A43: Column [5]: | B43: Page 7
A44: Column [6]: | B44: Page 7
A45: Column [7]: | B45: Page 7
A46: Column [8]: | B46: (4) * (5) * (6) * (7)
A47: Column [9]: | B47: (2) * (3)
...

Sheet SCF
A1: Periodicals
A2: Calculation of Crossdocking Costs at SCFs
E5: [1] | G5: [2] | H5: [3] | I5: [4] | J5: [5] | K5: [6] | L5: [7] | M5: [8]
E6: Productivity | G6: Pieces Per | I6: Piggyback | J6: Premium | K6: Cost Per | L6: Pieces Per | M6: Cost Per
D7: Operation | E7: Containers/Hr | G7: Container | H7: Wage Rate | I7: Factor | J7: Pay Factor | K7: Hour | L7: Hour | M7: Piece
A8: Sacks | C8: Manual | D8: Unload sacks from van to in-house container | E8: ='Inputs 1'!C9 -> 158.99528 | G8: ='Inputs 2'!$A$10 -> 44.632629 | H8: ='Inputs 2'!$A$9 -> 50.107175 | I8: ='Inputs 2'!$A$26 -> 1.3606062 | J8: ='Inputs 2'!$A$30 -> 1.004024 | K8: =J8*I8*H8 -> 68.45047 | L8: =E8*G8 -> 7096.3776 | M8: =K8/L8 -> 0.0096458325
D9: Move APC to outbound dock | E9: ='Inputs 1'!C10*'Inputs 1'!A33 -> 578.04966 | F9: 1 | G9: ='Inputs 2'!$A$10 -> 44.632629 | H9: ='Inputs 2'!$A$9 -> 50.107175 | I9: ='Inputs 2'!A26 -> 1.3606062 | J9: ='Inputs 2'!$A$30 -> 1.004024 | K9: =J9*I9*H9 -> 68.45047 | L9: =E9*G9 -> 25799.876 | M9: =K9/L9 -> 0.0026531317
D10: Load sacks to van | E10: ='Inputs 1'!C11 -> 194.2556 | G10: ='Inputs 2'!$A$10 -> 44.632629 | H10: ='Inputs 2'!$A$9 -> 50.107175 | I10: ='Inputs 2'!A26 -> 1.3606062 | J10: ='Inputs 2'!$A$30 -> 1.004024 | K10: =J10*I10*H10 -> 68.45047 | L10: =E10*G10 -> 8670.138 | M10: =K10/L10 -> 0.0078949689
C11: Mechanized | D11: Unload sacks to conveyor | E11: ='Inputs 1'!C12 -> 192.95625 | G11: ='Inputs 2'!$A$10 -> 44.632629 | H11: ='Inputs 2'!$A$9 -> 50.107175 | I11: ='Inputs 2'!$A$26 -> 1.3606062 | J11: ='Inputs 2'!$A$30 -> 1.004024 | K11: =J11*I11*H11 -> 68.45047 | L11: =E11*G11 -> 8612.1447 | M11: =K11/L11 -> 0.0079481328
D12: Load sacks to van from extendible conveyor | E12: ='Inputs 1'!C13 -> 188.3373 | G12: ='Inputs 2'!$A$10 -> 44.632629 | H12: ='Inputs 2'!$A$9 -> 50.107175 | I12: ='Inputs 2'!$A$26 -> 1.3606062 | J12: ='Inputs 2'!$A$30 -> 1.004024 | K12: =J12*I12*H12 -> 68.45047 | L12: =E12*G12 -> 8405.9891 | M12: =K12/L12 -> 0.0081430596
D13: Sack sorter | E13: ='Inputs 1'!C14 -> 2969.1222 | G13: ='Inputs 2'!$A$10 -> 44.632629 | H13: ='Inputs 2'!$A$9 -> 50.107175 | I13: ='Inputs 2'!A24 -> 1.5773008 | J13: ='Inputs 2'!$A$30 -> 1.004024 | K13: =J13*I13*H13 -> 79.352119 | L13: =E13*G13 -> 132519.73 | M13: =K13/L13 -> 0.00059879475
A14: Pallets | C14: Manual | D14: Unload pallets | E14: ='Inputs 1'!C15 -> 13.055967 | G14: ='Inputs 2'!$A$11 -> 2918.1814 | H14: ='Inputs 2'!$A$9 -> 50.107175 | I14: ='Inputs 2'!$A$26 -> 1.3606062 | J14: ='Inputs 2'!$A$30 -> 1.004024 | K14: =J14*I14*H14 -> 68.45047 | L14: =E14*G14 -> 38099.679 | M14: =K14/L14 -> 0.0017966154
D15: Move pallets to outbound dock | E15: ='Inputs 1'!C16 -> 7.3074202 | G15: ='Inputs 2'!$A$11 -> 2918.1814 | H15: ='Inputs 2'!$A$9 -> 50.107175 | I15: ='Inputs 2'!A26 -> 1.3606062 | J15: ='Inputs 2'!$A$30 -> 1.004024 | K15: =J15*I15*H15 -> 68.45047 | L15: =E15*G15 -> 21324.377 | M15: =K15/L15 -> 0.0032099633
D16: Load pallets to van | E16: ='Inputs 1'!C17 -> 14.25402 | G16: ='Inputs 2'!$A$11 -> 2918.1814 | H16: ='Inputs 2'!$A$9 -> 50.107175 | I16: ='Inputs 2'!$A$26 -> 1.3606062 | J16: ='Inputs 2'!$A$30 -> 1.004024 | K16: =J16*I16*H16 -> 68.45047 | L16: =E16*G16 -> 41595.815 | M16: =K16/L16 -> 0.0016456095
A19: Weighted Cost per Piece
D20: [9] | G20: [10] | H20: [11] | I20: [12] | J20: [13]
G21: Percent Volume | H21: % Overall | I21: Cost | J21: Weighted Cost
D22: Percent of Volume in Container Type | G22: By Method | H22: Col 9*Col 10 | I22: Per Piece | J22: Per Piece
A23: Sacks | D23: ='Inputs 2'!$A$14 -> 0.097226398 | E23: Manual | G23: ='Inputs 2'!A13 -> 0.88865096 | H23: =G23*D23 -> 0.086400333 | I23: =SUM(M8:M10) -> 0.020193933 | J23: =I23*H23 -> 0.0017447625
E24: Mechanized | G24: ='Inputs 2'!A12 -> 0.11134904 | H24: =G24*D23 -> 0.010826066 | I24: =SUM(M11:M13) -> 0.016689987 | J24: =I24*H24 -> 0.0001806869
A25: Pallets | D25: ='Inputs 2'!$A$15 -> 0.91300888 | E25: Manual | G25: 1 | H25: =G25*D25 -> 0.91300888 | I25: =SUM(M14:M16) -> 0.0066521883 | J25: =I25*H25 -> 0.0060735069
A26: Total | D26: =D25+D23 -> 1.0102353 | H26: =H25+H24+H23 -> 1.0102353 | J26: =SUM(J23:J25) -> 0.0079989564
A29: Weighted Cost per Pound
A30: =J26*'Inputs 2'!A17 -> 0.026440928 | B30: 2
A32: 1 Includes a container conversion factor of 26.5 sacks per IHC from page 47.
A33: 2 Weighted average cost per piece multiplied by test year pieces per pound (page 48).
A35: Sources:
A36: Column [1]: | B36: Page 6
A37: Column [2]: | B37: Page 7
A38: Column [3]: | B38: Page 7
A39: Column [4]: | B39: Page 7
A40: Column [5]: | B40: Page 7
A41: Column [6]: | B41: (3) * (4) * (5)
A42: Column [7]: | B42: (1) * ( 2)
A43: Column [8]: | B43: (6) / (7)
A44: Column [9]: | B44: Page 7
A45: Column [10]: | B45: Page 7
A46: Column [11]: | B46: (9) * (10)
A47: Column [12]: | B47: ="(8)" -> (8)
A48: Column [13]: | B48: (11) * (12)

Sheet DU
A1: Periodicals
A2: Calculation of Unloading Costs at DDUs
E5: [1] | F5: [2] | G5: [3] | H5: [4] | I5: [5] | J5: [6] | K5: [7] | L5: [8]
E6: Productivity | H6: Piggyback | I6: Premium | J6: Cost Per | K6: Piece Per | L6: Cost Per
D7: Operation | E7: Containers/Hr | F7: Pieces per Container | G7: Wage Rate | H7: Factor | I7: Pay Factor | J7: Hour | K7: Hour | L7: Piece
A8: Sacks | C8: Manual | D8: Unload sacks from van to in-house container | E8: ='Inputs 1'!C9 -> 158.99528 | F8: ='Inputs 2'!$A$10 -> 44.632629 | G8: ='Inputs 2'!$A$9 -> 50.107175 | H8: ='Inputs 2'!$A$27 -> 1.6214861 | I8: ='Inputs 2'!$A$30 -> 1.004024 | J8: =I8*H8*G8 -> 81.575024 | K8: =E8*F8 -> 7096.3776 | L8: =J8/K8 -> 0.011495305
A9: Pallets | C9: Manual | D9: Unload pallets | E9: ='Inputs 1'!C15 -> 13.055967 | F9: ='Inputs 2'!$A$11 -> 2918.1814 | G9: ='Inputs 2'!$A$9 -> 50.107175 | H9: ='Inputs 2'!$A$27 -> 1.6214861 | I9: ='Inputs 2'!$A$30 -> 1.004024 | J9: =I9*H9*G9 -> 81.575024 | K9: =E9*F9 -> 38099.679 | L9: =J9/K9 -> 0.0021410948
A12: Weighted Cost per Piece
D13: [9] | F13: [10] | G13: [11] | H13: [12] | I13: [13]
F14: Percent Vol. | G14: Percent | I14: Weighted Cost
D15: Percent of Volume in Container Type | F15: In Operation | G15: Overall | H15: Cost/Piece | I15: Per Piece
A16: Sacks | D16: ='Inputs 2'!$A$14 -> 0.097226398 | E16: Manual | F16: 1 | G16: =F16*D16 -> 0.097226398 | H16: =L8 -> 0.011495305 | I16: =H16*G16 -> 0.0011176471
A17: Pallets | D17: ='Inputs 2'!$A$15 -> 0.91300888 | E17: Manual | F17: 1 | G17: =F17*D17 -> 0.91300888 | H17: =L9 -> 0.0021410948 | I17: =H17*G17 -> 0.0019548385
A18: Total | D18: =D17+D16 -> 1.0102353 | G18: =G17+G16 -> 1.0102353 | I18: =SUM(I16:I17) -> 0.0030724856
A21: Sources:
A22: Column [1]: | B22: Page 6
A23: Column [2]: | B23: Page 7
A24: Column [3]: | B24: Page 7
A25: Column [4]: | B25: Page 7
A26: Column [5]: | B26: Page 7
A27: Column [6]: | B27: (3) * (4) * (5)
A28: Column [7]: | B28: (1) * (2)
A29: Column [8]: | B29: (6) / (7)
A30: Column [9]: | B30: Page 7
A31: Column [10]: | B31: 100 % volume processed
A32: Column [11]: | B32: (9) * (10)
A33: Column [12]: | B33: ="(8)" -> (8)
A34: Column [13]: | B34: (11) * (12)

Sheet Inputs 1
A1: Inputs to Periodicals Destination Entry Cost Avoidance Models
A2: Productivities and Conversion Factors
A6: Productivity | C6: Adjusted
A7: (Units per Hour) | B7: Variability 1 | C7: Productivity | E7: Operation | G7: Sources
A9: 145.779 | B9: 0.91687625 | C9: =+A9/B9 -> 158.99528 | E9: unload sacks from van to in-house countainer (IHC) - (PDC) | G9: Docket No. R97-1, LR-H-132, page 329.
A10: 20 | B10: =B9 -> 0.91687625 | C10: =+A10/B10 -> 21.813195 | E10: move all-purpose container (APC), IHC to outbound dock - (PDC) | G10: Docket No. R97-1, LR-H-111, Appendix F
A11: 172.682 | B11: 0.88894222 | C11: =+A11/B11 -> 194.2556 | E11: load sacks to van from IHC - (NDC) | G11: Docket No. R97-1, LR-H-132, page 329.
A12: 176.917 | B12: =B9 -> 0.91687625 | C12: =+A12/B12 -> 192.95625 | E12: unload sacks to conveyor - (PDC) | G12: Docket No. R97-1, LR-H-132, page 329.
A13: 172.682 | B13: =B9 -> 0.91687625 | C13: =+A13/B13 -> 188.3373 | E13: load sacks to van from extendible conveyor - (PDC) | G13: Docket No. R97-1, LR-H-132, page 329.
A14: 2848.2562 | B14: 0.95929236 | C14: =+A14/B14 -> 2969.1222 | E14: sack sorter - (PDC - NDC value used as a proxy productivity value) | G14: USPS-FY25-23
A15: 11.606 | B15: =B11 -> 0.88894222 | C15: =+A15/B15 -> 13.055967 | E15: unload pallets - (NDC) | G15: Docket No. R97-1, LR-H-132, page 329.
A16: 6.7 | B16: =B9 -> 0.91687625 | C16: =+A16/B16 -> 7.3074202 | E16: move pallets to outbound dock - (PDC) | G16: Docket No. R97-1, LR-H-111, Appendix F
A17: 12.671 | B17: =B11 -> 0.88894222 | C17: =+A17/B17 -> 14.25402 | E17: load pallets to van - (NDC) | G17: Docket No. R97-1, LR-H-132, page 329.
A18: 176.917 | B18: =B11 -> 0.88894222 | C18: =+A18/B18 -> 199.01968 | E18: unload sacks to extendible conveyor - (NDC) | G18: Docket No. R97-1, LR-H-132, page 329.
A19: 172.682 | B19: =B11 -> 0.88894222 | C19: =+A19/B19 -> 194.2556 | E19: load sacks to van from extendible conveyor - (NDC) | G19: Docket No. R97-1, LR-H-132, page 329.
A20: 9.8 | B20: =B11 -> 0.88894222 | C20: =+A20/B20 -> 11.024339 | E20: load wheeled containers to van - (NDC) | G20: Docket No. R97-1, LR-H-132, page 329.
A21: 172.682 | B21: =B11 -> 0.88894222 | C21: =+A21/B21 -> 194.2556 | E21: load sacks from roller table to IHC - (NDC) | G21: Docket No. R97-1, LR-H-132, page 329.
A22: 2848.2562 | B22: 0.928342 | C22: =+A22/B22 -> 3068.1109 | E22: sack sorter - (NDC) | G22: USPS-FY25-23
A23: 6.659 | B23: =B11 -> 0.88894222 | C23: =+A23/B23 -> 7.4909256 | E23: crossdock pallets - (NDC) | G23: Docket No. R97-1, LR-H-132, page 329.
A24: 49.684425 | B24: 0.91586806 | C24: =+A24/B24 -> 54.248453 | E24: primary NMO sort - (NDC) | G24: USPS-FY25-23
A25: 47.967809 | B25: 0.97225878 | C25: =+A25/B25 -> 49.336463 | E25: secondary NMO sort - (PDC) | G25: USPS-FY25-23
A26: 167.097 | B26: =B11 -> 0.88894222 | C26: =+A26/B26 -> 187.97285 | E26: load NMOs to van from IHC - (NDC) | G26: Docket No. R97-1, LR-H-132, page 329.
A29: Container
A30: Conversion
A31: Factor | C31: Description | G31: Sources
A33: 26.5 | C33: sacks per IHC | G33: Docket No. R97-1, LR-H-111, Appendix F
A34: 40 | C34: sacks per NDC container | G34: Docket No. R97-1, LR-H-111, Appendix F
A39: Percentage | C39: Flow Description | G39: Sources
A41: 0.7379 | C41: sack sorter machine (SSM) to load to van from extendible conveyor | G41: Docket No. R97-1, LR-H-111, Appendix F
A42: 0.1601 | C42: SSM to roller table to NDC containers and load NDC containers to van | G42: Docket No. R97-1, LR-H-111, Appendix F
A43: 0.102 | C43: SSM to roller table to in-house containers and load sacks to van from IHCs | G43: Docket No. R97-1, LR-H-111, Appendix F
A46: 1 USPS-FY25-7, Part 6
A47: NDC volume variabilites are applied when marginal productivities at NDCs are used as proxies for marginal productivites at SCFs.
A48: 2 Productivity divided by volume variability.

Sheet Inputs 2
A1: Inputs to Periodicals Destination Entry Cost Avoidance Models
A2: Piggyback Factors, Wages and Volumes
A7: Value | C7: Description | E7: Sources
A9: 50.107175 | C9: Other Mail Processing Productive Hourly Wage Rate | E9: USPS-FY25-7, Part 8
A10: 44.632629 | C10: Periodical Pieces per Sack | E10: USPS-FY25-14
A11: 2918.1814 | C11: Periodical Pieces per Pallet | E11: USPS-FY25-14
A12: =52/467 -> 0.11134904 | C12: Proportion of SCFs That Are Mechanized | E12: Docket No. MC95-1, Exhibit USPS-T-11U
A13: =415/467 -> 0.88865096 | C13: Proportion of SCFs That Are Not Mechanized | E13: Docket No. MC95-1, Exhibit USPS-T-11U
A14: 0.097226398 | C14: Proportion of Periodicals Mail in Sacks | E14: USPS-FY25-14
A15: 0.91300888 | C15: Proportion of Periodicals Mail on Pallets | E15: USPS-FY25-14
A16: 1.0038569 | C16: Premium Pay Factor for All Facilities | E16: USPS-FY25-7, Part 5
A17: 3.3055472 | C17: Pieces per Pound for Outside County Publications | E17: RPW
A18: 0.9713 | C18: NDC Realization Factor | E18: Docket No. R94-1, Tr. 8/4006
A19: 0.9686 | C19: Proportion of Volume from DNDCs to DDUs via DSCFs | E19: Docket No. R90-1, Exhibit USPS-T-12B, p. 5
A20: 0.0314 | C20: Proportion of Volume from DNDCs Directly to DDUs | E20: Docket No. R90-1, Exhibit USPS-T-12B, p. 5
A21: 0.8 | C21: Proportion of Volume Bypassing DADC | E21: Docket No. R2006-1, USPS-T-25, page 7.
A22: 0.2 | C22: Proportion of Volume Not Bypassing DADC | E22: Docket No. R2006-1, USPS-T-25, page 7.
A23: 1.6196175 | C23: Piggyback Factor for Sack Sorters at NDCs | E23: USPS-FY25-25
A24: 1.5773008 | C24: Piggyback Factor for Sack Sorters at Non-NDCs | E24: USPS-FY25-25
A25: 1.3860239 | C25: Piggyback Factor for Platform at NDCs | E25: USPS-FY25-25
... A31: 3.500571 | C31: Pieces per Pound for Total Periodicals | E31: RPW
