Workbook
Name a_coa_exp: 'Parameters demand'!$Y$11:$Y$84
Name a_coa_ind: 'Parameters demand'!$V$11:$V$84
Name a_coa_oth: 'Parameters demand'!$X$11:$X$84
Name a_ele_com: 'Parameters demand'!$R$11:$R$84
Name a_ele_ind: 'Parameters demand'!$S$11:$S$84
Name a_ele_oth: 'Parameters demand'!$U$11:$U$84
Name a_ele_res: 'Parameters demand'!$Q$11:$Q$84
Name a_ele_tra: 'Parameters demand'!$T$11:$T$84
Name a_gas_com: 'Parameters demand'!$L$11:$L$84
Name a_gas_exp: 'Parameters demand'!$P$11:$P$84
Name a_gas_ind: 'Parameters demand'!$M$11:$M$84
Name a_gas_res: 'Parameters demand'!$K$11:$K$84
Name a_gas_tra: 'Parameters demand'!$N$11:$N$84
Name a_oil_com: 'Parameters demand'!$D$11:$D$84
Name a_oil_ind: 'Parameters demand'!$E$11:$E$84
Name a_oil_res: 'Parameters demand'!$C$11:$C$84
Name a_oil_row_crude: 'Parameters demand'!$H$11:$H$84
Name a_oil_row_non_us: 'Parameters demand'!$J$11:$J$84
Name a_oil_row_ref: 'Parameters demand'!$I$11:$I$84
Name a_oil_tra: 'Parameters demand'!$F$11:$F$84
Name aeo_dem_coa_2010: 'Coal demand projection'!$C$10:$G$10
Name aeo_dem_coa_ele: 'Coal demand projection'!$D$10:$D$84
Name aeo_dem_coa_exp: 'Coal demand projection'!$F$10:$F$84
Name aeo_dem_coa_ind: 'Coal demand projection'!$C$10:$C$84
Name aeo_dem_coa_oth: 'Coal demand projection'!$E$10:$E$84
Name aeo_dem_coa_tot: 'Coal demand projection'!$G$10:$G$84
Name aeo_dem_ele_2010: 'Electricity demand projection'!$C$10:$H$10
Name aeo_dem_ele_com: 'Electricity demand projection'!$D$10:$D$84
Name aeo_dem_ele_ind: 'Electricity demand projection'!$E$10:$E$84
Name aeo_dem_ele_oth: 'Electricity demand projection'!$G$10:$G$84
Name aeo_dem_ele_res: 'Electricity demand projection'!$C$10:$C$84
Name aeo_dem_ele_tot: 'Electricity demand projection'!$H$10:$H$84
Name aeo_dem_ele_tra: 'Electricity demand projection'!$F$10:$F$84
Name aeo_dem_gas_2010: 'Gas demand projection'!$C$10:$I$10
Name aeo_dem_gas_com: 'Gas demand projection'!$D$10:$D$84
Name aeo_dem_gas_ele: 'Gas demand projection'!$G$10:$G$84
Name aeo_dem_gas_exp: 'Gas demand projection'!$H$10:$H$84
Name aeo_dem_gas_ind: 'Gas demand projection'!$E$10:$E$84
Name aeo_dem_gas_res: 'Gas demand projection'!$C$10:$C$84
Name aeo_dem_gas_tot: 'Gas demand projection'!$I$10:$I$84
Name aeo_dem_gas_tra: 'Gas demand projection'!$F$10:$F$84
Name aeo_dem_oil_2010: 'Oil demand projection'!$C$10:$K$10
Name aeo_dem_oil_com: 'Oil demand projection'!$D$10:$D$84
Name aeo_dem_oil_ele: 'Oil demand projection'!$G$10:$G$84
Name aeo_dem_oil_ind: 'Oil demand projection'!$E$10:$E$84
Name aeo_dem_oil_res: 'Oil demand projection'!$C$10:$C$84
Name aeo_dem_oil_row: 'Oil demand projection'!$M$10:$M$84
Name aeo_dem_oil_row_2010: 'Oil demand projection'!$H$10:$J$10
Name aeo_dem_oil_row_crude: 'Oil demand projection'!$H$10:$H$84
Name aeo_dem_oil_row_non_us: 'Oil demand projection'!$J$10:$J$84
Name aeo_dem_oil_row_ref: 'Oil demand projection'!$I$10:$I$84
Name aeo_dem_oil_tot: 'Oil demand projection'!$K$10:$K$84
Name aeo_dem_oil_tra: 'Oil demand projection'!$F$10:$F$84
Name aeo_price_2010: Prices!$C$10:$F$10
Name aeo_price_coa: Prices!$E$10:$E$84
Name aeo_price_ele: Prices!$F$10:$F$84
Name aeo_price_gas: Prices!$D$10:$D$84
Name aeo_price_oil: Prices!$C$10:$C$84
Name aeo_prices: Prices!$C$10:$F$84
Name aeo_sup_coa_2010: 'Coal supply projection'!$C$10:$E$10

Sheet Table of Contents
B2: MARKETSIM TABLE OF CONTENTS
B3: Click an underlined heading below to view the associated tab
C5: MODEL RUN INTERFACE
C7: Detailed Results
C9: E&D SCENARIO INPUT: OIL | F9: AEO BASELINE PROJECTIONS
C10: E&D SCENARIO INPUT: GAS | F10: Supply | G10: Demand
C11: BOE Percentage by Planning Area | F11: Oil | G11: Oil
F12: Gas | G12: Gas
C13: SIMULATION QUANTITIES | F13: Electricity | G13: Electricity
C14: Supply | D14: Demand | F14: Coal | G14: Coal
C15: Oil | D15: Oil
C16: Gas | D16: Gas | F16: PARAMETER CALCULATIONS
C17: Electricity | D17: Electricity | F17: Supply | G17: Demand
C18: Coal | D18: Coal
F19: ELASTICITY & ADJUSTMENT
C20: AEO Baseline Prices & MarketSim Simulated Prices | F20: Supply | G20: Demand
F21: Oil | G21: Oil
F22: Gas | G22: Gas
C23: Change in Consumer Surplus | F23: Electricity | G23: Electricity
F24: Coal | G24: Coal
F25: Adjustment Rates
C27: CALCULATIONS FOR ESTIMATION OF OCS EXPORTS | F27: DATA SUPPORTING CALCULATION OF OCS EXPORTS
C28: Calculaton of OCS Crude Oil Exports | F28: API Gravity of U.S. Crude Production and Imports
C29: Calculation of OCS-Derived Refined Product Exports | F29: API Gravity of OCS Crude

Sheet Update Directions
B1: Return to Table of Contents
B3: DIRECTIONS FOR UPDATING
B5: Updates to MarketSim may involve: (1) updates to baseline supply and demand projections, (2) updates to elasticity values or adjustment rates, or (3) updates to the inflation forecast. Baseline Supply and Demand Projections In Item 1 below, the existing baseline data may be cleared from MarketSim. It is recommended that users do this rather than copy over the existing data. In Item 2 the user enters the first year and last year to be reflected in the AEO baseline data to be incorporated into MarketSim. Items 3 through 10 below will direct the user to the specific worksheets where the baseline supply and demand projections may be updated using data from EIA's NEMS model. Where necessary, special instructions are included with each of these items to address potential imbalances between supply and demand in the NEMS forecast. The bottom of each column in each worksheet includes detailed information on the AEO tables and rown numbers where baseline data are avaialble. However, because EIA changes these tables periodically, model users may need re-examine the structure of the EIA data and identify the correct tables/rows where the required baseline data are located.
B6: Energy Price Projections Item 11 below directs users to where they can update the baseline energy price projections. Extrapolation Beyond AEO Data Item 12 below is where model users must prompt MarketSim to extrapolate beyond the baseline NEMS data. Default Elasticity Values and Adjustment Rates Item 13 below provides directions on how to update elasticity values and adjustment rates in the model. Inflation Indices Item 14 below includes directions on how to update the inflation indices in the model.
A7: 1. | B7: CLEAR EXISTING BASELINE DATA IN MODEL
B8: It is recommended that users clear the existing baseline data using the button at right rather than copying over existing baseline data.
A9: 2. | B9: UPDATE FIRST AND LAST YEARS REPRESENTED IN BASELINE SUPPLY AND DEMAND DATA
B10: Enter the first year represented by the baseline data in MarketSim: | D10: 2019
B11: Enter the last year covered by the AEO baseline projection: | D11: 2050 | F11: Projections last updated on 11/2/2023 10:19:47 AM
A13: 3. | B13: UPDATE OIL SUPPLY PROJECTION
B14: Oil Supply | C14: Columns C through G, I, K, and O require updating. All other columns update automatically. Based on past experience, supply and demand in the NEMS oil market data may be imbalanced. To generate a balanced forecast, this worksheet is set up to calculate the difference between total supply and total demand and adjust "Other" domestic supply to force supply and demand to balance.
A16: 4. | B16: UPDATE GAS SUPPLY PROJECTION
B17: Gas Supply | C17: Columns C through J require updating.
A19: 5. | B19: UPDATE ELECTRICITY SUPPLY PROJECTION
B20: Electricity Supply | C20: Columns C through L require updating.
A22: 6. | B22: UPDATE COAL SUPPLY PROJECTION
B23: Coal Supply | C23: Columns C and D require updating.
A25: 7. | B25: UPDATE OIL DEMAND PROJECTION
B26: Oil Demand | C26: Columns C though J require updating. All other columns update automatically.
A28: 8. | B28: UPDATE GAS DEMAND PROJECTION
B29: Gas Demand | C29: Columns C through H require updating.
A31: 9. | B31: UPDATE ELECTRICITY DEMAND PROJECTION
B32: Electricity Demand | C32: Columns L through P require updating. If the note at the top of the worksheet indicates that supply and demand are not in equilibrium, click on the "Equilibrate Electricity" button.
A34: 10. | B34: UPDATE COAL DEMAND PROJECTION
B35: Coal Demand | C35: Columns C through F require updating.
A37: 11. | B37: UPDATE ENERGY PRICE PROJECTIONS
B38: Prices | C38: The baseline price projection in columns C through F require updating.
A40: 12. | B40: EXTRAPOLATE BEYOND AEO DATA
B41: Press the button at right to prompt MarketSim to extrapolate to years after the AEO forecast horizon.
H43: Projections last updated on 2020/08/13 4:53 PM
A45: 13. | B45: UPDATE DEFAULTS (IF UPDATING ELASTICITIES OR ADJUSTMENT RATES)
B46: Defaults | C46: The default values for supply and demand elasticities and adjustment rates are included in this worksheet. As new estimates for these values become available, model users can change the values on this worksheet to make these updated values the model defaults. After entering these new values, users are also encouraged to enter the corresponding source information. Once the new default values and the corresponding source information have been entered, go to any of the following worksheets and press "Restore THIS TAB's default elasticities" OR "Restore ALL default elasticities": Oil demand elasticities, Gas demand elasticities, Electricity demand elasticities, Coal demand elasticities, Oil supply elasticities, Gas supply elasticities, Electricity supply elasticities, Coal supply elasticities.
A50: 14. | B50: UPDATE INFLATION
B51: Inflation | C51: Columns C through E require updating.
C94: =Inflation!$C$7 -> GDP Chain-type Price Index | D94: =Inflation!$D$7 -> CPI All-urban | E94: =Inflation!$E$7 -> CPI Energy Commodities and Services | F94: =Inflation!$F$7 -> User defined

Sheet Model Run Interface
B1: Return to Table of Contents
B3: MODEL RUN INTERFACE
J4: SUMMARY RESULTS
A5: 1. | B5: INPUT E&D SCENARIO
B6: Jump to E&D scenario sheets to input OCS production schedules manually or import OECM scenario automatically. | J6: CHANGE IN PRODUCTION AND CONSUMPTION
K7: Baseline | L7: Simulation | M7: Change In Sector | N7: % Change In Sector
B9: E&D SCENARIO INPUT: OIL | J9: OIL (million barrels)
B10: E&D SCENARIO INPUT: GAS | J10: U.S. Consumption | K10: {=SUM(OFFSET(aeo_dem_oil_tot,begin_year-'OCS Oil SIM'!$B$10,0,length_year)-OFFSET(aeo_dem_oil_row,begin_year-'OCS Oil SIM'!$B$10,0,length_year))*365} -> 135117.83 | L10: {=SUM(OFFSET(sim_dem_oil_tot,begin_year-'OCS Oil SIM'!$B$11,0,length_year)-OFFSET(sim_dem_oil_row,begin_year-'OCS Oil SIM'!$B$11,0,length_year))*365} -> 135124.15 | M10: =L10-K10 -> 6.3206354 | N10: =IFERROR(M10/K10,0) -> 4.6778694e-05
J11: U.S. Production | K11: {=SUM(OFFSET(aeo_sup_oil_tot,begin_year-'OCS Oil SIM'!$B$10,0,length_year)-OFFSET(aeo_sup_oil_row,begin_year-'OCS Oil SIM'!$B$10,0,length_year))*365} -> 150552.41 | L11: {=SUM(OFFSET(sim_sup_oil_tot,begin_year-'OCS Oil SIM'!$B$11,0,length_year)+OFFSET(sim_sup_oil_ocs,begin_year-'OCS Oil SIM'!$B$10,0,length_year)-OFFSET(sim_sup_oil_row,begin_year-'OCS Oil SIM'!$B$11,0,length_year))*365} -> 150621.45 | M11: =L11-K11 -> 69.03709 | N11: =IFERROR(M11/K11,0) -> 0.00045855851
A12: 2. | B12: DEFINE SCENARIO PARAMETERS | J12: Lower 48 onshore, biofuels, other | K12: =K11-K13-K14-K15 -> 136029.54 | L12: =L11-L13-L14-L15 -> 136004.63 | M12: =L12-K12 -> -24.914874 | N12: =IFERROR(M12/K12,0) -> -0.00018315782
B13: Edit the scenario name and calculation parameters. | J13: Lower 48 offshore | K13: {=SUM(OFFSET(aeo_sup_oil_off,begin_year-'OCS Oil SIM'!$B$10,0,length_year))*365} -> 10296.63 | L13: {=SUM(OFFSET(sim_sup_oil_off,begin_year-'OCS Oil SIM'!$B$11,0,length_year)+OFFSET(sim_sup_oil_ocs_atn,begin_year-'OCS Oil SIM'!$B$10,0,length_year)+OFFSET(sim_sup_oil_ocs_atm,begin_year-'OCS Oil SIM'!$B$10,0,length_year)+OFFSET(sim_sup_oil_ocs_ats,begin_year-'OCS Oil SIM'!$B$10,0,length_year)+OFFSET(sim_sup_oil_ocs_atf,begin_year-'OCS Oil SIM'!$B$10,0,length_year)+OFFSET(sim_sup_oil_ocs_gme,begin_year-'OCS Oil SIM'!$B$10,0,length_year)+OFFSET(sim_sup_oil_ocs_gmc,begin_year-'OCS Oil SIM'!$B$10,0,length_year)+OFFSET(sim_sup_oil_ocs_gmw,begin_year-'OCS Oil SIM'!$B$10,0,length_year)+OFFSET(sim_sup_oil_ocs_pas,begin_year-'OCS Oil SIM'!$B$10,0,length_year)+OFFSET(sim_sup_oil_ocs_pac,begin_year-'OCS Oil SIM'!$B$10,0,length_year)+OFFSET(sim_sup_oil_ocs_pan,begin_year-'OCS Oil SIM'!$B$10,0,length_year)+OFFSET(sim_sup_oil_ocs_paw,begin_year-'OCS Oil SIM'!$B$10,0,length_year))*365} -> 10335.237 | M13: =L13-K13 -> 38.60712 | N13: =IFERROR(M13/K13,0) -> 0.0037494907
J14: Alaska onshore | K14: {=SUM(OFFSET(aeo_sup_oil_ala_on,begin_year-'OCS Oil SIM'!$B$10,0,length_year))*365} -> 3416.6201 | L14: {=SUM(OFFSET(sim_sup_oil_ala_on,begin_year-'OCS Oil SIM'!$B$11,0,length_year))*365} -> 3416.1559 | M14: =L14-K14 -> -0.46417095 | N14: =IFERROR(M14/K14,0) -> -0.00013585676
B15: Scenario name: | F15: GenericE&DtemplateCIandGOA | J15: Alaska offshore | K15: {=SUM(OFFSET(aeo_sup_oil_ala_off,begin_year-'OCS Oil SIM'!$B$10,0,length_year))*365} -> 809.61964 | L15: {=365*(SUM(OFFSET(sim_sup_oil_ala_off,begin_year-'OCS Oil SIM'!$B$11,0,length_year)+OFFSET(sim_sup_oil_ocs,begin_year-'OCS Oil SIM'!$B$10,0,length_year))-SUM(OFFSET(sim_sup_oil_ocs_atn,begin_year-'OCS Oil SIM'!$B$10,0,length_year)+OFFSET(sim_sup_oil_ocs_atm,begin_year-'OCS Oil SIM'!$B$10,0,length_year)+OFFSET(sim_sup_oil_ocs_ats,begin_year-'OCS Oil SIM'!$B$10,0,length_year)+OFFSET(sim_sup_oil_ocs_atf,begin_year-'OCS Oil SIM'!$B$10,0,length_year)+OFFSET(sim_sup_oil_ocs_gme,begin_year-'OCS Oil SIM'!$B$10,0,length_year)+OFFSET(sim_sup_oil_ocs_gmc,begin_year-'OCS Oil SIM'!$B$10,0,length_year)+OFFSET(sim_sup_oil_ocs_gmw,begin_year-'OCS Oil SIM'!$B$10,0,length_year)+OFFSET(sim_sup_oil_ocs_pas,begin_year-'OCS Oil SIM'!$B$10,0,length_year)+OFFSET(sim_sup_oil_ocs_pac,begin_year-'OCS Oil SIM'!$B$10,0,length_year)+OFFSET(sim_sup_oil_ocs_pan,begin_year-'OCS Oil SIM'!$B$10,0,length_year)+OFFSET(sim_sup_oil_ocs_paw,begin_year-'OCS Oil SIM'!$B$10,0,length_year)))} -> 865.42866 | M15: =L15-K15 -> 55.809016 | N15: =IFERROR(M15/K15,0) -> 0.068932388
B16: Scenario begin year: | F16: 2026 | J16: Net Imports | K16: =K10-K11 -> -15434.585 | L16: =L10-L11 -> -15497.301 | M16: =L16-K16 -> -62.716455 | N16: =IFERROR(M16/K16,0) -> 0.0040633716
B17: Scenario end year: | F17: {=OFFSET(year_oil,MATCH(2,INDEX(1/(sim_sup_oil_ocs+sim_sup_gas_ocs>0),0))-1,0)} -> 2044 | J17: GAS (trillion cubic feet)
B18: Scenario length (years): | F18: =end_year-begin_year+1 -> 19 | J18: U.S. Consumption | K18: {=SUM(OFFSET(aeo_dem_gas_tot,begin_year-'OCS Oil SIM'!$B$10,0,length_year)-OFFSET(aeo_dem_gas_exp,begin_year-'OCS Oil SIM'!$B$10,0,length_year))} -> 537.92636 | L18: {=SUM(OFFSET(sim_dem_gas_tot,begin_year-'OCS Oil SIM'!$B$11,0,length_year)-OFFSET(sim_dem_gas_exp,begin_year-'OCS Oil SIM'!$B$11,0,length_year))} -> 537.92836 | M18: =L18-K18 -> 0.0019971848 | N18: =IFERROR(M18/K18,0) -> 3.7127475e-06
B19: NPV base year: | F19: 2025 | J19: U.S. Production | K19: {=SUM(OFFSET(aeo_sup_gas_tot,begin_year-'OCS Oil SIM'!$B$10,0,length_year)-OFFSET(aeo_sup_gas_pip,begin_year-'OCS Oil SIM'!$B$10,0,length_year)-OFFSET(aeo_sup_gas_lng,begin_year-'OCS Oil SIM'!$B$10,0,length_year))} -> 735.68529 | L19: {=SUM(OFFSET(sim_sup_gas_tot,begin_year-'OCS Oil SIM'!$B$11,0,length_year)+OFFSET(sim_sup_gas_ocs,begin_year-'OCS Oil SIM'!$B$10,0,length_year)-OFFSET(sim_sup_gas_lng,begin_year-'OCS Oil SIM'!$B$11,0,length_year)-OFFSET(sim_sup_gas_pip,begin_year-'OCS Oil SIM'!$B$11,0,length_year))} -> 735.70769 | M19: =L19-K19 -> 0.022401529 | N19: =IFERROR(M19/K19,0) -> 3.0449881e-05
B20: Discount rate: | F20: 0.03 | J20: Lower 48 onshore and other | K20: =K19-K21-K22-K23 -> 715.51627 | L20: =L19-L21-L22-L23 -> 715.79924 | M20: =L20-K20 -> 0.2829649 | N20: =IFERROR(M20/K20,0) -> 0.00039546955 | P20: =10^12/(F24*10^6) -> 177.93594
B21: Baseline prices in constant dollars of year: | F21: 2019 | J21: Lower 48 offshore | K21: {=SUM(OFFSET(aeo_sup_gas_off,begin_year-'OCS Oil SIM'!$B$10,0,length_year))} -> 13.265218 | L21: {=SUM(OFFSET(sim_sup_gas_off,begin_year-'OCS Oil SIM'!$B$11,0,length_year)+OFFSET(sim_sup_gas_ocs_atn,begin_year-'OCS Oil SIM'!$B$10,0,length_year)+OFFSET(sim_sup_gas_ocs_atm,begin_year-'OCS Oil SIM'!$B$10,0,length_year)+OFFSET(sim_sup_gas_ocs_ats,begin_year-'OCS Oil SIM'!$B$10,0,length_year)+OFFSET(sim_sup_gas_ocs_atf,begin_year-'OCS Oil SIM'!$B$10,0,length_year)+OFFSET(sim_sup_gas_ocs_gme,begin_year-'OCS Oil SIM'!$B$10,0,length_year)+OFFSET(sim_sup_gas_ocs_gmc,begin_year-'OCS Oil SIM'!$B$10,0,length_year)+OFFSET(sim_sup_gas_ocs_gmw,begin_year-'OCS Oil SIM'!$B$10,0,length_year)+OFFSET(sim_sup_gas_ocs_pas,begin_year-'OCS Oil SIM'!$B$10,0,length_year)+OFFSET(sim_sup_gas_ocs_pac,begin_year-'OCS Oil SIM'!$B$10,0,length_year)+OFFSET(sim_sup_gas_ocs_pan,begin_year-'OCS Oil SIM'!$B$10,0,length_year)+OFFSET(sim_sup_gas_ocs_paw,begin_year-'OCS Oil SIM'!$B$10,0,length_year))} -> 13.291027 | M21: =L21-K21 -> 0.025808658 | N21: =IFERROR(M21/K21,0) -> 0.0019455887
B22: Inflation index: | F22: GDP Chain-type Price Index | J22: Alaska onshore | K22: {=SUM(OFFSET(aeo_sup_gas_ala_on,begin_year-'OCS Oil SIM'!$B$10,0,length_year))} -> 6.903796 | L22: {=SUM(OFFSET(sim_sup_gas_ala_on,begin_year-'OCS Oil SIM'!$B$10,0,length_year))} -> 6.561424 | M22: =L22-K22 -> -0.34237203 | N22: =IFERROR(M22/K22,0) -> -0.049591852
B23: Display dollars in constant dollars of year: | F23: 2026 | J23: Alaska offshore | K23: {=SUM(OFFSET(aeo_sup_gas_ala_off,begin_year-'OCS Oil SIM'!$B$10,0,length_year))} -> 0 | L23: {=SUM(OFFSET(sim_sup_gas_ala_off,begin_year-'OCS Oil SIM'!$B$10,0,length_year)+OFFSET(sim_sup_gas_ocs,begin_year-'OCS Oil SIM'!$B$10,0,length_year))-SUM(OFFSET(sim_sup_gas_ocs_atn,begin_year-'OCS Oil SIM'!$B$10,0,length_year)+OFFSET(sim_sup_gas_ocs_atm,begin_year-'OCS Oil SIM'!$B$10,0,length_year)+OFFSET(sim_sup_gas_ocs_ats,begin_year-'OCS Oil SIM'!$B$10,0,length_year)+OFFSET(sim_sup_gas_ocs_atf,begin_year-'OCS Oil SIM'!$B$10,0,length_year)+OFFSET(sim_sup_gas_ocs_gme,begin_year-'OCS Oil SIM'!$B$10,0,length_year)+OFFSET(sim_sup_gas_ocs_gmc,begin_year-'OCS Oil SIM'!$B$10,0,length_year)+OFFSET(sim_sup_gas_ocs_gmw,begin_year-'OCS Oil SIM'!$B$10,0,length_year)+OFFSET(sim_sup_gas_ocs_pas,begin_year-'OCS Oil SIM'!$B$10,0,length_year)+OFFSET(sim_sup_gas_ocs_pac,begin_year-'OCS Oil SIM'!$B$10,0,length_year)+OFFSET(sim_sup_gas_ocs_pan,begin_year-'OCS Oil SIM'!$B$10,0,length_year)+OFFSET(sim_sup_gas_ocs_paw,begin_year-'OCS Oil SIM'!$B$10,0,length_year))} -> 0.056 | M23: =L23-K23 -> 0.056 | N23: =IFERROR(M23/K23,0) -> 0
B24: Natural gas barrel of oil equiv. in cubic ft.: | F24: 5620 | J24: Net Imports | K24: =K18-K19 -> -197.75892 | L24: =L18-L19 -> -197.77933 | M24: =L24-K24 -> -0.020404345 | N24: =IFERROR(M24/K24,0) -> 0.00010317787
J25: COAL (million short tons)
A26: 3. | B26: EQUILIBRATE ELECTRICITY MARKET | J26: U.S. Consumption | K26: {=SUM(OFFSET(aeo_dem_coa_tot,begin_year-'OCS Oil SIM'!$B$10,0,length_year)-OFFSET(aeo_dem_coa_exp,begin_year-'OCS Oil SIM'!$B$10,0,length_year))} -> 4249.6128 | L26: {=SUM(OFFSET(sim_dem_coa_tot,begin_year-'OCS Oil SIM'!$B$11,0,length_year)-OFFSET(sim_dem_coa_exp,begin_year-'OCS Oil SIM'!$B$11,0,length_year))} -> 4249.5704 | M26: =L26-K26 -> -0.042361755 | N26: =M26/K26 -> -9.96838e-06
B27: Confirm that the AEO baseline electricity markets are in equilibrium. Jump to electricity demand tab to solve imbalance. | J27: U.S. Production | K27: {=SUM(OFFSET(aeo_sup_coa_dom,begin_year-'OCS Oil SIM'!$B$10,0,length_year))} -> 6383.5948 | L27: {=SUM(OFFSET(sim_sup_coa_dom,begin_year-'OCS Oil SIM'!$B$11,0,length_year))} -> 6383.5544 | M27: =L27-K27 -> -0.040417348 | N27: =M27/K27 -> -6.3314401e-06
J28: Net Exports | K28: =K27-K26 -> 2133.982 | L28: =L27-L26 -> 2133.984 | M28: =L28-K28 -> 0.0019444065 | N28: =M28/K28 -> 9.1116345e-07
J29: ELECTRICITY (billion kilowatt hours)
B30: Baseline electricity markets are: | F30: =ele_equil -> In equilibrium | J30: U.S. Consumption | K30: {=SUM(OFFSET(aeo_dem_ele_tot,begin_year-'OCS Oil SIM'!$B$10,0,length_year))} -> 80966.071 | L30: {=SUM(OFFSET(sim_dem_ele_tot,begin_year-'OCS Oil SIM'!$B$11,0,length_year))} -> 80964.449 | M30: =L30-K30 -> -1.6213822 | N30: =M30/K30 -> -2.0025452e-05
J31: U.S. Production | K31: {=SUM(OFFSET(aeo_sup_ele_tot,begin_year-'OCS Oil SIM'!$B$10,0,length_year)-OFFSET(aeo_sup_ele_imp,begin_year-'OCS Oil SIM'!$B$10,0,length_year))} -> 80138.681 | L31: {=SUM(OFFSET(sim_sup_ele_tot,begin_year-'OCS Oil SIM'!$B$11,0,length_year)-OFFSET(sim_sup_ele_imp,begin_year-'OCS Oil SIM'!$B$11,0,length_year))} -> 80137.066 | M31: =L31-K31 -> -1.6154003 | N31: =M31/K31 -> -2.015756e-05
B32: AEO BASELINE ELECTRICITY DEMAND | J32: Net Imports | K32: =K30-K31 -> 827.38954 | L32: =L30-L31 -> 827.38356 | M32: =L32-K32 -> -0.0059818741 | N32: =M32/K32 -> -7.229816e-06
J33: * AEO projections do not differentiate offshore and onshore gas production for Alaska.
A34: 4. | B34: RUN MARKET SIMULATION
B35: Once all parameters and scenarios are entered, run market simulation to find fuel prices that clear all markets. | J35: =IF('Detailed Results'!$H$46=2,"PRESENT VALUE CHANGE IN CONSUMER SURPLUS","NOMINAL CHANGE IN CONSUMER SURPLUS") -> PRESENT VALUE CHANGE IN CONSUMER SURPLUS
J36: Fuel | K36: ΔCS ($ million) | L36: OCS Oil & Gas Prod. (MMBOE) | M36: ΔCS per BOE
J38: OIL | K38: {=TRANSPOSE('Detailed Results'!$D$39:$H$39)} -> 216.13041 | L38: {=SUM(OFFSET(sim_sup_oil_ocs,begin_year-'OCS Oil SIM'!$B$10,0,length_year))*365+SUM(OFFSET(sim_sup_gas_ocs,begin_year-'OCS Oil SIM'!$B$10,0,length_year))*gas_boe} -> 109.59075 | M38: =K38/$L$38 -> 1.9721593
J39: GAS | K39: 13.103934 | M39: =K39/$L$38 -> 0.11957154
J40: ELECTRICITY | K40: 5.5325192 | M40: =K40/$L$38 -> 0.050483452
J41: COAL | K41: 0.00068938048 | M41: =K41/$L$38 -> 6.290499e-06
B42: Scenario markets are: | F42: =IF(IF(ISERROR(SUM(OFFSET(scenario_equilibrium,begin_year-'OCS Oil SIM'!$B$10,0,length_year-1))),1,SUM(OFFSET(scenario_equilibrium,begin_year-'OCS Oil SIM'!$B$10,0,length_year-1)))>0.00001,"IMBALANCED!","In equilibrium") -> In equilibrium | J42: TOTAL | K42: 234.76756 | L42: {=SUM(OFFSET(sim_sup_oil_ocs,begin_year-'OCS Oil SIM'!$B$10,0,length_year))*365+SUM(OFFSET(sim_sup_gas_ocs,begin_year-'OCS Oil SIM'!$B$10,0,length_year))*gas_boe} -> 109.59075 | M42: =K42/L42 -> 2.1422206
B46: DETAILED SIMULATION RESULTS
...

Sheet Detailed Results
B1: Return to Table of Contents | E1: Jump to Alaska Offshore Correction and Conversions →
B3: DETAILED SIMULATION RESULTS
B4: =scenario_name -> GenericE&DtemplateCIandGOA
B5: =IF($H$46=1,IF($H$47=1,"Nominal Consumer Surplus Change from OCS Production by Planning Area and Fuel","Nominal Consumer Surplus Change Net of Domestic Producer Transfer from OCS Production by Planning Area and Fuel"),IF($H$47=1,"Net Present Value of Consumer Surplus Change from OCS Production by Planning Area and Fuel ("&TEXT(npv_base_year,0)&" Base Year, "&TEXT(inflator_year,0)&" Constant Dollars)","Net Present Value of Consumer Surplus Change Net of Domestic Producer Transfer from OCS Production by Planning Area and Fuel ("&TEXT(npv_base_year,0)&" Base Year, "&TEXT(inflator_year,0)&" Constant Dollars)")) -> Net Present Value of Consumer Surplus Change Net of Domestic Producer Transfer from OCS Production by Planning Area and Fuel (2025 Base Year, 2026 Constant Dollars)
K7: Production Effects | Q7: Substitution Effects | U7: Petroleum Export Details
B8: OCS Region | D8: Oil | E8: Gas | F8: Electricity | G8: Coal | H8: TOTAL | L8: Baseline | M8: Simulation | N8: Change In Sector | O8: % Change In Sector | R8: Foregone offshore oil production (mmbbl) | S8: =SUM(OFFSET(sim_sup_oil_ocs,begin_year-'OCS Oil SIM'!$B$10,0,length_year))*365 -> 95 | U8: Export Category | V8: Exports (millions of barrels)
R9: Foregone offshore gas (mmBOE) | S9: =SUM(OFFSET(sim_sup_gas_ocs,begin_year-'OCS Oil SIM'!$B$10,0,length_year))*gas_boe -> 14.590747
K10: OIL (millions of barrels) | R10: Total foregone production (mmBOE) | S10: =D41 -> 109.59075 | U10: Change in Crude Oil Exports | V10: =N68 -> 0.67855402 | AA10: Conversion Factors
C11: Planning Area | D11: $ million | E11: $ million | F11: $ million | G11: $ million | H11: $ million | K11: U.S. Production | L11: =SUM(L12,L16,L19:L20) -> 150552.41 | M11: =SUM(M12,M16,M19:M20) -> 150621.45 | N11: =M11-L11 -> 69.03709 | O11: =IFERROR(N11/L11,0) -> 0.00045855851 | U11: OCS Oil (low and high estimates, respectively) | V11: =IF(ocs_crude_export_low*365>V10,V10,ocs_crude_export_low*365) -> 0.67855402 | W11: =IF(ocs_crude_export_high*365>V10,V10,ocs_crude_export_high*365) -> 0.67855402 | AA11: Coal
B12: ATL | C12: North Atlantic | D12: {=SUM(OFFSET(sim_sup_per_ocs_atn,begin_year-'OCS Oil SIM'!$B$10,0)*IF(ISERROR(D$61:D$135),0,D$61:D$135))+sim_sup_tot_ocs_atn*D$38} -> 0 | E12: {=SUM(OFFSET(sim_sup_per_ocs_atn,begin_year-'OCS Oil SIM'!$B$10,0)*IF(ISERROR(E$61:E$135),0,E$61:E$135))+sim_sup_tot_ocs_atn*E$38} -> 0 | F12: {=SUM(OFFSET(sim_sup_per_ocs_atn,begin_year-'OCS Oil SIM'!$B$10,0)*IF(ISERROR(F$61:F$135),0,F$61:F$135))+sim_sup_tot_ocs_atn*F$38} -> 0 | G12: {=SUM(OFFSET(sim_sup_per_ocs_atn,begin_year-'OCS Oil SIM'!$B$10,0)*IF(ISERROR(G$61:G$135),0,G$61:G$135))+sim_sup_tot_ocs_atn*G$38} -> 0 | H12: =SUM(D12:G12) -> 0 | K12: U.S. Onshore | L12: =SUM(L13:L15) -> 77530.688 | M12: =SUM(M13:M15) -> 77515.151 | N12: =M12-L12 -> -15.537561 | O12: =IFERROR(N12/L12,0) -> -0.0002004053 | R12: Change in Sector (mmBOE) | S12: Change as % of Foregone | U12: Non-OCS Oil (high and low estimates, respectively) | V12: =V10-V11 -> 0 | W12: =V10-W11 -> 0 | AA12: Calculation | AC12: Conversion Factor | AD12: Source
C13: Mid-Atlantic | D13: {=SUM(OFFSET(sim_sup_per_ocs_atm,begin_year-'OCS Oil SIM'!$B$10,0)*IF(ISERROR(D$61:D$135),0,D$61:D$135))+sim_sup_tot_ocs_atm*D$38} -> 0 | E13: {=SUM(OFFSET(sim_sup_per_ocs_atm,begin_year-'OCS Oil SIM'!$B$10,0)*IF(ISERROR(E$61:E$135),0,E$61:E$135))+sim_sup_tot_ocs_atm*E$38} -> 0 | F13: {=SUM(OFFSET(sim_sup_per_ocs_atm,begin_year-'OCS Oil SIM'!$B$10,0)*IF(ISERROR(F$61:F$135),0,F$61:F$135))+sim_sup_tot_ocs_atm*F$38} -> 0 | G13: {=SUM(OFFSET(sim_sup_per_ocs_atm,begin_year-'OCS Oil SIM'!$B$10,0)*IF(ISERROR(G$61:G$135),0,G$61:G$135))+sim_sup_tot_ocs_atm*G$38} -> 0 | H13: =SUM(D13:G13) -> 0 | K13: Lower 48 Onshore (Tight) | L13: =SUM(OFFSET(aeo_sup_oil_l48_t,begin_year-'OCS Oil SIM'!$B$10,0,length_year))*365 -> 63599.445 | M13: =SUM(OFFSET(sim_sup_oil_l48_t,begin_year-'OCS Oil SIM'!$B$11,0,length_year))*365 -> 63587.08 | N13: =M13-L13 -> -12.365298 | O13: =IFERROR(N13/L13,0) -> -0.00019442462 | AA13: Convert Million Tons to Tons | AB13: * | AC13: 1000000 | AD13: http://www.eia.gov/forecasts/aeo/er/early_production.cfm
C14: South Atlantic | D14: {=SUM(OFFSET(sim_sup_per_ocs_ats,begin_year-'OCS Oil SIM'!$B$10,0)*IF(ISERROR(D$61:D$135),0,D$61:D$135))+sim_sup_tot_ocs_ats*D$38} -> 0 | E14: {=SUM(OFFSET(sim_sup_per_ocs_ats,begin_year-'OCS Oil SIM'!$B$10,0)*IF(ISERROR(E$61:E$135),0,E$61:E$135))+sim_sup_tot_ocs_ats*E$38} -> 0 | F14: {=SUM(OFFSET(sim_sup_per_ocs_ats,begin_year-'OCS Oil SIM'!$B$10,0)*IF(ISERROR(F$61:F$135),0,F$61:F$135))+sim_sup_tot_ocs_ats*F$38} -> 0 | G14: {=SUM(OFFSET(sim_sup_per_ocs_ats,begin_year-'OCS Oil SIM'!$B$10,0)*IF(ISERROR(G$61:G$135),0,G$61:G$135))+sim_sup_tot_ocs_ats*G$38} -> 0 | H14: =SUM(D14:G14) -> 0 | K14: Lower 48 Onshore (Conventional) | L14: =SUM(OFFSET(aeo_sup_oil_l48,begin_year-'OCS Oil SIM'!$B$10,0,length_year))*365 -> 10514.623 | M14: =SUM(OFFSET(sim_sup_oil_l48,begin_year-'OCS Oil SIM'!$B$11,0,length_year))*365 -> 10511.915 | N14: =M14-L14 -> -2.7080921 | O14: =IFERROR(N14/L14,0) -> -0.00025755485
C15: Straits of Florida | D15: {=SUM(OFFSET(sim_sup_per_ocs_atf,begin_year-'OCS Oil SIM'!$B$10,0)*IF(ISERROR(D$61:D$135),0,D$61:D$135))+sim_sup_tot_ocs_atf*D$38} -> 0 | E15: {=SUM(OFFSET(sim_sup_per_ocs_atf,begin_year-'OCS Oil SIM'!$B$10,0)*IF(ISERROR(E$61:E$135),0,E$61:E$135))+sim_sup_tot_ocs_atf*E$38} -> 0 | F15: {=SUM(OFFSET(sim_sup_per_ocs_atf,begin_year-'OCS Oil SIM'!$B$10,0)*IF(ISERROR(F$61:F$135),0,F$61:F$135))+sim_sup_tot_ocs_atf*F$38} -> 0 | G15: {=SUM(OFFSET(sim_sup_per_ocs_atf,begin_year-'OCS Oil SIM'!$B$10,0)*IF(ISERROR(G$61:G$135),0,G$61:G$135))+sim_sup_tot_ocs_atf*G$38} -> 0 | H15: =SUM(D15:G15) -> 0 | K15: Alaska Onshore | L15: {=SUM(OFFSET(aeo_sup_oil_ala_on,begin_year-'OCS Oil SIM'!$B$10,0,length_year))*365} -> 3416.6201 | M15: {=SUM(OFFSET(sim_sup_oil_ala_on,begin_year-'OCS Oil SIM'!$B$11,0,length_year))*365} -> 3416.1559 | N15: =M15-L15 -> -0.46417095 | O15: =IFERROR(N15/L15,0) -> -0.00013585676 | Q15: ONSHORE PRODUCTION | R15: =SUM(R16:R17) -> 26.09813 | S15: =T15/$T$44 -> 0.23852108 | T15: =R15/$S$10 -> 0.23814173 | U15: Change in Refined Product Exports | V15: =N69 -> 1.8576055 | AA15: Convert Short Tons to BTU | AB15: * | AC15: 20387454 | AD15: Whitney, G. , C.E. Behrens, and C. Glover, “U.S. Fossil Fuel Resources: Terminology, Reporting, and Summary,” CRS Report for Congress, R40872, Table 5 (Washington, DC: Congressional Research Service, Library of Congress, 30 October 2009), 17.
B16: GoM | C16: Eastern Gulf | D16: {=SUM(OFFSET(sim_sup_per_ocs_gme,begin_year-'OCS Oil SIM'!$B$10,0)*IF(ISERROR(D$61:D$135),0,D$61:D$135))+sim_sup_tot_ocs_gme*D$38} -> 0 | E16: {=SUM(OFFSET(sim_sup_per_ocs_gme,begin_year-'OCS Oil SIM'!$B$10,0)*IF(ISERROR(E$61:E$135),0,E$61:E$135))+sim_sup_tot_ocs_gme*E$38} -> 0 | F16: {=SUM(OFFSET(sim_sup_per_ocs_gme,begin_year-'OCS Oil SIM'!$B$10,0)*IF(ISERROR(F$61:F$135),0,F$61:F$135))+sim_sup_tot_ocs_gme*F$38} -> 0 | G16: {=SUM(OFFSET(sim_sup_per_ocs_gme,begin_year-'OCS Oil SIM'!$B$10,0)*IF(ISERROR(G$61:G$135),0,G$61:G$135))+sim_sup_tot_ocs_gme*G$38} -> 0 | H16: =SUM(D16:G16) -> 0 | K16: U.S. Offshore | L16: =SUM(L17:L18) -> 11106.25 | M16: =SUM(M17:M18) -> 11200.666 | N16: =M16-L16 -> 94.416135 | O16: =IFERROR(N16/L16,0) -> 0.0085011715 | Q16: Oil | R16: =-N12 -> 15.537561 | S16: =T16/$T$44 -> 0.14200388 | T16: =R16/$S$10 -> 0.14177804 | U16: Derived from OCS Oil | V16: =V15*ocs_feedstock_percent -> 0.28416882 | AA16: Convert BTU to BOE | AB16: / | AC16: 5800000
C17: Central Gulf | D17: {=SUM(OFFSET(sim_sup_per_ocs_gmc,begin_year-'OCS Oil SIM'!$B$10,0)*IF(ISERROR(D$61:D$135),0,D$61:D$135))+sim_sup_tot_ocs_gmc*D$38} -> 77.021782 | E17: {=SUM(OFFSET(sim_sup_per_ocs_gmc,begin_year-'OCS Oil SIM'!$B$10,0)*IF(ISERROR(E$61:E$135),0,E$61:E$135))+sim_sup_tot_ocs_gmc*E$38} -> 4.877229 | F17: {=SUM(OFFSET(sim_sup_per_ocs_gmc,begin_year-'OCS Oil SIM'!$B$10,0)*IF(ISERROR(F$61:F$135),0,F$61:F$135))+sim_sup_tot_ocs_gmc*F$38} -> 1.9656055 | G17: {=SUM(OFFSET(sim_sup_per_ocs_gmc,begin_year-'OCS Oil SIM'!$B$10,0)*IF(ISERROR(G$61:G$135),0,G$61:G$135))+sim_sup_tot_ocs_gmc*G$38} -> 0.0002917405 | H17: =SUM(D17:G17) -> 83.864908 | K17: Lower 48 Offshore | L17: {=SUM(OFFSET(aeo_sup_oil_off,begin_year-'OCS Oil SIM'!$B$10,0,length_year))*365} -> 10296.63 | M17: {=SUM(OFFSET(sim_sup_oil_off,begin_year-'OCS Oil SIM'!$B$11,0,length_year)+OFFSET(sim_sup_oil_ocs_atn,begin_year-'OCS Oil SIM'!$B$10,0,length_year)+OFFSET(sim_sup_oil_ocs_atm,begin_year-'OCS Oil SIM'!$B$10,0,length_year)+OFFSET(sim_sup_oil_ocs_ats,begin_year-'OCS Oil SIM'!$B$10,0,length_year)+OFFSET(sim_sup_oil_ocs_atf,begin_year-'OCS Oil SIM'!$B$10,0,length_year)+OFFSET(sim_sup_oil_ocs_gme,begin_year-'OCS Oil SIM'!$B$10,0,length_year)+OFFSET(sim_sup_oil_ocs_gmc,begin_year-'OCS Oil SIM'!$B$10,0,length_year)+OFFSET(sim_sup_oil_ocs_gmw,begin_year-'OCS Oil SIM'!$B$10,0,length_year)+OFFSET(sim_sup_oil_ocs_pas,begin_year-'OCS Oil SIM'!$B$10,0,length_year)+OFFSET(sim_sup_oil_ocs_pac,begin_year-'OCS Oil SIM'!$B$10,0,length_year)+OFFSET(sim_sup_oil_ocs_pan,begin_year-'OCS Oil SIM'!$B$10,0,length_year)+OFFSET(sim_sup_oil_ocs_paw,begin_year-'OCS Oil SIM'!$B$10,0,length_year))*365} -> 10335.237 | N17: =M17-L17 -> 38.60712 | O17: =IFERROR(N17/L17,0) -> 0.0037494907 | Q17: Natural Gas | R17: =-N26*gas_boe -> 10.560569 | S17: =T17/$T$44 -> 0.096517196 | T17: =R17/$S$10 -> 0.096363695 | U17: Derived from Non-OCS Oil | V17: =V15-V16 -> 1.5734367 | AA17: Convert BOE to million BOE | AB17: / | AC17: 1000000
C18: Western Gulf | D18: {=SUM(OFFSET(sim_sup_per_ocs_gmw,begin_year-'OCS Oil SIM'!$B$10,0)*IF(ISERROR(D$61:D$135),0,D$61:D$135))+sim_sup_tot_ocs_gmw*D$38} -> 0 | E18: {=SUM(OFFSET(sim_sup_per_ocs_gmw,begin_year-'OCS Oil SIM'!$B$10,0)*IF(ISERROR(E$61:E$135),0,E$61:E$135))+sim_sup_tot_ocs_gmw*E$38} -> 0 | F18: {=SUM(OFFSET(sim_sup_per_ocs_gmw,begin_year-'OCS Oil SIM'!$B$10,0)*IF(ISERROR(F$61:F$135),0,F$61:F$135))+sim_sup_tot_ocs_gmw*F$38} -> 0 | G18: {=SUM(OFFSET(sim_sup_per_ocs_gmw,begin_year-'OCS Oil SIM'!$B$10,0)*IF(ISERROR(G$61:G$135),0,G$61:G$135))+sim_sup_tot_ocs_gmw*G$38} -> 0 | H18: =SUM(D18:G18) -> 0 | K18: Alaska Offshore | L18: {=SUM(OFFSET(aeo_sup_oil_ala_off,begin_year-'OCS Oil SIM'!$B$10,0,length_year))*365} -> 809.61964 | M18: {=365*(SUM(OFFSET(sim_sup_oil_ala_off,begin_year-'OCS Oil SIM'!$B$11,0,length_year)))+365*SUM(OFFSET(sim_sup_oil_ocs,begin_year-'OCS Oil SIM'!$B$10,0,length_year))-365*SUM(OFFSET(sim_sup_oil_ocs_atn,begin_year-'OCS Oil SIM'!$B$10,0,length_year),OFFSET(sim_sup_oil_ocs_atm,begin_year-'OCS Oil SIM'!$B$10,0,length_year),OFFSET(sim_sup_oil_ocs_ats,begin_year-'OCS Oil SIM'!$B$10,0,length_year),OFFSET(sim_sup_oil_ocs_atf,begin_year-'OCS Oil SIM'!$B$10,0,length_year),OFFSET(sim_sup_oil_ocs_gme,begin_year-'OCS Oil SIM'!$B$10,0,length_year),OFFSET(sim_sup_oil_ocs_gmc,begin_year-'OCS Oil SIM'!$B$10,0,length_year),OFFSET(sim_sup_oil_ocs_gmw,begin_year-'OCS Oil SIM'!$B$10,0,length_year),OFFSET(sim_sup_oil_ocs_pas,begin_year-'OCS Oil SIM'!$B$10,0,length_year),OFFSET(sim_sup_oil_ocs_pac,begin_year-'OCS Oil SIM'!$B$10,0,length_year),OFFSET(sim_sup_oil_ocs_pan,begin_year-'OCS Oil SIM'!$B$10,0,length_year),OFFSET(sim_sup_oil_ocs_paw,begin_year-'OCS Oil SIM'!$B$10,0,length_year))} -> 865.42866 | N18: =M18-L18 -> 55.809016 | O18: =IFERROR(N18/L18,0) -> 0.068932388 | Q18: EXISTING OFFSHORE PRODUCTION | R18: =SUM(R19:R20) -> 0.61791141 | S18: =T18/$T$44 -> 0.0056473354 | T18: =R18/$S$10 -> 0.0056383538 | AA18: Coal Conversion Factor | AC18: =AC13*AC15/AC16/AC17 -> 3.5150783 | AD18: Million BOE / Million Metric Tons
B19: PAC | C19: Southern California | D19: {=SUM(OFFSET(sim_sup_per_ocs_pas,begin_year-'OCS Oil SIM'!$B$10,0)*IF(ISERROR(D$61:D$135),0,D$61:D$135))+sim_sup_tot_ocs_pas*D$38} -> 0 | E19: {=SUM(OFFSET(sim_sup_per_ocs_pas,begin_year-'OCS Oil SIM'!$B$10,0)*IF(ISERROR(E$61:E$135),0,E$61:E$135))+sim_sup_tot_ocs_pas*E$38} -> 0 | F19: {=SUM(OFFSET(sim_sup_per_ocs_pas,begin_year-'OCS Oil SIM'!$B$10,0)*IF(ISERROR(F$61:F$135),0,F$61:F$135))+sim_sup_tot_ocs_pas*F$38} -> 0 | G19: {=SUM(OFFSET(sim_sup_per_ocs_pas,begin_year-'OCS Oil SIM'!$B$10,0)*IF(ISERROR(G$61:G$135),0,G$61:G$135))+sim_sup_tot_ocs_pas*G$38} -> 0 | H19: =SUM(D19:G19) -> 0 | K19: Biofuels | L19: {=SUM(OFFSET(aeo_sup_oil_bio,begin_year-'OCS Oil SIM'!$B$10,0,length_year))*365} -> 7623.3568 | M19: {=SUM(OFFSET(sim_sup_oil_bio,begin_year-'OCS Oil SIM'!$B$11,0,length_year))*365} -> 7622.8796 | N19: =M19-L19 -> -0.47715398 | O19: =IFERROR(N19/L19,0) -> -6.259106e-05 | Q19: Oil | R19: =S8-N16 -> 0.58386474 | S19: =T19/$T$44 -> 0.0053361695 | T19: =R19/$S$10 -> 0.0053276828
C20: Central California | D20: {=SUM(OFFSET(sim_sup_per_ocs_pac,begin_year-'OCS Oil SIM'!$B$10,0)*IF(ISERROR(D$61:D$135),0,D$61:D$135))+sim_sup_tot_ocs_pac*D$38} -> 0 | E20: {=SUM(OFFSET(sim_sup_per_ocs_pac,begin_year-'OCS Oil SIM'!$B$10,0)*IF(ISERROR(E$61:E$135),0,E$61:E$135))+sim_sup_tot_ocs_pac*E$38} -> 0 | F20: {=SUM(OFFSET(sim_sup_per_ocs_pac,begin_year-'OCS Oil SIM'!$B$10,0)*IF(ISERROR(F$61:F$135),0,F$61:F$135))+sim_sup_tot_ocs_pac*F$38} -> 0 | G20: {=SUM(OFFSET(sim_sup_per_ocs_pac,begin_year-'OCS Oil SIM'!$B$10,0)*IF(ISERROR(G$61:G$135),0,G$61:G$135))+sim_sup_tot_ocs_pac*G$38} -> 0 | H20: =SUM(D20:G20) -> 0 | K20: Other | L20: {=SUM(OFFSET(aeo_sup_oil_oth,begin_year-'OCS Oil SIM'!$B$10,0,length_year))*365} -> 54292.117 | M20: {=SUM(OFFSET(sim_sup_oil_oth,begin_year-'OCS Oil SIM'!$B$11,0,length_year))*365} -> 54282.753 | N20: =M20-L20 -> -9.3643302 | O20: =IFERROR(N20/L20,0) -> -0.00017248048 | Q20: Natural Gas | R20: =S9-N31*gas_boe -> 0.034046668 | S20: =T20/$T$44 -> 0.00031116589 | T20: =R20/$S$10 -> 0.00031067101 | AA20: Electricity
C21: Northern California | D21: {=SUM(OFFSET(sim_sup_per_ocs_pan,begin_year-'OCS Oil SIM'!$B$10,0)*IF(ISERROR(D$61:D$135),0,D$61:D$135))+sim_sup_tot_ocs_pan*D$38} -> 0 | E21: {=SUM(OFFSET(sim_sup_per_ocs_pan,begin_year-'OCS Oil SIM'!$B$10,0)*IF(ISERROR(E$61:E$135),0,E$61:E$135))+sim_sup_tot_ocs_pan*E$38} -> 0 | F21: {=SUM(OFFSET(sim_sup_per_ocs_pan,begin_year-'OCS Oil SIM'!$B$10,0)*IF(ISERROR(F$61:F$135),0,F$61:F$135))+sim_sup_tot_ocs_pan*F$38} -> 0 | G21: {=SUM(OFFSET(sim_sup_per_ocs_pan,begin_year-'OCS Oil SIM'!$B$10,0)*IF(ISERROR(G$61:G$135),0,G$61:G$135))+sim_sup_tot_ocs_pan*G$38} -> 0 | H21: =SUM(D21:G21) -> 0 | K21: Rest of World | L21: {=SUM(OFFSET(aeo_sup_oil_row,begin_year-'OCS Oil SIM'!$B$10,0,length_year))*365} -> 593183.28 | M21: {=SUM(OFFSET(sim_sup_oil_row,begin_year-'OCS Oil SIM'!$B$11,0,length_year))*365} -> 593139.25 | N21: =M21-L21 -> -44.036919 | O21: =IFERROR(N21/L21,0) -> -7.4238301e-05 | Q21: IMPORTS | R21: =SUM(R22:R23) -> 63.514606 | S21: =T21/$T$44 -> 0.58048496 | T21: =R21/$S$10 -> 0.57956176 | AA21: Calculation | AC21: Conversion Factor | AD21: Source
C22: Washington/Oregon | D22: {=SUM(OFFSET(sim_sup_per_ocs_paw,begin_year-'OCS Oil SIM'!$B$10,0)*IF(ISERROR(D$61:D$135),0,D$61:D$135))+sim_sup_tot_ocs_paw*D$38} -> 0 | E22: {=SUM(OFFSET(sim_sup_per_ocs_paw,begin_year-'OCS Oil SIM'!$B$10,0)*IF(ISERROR(E$61:E$135),0,E$61:E$135))+sim_sup_tot_ocs_paw*E$38} -> 0 | F22: {=SUM(OFFSET(sim_sup_per_ocs_paw,begin_year-'OCS Oil SIM'!$B$10,0)*IF(ISERROR(F$61:F$135),0,F$61:F$135))+sim_sup_tot_ocs_paw*F$38} -> 0 | G22: {=SUM(OFFSET(sim_sup_per_ocs_paw,begin_year-'OCS Oil SIM'!$B$10,0)*IF(ISERROR(G$61:G$135),0,G$61:G$135))+sim_sup_tot_ocs_paw*G$38} -> 0 | H22: =SUM(D22:G22) -> 0 | K22: Net Imports | L22: {=SUM(OFFSET(aeo_dem_oil_tot,begin_year-'OCS Oil SIM'!$B$10,0,length_year)-OFFSET(aeo_dem_oil_row,begin_year-'OCS Oil SIM'!$B$10,0,length_year))*365-L11} -> -15434.585 | M22: {=SUM(OFFSET(sim_dem_oil_tot,begin_year-'OCS Oil SIM'!$B$11,0,length_year)-OFFSET(sim_dem_oil_row,begin_year-'OCS Oil SIM'!$B$11,0,length_year))*365-M11} -> -15497.301 | N22: =M22-L22 -> -62.716455 | O22: =IFERROR(N22/L22,0) -> 0.0040633716 | Q22: Oil | R22: =-N22 -> 62.716455 | S22: =T22/$T$44 -> 0.57319034 | T22: =R22/$S$10 -> 0.57227874 | AA22: Convert billion kWh to single units | AB22: * | AC22: 1000000000 | AD22: www.extension.iastate.edu/agdm/wholefarm/pdf/c6-86.pdf
B23: A L A S K A | C23: Gulf of Alaska | D23: {=SUM(OFFSET(sim_sup_per_ocs_goa,begin_year-'OCS Oil SIM'!$B$10,0)*IF(ISERROR(D$61:D$135),0,D$61:D$135))+sim_sup_tot_ocs_goa*D$38} -> 85.038198 | E23: {=SUM(OFFSET(sim_sup_per_ocs_goa,begin_year-'OCS Oil SIM'!$B$10,0)*IF(ISERROR(E$61:E$135),0,E$61:E$135))+sim_sup_tot_ocs_goa*E$38} -> 4.8028181 | F23: {=SUM(OFFSET(sim_sup_per_ocs_goa,begin_year-'OCS Oil SIM'!$B$10,0)*IF(ISERROR(F$61:F$135),0,F$61:F$135))+sim_sup_tot_ocs_goa*F$38} -> 2.1870294 | G23: {=SUM(OFFSET(sim_sup_per_ocs_goa,begin_year-'OCS Oil SIM'!$B$10,0)*IF(ISERROR(G$61:G$135),0,G$61:G$135))+sim_sup_tot_ocs_goa*G$38} -> 0.00019283382 | H23: =SUM(D23:G23) -> 92.028238 | K23: Alaska Total (reflected in categories above) | L23: =L15+L18 -> 4226.2397 | M23: =M15+M18 -> 4281.5846 | N23: =M23-L23 -> 55.344845 | O23: =IFERROR(N23/L23,0) -> 0.013095529 | Q23: Natural Gas | R23: =-N35*gas_boe -> 0.79815181 | S23: =T23/$T$44 -> 0.0072946233 | T23: =R23/$S$10 -> 0.0072830219 | AA23: Convert kilowatt hour to BTU | AB23: * | AC23: 3412 | AD23: Whitney, G. , C.E. Behrens, and C. Glover, “U.S. Fossil Fuel Resources: Terminology, Reporting, and Summary,” CRS Report for Congress, R40872, Table 5 (Washington, DC: Congressional Research Service, Library of Congress, 30 October 2009), 17.
C24: Cook Inlet | D24: {=SUM(OFFSET(sim_sup_per_ocs_coo,begin_year-'OCS Oil SIM'!$B$10,0)*IF(ISERROR(D$61:D$135),0,D$61:D$135))+sim_sup_tot_ocs_coo*D$38} -> 54.070435 | E24: {=SUM(OFFSET(sim_sup_per_ocs_coo,begin_year-'OCS Oil SIM'!$B$10,0)*IF(ISERROR(E$61:E$135),0,E$61:E$135))+sim_sup_tot_ocs_coo*E$38} -> 3.4238872 | F24: {=SUM(OFFSET(sim_sup_per_ocs_coo,begin_year-'OCS Oil SIM'!$B$10,0)*IF(ISERROR(F$61:F$135),0,F$61:F$135))+sim_sup_tot_ocs_coo*F$38} -> 1.3798843 | G24: {=SUM(OFFSET(sim_sup_per_ocs_coo,begin_year-'OCS Oil SIM'!$B$10,0)*IF(ISERROR(G$61:G$135),0,G$61:G$135))+sim_sup_tot_ocs_coo*G$38} -> 0.00020480616 | H24: =SUM(D24:G24) -> 58.874411 | K24: GAS (trillion cubic feet) | Q24: OTHER | R24: =SUM(R25:R27) -> 9.8515783 | S24: =T24/$T$44 -> 0.090037448 | T24: =R24/$S$10 -> 0.089894252 | AA24: Convert BTU to BOE | AB24: / | AC24: 5800000
C25: Kodiak | D25: {=SUM(OFFSET(sim_sup_per_ocs_kod,begin_year-'OCS Oil SIM'!$B$10,0)*IF(ISERROR(D$61:D$135),0,D$61:D$135))+sim_sup_tot_ocs_kod*D$38} -> 0 | E25: {=SUM(OFFSET(sim_sup_per_ocs_kod,begin_year-'OCS Oil SIM'!$B$10,0)*IF(ISERROR(E$61:E$135),0,E$61:E$135))+sim_sup_tot_ocs_kod*E$38} -> 0 | F25: {=SUM(OFFSET(sim_sup_per_ocs_kod,begin_year-'OCS Oil SIM'!$B$10,0)*IF(ISERROR(F$61:F$135),0,F$61:F$135))+sim_sup_tot_ocs_kod*F$38} -> 0 | G25: {=SUM(OFFSET(sim_sup_per_ocs_kod,begin_year-'OCS Oil SIM'!$B$10,0)*IF(ISERROR(G$61:G$135),0,G$61:G$135))+sim_sup_tot_ocs_kod*G$38} -> 0 | H25: =SUM(D25:G25) -> 0 | K25: U.S. Production | L25: =SUM(L26,L31,L34) -> 735.68529 | M25: =SUM(M26,M31,M34) -> 735.70769 | N25: =M25-L25 -> 0.022401529 | O25: =IFERROR(N25/L25,0) -> 3.0449881e-05 | Q25: Biofuels | R25: =-N19 -> 0.47715398 | S25: =T25/$T$44 -> 0.0043608979 | T25: =R25/$S$10 -> 0.0043539623 | AA25: Convert BOE to million BOE | AB25: / | AC25: 1000000
C26: Shumagin | D26: {=SUM(OFFSET(sim_sup_per_ocs_shu,begin_year-'OCS Oil SIM'!$B$10,0)*IF(ISERROR(D$61:D$135),0,D$61:D$135))+sim_sup_tot_ocs_shu*D$38} -> 0 | E26: {=SUM(OFFSET(sim_sup_per_ocs_shu,begin_year-'OCS Oil SIM'!$B$10,0)*IF(ISERROR(E$61:E$135),0,E$61:E$135))+sim_sup_tot_ocs_shu*E$38} -> 0 | F26: {=SUM(OFFSET(sim_sup_per_ocs_shu,begin_year-'OCS Oil SIM'!$B$10,0)*IF(ISERROR(F$61:F$135),0,F$61:F$135))+sim_sup_tot_ocs_shu*F$38} -> 0 | G26: {=SUM(OFFSET(sim_sup_per_ocs_shu,begin_year-'OCS Oil SIM'!$B$10,0)*IF(ISERROR(G$61:G$135),0,G$61:G$135))+sim_sup_tot_ocs_shu*G$38} -> 0 | H26: =SUM(D26:G26) -> 0 | K26: U.S. Onshore | L26: =SUM(L27,L30) -> 721.22188 | M26: =SUM(M27,M30) -> 721.16253 | N26: =M26-L26 -> -0.0593504 | O26: =IFERROR(N26/L26,0) -> -8.2291457e-05 | Q26: Other Oil | R26: =-N20 -> 9.3643302 | S26: =T26/$T$44 -> 0.085584296 | T26: =R26/$S$10 -> 0.085448183 | AA26: Electricity Conversion Factor | AC26: =AC22*AC23/AC24/AC25 -> 0.58827586 | AD26: Million BOE / Billion kWh
C27: North Aleutian Basin | D27: {=SUM(OFFSET(sim_sup_per_ocs_nab,begin_year-'OCS Oil SIM'!$B$10,0)*IF(ISERROR(D$61:D$135),0,D$61:D$135))+sim_sup_tot_ocs_nab*D$38} -> 0 | E27: {=SUM(OFFSET(sim_sup_per_ocs_nab,begin_year-'OCS Oil SIM'!$B$10,0)*IF(ISERROR(E$61:E$135),0,E$61:E$135))+sim_sup_tot_ocs_nab*E$38} -> 0 | F27: {=SUM(OFFSET(sim_sup_per_ocs_nab,begin_year-'OCS Oil SIM'!$B$10,0)*IF(ISERROR(F$61:F$135),0,F$61:F$135))+sim_sup_tot_ocs_nab*F$38} -> 0 | G27: {=SUM(OFFSET(sim_sup_per_ocs_nab,begin_year-'OCS Oil SIM'!$B$10,0)*IF(ISERROR(G$61:G$135),0,G$61:G$135))+sim_sup_tot_ocs_nab*G$38} -> 0 | H27: =SUM(D27:G27) -> 0 | K27: Lower 48 Onshore | L27: =SUM(L28:L29) -> 714.31808 | M27: =SUM(M28:M29) -> 714.26004 | N27: =M27-L27 -> -0.05804937 | O27: =IFERROR(N27/L27,0) -> -8.1265436e-05 | Q27: Other Natural Gas | R27: =-N34*gas_boe -> 0.010094077 | S27: =T27/$T$44 -> 9.225374e-05 | T27: =R27/$S$10 -> 9.2107019e-05
C28: Aleutian Arc | D28: {=SUM(OFFSET(sim_sup_per_ocs_ala,begin_year-'OCS Oil SIM'!$B$10,0)*IF(ISERROR(D$61:D$135),0,D$61:D$135))+sim_sup_tot_ocs_ala*D$38} -> 0 | E28: {=SUM(OFFSET(sim_sup_per_ocs_ala,begin_year-'OCS Oil SIM'!$B$10,0)*IF(ISERROR(E$61:E$135),0,E$61:E$135))+sim_sup_tot_ocs_ala*E$38} -> 0 | F28: {=SUM(OFFSET(sim_sup_per_ocs_ala,begin_year-'OCS Oil SIM'!$B$10,0)*IF(ISERROR(F$61:F$135),0,F$61:F$135))+sim_sup_tot_ocs_ala*F$38} -> 0 | G28: {=SUM(OFFSET(sim_sup_per_ocs_ala,begin_year-'OCS Oil SIM'!$B$10,0)*IF(ISERROR(G$61:G$135),0,G$61:G$135))+sim_sup_tot_ocs_ala*G$38} -> 0 | H28: =SUM(D28:G28) -> 0 | K28: Conventional | L28: {=SUM(OFFSET(aeo_sup_gas_con,begin_year-'OCS Oil SIM'!$B$10,0,length_year))} -> 29.170369 | M28: {=SUM(OFFSET(sim_sup_gas_con,begin_year-'OCS Oil SIM'!$B$11,0,length_year))} -> 29.168648 | N28: =M28-L28 -> -0.0017209422 | O28: =IFERROR(N28/L28,0) -> -5.8996243e-05 | Q28: COAL | R28: =SUM(R29:R30) -> 0.14221814 | S28: =T28/$T$44 -> 0.0012997875 | T28: =R28/$S$10 -> 0.0012977203
C29: St. George Basin | D29: {=SUM(OFFSET(sim_sup_per_ocs_sgb,begin_year-'OCS Oil SIM'!$B$10,0)*IF(ISERROR(D$61:D$135),0,D$61:D$135))+sim_sup_tot_ocs_sgb*D$38} -> 0 | E29: {=SUM(OFFSET(sim_sup_per_ocs_sgb,begin_year-'OCS Oil SIM'!$B$10,0)*IF(ISERROR(E$61:E$135),0,E$61:E$135))+sim_sup_tot_ocs_sgb*E$38} -> 0 | F29: {=SUM(OFFSET(sim_sup_per_ocs_sgb,begin_year-'OCS Oil SIM'!$B$10,0)*IF(ISERROR(F$61:F$135),0,F$61:F$135))+sim_sup_tot_ocs_sgb*F$38} -> 0 | G29: {=SUM(OFFSET(sim_sup_per_ocs_sgb,begin_year-'OCS Oil SIM'!$B$10,0)*IF(ISERROR(G$61:G$135),0,G$61:G$135))+sim_sup_tot_ocs_sgb*G$38} -> 0 | H29: =SUM(D29:G29) -> 0 | K29: Unconventional | L29: {=SUM(OFFSET(aeo_sup_gas_unc,begin_year-'OCS Oil SIM'!$B$10,0,length_year))} -> 685.14772 | M29: {=SUM(OFFSET(sim_sup_gas_unc,begin_year-'OCS Oil SIM'!$B$11,0,length_year))} -> 685.09139 | N29: =M29-L29 -> -0.056328428 | O29: =IFERROR(N29/L29,0) -> -8.2213553e-05 | Q29: Domestic | R29: =-N40*$AC$18 -> 0.14207014 | S29: =T29/$T$44 -> 0.0012984349 | T29: =R29/$S$10 -> 0.0012963699 | AA29: Sources
C30: St. Matthew Hall | D30: {=SUM(OFFSET(sim_sup_per_ocs_smh,begin_year-'OCS Oil SIM'!$B$10,0)*IF(ISERROR(D$61:D$135),0,D$61:D$135))+sim_sup_tot_ocs_smh*D$38} -> 0 | E30: {=SUM(OFFSET(sim_sup_per_ocs_smh,begin_year-'OCS Oil SIM'!$B$10,0)*IF(ISERROR(E$61:E$135),0,E$61:E$135))+sim_sup_tot_ocs_smh*E$38} -> 0 | F30: {=SUM(OFFSET(sim_sup_per_ocs_smh,begin_year-'OCS Oil SIM'!$B$10,0)*IF(ISERROR(F$61:F$135),0,F$61:F$135))+sim_sup_tot_ocs_smh*F$38} -> 0 | G30: {=SUM(OFFSET(sim_sup_per_ocs_smh,begin_year-'OCS Oil SIM'!$B$10,0)*IF(ISERROR(G$61:G$135),0,G$61:G$135))+sim_sup_tot_ocs_smh*G$38} -> 0 | H30: =SUM(D30:G30) -> 0 | K30: Alaska Onshore | L30: {=SUM(OFFSET(aeo_sup_gas_ala_on,begin_year-'OCS Oil SIM'!$B$10,0,length_year))} -> 6.903796 | M30: {=SUM(OFFSET(sim_sup_gas_ala_on,begin_year-'OCS Oil SIM'!$B$11,0,length_year))} -> 6.902495 | N30: =M30-L30 -> -0.0013010292 | O30: =IFERROR(N30/L30,0) -> -0.00018845129 | Q30: Imported | R30: =-N41*$AC$18 -> 0.00014799415 | S30: =T30/$T$44 -> 1.3525767e-06 | T30: =R30/$S$10 -> 1.3504256e-06 | AA30: EIA. January 2012. AEO 2012 Early Release Overview. Accessed online March 2012 at <http://www.eia.gov/forecasts/aeo/er/early_production.cfm>.
C31: Bowers Basin | D31: {=SUM(OFFSET(sim_sup_per_ocs_bow,begin_year-'OCS Oil SIM'!$B$10,0)*IF(ISERROR(D$61:D$135),0,D$61:D$135))+sim_sup_tot_ocs_bow*D$38} -> 0 | E31: {=SUM(OFFSET(sim_sup_per_ocs_bow,begin_year-'OCS Oil SIM'!$B$10,0)*IF(ISERROR(E$61:E$135),0,E$61:E$135))+sim_sup_tot_ocs_bow*E$38} -> 0 | F31: {=SUM(OFFSET(sim_sup_per_ocs_bow,begin_year-'OCS Oil SIM'!$B$10,0)*IF(ISERROR(F$61:F$135),0,F$61:F$135))+sim_sup_tot_ocs_bow*F$38} -> 0 | G31: {=SUM(OFFSET(sim_sup_per_ocs_bow,begin_year-'OCS Oil SIM'!$B$10,0)*IF(ISERROR(G$61:G$135),0,G$61:G$135))+sim_sup_tot_ocs_bow*G$38} -> 0 | H31: =SUM(D31:G31) -> 0 | K31: U.S. Offshore | L31: =SUM(L32:L33) -> 13.265218 | M31: =SUM(M32:M33) -> 13.347027 | N31: =M31-L31 -> 0.081808658 | O31: =IFERROR(N31/L31,0) -> 0.0061671552 | Q31: ELECTRICITY | R31: =SUM(R32:R38) -> 1.0547047 | S31: =T31/$T$44 -> 0.009639361 | T31: =R31/$S$10 -> 0.0096240305 | AA31: Whitney, G. , C.E. Behrens, and C. Glover, “U.S. Fossil Fuel Resources: Terminology, Reporting, and Summary,” CRS Report for Congress, R40872, Table 5 (Washington, DC: Congressional Research Service, Library of Congress, 30 October 2009), 17.
C32: Aleutian Basin | D32: {=SUM(OFFSET(sim_sup_per_ocs_alb,begin_year-'OCS Oil SIM'!$B$10,0)*IF(ISERROR(D$61:D$135),0,D$61:D$135))+sim_sup_tot_ocs_alb*D$38} -> 0 | E32: {=SUM(OFFSET(sim_sup_per_ocs_alb,begin_year-'OCS Oil SIM'!$B$10,0)*IF(ISERROR(E$61:E$135),0,E$61:E$135))+sim_sup_tot_ocs_alb*E$38} -> 0 | F32: {=SUM(OFFSET(sim_sup_per_ocs_alb,begin_year-'OCS Oil SIM'!$B$10,0)*IF(ISERROR(F$61:F$135),0,F$61:F$135))+sim_sup_tot_ocs_alb*F$38} -> 0 | G32: {=SUM(OFFSET(sim_sup_per_ocs_alb,begin_year-'OCS Oil SIM'!$B$10,0)*IF(ISERROR(G$61:G$135),0,G$61:G$135))+sim_sup_tot_ocs_alb*G$38} -> 0 | H32: =SUM(D32:G32) -> 0 | K32: Lower 48 Offshore | L32: {=SUM(OFFSET(aeo_sup_gas_off,begin_year-'OCS Oil SIM'!$B$10,0,length_year))} -> 13.265218 | M32: {=SUM(OFFSET(sim_sup_gas_off,begin_year-'OCS Oil SIM'!$B$11,0,length_year)+OFFSET(sim_sup_gas_ocs_atn,begin_year-'OCS Oil SIM'!$B$10,0,length_year)+OFFSET(sim_sup_gas_ocs_atm,begin_year-'OCS Oil SIM'!$B$10,0,length_year)+OFFSET(sim_sup_gas_ocs_ats,begin_year-'OCS Oil SIM'!$B$10,0,length_year)+OFFSET(sim_sup_gas_ocs_atf,begin_year-'OCS Oil SIM'!$B$10,0,length_year)+OFFSET(sim_sup_gas_ocs_gme,begin_year-'OCS Oil SIM'!$B$10,0,length_year)+OFFSET(sim_sup_gas_ocs_gmc,begin_year-'OCS Oil SIM'!$B$10,0,length_year)+OFFSET(sim_sup_gas_ocs_gmw,begin_year-'OCS Oil SIM'!$B$10,0,length_year)+OFFSET(sim_sup_gas_ocs_pas,begin_year-'OCS Oil SIM'!$B$10,0,length_year)+OFFSET(sim_sup_gas_ocs_pac,begin_year-'OCS Oil SIM'!$B$10,0,length_year)+OFFSET(sim_sup_gas_ocs_pan,begin_year-'OCS Oil SIM'!$B$10,0,length_year)+OFFSET(sim_sup_gas_ocs_paw,begin_year-'OCS Oil SIM'!$B$10,0,length_year))} -> 13.291027 | N32: =M32-L32 -> 0.025808658 | O32: =IFERROR(N32/L32,0) -> 0.0019455887 | Q32: Nuclear | R32: =(L47-M47)*$AC$26 -> 0.026230273 | S32: =T32/$T$44 -> 0.00023972878 | T32: =R32/$S$10 -> 0.00023934751 | AA32: Hofstrand, D. October 2008. Energy Measurements and Conversions. Iowa State University - University Extension. Accessed online March 2012 at <www.extension.iastate.edu/agdm/wholefarm/pdf/c6-86.pdf>.
C33: Navarin Basin | D33: {=SUM(OFFSET(sim_sup_per_ocs_nav,begin_year-'OCS Oil SIM'!$B$10,0)*IF(ISERROR(D$61:D$135),0,D$61:D$135))+sim_sup_tot_ocs_nav*D$38} -> 0 | E33: {=SUM(OFFSET(sim_sup_per_ocs_nav,begin_year-'OCS Oil SIM'!$B$10,0)*IF(ISERROR(E$61:E$135),0,E$61:E$135))+sim_sup_tot_ocs_nav*E$38} -> 0 | F33: {=SUM(OFFSET(sim_sup_per_ocs_nav,begin_year-'OCS Oil SIM'!$B$10,0)*IF(ISERROR(F$61:F$135),0,F$61:F$135))+sim_sup_tot_ocs_nav*F$38} -> 0 | G33: {=SUM(OFFSET(sim_sup_per_ocs_nav,begin_year-'OCS Oil SIM'!$B$10,0)*IF(ISERROR(G$61:G$135),0,G$61:G$135))+sim_sup_tot_ocs_nav*G$38} -> 0 | H33: =SUM(D33:G33) -> 0 | K33: Alaska Offshore | L33: {=SUM(OFFSET(aeo_sup_gas_ala_off,begin_year-'OCS Oil SIM'!$B$10,0,length_year))} -> 0 | M33: {=SUM(OFFSET(sim_sup_gas_ala_off,begin_year-'OCS Oil SIM'!$B$11,0,length_year))+SUM(OFFSET(sim_sup_gas_ocs,begin_year-'OCS Oil SIM'!$B$10,0,length_year))-SUM(OFFSET(sim_sup_gas_ocs_atn,begin_year-'OCS Oil SIM'!$B$10,0,length_year)+OFFSET(sim_sup_gas_ocs_atm,begin_year-'OCS Oil SIM'!$B$10,0,length_year)+OFFSET(sim_sup_gas_ocs_ats,begin_year-'OCS Oil SIM'!$B$10,0,length_year)+OFFSET(sim_sup_gas_ocs_atf,begin_year-'OCS Oil SIM'!$B$10,0,length_year)+OFFSET(sim_sup_gas_ocs_gme,begin_year-'OCS Oil SIM'!$B$10,0,length_year)+OFFSET(sim_sup_gas_ocs_gmc,begin_year-'OCS Oil SIM'!$B$10,0,length_year)+OFFSET(sim_sup_gas_ocs_gmw,begin_year-'OCS Oil SIM'!$B$10,0,length_year)+OFFSET(sim_sup_gas_ocs_pas,begin_year-'OCS Oil SIM'!$B$10,0,length_year)+OFFSET(sim_sup_gas_ocs_pac,begin_year-'OCS Oil SIM'!$B$10,0,length_year)+OFFSET(sim_sup_gas_ocs_pan,begin_year-'OCS Oil SIM'!$B$10,0,length_year)+OFFSET(sim_sup_gas_ocs_paw,begin_year-'OCS Oil SIM'!$B$10,0,length_year))} -> 0.056 | N33: =M33-L33 -> 0.056 | O33: =IFERROR(N33/L33,0) -> 0 | Q33: Hydro | R33: =(L48-M48)*$AC$26 -> 0.00085076167 | S33: =T33/$T$44 -> 7.7754455e-06 | T33: =R33/$S$10 -> 7.7630794e-06
C34: Norton Basin | D34: {=SUM(OFFSET(sim_sup_per_ocs_nor,begin_year-'OCS Oil SIM'!$B$10,0)*IF(ISERROR(D$61:D$135),0,D$61:D$135))+sim_sup_tot_ocs_nor*D$38} -> 0 | E34: {=SUM(OFFSET(sim_sup_per_ocs_nor,begin_year-'OCS Oil SIM'!$B$10,0)*IF(ISERROR(E$61:E$135),0,E$61:E$135))+sim_sup_tot_ocs_nor*E$38} -> 0 | F34: {=SUM(OFFSET(sim_sup_per_ocs_nor,begin_year-'OCS Oil SIM'!$B$10,0)*IF(ISERROR(F$61:F$135),0,F$61:F$135))+sim_sup_tot_ocs_nor*F$38} -> 0 | G34: {=SUM(OFFSET(sim_sup_per_ocs_nor,begin_year-'OCS Oil SIM'!$B$10,0)*IF(ISERROR(G$61:G$135),0,G$61:G$135))+sim_sup_tot_ocs_nor*G$38} -> 0 | H34: =SUM(D34:G34) -> 0 | K34: Other | L34: {=SUM(OFFSET(aeo_sup_gas_oth,begin_year-'OCS Oil SIM'!$B$10,0,length_year))} -> 1.19819 | M34: {=SUM(OFFSET(sim_sup_gas_oth,begin_year-'OCS Oil SIM'!$B$11,0,length_year))} -> 1.1981333 | N34: =M34-L34 -> -5.6728713e-05 | O34: =IFERROR(N34/L34,0) -> -4.734534e-05 | Q34: Solar | R34: =(L49-M49)*$AC$26 -> 0.77072367 | S34: =T34/$T$44 -> 0.0070439467 | T34: =R34/$S$10 -> 0.007032744
C35: Hope Basin | D35: {=SUM(OFFSET(sim_sup_per_ocs_hop,begin_year-'OCS Oil SIM'!$B$10,0)*IF(ISERROR(D$61:D$135),0,D$61:D$135))+sim_sup_tot_ocs_hop*D$38} -> 0 | E35: {=SUM(OFFSET(sim_sup_per_ocs_hop,begin_year-'OCS Oil SIM'!$B$10,0)*IF(ISERROR(E$61:E$135),0,E$61:E$135))+sim_sup_tot_ocs_hop*E$38} -> 0 | F35: {=SUM(OFFSET(sim_sup_per_ocs_hop,begin_year-'OCS Oil SIM'!$B$10,0)*IF(ISERROR(F$61:F$135),0,F$61:F$135))+sim_sup_tot_ocs_hop*F$38} -> 0 | G35: {=SUM(OFFSET(sim_sup_per_ocs_hop,begin_year-'OCS Oil SIM'!$B$10,0)*IF(ISERROR(G$61:G$135),0,G$61:G$135))+sim_sup_tot_ocs_hop*G$38} -> 0 | H35: =SUM(D35:G35) -> 0 | K35: Total Imports | L35: =SUM(L36:L37) -> 40.39316 | M35: =SUM(M36:M37) -> 40.388674 | N35: =M35-L35 -> -0.0044856132 | O35: =IFERROR(N35/L35,0) -> -0.00011104883 | Q35: Wind Onshore | R35: =(L50-M50)*$AC$26 -> 0.2563123 | S35: =T35/$T$44 -> 0.0023425389 | T35: =R35/$S$10 -> 0.0023388133
C36: Chukchi Sea | D36: {=SUM(OFFSET(sim_sup_per_ocs_chu,begin_year-'OCS Oil SIM'!$B$10,0)*IF(ISERROR(D$61:D$135),0,D$61:D$135))+sim_sup_tot_ocs_chu*D$38} -> 0 | E36: {=SUM(OFFSET(sim_sup_per_ocs_chu,begin_year-'OCS Oil SIM'!$B$10,0)*IF(ISERROR(E$61:E$135),0,E$61:E$135))+sim_sup_tot_ocs_chu*E$38} -> 0 | F36: {=SUM(OFFSET(sim_sup_per_ocs_chu,begin_year-'OCS Oil SIM'!$B$10,0)*IF(ISERROR(F$61:F$135),0,F$61:F$135))+sim_sup_tot_ocs_chu*F$38} -> 0 | G36: {=SUM(OFFSET(sim_sup_per_ocs_chu,begin_year-'OCS Oil SIM'!$B$10,0)*IF(ISERROR(G$61:G$135),0,G$61:G$135))+sim_sup_tot_ocs_chu*G$38} -> 0 | H36: =SUM(D36:G36) -> 0 | K36: Imports Pipeline | L36: {=SUM(OFFSET(aeo_sup_gas_pip,begin_year-'OCS Oil SIM'!$B$10,0,length_year))} -> 39.364191 | M36: {=SUM(OFFSET(sim_sup_gas_pip,begin_year-'OCS Oil SIM'!$B$11,0,length_year))} -> 39.359803 | N36: =M36-L36 -> -0.0043879428 | O36: =IFERROR(N36/L36,0) -> -0.00011147042 | Q36: Wind Offshore | R36: =(L51-M51)*$AC$26 -> 0.00044955737 | S36: =T36/$T$44 -> 4.1086816e-06 | T36: =R36/$S$10 -> 4.1021471e-06
C37: Beaufort Sea | D37: {=SUM(OFFSET(sim_sup_per_ocs_bea,begin_year-'OCS Oil SIM'!$B$10,0)*IF(ISERROR(D$61:D$135),0,D$61:D$135))+sim_sup_tot_ocs_bea*D$38} -> 0 | E37: {=SUM(OFFSET(sim_sup_per_ocs_bea,begin_year-'OCS Oil SIM'!$B$10,0)*IF(ISERROR(E$61:E$135),0,E$61:E$135))+sim_sup_tot_ocs_bea*E$38} -> 0 | F37: {=SUM(OFFSET(sim_sup_per_ocs_bea,begin_year-'OCS Oil SIM'!$B$10,0)*IF(ISERROR(F$61:F$135),0,F$61:F$135))+sim_sup_tot_ocs_bea*F$38} -> 0 | G37: {=SUM(OFFSET(sim_sup_per_ocs_bea,begin_year-'OCS Oil SIM'!$B$10,0)*IF(ISERROR(G$61:G$135),0,G$61:G$135))+sim_sup_tot_ocs_bea*G$38} -> 0 | H37: =SUM(D37:G37) -> 0 | K37: Imports LNG | L37: {=SUM(OFFSET(aeo_sup_gas_lng,begin_year-'OCS Oil SIM'!$B$10,0,length_year))} -> 1.028969 | M37: {=SUM(OFFSET(sim_sup_gas_lng,begin_year-'OCS Oil SIM'!$B$11,0,length_year))} -> 1.0288713 | N37: =M37-L37 -> -9.7670403e-05 | O37: =IFERROR(N37/L37,0) -> -9.4920646e-05 | Q37: Other Electric | R37: =(L52-M52)*$AC$26 -> -0.004064456 | S37: =T37/$T$44 -> -3.7146662e-05 | T37: =R37/$S$10 -> -3.7087583e-05
B38: TOTAL BENEFITS ($ million) | D38: {=SUM(IFERROR(IF((OFFSET(sim_sup_oil_ocs,begin_year-'OCS Oil SIM'!$B$10,0)+OFFSET(sim_sup_gas_ocs,begin_year-'OCS Oil SIM'!$B$10,0))>0,0,1),0)*IF(ISERROR(D$61:D$135),0,D$61:D$135))} -> 0 | E38: {=SUM(IFERROR(IF((OFFSET(sim_sup_oil_ocs,begin_year-'OCS Oil SIM'!$B$10,0)+OFFSET(sim_sup_gas_ocs,begin_year-'OCS Oil SIM'!$B$10,0))>0,0,1),0)*IF(ISERROR(E$61:E$135),0,E$61:E$135))} -> 0 | F38: {=SUM(IFERROR(IF((OFFSET(sim_sup_oil_ocs,begin_year-'OCS Oil SIM'!$B$10,0)+OFFSET(sim_sup_gas_ocs,begin_year-'OCS Oil SIM'!$B$10,0))>0,0,1),0)*IF(ISERROR(F$61:F$135),0,F$61:F$135))} -> 0 | G38: {=SUM(IFERROR(IF((OFFSET(sim_sup_oil_ocs,begin_year-'OCS Oil SIM'!$B$10,0)+OFFSET(sim_sup_gas_ocs,begin_year-'OCS Oil SIM'!$B$10,0))>0,0,1),0)*IF(ISERROR(G$61:G$135),0,G$61:G$135))} -> 0 | K38: Alaska Total (reflected in categories above) | L38: =L30+L33 -> 6.903796 | M38: =M30+M33 -> 6.958495 | N38: =M38-L38 -> 0.054698971 | O38: =IFERROR(N38/L38,0) -> 0.0079230283 | Q38: Imports | R38: =(L53-M53)*$AC$26 -> 0.0042025902 | S38: =T38/$T$44 -> 3.8409125e-05 | T38: =R38/$S$10 -> 3.8348039e-05
D39: {=SUM(IF(ISERROR(D$61:D$135),0,D$61:D$135))} -> 216.13041 | E39: {=SUM(IF(ISERROR(E$61:E$135),0,E$61:E$135))} -> 13.103934 | F39: {=SUM(IF(ISERROR(F$61:F$135),0,F$61:F$135))} -> 5.5325192 | G39: {=SUM(IF(ISERROR(G$61:G$135),0,G$61:G$135))} -> 0.00068938048 | H39: =SUM(D39:G39) -> 234.76756 | K39: COAL (million short tons) | Q39: REDUCED DEMAND | R39: =SUM(R40:R43) -> 8.1373047 | S39: =T39/$T$44 -> 0.074370027 | T39: =R39/$S$10 -> 0.074251749
K40: U.S. Production | L40: {=SUM(OFFSET(aeo_sup_coa_dom,begin_year-'OCS Oil SIM'!$B$10,0,length_year))} -> 6383.5948 | M40: {=SUM(OFFSET(sim_sup_coa_dom,begin_year-'OCS Oil SIM'!$B$11,0,length_year))} -> 6383.5544 | N40: =M40-L40 -> -0.040417348 | O40: =N40/L40 -> -6.3314401e-06 | Q40: Oil | R40: =SUM(M61:M64)-SUM(L61:L64) -> 6.3189755 | S40: =T40/$T$44 -> 0.057751602 | T40: =R40/$S$10 -> 0.057659754
B41: OCS scenario total million barrels of oil equivalent | D41: {=SUM(OFFSET(sim_sup_oil_ocs,begin_year-'OCS Oil SIM'!$B$10,0,length_year))*365+SUM(OFFSET(sim_sup_gas_ocs,begin_year-'OCS Oil SIM'!$B$10,0,length_year))*gas_boe} -> 109.59075 | H41: {=SUM(OFFSET(sim_sup_oil_ocs,begin_year-'OCS Oil SIM'!$B$10,0,length_year))*365+SUM(OFFSET(sim_sup_gas_ocs,begin_year-'OCS Oil SIM'!$B$10,0,length_year))*gas_boe} -> 109.59075 | K41: Total Imports | L41: {=SUM(OFFSET(aeo_sup_coa_imp,begin_year-'OCS Oil SIM'!$B$10,0,length_year))} -> 30.874451 | M41: {=SUM(OFFSET(sim_sup_coa_imp,begin_year-'OCS Oil SIM'!$B$11,0,length_year))} -> 30.874409 | N41: =M41-L41 -> -4.210266e-05 | O41: =N41/L41 -> -1.3636732e-06 | Q41: Natural Gas | R41: =(SUM(M72:M75,M78)-SUM(L72:L75,L78))*gas_boe -> 2.8930987 | S41: =T41/$T$44 -> 0.026441167 | T41: =R41/$S$10 -> 0.026399115
K42: ELECTRICITY (billion kilowatt hours) | Q42: Coal | R42: =(SUM(M80,M82,M84)-SUM(L80,L82,L84))*$AC$18 -> -0.12094959 | S42: =T42/$T$44 -> -0.0011054059 | T42: =R42/$S$10 -> -0.0011036478
...

Sheet Inflation
B1: Return to Table of Contents
B6: INFLATION INDICES
B7: Series | C7: GDP Chain-type Price Index | D7: CPI All-urban | E7: CPI Energy Commodities and Services | F7: User defined
B8: 2000 | C8: 0.780685 | D8: 2.180762 | E8: 2.116822
B9: 2001 | C9: 0.798215 | D9: 2.24923 | E9: 2.437438
B10: 2002 | C10: 0.810387 | D10: 2.295861 | E10: 2.459985
B11: 2003 | C11: 0.82567 | D11: 2.329518 | E11: 2.443281
B12: 2004 | C12: 0.847782 | D12: 2.36715 | E12: 2.433069
B13: 2005 | C13: 0.87407 | D13: 2.370018 | E13: 2.026325
B14: 2006 | C14: 0.90074 | D14: 2.400054 | E14: 1.895002
B15: 2007 | C15: 0.924977 | D15: 2.45121 | E15: 2.046964
B16: 2008 | C16: 0.942635 | D16: 2.510989 | E16: 2.198792 | H16: =INDEX(indices,MATCH(inflator_year,Inflation!$B$8:$B$48,0),MATCH(inflation_index,Inflation!$C$7:$F$7,0))/INDEX(indices,MATCH(dollars_year,Inflation!$B$8:$B$48,0),MATCH(inflation_index,Inflation!$C$7:$F$7,0)) -> 1.2583816
B17: 2009 | C17: 0.94999 | D17: 2.556465 | E17: 2.152251
B18: 2010 | C18: 0.96164 | D18: 2.588382 | E18: 1.972384
