Workbook
Name ARFN5_IN_1991: AnimasRiverTotalOutflow!$E$4:$E$80
Name ARFN5_IN_1992: AnimasRiverTotalOutflow!$F$4:$F$80
Name ARFN5_IN_1993: AnimasRiverTotalOutflow!$G$4:$G$80
Name ARFN5_IN_1994: AnimasRiverTotalOutflow!$H$4:$H$80
Name ARFN5_IN_1995: AnimasRiverTotalOutflow!$I$4:$I$80
Name ARFN5_IN_1996: AnimasRiverTotalOutflow!$J$4:$J$80
Name ARFN5_IN_1997: AnimasRiverTotalOutflow!$K$4:$K$80
Name ARFN5_IN_1998: AnimasRiverTotalOutflow!$L$4:$L$80
Name ARFN5_IN_1999: AnimasRiverTotalOutflow!$M$4:$M$80
Name ARFN5_IN_2000: AnimasRiverTotalOutflow!$N$4:$N$80
Name ARFN5_IN_2001: AnimasRiverTotalOutflow!$O$4:$O$80
Name ARFN5_IN_2002: AnimasRiverTotalOutflow!$P$4:$P$80
Name ARFN5_IN_2003: AnimasRiverTotalOutflow!$Q$4:$Q$80
Name ARFN5_IN_2004: AnimasRiverTotalOutflow!$R$4:$R$80
Name ARFN5_IN_2005: AnimasRiverTotalOutflow!$S$4:$S$80
Name ARFN5_IN_2006: AnimasRiverTotalOutflow!$T$4:$T$80
Name ARFN5_IN_2007: AnimasRiverTotalOutflow!$U$4:$U$80
Name ARFN5_IN_2008: AnimasRiverTotalOutflow!$V$4:$V$80
Name ARFN5_IN_2009: AnimasRiverTotalOutflow!$W$4:$W$80
Name ARFN5_IN_2010: AnimasRiverTotalOutflow!$X$4:$X$80
Name ARFN5_IN_2011: AnimasRiverTotalOutflow!$Y$4:$Y$80
Name ARFN5_IN_2012: AnimasRiverTotalOutflow!$Z$4:$Z$80
Name ARFN5_IN_2013: AnimasRiverTotalOutflow!$AA$4:$AA$80
Name ARFN5_IN_2014: AnimasRiverTotalOutflow!$AB$4:$AB$80
Name ARFN5_IN_2015: AnimasRiverTotalOutflow!$AC$4:$AC$80
Name ARFN5_IN_2016: AnimasRiverTotalOutflow!$AD$4:$AD$80
Name ARFN5_IN_2017: AnimasRiverTotalOutflow!$AE$4:$AE$80
Name ARFN5_IN_2018: AnimasRiverTotalOutflow!$AF$4:$AF$80
Name ARFN5_IN_2019: AnimasRiverTotalOutflow!$AG$4:$AG$80
Name ARFN5_IN_2020: AnimasRiverTotalOutflow!$AH$4:$AH$80
Name ARFN5_IN_2021: AnimasRiverTotalOutflow!$AS$4:$AS$80
Name ARFN5_IN_2022: AnimasRiverTotalOutflow!$AT$4:$AT$80
Name ARFN5_IN_2023: AnimasRiverTotalOutflow!$AU$4:$AU$80
Name ARFN5_IN_2024: AnimasRiverTotalOutflow!$AV$4:$AV$80
Name ARFN5_IN_2025: AnimasRiverTotalOutflow!$AW$4:$AW$80
Name ARFN5_IN_2026: AnimasRiverTotalOutflow!$AX$4:$AX$80
Name ARFN5_IN_2027: AnimasRiverTotalOutflow!$AY$4:$AY$80
Name ARFN5_IN_2028: AnimasRiverTotalOutflow!$AZ$4:$AZ$80
Name ARFN5_IN_2029: AnimasRiverTotalOutflow!$BA$4:$BA$80
Name ARFN5_IN_Max: AnimasRiverTotalOutflow!$B$4:$B$80
Name ARFN5_IN_Min: AnimasRiverTotalOutflow!$C$4:$C$80
Name ARFN5_IN_Most: AnimasRiverTotalOutflow!$D$4:$D$80
Name ARFN5_IN_TIME: AnimasRiverTotalOutflow!$A$4:$A$80
Name BlwImpGainsAbvDavis: GainsAboveDavis!$A$4:$A$71
Name BMESA_IN_1991: BlueMesaInflow.Unregulated!$E$4:$E$80
Name BMESA_IN_1992: BlueMesaInflow.Unregulated!$F$4:$F$80
Name BMESA_IN_1993: BlueMesaInflow.Unregulated!$G$4:$G$80
Name BMESA_IN_1994: BlueMesaInflow.Unregulated!$H$4:$H$80
Name BMESA_IN_1995: BlueMesaInflow.Unregulated!$I$4:$I$80
Name BMESA_IN_1996: BlueMesaInflow.Unregulated!$J$4:$J$80
Name BMESA_IN_1997: BlueMesaInflow.Unregulated!$K$4:$K$80
Name BMESA_IN_1998: BlueMesaInflow.Unregulated!$L$4:$L$80
Name BMESA_IN_1999: BlueMesaInflow.Unregulated!$M$4:$M$80
Name BMESA_IN_2000: BlueMesaInflow.Unregulated!$N$4:$N$80
Name BMESA_IN_2001: BlueMesaInflow.Unregulated!$O$4:$O$80
Name BMESA_IN_2002: BlueMesaInflow.Unregulated!$P$4:$P$80
Name BMESA_IN_2003: BlueMesaInflow.Unregulated!$Q$4:$Q$80
Name BMESA_IN_2004: BlueMesaInflow.Unregulated!$R$4:$R$80
Name BMESA_IN_2005: BlueMesaInflow.Unregulated!$S$4:$S$80
Name BMESA_IN_2006: BlueMesaInflow.Unregulated!$T$4:$T$80

Sheet BlueMesaInflow.Unregulated
B2: Max | C2: Min | D2: Most | E2: 1991 | F2: 1992 | G2: 1993 | H2: 1994 | I2: 1995 | J2: 1996 | K2: 1997 | L2: 1998 | M2: 1999 | N2: 2000 | O2: 2001 | P2: 2002 | Q2: 2003 | R2: 2004 | S2: 2005 | T2: 2006 | U2: 2007 | V2: 2008 | W2: 2009 | X2: 2010 | Y2: 2011 | Z2: 2012 | AA2: 2013 | AB2: 2014 | AC2: 2015 | AD2: 2016 | AE2: 2017 | AF2: 2018 | AG2: 2019 | AH2: 2020
B3: Trace1 | C3: Trace2 | D3: Trace3 | E3: Trace4 | F3: Trace5 | G3: Trace6 | H3: Trace7 | I3: Trace8 | J3: Trace9 | K3: Trace10 | L3: Trace11 | M3: Trace12 | N3: Trace13 | O3: Trace14 | P3: Trace15 | Q3: Trace16 | R3: Trace17 | S3: Trace18 | T3: Trace19 | U3: Trace20 | V3: Trace21 | W3: Trace22 | X3: Trace23 | Y3: Trace24 | Z3: Trace25 | AA3: Trace26 | AB3: Trace27 | AC3: Trace28 | AD3: Trace29 | AE3: Trace30 | AF3: Trace31 | AG3: Trace32 | AH3: Trace33
A4: 46143 | B4: 104 | C4: 34 | D4: 62 | E4: 51.192 | F4: 77.856 | G4: 69.178 | H4: 61.133 | I4: 75.285 | J4: 54.677 | K4: 60.78 | L4: 47.445 | M4: 73.932 | N4: 72.81 | O4: 80.834 | P4: 47.331 | Q4: 75.35 | R4: 59.336 | S4: 76.31 | T4: 59.152 | U4: 66.08 | V4: 62.867 | W4: 72.003 | X4: 54.454 | Y4: 52.76 | Z4: 59.722 | AA4: 66.037 | AB4: 71.437 | AC4: 59.046 | AD4: 64.128 | AE4: 57.324 | AF4: 63.663 | AG4: 43.948 | AH4: 61.051
A5: 46174 | B5: 79 | C5: 26 | D5: 47 | E5: 50.45 | F5: 66.42 | G5: 54.639 | H5: 35.686 | I5: 151.109 | J5: 26.466 | K5: 70.771 | L5: 32.897 | M5: 71.572 | N5: 37.373 | O5: 44.918 | P5: 26.251 | Q5: 53.883 | R5: 29.075 | S5: 42.026 | T5: 29.796 | U5: 41.42 | V5: 58.682 | W5: 41.614 | X5: 49.082 | Y5: 66.009 | Z5: 24.196 | AA5: 43.96 | AB5: 55.972 | AC5: 139.574 | AD5: 57.19 | AE5: 55.588 | AF5: 26.236 | AG5: 87.425 | AH5: 36.457
A6: 46204 | B6: 40 | C6: 13 | D6: 24 | E6: 27.402 | F6: 35.702 | G6: 26.173 | H6: 19.781 | I6: 81.968 | J6: 17.775 | K6: 31.261 | L6: 19.138 | M6: 37.418 | N6: 21.805 | O6: 23.629 | P6: 17.896 | Q6: 22.884 | R6: 19.504 | S6: 22.676 | T6: 22.781 | U6: 24.371 | V6: 26.924 | W6: 23.375 | X6: 23.303 | Y6: 29.336 | Z6: 17.88 | AA6: 26.975 | AB6: 25.862 | AC6: 56.892 | AD6: 27.265 | AE6: 28.509 | AF6: 17.862 | AG6: 37.121 | AH6: 21.424
A7: 46235 | B7: 38 | C7: 22 | D7: 27 | E7: 25.886 | F7: 39.061 | G7: 24.007 | H7: 21.291 | I7: 39.664 | J7: 18.172 | K7: 30.455 | L7: 20.805 | M7: 33.921 | N7: 27.493 | O7: 31.832 | P7: 18.956 | Q7: 26.161 | R7: 21.034 | S7: 26.895 | T7: 27.795 | U7: 27.815 | V7: 25.754 | W7: 22.254 | X7: 27.543 | Y7: 23.826 | Z7: 20.968 | AA7: 28.639 | AB7: 27.105 | AC7: 34.467 | AD7: 27.999 | AE7: 27.263 | AF7: 18.747 | AG7: 28.232 | AH7: 21.173
A8: 46266 | B8: 31 | C8: 23 | D8: 21 | E8: 19.346 | F8: 30.729 | G8: 22.603 | H8: 20.426 | I8: 29.755 | J8: 17.152 | K8: 26.158 | L8: 16.721 | M8: 24.622 | N8: 22.114 | O8: 20.506 | P8: 18.917 | Q8: 42.954 | R8: 21.448 | S8: 20.906 | T8: 23.136 | U8: 28.212 | V8: 19.346 | W8: 18.306 | X8: 18.348 | Y8: 18.482 | Z8: 18.439 | AA8: 44.154 | AB8: 31.735 | AC8: 27.773 | AD8: 21.094 | AE8: 19.221 | AF8: 16.163 | AG8: 19.497 | AH8: 24.018
A9: 46296 | B9: 40 | C9: 32 | D9: 26 | E9: 18.268 | F9: 23.062 | G9: 23.581 | H9: 26.362 | I9: 33.986 | J9: 24.809 | K9: 30.558 | L9: 25.722 | M9: 22.706 | N9: 20.762 | O9: 20.685 | P9: 26.544 | Q9: 26.399 | R9: 21.878 | S9: 32.898 | T9: 41.79 | U9: 29.446 | V9: 20.616 | W9: 22.002 | X9: 20.543 | Y9: 21.438 | Z9: 18.143 | AA9: 41.095 | AB9: 39.08 | AC9: 24.696 | AD9: 20.011 | AE9: 22.734 | AF9: 18.676 | AG9: 19.841 | AH9: 24.714
A10: 46327 | B10: 31 | C10: 29 | D10: 27 | E10: 17.829 | F10: 19.149 | G10: 19.563 | H10: 20.909 | I10: 25.685 | J10: 22.095 | K10: 23.415 | L10: 22.363 | M10: 18.699 | N10: 17.786 | O10: 21.286 | P10: 17.643 | Q10: 19.298 | R10: 19.846 | S10: 26.295 | T10: 30.547 | U10: 24.99 | V10: 17.876 | W10: 20.397 | X10: 21.455 | Y10: 18.127 | Z10: 15.089 | AA10: 26.431 | AB10: 24.408 | AC10: 22.758 | AD10: 16.785 | AE10: 19.283 | AF10: 17.562 | AG10: 17.676 | AH10: 27.304
A11: 46357 | B11: 26 | C11: 25 | D11: 26 | E11: 16.345 | F11: 17.245 | G11: 15.99 | H11: 16.683 | I11: 24.12 | J11: 17.75 | K11: 18.567 | L11: 20.621 | M11: 16.415 | N11: 15.646 | O11: 16.855 | P11: 15.25 | Q11: 17.447 | R11: 16.07 | S11: 18.91 | T11: 20.817 | U11: 17.868 | V11: 15.654 | W11: 16.281 | X11: 18 | Y11: 15.712 | Z11: 13.555 | AA11: 20.063 | AB11: 19.55 | AC11: 19.93 | AD11: 15.621 | AE11: 18.377 | AF11: 14.06 | AG11: 16.465 | AH11: 21.283
A12: 46388 | B12: 25 | C12: 24 | D12: 25 | E12: 14.77 | F12: 16.29 | G12: 14.755 | H12: 15.279 | I12: 20.494 | J12: 14.991 | K12: 16.819 | L12: 17.852 | M12: 17.091 | N12: 14.697 | O12: 14.718 | P12: 14.664 | Q12: 15.84 | R12: 15.847 | S12: 16.375 | T12: 17.761 | U12: 14.885 | V12: 14.498 | W12: 14.597 | X12: 16.73 | Y12: 15.359 | Z12: 12.642 | AA12: 17.627 | AB12: 17.281 | AC12: 18.554 | AD12: 14.549 | AE12: 15.854 | AF12: 13.025 | AG12: 15.249 | AH12: 16.964
A13: 46419 | B13: 23 | C13: 23 | D13: 23 | E13: 14.095 | F13: 15.163 | G13: 12.615 | H13: 18.125 | I13: 20.915 | J13: 12.394 | K13: 14.995 | L13: 17.788 | M13: 18.095 | N13: 14.586 | O13: 12.575 | P13: 17.055 | Q13: 13.74 | R13: 14.419 | S13: 13.468 | T13: 17.016 | U13: 12.168 | V13: 13.145 | W13: 12.201 | X13: 14.114 | Y13: 13.043 | Z13: 11.15 | AA13: 17.565 | AB13: 21.823 | AC13: 17.391 | AD13: 19.671 | AE13: 17.978 | AF13: 11.268 | AG13: 13.753 | AH13: 16.452
A14: 46447 | B14: 41 | C14: 35 | D14: 38 | E14: 25.362 | F14: 28.653 | G14: 28.231 | H14: 38.135 | I14: 30.218 | J14: 30.765 | K14: 29.186 | L14: 27.042 | M14: 23.203 | N14: 23.921 | O14: 16.945 | P14: 27.172 | Q14: 40.266 | R14: 19.875 | S14: 21.546 | T14: 42.686 | U14: 13.208 | V14: 29.269 | W14: 15.506 | X14: 25.521 | Y14: 27.086 | Z14: 18.052 | AA14: 23.981 | AB14: 38.912 | AC14: 31.701 | AD14: 49.555 | AE14: 19.844 | AF14: 16.361 | AG14: 24.709 | AH14: 22.651
A15: 46478 | B15: 93 | C15: 64 | D15: 78 | E15: 59.122 | F15: 62.348 | G15: 53.541 | H15: 47.57 | I15: 75.934 | J15: 61.553 | K15: 45.383 | L15: 38.462 | M15: 68.532 | N15: 51.301 | O15: 46.848 | P15: 48.717 | Q15: 84.812 | R15: 53.389 | S15: 71.258 | T15: 71.291 | U15: 42.613 | V15: 45.498 | W15: 41.236 | X15: 57.16 | Y15: 60.662 | Z15: 35.122 | AA15: 59.684 | AB15: 59.718 | AC15: 53.747 | AD15: 94.223 | AE15: 34.794 | AF15: 66.558 | AG15: 38.179 | AH15: 43.974
... A27: 46844 | B27: 78 | C27: 78 | D27: 78 | E27: 66.888 | F27: 72.964 | G27: 56.482 | H27: 94.64 | I27: 76.73 | J27: 59.808 | K27: 47.382 | L27: 83.425 | M27: 59.674 | N27: 53.425 | O27: 48.884 | P27: 93.075 | Q27: 61.409 | R27: 87.822 | S27: 87.479 | T27: 45.837 | U27: 63.798 | V27: 50.601 | W27: 61.528 | X27: 80.324 | Y27: 35.569 | Z27: 64.882 | AA27: 75.048 | AB27: 57.646 | AC27: 104.504 | AD27: 46.929 | AE27: 71.541 | AF27: 49.286 | AG27: 47.991 | AH27: 72.34
A28: 46874 | B28: 204 | C28: 204 | D28: 204 | E28: 276.128 | F28: 213.497 | G28: 234.748 | H28: 356.015 | I28: 315.677 | J28: 192.775 | K28: 199.268 | L28: 239.515 | M28: 239.348 | N28: 93.77 | O28: 164.316 | P28: 221.205 | Q28: 259.3 | R28: 231.465 | S28: 217.218 | T28: 230.583 | U28: 300.339 | V28: 119.187 | W28: 143.048 | X28: 140.149 | Y28: 100.016 | Z28: 237.002 | AA28: 158.81 | AB28: 156.772 | AC28: 247.936 | AD28: 161.059 | AE28: 170.184 | AF28: 179.907 | AG28: 132.201 | AH28: 206.946 | ALQ28: #N/A
A29: 46905 | B29: 251 | C29: 251 | D29: 251 | E29: 400.167 | F29: 207.821 | G29: 568.981 | H29: 305.269 | I29: 476.434 | J29: 201.141 | K29: 316.779 | L29: 146.325 | M29: 177.313 | N29: 53.319 | O29: 198.071 | P29: 134.741 | Q29: 273.315 | R29: 176.785 | S29: 159.618 | T29: 466.237 | U29: 252.008 | V29: 251.968 | W29: 415.551 | X29: 51.816 | Y29: 143.85 | Z29: 317.23 | AA29: 341.142 | AB29: 279.851 | AC29: 379.109 | AD29: 71.333 | AE29: 397.044 | AF29: 186.174 | AG29: 261.066 | AH29: 153.497 | ALQ29: #N/A
A30: 46935 | B30: 86 | C30: 86 | D30: 86 | E30: 175.228 | F30: 63.338 | G30: 418.378 | H30: 108.214 | I30: 161.479 | J30: 95.417 | K30: 204.72 | L30: 49.417 | M30: 55.927 | N30: 23.546 | O30: 55.005 | P30: 52.821 | Q30: 106.141 | R30: 69.144 | S30: 61.811 | T30: 204.533 | U30: 126.242 | V30: 66.85 | W30: 215.168 | X30: 27.483 | Y30: 53.029 | Z30: 97.475 | AA30: 113.501 | AB30: 89.245 | AC30: 124.909 | AD30: 31.46 | AE30: 243.574 | AF30: 58.344 | AG30: 109.917 | AH30: 63.101 | ALQ30: #N/A
A31: 46966 | B31: 55 | C31: 55 | D31: 55 | E31: 67.133 | F31: 42.069 | G31: 121.368 | H31: 53.171 | I31: 79.096 | J31: 48.871 | K31: 84.706 | L31: 43.657 | M31: 50.756 | N31: 20.756 | O31: 40.843 | P31: 36.87 | Q31: 56.74 | R31: 48.323 | S31: 45.15 | T31: 76.451 | U31: 52.647 | V31: 47.78 | W31: 67.798 | X31: 27.948 | Y31: 37.532 | Z31: 55.396 | AA31: 52.488 | AB31: 51.993 | AC31: 61.638 | AD31: 26.101 | AE31: 79.06 | AF31: 38.729 | AG31: 52.626 | AH31: 52.642 | ALQ31: #N/A
A32: 46997 | B32: 35 | C32: 35 | D32: 35 | E32: 47.446 | F32: 33.636 | G32: 63.244 | H32: 38.747 | I32: 54.152 | J32: 31.632 | K32: 45.518 | L32: 32.229 | M32: 29.374 | N32: 20.419 | O32: 53.857 | P32: 32.886 | Q32: 37.271 | R32: 36.301 | S32: 39.508 | T32: 43.277 | U32: 35.69 | V32: 27.418 | W32: 38.805 | X32: 22.952 | Y32: 52.384 | Z32: 51.552 | AA32: 37.928 | AB32: 33.812 | AC32: 38.139 | AD32: 21.31 | AE32: 41.596 | AF32: 36.266 | AG32: 32.513 | AH32: 36.827 | ALQ32: #N/A
A33: 47027 | B33: 40 | C33: 31 | D33: 36 | E33: 43.794 | F33: 39.924 | G33: 56.948 | H33: 45.721 | I33: 54.733 | J33: 41.064 | K33: 36.772 | L33: 28.689 | M33: 28.409 | N33: 27.534 | O33: 32.511 | P33: 30.793 | Q33: 48.055 | R33: 57.038 | S33: 39.377 | T33: 39.447 | U33: 37.32 | V33: 28.636 | W33: 37.939 | X33: 22.082 | Y33: 45.313 | Z33: 56.532 | AA33: 32.779 | AB33: 29.679 | AC33: 39.222 | AD33: 23.93 | AE33: 36.08 | AF33: 35.302 | AG33: 27.663 | AH33: 27.716 | ALQ33: #N/A
A34: 47058 | B34: 33 | C34: 29 | D34: 31 | E34: 35.109 | F34: 30.754 | G34: 43.104 | H34: 38.967 | I34: 41.508 | J34: 33.479 | K34: 29.295 | L34: 25.059 | M34: 27.565 | N34: 18.168 | O34: 24.251 | P34: 27.799 | Q34: 36.849 | R34: 40.258 | S34: 31.969 | T34: 33.469 | U34: 32.985 | V34: 28.538 | W34: 31.028 | X34: 18.343 | Y34: 29.304 | Z34: 35.928 | AA34: 29.242 | AB34: 25.458 | AC34: 33.29 | AD34: 21.877 | AE34: 30.968 | AF34: 36.297 | AG34: 26.064 | AH34: 23.579 | ALQ34: #N/A
A35: 47088 | B35: 26 | C35: 26 | D35: 26 | E35: 29.825 | F35: 25.483 | G35: 39.162 | H35: 32.423 | I35: 33.342 | J35: 30.307 | K35: 25.879 | L35: 22.078 | M35: 22.281 | N35: 15.699 | O35: 21.809 | P35: 22.852 | Q35: 27.519 | R35: 28.353 | S35: 23.437 | T35: 29.491 | U35: 26.993 | V35: 23.936 | W35: 27.099 | X35: 16.562 | Y35: 22.358 | Z35: 28.994 | AA35: 25.757 | AB35: 23.285 | AC35: 30.514 | AD35: 17.908 | AE35: 28.372 | AF35: 28.799 | AG35: 23.385 | AH35: 21.104 | ALQ35: #N/A
A36: 47119 | B36: 25 | C36: 25 | D36: 25 | E36: 27.119 | F36: 23.124 | G36: 33.407 | H36: 27.858 | I36: 29.645 | J36: 26.408 | K36: 25.748 | L36: 20.457 | M36: 19.531 | N36: 15.261 | O36: 19.697 | P36: 21.863 | Q36: 23.939 | R36: 24.211 | S36: 19.673 | T36: 26.894 | U36: 24.098 | V36: 21.893 | W36: 25.558 | X36: 15.349 | Y36: 19.602 | Z36: 25.521 | AA36: 23.741 | AB36: 21.388 | AC36: 26.638 | AD36: 16.444 | AE36: 25.863 | AF36: 23.455 | AG36: 21.232 | AH36: 19.749 | ALQ36: #N/A
A37: 47150 | B37: 23 | C37: 23 | D37: 23 | E37: 22.779 | F37: 25.04 | G37: 32.017 | H37: 22.839 | I37: 25.412 | J37: 24.934 | K37: 25.163 | L37: 19.282 | M37: 16.51 | N37: 17.216 | O37: 16.978 | P37: 19.308 | Q37: 19.614 | R37: 22.382 | S37: 16.017 | T37: 23.394 | U37: 19.959 | V37: 18.398 | W37: 21.339 | X37: 13.364 | Y37: 19.535 | Z37: 29.054 | AA37: 21.854 | AB37: 25.426 | AC37: 27.035 | AD37: 14.054 | AE37: 22.439 | AF37: 21.778 | AG37: 19.463 | AH37: 18.005 | ALQ37: #N/A
A38: 47178 | B38: 38 | C38: 38 | D38: 38 | E38: 40.207 | F38: 45.549 | G38: 41.276 | H38: 43.86 | I38: 42.188 | J38: 35.998 | K38: 30.754 | L38: 28.903 | M38: 21.396 | N38: 27.652 | O38: 43.974 | P38: 24.861 | Q38: 28.222 | R38: 52.713 | S38: 17.226 | T38: 41.206 | U38: 23.941 | V38: 30.222 | W38: 37.468 | X38: 20.311 | Y38: 25.749 | Z38: 50.485 | AA38: 36.681 | AB38: 57.046 | AC38: 29.234 | AD38: 19.718 | AE38: 34.23 | AF38: 28.098 | AG38: 32.171 | AH38: 32.758 | ALQ38: #N/A
A39: 47209 | B39: 78 | C39: 78 | D39: 78 | E39: 73.416 | F39: 59.77 | G39: 95.332 | H39: 78.134 | I39: 61.928 | J39: 50.213 | K39: 84.778 | L39: 58.907 | M39: 54.23 | N39: 50.172 | O39: 92.081 | P39: 60.562 | Q39: 88.699 | R39: 88.968 | S39: 46.697 | T39: 61.343 | U39: 53.758 | V39: 63.419 | W39: 80.937 | X39: 37.138 | Y39: 64.39 | Z39: 74.971 | AA39: 59.793 | AB39: 106.222 | AC39: 48.205 | AD39: 75.101 | AE39: 49.426 | AF39: 50.626 | AG39: 73.387 | AH39: 68.188 | ALQ39: #N/A
... A68: 48092 | B68: 35 | C68: 35 | D68: 35 | E68: 38.98 | F68: 55.09 | G68: 32.582 | H68: 46.333 | I68: 32.788 | J68: 30.222 | K68: 20.389 | L68: 54.208 | M68: 32.732 | N68: 36.911 | O68: 36.293 | P68: 39.821 | Q68: 43.454 | R68: 35.837 | S68: 28.553 | T68: 39.314 | U68: 23.102 | V68: 52.666 | W68: 50.639 | X68: 37.885 | Y68: 34.201 | Z68: 38.398 | AA68: 21.659 | AB68: 42.174 | AC68: 36.331 | AD68: 33.326 | AE68: 37.917 | AF68: 47.637 | AG68: 33.687 | AH68: 33.687 | ALQ68: #N/A
ALQ69: #N/A
ALQ70: #N/A
ALQ71: #N/A
ALQ72: #N/A

Sheet CrystalInflow.Unregulated
B2: Max | C2: Min | D2: Most | E2: 1991 | F2: 1992 | G2: 1993 | H2: 1994 | I2: 1995 | J2: 1996 | K2: 1997 | L2: 1998 | M2: 1999 | N2: 2000 | O2: 2001 | P2: 2002 | Q2: 2003 | R2: 2004 | S2: 2005 | T2: 2006 | U2: 2007 | V2: 2008 | W2: 2009 | X2: 2010 | Y2: 2011 | Z2: 2012 | AA2: 2013 | AB2: 2014 | AC2: 2015 | AD2: 2016 | AE2: 2017 | AF2: 2018 | AG2: 2019 | AH2: 2020
B3: Trace1 | C3: Trace2 | D3: Trace3 | E3: Trace4 | F3: Trace5 | G3: Trace6 | H3: Trace7 | I3: Trace8 | J3: Trace9 | K3: Trace10 | L3: Trace11 | M3: Trace12 | N3: Trace13 | O3: Trace14 | P3: Trace15 | Q3: Trace16 | R3: Trace17 | S3: Trace18 | T3: Trace19 | U3: Trace20 | V3: Trace21 | W3: Trace22 | X3: Trace23 | Y3: Trace24 | Z3: Trace25 | AA3: Trace26 | AB3: Trace27 | AC3: Trace28 | AD3: Trace29 | AE3: Trace30 | AF3: Trace31 | AG3: Trace32 | AH3: Trace33
A4: 46143 | B4: 126 | C4: 43 | D4: 75 | E4: 59.983 | F4: 94.667 | G4: 85.703 | H4: 74.949 | I4: 90.948 | J4: 66.322 | K4: 72.099 | L4: 56.194 | M4: 91.675 | N4: 88.531 | O4: 101.278 | P4: 56.885 | Q4: 87.319 | R4: 71.43 | S4: 88.924 | T4: 71.365 | U4: 82.999 | V4: 75.051 | W4: 86.001 | X4: 62.717 | Y4: 67.712 | Z4: 71.211 | AA4: 76.578 | AB4: 84.904 | AC4: 75.166 | AD4: 74.671 | AE4: 69.797 | AF4: 77.146 | AG4: 52.933 | AH4: 72.43
A5: 46174 | B5: 87 | C5: 30 | D5: 52 | E5: 56.118 | F5: 80.323 | G5: 61.369 | H5: 39.803 | I5: 171.089 | J5: 28.827 | K5: 78.307 | L5: 36.517 | M5: 83.917 | N5: 41.256 | O5: 49.848 | P5: 29.077 | Q5: 58.05 | R5: 31.456 | S5: 45.356 | T5: 32.548 | U5: 48.096 | V5: 67.402 | W5: 45.506 | X5: 54.152 | Y5: 79.616 | Z5: 26.596 | AA5: 47.319 | AB5: 64.136 | AC5: 164.153 | AD5: 64.572 | AE5: 64.719 | AF5: 28.648 | AG5: 101.67 | AH5: 40.047
A6: 46204 | B6: 45 | C6: 16 | D6: 27 | E6: 30.625 | F6: 39.795 | G6: 29.17 | H6: 22.322 | I6: 91.868 | J6: 20.201 | K6: 34.485 | L6: 21.589 | M6: 43.066 | N6: 24.385 | O6: 26.612 | P6: 20.43 | Q6: 25.486 | R6: 21.979 | S6: 25.26 | T6: 25.749 | U6: 27.388 | V6: 30.035 | W6: 26.202 | X6: 26.121 | Y6: 33.223 | Z6: 20.379 | AA6: 29.735 | AB6: 29.166 | AC6: 62.39 | AD6: 30.57 | AE6: 31.932 | AF6: 20.262 | AG6: 41.2 | AH6: 24.445
A7: 46235 | B7: 43 | C7: 25 | D7: 31 | E7: 29.528 | F7: 45.847 | G7: 27.731 | H7: 24.576 | I7: 45.007 | J7: 21.308 | K7: 35.024 | L7: 24.226 | M7: 40.767 | N7: 31.531 | O7: 36.547 | P7: 22.382 | Q7: 29.994 | R7: 24.358 | S7: 30.696 | T7: 32.704 | U7: 32.893 | V7: 29.502 | W7: 25.684 | X7: 32.227 | Y7: 27.663 | Z7: 24.719 | AA7: 33.199 | AB7: 32.172 | AC7: 38.921 | AD7: 31.962 | AE7: 31.304 | AF7: 21.951 | AG7: 32.347 | AH7: 24.926
A8: 46266 | B8: 38 | C8: 27 | D8: 25 | E8: 22.841 | F8: 36.266 | G8: 26.925 | H8: 24.895 | I8: 34.965 | J8: 20.829 | K8: 33.348 | L8: 19.958 | M8: 30.316 | N8: 26.046 | O8: 24.543 | P8: 22.905 | Q8: 54.331 | R8: 28.247 | S8: 24.24 | T8: 27.907 | U8: 36.843 | V8: 23.017 | W8: 21.621 | X8: 21.797 | Y8: 22.128 | Z8: 21.727 | AA8: 52.988 | AB8: 39.069 | AC8: 31.932 | AD8: 25.105 | AE8: 22.803 | AF8: 19.353 | AG8: 22.971 | AH8: 27.897
A9: 46296 | B9: 48 | C9: 38 | D9: 31 | E9: 21.404 | F9: 27.043 | G9: 28.3 | H9: 35.3 | I9: 40.985 | J9: 35.885 | K9: 43.308 | L9: 33.877 | M9: 27.16 | N9: 26.508 | O9: 24.723 | P9: 36.273 | Q9: 32.046 | R9: 29.692 | S9: 41.469 | T9: 63.727 | U9: 42.357 | V9: 24.607 | W9: 26.503 | X9: 25.357 | Y9: 27.226 | Z9: 21.184 | AA9: 52.767 | AB9: 51.654 | AC9: 29.686 | AD9: 23.782 | AE9: 26.953 | AF9: 22.856 | AG9: 23.152 | AH9: 30.117
A10: 46327 | B10: 38 | C10: 35 | D10: 32 | E10: 22.359 | F10: 23.371 | G10: 24.054 | H10: 28.124 | I10: 31.21 | J10: 29.783 | K10: 32.22 | L10: 30.626 | M10: 22.996 | N10: 23.806 | O10: 25.447 | P10: 23.755 | Q10: 23.932 | R10: 27.771 | S10: 33.811 | T10: 42.814 | U10: 34.345 | V10: 22.62 | W10: 25.986 | X10: 27.258 | Y10: 23.407 | Z10: 18.514 | AA10: 34.065 | AB10: 30.85 | AC10: 28.55 | AD10: 20.588 | AE10: 23.887 | AF10: 22.474 | AG10: 21.538 | AH10: 34.911
A11: 46357 | B11: 32 | C11: 31 | D11: 32 | E11: 20.557 | F11: 21.225 | G11: 19.887 | H11: 21.393 | I11: 29.852 | J11: 23.307 | K11: 23.892 | L11: 27.371 | M11: 20.456 | N11: 20.342 | O11: 20.591 | P11: 20.081 | Q11: 22.089 | R11: 21.202 | S11: 23.653 | T11: 28.704 | U11: 23.553 | V11: 20.06 | W11: 20.418 | X11: 22.931 | Y11: 20.229 | Z11: 16.947 | AA11: 25.31 | AB11: 25.126 | AC11: 25.071 | AD11: 19.638 | AE11: 22.735 | AF11: 17.867 | AG11: 20.499 | AH11: 26.846
A12: 46388 | B12: 30 | C12: 30 | D12: 31 | E12: 18.406 | F12: 20.1 | G12: 18.392 | H12: 19.507 | I12: 25.043 | J12: 19.849 | K12: 21.572 | L12: 23.54 | M12: 21.525 | N12: 18.923 | O12: 18.113 | P12: 19.062 | Q12: 19.818 | R12: 21.297 | S12: 20.33 | T12: 24.134 | U12: 19.404 | V12: 18.323 | W12: 18.106 | X12: 21.104 | Y12: 20.04 | Z12: 15.836 | AA12: 21.962 | AB12: 21.934 | AC12: 22.957 | AD12: 18.797 | AE12: 19.975 | AF12: 16.54 | AG12: 18.906 | AH12: 21.141
A13: 46419 | B13: 28 | C13: 28 | D13: 29 | E13: 17.685 | F13: 18.873 | G13: 15.815 | H13: 23.151 | I13: 26.093 | J13: 16.095 | K13: 19.106 | L13: 24.025 | M13: 23.039 | N13: 18.843 | O13: 15.494 | P13: 22.491 | Q13: 17.133 | R13: 19.039 | S13: 16.692 | T13: 24.903 | U13: 15.759 | V13: 17.01 | W13: 15.122 | X13: 17.538 | Y13: 16.861 | Z13: 14.1 | AA13: 23.312 | AB13: 28.42 | AC13: 22.057 | AD13: 26.143 | AE13: 23.235 | AF13: 14.562 | AG13: 17.457 | AH13: 20.833
A14: 46447 | B14: 50 | C14: 42 | D14: 46 | E14: 35.348 | F14: 37.195 | G14: 36.347 | H14: 52.809 | I14: 38.993 | J14: 43.709 | K14: 37.803 | L14: 39.48 | M14: 30.339 | N14: 30.99 | O14: 21.695 | P14: 38.07 | Q14: 54.26 | R14: 26.298 | S14: 27.64 | T14: 68.93 | U14: 18.328 | V14: 39.051 | W14: 19.756 | X14: 34.139 | Y14: 37.887 | Z14: 22.819 | AA14: 34.762 | AB14: 52.636 | AC14: 42.513 | AD14: 67.985 | AE14: 25.798 | AF14: 24.161 | AG14: 32.116 | AH14: 30.411
A15: 46478 | B15: 117 | C15: 82 | D15: 100 | E15: 83.014 | F15: 89.253 | G15: 71.324 | H15: 65.32 | I15: 100.898 | J15: 92.221 | K15: 67.452 | L15: 59.781 | M15: 88.966 | N15: 71.654 | O15: 58.141 | P15: 71.658 | Q15: 127.875 | R15: 73.061 | S15: 96.443 | T15: 115.27 | U15: 67.635 | V15: 64.407 | W15: 56.886 | X15: 87.112 | Y15: 88.517 | Z15: 47.068 | AA15: 78.304 | AB15: 82.284 | AC15: 77.583 | AD15: 126.187 | AE15: 49.885 | AF15: 101.913 | AG15: 51.246 | AH15: 58.278
... A27: 46844 | B27: 100 | C27: 100 | D27: 100 | E27: 97.416 | F27: 95.765 | G27: 77.418 | H27: 124.829 | I27: 113.607 | J27: 88.85 | K27: 75.567 | L27: 107.972 | M27: 84.097 | N27: 66.963 | O27: 71.738 | P27: 140.3 | Q27: 85.153 | R27: 118.637 | S27: 138.376 | T27: 75.867 | U27: 89.512 | V27: 70.296 | W27: 95.306 | X27: 115.813 | Y27: 49.035 | Z27: 85.311 | AA27: 101.584 | AB27: 83.354 | AC27: 141.978 | AD27: 66.424 | AE27: 111.301 | AF27: 66.47 | AG27: 63.613 | AH27: 101.101
A28: 46874 | B28: 251 | C28: 251 | D28: 251 | E28: 343.113 | F28: 266.995 | G28: 304.077 | H28: 431.317 | I28: 418.224 | J28: 260.526 | K28: 283.488 | L28: 296.957 | M28: 318.447 | N28: 111.016 | O28: 200.192 | P28: 278.96 | Q28: 328.836 | R28: 290.56 | S28: 296.751 | T28: 329.797 | U28: 380.321 | V28: 161.712 | W28: 215.196 | X28: 179.547 | Y28: 124.378 | Z28: 297.488 | AA28: 211.011 | AB28: 206.983 | AC28: 316.059 | AD28: 196.666 | AE28: 248.95 | AF28: 223.18 | AG28: 173.994 | AH28: 258.586 | ALQ28: #N/A
A29: 46905 | B29: 293 | C29: 293 | D29: 293 | E29: 460.594 | F29: 242.781 | G29: 672.189 | H29: 350.177 | I29: 574.158 | J29: 248.788 | K29: 400.198 | L29: 178.735 | M29: 220.105 | N29: 60.817 | O29: 230.442 | P29: 164.517 | Q29: 328.629 | R29: 209.637 | S29: 210.063 | T29: 571.369 | U29: 302.089 | V29: 318.114 | W29: 514.263 | X29: 65.031 | Y29: 167.906 | Z29: 381.748 | AA29: 415.581 | AB29: 350.806 | AC29: 455.73 | AD29: 80.348 | AE29: 489.504 | AF29: 222.831 | AG29: 315.65 | AH29: 190.807 | ALQ29: #N/A
A30: 46935 | B30: 98 | C30: 98 | D30: 98 | E30: 191.985 | F30: 68.807 | G30: 481.469 | H30: 117.383 | I30: 183.177 | J30: 113.444 | K30: 248.134 | L30: 54.566 | M30: 62.32 | N30: 26.273 | O30: 59.727 | P30: 58.913 | Q30: 118.938 | R30: 76.292 | S30: 71.126 | T30: 234.618 | U30: 142.1 | V30: 76.321 | W30: 246.71 | X30: 31.321 | Y30: 57.899 | Z30: 109.49 | AA30: 128.005 | AB30: 104.583 | AC30: 138.59 | AD30: 34.66 | AE30: 289.838 | AF30: 65.276 | AG30: 128.101 | AH30: 70.583 | ALQ30: #N/A
A31: 46966 | B31: 63 | C31: 63 | D31: 63 | E31: 73.266 | F31: 46.09 | G31: 131.81 | H31: 57.996 | I31: 88.443 | J31: 55.075 | K31: 97.874 | L31: 48.617 | M31: 56.687 | N31: 23.58 | O31: 45.144 | P31: 41.34 | Q31: 62.572 | R31: 55.61 | S31: 53.591 | T31: 84.586 | U31: 58.493 | V31: 55.136 | W31: 74.876 | X31: 32.569 | Y31: 42.161 | Z31: 63.214 | AA31: 57.516 | AB31: 57.812 | AC31: 67.944 | AD31: 29.275 | AE31: 88.705 | AF31: 43.604 | AG31: 58.069 | AH31: 60.646 | ALQ31: #N/A
A32: 46997 | B32: 42 | C32: 42 | D32: 42 | E32: 52.895 | F32: 38.972 | G32: 70.512 | H32: 43.824 | I32: 65.184 | J32: 36.2 | K32: 53.571 | L32: 36.396 | M32: 33.721 | N32: 23.614 | O32: 65.548 | P32: 41.668 | Q32: 41.225 | R32: 41.987 | S32: 50.496 | T32: 49.193 | U32: 40.181 | V32: 31.592 | W32: 43.842 | X32: 26.437 | Y32: 60.79 | Z32: 60.615 | AA32: 41.721 | AB32: 38.823 | AC32: 43.002 | AD32: 24.221 | AE32: 46.75 | AF32: 40.381 | AG32: 36.714 | AH32: 42.2 | ALQ32: #N/A
A33: 47027 | B33: 48 | C33: 38 | D33: 43 | E33: 51.778 | F33: 51.979 | G33: 67.305 | H33: 61.564 | I33: 74.13 | J33: 54.809 | K33: 43.887 | L33: 36.937 | M33: 34.356 | N33: 37.496 | O33: 39.446 | P33: 41.825 | Q33: 61.162 | R33: 84.593 | S33: 56.901 | T33: 47.987 | U33: 45.335 | V33: 36.126 | W33: 47.708 | X33: 26.697 | Y33: 58.532 | Z33: 72.692 | AA33: 39.465 | AB33: 35.942 | AC33: 46.337 | AD33: 29.235 | AE33: 43.051 | AF33: 43.051 | AG33: 32.784 | AH33: 33.201 | ALQ33: #N/A
A34: 47058 | B34: 39 | C34: 35 | D34: 37 | E34: 42.071 | F34: 39.733 | G34: 51.309 | H34: 49.551 | I34: 54 | J34: 45.181 | K34: 35.836 | L34: 33.031 | M34: 33.319 | N34: 24.226 | O34: 29.991 | P34: 38.257 | Q34: 46.781 | R34: 54.719 | S34: 44.016 | T34: 42.23 | U34: 41.824 | V34: 36.621 | W34: 39.187 | X34: 23.238 | Y34: 37.81 | Z34: 44.283 | AA34: 36.378 | AB34: 31.37 | AC34: 40.595 | AD34: 27.57 | AE34: 38.174 | AF34: 46.113 | AG34: 32.561 | AH34: 29.115 | ALQ34: #N/A
A35: 47088 | B35: 32 | C35: 32 | D35: 32 | E35: 36.014 | F35: 31.622 | G35: 47.207 | H35: 40.196 | I35: 41.437 | J35: 39.964 | K35: 32.028 | L35: 28.319 | M35: 27.488 | N35: 20.508 | O35: 27.438 | P35: 29.853 | Q35: 34.099 | R35: 37.667 | S35: 31.335 | T35: 37.565 | U35: 33.626 | V35: 30.737 | W35: 34.226 | X35: 21.338 | Y35: 28.193 | Z35: 36.297 | AA35: 32.157 | AB35: 29.303 | AC35: 37.222 | AD35: 22.46 | AE35: 35.565 | AF35: 36.065 | AG35: 29.234 | AH35: 26.278 | ALQ35: #N/A
A36: 47119 | B36: 31 | C36: 31 | D36: 31 | E36: 32.849 | F36: 28.65 | G36: 39.9 | H36: 34.634 | I36: 36.909 | J36: 34.537 | K36: 32.213 | L36: 26.045 | M36: 24.273 | N36: 19.722 | O36: 24.548 | P36: 29.063 | Q36: 29.525 | R36: 31.797 | S36: 26.1 | T36: 33.98 | U36: 29.808 | V36: 27.834 | W36: 32.698 | X36: 19.811 | Y36: 24.476 | Z36: 31.676 | AA36: 29.27 | AB36: 27.474 | AC36: 32.933 | AD36: 20.632 | AE36: 32.37 | AF36: 29.059 | AG36: 26.412 | AH36: 24.651 | ALQ36: #N/A
A37: 47150 | B37: 29 | C37: 29 | D37: 29 | E37: 27.74 | F37: 31.409 | G37: 39.069 | H37: 28.068 | I37: 31.587 | J37: 33.466 | K37: 31.889 | L37: 24.68 | M37: 20.558 | N37: 22.612 | O37: 21.13 | P37: 25.366 | Q37: 24.193 | R37: 31.657 | S37: 21.173 | T37: 30.095 | U37: 24.678 | V37: 23.133 | W37: 27.16 | X37: 17.375 | Y37: 26.085 | Z37: 37.231 | AA37: 27.588 | AB37: 33.82 | AC37: 34.288 | AD37: 17.936 | AE37: 28.609 | AF37: 27.412 | AG37: 24.4 | AH37: 22.681 | ALQ37: #N/A
A38: 47178 | B38: 46 | C38: 46 | D38: 46 | E38: 50.992 | F38: 62.4 | G38: 52.138 | H38: 59.903 | I38: 54.537 | J38: 52.361 | K38: 40.076 | L38: 37.422 | M38: 27.566 | N38: 38.749 | O38: 59.628 | P38: 33.046 | Q38: 35.988 | R38: 82.249 | S38: 24.383 | T38: 55.313 | U38: 30.391 | V38: 40.813 | W38: 52.123 | X38: 26.287 | Y38: 37.264 | Z38: 67.452 | AA38: 49.093 | AB38: 79.027 | AC38: 37.337 | AD38: 28.648 | AE38: 44.985 | AF38: 37.359 | AG38: 44.908 | AH38: 43.459 | ALQ38: #N/A
A39: 47209 | B39: 100 | C39: 100 | D39: 100 | E39: 96.332 | F39: 81.199 | G39: 125.471 | H39: 114.026 | I39: 91.046 | J39: 78.923 | K39: 109.593 | L39: 82.446 | M39: 67.925 | N39: 73.509 | O39: 138.903 | P39: 83.846 | Q39: 119.745 | R39: 140.153 | S39: 76.712 | T39: 86.419 | U39: 74.242 | V39: 97.733 | W39: 116.525 | X39: 50.864 | Y39: 84.935 | Z39: 101.443 | AA39: 85.838 | AB39: 144.091 | AC39: 67.937 | AD39: 115.796 | AE39: 66.662 | AF39: 67.015 | AG39: 102.369 | AH39: 99.148 | ALQ39: #N/A
... A68: 48092 | B68: 42 | C68: 42 | D68: 42 | E68: 44.066 | F68: 66.108 | G68: 37.199 | H68: 54.432 | I68: 37.007 | J68: 34.658 | K68: 23.506 | L68: 65.975 | M68: 41.489 | N68: 40.823 | O68: 41.853 | P68: 50.822 | Q68: 49.378 | R68: 40.411 | S68: 32.845 | T68: 44.393 | U68: 26.618 | V68: 61.019 | W68: 59.199 | X68: 41.69 | Y68: 39.232 | Z68: 43.227 | AA68: 24.613 | AB68: 47.372 | AC68: 40.454 | AD68: 37.63 | AE68: 43.508 | AF68: 53.115 | AG68: 39.054 | AH68: 39.054 | ALQ68: #N/A
ALQ69: #N/A
ALQ70: #N/A
ALQ71: #N/A
ALQ72: #N/A

Sheet Fontenelle.Inflow
B2: Max | C2: Min | D2: Most | E2: 1991 | F2: 1992 | G2: 1993 | H2: 1994 | I2: 1995 | J2: 1996 | K2: 1997 | L2: 1998 | M2: 1999 | N2: 2000 | O2: 2001 | P2: 2002 | Q2: 2003 | R2: 2004 | S2: 2005 | T2: 2006 | U2: 2007 | V2: 2008 | W2: 2009 | X2: 2010 | Y2: 2011 | Z2: 2012 | AA2: 2013 | AB2: 2014 | AC2: 2015 | AD2: 2016 | AE2: 2017 | AF2: 2018 | AG2: 2019 | AH2: 2020
B3: Trace1 | C3: Trace2 | D3: Trace3 | E3: Trace4 | F3: Trace5 | G3: Trace6 | H3: Trace7 | I3: Trace8 | J3: Trace9 | K3: Trace10 | L3: Trace11 | M3: Trace12 | N3: Trace13 | O3: Trace14 | P3: Trace15 | Q3: Trace16 | R3: Trace17 | S3: Trace18 | T3: Trace19 | U3: Trace20 | V3: Trace21 | W3: Trace22 | X3: Trace23 | Y3: Trace24 | Z3: Trace25 | AA3: Trace26 | AB3: Trace27 | AC3: Trace28 | AD3: Trace29 | AE3: Trace30 | AF3: Trace31 | AG3: Trace32 | AH3: Trace33
A4: 46143 | B4: 116 | C4: 31 | D4: 65 | E4: 71.309 | F4: 116.082 | G4: 125.307 | H4: 94.97 | I4: 46.156 | J4: 50.23 | K4: 70.582 | L4: 56.938 | M4: 47.198 | N4: 94.013 | O4: 79.179 | P4: 42.917 | Q4: 53.486 | R4: 59.012 | S4: 84.136 | T4: 85.641 | U4: 97.502 | V4: 64.401 | W4: 60.607 | X4: 23.563 | Y4: 35.261 | Z4: 60.387 | AA4: 72.708 | AB4: 65.599 | AC4: 66.589 | AD4: 90.384 | AE4: 57.24 | AF4: 94.388 | AG4: 38.356 | AH4: 39.451
A5: 46174 | B5: 293 | C5: 77 | D5: 165 | E5: 240.777 | F5: 104.633 | G5: 182.475 | H5: 113.384 | I5: 275.589 | J5: 211.899 | K5: 184.874 | L5: 169.08 | M5: 197.96 | N5: 147.31 | O5: 97.689 | P5: 149.876 | Q5: 134.671 | R5: 187.952 | S5: 198.852 | T5: 76.902 | U5: 77.141 | V5: 160.311 | W5: 237.688 | X5: 187.125 | Y5: 131.907 | Z5: 126.498 | AA5: 88.255 | AB5: 128.59 | AC5: 232.86 | AD5: 194.191 | AE5: 121.115 | AF5: 190.812 | AG5: 160.92 | AH5: 183.543
A6: 46204 | B6: 140 | C6: 37 | D6: 79 | E6: 103.652 | F6: 59.26 | G6: 111.446 | H6: 21.085 | I6: 209.791 | J6: 84.194 | K6: 66.188 | L6: 209.256 | M6: 106.724 | N6: 39.6 | O6: 26.428 | P6: 54.233 | Q6: 42.278 | R6: 139.894 | S6: 130.152 | T6: 8.981 | U6: 18.618 | V6: 101.166 | W6: 174.431 | X6: 174.643 | Y6: 184.696 | Z6: 44.848 | AA6: 31.696 | AB6: 73.856 | AC6: 134.859 | AD6: 59.34 | AE6: 45.098 | AF6: 65.947 | AG6: 116.678 | AH6: 84.144
A7: 46235 | B7: 60 | C7: 27 | D7: 30 | E7: 44.895 | F7: 23.848 | G7: 98.673 | H7: 17.18 | I7: 68.439 | J7: 30.005 | K7: 46.271 | L7: 61.822 | M7: 39.061 | N7: 22.001 | O7: 16.739 | P7: 23.165 | Q7: 20.031 | R7: 48.961 | S7: 43.91 | T7: 14.71 | U7: 22.497 | V7: 31.495 | W7: 47.846 | X7: 52.45 | Y7: 49.691 | Z7: 20.11 | AA7: 18.025 | AB7: 29.995 | AC7: 39.668 | AD7: 26.626 | AE7: 21.453 | AF7: 26.317 | AG7: 38.617 | AH7: 27.608
A8: 46266 | B8: 42 | C8: 26 | D8: 27 | E8: 41.277 | F8: 22.615 | G8: 38.6 | H8: 17.109 | I8: 35.03 | J8: 22.384 | K8: 40.817 | L8: 32.225 | M8: 36.715 | N8: 27.741 | O8: 16.183 | P8: 25.879 | Q8: 23.57 | R8: 39.411 | S8: 27.41 | T8: 15.897 | U8: 20.217 | V8: 28.418 | W8: 26.59 | X8: 32.317 | Y8: 28.122 | Z8: 16.526 | AA8: 24.194 | AB8: 29.124 | AC8: 28.512 | AD8: 26.223 | AE8: 24.742 | AF8: 19.902 | AG8: 31.36 | AH8: 20.394
A9: 46296 | B9: 51 | C9: 39 | D9: 36 | E9: 35.27 | F9: 25.271 | G9: 40.85 | H9: 32.37 | I9: 42.65 | J9: 31.291 | K9: 50.699 | L9: 42.153 | M9: 32.16 | N9: 33.108 | O9: 22.494 | P9: 33.857 | Q9: 24.61 | R9: 44.415 | S9: 36.156 | T9: 37.035 | U9: 41.39 | V9: 32.452 | W9: 38.803 | X9: 33.087 | Y9: 36.762 | Z9: 23.008 | AA9: 34.296 | AB9: 87.353 | AC9: 43.378 | AD9: 65.809 | AE9: 43.562 | AF9: 28.919 | AG9: 37.667 | AH9: 26.51
A10: 46327 | B10: 45 | C10: 39 | D10: 38 | E10: 36.648 | F10: 26.616 | G10: 34.97 | H10: 30.303 | I10: 40.194 | J10: 33.85 | K10: 34.502 | L10: 35.034 | M10: 30.339 | N10: 30.196 | O10: 31.459 | P10: 29.542 | Q10: 26.636 | R10: 44.365 | S10: 33.853 | T10: 28.584 | U10: 34.992 | V10: 35.48 | W10: 38.073 | X10: 33.87 | Y10: 35.135 | Z10: 30.218 | AA10: 29.623 | AB10: 43.844 | AC10: 34.466 | AD10: 66.924 | AE10: 37.398 | AF10: 31.106 | AG10: 32.309 | AH10: 31.495
A11: 46357 | B11: 34 | C11: 32 | D11: 32 | E11: 31.496 | F11: 22.856 | G11: 29.235 | H11: 23.868 | I11: 39.797 | J11: 31.515 | K11: 26.919 | L11: 30.895 | M11: 26.157 | N11: 24.597 | O11: 23.979 | P11: 24.304 | Q11: 22.622 | R11: 31.237 | S11: 29.519 | T11: 24.791 | U11: 25.383 | V11: 27.943 | W11: 30.314 | X11: 28.395 | Y11: 28.033 | Z11: 25.164 | AA11: 23.592 | AB11: 32.534 | AC11: 28.286 | AD11: 37.194 | AE11: 33.589 | AF11: 25.422 | AG11: 26.72 | AH11: 26.14
A12: 46388 | B12: 33 | C12: 29 | D12: 31 | E12: 26.969 | F12: 20.541 | G12: 25.443 | H12: 20.679 | I12: 30.948 | J12: 32.757 | K12: 22.97 | L12: 26.135 | M12: 22.954 | N12: 21.36 | O12: 19.849 | P12: 21.179 | Q12: 20.178 | R12: 26.222 | S12: 29.536 | T12: 23.184 | U12: 20.983 | V12: 25.805 | W12: 25.946 | X12: 25.684 | Y12: 25.556 | Z12: 21.076 | AA12: 20.908 | AB12: 30.11 | AC12: 25.064 | AD12: 29.885 | AE12: 28.767 | AF12: 22.173 | AG12: 23.059 | AH12: 22.295
A13: 46419 | B13: 31 | C13: 27 | D13: 29 | E13: 23.52 | F13: 19.14 | G13: 21.791 | H13: 29.001 | I13: 35.096 | J13: 26.513 | K13: 19.74 | L13: 24.317 | M13: 24.018 | N13: 18.936 | O13: 17.35 | P13: 27.031 | Q13: 18.941 | R13: 23.33 | S13: 24.891 | T13: 22.262 | U13: 17.921 | V13: 24.727 | W13: 22.089 | X13: 24.096 | Y13: 24.338 | Z13: 18.85 | AA13: 25.368 | AB13: 34.089 | AC13: 30.519 | AD13: 41.917 | AE13: 26.517 | AF13: 22.456 | AG13: 20.834 | AH13: 23.63
A14: 46447 | B14: 64 | C14: 43 | D14: 51 | E14: 44.99 | F14: 41.94 | G14: 43.334 | H14: 58.644 | I14: 52.174 | J14: 50.554 | K14: 38.321 | L14: 41.348 | M14: 34.142 | N14: 32.643 | O14: 26.22 | P14: 35.545 | Q14: 50.6 | R14: 44.808 | S14: 33.66 | T14: 55.602 | U14: 26.167 | V14: 44.227 | W14: 32.266 | X14: 32.028 | Y14: 52.707 | Z14: 33.359 | AA14: 38.694 | AB14: 61.907 | AC14: 50.116 | AD14: 124.707 | AE14: 33.863 | AF14: 36.946 | AG14: 38.869 | AH14: 30.948
A15: 46478 | B15: 97 | C15: 65 | D15: 77 | E15: 62.066 | F15: 63.2 | G15: 78.954 | H15: 57.642 | I15: 106.606 | J15: 79.439 | K15: 67.707 | L15: 56.308 | M15: 68.555 | N15: 43.397 | O15: 55.63 | P15: 58.884 | Q15: 101.37 | R15: 68.834 | S15: 90.347 | T15: 59.308 | U15: 31.542 | V15: 73.064 | W15: 45.632 | X15: 55.651 | Y15: 108.41 | Z15: 40.636 | AA15: 68.764 | AB15: 67.735 | AC15: 79.469 | AD15: 244.487 | AE15: 63.805 | AF15: 86.729 | AG15: 57.478 | AH15: 53.612
... A63: 47939 | B63: 77 | C63: 77 | D63: 77 | E63: 112.04 | F63: 90.81 | G63: 84.086 | H63: 63.018 | I63: 81.028 | J63: 47.116 | K63: 55.945 | L63: 59.662 | M63: 105.551 | N63: 71.202 | O63: 97.101 | P63: 68.613 | Q63: 32.552 | R63: 77.279 | S63: 52.149 | T63: 55.538 | U63: 131.142 | V63: 45.522 | W63: 68.824 | X63: 81.628 | Y63: 82.67 | Z63: 246.178 | AA63: 84.36 | AB63: 97.57 | AC63: 63.146 | AD63: 59.435 | AE63: 65.467 | AF63: 62.087 | AG63: 89.89 | AH63: 61.275
A64: 47969 | B64: 166 | C64: 166 | D64: 166 | E64: 154.675 | F64: 340.5 | G64: 162.293 | H64: 179.53 | I64: 173.235 | J64: 104.024 | K64: 50.479 | L64: 72.114 | M64: 100.908 | N64: 137.246 | O64: 234.853 | P64: 173.004 | Q64: 107.737 | R64: 137.413 | S64: 27.255 | T64: 144.788 | U64: 178.287 | V64: 71.157 | W64: 174.63 | X64: 188.582 | Y64: 127.266 | Z64: 368.149 | AA64: 275.84 | AB64: 87.038 | AC64: 125.673 | AD64: 81.97 | AE64: 151.075 | AF64: 200.793 | AG64: 193.472 | AH64: 193.472 | ALQ64: #N/A
A65: 48000 | B65: 301 | C65: 301 | D65: 301 | E65: 582.794 | F65: 712.318 | G65: 310.288 | H65: 533.898 | I65: 217.381 | J65: 119.214 | K65: 188.091 | L65: 209.056 | M65: 244.785 | N65: 362.429 | O65: 277.598 | P65: 64.304 | Q65: 272.16 | R65: 448.301 | S65: 202.232 | T65: 400.637 | U65: 207.884 | V65: 95.417 | W65: 442.824 | X65: 297.39 | Y65: 276.537 | Z65: 711.41 | AA65: 453.814 | AB65: 268.394 | AC65: 342.059 | AD65: 331.853 | AE65: 57.319 | AF65: 345.762 | AG65: 149.803 | AH65: 149.803 | ALQ65: #N/A
A66: 48030 | B66: 146 | C66: 146 | D66: 146 | E66: 282.358 | F66: 311.74 | G66: 354.608 | H66: 321.549 | I66: 65.439 | J66: 31.353 | K66: 78.955 | L66: 72.474 | M66: 166.212 | N66: 254.024 | O66: 78.081 | P66: 11.795 | Q66: 190.748 | R66: 343.871 | S66: 177.434 | T66: 599.543 | U66: 72.352 | V66: 37.059 | W66: 286.57 | X66: 132.428 | Y66: 90.021 | Z66: 355.95 | AA66: 196.289 | AB66: 211.662 | AC66: 167.735 | AD66: 161.405 | AE66: 31.328 | AF66: 222.926 | AG66: 28.749 | AH66: 28.749 | ALQ66: #N/A
A67: 48061 | B67: 59 | C67: 59 | D67: 59 | E67: 90.536 | F67: 151.24 | G67: 119.655 | H67: 112.274 | I67: 38.287 | J67: 21.42 | K67: 34.104 | L67: 34.042 | M67: 66.57 | N67: 83.482 | O67: 45.837 | P67: 28.127 | Q67: 61.363 | R67: 107.546 | S67: 59.454 | T67: 175.972 | U67: 38.57 | V67: 24.267 | W67: 97.829 | X67: 52.337 | Y67: 43.788 | Z67: 116.154 | AA67: 71.858 | AB67: 78.987 | AC67: 59.837 | AD67: 71.806 | AE67: 20.696 | AF67: 170.384 | AG67: 26.899 | AH67: 26.899 | ALQ67: #N/A
A68: 48092 | B68: 39 | C68: 39 | D68: 39 | E68: 54.884 | F68: 95.901 | G68: 57.275 | H68: 78.413 | I68: 43.031 | J68: 20.429 | K68: 34.676 | L68: 34.42 | M68: 53.825 | N68: 47.122 | O68: 37.296 | P68: 27.023 | Q68: 46.292 | R68: 52.28 | S68: 39.269 | T68: 77.937 | U68: 30.676 | V68: 30.832 | W68: 66.876 | X68: 40.735 | Y68: 39.289 | Z68: 80.368 | AA68: 45.647 | AB68: 55.304 | AC68: 39.595 | AD68: 57.993 | AE68: 24.504 | AF68: 67.416 | AG68: 25.915 | AH68: 25.915 | ALQ68: #N/A
ALQ69: #N/A
ALQ70: #N/A
ALQ71: #N/A
ALQ72: #N/A

Sheet PowellInflow.Unregulated
B2: Max | C2: Min | D2: Most | E2: 1991 | F2: 1992 | G2: 1993 | H2: 1994 | I2: 1995 | J2: 1996 | K2: 1997 | L2: 1998 | M2: 1999 | N2: 2000 | O2: 2001 | P2: 2002 | Q2: 2003 | R2: 2004 | S2: 2005 | T2: 2006 | U2: 2007 | V2: 2008 | W2: 2009 | X2: 2010 | Y2: 2011 | Z2: 2012 | AA2: 2013 | AB2: 2014 | AC2: 2015 | AD2: 2016 | AE2: 2017 | AF2: 2018 | AG2: 2019 | AH2: 2020
B3: Trace1 | C3: Trace2 | D3: Trace3 | E3: Trace4 | F3: Trace5 | G3: Trace6 | H3: Trace7 | I3: Trace8 | J3: Trace9 | K3: Trace10 | L3: Trace11 | M3: Trace12 | N3: Trace13 | O3: Trace14 | P3: Trace15 | Q3: Trace16 | R3: Trace17 | S3: Trace18 | T3: Trace19 | U3: Trace20 | V3: Trace21 | W3: Trace22 | X3: Trace23 | Y3: Trace24 | Z3: Trace25 | AA3: Trace26 | AB3: Trace27 | AC3: Trace28 | AD3: Trace29 | AE3: Trace30 | AF3: Trace31 | AG3: Trace32 | AH3: Trace33
A4: 46143 | B4: 517 | C4: 54 | D4: 180 | E4: 51.395 | F4: 348.96 | G4: 269.281 | H4: 158.187 | I4: 510.752 | J4: 135.529 | K4: 232.891 | L4: 70.603 | M4: 225.964 | N4: 231.63 | O4: 330 | P4: 0.786 | Q4: 257.723 | R4: 157.843 | S4: 245.381 | T4: 153.234 | U4: 334.9 | V4: 161.762 | W4: 268.076 | X4: 43.182 | Y4: 168.438 | Z4: 130.101 | AA4: 183.059 | AB4: 176.941 | AC4: 442.604 | AD4: 445.834 | AE4: 154.461 | AF4: 262.386 | AG4: 117.187 | AH4: 137.937
A5: 46174 | B5: 631 | C5: 66 | D5: 220 | E5: 273.853 | F5: 231.427 | G5: 270.768 | H5: 40.422 | I5: 910.382 | J5: 70.995 | K5: 315.692 | L5: 133.908 | M5: 388.236 | N5: 113.59 | O5: 87.793 | P5: 25.94 | Q5: 257.801 | R5: 3.032 | S5: 258.068 | T5: 28.386 | U5: 82.249 | V5: 234.836 | W5: 208.573 | X5: 296.066 | Y5: 358.72 | Z5: -22.666 | AA5: 93.912 | AB5: 241.356 | AC5: 728.782 | AD5: 250.952 | AE5: 164.434 | AF5: 33.089 | AG5: 473.611 | AH5: 82.559
A6: 46204 | B6: 80 | C6: 8 | D6: 28 | E6: 60.514 | F6: 27.307 | G6: 42.362 | H6: -71.661 | I6: 531.827 | J6: 0.955 | K6: 39.41 | L6: 105.638 | M6: 149.861 | N6: -44.827 | O6: -40.641 | P6: -52.164 | Q6: -9.019 | R6: 28.693 | S6: 80.451 | T6: -60.922 | U6: -52.672 | V6: 58.23 | W6: 115.339 | X6: 107.08 | Y6: 170.684 | Z6: -37.886 | AA6: -32.264 | AB6: 6.674 | AC6: 251.491 | AD6: 31.536 | AE6: -1.652 | AF6: -31.591 | AG6: 207.43 | AH6: -19.372
A7: 46235 | B7: 181 | C7: 107 | D7: 100 | E7: 108.269 | F7: 107.994 | G7: 138.624 | H7: 21.181 | I7: 238.626 | J7: 31.34 | K7: 190.302 | L7: 122.733 | M7: 242.351 | N7: 31.421 | O7: 78.507 | P7: 26.898 | Q7: 60.407 | R7: 67.694 | S7: 104.08 | T7: 66.011 | U7: 97.441 | V7: 91.405 | W7: 90.081 | X7: 143.668 | Y7: 126.046 | Z7: 47.851 | AA7: 105.32 | AB7: 105.495 | AC7: 149.826 | AD7: 118.358 | AE7: 71.32 | AF7: 36.461 | AG7: 102.559 | AH7: 35.437
A8: 46266 | B8: 273 | C8: 178 | D8: 150 | E8: 200.617 | F8: 162.837 | G8: 209.901 | H8: 121.746 | I8: 205.875 | J8: 121.759 | K8: 291.608 | L8: 142.757 | M8: 232.989 | N8: 111.136 | O8: 99.501 | P8: 151.029 | Q8: 228.744 | R8: 172.2 | S8: 122.561 | T8: 142.592 | U8: 177.428 | V8: 148.971 | W8: 103.384 | X8: 129.226 | Y8: 160.499 | Z8: 83.517 | AA8: 307.828 | AB8: 204.601 | AC8: 164.825 | AD8: 194.95 | AE8: 98.308 | AF8: 76.229 | AG8: 112.658 | AH8: 95.205
A9: 46296 | B9: 516 | C9: 350 | D9: 271 | E9: 214.349 | F9: 202.883 | G9: 296.221 | H9: 304.271 | I9: 354.534 | J9: 316.032 | K9: 554.869 | L9: 296.039 | M9: 230.647 | N9: 303.101 | O9: 179.128 | P9: 293.92 | Q9: 239.689 | R9: 376.475 | S9: 360.503 | T9: 846.34 | U9: 395.72 | V9: 232.268 | W9: 221.799 | X9: 324.075 | Y9: 328.55 | Z9: 173.548 | AA9: 481.564 | AB9: 482.89 | AC9: 329.427 | AD9: 328.104 | AE9: 296.419 | AF9: 284.133 | AG9: 222.275 | AH9: 201.608
A10: 46327 | B10: 456 | C10: 429 | D10: 371 | E10: 330.946 | F10: 288.498 | G10: 340.323 | H10: 355.922 | I10: 370.096 | J10: 377.899 | K10: 406.504 | L10: 424.583 | M10: 275.252 | N10: 320.74 | O10: 272.321 | P10: 315.164 | Q10: 303.561 | R10: 504.672 | S10: 386.105 | T10: 458.387 | U10: 388.264 | V10: 297.932 | W10: 312.082 | X10: 356.981 | Y10: 360.358 | Z10: 245.046 | AA10: 429.956 | AB10: 367.593 | AC10: 356.99 | AD10: 345.071 | AE10: 301.877 | AF10: 313.238 | AG10: 300.268 | AH10: 327.697
A11: 46357 | B11: 354 | C11: 347 | D11: 361 | E11: 284.528 | F11: 249.55 | G11: 257.626 | H11: 277.589 | I11: 337.648 | J11: 352.034 | K11: 294.813 | L11: 320.571 | M11: 250.901 | N11: 248.109 | O11: 250.047 | P11: 255.009 | Q11: 277.984 | R11: 310.725 | S11: 279.883 | T11: 313.553 | U11: 329.673 | V11: 273.188 | W11: 268.904 | X11: 322.688 | Y11: 286.614 | Z11: 236.702 | AA11: 300.138 | AB11: 294.919 | AC11: 295.125 | AD11: 298.307 | AE11: 270.192 | AF11: 249.927 | AG11: 294.991 | AH11: 274.567
A12: 46388 | B12: 364 | C12: 333 | D12: 350 | E12: 237.875 | F12: 320.985 | G12: 220.874 | H12: 261.403 | I12: 284.238 | J12: 313.992 | K12: 257.844 | L12: 251.779 | M12: 229.026 | N12: 224.821 | O12: 210.826 | P12: 217.926 | Q12: 239.605 | R12: 450.948 | S12: 250.582 | T12: 260.814 | U12: 261.305 | V12: 258.267 | W12: 234.334 | X12: 298.679 | Y12: 256.468 | Z12: 213.514 | AA12: 242.243 | AB12: 264.631 | AC12: 266.913 | AD12: 324.868 | AE12: 227.48 | AF12: 226.23 | AG12: 247.821 | AH12: 217.119
A13: 46419 | B13: 398 | C13: 378 | D13: 397 | E13: 256.069 | F13: 420.931 | G13: 195.653 | H13: 281.084 | I13: 294.707 | J13: 288.359 | K13: 260.873 | L13: 242.621 | M13: 258.196 | N13: 206.174 | O13: 159.507 | P13: 235.448 | Q13: 207.648 | R13: 453.67 | S13: 204.549 | T13: 264.423 | U13: 243.305 | V13: 255.386 | W13: 264.612 | X13: 243.493 | Y13: 228.103 | Z13: 207.105 | AA13: 234.636 | AB13: 344.743 | AC13: 298.787 | AD13: 447.09 | AE13: 218.133 | AF13: 230.421 | AG13: 214.317 | AH13: 202.981
A14: 46447 | B14: 660 | C14: 564 | D14: 614 | E14: 451.584 | F14: 497.674 | G14: 392.835 | H14: 808.256 | I14: 462.182 | J14: 626.722 | K14: 356.646 | L14: 346.334 | M14: 361.275 | N14: 397.733 | O14: 208.143 | P14: 392.945 | Q14: 531.967 | R14: 608.971 | S14: 304.498 | T14: 633.129 | U14: 343.763 | V14: 456.155 | W14: 404.486 | X14: 389.596 | Y14: 362.563 | Z14: 292.756 | AA14: 403.319 | AB14: 540.783 | AC14: 485.563 | AD14: 1037.175 | AE14: 277.195 | AF14: 472.263 | AG14: 370.541 | AH14: 326.552
A15: 46478 | B15: 1106 | C15: 716 | D15: 920 | E15: 852.851 | F15: 1176.78 | G15: 620.391 | H15: 745.263 | I15: 792.913 | J15: 1171.287 | K15: 761.23 | L15: 488.302 | M15: 604.021 | N15: 656.599 | O15: 369.782 | P15: 530.398 | Q15: 1218.578 | R15: 1232.239 | S15: 795.686 | T15: 948.591 | U15: 552.886 | V15: 573.86 | W15: 534.482 | X15: 928.965 | Y15: 797.799 | Z15: 280.688 | AA15: 575.788 | AB15: 542.845 | AC15: 708.988 | AD15: 1685.067 | AE15: 305.969 | AF15: 1024.375 | AG15: 435.99 | AH15: 363.5
... A63: 47939 | B63: 920 | C63: 920 | D63: 920 | E63: 1054.729 | F63: 1422.399 | G63: 1087.801 | H63: 712.34 | I63: 818.231 | J63: 787.499 | K63: 477.264 | L63: 553.846 | M63: 1378.734 | N63: 1396.574 | O63: 1071.401 | P63: 1168.752 | Q63: 666.288 | R63: 793.882 | S63: 733.533 | T63: 1107.199 | U63: 1194.504 | V63: 368.945 | W63: 666.445 | X63: 714.785 | Y63: 766.359 | Z63: 1881.444 | AA63: 490.274 | AB63: 1113.686 | AC63: 626.607 | AD63: 484.727 | AE63: 1020.845 | AF63: 1322.077 | AG63: 1001.244 | AH63: 914.814
A64: 47969 | B64: 2060 | C64: 2060 | D64: 2060 | E64: 3029.1 | F64: 4003.339 | G64: 2660.645 | H64: 2192.649 | I64: 2023.39 | J64: 2254.13 | K64: 302.246 | L64: 1405.591 | M64: 1775.783 | N64: 2997.564 | O64: 2392.268 | P64: 2074.589 | Q64: 2150.605 | R64: 2767.837 | S64: 988.465 | T64: 2409.257 | U64: 1367.706 | V64: 753.78 | W64: 1672.363 | X64: 1419.685 | Y64: 2033.998 | Z64: 2471.448 | AA64: 1275.5 | AB64: 2464.55 | AC64: 1570.331 | AD64: 1000.218 | AE64: 1882.442 | AF64: 3481.887 | AG64: 2091.294 | AH64: 2091.294 | ALQ64: #N/A
A65: 48000 | B65: 2423 | C65: 2423 | D65: 2423 | E65: 2887.08 | F65: 4852.396 | G65: 2548.119 | H65: 3311.496 | I65: 1394.195 | J65: 1557.36 | K65: 387.319 | L65: 2128.235 | M65: 1030.879 | N65: 3526.776 | O65: 2006.026 | P65: 1160.007 | Q65: 3711.269 | R65: 2567.931 | S65: 2575.158 | T65: 5040.035 | U65: 433.112 | V65: 1239.434 | W65: 2957.754 | X65: 2199.399 | Y65: 2500.478 | Z65: 3245.023 | AA65: 960.248 | AB65: 3767.66 | AC65: 1778.969 | AD65: 2358.643 | AE65: 1162.015 | AF65: 4362.314 | AG65: 1634.534 | AH65: 1634.534 | ALQ65: #N/A
A66: 48030 | B66: 711 | C66: 711 | D66: 711 | E66: 1181.504 | F66: 1750.979 | G66: 1515.153 | H66: 1850.712 | I66: 257.115 | J66: 342.784 | K66: 15.012 | L66: 507.362 | M66: 405.432 | N66: 1468.558 | O66: 500.561 | P66: 317.82 | Q66: 1877.132 | R66: 1537.053 | S66: 876.904 | T66: 3676.848 | U66: 105.676 | V66: 298.007 | W66: 1071.355 | X66: 798.586 | Y66: 748.196 | Z66: 1157.116 | AA66: 251.464 | AB66: 2261.459 | AC66: 472.299 | AD66: 983.838 | AE66: 413.715 | AF66: 1916.485 | AG66: 319.135 | AH66: 319.135 | ALQ66: #N/A
A67: 48061 | B67: 371 | C67: 371 | D67: 371 | E67: 376.492 | F67: 852.817 | G67: 564.695 | H67: 765.008 | I67: 167.756 | J67: 258.345 | K67: 61.115 | L67: 217.653 | M67: 208.321 | N67: 508.284 | O67: 314.475 | P67: 290.395 | Q67: 577.079 | R67: 459.511 | S67: 415.942 | T67: 861.172 | U67: 156.741 | V67: 239.971 | W67: 453.135 | X67: 289.834 | Y67: 355.199 | Z67: 496.203 | AA67: 159.638 | AB67: 596.23 | AC67: 227.05 | AD67: 380.136 | AE67: 286.19 | AF67: 705.966 | AG67: 200.621 | AH67: 200.621 | ALQ67: #N/A
A68: 48092 | B68: 316 | C68: 316 | D68: 316 | E68: 383.245 | F68: 761.05 | G68: 423.399 | H68: 526.585 | I68: 249.704 | J68: 233.817 | K68: 205.942 | L68: 399.987 | M68: 334.229 | N68: 388.919 | O68: 362.926 | P68: 359.503 | Q68: 440.978 | R68: 324.223 | S68: 295.624 | T68: 548.14 | U68: 190.671 | V68: 476.812 | W68: 459.066 | X68: 268.628 | Y68: 381.75 | Z68: 367.839 | AA68: 175.395 | AB68: 388.227 | AC68: 247.691 | AD68: 414.929 | AE68: 310.412 | AF68: 602.97 | AG68: 312.232 | AH68: 312.232 | ALQ68: #N/A
ALQ69: #N/A
ALQ70: #N/A
ALQ71: #N/A
ALQ72: #N/A

Sheet FlamingGorgeInflow.Unregulated
B2: Max | C2: Min | D2: Most | E2: 1991 | F2: 1992 | G2: 1993 | H2: 1994 | I2: 1995 | J2: 1996 | K2: 1997 | L2: 1998 | M2: 1999 | N2: 2000 | O2: 2001 | P2: 2002 | Q2: 2003 | R2: 2004 | S2: 2005 | T2: 2006 | U2: 2007 | V2: 2008 | W2: 2009 | X2: 2010 | Y2: 2011 | Z2: 2012 | AA2: 2013 | AB2: 2014 | AC2: 2015 | AD2: 2016 | AE2: 2017 | AF2: 2018 | AG2: 2019 | AH2: 2020
B3: Trace1 | C3: Trace2 | D3: Trace3 | E3: Trace4 | F3: Trace5 | G3: Trace6 | H3: Trace7 | I3: Trace8 | J3: Trace9 | K3: Trace10 | L3: Trace11 | M3: Trace12 | N3: Trace13 | O3: Trace14 | P3: Trace15 | Q3: Trace16 | R3: Trace17 | S3: Trace18 | T3: Trace19 | U3: Trace20 | V3: Trace21 | W3: Trace22 | X3: Trace23 | Y3: Trace24 | Z3: Trace25 | AA3: Trace26 | AB3: Trace27 | AC3: Trace28 | AD3: Trace29 | AE3: Trace30 | AF3: Trace31 | AG3: Trace32 | AH3: Trace33
A4: 46143 | B4: 127 | C4: 32 | D4: 70 | E4: 80.453 | F4: 124.738 | G4: 140.512 | H4: 98.898 | I4: 64.816 | J4: 60.345 | K4: 78.419 | L4: 65.378 | M4: 54.66 | N4: 97.864 | O4: 87.636 | P4: 48.781 | Q4: 63.51 | R4: 66.774 | S4: 96.576 | T4: 90.891 | U4: 113.616 | V4: 69.528 | W4: 66.171 | X4: 35.406 | Y4: 57.164 | Z4: 68.538 | AA4: 78.591 | AB4: 70.472 | AC4: 99.515 | AD4: 223.746 | AE4: 66.355 | AF4: 103.637 | AG4: 57.773 | AH4: 47.118
A5: 46174 | B5: 319 | C5: 79 | D5: 175 | E5: 261.594 | F5: 103.433 | G5: 188.816 | H5: 115.122 | I5: 313.879 | J5: 206.962 | K5: 177.663 | L5: 181.973 | M5: 201.332 | N5: 147.838 | O5: 100.575 | P5: 144.304 | Q5: 151.519 | R5: 176.72 | S5: 193.506 | T5: 79.804 | U5: 78.874 | V5: 157.841 | W5: 231.955 | X5: 186.901 | Y5: 148.139 | Z5: 119.698 | AA5: 88.776 | AB5: 130.109 | AC5: 240.505 | AD5: 218.678 | AE5: 116.09 | AF5: 187.973 | AG5: 173.28 | AH5: 177.224
A6: 46204 | B6: 153 | C6: 38 | D6: 84 | E6: 115.282 | F6: 65.158 | G6: 115.66 | H6: 21.962 | I6: 230.385 | J6: 91.464 | K6: 71.157 | L6: 219.817 | M6: 115.127 | N6: 41.82 | O6: 29.365 | P6: 59.499 | Q6: 59.758 | R6: 149.26 | S6: 141.796 | T6: 8.996 | U6: 17.811 | V6: 110.3 | W6: 188.787 | X6: 188.036 | Y6: 198.353 | Z6: 48.978 | AA6: 32.53 | AB6: 77.839 | AC6: 150.784 | AD6: 72.801 | AE6: 51.639 | AF6: 71.302 | AG6: 122.989 | AH6: 90.161
A7: 46235 | B7: 68 | C7: 29 | D7: 34 | E7: 51.723 | F7: 25.223 | G7: 105.312 | H7: 17.621 | I7: 75.23 | J7: 31.931 | K7: 52.823 | L7: 67.471 | M7: 42.016 | N7: 22.173 | O7: 18.797 | P7: 25.34 | Q7: 23.785 | R7: 51.117 | S7: 46.355 | T7: 15.221 | U7: 23.774 | V7: 33.727 | W7: 52.004 | X7: 55.553 | Y7: 54.322 | Z7: 20.511 | AA7: 18.494 | AB7: 35.564 | AC7: 43.595 | AD7: 34.273 | AE7: 24.772 | AF7: 27.576 | AG7: 41.369 | AH7: 28.744
A8: 46266 | B8: 47 | C8: 28 | D8: 28 | E8: 45.195 | F8: 21.989 | G8: 39.615 | H8: 16.161 | I8: 37.06 | J8: 23.554 | K8: 43.274 | L8: 32.284 | M8: 38.332 | N8: 29.349 | O8: 15.434 | P8: 26.169 | Q8: 25.314 | R8: 39.934 | S8: 27.757 | T8: 15.92 | U8: 20.538 | V8: 31.554 | W8: 25.982 | X8: 32.784 | Y8: 29.149 | Z8: 15.258 | AA8: 23.849 | AB8: 35.151 | AC8: 28.243 | AD8: 36.926 | AE8: 24.967 | AF8: 18.953 | AG8: 32.404 | AH8: 20.839
A9: 46296 | B9: 61 | C9: 44 | D9: 40 | E9: 39.275 | F9: 25.941 | G9: 46.12 | H9: 49.195 | I9: 47.332 | J9: 34.333 | K9: 58.391 | L9: 46.076 | M9: 34.53 | N9: 38.788 | O9: 23.057 | P9: 38.151 | Q9: 27.859 | R9: 51.378 | S9: 37.182 | T9: 41.24 | U9: 52.532 | V9: 35.627 | W9: 40.783 | X9: 34.532 | Y9: 43.644 | Z9: 24.032 | AA9: 51.03 | AB9: 99.442 | AC9: 45.895 | AD9: 83.479 | AE9: 50.297 | AF9: 35.001 | AG9: 42.319 | AH9: 28.239
A10: 46327 | B10: 55 | C10: 46 | D10: 44 | E10: 50.539 | F10: 30.893 | G10: 43.98 | H10: 39.433 | I10: 49.701 | J10: 45.513 | K10: 41.091 | L10: 44.384 | M10: 36.961 | N10: 37.274 | O10: 35.254 | P10: 35.19 | Q10: 35.799 | R10: 72.527 | S10: 40.378 | T10: 34.649 | U10: 43.851 | V10: 42.716 | W10: 46.002 | X10: 41.186 | Y10: 45.894 | Z10: 35.712 | AA10: 39.003 | AB10: 54.246 | AC10: 42.885 | AD10: 84.76 | AE10: 45.325 | AF10: 39.738 | AG10: 39.964 | AH10: 37.178
A11: 46357 | B11: 37 | C11: 33 | D11: 34 | E11: 41.763 | F11: 25.995 | G11: 36.5 | H11: 29.329 | I11: 50.155 | J11: 41.307 | K11: 31.639 | L11: 39.698 | M11: 31.89 | N11: 28.195 | O11: 27.769 | P11: 27.77 | Q11: 28.187 | R11: 42.3 | S11: 34.516 | T11: 28.595 | U11: 30.02 | V11: 33.749 | W11: 37.244 | X11: 35.74 | Y11: 37.126 | Z11: 28.56 | AA11: 28.591 | AB11: 41.48 | AC11: 36.508 | AD11: 52.04 | AE11: 40.336 | AF11: 29.578 | AG11: 34.042 | AH11: 29.985
A12: 46388 | B12: 45 | C12: 40 | D12: 42 | E12: 33.246 | F12: 23.678 | G12: 30.383 | H12: 27.387 | I12: 39.834 | J12: 57.038 | K12: 27.457 | L12: 32.917 | M12: 26.748 | N12: 24.979 | O12: 23.406 | P12: 24.961 | Q12: 25.631 | R12: 35.818 | S12: 34.72 | T12: 27.065 | U12: 25.064 | V12: 29.579 | W12: 32.531 | X12: 32.389 | Y12: 33.617 | Z12: 24.117 | AA12: 25.871 | AB12: 39.73 | AC12: 30.135 | AD12: 43.434 | AE12: 33.541 | AF12: 26.056 | AG12: 29.592 | AH12: 25.779
A13: 46419 | B13: 50 | C13: 42 | D13: 43 | E13: 36.893 | F13: 26.164 | G13: 30.398 | H13: 45.609 | I13: 51.419 | J13: 42.895 | K13: 28.381 | L13: 33.502 | M13: 34.657 | N13: 26.547 | O13: 24.873 | P13: 37.607 | Q13: 28.301 | R13: 36.178 | S13: 33.666 | T13: 32.857 | U13: 25.505 | V13: 33.606 | W13: 29.366 | X13: 33.022 | Y13: 34.553 | Z13: 26.192 | AA13: 37.56 | AB13: 50.169 | AC13: 45.222 | AD13: 83.445 | AE13: 38.079 | AF13: 29.708 | AG13: 28.943 | AH13: 33.556
A14: 46447 | B14: 120 | C14: 68 | D14: 85 | E14: 112.352 | F14: 90.052 | G14: 90.855 | H14: 104.661 | I14: 86.708 | J14: 99.469 | K14: 73.769 | L14: 72.564 | M14: 58.215 | N14: 61.862 | O14: 49.144 | P14: 63.199 | Q14: 92.527 | R14: 83.04 | S14: 59.639 | T14: 87.835 | U14: 47.18 | V14: 73.361 | W14: 53.035 | X14: 61.622 | Y14: 87.583 | Z14: 58.542 | AA14: 68.272 | AB14: 91.006 | AC14: 88.414 | AD14: 326.359 | AE14: 60.781 | AF14: 64.535 | AG14: 86.672 | AH14: 53.565
A15: 46478 | B15: 146 | C15: 91 | D15: 111 | E15: 109.72 | F15: 154.935 | G15: 112.224 | H15: 88.046 | I15: 139.048 | J15: 123.416 | K15: 136.019 | L15: 92.852 | M15: 93.715 | N15: 95.82 | O15: 79.374 | P15: 87.947 | Q15: 140.673 | R15: 119.423 | S15: 121.453 | T15: 88.006 | U15: 52.389 | V15: 113.011 | W15: 73.841 | X15: 193.578 | Y15: 147.468 | Z15: 63.144 | AA15: 88.802 | AB15: 90.757 | AC15: 139.845 | AD15: 519.515 | AE15: 85.84 | AF15: 253.732 | AG15: 115.452 | AH15: 75.478
... A63: 47939 | B63: 111 | C63: 111 | D63: 111 | E63: 158.951 | F63: 140.446 | G63: 162.785 | H63: 109.172 | I63: 117.363 | J63: 104.315 | K63: 83.898 | L63: 90.098 | M63: 149.07 | N63: 125.049 | O63: 134.864 | P63: 100.605 | Q63: 54.54 | R63: 121.223 | S63: 85.558 | T63: 197.659 | U63: 193.145 | V63: 72.403 | W63: 91.727 | X63: 108.213 | Y63: 145.508 | Z63: 537.05 | AA63: 120.231 | AB63: 273.542 | AC63: 130.707 | AD63: 87.253 | AE63: 117.598 | AF63: 159.566 | AG63: 137.366 | AH63: 96.814
A64: 47969 | B64: 239 | C64: 239 | D64: 239 | E64: 251.258 | F64: 471.325 | G64: 255.956 | H64: 358.982 | I64: 200.501 | J64: 169.236 | K64: 56.971 | L64: 86.394 | M64: 122.818 | N64: 267.222 | O64: 292.926 | P64: 211.597 | Q64: 134.25 | R64: 192.198 | S64: 62.678 | T64: 351.736 | U64: 232.076 | V64: 93.6 | W64: 198.336 | X64: 243.508 | Y64: 394.263 | Z64: 573.842 | AA64: 324.883 | AB64: 183.325 | AC64: 171.084 | AD64: 117.962 | AE64: 192.219 | AF64: 333.204 | AG64: 237.754 | AH64: 237.754 | ALQ64: #N/A
A65: 48000 | B65: 389 | C65: 389 | D65: 389 | E65: 690.51 | F65: 854.378 | G65: 467.58 | H65: 753.176 | I65: 239.883 | J65: 152.862 | K65: 189.329 | L65: 248.564 | M65: 246.15 | N65: 468.378 | O65: 327.515 | P65: 77.262 | Q65: 325.782 | R65: 526.976 | S65: 276.911 | T65: 683.838 | U65: 217.216 | V65: 104.842 | W65: 490.053 | X65: 353.874 | Y65: 414.702 | Z65: 870.83 | AA65: 500.528 | AB65: 355.049 | AC65: 397.873 | AD65: 414.636 | AE65: 73.924 | AF65: 461.72 | AG65: 183.208 | AH65: 183.208 | ALQ65: #N/A
A66: 48030 | B66: 161 | C66: 161 | D66: 161 | E66: 308 | F66: 341.532 | G66: 436.478 | H66: 383.832 | I66: 71.944 | J66: 39.278 | K66: 85.556 | L66: 96.321 | M66: 177.169 | N66: 299.447 | O66: 84.727 | P66: 11.123 | Q66: 222.508 | R66: 390.073 | S66: 213.903 | T66: 792.393 | U66: 79.701 | V66: 39 | W66: 299.607 | X66: 152.504 | Y66: 124.184 | Z66: 406.433 | AA66: 211.78 | AB66: 247.534 | AC66: 184.118 | AD66: 185.706 | AE66: 38.582 | AF66: 257.157 | AG66: 34.689 | AH66: 34.689 | ALQ66: #N/A
A67: 48061 | B67: 66 | C67: 66 | D67: 66 | E67: 100.06 | F67: 170.068 | G67: 142.722 | H67: 131.765 | I67: 42.159 | J67: 25.687 | K67: 36.561 | L67: 40.398 | M67: 71.111 | N67: 96.032 | O67: 49.787 | P67: 30.007 | Q67: 68.743 | R67: 120.535 | S67: 68.89 | T67: 206.983 | U67: 42.802 | V67: 25.966 | W67: 110.314 | X67: 59.078 | Y67: 63.573 | Z67: 146.021 | AA67: 81.679 | AB67: 95.152 | AC67: 68.966 | AD67: 86.244 | AE67: 26.128 | AF67: 190.909 | AG67: 32.674 | AH67: 32.674 | ALQ67: #N/A
A68: 48092 | B68: 43 | C68: 43 | D68: 43 | E68: 61.808 | F68: 108.269 | G68: 66.403 | H68: 94.356 | I68: 48.905 | J68: 22.254 | K68: 34.215 | L68: 37.752 | M68: 56.921 | N68: 54.064 | O68: 40.196 | P68: 28.629 | Q68: 54.944 | R68: 55.851 | S68: 43.857 | T68: 90.755 | U68: 32.891 | V68: 30.334 | W68: 78.913 | X68: 42.163 | Y68: 63.253 | Z68: 99.736 | AA68: 51.116 | AB68: 68.362 | AC68: 48.557 | AD68: 70.194 | AE68: 27.483 | AF68: 77.295 | AG68: 28.775 | AH68: 28.775 | ALQ68: #N/A
ALQ69: #N/A
ALQ70: #N/A
ALQ71: #N/A
ALQ72: #N/A

Sheet MorrowPointInflow.Unregulated
A1: MPOIN_IN_
B2: Max | C2: Min | D2: Most | E2: 1991 | F2: 1992 | G2: 1993 | H2: 1994 | I2: 1995 | J2: 1996 | K2: 1997 | L2: 1998 | M2: 1999 | N2: 2000 | O2: 2001 | P2: 2002 | Q2: 2003 | R2: 2004 | S2: 2005 | T2: 2006 | U2: 2007 | V2: 2008 | W2: 2009 | X2: 2010 | Y2: 2011 | Z2: 2012 | AA2: 2013 | AB2: 2014 | AC2: 2015 | AD2: 2016 | AE2: 2017 | AF2: 2018 | AG2: 2019 | AH2: 2020
B3: Trace1 | C3: Trace2 | D3: Trace3 | E3: Trace4 | F3: Trace5 | G3: Trace6 | H3: Trace7 | I3: Trace8 | J3: Trace9 | K3: Trace10 | L3: Trace11 | M3: Trace12 | N3: Trace13 | O3: Trace14 | P3: Trace15 | Q3: Trace16 | R3: Trace17 | S3: Trace18 | T3: Trace19 | U3: Trace20 | V3: Trace21 | W3: Trace22 | X3: Trace23 | Y3: Trace24 | Z3: Trace25 | AA3: Trace26 | AB3: Trace27 | AC3: Trace28 | AD3: Trace29 | AE3: Trace30 | AF3: Trace31 | AG3: Trace32 | AH3: Trace33
A4: 46143 | B4: 113 | C4: 39 | D4: 68 | E4: 56.235 | F4: 85.29 | G4: 76.564 | H4: 67.472 | I4: 81.172 | J4: 60.265 | K4: 66.555 | L4: 52.167 | M4: 81.526 | N4: 79.473 | O4: 89.5 | P4: 52.209 | Q4: 80.769 | R4: 65.149 | S4: 82.163 | T4: 64.893 | U4: 73.774 | V4: 68.529 | W4: 78.154 | X4: 58.862 | Y4: 59.064 | Z4: 65.241 | AA4: 71.321 | AB4: 77.755 | AC4: 65.005 | AD4: 69.405 | AE4: 63.618 | AF4: 69.806 | AG4: 48.482 | AH4: 66.432
A5: 46174 | B5: 82 | C5: 28 | D5: 49 | E5: 52.367 | F5: 70.969 | G5: 57.053 | H5: 37.534 | I5: 155.462 | J5: 27.925 | K5: 72.496 | L5: 34.597 | M5: 75.34 | N5: 39.205 | O5: 46.94 | P5: 27.783 | Q5: 55.492 | R5: 30.516 | S5: 43.659 | T5: 31.411 | U5: 43.905 | V5: 61.721 | W5: 43.279 | X5: 51.06 | Y5: 70.423 | Z5: 25.763 | AA5: 45.409 | AB5: 58.811 | AC5: 145.557 | AD5: 59.474 | AE5: 58.477 | AF5: 27.772 | AG5: 91.658 | AH5: 38
